28875591A3K27G600007IB002000CVS   0000080000Y
28875591A1K27GA00006BB002000AFL   0000132200Y
28875591XAK27GA000109001000
28875592XAK27GA00010A000100
28875592A4K27GA0000EBS000200DIA   0001299100Y
28875593X3K27G600007H000100
28875592X4K27GA0000E7000100
28875593AAK27GA00010RB001000SDS   0000547700Y
28875593XAK27GA00010H001000
28875594A9K27G60000PKB002000QQQQ  0000495500Y
28875597XAK27GA00010G003000
28875597XAK27GA00010F003000
28875597X4K27GA0000EB000200
28875598A4K27GA0000ECB002000DIS   0000328500Y
28875601X8K27G600003G000500
28875601X8K27G6000033000500
28875601X8K27G600003H000100
28875600XAK27GA0000K1001000
28875600AAK27GA0000K1S001000SPY   0001425900Y
28875600XAK27GA0000EW000500
28875600AAK27GA0000EWS000500SPY   0001425900Y
28875600A4K27GA0000EDS000200DIA   0001298800Y
28875601X8K27G600003F000100
28875601X8K27G6000032000500
28875601X8K27G600003I000500
28875601X8K27G6000034000100
28875601X8K27G6000031000100
28875601XAK27GA0000FE000500
28875601AAK27GA0000FEB000500SPY   0001425300Y
28875601AAK27GA00010SS003000SPY   0001426200Y
28875601X9K27G60000G8002000
28875601A9K27G60000G8B002000QQQQ  0000495700Y
28875601XAK27GA0000ZV003000
28875601XAK27GA0000ZI003000
28875601XAK27GA0000ZK002000
28875601XAK27GA0000ZX001000
28875601X9K27G60000G1002000
28875601A9K27G60000G1S002000QQQQ  0000496300Y
28875601AAK27GA00010TS003000SPY   0001426200Y
28875601XAK27GA00010N002000
28875601AAK27GA00010NB002000SPY   0001425300Y
28875601XAK27GA0000O6000500
28875601AAK27GA0000O6S000500SPY   0001426000Y
28875601XAK27GA0000EX000500
28875601AAK27GA0000EXB000500SPY   0001425300Y
28875601XAK27GA0000E5001000
28875601AAK27GA0000E5S001000SPY   0001426000Y
28875601AAK27GA00010UB003000SPY   0001425300Y
28875601XAK27GA0000ZM000500
28875601AAK27GA0000ZMS000500SPY   0001426000Y
28875601XAK27GA0000ZH003000
28875601XAK27GA0000ZT003000
28875601AAK27GA00010VB003000SPY   0001425300Y
28875601AAK27GA00010WB002000SPY   0001425300Y
28875602XAK27GA0000ZS002000
28875602A1K27GA00006CB002000ANN   0000258900Y
28875602X4K27GA0000ED000200
28875602XAK27GA0000FD000500
28875602AAK27GA0000FDB000500SPY   0001425300Y
28875602AAK27GA00010XS001000SDS   0000549000Y
28875602AAK27GA00010YB002000SPY   0001425300Y
28875603XBK27GA0000Q0001000
28875603ABK27GA0000Q6B001000SSO   0000764200Y
28875603AAK27GA00010ZS003000SPY   0001426400Y
28875603A8K27G600003JB000500MZZ   0000491600Y
28875603XBK27GA0000Q5001000
28875604A8K27G600003KS000100MVV   0000809400Y
28875603AAK27GA000110S001000SPY   0001425900Y
28875603AAK27GA000111S003000SPY   0001426400Y
28875603AAK27GA000112S002000SPY   0001425900Y
28875603XAK27GA0000F7000500
28875603AAK27GA0000F7B000500SPY   0001425300Y
28875603XAK27GA0000E4001000
28875603AAK27GA0000E4B001000SPY   0001425300Y
28875604XAK27GA0000ZU001000
28875604AAK27GA000113B001000SPY   0001425300Y
28875604XAK27GA0000EB001000
28875604AAK27GA0000EBB001000SPY   0001425300Y
28875605XBK27GA0000Q4001000
28875605ABK27GA0000Q7B001000SSO   0000764000Y
28875604AAK27GA000114S000100SH    0000618900Y
28875605ABK27GA0000Q8B001000SSO   0000764300Y
28875605XBK27GA0000Q6001000
28875605ABK27GA0000Q9S001000SSO   0000765200Y
28875605XAK27GA0000ZQ001000
28875605AAK27GA000115B001000SPY   0001425300Y
28875606XBK27GA0000Q8001000
28875606XAK27GA000114000100
28875606XAK27GA0000F7000500
28875606AAK27GA0000F7B000500SPY   0001425100Y
28875606XAK27GA00010L000500
28875606XAK27GA00010Q002500
28875607ABK27GA0000QAB001000SSO   0000764100Y
28875607A4K27GA0000EES000200DIA   0001299100Y
28875608XBK27GA0000Q7001000
28875608ABK27GA0000QBB001000SSO   0000764300Y
28875607AAK27GA000116S000100SH    0000618900Y
28875608XAK27GA0000ZP001000
28875608XAK27GA0000F7000500
28875608AAK27GA0000F7B000500SPY   0001425300Y
28875611XAK27GA00010R001000
28875613AAK27GA000117B001000SDS   0000547600Y
28875613A6K27GA00008LB002000IWM   0000736400Y
28875615X4K27GA0000E0000100
28875615X3K27G600007A000100
28875616A8K27G600003LS000100MVV   0000809300Y
28875617A4K27GA0000EFB002000ELN   0000227400Y
28875617AAK27GA000118S001000SPY   0001426000Y
28875621A4K27GA0000EGB002000EIX   0000094900Y
28875621X6K27GA00005F000500
28875621A6K27GA00005FB000500IWM   0000736500Y
28875624ABK27GA0000QCB000100UWM   0000542400Y
28875624ABK27GA0000QDS000100TWM   0000702400Y
28875624XBK27GA0000PY000100
28875622X6K27GA00005F000500
28875622A6K27GA00005FB000500IWM   0000736100Y
28875625X6K27GA00005F000500
28875625A6K27GA00005FB000500IWM   0000736500Y
28875631A5K27GA000052B002000HNZ   0000086100Y
28875632A5K27GA000053B002000HNZ   0000086900Y
28875636X9K27G60000F6003200
28875636A9K27G60000F6S003200QQQQ  0000496400Y
28875636X6K27GA00005F000500
28875636A6K27GA00005FB000500IWM   0000736100Y
28875639A5K27GA000054B002000HOT   0000088900Y
28875640X6K27GA00005F000500
28875640A6K27GA00005FB000500IWM   0000736500Y
28875645A7K27GA00004AB002000MAY   0000092200Y
28875648XAK27GA00010N002000
28875648AAK27GA00010NB002000SPY   0001425400Y
28875648XAK27GA0000EX000500
28875648AAK27GA0000EXB000500SPY   0001425400Y
28875648XAK27GA00010U003000
28875648AAK27GA00010UB003000SPY   0001425400Y
28875648XAK27GA00010V003000
28875648AAK27GA00010VB003000SPY   0001425400Y
28875648XAK27GA0000FD000500
28875648AAK27GA0000FDB000500SPY   0001425400Y
28875648XAK27GA00010Y002000
28875648AAK27GA00010YB002000SPY   0001425400Y
28875648XAK27GA0000E4001000
28875648AAK27GA0000E4B001000SPY   0001425400Y
28875648XAK27GA000113001000
28875648AAK27GA000113B001000SPY   0001425400Y
28875648XAK27GA0000EB001000
28875648AAK27GA0000EBB001000SPY   0001425400Y
28875648XAK27GA000115001000
28875648AAK27GA000115B001000SPY   0001425400Y
28875648XAK27GA0000F7000500
28875648AAK27GA0000F7B000500SPY   0001425400Y
28875649X4K27GA0000E9000200
28875651A9K27G60000PLS001000QID   0000382000Y
28875651A9K27G60000PMB001000QLD   0000889100Y
28875650X6K27GA00002A000500
28875650A6K27GA00002AS000500IWM   0000737100Y
28875651X9K27G60000PL001000
28875652A9K27G60000PNS001000QID   0000381900Y
28875652X9K27G60000PM001000
28875652A9K27G60000POB001000QLD   0000889200Y
28875652A4K27GA0000EHS000200DIA   0001298900Y
28875652X4K27GA0000DY000100
28875653A9K27G60000PPS000100QID   0000382200Y
28875651X6K27GA00008F002000
28875653X3K27G6000079000100
28875652XAK27GA000112002000
28875654X4K27GA0000EH000200
28875654AAK27GA000119S002000SPY   0001426000Y
28875656XBK27GA0000PQ000100
28875656XBK27GA0000PR000100
28875656XBK27GA0000PS000100
28875660X9K27G60000PO001000
28875660A9K27G60000PQB001000QLD   0000889300Y
28875662X9K27G60000F6003200
28875662A9K27G60000F6S003200QQQQ  0000495900Y
28875662A9K27G60000PRB001000QQQQ  0000495400Y
28875662X9K27G60000PR001000
28875662A4K27GA0000EIS000200DIA   0001299200Y
28875664A9K27G60000PSB001000QQQQ  0000495400Y
28875666X9K27G60000PS001000
28875666XAK27GA000119001000
28875668X8K27G600003J000500
28875668X8K27G600003K000100
28875668X8K27G600003L000100
28875670A8K27G600003MB000500MZZ   0000491500Y
28875670A8K27G600003NS000100MVV   0000809500Y
28875672X6K27GA00008B000500
28875672A6K27GA00008BB000500IWM   0000736600Y
28875673A6K27GA00008MB002000IWM   0000736500Y
28875676A8K27G600003OS000500MZZ   0000494000Y
28875676A8K27G600003PB000100MVV   0000806100Y
28875675ABK27GA0000QEB000100UWM   0000542500Y
28875676ABK27GA0000QFS000100TWM   0000702200Y
28875676XBK27GA0000QD000100
28875675X6K27GA00008B000500
28875675A6K27GA00008BB000500IWM   0000736200Y
28875686X4K27GA0000DX000200
28875686A4K27GA0000DXB000200DIA   0001298600Y
28875686X4K27GA000062000200
28875686A4K27GA000062B000200DIA   0001298700Y
28875688A4K27GA0000EJS000100DOG   0000598400Y
28875688A4K27GA0000EKS000100DXD   0000500200Y
28875688A3K27G600007JB000100DDM   0000801100Y
28875710XBK27GA0000Q9001000
28875712ABK27GA0000QGS001000SSO   0000765300Y
28875730X9K27G60000F6003200
28875730A9K27G60000F6S003200QQQQ  0000496400Y
28875741X9K27G60000PB005000
28875744X4K27GA00007C000200
28875744A4K27GA00007CB000200DIA   0001298800Y
28875744A9K27G60000PTB005000QQQQ  0000495800Y
28875746A9K27G60000PUB001000QLD   0000889200Y
28875746A4K27GA0000ELS000100DOG   0000598300Y
28875746A4K27GA0000EMS000100DXD   0000500100Y
28875746A3K27G600007KB000100DDM   0000801200Y
28875751XAK27GA000117001000
28875767AAK27GA00011AS001000SPY   0001426100Y
28875767XAK27GA000119001000
28875769AAK27GA00011BS001000SPY   0001426100Y
28875769X9K27G60000PA005000
28875770X9K27G60000P7005000
28875770A9K27G60000PVB002000QQQQ  0000495800Y
28875770X9K27G60000P6005000
28875770A9K27G60000PWB005000QQQQ  0000495800Y
28875771X9K27G60000EO002000
28875771A9K27G60000EOB002000QQQQ  0000495800Y
28875771X9K27G60000P5002000
28875771A9K27G60000PXS005000QQQQ  0000496300Y
28875772A9K27G60000PYS005000QQQQ  0000496300Y
28875780X9K27G60000ET002000
28875780A9K27G60000ETS002000QQQQ  0000496200Y
28875781XAK27GA0000O8000500
28875781AAK27GA0000O8S000500SPY   0001426100Y
28875784AAK27GA00011CB000500SPY   0001425400Y
28875785XAK27GA00010E000500
28875940XAK27GA0000NZ000500
28875940AAK27GA0000NZS000500SPY   0001426100Y
28875951AAK27GA00011DS001000SDS   0000548900Y
28875951XBK27GA0000QB001000
28875951ABK27GA0000QHB001000SSO   0000764400Y
28875953XBK27GA0000QA001000
28875953ABK27GA0000QIB001000SSO   0000764200Y
28875968AAK27GA00011EB001000SPY   0001425400Y
28875968XAK27GA000101001000
28875968XAK27GA000102001000
28875983AAK27GA00011FS005000SPY   0001426200Y
28875983XAK27GA000105005000
28875986AAK27GA00011GB002500SPY   0001425400Y
28875988AAK27GA00011HS000500SPY   0001426000Y
28876044X6K27GA00008B000500
28876046XBK27GA0000QE000100
28876046XBK27GA0000QF000100
28876048ABK27GA0000QJS000100TWM   0000702400Y
28876049ABK27GA0000QKB000100UWM   0000542500Y
28876049ABK27GA0000QLS000100TWM   0000702200Y
28876050XBK27GA0000QJ000100
28876049A6K27GA00008NB000500IWM   0000736600Y
28876062X6K27GA00008N000500
28876062A6K27GA00008NB000500IWM   0000736200Y
28876066XBK27GA0000QK000100
28876066XBK27GA0000QL000100
28876068ABK27GA0000QMS000100TWM   0000702400Y
28876067X6K27GA00008N000500
28876067A6K27GA00008NB000500IWM   0000736600Y
28876069ABK27GA0000QNB000100UWM   0000542500Y
28876069XBK27GA0000QM000100
28876069ABK27GA0000QOS000100TWM   0000702200Y
28876075X6K27GA00008N000500
28876075A6K27GA00008NB000500IWM   0000736200Y
28876078XBK27GA0000QN000100
28876078XBK27GA0000QO000100
28876080ABK27GA0000QPS000100TWM   0000702400Y
28876079X6K27GA00008N000500
28876079A6K27GA00008NB000500IWM   0000736600Y
28876082ABK27GA0000QQB000100UWM   0000542500Y
28876082ABK27GA0000QRS000100TWM   0000702200Y
28876082XBK27GA0000QP000100
28876085X6K27GA00008N000500
28876085A6K27GA00008NB000500IWM   0000736200Y
28876088XBK27GA0000QQ000100
28876090XBK27GA0000QR000100
28876088A6K27GA00008OB000100IWM   0000736100Y
28876089X6K27GA00008N000500
28876089A6K27GA00008NB000500IWM   0000736600Y
28876090X6K27GA00008O000100
28876091ABK27GA0000QSB000100UWM   0000542500Y
28876091ABK27GA0000QTS000100TWM   0000702200Y
28876095X6K27GA00008N000500
28876095A6K27GA00008NB000500IWM   0000736200Y
28876098XBK27GA0000QS000100
28876098XBK27GA0000QT000100
28876100ABK27GA0000QUS000100TWM   0000702400Y
28876099X6K27GA00008N000500
28876099A6K27GA00008NB000500IWM   0000736600Y
28876102ABK27GA0000QVB000100UWM   0000542500Y
28876102ABK27GA0000QWS000100TWM   0000702200Y
28876102XBK27GA0000QU000100
28876105X6K27GA00008N000500
28876105A6K27GA00008NB000500IWM   0000736200Y
28876108XBK27GA0000QV000100
28876108XBK27GA0000QW000100
28876107X6K27GA00008N000500
28876107A6K27GA00008NB000500IWM   0000736600Y
28876110ABK27GA0000QXB000100UWM   0000542500Y
28876110ABK27GA0000QYS000100TWM   0000702200Y
28876136A8K27G600003QB000100MVV   0000806300Y
28876136A8K27G600003RB000100MVV   0000806200Y
28876136A8K27G600003SS000500MZZ   0000493800Y
28876136A8K27G600003TS000500MZZ   0000493900Y
28876197A9K27G60000PZB002000QQQQ  0000495600Y
28876302X6K27GA00002B000500
28876302A6K27GA00002BS000500IWM   0000737200Y
28876306XBK27GA0000ND000100
28876307XBK27GA0000NE000100
28876307XBK27GA0000NF000100
28876308ABK27GA0000QZB000100TWM   0000700500Y
28876377A9K27G60000Q0B000500QQQQ  0000495200Y
28876388AAK27GA00011IS002500SPY   0001426000Y
28876393A3K27G600007LB002000CELG  0000479900Y
28876393X4K27GA0000DN000100
28876393X3K27G6000074000100
28876393X4K27GA0000EA000200
28876393X4K27GA0000DO000100
28876394X7K27GA000049002000
28876395A4K27GA0000ENB000100DXD   0000499100Y
28876395A3K27G600007MS000100DDM   0000802700Y
28876397X7K27GA000048002000
28876402A4K27GA0000EOS000200DIA   0001299300Y
28876413X9K27G60000F5003200
28876413A9K27G60000F5B003200QQQQ  0000495800Y
28876415X1K27GA000069002000
28876430XCK27GA00003F002000
28876432X1K27GA00005E002000
28876432AAK27GA00011JB002000SPLS  0000038600Y
28876449X2K27G600005K002000
28876457X1K27GA00006B002000
28876463X2K27G6000059002000
28876463X1K27GA00005G002000
28876472X3K27G600007G002000
28876481X2K27G600005B002000
28876481X3K27G600007I002000
28876501X2K27G600005I002000
28876500A6K27GA00008PB010000IOM   0000038200Y
28876503X5K27GA000052002000
28876505X5K27GA000054002000
28876518X4K27GA0000EG002000
28876517X6K27GA000066002000
28876523X5K27GA000053002000
28876530X7K27GA00003Z002000
28876537X6K27GA00008J002000
28876547ABK27GA0000R0B002000UTX   0000145100Y
28876548ABK27GA0000R1B002000UTX   0000144300Y
28876563A1K27GA00006DB002000ABT   0000108900Y
28876564ACK27GA00003GB002000WYE   0000083300Y
28876579A1K27GA00006EB002000ABT   0000108000Y
28876589XAK27GA0000FG000500
28876589AAK27GA0000FGB000500SPY   0001425500Y
28876592A4K27GA0000EPB002000EIX   0000095500Y
28876610A6K27GA00008QB002000JCI   0000064200Y
28876627A2K27G600005NB002000BBT   0000064100Y
28876629A7K27GA00004BB002000MMC   0000041300Y
28876646A3K27G600007NB002000COH   0000067500Y
28876648A7K27GA00004CB002000MRK   0000075300Y
28876664A3K27G600007OB002000CVS   0000082000Y
28876668A8K27G600003UB002000MYL   0000014300Y
28876697A5K27GA000055B002000HOT   0000091100Y
28876703A6K27GA00008RB002000JCP   0000414100Y
28876713A6K27GA00008SB002000KEY   0000211600Y
28877136XAK27GA00011J002000
28877136X3K27G600007L002000
28877136XAK27GA00010K002000
28877139X3K27G600007E002000
28877139X4K27GA0000DP002000
28877140X9K27G60000P0002000
28877138X6K27GA00007T002000
28877141XAK27GA0000XY002000
28877141X4K27GA0000CC002000
28877142X9K27G60000N7002000
28877143X3K27G6000054002000
28877141XCK27GA00001Q002000
28877141XCK27GA00001O002000
28877142X8K27G6000030002000
28877141X1K27GA00005A002000
28877141X1K27GA000059002000
28877142X1K27GA000053002000
28877141X7K27GA000035002000
28877144XBK27GA00006R002000
28877144XBK27GA00006Q002000
28877144XBK27GA00006P002000
28877144XBK27GA00006L002000
28877144XBK27GA00006K002000
28877142XAK27GA0000SM002000
28877145XBK27GA00006J002000
28877145XBK27GA000069002000
28877146XAK27GA0000HV002000
28877146XAK27GA0000HO002000
28877146XAK27GA0000HI002000
28877146XAK27GA0000HC002000
28877147X9K27G60000HF002000
28877147X9K27G60000HE002000
28877151X9K27G60000H5002000
28877151X8K27G600000T002000
28877151X8K27G600000S002000
28877151X8K27G600000R002000
28877153X8K27G600000P002000
28877154X8K27G600000O002000
28877155X8K27G600000N002000
28877154X7K27GA000016002000
28877154X7K27GA000013002000
28877156X7K27GA000011002000
28877157X7K27GA000010002000
28877157X7K27GA00000Z002000
28877157X7K27GA00000Y002000
28877156X6K27GA00002Z002000
28877156X6K27GA00002Y002000
28877156X6K27GA00002X002000
28877158X4K27GA00004A002000
28877163X4K27GA000048002000
28877163X4K27GA000047002000
28877164X3K27G600000S002000
28877164X3K27G600000R002000
28877165X3K27G600000Q002000
28877165X3K27G600000P002000
28877165X3K27G600000N002000
28877166X3K27G600000M002000
28877166X3K27G600000L002000
28877166X3K27G600000K002000
28877166X2K27G600000M002000
28877167X2K27G600000L002000
28877168X1K27GA00001J002000
28877169X1K27GA00001I002000
28877169X1K27GA00001G002000
28877169X1K27GA00001E002000
28877169XCK27GA00001A002000
28877169XCK27GA000019002000
28877171XCK27GA000018002000
28877171XCK27GA000017002000
28877173XBK27GA000014002000
28877173XBK27GA000013002000
28877173XAK27GA0000FN002000
28877174XAK27GA0000FM002000
28877174X9K27G60000FV002000
28877174X9K27G60000FU002000
28877175X8K27G6000007002000
28877174X7K27GA00000K002000
28877173X6K27GA00002H002000
28877174X6K27GA00002G002000
28877176X5K27GA000011002000
28877176X5K27GA000010002000
28877176X4K27GA00003Z002000
28877176X4K27GA00003Y002000
28877177X4K27GA00003W002000
28877177X4K27GA00003V002000
28877178X3K27G600000H002000
28877179X3K27G600000G002000
28877179X3K27G600000F002000
28877180X2K27G600000F002000
28877179X1K27GA000013002000
28877184X1K27GA000012002000
28877186X8K27G6000006002000
28877306XAK27GA0000E6001000
28877306AAK27GA0000E6S001000SPY   0001426100Y
28877383X4K27GA0000EO000200
28877383XAK27GA0000E6001000
28877383AAK27GA0000E6S001000SPY   0001425700Y
28877383XAK27GA0000FG000500
28877383AAK27GA0000FGB000500SPY   0001425100Y
28877384XAK27GA0000O8000500
28877384AAK27GA0000O8S000500SPY   0001425700Y
28877384A4K27GA0000EQS000047DIA   0001299000Y
28877385AAK27GA00011KB005000SPY   0001425200Y
28877386A3K27G600007PS000100DDM   0000802600Y
28877385A4K27GA0000ERB000100DXD   0000499400Y
28877386A4K27GA0000ESB000100DOG   0000597000Y
28877443X2K27G600005L002000
28877443XBK27GA0000R1002000
28877445XCK27GA00003G002000
28877451XBK27GA0000R0002000
28877472X1K27GA00006E002000
28877472X1K27GA00006D002000
28877491X2K27G600005M002000
28877496X3K27G600007O002000
28877498X4K27GA0000EP002000
28877527X3K27G600006G002000
28877544X7K27GA00004C002000
28877547X5K27GA000055002000
28877565XAK27GA00011E001000
28877568A7K27GA00004EB002000LMT   0000225100Y
28877600ACK27GA00003HB002000WYE   0000085300Y
28877614A1K27GA00006FB002000AFL   0000135900Y
28877622A7K27GA00004FB002000LMT   0000224300Y
28877632A1K27GA00006GB002000ARO   0000296500Y
28877655A2K27G600005OB002000BDX   0000766000Y
28877661A1K27GA00006HB002000AFL   0000135100Y
28877685A1K27GA00006IB002000ARO   0000295700Y
28877688A2K27G600005PB002000CAG   0000041800Y
28877713A2K27G600005QB002000BBT   0000064200Y
28877721A4K27GA0000ETB002000EIX   0000097700Y
28877729A2K27G600005RB002000BDX   0000765200Y
28877739A3K27G600007QB002000COH   0000067700Y
28877743A5K27GA000056B002000HNZ   0000089500Y
28877757A3K27G600007RB002000CVS   0000082400Y
28877759A6K27GA00008TB002000JCI   0000066000Y
28877795A5K27GA000057B002000HNZ   0000088700Y
28877817A5K27GA000058B002000HOT   0000091600Y
28877825A6K27GA00008UB002000KFT   0000305100Y
28878117X1K27GA00004W000100
28878117A1K27GA00004WB000100AAPL  0001829900Y
28878128X1K27GA00004W000100
28878128A1K27GA00004WB000100AAPL  0001830000Y
28878136X1K27GA00000V000100
28878136A1K27GA00000VB000100AAPL  0001830000Y
28878289XAK27GA0000O8000500
28878289AAK27GA0000O8S000500SPY   0001426100Y
28878352A2K27G600005SB002000BMY   0000039400Y
28878371X7K27GA00004E002000
28878382ABK27GA0000R2B002000UTX   0000149100Y
28878385XCK27GA00003H002000
28878397X1K27GA00006F002000
28878402A1K27GA00006JB002000ABT   0000112000Y
28878405X2K27G600005N002000
28878412X3K27G600007N002000
28878427A3K27G600007SB002000CVS   0000084400Y
28878436X4K27GA0000AQ002000
28878447X4K27GA0000ET002000
28878452A3K27G600007TB002000DD    0000458000Y
28878455X4K27GA0000AS002000
28878469X5K27GA000056002000
28878476X7K27GA00004F002000
28878517X1K27GA00006H002000
28878535ABK27GA0000R3B002000UTX   0000148300Y
28878539A5K27GA000059B002000HOT   0000093700Y
28878539X3K27G600007R002000
28878546X3K27G600006J002000
28878555X4K27GA0000AO002000
28878564ACK27GA00003IB002000WYE   0000085700Y
28878577A7K27GA00004GB002000MCD   0000589000Y
28878589X5K27GA000057002000
28878595X5K27GA000058002000
28878595A1K27GA00006KB002000ABT   0000111100Y
28878606X6K27GA00008Q002000
28878621A2K27G600005TB002000CAG   0000041600Y
28878631A4K27GA0000EUB002000EIX   0000098300Y
28878632X7K27GA00004B002000
28878659A7K27GA00004HB002000MDY   0001576800Y
28878667A7K27GA00004IB002000MRK   0000077500Y
28879071XBK27GA0000QI001000
28879387XBK27GA0000R3002000
28879387XBK27GA0000R2002000
28879389XCK27GA00003I002000
28879402X1K27GA00006K002000
28879402X1K27GA00006J002000
28879410X1K27GA00004D002000
28879414X1K27GA00004C002000
28879418X2K27G600005J002000
28879419X2K27G600005Q002000
28879424X2K27G600005H002000
28879437X3K27G600007Q002000
28879438X2K27G600005P002000
28879455X4K27GA0000EU002000
28879458A7K27GA00004JB002000LMT   0000231100Y
28879472X4K27GA0000B4002000
28879472X5K27GA00001L002000
28879473X3K27G600007S002000
28879474X7K27GA00004I002000
28879475A7K27GA00004KB002000LMT   0000230300Y
28879492ABK27GA0000R4B001000SSO   0000764200Y
28879492ACK27GA00003JB002000WYE   0000087700Y
28879512A1K27GA00006LB002000AFL   0000138800Y
28879514A1K27GA00006MB002000AFL   0000139600Y
28879534A2K27G600005UB002000BBT   0000066900Y
28879550X4K27GA0000B6002000
28879559A3K27G600007UB002000CVS   0000084700Y
28879564X5K27GA00001Q002000
28879580A3K27G600007VB002000DD    0000457300Y
28879583X5K27GA000059002000
28879589X6K27GA00008T002000
28879591A4K27GA0000EVB002000DUK   0000163300Y
28879596A3K27G600007WB002000COH   0000070500Y
28879602A5K27GA00005AB002000HNZ   0000091200Y
28879611XAK27GA0000FG000500
28879611AAK27GA0000FGB000500SPY   0001425500Y
28879612A5K27GA00005BB002000HOT   0000094300Y
28879616A4K27GA0000EWB002000DUK   0000164100Y
28879621A6K27GA00008VB002000JCI   0000067100Y
28879632A4K27GA0000EXB002000EIX   0000100500Y
28879640A7K27GA00004LB002000MMC   0000043400Y
28879647A4K27GA0000EYB002000EK    0000147600Y
28880003XBK27GA0000R4001000
28880004X4K27GA00007C000200
28880004A4K27GA00007CB000200DIA   0001298500Y
28880008X4K27GA0000EI000200
28880008A4K27GA0000EIS000200DIA   0001298900Y
28880011ABK27GA0000R5B001000SSO   0000764100Y
28880011XAK27GA00011D001000
28880011XBK27GA0000QH001000
28880012X4K27GA0000EI000200
28880012A4K27GA0000EIS000200DIA   0001299200Y
28880012X4K27GA0000EL000100
28880012X4K27GA0000EM000100
28880012X3K27G600007K000100
28880014ABK27GA0000R6B001000SSO   0000764300Y
28880381X2K27G600005S002000
28880382X7K27GA00004K002000
28880387P4K27GA0000EZB000100DRYS  0001074900000A001NJEPR
28880399X7K27GA00004J002000
28880402ABK27GA0000R7B002000UTX   0000152300Y
28880409XCK27GA00003J002000
28880419X1K27GA00006M002000
28880429X2K27G600004L002000
28880428ACK27GA00003KB002000WYE   0000088100Y
28880440X4K27GA0000EX002000
28880447X4K27GA000098002000
28880451A1K27GA00006NB002000ABT   0000114200Y
28880457X1K27GA00006L002000
28880460ABK27GA0000R8B002000UTX   0000153100Y
28880482A1K27GA00006OB002000ABT   0000115000Y
28880489A1K27GA00006PB002000ANF   0000721300Y
28880502X2K27G600004J002000
28880503A2K27G600005VB002000AXP   0000407900Y
28880505A1K27GA00006QB002000ANF   0000722100Y
28880508A2K27G600005WB002000BBT   0000067100Y
28880526X2K27G600005T002000
28880531A2K27G600005XB002000AXP   0000408700Y
28880541A3K27G600007XB002000COH   0000070700Y
28880549X4K27GA00007C000200
28880549A4K27GA00007CB000200DIA   0001298800Y
28880549XAK27GA0000E6001000
28880549AAK27GA0000E6S001000SPY   0001426100Y
28880551A2K27G600005YB002000CAG   0000043700Y
28880552X3K27G600007U002000
28880552A4K27GA0000F0S000100DOG   0000598300Y
28880552AAK27GA00011LB005000SPY   0001425400Y
28880552A3K27G600007YB000100DDM   0000801200Y
28880552A4K27GA0000F1S000100DXD   0000500100Y
28880552XAK27GA00011K005000
28880574A3K27G600007ZB002000CVS   0000086700Y
28880595X8K27G600003M000500
28880595X8K27G600003N000100
28880597A8K27G600003VB000500MZZ   0000491400Y
28880597A8K27G600003WS000100MVV   0000809700Y
28880598A4K27GA0000F2B002000EIX   0000101100Y
28880606A8K27G600003XS000100MVV   0000809600Y
28880611X4K27GA0000AY002000
28880619X4K27GA000099002000
28880620A4K27GA0000F3B002000FDX   0000878900Y
28880629A4K27GA0000F4B002000FDX   0000878100Y
28880636X4K27GA00007C000200
28880636A4K27GA00007CB000200DIA   0001298500Y
28880638X4K27GA0000F0000100
28880638X4K27GA0000F1000100
28880639X3K27G600007Y000100
28880639X5K27GA00004I002000
28880642X5K27GA00005A002000
28880642A5K27GA00005CB002000FRE   0000253100Y
28880644A5K27GA00005DB002000FRE   0000253900Y
28880651X5K27GA00005B002000
28880673X8K27G600003U002000
28881388XBK27GA0000HW002000
28881388XBK27GA0000R8002000
28881392X1K27GA00006O002000
28881395A7K27GA00004MB002000LMT   0000236300Y
28881413X2K27G600005U002000
28881420XBK27GA0000R7002000
28881428X2K27G600004E002000
28881440XCK27GA00003K002000
28881450X3K27G600007W002000
28881484X3K27G600007Z002000
28881505X4K27GA00007C000200
28881505A4K27GA00007CB000200DIA   0001298800Y
28881507A4K27GA0000F5S000100DOG   0000598300Y
28881507AAK27GA00011MB005000SPY   0001425500Y
28881507A4K27GA0000F6S000100DXD   0000500100Y
28881508A3K27G6000080B000100DDM   0000801200Y
28881508AAK27GA00011NB000500SPY   0001425500Y
28881508XAK27GA00011L005000
28881508XAK27GA00011C000500
28881508XAK27GA0000F5000500
28881508AAK27GA0000F5B000500SPY   0001425500Y
28881510XBK27GA0000R6001000
28881509AAK27GA00011OS001000SDS   0000548900Y
28881510ABK27GA0000R9B001000SSO   0000764400Y
28881511XBK27GA0000R5001000
28881511ABK27GA0000RAB001000SSO   0000764200Y
28881511XAK27GA0000F5000500
28881511AAK27GA0000F5B000500SPY   0001425200Y
28881511XAK27GA0000NZ000500
28881511AAK27GA0000NZS000500SPY   0001425700Y
28881511XAK27GA0000E8001000
28881511AAK27GA0000E8B001000SPY   0001425500Y
28881511AAK27GA00011PB002000SPY   0001425500Y
28881513X4K27GA0000EQ000047
28881517A4K27GA0000F7S000200DIA   0001299300Y
28881521X1K27GA00006N002000
28881520X6K27GA000084002000
28881528XAK27GA0000NZ000500
28881528AAK27GA0000NZS000500SPY   0001426100Y
28881528XAK27GA0000ZO001000
28881527X6K27GA00006J002000
28881529AAK27GA00011QB001000SPY   0001425500Y
28881540X6K27GA00007U000500
28881540A6K27GA00007UB000500IWM   0000736700Y
28881541A6K27GA00008WB002000IWM   0000736600Y
28881541X6K27GA00008H002000
28881543ABK27GA0000RBB000100UWM   0000542700Y
28881543ABK27GA0000RCS000100TWM   0000702000Y
28881543XBK27GA0000QY000100
28881544X6K27GA00007U000500
28881544A6K27GA00007UB000500IWM   0000736300Y
28881546AAK27GA00011RB001000SPY   0001425400Y
28881554X6K27GA00007U000500
28881554A6K27GA00007UB000500IWM   0000736700Y
28881556XBK27GA0000RB000100
28881556XBK27GA0000RC000100
28881558ABK27GA0000RDB000100UWM   0000542700Y
28881558ABK27GA0000RES000100TWM   0000702000Y
28881564X6K27GA00007U000500
28881564A6K27GA00007UB000500IWM   0000736300Y
28881568X4K27GA0000F2002000
28881574X6K27GA00007U000500
28881574A6K27GA00007UB000500IWM   0000736700Y
28881576XBK27GA0000RD000100
28881576XBK27GA0000RE000100
28881578ABK27GA0000RFB000100UWM   0000542700Y
28881578ABK27GA0000RGS000100TWM   0000702000Y
28881584X6K27GA00007U000500
28881584A6K27GA00007UB000500IWM   0000736300Y
28881594A2K27G600005ZB002000BMY   0000041200Y
28881594X6K27GA00008V002000
28881594X6K27GA00007U000500
28881594A6K27GA00007UB000500IWM   0000736700Y
28881596XBK27GA0000RF000100
28881596XBK27GA0000RG000100
28881598ABK27GA0000RHB000100UWM   0000542700Y
28881596A6K27GA00008XB000100IWM   0000736200Y
28881597X6K27GA00008X000100
28881598ABK27GA0000RIS000100TWM   0000702000Y
28881598X6K27GA00007U000500
28881598A6K27GA00007UB000500IWM   0000736300Y
28881601XBK27GA0000RH000100
28881601XBK27GA0000RI000100
28881602A6K27GA00008YB000100IWM   0000736200Y
28881603ABK27GA0000RJS000100TWM   0000702200Y
28881602X6K27GA00008Y000100
28881602X6K27GA00007U000500
28881602A6K27GA00007UB000500IWM   0000736700Y
28881605ABK27GA0000RKB000100UWM   0000542700Y
28881605XBK27GA0000RJ000100
28881605ABK27GA0000RLS000100TWM   0000702000Y
28881606X7K27GA00002A002000
28881604X6K27GA00007U000500
28881604A6K27GA00007UB000500IWM   0000736300Y
28881607X7K27GA00002O002000
28881610X7K27GA00004L002000
28881610XAK27GA0000E8001000
28881610AAK27GA0000E8B001000SPY   0001425600Y
28881610XAK27GA00011P002000
28881610AAK27GA00011PB002000SPY   0001425600Y
28881610XAK27GA00011Q001000
28881610AAK27GA00011QB001000SPY   0001425600Y
28881616XBK27GA0000RK000100
28881616XBK27GA0000RL000100
28881618ABK27GA0000RMS000100TWM   0000702200Y
28881621A7K27GA00004NB002000LMT   0000237100Y
28881628X8K27G600003D000100
28881628A8K27G600003YB000100MVV   0000806400Y
28881636A1K27GA00006RB002000AFL   0000142500Y
28881642ACK27GA00003LB002000WYE   0000090100Y
28881647A2K27G6000060B002000AZN   0000418900Y
28881654A2K27G6000061B002000CAG   0000043600Y
28881670A1K27GA00006SB002000AFL   0000143300Y
28881670A3K27G6000081B002000CVS   0000087100Y
28881673A2K27G6000062B002000AZN   0000419700Y
28881691A4K27GA0000F8B002000EK    0000146900Y
28881694A4K27GA0000F9B002000EIX   0000103300Y
28881707A4K27GA0000FAB002000FCX   0001224600Y
28881709A4K27GA0000FBB002000FCX   0001225400Y
28881713A5K27GA00005EB002000HMY   0000087500Y
28881719A5K27GA00005FB002000HNZ   0000093800Y
28881726A5K27GA00005GB002000HOT   0000096900Y
28881730A5K27GA00005HB002000HNZ   0000094600Y
28882352X7K27GA00004M002000
28882357X7K27GA00004N002000
28882387ABK27GA0000RNB002000TGT   0000519100Y
28882386XCK27GA00003L002000
28882403ABK27GA0000ROB002000UTX   0000156300Y
28882405X1K27GA00006S002000
28882408ABK27GA0000RPB002000UTX   0000157100Y
28882421ACK27GA00003MB002000WYE   0000090500Y
28882432A1K27GA00006TB002000ABT   0000118100Y
28882438X1K27GA00006R002000
28882449A1K27GA00006UB002000ABT   0000117200Y
28882461A2K27G6000063B002000BBT   0000069800Y
28882470X2K27G600005Y002000
28882481X2K27G600004N002000
28882487X2K27G600005W002000
28882492X2K27G600004K002000
28882499X3K27G600007X002000
28882505X3K27G6000081002000
28882520A2K27G6000064B002000BK    0000427400Y
28882519X3K27G6000059002000
28882545X3K27G6000058002000
28882550X5K27GA00005F002000
28882553X5K27GA00005G002000
28882560X4K27GA0000F9002000
28882561X7K27GA00002G002000
28882566A4K27GA0000FCB002000EIX   0000103900Y
28882586A3K27G6000082B002000COH   0000073500Y
28882591X5K27GA00004P002000
28882600X5K27GA00005H002000
28882599A6K27GA00008ZB002000JCI   0000069900Y
28882615A7K27GA00004OB002000KMB   0000611900Y
28882622A7K27GA00004PB002000LLY   0000464500Y
28882625A3K27G6000083B002000CVS   0000089100Y
28882652A5K27GA00005IB002000HOT   0000099100Y
28882662A6K27GA000090B002000JCI   0000070700Y
28883208XAK27GA00011G002500
28883352A7K27GA00004QB002000LMT   0000242300Y
28883356X2K27G600005Z002000
28883392A7K27GA00004RB002000LMT   0000243100Y
28883399XBK27GA0000RO002000
28883409XBK27GA0000I4002000
28883410XCK27GA00003M002000
28883430X9K27G60000PZ002000
28883432XBK27GA0000RP002000
28883432X1K27GA00006U002000
28883446A1K27GA00006VB002000AFL   0000146200Y
28883452ACK27GA00003NB002000WYE   0000092600Y
28883469X1K27GA00006T002000
28883479X2K27G600003L002000
28883479X9K27G60000PX005000
28883479X9K27G60000F5003200
28883479A9K27G60000F5B003200QQQQ  0000495300Y
28883479X9K27G60000PY005000
28883480A9K27G60000Q1S005000QQQQ  0000495900Y
28883480A9K27G60000Q2S005000QQQQ  0000495900Y
28883486A2K27G6000065B002000BBT   0000069900Y
28883489A1K27GA00006WB002000AFL   0000147000Y
28883504X2K27G600003K002000
28883512X2K27G600005O002000
28883522X2K27G600005R002000
28883526X9K27G60000ET002000
28883526A9K27G60000ETS002000QQQQ  0000495900Y
28883526A9K27G60000Q3S002000QQQQ  0000496000Y
28883529X2K27G600004G002000
28883529A2K27G6000066B002000BK    0000426600Y
28883541X2K27G600004F002000
28883544X2K27G6000061002000
28883553A2K27G6000067B002000CAG   0000045700Y
28883557A3K27G6000084B002000COH   0000073700Y
28883572A3K27G6000085B002000CVS   0000089500Y
28883582A3K27G6000086B002000DHR   0000760300Y
28883593X4K27GA0000FC002000
28883599A2K27G6000068B002000CAT   0000818000Y
28883615X3K27G6000083002000
28883619A5K27GA00005JB002000HNZ   0000096300Y
28883635A5K27GA00005KB002000HOT   0000099600Y
28883655A3K27G6000087B002000DHR   0000761100Y
28883666A4K27GA0000FDB002000EIX   0000106100Y
28883675A5K27GA00005LB002000HMY   0000088500Y
28883682X5K27GA00005I002000
28883711AAK27GA00011SB002500SPY   0001425400Y
28883841X6K27GA00008W002000
28883857A6K27GA000091S002000IWM   0000737100Y
28884044X8K27G600003S000500
28884044X8K27G600003Q000100
28884044X8K27G600003Y000100
28884046A8K27G600003ZS000500MZZ   0000493800Y
28884046A8K27G6000040B000100MVV   0000806300Y
28884112XAK27GA00011S002500
28884135X6K27GA000091002000
28884152A6K27GA000092S002000IWM   0000737100Y
28884162AAK27GA00011TB002500SPY   0001425400Y
28884172X6K27GA000092002000
28884187A6K27GA000093S002000IWM   0000737100Y
28884189X1K27GA00000V000100
28884189A1K27GA00000VB000100AAPL  0001828700Y
28884196X1K27GA00004W000100
28884196A1K27GA00004WB000100AAPL  0001828700Y
28884197X6K27GA000093002000
28884211A6K27GA000094S002000IWM   0000737100Y
28884219X6K27GA000094002000
28884235X9K27G60000Q3002000
28884241A6K27GA000095S002000IWM   0000737100Y
28884269X9K27G60000Q1005000
28884269X9K27G60000Q2005000
28884269X9K27G60000F5003200
28884269A9K27G60000F5B003200QQQQ  0000495800Y
28884270X9K27G60000ET002000
28884270A9K27G60000ETS002000QQQQ  0000496200Y
28884271A9K27G60000Q4S005000QQQQ  0000496300Y
28884271A9K27G60000Q5S005000QQQQ  0000496300Y
28884272A9K27G60000Q6B002000QQQQ  0000495600Y
28884275X1K27GA00004W000100
28884275A1K27GA00004WB000100AAPL  0001830000Y
28884276X6K27GA000095002000
28884292A6K27GA000096B002000IWM   0000736600Y
28884377X4K27GA000041002000
28884380X4K27GA000044002000
28884394X6K27GA000070002000
28884398X7K27GA00004Q002000
28884408A1K27GA00006XB002000AMAT  0000183300Y
28884442X1K27GA00006V002000
28884442X7K27GA00004R002000
28884445X2K27G600004U002000
28884451X3K27G6000085002000
28884450XCK27GA00003N002000
28884457A8K27G6000041B000100MVV   0000806400Y
28884469X4K27GA0000AW002000
28884484X1K27GA00006W002000
28884498A1K27GA00006YS002000AMAT  0000204800Y
28884499X2K27G6000063002000
28884499X5K27GA00005J002000
28884514X5K27GA00005K002000
28884526A2K27G6000069B002000BMY   0000043100Y
28884525X6K27GA00008Z002000
28884532ABK27GA0000RQB002000UTX   0000160300Y
28884546A1K27GA00006ZB002000AMGN  0000413600Y
28884553ACK27GA00003OB002000WYE   0000093000Y
28884572A1K27GA000070B002000ABT   0000120300Y
28884585A2K27G600006AB002000BA    0000853200Y
28884588A2K27G600006BB002000BDX   0000766600Y
28884600A2K27G600006CB002000BNI   0001059900Y
28884608A1K27GA000071S002000AMGN  0000489900Y
28884609A2K27G600006DB002000CAG   0000045500Y
28884609XAK27GA00011T002500
28884612ABK27GA0000RRB002000TGT   0000520000Y
28884622X3K27G6000082002000
28884654A1K27GA000072B002000AMZN  0000800000Y
28884673X4K27GA0000AV002000
28884673A4K27GA0000FEB002000EIX   0000106700Y
28884674ABK27GA0000RSB002000UTX   0000161100Y
28884693X4K27GA0000FD002000
28884726X6K27GA000090002000
28884728A1K27GA000073S002000AMZN  0000834800Y
28884732A7K27GA00004SB002000KMX   0000186900Y
28884744A7K27GA00004TB002000MMC   0000046800Y
28884777A2K27G600006EB002000BRCM  0000261200Y
28884780A1K27GA000074B002000ABT   0000121100Y
28884814A2K27G600006FB002000BA    0000854000Y
28884818A2K27G600006GS002000BRCM  0000290800Y
28884837A2K27G600006HB002000BDX   0000767400Y
28884848A3K27G6000088B002000CELG  0000482800Y
28884848X6K27GA00001N000100
28884848A6K27GA000097S000100IYF   0000858600Y
28884848A6K27GA000098S000100IYF   0000858500Y
28884850ABK27GA0000RTS000100UYG   0000321900Y
28884848X6K27GA00001M000100
28884859A2K27G600006IB002000BNI   0001060700Y
28884866A3K27G6000089S002000CELG  0000613300Y
28884878A3K27G600008AB002000CVS   0000091400Y
28884923XAK27GA0000E8001000
28884923AAK27GA0000E8B001000SPY   0001425200Y
28884924X4K27GA0000F7000200
28884924XAK27GA0000NZ000500
28884924AAK27GA0000NZS000500SPY   0001425700Y
28884924XAK27GA00011Q001000
28884924XAK27GA00011N000500
28884924XAK27GA00011P002000
28884924AAK27GA00011UB000500SPY   0001425400Y
28884925AAK27GA00011VB002500SPY   0001425400Y
28884926XAK27GA00011M005000
28884926AAK27GA00011WB001000SPY   0001425200Y
28884926AAK27GA00011XB005000SPY   0001425200Y
28884929A4K27GA0000FFS000200DIA   0001299000Y
28884931XAK27GA0000F7000500
28884931AAK27GA0000F7B000500SPY   0001425100Y
28884942XAK27GA00011R001000
28884942X9K27G60000Q5005000
28884942X9K27G60000F5003200
28884942A9K27G60000F5B003200QQQQ  0000495300Y
28884942X9K27G60000Q4005000
28884941X6K27GA000096002000
28884942X4K27GA00007C000200
28884942A4K27GA00007CB000200DIA   0001298500Y
28884943A9K27G60000Q7S005000QQQQ  0000495900Y
28884943A9K27G60000Q8S005000QQQQ  0000495900Y
28884943X9K27G60000Q6002000
28884944XAK27GA0000FG000500
28884944AAK27GA0000FGB000500SPY   0001425100Y
28884944X4K27GA0000F5000100
28884944X4K27GA0000F6000100
28884944X3K27G6000080000100
28884952A6K27GA000099S002000IWM   0000737100Y
28884989X8K27G600003V000500
28884989X8K27G600003W000100
28884989X8K27G600003X000100
28884990A8K27G6000042B000500MZZ   0000491400Y
28884991A8K27G6000043S000100MVV   0000809700Y
28884998X6K27GA00002B000500
28884998A6K27GA00002BS000500IWM   0000736800Y
28885001ABK27GA0000RUS000100UWM   0000543500Y
28885002ABK27GA0000RVB000100TWM   0000700900Y
28885002ABK27GA0000RWB000100TWM   0000700800Y
28885010A8K27G6000044S000100MVV   0000809600Y
28885035X8K27G6000042000500
28885035X8K27G6000044000100
28885035X8K27G6000043000100
28885037A8K27G6000045B000500MZZ   0000491400Y
28885037A8K27G6000046S000100MVV   0000809700Y
28885072A4K27GA0000FGB000100DXD   0000499500Y
28885072A3K27G600008BS000100DDM   0000802500Y
28885127A8K27G6000047B000500MZZ   0000491500Y
28885127A8K27G6000048S000100MVV   0000809500Y
28885156X8K27G600003Z000500
28885156X8K27G6000041000100
28885156X8K27G6000040000100
28885158A8K27G6000049S000500MZZ   0000493800Y
28885158A8K27G600004AB000100MVV   0000806300Y
28885397XBK27GA0000RS002000
28885405XBK27GA0000RQ002000
28885405A3K27G600008CB002000CHKP  0000232100Y
28885404X1K27GA000074002000
28885448XCK27GA00003O002000
28885451X2K27G600005X002000
28885450X1K27GA000070002000
28885451X2K27G6000067002000
28885453X2K27G600005V002000
28885453X3K27G600008A002000
28885453X2K27G6000065002000
28885453A3K27G600008DS002000CHKP  0000263100Y
28885451X6K27GA00006L002000
28885453A4K27GA0000FHB002000DNA   0000687200Y
28885453X3K27G6000084002000
28885454X4K27GA0000FE002000
28885473X7K27GA00004H002000
28885473X9K27G60000Q7005000
28885474X9K27G60000F5003200
28885474A9K27G60000F5B003200QQQQ  0000495800Y
28885474X9K27G60000Q8005000
28885475A9K27G60000Q9B002000QQQQ  0000495600Y
28885475A9K27G60000QAS005000QQQQ  0000496300Y
28885475A9K27G60000QBS005000QQQQ  0000496300Y
28885495X7K27GA00003Q002000
28885501A4K27GA0000FIB002000DNA   0000686400Y
28885502X9K27G60000F5003200
28885502A9K27G60000F5B003200QQQQ  0000495300Y
28885503X9K27G60000Q9002000
28885505A7K27GA00004UB002000LMT   0000249100Y
28885511X9K27G60000QA005000
28885511X9K27G60000QB005000
28885511A3K27G600008EB002000CREE  0000238500Y
28885512A9K27G60000QCS005000QQQQ  0000495900Y
28885512A9K27G60000QDS005000QQQQ  0000495900Y
28885511A6K27GA00009AB002000JNJ   0000641300Y
28885517X9K27G60000QC005000
28885517X9K27G60000QD005000
28885518X9K27G60000F5003200
28885518A9K27G60000F5B003200QQQQ  0000495800Y
28885519A9K27G60000QES005000QQQQ  0000496300Y
28885519A9K27G60000QFS005000QQQQ  0000496300Y
28885526A7K27GA00004VB002000LMT   0000248300Y
28885531X9K27G60000QE005000
28885531X9K27G60000QF005000
28885531X9K27G60000F5003200
28885531A9K27G60000F5B003200QQQQ  0000495300Y
28885531A9K27G60000QGS005000QQQQ  0000495900Y
28885531A9K27G60000QHS005000QQQQ  0000495900Y
28885539X9K27G60000ET002000
28885539A9K27G60000ETS002000QQQQ  0000495900Y
28885542A3K27G600008FB002000CYMI  0000285200Y
28885544ACK27GA00003PB002000WYE   0000095000Y
28885580A1K27GA000075B002000AFL   0000150700Y
28885585A2K27G600006JB002000BBT   0000072600Y
28885591A1K27GA000076B002000AFL   0000149900Y
28885598A3K27G600008GS002000CYMI  0000320900Y
28885601A2K27G600006KB002000CAT   0000817300Y
28885617A3K27G600008HB002000COH   0000076500Y
28885630A3K27G600008IB002000CVS   0000091800Y
28885633A4K27GA0000FJB002000DISH  0000320300Y
28885659A4K27GA0000FKB002000DOW   0000399400Y
28885660A4K27GA0000FLB002000DOW   0000398600Y
28885661A4K27GA0000FMS002000DISH  0000359800Y
28885704A4K27GA0000FNB002000DRIV  0000359900Y
28885704A4K27GA0000FOB002000EIX   0000108900Y
28885713A5K27GA00005MB002000HNZ   0000098900Y
28885735A4K27GA0000FPS002000DRIV  0000394000Y
28885736A5K27GA00005NB002000HOT   0000102300Y
28885774A6K27GA00009BB002000JCI   0000072800Y
28885779A4K27GA0000FQB002000EBAY  0000293600Y
28886397X2K27G6000069002000
28886406A4K27GA0000FRS002000EBAY  0000330100Y
28886407X6K27GA000073002000
28886411X2K27G600004I002000
28886420X7K27GA00004U002000
28886434XCK27GA00003P002000
28886441A4K27GA0000FSB002000ENZN  0000069500Y
28886452X7K27GA00004V002000
28886455X1K27GA000075002000
28886473X4K27GA000059002000
28886492X4K27GA0000FO002000
28886496X1K27GA000076002000
28886506ABK27GA0000RXB002000UTX   0000165100Y
28886519A4K27GA0000FTS002000ENZN  0000105500Y
28886527X2K27G600006D002000
28886543X3K27G600008I002000
28886545A1K27GA000077B002000ABT   0000124200Y
28886554A5K27GA00005OB002000GILD  0000515700Y
28886558X4K27GA00005C002000
28886572X5K27GA00005M002000
28886591A5K27GA00005PS002000GILD  0000553400Y
28886592X5K27GA00005N002000
28886597X7K27GA00004T002000
28886610A2K27G600006LB002000AXP   0000410100Y
28886618ABK27GA0000RYB002000UTX   0000164300Y
28886622A5K27GA00005QB002000IACI  0000220300Y
28886639ACK27GA00003QB002000WYE   0000095400Y
28886642A2K27G600006MB002000CAG   0000047600Y
28886661A1K27GA000078B002000ABT   0000123300Y
28886662A5K27GA00005RS002000IACI  0000265400Y
28886684A3K27G600008JB002000CVS   0000093800Y
28886699A6K27GA00009CB002000IMCL  0000345400Y
28886707A2K27G600006NB002000AXP   0000409300Y
28886728A6K27GA00009DS002000IMCL  0000520400Y
28886731A5K27GA00005SB002000HNZ   0000101000Y
28886732A2K27G600006OB002000BBT   0000072800Y
28886756A6K27GA00009EB002000INTC  0000237800Y
28886758A5K27GA00005TB002000HOT   0000104400Y
28886767A3K27G600008KB002000COH   0000076700Y
28886789A6K27GA00009FB002000JCI   0000074500Y
28886793A4K27GA0000FUB002000EIX   0000109500Y
28886841A7K27GA00004WB002000MDY   0001578100Y
28886930A6K27GA00009GB002000IWM   0000736500Y
28887152A6K27GA00009HS002000IWM   0000737400Y
28887157X9K27G60000PW005000
28887158X9K27G60000PV002000
28887158A9K27G60000QIS002000QQQQ  0000496000Y
28887159A9K27G60000QJB005000QQQQ  0000495400Y
28887160X9K27G60000EO002000
28887160A9K27G60000EOB002000QQQQ  0000495500Y
28887170X9K27G60000PU001000
28887172A9K27G60000QKB001000QQQQ  0000495400Y
28887176X9K27G60000QK001000
28887394A6K27GA00009IS002000INTC  0000258900Y
28887400XBK27GA0000RX002000
28887405A6K27GA00009JB002000IWM   0000736400Y
28887411X5K27GA00004V002000
28887412XBK27GA0000RY002000
28887430X1K27GA000077002000
28887429XCK27GA00003Q002000
28887443X1K27GA000078002000
28887446A2K27G600006PB002000BRL   0000373700Y
28887451A6K27GA00009KB002000INTU  0000258200Y
28887455X2K27G600006J002000
28887471X3K27G600008H002000
28887472XAK27GA0000E6001000
28887472AAK27GA0000E6S001000SPY   0001425700Y
28887472XAK27GA00010Y002000
28887472X4K27GA0000EI000200
28887472XAK27GA0000O8000500
28887472AAK27GA0000O8S000500SPY   0001425700Y
28887473XBK27GA0000RA001000
28887474AAK27GA00011YS002500SPY   0001425900Y
28887474AAK27GA00011ZS005000SPY   0001426000Y
28887474AAK27GA000120S000500SPY   0001425900Y
28887475XAK27GA00011H000500
28887475XAK27GA00011F005000
28887475XAK27GA00011I002500
28887481XAK27GA00011O001000
28887481XBK27GA0000R9001000
28887481ABK27GA0000RZB001000SSO   0000764100Y
28887481A4K27GA0000FVS000200DIA   0001298900Y
28887483ABK27GA0000S0B001000SSO   0000764300Y
28887486X3K27G600008J002000
28887486XAK27GA0000ZM000500
28887486AAK27GA0000ZMS000500SPY   0001425700Y
28887487AAK27GA000121B001000SDS   0000547600Y
28887488AAK27GA000122S001000SPY   0001426000Y
28887500X4K27GA0000D8002000
28887500A6K27GA00009LS002000INTU  0000291500Y
28887510X8K27G6000049000500
28887510X8K27G600004A000100
28887512X5K27GA00005S002000
28887523A7K27GA00004XB002000LMT   0000254300Y
28887525X5K27GA00005T002000
28887538A6K27GA00009MS002000IVGN  0001029800Y
28887545A2K27G600006QB002000BMY   0000044900Y
28887580A7K27GA00004YB002000MRVL  0000135300Y
28887581A6K27GA00009NB002000JNJ   0000642200Y
28887588A6K27GA00009OB002000IWM   0000736300Y
28887595X9K27G60000PT005000
28887595XAK27GA0000ZM000500
28887595AAK27GA0000ZMS000500SPY   0001425600Y
28887597X9K27G60000PN001000
28887597A9K27G60000QLB001000QQQQ  0000495200Y
28887597X9K27G60000PQ001000
28887599A9K27G60000QMB001000QQQQ  0000495400Y
28887600A9K27G60000QNB005000QQQQ  0000495400Y
28887601A7K27GA00004ZB002000LMT   0000255100Y
28887606X9K27G60000PP000100
28887606X9K27G60000QM001000
28887623A7K27GA000050S002000MRVL  0000158000Y
28887642ACK27GA00003RB002000WYE   0000097400Y
28887650A1K27GA000079B002000AFL   0000153600Y
28887656A8K27G600004BB002000MSFT  0000283100Y
28887673X4K27GA0000FU002000
28887691A1K27GA00007AB002000AFL   0000154400Y
28887704X4K27GA0000D7002000
28887705A8K27G600004CS002000MSFT  0000306000Y
28887724A4K27GA0000FWB002000DOX   0000303500Y
28887739X6K27GA00009B002000
28887739X6K27GA00007D002000
28887741A2K27G600006RB002000CAG   0000047500Y
28887745A8K27G600004DB002000NFLX  0000307700Y
28887761A4K27GA0000FXB002000EIX   0000111700Y
28887764A3K27G600008LB002000CVS   0000094200Y
28887787A6K27GA00009PB002000JWN   0000351900Y
28887796A4K27GA0000FYB002000DOX   0000302700Y
28887814A6K27GA00009QS002000IWM   0000737300Y
28888035A6K27GA00009RS002000IWM   0000737500Y
28888256A6K27GA00009SB002000IWM   0000736200Y
28888373X7K27GA00003D002000
28888406X7K27GA00003E002000
28888408A9K27G60000QOB002000QCOM  0000457500Y
28888409X7K27GA00004X002000
28888410X7K27GA00004Z002000
28888428X1K27GA000079002000
28888427XCK27GA00003R002000
28888436X2K27G600006O002000
28888442X1K27GA00007A002000
28888446X3K27G600008K002000
28888455X3K27G600008L002000
28888455X2K27G600006M002000
28888460A9K27G60000QPS002000QCOM  0000487300Y
28888468X5K27GA00004N002000
28888470X4K27GA0000FX002000
28888478X5K27GA00004O002000
28888478A5K27GA00005UB002000GM    0000176800Y
28888477A6K27GA00009TS002000IWM   0000737200Y
28888490ABK27GA0000S1B002000UTX   0000168300Y
28888498A9K27G60000QQB002000QLGC  0000144200Y
28888508X6K27GA00009F002000
28888512X9K27G60000F6003200
28888512A9K27G60000F6S003200QQQQ  0000495900Y
28888528ABK27GA0000S2B002000UTX   0000169100Y
28888531ACK27GA00003SB002000WYE   0000097800Y
28888543A9K27G60000QRS002000QLGC  0000179200Y
28888552A1K27GA00007BB002000ABT   0000126400Y
28888565A1K27GA00007CB002000ABT   0000127300Y
28888592AAK27GA000123B002000SHLD  0000751900Y
28888600A2K27G600006SB002000BBT   0000075500Y
28888628AAK27GA000124B002000SINA  0000509800Y
28888639A3K27G600008MB002000COH   0000079500Y
28888640A4K27GA0000FZB002000EIX   0000112300Y
28888659A4K27GA0000G0B002000ESI   0000618000Y
28888665AAK27GA000125S002000SINA  0000557500Y
28888666A5K27GA00005VB002000HNZ   0000102700Y
28888675A3K27G600008NB002000CVS   0000096200Y
28888696AAK27GA000126B002000SMTC  0000162200Y
28888701A6K27GA00009UB002000IWM   0000736100Y
28888702A4K27GA0000G1B002000ESI   0000618800Y
28888710A5K27GA00005WB002000HOT   0000106300Y
28888732AAK27GA000127S002000SMTC  0000197100Y
28888738A5K27GA00005XB002000HNZ   0000103500Y
28888741A6K27GA00009VB002000JCI   0000075600Y
28888752A6K27GA00009WB002000KEY   0000211400Y
28888765A5K27GA00005YB002000HOT   0000107100Y
28888846X6K27GA00008N000500
28888846A6K27GA00008NB000500IWM   0000736200Y
28888854X6K27GA00008N000500
28888854A6K27GA00008NB000500IWM   0000736600Y
28888856XBK27GA0000QX000100
28888856XBK27GA0000RM000100
28888858ABK27GA0000S3B000100UWM   0000542500Y
28888858ABK27GA0000S4S000100TWM   0000702200Y
28888858X6K27GA00008N000500
28888858A6K27GA00008NB000500IWM   0000736200Y
28888859A6K27GA00009XS002000IWM   0000737600Y
28888861XBK27GA0000S3000100
28888861XBK27GA0000S4000100
28888861A6K27GA00009YB000100IWM   0000736100Y
28888863ABK27GA0000S5S000100TWM   0000702400Y
28888861X6K27GA00009Y000100
28888862X6K27GA00008N000500
28888862A6K27GA00008NB000500IWM   0000736600Y
28888864ABK27GA0000S6B000100UWM   0000542500Y
28888865ABK27GA0000S7S000100TWM   0000702200Y
28888865XBK27GA0000S5000100
28888864X6K27GA00008N000500
28888864A6K27GA00008NB000500IWM   0000736200Y
28888874X6K27GA00008N000500
28888874A6K27GA00008NB000500IWM   0000736600Y
28888876XBK27GA0000S6000100
28888876XBK27GA0000S7000100
28888878ABK27GA0000S8B000100UWM   0000542500Y
28888878ABK27GA0000S9S000100TWM   0000702200Y
28888884X6K27GA00008N000500
28888884A6K27GA00008NB000500IWM   0000736200Y
28888894X6K27GA00008N000500
28888894A6K27GA00008NB000500IWM   0000736600Y
28888896XBK27GA0000S8000100
28888896XBK27GA0000S9000100
28888898ABK27GA0000SAS000100TWM   0000702200Y
28888898ABK27GA0000SBB000100UWM   0000542500Y
28888904X6K27GA00008N000500
28888904A6K27GA00008NB000500IWM   0000736200Y
28888914X6K27GA00008N000500
28888914A6K27GA00008NB000500IWM   0000736600Y
28888916XBK27GA0000SB000100
28888916XBK27GA0000SA000100
28888916A6K27GA00009ZB000100IWM   0000736100Y
28888917ABK27GA0000SCB000100UWM   0000542500Y
28888916X6K27GA00009Z000100
28888918ABK27GA0000SDS000100TWM   0000702200Y
28888924X6K27GA00008N000500
28888924A6K27GA00008NB000500IWM   0000736200Y
28888934X6K27GA00008N000500
28888934A6K27GA00008NB000500IWM   0000736600Y
28888936XBK27GA0000SC000100
28888936XBK27GA0000SD000100
28888938ABK27GA0000SES000100TWM   0000702200Y
28888938ABK27GA0000SFB000100UWM   0000542500Y
28888944X6K27GA00008N000500
28888944A6K27GA00008NB000500IWM   0000736200Y
28888954X6K27GA00008N000500
28888954A6K27GA00008NB000500IWM   0000736600Y
28888956XBK27GA0000SF000100
28888956XBK27GA0000SE000100
28888958ABK27GA0000SGB000100UWM   0000542500Y
28888958ABK27GA0000SHS000100TWM   0000702200Y
28888964X6K27GA00008N000500
28888964A6K27GA00008NB000500IWM   0000736200Y
28888974X6K27GA00008N000500
28888974A6K27GA00008NB000500IWM   0000736600Y
28888976XBK27GA0000SG000100
28888976XBK27GA0000SH000100
28888978ABK27GA0000SIS000100TWM   0000702400Y
28888984X6K27GA00008N000500
28888984A6K27GA00008NB000500IWM   0000736200Y
28888986ABK27GA0000SJB000100UWM   0000542500Y
28888986XBK27GA0000SI000100
28888986ABK27GA0000SKS000100TWM   0000702200Y
28888994X6K27GA00008N000500
28888994A6K27GA00008NB000500IWM   0000736600Y
28888996XBK27GA0000SJ000100
28888996XBK27GA0000SK000100
28888998ABK27GA0000SLS000100TWM   0000702400Y
28889004X6K27GA00008N000500
28889004A6K27GA00008NB000500IWM   0000736200Y
28889014X6K27GA00008N000500
28889014A6K27GA00008NB000500IWM   0000736600Y
28889024X6K27GA00008N000500
28889024A6K27GA00008NB000500IWM   0000736200Y
28889034X6K27GA00008N000500
28889034A6K27GA00008NB000500IWM   0000736600Y
28889044X6K27GA00008N000500
28889044A6K27GA00008NB000500IWM   0000736200Y
28889054X6K27GA00008N000500
28889054A6K27GA00008NB000500IWM   0000736600Y
28889064X6K27GA00008N000500
28889064A6K27GA00008NB000500IWM   0000736200Y
28889074X6K27GA00008N000500
28889074A6K27GA00008NB000500IWM   0000736600Y
28889084X6K27GA00008N000500
28889084A6K27GA00008NB000500IWM   0000736200Y
28889094X6K27GA00008N000500
28889094A6K27GA00008NB000500IWM   0000736600Y
28889104X6K27GA00008N000500
28889104A6K27GA00008NB000500IWM   0000736200Y
28889114X6K27GA00008N000500
28889114A6K27GA00008NB000500IWM   0000736600Y
28889124X6K27GA00008N000500
28889124A6K27GA00008NB000500IWM   0000736200Y
28889134X6K27GA00008N000500
28889134A6K27GA00008NB000500IWM   0000736600Y
28889144X6K27GA00008N000500
28889144A6K27GA00008NB000500IWM   0000736200Y
28889154X6K27GA00008N000500
28889154A6K27GA00008NB000500IWM   0000736600Y
28889164X6K27GA00008N000500
28889164A6K27GA00008NB000500IWM   0000736200Y
28889174X6K27GA00008N000500
28889174A6K27GA00008NB000500IWM   0000736600Y
28889184X6K27GA00008N000500
28889184A6K27GA00008NB000500IWM   0000736200Y
28889194X6K27GA00008N000500
28889194A6K27GA00008NB000500IWM   0000736600Y
28889204X6K27GA00008N000500
28889204A6K27GA00008NB000500IWM   0000736200Y
28889214X6K27GA00008N000500
28889214A6K27GA00008NB000500IWM   0000736600Y
28889224X6K27GA00008N000500
28889224A6K27GA00008NB000500IWM   0000736200Y
28889382X2K27G600006Q002000
28889406AAK27GA000128B002000SOHU  0000800400Y
28889411XBK27GA0000S2002000
28889426X1K27GA00007C002000
28889438A7K27GA000051B002000KSS   0000456300Y
28889459XBK27GA0000S1002000
28889460AAK27GA000129S002000SOHU  0000850800Y
28889474X3K27G600008N002000
28889478XCK27GA00003S002000
28889490X5K27GA00005X002000
28889495A7K27GA000052B002000LMT   0000260300Y
28889507X1K27GA00007B002000
28889511X5K27GA00005Y002000
28889514AAK27GA00012AB002000SPLS  0000046700Y
28889525A7K27GA000053B002000KSS   0000457100Y
28889553AAK27GA00012BS002000SPLS  0000249600Y
28889574X6K27GA00008N000500
28889575A6K27GA0000A0B000500IWM   0000736100Y
28889579A7K27GA000054B002000LMT   0000261100Y
28889584X6K27GA0000A0000500
28889584A6K27GA0000A0B000500IWM   0000736200Y
28889587A1K27GA00007DB002000AFL   0000157400Y
28889594X6K27GA0000A0000500
28889594A6K27GA0000A0B000500IWM   0000736600Y
28889597ABK27GA0000SMB002000SYMC  0000195200Y
28889598ABK27GA0000SNS000100TWM   0000702200Y
28889598ABK27GA0000SOB000100UWM   0000542500Y
28889598XBK27GA0000SL000100
28889596X6K27GA0000A0000500
28889596A6K27GA0000A0B000500IWM   0000736200Y
28889600XBK27GA0000SN000100
28889600XBK27GA0000SO000100
28889601ABK27GA0000SPS000100TWM   0000702400Y
28889603X2K27G600006R002000
28889605X6K27GA0000A0000500
28889605A6K27GA0000A0B000500IWM   0000736600Y
28889608ABK27GA0000SQB000100UWM   0000542500Y
28889608XBK27GA0000SP000100
28889608ABK27GA0000SRS000100TWM   0000702200Y
28889615X6K27GA0000A0000500
28889615A6K27GA0000A0B000500IWM   0000736200Y
28889618XBK27GA0000SQ000100
28889618XBK27GA0000SR000100
28889620ABK27GA0000SSS000100TWM   0000702400Y
28889621A2K27G600006TB002000BBT   0000075600Y
28889625X6K27GA0000A0000500
28889625A6K27GA0000A0B000500IWM   0000736600Y
28889628ABK27GA0000STB000100UWM   0000542500Y
28889628XBK27GA0000SS000100
28889628ABK27GA0000SUS000100TWM   0000702200Y
28889631ABK27GA0000SVS002000SYMC  0000217800Y
28889630ACK27GA00003TB002000WYE   0000099800Y
28889635X6K27GA0000A0000500
28889635A6K27GA0000A0B000500IWM   0000736200Y
28889638XBK27GA0000ST000100
28889638XBK27GA0000SU000100
28889640ABK27GA0000SWS000100TWM   0000702400Y
28889645X6K27GA0000A0000500
28889645A6K27GA0000A0B000500IWM   0000736600Y
28889648ABK27GA0000SXB000100UWM   0000542500Y
28889649ABK27GA0000SYS000100TWM   0000702200Y
28889649XBK27GA0000SW000100
28889650A3K27G600008OB002000COH   0000079700Y
28889654X6K27GA0000A0000500
28889654A6K27GA0000A0B000500IWM   0000736200Y
28889657XBK27GA0000SX000100
28889657XBK27GA0000SY000100
28889659ABK27GA0000SZS000100TWM   0000702400Y
28889659X6K27GA0000A0000500
28889659A6K27GA0000A0B000500IWM   0000736600Y
28889662ABK27GA0000T0S000100TWM   0000702200Y
28889662ABK27GA0000T1B000100UWM   0000542500Y
28889662XBK27GA0000SZ000100
28889663ABK27GA0000T2B002000TTWO  0000255100Y
28889664X6K27GA0000A0000500
28889664A6K27GA0000A0B000500IWM   0000736200Y
28889668XBK27GA0000T1000100
28889668XBK27GA0000T0000100
28889669ABK27GA0000T3S000100TWM   0000702400Y
28889674X6K27GA0000A0000500
28889674A6K27GA0000A0B000500IWM   0000736600Y
28889677ABK27GA0000T4B000100UWM   0000542500Y
28889677XBK27GA0000T3000100
28889677ABK27GA0000T5S000100TWM   0000702200Y
28889676X6K27GA0000A0000500
28889676A6K27GA0000A0B000500IWM   0000736200Y
28889680XBK27GA0000T5000100
28889680XBK27GA0000T4000100
28889681ABK27GA0000T6S000100TWM   0000702400Y
28889685X6K27GA0000A0000500
28889685A6K27GA0000A0B000500IWM   0000736600Y
28889688ABK27GA0000T7B000100UWM   0000542500Y
28889688XBK27GA0000T6000100
28889688ABK27GA0000T8S000100TWM   0000702200Y
28889689A1K27GA00007EB002000AFL   0000158200Y
28889695X6K27GA0000A0000500
28889695A6K27GA0000A0B000500IWM   0000736200Y
28889697X4K27GA0000FZ002000
28889698XBK27GA0000T7000100
28889698XBK27GA0000T8000100
28889700ABK27GA0000T9S000100TWM   0000702400Y
28889701ABK27GA0000TAS002000TTWO  0000286600Y
28889705X6K27GA0000A0000500
28889705A6K27GA0000A0B000500IWM   0000736600Y
28889715X6K27GA0000A0000500
28889715A6K27GA0000A0B000500IWM   0000736200Y
28889717A3K27G600008PB002000CVS   0000096600Y
28889717X6K27GA0000A0000500
28889717A6K27GA0000A0B000500IWM   0000736600Y
28889723A2K27G600006UB002000CAG   0000049600Y
28889724X6K27GA0000A0000500
28889724A6K27GA0000A0B000500IWM   0000736200Y
28889730ACK27GA00003UB002000VSEA  0000373100Y
28889734X6K27GA0000A0000500
28889734A6K27GA0000A0B000500IWM   0000736600Y
28889739X5K27GA00005V002000
28889744X6K27GA0000A0000500
28889744A6K27GA0000A0B000500IWM   0000736200Y
28889747X5K27GA00005W002000
28889754X6K27GA0000A0000500
28889754A6K27GA0000A0B000500IWM   0000736600Y
28889756X6K27GA0000A0000500
28889756A6K27GA0000A0B000500IWM   0000736200Y
28889765X6K27GA0000A0000500
28889765A6K27GA0000A0B000500IWM   0000736600Y
28889769A4K27GA0000G2B002000EIX   0000114500Y
28889775X6K27GA0000A0000500
28889775A6K27GA0000A0B000500IWM   0000736200Y
28889786A5K27GA00005ZB002000GE    0000300400Y
28889785X6K27GA0000A0000500
28889785A6K27GA0000A0B000500IWM   0000736600Y
28889793X7K27GA00002Z002000
28889793A5K27GA000060B002000GE    0000301200Y
28889795X6K27GA0000A0000500
28889795A6K27GA0000A0B000500IWM   0000736200Y
28889797X6K27GA0000A0000500
28889797A6K27GA0000A0B000500IWM   0000736600Y
28889804X6K27GA0000A0000500
28889804A6K27GA0000A0B000500IWM   0000736200Y
28889812A6K27GA0000A1B002000JCI   0000077400Y
28889814X6K27GA0000A0000500
28889814A6K27GA0000A0B000500IWM   0000736600Y
28889819X3K27G600008P002000
28889819X5K27GA00005Z002000
28889822X3K27G600008O002000
28889822X2K27G600006T002000
28889822X1K27GA00007D002000
28889824X7K27GA000052002000
28889824X7K27GA000051002000
28889823X6K27GA00009W002000
28889823X6K27GA00009V002000
28889824X4K27GA0000G0002000
28889825X5K27GA00005U002000
28889824X4K27GA0000FY002000
28889825X2K27G600006P002000
28889825X7K27GA00004W002000
28889826X2K27G600006N002000
28889824X6K27GA0000A0000500
28889824A6K27GA0000A0B000500IWM   0000736200Y
28889833X4K27GA0000FL002000
28889835X2K27G600006K002000
28889833X6K27GA00009A002000
28889834X4K27GA0000FI002000
28889835X7K27GA00004S002000
28889834X6K27GA0000A0000500
28889834A6K27GA0000A0B000500IWM   0000736600Y
28889837X2K27G600006C002000
28889837X2K27G600006B002000
28889837X2K27G600006A002000
28889837X3K27G6000086002000
28889837X2K27G6000066002000
28889837X7K27GA00004P002000
28889837X7K27GA00004O002000
28889836X6K27GA0000A0000500
28889836A6K27GA0000A0B000500IWM   0000736200Y
28889836A6K27GA0000A2B002000KFT   0000306300Y
28889838XBK27GA0000RN002000
28889838X5K27GA00005E002000
28889839X4K27GA0000FA002000
28889839X4K27GA0000F8002000
28889840X2K27G6000060002000
28889839X5K27GA00005C002000
28889839X4K27GA0000F4002000
28889839X1K27GA00006P002000
28889840X4K27GA0000EV002000
28889840X3K27G600007V002000
28889840X6K27GA00008U002000
28889842X1K27GA00006I002000
28889842X4K27GA0000EF002000
28889843X4K27GA0000EC002000
28889843X1K27GA00006A002000
28889844X7K27GA000047002000
28889845X8K27G600003E002000
28889843XCK27GA00003D002000
28889846X5K27GA00004U002000
28889844X6K27GA00008A002000
28889847X3K27G6000070002000
28889845X6K27GA0000A0000500
28889845A6K27GA0000A0B000500IWM   0000736600Y
28889847X4K27GA0000DF002000
28889847X6K27GA00007O002000
28889849X3K27G600006T002000
28889849X4K27GA0000D4002000
28889849X7K27GA00003S002000
28889852X7K27GA00003O002000
28889852X6K27GA00007E002000
28889853X7K27GA00003M002000
28889854X7K27GA00003H002000
28889855X7K27GA00003A002000
28889855X7K27GA000038002000
28889855X7K27GA000033002000
28889856X1K27GA000056002000
28889856X5K27GA00003W002000
28889856X7K27GA000030002000
28889855X6K27GA0000A0000500
28889855A6K27GA0000A0B000500IWM   0000736200Y
28889856X7K27GA00002V002000
28889856X7K27GA00002U002000
28889857X7K27GA00002T002000
28889857X7K27GA00002P002000
28889857X7K27GA00002L002000
28889857X7K27GA00002I002000
28889858X7K27GA00002H002000
28889858X1K27GA00004I002000
28889858X6K27GA00005Y002000
28889858X6K27GA00005H002000
28889859X6K27GA000055002000
28889859X6K27GA000052002000
28889859X6K27GA000051002000
28889859X6K27GA000050002000
28889861X5K27GA00002F002000
28889862X5K27GA000027002000
28889863X5K27GA000021002000
28889863X5K27GA00001Y002000
28889863X5K27GA00001X002000
28889864X5K27GA00001W002000
28889865X5K27GA00001T002000
28889865X5K27GA00001R002000
28889866X5K27GA00001P002000
28889866X5K27GA00001N002000
28889866X5K27GA00001K002000
28889866X4K27GA000070002000
28889865X6K27GA0000A0000500
28889865A6K27GA0000A0B000500IWM   0000736600Y
28889866X4K27GA00006P002000
28889867X4K27GA00006N002000
28889868X4K27GA00006I002000
28889868X4K27GA00006B002000
28889868X4K27GA00006A002000
28889868X4K27GA000069002000
28889868X4K27GA00005X002000
28889869X4K27GA00005R002000
28889870X3K27G6000021002000
28889872X3K27G600001V002000
28889874X3K27G600001U002000
28889874X3K27G600001T002000
28889874X3K27G600001P002000
28889874X3K27G600001J002000
28889874X3K27G600001I002000
28889875X3K27G600001H002000
28889875X3K27G600001F002000
28889876X3K27G600001B002000
28889876X2K27G600001L002000
28889875X6K27GA0000A0000500
28889875A6K27GA0000A0B000500IWM   0000736200Y
28889877X2K27G600001K002000
28889877X2K27G600001J002000
28889877X2K27G600001I002000
28889878X2K27G600001H002000
28889878X2K27G600001C002000
28889878X2K27G6000018002000
28889878X2K27G6000013002000
28889879X2K27G6000011002000
28889879X2K27G6000010002000
28889880X2K27G600000P002000
28889880X1K27GA000027002000
28889881X1K27GA00001W002000
28889883X1K27GA00001P002000
28889884X1K27GA00001N002000
28889885X1K27GA00001M002000
28889884XCK27GA00001C002000
28889884XCK27GA00001B002000
28889886XBK27GA000017002000
28889886XBK27GA000016002000
28889884X6K27GA0000A0000500
28889884A6K27GA0000A0B000500IWM   0000736600Y
28889887X8K27G6000009002000
28889887X8K27G6000008002000
28889886X7K27GA00000P002000
28889887X7K27GA00000N002000
28889885X6K27GA00002I002000
28889887X5K27GA000012002000
28889887X4K27GA000042002000
28889888X3K27G600000I002000
28889888X2K27G600000I002000
28889888X2K27G600000G002000
28889888X1K27GA00001A002000
28889888X1K27GA000019002000
28889888X1K27GA000018002000
28889888X1K27GA000017002000
28889889X1K27GA000016002000
28889889X1K27GA000015002000
28889895X6K27GA0000A0000500
28889895A6K27GA0000A0B000500IWM   0000736200Y
28889905X6K27GA0000A0000500
28889905A6K27GA0000A0B000500IWM   0000736600Y
28889915X6K27GA0000A0000500
28889915A6K27GA0000A0B000500IWM   0000736200Y
28889925X6K27GA0000A0000500
28889925A6K27GA0000A0B000500IWM   0000736600Y
28889935X6K27GA0000A0000500
28889935A6K27GA0000A0B000500IWM   0000736200Y
28889945X6K27GA0000A0000500
28889945A6K27GA0000A0B000500IWM   0000736600Y
28889947X6K27GA0000A0000500
28889947A6K27GA0000A0B000500IWM   0000736200Y
28889955X6K27GA0000A0000500
28889955A6K27GA0000A0B000500IWM   0000736600Y
28889965X6K27GA0000A0000500
28889965A6K27GA0000A0B000500IWM   0000736200Y
28889974X6K27GA0000A0000500
28889974A6K27GA0000A0B000500IWM   0000736600Y
28889985X6K27GA0000A0000500
28889985A6K27GA0000A0B000500IWM   0000736200Y
28889987X6K27GA0000A0000500
28889987A6K27GA0000A0B000500IWM   0000736600Y
28889994X6K27GA0000A0000500
28889994A6K27GA0000A0B000500IWM   0000736200Y
28890345X6K27GA0000A0000500
28890345A6K27GA0000A3B000500IWM   0000736100Y
28890348X3K27G6000088002000
28890354X6K27GA0000A3000500
28890354A6K27GA0000A3B000500IWM   0000736200Y
28890365X6K27GA0000A3000500
28890365A6K27GA0000A3B000500IWM   0000736600Y
28890368ABK27GA0000TBB000100UWM   0000542500Y
28890368XBK27GA0000T9000100
28890368ABK27GA0000TCS000100TWM   0000702200Y
28890375X6K27GA0000A3000500
28890375A6K27GA0000A3B000500IWM   0000736200Y
28890378XBK27GA0000TB000100
28890378XBK27GA0000TC000100
28890380ABK27GA0000TDS000100TWM   0000702400Y
28890386A2K27G600006VB002000BMY   0000046800Y
28890385X6K27GA0000A3000500
28890385A6K27GA0000A3B000500IWM   0000736600Y
28890388ABK27GA0000TEB000100UWM   0000542500Y
28890388XBK27GA0000TD000100
28890388ABK27GA0000TFS000100TWM   0000702200Y
28890395X6K27GA0000A3000500
28890395A6K27GA0000A3B000500IWM   0000736200Y
28890398XBK27GA0000TE000100
28890398XBK27GA0000TF000100
28890400ABK27GA0000TGS000100TWM   0000702400Y
28890400X5K27GA000051002000
28890404ACK27GA00003VS002000VSEA  0000430500Y
28890404X6K27GA0000A3000500
28890404A6K27GA0000A3B000500IWM   0000736600Y
28890408ABK27GA0000THB000100UWM   0000542500Y
28890408XBK27GA0000TG000100
28890408ABK27GA0000TIS000100TWM   0000702200Y
28890409X7K27GA000054002000
28890414X6K27GA0000A3000500
28890414A6K27GA0000A3B000500IWM   0000736200Y
28890417XBK27GA0000TH000100
28890417XBK27GA0000TI000100
28890419ABK27GA0000TJS000100TWM   0000702400Y
28890418A6K27GA0000A4B000100IWM   0000736100Y
28890418X6K27GA0000A4000100
28890418X6K27GA0000A3000500
28890418A6K27GA0000A3B000500IWM   0000736600Y
28890421ABK27GA0000TKB000100UWM   0000542500Y
28890422ABK27GA0000TLS000100TWM   0000702200Y
28890422XBK27GA0000TJ000100
28890424X6K27GA0000A3000500
28890424A6K27GA0000A3B000500IWM   0000736200Y
28890428XBK27GA0000TK000100
28890428XBK27GA0000TL000100
28890426ACK27GA00003WB002000WFMI  0000276500Y
28890429X6K27GA0000A3000500
28890429A6K27GA0000A3B000500IWM   0000736600Y
28890431ABK27GA0000TMS000100TWM   0000702400Y
28890430A6K27GA0000A5B000100IWM   0000736100Y
28890430X6K27GA0000A5000100
28890430XCK27GA00003T002000
28890432XBK27GA0000TM000100
28890432ABK27GA0000TNB000100UWM   0000542500Y
28890432ABK27GA0000TOS000100TWM   0000702200Y
28890431X6K27GA0000A3000500
28890431A6K27GA0000A3B000500IWM   0000736200Y
28890434XBK27GA0000TN000100
28890434XBK27GA0000TO000100
28890434X6K27GA0000A3000500
28890434A6K27GA0000A3B000500IWM   0000736600Y
28890436ABK27GA0000TPS000100TWM   0000702400Y
28890437ABK27GA0000TQB000100UWM   0000542500Y
28890437XBK27GA0000TP000100
28890437ABK27GA0000TRS000100TWM   0000702200Y
28890440ABK27GA0000TSB002000UTX   0000173100Y
28890444X6K27GA0000A3000500
28890444A6K27GA0000A3B000500IWM   0000736200Y
28890447XBK27GA0000TQ000100
28890447XBK27GA0000TR000100
28890448A6K27GA0000A6B000100IWM   0000736100Y
28890449ABK27GA0000TTS000100TWM   0000702400Y
28890448X6K27GA0000A6000100
28890448X6K27GA0000A3000500
28890448A6K27GA0000A3B000500IWM   0000736600Y
28890450ACK27GA00003XB002000XLNX  0000255700Y
28890452ABK27GA0000TUB000100UWM   0000542500Y
28890452XBK27GA0000TT000100
28890452ABK27GA0000TVS000100TWM   0000702200Y
28890454X6K27GA0000A3000500
28890454A6K27GA0000A3B000500IWM   0000736200Y
28890458XBK27GA0000TU000100
28890458XBK27GA0000TV000100
28890458A6K27GA0000A7B000100IWM   0000736100Y
28890459ABK27GA0000TWS000100TWM   0000702400Y
28890458X6K27GA0000A7000100
28890459X6K27GA0000A3000500
28890459A6K27GA0000A3B000500IWM   0000736600Y
28890461X6K27GA0000A3000500
28890461A6K27GA0000A3B000500IWM   0000736200Y
28890465X1K27GA00007E002000
28890465X6K27GA0000A3000500
28890465A6K27GA0000A3B000500IWM   0000736600Y
28890467A1K27GA00007FB002000ABT   0000130300Y
28890474X2K27G600006S002000
28890475X6K27GA0000A3000500
28890475A6K27GA0000A3B000500IWM   0000736200Y
28890485X6K27GA0000A3000500
28890485A6K27GA0000A3B000500IWM   0000736600Y
28890486ACK27GA00003YS002000XLNX  0000289900Y
28890490X2K27G600006H002000
28890495X6K27GA0000A3000500
28890495A6K27GA0000A3B000500IWM   0000736200Y
28890500X3K27G600008M002000
28890504X6K27GA0000A3000500
28890504A6K27GA0000A3B000500IWM   0000736600Y
28890506X6K27GA0000A3000500
28890506A6K27GA0000A3B000500IWM   0000736200Y
28890513ACK27GA00003ZB002000YHOO  0000265100Y
28890515X6K27GA0000A3000500
28890515A6K27GA0000A3B000500IWM   0000736600Y
28890525X6K27GA0000A3000500
28890525A6K27GA0000A3B000500IWM   0000736200Y
28890534X6K27GA0000A3000500
28890534A6K27GA0000A3B000500IWM   0000736600Y
28890538ACK27GA000040S002000YHOO  0000287600Y
28890540X4K27GA0000DG002000
28890545X6K27GA0000A3000500
28890545A6K27GA0000A3B000500IWM   0000736200Y
28890553X4K27GA0000G2002000
28890554X6K27GA0000A3000500
28890554A6K27GA0000A3B000500IWM   0000736600Y
28890556X6K27GA0000A3000500
28890556A6K27GA0000A3B000500IWM   0000736200Y
28890564A1K27GA00007GB002000AAPL  0001817200Y
28890565X6K27GA0000A3000500
28890565A6K27GA0000A3B000500IWM   0000736600Y
28890569A3K27G600008QB002000CVS   0000098500Y
28890575X6K27GA0000A3000500
28890575A6K27GA0000A3B000500IWM   0000736200Y
28890585A1K27GA00007HS002000AAPL  0001844700Y
28890585X6K27GA0000A3000500
28890585A6K27GA0000A3B000500IWM   0000736600Y
28890592A5K27GA000061B002000HNZ   0000106100Y
28890595X6K27GA0000A3000500
28890595A6K27GA0000A3B000500IWM   0000736200Y
28890597X6K27GA0000A3000500
28890597A6K27GA0000A3B000500IWM   0000736600Y
28890604X6K27GA0000A3000500
28890604A6K27GA0000A3B000500IWM   0000736200Y
28890607A1K27GA00007IB002000ADSK  0000384200Y
28890611A5K27GA000062B002000HOT   0000109700Y
28890614X6K27GA0000A3000500
28890614A6K27GA0000A3B000500IWM   0000736600Y
28890624X6K27GA0000A3000500
28890624A6K27GA0000A3B000500IWM   0000736200Y
28890634X6K27GA0000A3000500
28890634A6K27GA0000A3B000500IWM   0000736600Y
28890638A7K27GA000055B002000MDY   0001579600Y
28890645X6K27GA0000A3000500
28890645A6K27GA0000A3B000500IWM   0000736200Y
28890655X6K27GA0000A3000500
28890655A6K27GA0000A3B000500IWM   0000736600Y
28890665X6K27GA0000A3000500
28890665A6K27GA0000A3B000500IWM   0000736200Y
28890675X6K27GA0000A3000500
28890675A6K27GA0000A3B000500IWM   0000736600Y
28890685X6K27GA0000A3000500
28890685A6K27GA0000A3B000500IWM   0000736200Y
28890695X6K27GA0000A3000500
28890695A6K27GA0000A3B000500IWM   0000736600Y
28890705X6K27GA0000A3000500
28890705A6K27GA0000A3B000500IWM   0000736200Y
28890715X6K27GA0000A3000500
28890715A6K27GA0000A3B000500IWM   0000736600Y
28890725X6K27GA0000A3000500
28890725A6K27GA0000A3B000500IWM   0000736200Y
28890735X6K27GA0000A3000500
28890735A6K27GA0000A3B000500IWM   0000736600Y
28890745X6K27GA0000A3000500
28890745A6K27GA0000A3B000500IWM   0000736200Y
28890754X6K27GA0000A3000500
28890754A6K27GA0000A3B000500IWM   0000736600Y
28890765X6K27GA0000A3000500
28890765A6K27GA0000A3B000500IWM   0000736200Y
28890788E1K27GA00004W00010000001AQ00004
28890983XAK27GA000118001000
28890984AAK27GA00012CS001000SPY   0001425600Y
28890984XAK27GA000115001000
28890985XBK27GA0000QG001000
28890985ABK27GA0000TXS001000SSO   0000765200Y
28890985AAK27GA00012DS005000SPY   0001425900Y
28890986AAK27GA00012ES000500SPY   0001425800Y
28890986XAK27GA00011Z005000
28890986XAK27GA000120000500
28890986AAK27GA00012FB001000SPY   0001425100Y
28890995X4K27GA000062000200
28890995A4K27GA000062B000200DIA   0001298400Y
28890997X3K27G600007J000100
28890999A3K27G600008RB000100DDM   0000801000Y
28891010A6K27GA0000A8S002000IWM   0000737100Y
28891033X6K27GA00008M002000
28891321X8K27G600003T000500
28891321X8K27G600003R000100
28891373A3K27G600008SB002000CELG  0000485300Y
28891376XBK27GA0000TS002000
28891394X1K27GA00007F002000
28891400A1K27GA00007KS002000ADSK  0000420200Y
28891405X2K27G600006L002000
28891417X2K27G600006U002000
28891425A1K27GA00007LB002000ADTN  0000228200Y
28891431A5K27GA000063B002000GM    0000177800Y
28891441X3K27G600008Q002000
28891453A1K27GA00007MS002000ADTN  0000264200Y
28891454X3K27G600007T002000
28891469A7K27GA000056B002000LMT   0000267100Y
28891477A1K27GA00007NB002000ALTR  0000213300Y
28891495ACK27GA000041B002000WYE   0000102200Y
28891499A1K27GA00007OS002000ALTR  0000246300Y
28891509X5K27GA000061002000
28891516X5K27GA000062002000
28891528X6K27GA0000A1002000
28891534X7K27GA000031002000
28891542X7K27GA00003L002000
28891550A1K27GA00007PB002000APOL  0000410200Y
28891561A1K27GA00007QB002000AFL   0000161900Y
28891582A2K27G600006WB002000BBT   0000078300Y
28891581A1K27GA00007RS002000APOL  0000536500Y
28891594A2K27G600006XB002000BDX   0000768800Y
28891594A1K27GA00007SB002000APPX  0000095800Y
28891612A3K27G600008TB002000COH   0000082400Y
28891627A4K27GA0000G3B002000EAT   0000200600Y
28891637A4K27GA0000G4B002000EIX   0000117300Y
28892374XAK27GA000123002000
28892378X2K27G600006V002000
28892384A1K27GA00007TS002000APPX  0000149400Y
28892390X7K27GA000056002000
28892399XCK27GA000041002000
28892409X1K27GA00007Q002000
28892410A2K27G600006YB002000BBBY  0000307600Y
28892418X1K27GA00006G002000
28892422X4K27GA0000G4002000
28892431X7K27GA000032002000
28892443A2K27G600006ZS002000BBBY  0000350200Y
28892444ABK27GA0000TYB002000UTX   0000177100Y
28892469A2K27G6000070B002000CAKE  0000193900Y
28892477A1K27GA00007UB002000ABT   0000133400Y
28892493A2K27G6000071S002000CAKE  0000251300Y
28892500A2K27G6000072B002000AXP   0000411400Y
28892512A3K27G600008UB002000CECO  0000107600Y
28892520A2K27G6000073B002000CAG   0000051500Y
28892537A3K27G600008VS002000CECO  0000193000Y
28892541A3K27G600008WB002000CVS   0000100900Y
28892557A3K27G600008XB002000DD    0000459100Y
28892561A3K27G600008YB002000CEPH  0000645200Y
28892577A5K27GA000064B002000HNZ   0000108600Y
28892586A5K27GA000065B002000HOT   0000112400Y
28892619A3K27G600008ZS002000CEPH  0000779800Y
28892727X4K27GA000062000200
28892727A4K27GA000062B000200DIA   0001298700Y
28892730A3K27G6000090B000100DDM   0000801100Y
28892730XAK27GA00012D005000
28892730AAK27GA00012GS005000SPY   0001426200Y
28892730XAK27GA00012E000500
28892731AAK27GA00012HS000500SPY   0001425900Y
28892731XAK27GA0000O8000500
28892731AAK27GA0000O8S000500SPY   0001426100Y
28892731X4K27GA0000FV000200
28892731XAK27GA0000ZM000500
28892731AAK27GA0000ZMS000500SPY   0001426000Y
28892731XAK27GA00012C001000
28892731XAK27GA00012F001000
28892731AAK27GA00012IB002000SPY   0001425500Y
28892731AAK27GA00012JB001000SPY   0001425500Y
28892733AAK27GA00012KS001000SPY   0001426000Y
28892733XBK27GA0000TX001000
28892733XAK27GA00011Y002500
28892734AAK27GA00012LS002500SPY   0001426000Y
28892735ABK27GA0000TZS001000SSO   0000765300Y
28892736A4K27GA0000G5S000200DIA   0001299200Y
28892738XAK27GA00012H000500
28892740XAK27GA000121001000
28892745XAK27GA0000FG000500
28892745AAK27GA0000FGB000500SPY   0001425500Y
28892748X6K27GA0000A3000500
28892748A6K27GA0000A9B002000IWM   0000736500Y
28892750XAK27GA000122001000
28892749A6K27GA0000AAB000500IWM   0000736600Y
28892751ABK27GA0000U0B000100UWM   0000542500Y
28892750X6K27GA0000A8002000
28892751XBK27GA0000TW000100
28892751ABK27GA0000U1S000100TWM   0000702200Y
28892750X6K27GA0000AA000500
28892750A6K27GA0000AAB000500IWM   0000736200Y
28892752X6K27GA0000AA000500
28892752A6K27GA0000AAB000500IWM   0000736600Y
28892753XBK27GA0000U0000100
28892754XBK27GA0000U1000100
28892755ABK27GA0000U2B000100UWM   0000542500Y
28892754A6K27GA0000ABB000100IWM   0000736100Y
28892755ABK27GA0000U3S000100TWM   0000702200Y
28892754X6K27GA0000AA000500
28892754A6K27GA0000AAB000500IWM   0000736200Y
28892754X6K27GA0000AB000100
28892764X6K27GA0000AA000500
28892764A6K27GA0000AAB000500IWM   0000736600Y
28892766XBK27GA0000U2000100
28892766XBK27GA0000U3000100
28892768ABK27GA0000U4B000100UWM   0000542500Y
28892768ABK27GA0000U5S000100TWM   0000702200Y
28892767X6K27GA0000AA000500
28892767A6K27GA0000AAB000500IWM   0000736200Y
28892774X6K27GA0000AA000500
28892774A6K27GA0000AAB000500IWM   0000736600Y
28892778X6K27GA0000AA000500
28892778A6K27GA0000AAB000500IWM   0000736200Y
28892784X6K27GA0000AA000500
28892784A6K27GA0000AAB000500IWM   0000736600Y
28892794X6K27GA0000AA000500
28892794A6K27GA0000AAB000500IWM   0000736200Y
28892797XBK27GA0000U4000100
28892797XBK27GA0000U5000100
28892799ABK27GA0000U6S000100TWM   0000702400Y
28892798X6K27GA0000AA000500
28892798A6K27GA0000AAB000500IWM   0000736600Y
28892801ABK27GA0000U7B000100UWM   0000542500Y
28892801ABK27GA0000U8S000100TWM   0000702200Y
28892801XBK27GA0000U6000100
28892804X6K27GA0000AA000500
28892804A6K27GA0000AAB000500IWM   0000736200Y
28892807XBK27GA0000U7000100
28892807XBK27GA0000U8000100
28892809ABK27GA0000U9S000100TWM   0000702400Y
28892814X6K27GA0000AA000500
28892814A6K27GA0000AAB000500IWM   0000736600Y
28892816ABK27GA0000UAB000100UWM   0000542500Y
28892816ABK27GA0000UBS000100TWM   0000702200Y
28892816XBK27GA0000U9000100
28892824X6K27GA0000AA000500
28892824A6K27GA0000AAB000500IWM   0000736200Y
28892827XBK27GA0000UA000100
28892827XBK27GA0000UB000100
28892829ABK27GA0000UCS000100TWM   0000702400Y
28892829X6K27GA0000AA000500
28892829A6K27GA0000AAB000500IWM   0000736600Y
28892834X6K27GA0000AA000500
28892834A6K27GA0000AAB000500IWM   0000736200Y
28892844X6K27GA0000AA000500
28892844A6K27GA0000AAB000500IWM   0000736600Y
28892846ABK27GA0000UDB000100UWM   0000542500Y
28892846ABK27GA0000UES000100TWM   0000702200Y
28892846XBK27GA0000UC000100
28892854X6K27GA0000AA000500
28892854A6K27GA0000AAB000500IWM   0000736200Y
28892855XBK27GA0000UD000100
28892855XBK27GA0000UE000100
28892856A6K27GA0000ACB000100IWM   0000736100Y
28892857ABK27GA0000UFS000100TWM   0000702400Y
28892856X6K27GA0000AC000100
28892856X6K27GA0000AA000500
28892856A6K27GA0000AAB000500IWM   0000736600Y
28892864X6K27GA0000AA000500
28892864A6K27GA0000AAB000500IWM   0000736200Y
28892874X6K27GA0000AA000500
28892874A6K27GA0000AAB000500IWM   0000736600Y
28892876ABK27GA0000UGB000100UWM   0000542500Y
28892876XBK27GA0000UF000100
28892876ABK27GA0000UHS000100TWM   0000702200Y
28892884X6K27GA0000AA000500
28892884A6K27GA0000AAB000500IWM   0000736200Y
28892885XBK27GA0000UG000100
28892885XBK27GA0000UH000100
28892887ABK27GA0000UIS000100TWM   0000702400Y
28892887X6K27GA0000AA000500
28892887A6K27GA0000AAB000500IWM   0000736600Y
28892891X6K27GA0000AA000500
28892891A6K27GA0000AAB000500IWM   0000736200Y
28892894X6K27GA0000AA000500
28892894A6K27GA0000AAB000500IWM   0000736600Y
28892896ABK27GA0000UJB000100UWM   0000542500Y
28892896XBK27GA0000UI000100
28892896ABK27GA0000UKS000100TWM   0000702200Y
28892899XAK27GA0000E6001000
28892899AAK27GA0000E6S001000SPY   0001426100Y
28892904X6K27GA0000AA000500
28892904A6K27GA0000AAB000500IWM   0000736200Y
28892905XBK27GA0000UJ000100
28892905XBK27GA0000UK000100
28892907ABK27GA0000ULS000100TWM   0000702400Y
28892907X6K27GA0000AA000500
28892907A6K27GA0000AAB000500IWM   0000736600Y
28892914X6K27GA0000AA000500
28892914A6K27GA0000AAB000500IWM   0000736200Y
28892924X6K27GA0000AA000500
28892924A6K27GA0000AAB000500IWM   0000736600Y
28892925ABK27GA0000UMB000100UWM   0000542500Y
28892925XBK27GA0000UL000100
28892926ABK27GA0000UNS000100TWM   0000702200Y
28892934X6K27GA0000AA000500
28892934A6K27GA0000AAB000500IWM   0000736200Y
28892935XBK27GA0000UM000100
28892935XBK27GA0000UN000100
28892937AAK27GA00012MS000500SPY   0001426000Y
28892937ABK27GA0000UOS000100TWM   0000702400Y
28892937X6K27GA0000AA000500
28892937A6K27GA0000AAB000500IWM   0000736600Y
28892944X6K27GA0000AA000500
28892944A6K27GA0000AAB000500IWM   0000736200Y
28892954X6K27GA0000AA000500
28892954A6K27GA0000AAB000500IWM   0000736600Y
28892960A8K27G600004ES000500MZZ   0000493900Y
28892960A8K27G600004FB000100MVV   0000806200Y
28892964X6K27GA0000AA000500
28892964A6K27GA0000AAB000500IWM   0000736200Y
28892974X6K27GA0000AA000500
28892974A6K27GA0000AAB000500IWM   0000736600Y
28892984X6K27GA0000AA000500
28892984A6K27GA0000AAB000500IWM   0000736200Y
28892994X6K27GA0000AA000500
28892994A6K27GA0000AAB000500IWM   0000736600Y
28893004X6K27GA0000AA000500
28893004A6K27GA0000AAB000500IWM   0000736200Y
28893024X6K27GA0000AA000500
28893024A6K27GA0000AAB000500IWM   0000736600Y
28893034X6K27GA0000AA000500
28893034A6K27GA0000AAB000500IWM   0000736200Y
28893044X6K27GA0000AA000500
28893044A6K27GA0000AAB000500IWM   0000736600Y
28893054X6K27GA0000AA000500
28893054A6K27GA0000AAB000500IWM   0000736200Y
28893064X6K27GA0000AA000500
28893064A6K27GA0000AAB000500IWM   0000736600Y
28893070XAK27GA0000SJ000600
28893074AAK27GA00012NB001000SPY   0001419700Y
28893074X6K27GA0000AA000500
28893074A6K27GA0000AAB000500IWM   0000736200Y
28893084X6K27GA0000AA000500
28893084A6K27GA0000AAB000500IWM   0000736600Y
28893094X6K27GA0000AA000500
28893094A6K27GA0000AAB000500IWM   0000736200Y
28893104X6K27GA0000AA000500
28893104A6K27GA0000AAB000500IWM   0000736600Y
28893114X6K27GA0000AA000500
28893114A6K27GA0000AAB000500IWM   0000736200Y
28893124X6K27GA0000AA000500
28893124A6K27GA0000AAB000500IWM   0000736600Y
28893132X4K27GA0000FG000100
28893132X3K27G600008B000100
28893134X6K27GA0000AA000500
28893134A6K27GA0000AAB000500IWM   0000736200Y
28893144X6K27GA0000AA000500
28893144A6K27GA0000AAB000500IWM   0000736600Y
28893154X6K27GA0000AA000500
28893154A6K27GA0000AAB000500IWM   0000736200Y
28893186X4K27GA00007C000200
28893186A4K27GA00007CB000200DIA   0001298800Y
28893188A4K27GA0000G6S000100DOG   0000598300Y
28893188A4K27GA0000G7S000100DXD   0000500100Y
28893188A3K27G6000091B000100DDM   0000801200Y
28893312XAK27GA00011V002500
28893356X1K27GA000071002000
28893375A2K27G6000074B002000BMY   0000048600Y
28893389XAK27GA00012A002000
28893396XBK27GA0000TY002000
28893395AAK27GA00012OB002000SHLD  0000754800Y
28893402XCK27GA00003B002000
28893420A3K27G6000092B002000CCMP  0000354200Y
28893423XAK27GA0000E8001000
28893423AAK27GA0000E8B001000SPY   0001425600Y
28893423XAK27GA0000F7000500
28893423AAK27GA0000F7B000500SPY   0001425500Y
28893423AAK27GA00012PB002000SPY   0001425600Y
28893423XAK27GA0000NZ000500
28893423AAK27GA0000NZS000500SPY   0001426100Y
28893424XAK27GA00011W001000
28893424XBK27GA0000S0001000
28893424AAK27GA00012QS001000SDS   0000548900Y
28893424ABK27GA0000UPB001000SSO   0000764400Y
28893424XAK27GA00011X005000
28893424AAK27GA00012RB001000SPY   0001425600Y
28893425AAK27GA00012SB002500SPY   0001425500Y
28893427ABK27GA0000UQB001000SSO   0000764200Y
28893427XBK27GA0000RZ001000
28893428A7K27GA000057B002000LMT   0000273100Y
28893441XAK27GA0000ZJ001000
28893443AAK27GA00012TS001000SPY   0001426100Y
28893444A3K27G6000093S002000CCMP  0000390000Y
28893444X1K27GA00007U002000
28893445A6K27GA0000ADB002000IWM   0000736600Y
28893446X6K27GA00002B000500
28893446A6K27GA00002BS000500IWM   0000737200Y
28893448X4K27GA0000FF000200
28893448ABK27GA0000URB000100UWM   0000542500Y
28893449ABK27GA0000USS000100TWM   0000702200Y
28893449XBK27GA0000UO000100
28893450XBK27GA0000TZ001000
28893451A4K27GA0000G8S000200DIA   0001299300Y
28893452A8K27G600004GS000500MZZ   0000493800Y
28893452A8K27G600004HB000100MVV   0000806300Y
28893452ABK27GA0000UTS001000SSO   0000765400Y
28893456XBK27GA0000RU000100
28893456XBK27GA0000RW000100
28893456XBK27GA0000RV000100
28893475X8K27G6000047000500
28893475X8K27G6000048000100
28893477A8K27G600004IS000100MVV   0000809600Y
28893489A3K27G6000094B002000CMCSA 0000192800Y
28893490ACK27GA000042B002000WYE   0000104600Y
28893525A1K27GA00007VB002000AFL   0000165600Y
28893546X2K27G600006W002000
28893566A3K27G6000095S002000CMCSA 0000239100Y
28893585X3K27G600008T002000
28893599X3K27G600008W002000
28893602AAK27GA00012UB001000SPY   0001425400Y
28893613X6K27GA0000AA000500
28893619A6K27GA0000AEB000500IWM   0000736600Y
28893637A3K27G6000096S002000CMCSK 0000274600Y
28893656X5K27GA000064002000
28893663A3K27G6000097B002000COST  0000697300Y
28893663A1K27GA00007WB002000ARO   0000297600Y
28893671X5K27GA000065002000
28893687A3K27G6000098S002000COST  0000745700Y
28893704A4K27GA0000G9B002000EIX   0000120100Y
28893716A6K27GA0000AFB002000JCI   0000081200Y
28893728A7K27GA000058B002000KMB   0000613000Y
28893739A7K27GA000059B002000KMX   0000188000Y
28894362X7K27GA000057002000
28894370A1K27GA00007XS002000AMGN  0000487400Y
28894394ABK27GA0000UUB002000UTX   0000181100Y
28894396AAK27GA00012VB002000SPLS  0000049900Y
28894412A3K27G6000099B002000CSCO  0000251300Y
28894411ACK27GA000043B002000WMT   0000539900Y
28894422XCK27GA000042002000
28894440A3K27G600009AS002000CSCO  0000274300Y
28894445A1K27GA00007YB002000ABT   0000136400Y
28894455X1K27GA00007V002000
28894466A3K27G600009BB002000CTAS  0000281600Y
28894485A2K27G6000075B002000BBT   0000081200Y
28894487A3K27G600009CS002000CTAS  0000323900Y
28894501X2K27G6000073002000
28894514A3K27G600009DB002000CTSH  0000072100Y
28894520A3K27G600009EB002000COH   0000085400Y
28894534A3K27G600009FS002000CTSH  0000337600Y
28894545A3K27G600009GB002000CVS   0000103300Y
28894582A3K27G600009HB002000DAL   0000010000Y
28894582X4K27GA0000G9002000
28894590X5K27GA00005L002000
28894602A5K27GA000066B002000HNZ   0000111200Y
28894611A5K27GA000067B002000HOT   0000115100Y
28894685XAK27GA00012P002000
28894685XAK27GA00012R001000
28894685XAK27GA00012T001000
28894685X4K27GA0000G8000200
28894685XAK27GA0000NZ000500
28894685AAK27GA0000NZS000500SPY   0001425700Y
28894685AAK27GA00012WS001000SPY   0001425700Y
28894685XAK27GA0000E8001000
28894685AAK27GA0000E8B001000SPY   0001425200Y
28894687XBK27GA0000UT001000
28894687ABK27GA0000UVS001000SSO   0000765300Y
28894686AAK27GA00012XB001000SPY   0001425200Y
28894687AAK27GA00012YB005000SPY   0001425200Y
28894687XAK27GA00012S002500
28894688AAK27GA00012ZB002500SPY   0001425400Y
28894690XAK27GA00012Q001000
28894691XBK27GA0000UP001000
28894691ABK27GA0000UWB001000SSO   0000764100Y
28894691A4K27GA0000GAS000200DIA   0001299000Y
28894692XBK27GA0000UQ001000
28894693ABK27GA0000UXB001000SSO   0000764300Y
28894702X4K27GA00007C000200
28894702A4K27GA00007CB000200DIA   0001298500Y
28894704X4K27GA0000G6000100
28894704X4K27GA0000G7000100
28894704X3K27G6000091000100
28894718X8K27G6000045000500
28894719X8K27G600004I000100
28894719X8K27G6000046000100
28894720A8K27G600004JB000500MZZ   0000491400Y
28894721A8K27G600004KS000100MVV   0000809700Y
28894811A4K27GA0000GBB000100DXD   0000499500Y
28894812A3K27G600009IS000100DDM   0000802500Y
28894921XAK27GA00012U001000
28894941A8K27G600004LB000500MZZ   0000491500Y
28894941A8K27G600004MS000100MVV   0000809500Y
28894940X4K27GA0000G5000200
28894948A4K27GA0000GCS000200DIA   0001298900Y
28895398X2K27G6000074002000
28895398A3K27G600009JB002000CYBX  0000139900Y
28895404XBK27GA0000UU002000
28895407A1K27GA00007ZB002000AA    0000431500Y
28895410X1K27GA00007Y002000
28895423X3K27G6000071002000
28895430X3K27G600009G002000
28895436X5K27GA000066002000
28895442A3K27G600009KS002000CYBX  0000190700Y
28895450X5K27GA000067002000
28895458X6K27GA00007V002000
28895460A1K27GA000080S002000AA    0000462100Y
28895468X6K27GA0000AF002000
28895478X6K27GA0000AD002000
28895479X6K27GA00002B000500
28895479A6K27GA00002BS000500IWM   0000736800Y
28895482ABK27GA0000UYS000100UWM   0000543500Y
28895482ABK27GA0000UZB000100TWM   0000700900Y
28895482ABK27GA0000V0B000100TWM   0000700800Y
28895485A3K27G600009LB002000DELL  0000194500Y
28895491A1K27GA000081B002000ADI   0000339900Y
28895498A7K27GA00005AB002000LMT   0000279100Y
28895515A3K27G600009MS002000DELL  0000223400Y
28895531A1K27GA000082S002000ADI   0000366800Y
28895542ACK27GA000044B002000WYE   0000107100Y
28895560A4K27GA0000GDB002000ESRX  0000648000Y
28895560A1K27GA000083B002000ADP   0000419300Y
28895569A1K27GA000084B002000AFL   0000169300Y
28895583A2K27G6000076B002000CAG   0000053500Y
28895593A1K27GA000085S002000ADP   0000446600Y
28895613A4K27GA0000GEB002000EIX   0000122900Y
28895619A4K27GA0000GFS002000ESRX  0000735800Y
28895628A1K27GA000086B002000AIG   0000372500Y
28895634A5K27GA000068B002000HMY   0000089700Y
28895654A4K27GA0000GGB002000EXPD  0000444000Y
28895662A1K27GA000087S002000AIG   0000400200Y
28895699A1K27GA000088B002000APA   0001428400Y
28895699A4K27GA0000GHS002000EXPD  0000499400Y
28895719A7K27GA00005BB002000LLY   0000465800Y
28895729A1K27GA000089S002000APA   0001480900Y
28895742A7K27GA00005CB002000MEE   0000624100Y
28895772A7K27GA00005DB002000MER   0000463900Y
28896221XAK27GA00012I002000
28896221XAK27GA0000E6001000
28896221AAK27GA0000E6S001000SPY   0001425700Y
28896221XAK27GA0000O8000500
28896221AAK27GA0000O8S000500SPY   0001425700Y
28896221XAK27GA0000FG000500
28896221AAK27GA0000FGB000500SPY   0001425100Y
28896221XAK27GA0000F7000500
28896221AAK27GA0000F7B000500SPY   0001425100Y
28896221X4K27GA000062000200
28896221A4K27GA000062B000200DIA   0001298400Y
28896223AAK27GA000130S005000SPY   0001426000Y
28896224X3K27G6000090000100
28896224AAK27GA000131S000500SPY   0001425900Y
28896224XAK27GA00012M000500
28896225AAK27GA000132S002500SPY   0001425900Y
28896225XAK27GA00012G005000
28896225XAK27GA00012L002500
28896234X8K27G600004G000500
28896234X8K27G600004H000100
28896238X6K27GA0000AE000500
28896238A6K27GA0000AEB000500IWM   0000736200Y
28896240AAK27GA000133S001000SPY   0001426000Y
28896244X6K27GA0000AE000500
28896244A6K27GA0000AEB000500IWM   0000736600Y
28896246XBK27GA0000US000100
28896246XBK27GA0000UR000100
28896246A6K27GA0000AGB000100IWM   0000736100Y
28896248ABK27GA0000V1S000100TWM   0000702200Y
28896248ABK27GA0000V2B000100UWM   0000542500Y
28896247X6K27GA0000AG000100
28896254X6K27GA0000AE000500
28896254A6K27GA0000AEB000500IWM   0000736200Y
28896258X6K27GA0000AE000500
28896258A6K27GA0000AEB000500IWM   0000736600Y
28896261A4K27GA0000GIB000100DOG   0000597100Y
28896262A3K27G600009NS000100DDM   0000802400Y
28896264X6K27GA0000AE000500
28896264A6K27GA0000AEB000500IWM   0000736200Y
28896266X6K27GA0000AE000500
28896266A6K27GA0000AEB000500IWM   0000736600Y
28896274X6K27GA0000AE000500
28896274A6K27GA0000AEB000500IWM   0000736200Y
28896284X6K27GA0000AE000500
28896284A6K27GA0000AEB000500IWM   0000736600Y
28896285XBK27GA0000V2000100
28896285XBK27GA0000V1000100
28896287ABK27GA0000V3B000100UWM   0000542500Y
28896287ABK27GA0000V4S000100TWM   0000702200Y
28896294X6K27GA0000AE000500
28896294A6K27GA0000AEB000500IWM   0000736200Y
28896304X6K27GA0000AE000500
28896304A6K27GA0000AEB000500IWM   0000736600Y
28896305XBK27GA0000V3000100
28896305XBK27GA0000V4000100
28896307ABK27GA0000V5S000100TWM   0000702200Y
28896307ABK27GA0000V6B000100UWM   0000542500Y
28896314X6K27GA0000AE000500
28896314A6K27GA0000AEB000500IWM   0000736200Y
28896324X6K27GA0000AE000500
28896324A6K27GA0000AEB000500IWM   0000736600Y
28896325XBK27GA0000V6000100
28896325XBK27GA0000V5000100
28896327ABK27GA0000V7B000100UWM   0000542500Y
28896327ABK27GA0000V8S000100TWM   0000702200Y
28896333X9K27G60000O5002000
28896334X6K27GA0000AE000500
28896334A6K27GA0000AEB000500IWM   0000736200Y
28896336A9K27G60000QSS000700QQQQ  0000495800Y
28896344X6K27GA0000AE000500
28896344A6K27GA0000AEB000500IWM   0000736600Y
28896345XBK27GA0000V7000100
28896346XBK27GA0000V8000100
28896347ABK27GA0000V9S000100TWM   0000702400Y
28896350X6K27GA00009D002000
28896354X6K27GA0000AE000500
28896354A6K27GA0000AEB000500IWM   0000736200Y
28896355ABK27GA0000VAB000100UWM   0000542500Y
28896355XBK27GA0000V9000100
28896356ABK27GA0000VBS000100TWM   0000702200Y
28896364X4K27GA0000D5002000
28896364X6K27GA0000AE000500
28896364A6K27GA0000AEB000500IWM   0000736600Y
28896365XBK27GA0000VA000100
28896365XBK27GA0000VB000100
28896367ABK27GA0000VCS000100TWM   0000702400Y
28896374X4K27GA0000EE000200
28896374XAK27GA0000ZM000500
28896374AAK27GA0000ZMS000500SPY   0001425600Y
28896374X6K27GA0000AE000500
28896374A6K27GA0000AEB000500IWM   0000736200Y
28896376XAK27GA00012K001000
28896376AAK27GA000134S001000SPY   0001425600Y
28896376AAK27GA000135B001000SDS   0000547600Y
28896376XAK27GA00012J001000
28896377XBK27GA0000UV001000
28896377ABK27GA0000VDS001000SSO   0000765200Y
28896383A4K27GA0000GJS000200DIA   0001298800Y
28896383AAK27GA000136B001000SPY   0001425100Y
28896386A2K27G6000077B002000BAC   0000347800Y
28896384X6K27GA0000AE000500
28896384A6K27GA0000AEB000500IWM   0000736600Y
28896394X6K27GA0000AE000500
28896394A6K27GA0000AEB000500IWM   0000736200Y
28896404X6K27GA0000AE000500
28896404A6K27GA0000AEB000500IWM   0000736600Y
28896406X7K27GA00005A002000
28896414X6K27GA0000AE000500
28896414A6K27GA0000AEB000500IWM   0000736200Y
28896424X6K27GA0000AE000500
28896424A6K27GA0000AEB000500IWM   0000736600Y
28896434X6K27GA0000AE000500
28896434A6K27GA0000AEB000500IWM   0000736200Y
28896439XCK27GA000044002000
28896444X6K27GA0000AE000500
28896444A6K27GA0000AEB000500IWM   0000736600Y
28896454X6K27GA0000AE000500
28896454A6K27GA0000AEB000500IWM   0000736200Y
28896459A2K27G6000078B002000BMY   0000050400Y
28896459A2K27G6000079S002000BAC   0000372700Y
28896464X6K27GA0000AE000500
28896464A6K27GA0000AEB000500IWM   0000736600Y
28896470A4K27GA0000GKB002000FFIV  0000265500Y
28896474X6K27GA0000AE000500
28896474A6K27GA0000AEB000500IWM   0000736200Y
28896485XAK27GA0000EX000500
28896485AAK27GA0000EXB000500SPY   0001425000Y
28896484X6K27GA0000AE000500
28896484A6K27GA0000AEB000500IWM   0000736600Y
28896487X1K27GA000084002000
28896487AAK27GA000137S000500SPY   0001425800Y
28896488XAK27GA000131000500
28896493X6K27GA0000AE000500
28896493A6K27GA0000AEB000500IWM   0000736200Y
28896496A6K27GA0000AHS002000IWM   0000737100Y
28896507X6K27GA0000A9002000
28896510X2K27G6000075002000
28896519A2K27G600007AS002000BMY   0000234800Y
28896520A4K27GA0000GLS002000FFIV  0000308200Y
28896539ABK27GA0000VEB002000UTX   0000185100Y
28896548A2K27G600007BB002000BRL   0000374100Y
28896559X3K27G600009E002000
28896572A4K27GA0000GMB002000FISV  0000500200Y
28896578A1K27GA00008AB002000ABT   0000139500Y
28896593A4K27GA0000GNS002000FISV  0000543500Y
28896598X4K27GA0000GE002000
28896612X4K27GA0000E2002000
28896621A4K27GA0000GOB002000FITB  0000180200Y
28896623XAK27GA0000EB001000
28896623AAK27GA0000EBB001000SPY   0001425100Y
28896625XAK27GA000132002500
28896625AAK27GA000138S005000SPY   0001425900Y
28896626XAK27GA000130005000
28896631A3K27G600009OB002000CCE   0000192400Y
28896637A9K27G60000QTS002000QQQQ  0000496000Y
28896646X9K27G60000G8002000
28896646A9K27G60000G8B002000QQQQ  0000495200Y
28896645A4K27GA0000GPS002000FITB  0000226600Y
28896666A2K27G600007CS002000BRL   0000424900Y
28896677A3K27G600009PB002000CVS   0000105600Y
28896677A6K27GA0000AIB002000INSP  0000078000Y
28896701A5K27GA000069B002000HNZ   0000113700Y
28896702A2K27G600007DB002000C     0000218600Y
28896713X4K27GA0000E4000100
28896713X4K27GA0000E5000100
28896712A6K27GA0000AJS002000INSP  0000113700Y
28896715A4K27GA0000GQB000100DRYS  0001073400Y
28896715A4K27GA0000GRB000100DRYS  0001073400Y
28896740A5K27GA00006AB002000HOT   0000117700Y
28896741A2K27G600007ES002000C     0000238800Y
28896757A6K27GA0000AKB002000IWN   0000666700Y
28896767A3K27G600009QB002000COF   0000495200Y
28896770A6K27GA0000ALB002000JCI   0000084000Y
28896781A3K27G600009RS002000COF   0000525300Y
28896792A7K27GA00005EB002000MET   0000590700Y
28896791X4K27GA0000GQ000100
28896791A4K27GA0000GQB000100DRYS  0001073500Y
28896791X4K27GA0000GR000100
28896791A4K27GA0000GRB000100DRYS  0001073500Y
28896799A4K27GA0000GSB002000DNA   0000686500Y
28896858AAK27GA000139S002500SPY   0001425900Y
28896875XAK27GA000133001000
28896884X8K27G600004E000500
28896884X8K27G600004F000100
28896964AAK27GA00013AS001000SPY   0001426000Y
28896996XAK27GA00010N002000
28896996X9K27G60000G1002000
28896996A9K27G60000G1S002000QQQQ  0000495800Y
28896996XAK27GA00010Z003000
28896996X4K27GA0000DX000200
28896996A4K27GA0000DXB000200DIA   0001298300Y
28896996XAK27GA000111003000
28896996XAK27GA0000E5001000
28896996AAK27GA0000E5S001000SPY   0001425600Y
28896996XAK27GA00010U003000
28896996XAK27GA0000FD000500
28896996AAK27GA0000FDB000500SPY   0001425000Y
28896996XAK27GA0000O6000500
28896996AAK27GA0000O6S000500SPY   0001425600Y
28896996XAK27GA00010W001000
28896996XAK27GA00010V003000
28896996AAK27GA00013BS003000SPY   0001425700Y
28896996AAK27GA00013CS003000SPY   0001425700Y
28896996XAK27GA00011B001000
28896997AAK27GA00013DS002000SPY   0001425800Y
28896997XAK27GA0000F2000500
28896997AAK27GA0000F2B000500SPY   0001424900Y
28896998AAK27GA00013EB003000SPY   0001424800Y
28896998X4K27GA0000EJ000100
28896998X4K27GA0000EK000100
28896998X3K27G600008R000100
28896998AAK27GA00013FB003000SPY   0001424800Y
28896999XAK27GA00012Y005000
28896999XAK27GA0000F2000500
28896999AAK27GA0000F2B000500SPY   0001425400Y
28896999XAK27GA0000EX000500
28896999AAK27GA0000EXB000500SPY   0001425300Y
28896999XAK27GA00012Z002500
28897000XAK27GA00011U000500
28897001AAK27GA00013GB000500SPY   0001425200Y
28897001XAK27GA0000F2000500
28897001AAK27GA0000F2B000500SPY   0001425000Y
28897001XAK27GA000137000500
28897002XAK27GA0000E4001000
28897002AAK27GA0000E4B001000SPY   0001425000Y
28897002XAK27GA000113001000
28897004AAK27GA00013HB001000SPY   0001425000Y
28897010XAK27GA000116000100
28897011XBK27GA0000UX001000
28897011ABK27GA0000VFB001000SSO   0000764000Y
28897011XBK27GA0000VF001000
28897012XBK27GA0000UW001000
28897012ABK27GA0000VGB001000SSO   0000764200Y
28897013A6K27GA0000AMS002000IWM   0000737000Y
28897020XAK27GA00010X001000
28897020XBK27GA0000VG001000
28897020ABK27GA0000VHB001000SSO   0000763900Y
28897022ABK27GA0000VIB001000SSO   0000764100Y
28897036X9K27G60000PK002000
28897036A4K27GA0000GTS000047DIA   0001298700Y
28897036X4K27GA0000GA000200
28897044XAK27GA00010W001000
28897044AAK27GA00013IB001000SPY   0001425200Y
28897046AAK27GA00013JB001000SPY   0001425200Y
28897051A8K27G600004NB000500MZZ   0000491600Y
28897051A8K27G600004OS000100MVV   0000809300Y
28897052X6K27GA00009G002000
28897052A6K27GA0000ANB002000IWM   0000736000Y
28897053X6K27GA00002A000500
28897053A6K27GA00002AS000500IWM   0000736700Y
28897055ABK27GA0000VJS000100UWM   0000543400Y
28897054X6K27GA00005F000500
28897054A6K27GA00005FB000500IWM   0000736100Y
28897058ABK27GA0000VKB000100TWM   0000701100Y
28897058XBK27GA0000QZ000100
28897058ABK27GA0000VLB000100TWM   0000701000Y
28897059AAK27GA00013KB005000SPY   0001425100Y
28897061X4K27GA0000GC000200
28897061A4K27GA0000GCS000200DIA   0001298600Y
28897061X4K27GA00007C000200
28897061A4K27GA00007CB000200DIA   0001298200Y
28897063A4K27GA0000GUB000100DXD   0000499600Y
28897063X4K27GA0000EN000100
28897063X4K27GA00008X000100
28897064X3K27G600007D000100
28897064A3K27G600009SS000100DDM   0000802200Y
28897064X3K27G600007M000100
28897064XAK27GA0000E4001000
28897064AAK27GA0000E4B001000SPY   0001425400Y
28897064XAK27GA00013H001000
28897064X4K27GA0000GC000200
28897064A4K27GA0000GCS000200DIA   0001298900Y
28897064XAK27GA0000F2000500
28897064AAK27GA0000F2B000500SPY   0001425400Y
28897064AAK27GA00013LB002000SPY   0001425300Y
28897064X4K27GA00007C000200
28897064A4K27GA00007CB000200DIA   0001298500Y
28897064XAK27GA00013D001000
28897064AAK27GA00013MB001000SPY   0001425400Y
28897065X4K27GA0000GT000047
28897066XBK27GA0000QC000100
28897066XBK27GA0000VC000100
28897065AAK27GA00013NS001000SDS   0000549000Y
28897066ABK27GA0000VMB001000SSO   0000764200Y
28897066XBK27GA0000VI001000
28897066A4K27GA0000GVS000100DXD   0000500600Y
28897066A3K27G600009TB000100DDM   0000800700Y
28897066X3K27G600009S000100
28897066A3K27G600009UB000100DDM   0000800800Y
28897066X4K27GA0000GU000100
28897066A4K27GA0000GWS000100DXD   0000500300Y
28897068X8K27G600003P000100
28897068XBK27GA0000VH001000
28897068ABK27GA0000VNB001000SSO   0000764000Y
28897068ABK27GA0000VOS000100TWM   0000702600Y
28897069A8K27G600004PB000100MVV   0000806000Y
28897069A4K27GA0000GXS000200DIA   0001299000Y
28897071A4K27GA0000GYB000100DXD   0000499600Y
28897072A3K27G600009VS000100DDM   0000802200Y
28897072X4K27GA0000GY000100
28897072X3K27G600009V000100
28897150X9K27G60000F7003200
28897150A9K27G60000F7B003200QQQQ  0000495200Y
28897151A9K27G60000QUS002000QQQQ  0000495900Y
28897226AAK27GA00013OS000500SPY   0001425700Y
28897295AAK27GA00013PS002500SPY   0001425700Y
28897296XAK27GA000139002500
28897388XBK27GA0000VE002000
28897409X3K27G600008S002000
28897408A4K27GA0000GZS002000DNA   0000720400Y
28897410XAK27GA00013D001000
28897410AAK27GA00013QS001000SPY   0001425900Y
28897412AAK27GA00013RS001000SPY   0001425900Y
28897417XAK27GA00012O002000
28897417X1K27GA00008A002000
28897424X2K27G6000072002000
28897424XAK27GA00011A001000
28897424XAK27GA00013R001000
28897426X3K27G600009D002000
28897430A6K27GA0000AOS002000IMCL  0000518000Y
28897434X2K27G600006X002000
28897464AAK27GA00013SS001000SPY   0001425900Y
28897467A4K27GA0000H0B002000DVN   0001208500Y
28897468X2K27G6000076002000
28897486X3K27G600009P002000
28897491X4K27GA0000DV002000
28897491A6K27GA0000APB002000ISIL  0000274200Y
28897497XAK27GA0000O6000500
28897497AAK27GA0000O6S000500SPY   0001426000Y
28897497XAK27GA00013B003000
28897497XAK27GA00013E003000
28897497XAK27GA00013C003000
28897497XAK27GA00013F003000
28897497X4K27GA0000DX000200
28897497A4K27GA0000DXB000200DIA   0001298600Y
28897497XAK27GA0000F7000500
28897497AAK27GA0000F7B000500SPY   0001425500Y
28897497XAK27GA0000ZM000500
28897497AAK27GA0000ZMS000500SPY   0001426000Y
28897497AAK27GA00013TB002000SPY   0001425400Y
28897497AAK27GA00013UB002000SPY   0001425300Y
28897498AAK27GA00013VB003000SPY   0001425400Y
28897498AAK27GA00013WB003000SPY   0001425400Y
28897498AAK27GA00013XS003000SPY   0001426400Y
28897498AAK27GA00013YS003000SPY   0001426400Y
28897499AAK27GA00013ZS000100SH    0000618900Y
28897499XAK27GA00013P002500
28897499ABK27GA0000VPB001000SSO   0000764300Y
28897499XBK27GA0000VM001000
28897499A4K27GA0000H1S000100DXD   0000500200Y
28897499A4K27GA0000H2S000100DOG   0000598400Y
28897500A3K27G600009WB000100DDM   0000801000Y
28897500AAK27GA000140B005000SPY   0001425200Y
28897500XAK27GA0000FD000500
28897500AAK27GA0000FDB000500SPY   0001425400Y
28897501XAK27GA00013K005000
28897502XAK27GA00013O000500
28897502AAK27GA000141B000500SPY   0001425400Y
28897502XAK27GA00013G000500
28897506X5K27GA000069002000
28897519XAK27GA00013Q001000
28897519XAK27GA00013S001000
28897520A4K27GA0000H3S002000DVN   0001240600Y
28897520X5K27GA00006A002000
28897521XAK27GA0000E5001000
28897521AAK27GA0000E5S001000SPY   0001426000Y
28897522XBK27GA0000VN001000
28897522ABK27GA0000VQB001000SSO   0000764100Y
28897527X6K27GA00008S002000
28897531X4K27GA0000GI000100
28897532X3K27G600009N000100
28897532X9K27G60000F7003200
28897532A9K27G60000F7B003200QQQQ  0000495700Y
28897533A9K27G60000QVB002000QQQQ  0000495500Y
28897533X6K27GA00005F000500
28897533A6K27GA00005FB000500IWM   0000736500Y
28897535ABK27GA0000VRB000100UWM   0000542400Y
28897536XBK27GA0000VO000100
28897536ABK27GA0000VSS000100TWM   0000702400Y
28897534A6K27GA0000AQS002000ISIL  0000309800Y
28897536X6K27GA00005F000500
28897536A6K27GA00005FB000500IWM   0000736100Y
28897546X6K27GA00005F000500
28897546A6K27GA00005FB000500IWM   0000736500Y
28897549X7K27GA000055002000
28897558A4K27GA0000H4B002000EMR   0000555100Y
28897557A6K27GA0000ARB002000IWM   0000736500Y
28897559A4K27GA0000H5B002000EMR   0000554300Y
28897572X9K27G60000QU002000
28897576A8K27G600004QB000100MVV   0000806100Y
28897580A6K27GA0000ASB002000JNPR  0000274000Y
28897589A4K27GA0000H6S002000EMR   0000602400Y
28897599A6K27GA0000ATS002000JNPR  0000305000Y
28897600X6K27GA00002A000500
28897600A6K27GA00002AS000500IWM   0000737100Y
28897606XBK27GA0000VJ000100
28897606XBK27GA0000VK000100
28897606XBK27GA0000VL000100
28897610A7K27GA00005FB002000LMT   0000285100Y
28897626A5K27GA00006BB002000FNM   0000276200Y
28897632A7K27GA00005GB002000KLAC  0000444200Y
28897638X4K27GA0000GJ000200
28897658A5K27GA00006CS002000FNM   0001545300Y
28897659ACK27GA000045B002000WYE   0000109500Y
28897677A7K27GA00005HS002000KLAC  0000479700Y
28897685A5K27GA00006DB002000GG    0000385600Y
28897697A1K27GA00008BB002000AFL   0000173000Y
28897703X6K27GA0000AM002000
28897709AAK27GA000142B002500SPY   0001425400Y
28897709AAK27GA000143S000500SPY   0001425800Y
28897715X8K27G600004N000500
28897715X8K27G600004O000100
28897714A7K27GA00005IB002000LAMR  0000381700Y
28897722A5K27GA00006ES002000GG    0000436500Y
28897729A2K27G600007FB002000BBT   0000084000Y
28897750A5K27GA00006FB002000GM    0000177400Y
28897753A3K27G600009XB002000COH   0000088400Y
28897785A4K27GA0000H7B002000EIX   0000125700Y
28897806A4K27GA0000H8B002000ELN   0000229200Y
28897845X9K27G60000G1002000
28897845A9K27G60000G1S002000QQQQ  0000496300Y
28898068X6K27GA0000AH002000
28898152A4K27GA0000H9S000200DIA   0001299100Y
28898154AAK27GA000144S002500SPY   0001425900Y
28898301XAK27GA0000EB001000
28898301AAK27GA0000EBB001000SPY   0001425500Y
28898306X9K27G60000G8002000
28898306A9K27G60000G8B002000QQQQ  0000495700Y
28898305AAK27GA000145B002000SPY   0001425500Y
28898305XAK27GA0000NZ000500
28898305AAK27GA0000NZS000500SPY   0001426100Y
28898305XAK27GA000136001000
28898306AAK27GA000146B001000SPY   0001425500Y
28898308XAK27GA000138005000
28898308XAK27GA000143000500
28898308X4K27GA000062000200
28898308A4K27GA000062B000200DIA   0001298700Y
28898308XAK27GA0000O8000500
28898308AAK27GA0000O8S000500SPY   0001426100Y
28898308XAK27GA000134001000
28898308AAK27GA000147S005000SPY   0001426000Y
28898308AAK27GA000148S000500SPY   0001425900Y
28898309XAK27GA0000F5000500
28898309AAK27GA0000F5B000500SPY   0001425500Y
28898310XAK27GA000144002500
28898310AAK27GA000149S001000SPY   0001426000Y
28898310AAK27GA00014AS001000SDS   0000548900Y
28898310XBK27GA0000VP001000
28898311ABK27GA0000VTB001000SSO   0000764400Y
28898311A3K27G600009YB000100DDM   0000801100Y
28898311XAK27GA000147005000
28898311XBK27GA0000VD001000
28898310X6K27GA0000AE000500
28898310A6K27GA0000AEB000500IWM   0000736600Y
28898311A6K27GA0000AUB002000IWM   0000736500Y
28898313ABK27GA0000VUS001000SSO   0000765300Y
28898313ABK27GA0000VVB000100UWM   0000542500Y
28898313ABK27GA0000VWS000100TWM   0000702200Y
28898313XBK27GA0000VS000100
28898314X6K27GA0000AE000500
28898314A6K27GA0000AEB000500IWM   0000736200Y
28898316XAK27GA000148000500
28898320XAK27GA000135001000
28898322XAK27GA00013A001000
28898322AAK27GA00014BS001000SPY   0001426100Y
28898324AAK27GA00014CS001000SPY   0001426100Y
28898326X6K27GA0000AE000500
28898326A6K27GA0000AEB000500IWM   0000736600Y
28898330X9K27G60000QT002000
28898342A6K27GA0000AVB002000IWM   0000736600Y
28898342X6K27GA0000AN002000
28898346X4K27GA000062000200
28898346A4K27GA000062B000200DIA   0001298400Y
28898348X6K27GA00002B000500
28898348A6K27GA00002BS000500IWM   0000737200Y
28898352X3K27G600009Y000100
28898352X4K27GA000062000200
28898352A4K27GA000062B000200DIA   0001298700Y
28898354A3K27G600009ZB000100DDM   0000801100Y
28898355XBK27GA0000UY000100
28898355XBK27GA0000UZ000100
28898355XBK27GA0000V0000100
28898357ABK27GA0000VXB000100TWM   0000700500Y
28898369X4K27GA000062000200
28898369A4K27GA000062B000200DIA   0001298400Y
28898371A8K27G600004RS000500MZZ   0000493800Y
28898371A8K27G600004SB000100MVV   0000806300Y
28898382X3K27G600009Z000100
28898389A4K27GA0000HAS000100DRYS  0001078300Y
28898396X4K27GA000062000200
28898396A4K27GA000062B000200DIA   0001298700Y
28898398A3K27G60000A0B000100DDM   0000801100Y
28898400A3K27G60000A1B002000CELG  0000487800Y
28898401X5K27GA00006C002000
28898411X2K27G6000078002000
28898413XAK27GA00012V002000
28898413X7K27GA00005F002000
28898456XAK27GA0000F5000500
28898456AAK27GA0000F5B000500SPY   0001425600Y
28898457A5K27GA00006GS002000GM    0000229100Y
28898458AAK27GA00014DB002000SHLD  0000757700Y
28898468XCK27GA000045002000
28898483A3K27G60000A2B002000CTSH  0000075600Y
28898484A5K27GA00006HB002000GS    0001818600Y
28898487XAK27GA0000FG000500
28898487AAK27GA0000FGB000500SPY   0001425500Y
28898500X1K27GA00008B002000
28898507A7K27GA00005JS002000LAMR  0000439100Y
28898521AAK27GA00014ES000500SPY   0001426000Y
28898528A5K27GA00006IS002000GS    0001863100Y
28898535X4K27GA0000H7002000
28898544A7K27GA00005KB002000LLTC  0000354600Y
28898556X6K27GA0000AL002000
28898581A6K27GA0000AWB002000IBM   0001246600Y
28898591X7K27GA00003U002000
28898596ABK27GA0000VYB002000UTX   0000189100Y
28898620A1K27GA00008CB002000ABT   0000142600Y
28898619A6K27GA0000AXS002000IBM   0001274700Y
28898628A7K27GA00005LS002000LLTC  0000389200Y
28898646A2K27G600007GB002000AXP   0000412700Y
28898657A7K27GA00005MB002000LNCR  0000236100Y
28898657A6K27GA0000AYB002000JNJ   0000641900Y
28898660AAK27GA00014FS002500SPY   0001426000Y
28898682A2K27G600007HB002000BDX   0000770200Y
28898693A7K27GA00005NS002000LNCR  0000280900Y
28898698A6K27GA0000AZS002000JNJ   0000690800Y
28898717A2K27G600007IB002000CAG   0000055400Y
28898739A7K27GA00005OB002000LPNT  0000204900Y
28898743A7K27GA00005PB002000KSS   0000456700Y
28898756A3K27G60000A3B002000CVS   0000108000Y
28898769AAK27GA00014GB005000SPY   0001425400Y
28898769XAK27GA000140005000
28898771A7K27GA00005QS002000KSS   0000506400Y
28898772A4K27GA0000HBB002000DIS   0000330300Y
28898778A9K27G60000QWS002000QQQQ  0000496000Y
28898785X1K27GA00000V000100
28898785A1K27GA00000VB000100AAPL  0001829900Y
28898788A7K27GA00005RB002000LMT   0000287300Y
28898792A5K27GA00006JB002000HNZ   0000116300Y
28898803A5K27GA00006KB002000HOT   0000120400Y
28898804X1K27GA00000V000100
28898804A1K27GA00000VB000100AAPL  0001830000Y
28898821A6K27GA0000B0B002000KEY   0000212700Y
28898834A7K27GA00005SB002000MDY   0001580900Y
28898854X5K27GA00001A000100
28898856X5K27GA00000Z000100
28898856A5K27GA00006LB000100FXP   0000653600Y
28898862X5K27GA00006L000100
28898862A5K27GA00006MB000100FXP   0000654000Y
28898862X5K27GA00006M000100
28898864A5K27GA00006NB000100FXP   0000653600Y
28899161X7K27GA00005S002000
28899160X6K27GA0000B0002000
28899163X5K27GA00006K002000
28899163X5K27GA00006J002000
28899163X4K27GA0000HB002000
28899164X3K27G60000A3002000
28899164X2K27G600007I002000
28899164X2K27G600007H002000
28899164X2K27G600007G002000
28899164X1K27GA00008C002000
28899165X4K27GA0000H8002000
28899166X3K27G600009X002000
28899165XBK27GA0000VY002000
28899166X2K27G600007F002000
28899166X4K27GA0000H4002000
28899167X7K27GA00005E002000
28899166X6K27GA0000AK002000
28899168X3K27G600009O002000
28899168X7K27GA00005D002000
28899168X7K27GA00005C002000
28899169X7K27GA00005B002000
28899170X5K27GA000068002000
28899170X3K27G600009H002000
28899169XCK27GA000043002000
28899171X7K27GA000059002000
28899171X7K27GA000058002000
28899171X1K27GA00007W002000
28899172X3K27G600008X002000
28899173X4K27GA0000G3002000
28899173X5K27GA000063002000
28899172X6K27GA0000A2002000
28899174X5K27GA000060002000
28899174X7K27GA000053002000
28899174X4K27GA0000G1002000
28899173X6K27GA00009P002000
28899175X4K27GA0000FW002000
28899175X6K27GA00009N002000
28899177X4K27GA0000FK002000
28899178X4K27GA0000FH002000
28899179X2K27G600006I002000
28899179X2K27G600006F002000
28899179XBK27GA0000RR002000
28899180X3K27G6000087002000
28899180X2K27G6000068002000
28899181X2K27G6000064002000
28899180X4K27GA0000FB002000
28899181X2K27G6000062002000
28899181X5K27GA00005D002000
28899180X4K27GA0000F3002000
28899181X1K27GA00006Q002000
28899181X4K27GA0000EY002000
28899181X4K27GA0000EW002000
28899182X7K27GA00004G002000
28899182X6K27GA00008R002000
28899183X7K27GA00004A002000
28899183X1K27GA00006C002000
28899183X7K27GA000043002000
28899184X5K27GA00004W002000
28899184X3K27G600006V002000
28899184X7K27GA00003T002000
28899187X7K27GA00003R002000
28899187X7K27GA00003N002000
28899187X7K27GA00003I002000
28899188X1K27GA00005I002000
28899188X7K27GA000034002000
28899189X5K27GA00003X002000
28899188X6K27GA00006E002000
28899189X7K27GA00002W002000
28899189X1K27GA00004P002000
28899189X6K27GA000062002000
28899189X6K27GA00005O002000
28899189X6K27GA00005M002000
28899189X6K27GA00005L002000
28899190X6K27GA00005I002000
28899192X5K27GA00002I002000
28899192X5K27GA00002C002000
28899192X5K27GA00002A002000
28899195X5K27GA000025002000
28899195X5K27GA000024002000
28899196X5K27GA000023002000
28899196X5K27GA000022002000
28899196X5K27GA000020002000
28899197X5K27GA00001V002000
28899197X5K27GA00001S002000
28899197X5K27GA00001M002000
28899197X4K27GA000075002000
28899197X4K27GA000072002000
28899202X4K27GA00006J002000
28899203X4K27GA00006H002000
28899203X4K27GA000068002000
28899204X4K27GA000060002000
28899204X4K27GA00005Z002000
28899205X4K27GA00005W002000
28899205X4K27GA00005H002000
28899206X3K27G600001W002000
28899206X3K27G600001N002000
28899207X3K27G600001L002000
28899207X3K27G600001K002000
28899207X3K27G600001E002000
28899207X3K27G600001A002000
28899207X3K27G6000018002000
28899208X3K27G6000017002000
28899208X3K27G6000016002000
28899209X3K27G6000015002000
28899210X2K27G600001F002000
28899210X2K27G600001E002000
28899210X2K27G600001B002000
28899211X2K27G6000019002000
28899212X2K27G6000017002000
28899212X2K27G6000015002000
28899213X2K27G600000Z002000
28899213X2K27G600000Y002000
28899214X2K27G600000W002000
28899220X2K27G600000V002000
28899220X2K27G600000N002000
28899219X1K27GA000025002000
28899219X1K27GA000021002000
28899220X1K27GA00001Z002000
28899220X1K27GA00001V002000
28899220X1K27GA00001T002000
28899220X1K27GA00001R002000
28899219XCK27GA00001F002000
28899219XCK27GA00001E002000
28899221XBK27GA00001B002000
28899221XBK27GA00001A002000
28899222X8K27G600000B002000
28899222X8K27G600000A002000
28899222X7K27GA00000V002000
28899222X7K27GA00000S002000
28899222X6K27GA00002L002000
28899225X5K27GA000016002000
28899225X4K27GA000045002000
28899226X3K27G600000J002000
28899227X2K27G600000K002000
28899228X2K27G600000J002000
28899228X1K27GA00001H002000
28899228X1K27GA00001F002000
28899228X1K27GA00001D002000
28899228X1K27GA00001C002000
28899228X1K27GA00001B002000
28899239AAK27GA00014HS005000SPY   0001426200Y
28899464AAK27GA00014IB002000SPLS  0000053000Y
28899464X7K27GA00005R002000
28899532A5K27GA00006OS002000FNM   0001535800Y
28899566A7K27GA00005TS002000LPNT  0000463200Y
28899606A7K27GA00005UB002000LRCX  0000392200Y
28899610A7K27GA00005VS002000LMT   0001128800Y
28899628A7K27GA00005WS002000LRCX  0000428300Y
28899637A7K27GA00005XB002000MDT   0000478800Y
28899646A7K27GA00005YB002000MNST  0000248500Y
28899657A7K27GA00005ZS002000MDT   0000507800Y
28899667A7K27GA000060S002000MNST  0000292300Y
28899676A7K27GA000061B002000MMM   0000764100Y
28899704A8K27G600004TB002000NPSP  0000030200Y
28899716A7K27GA000062S002000MMM   0000816500Y
28899728A8K27G600004US002000NPSP  0000051800Y
28899741A7K27GA000063B002000MO    0000211600Y
28899761A7K27GA000064S002000MO    0000239300Y
28899773A8K27G600004VB002000NBR   0000402800Y
28899785A8K27G600004WS002000NBR   0000429200Y
28899872XAK27GA0000FG000500
28899872AAK27GA0000FGB000500SPY   0001425100Y
28899872XAK27GA0000O8000500
28899872AAK27GA0000O8S000500SPY   0001425700Y
28899916XAK27GA0000F5000500
28899916AAK27GA0000F5B000500SPY   0001425200Y
28899919XAK27GA0000F5000500
28899919AAK27GA0000F5B000500SPY   0001425600Y
28899920XAK27GA00014A001000
28899920XBK27GA0000VT001000
28899921AAK27GA00014JS001000SDS   0000548900Y
28899922ABK27GA0000VZB001000SSO   0000764400Y
28899929XAK27GA0000F5000500
28899929AAK27GA0000F5B000500SPY   0001425200Y
28899939XAK27GA0000F5000500
28899939AAK27GA0000F5B000500SPY   0001425600Y
28899940XAK27GA00014J001000
28899940XBK27GA0000VZ001000
28899941AAK27GA00014KS001000SDS   0000548900Y
28899942ABK27GA0000W0B001000SSO   0000764400Y
28899943XAK27GA0000F5000500
28899943AAK27GA0000F5B000500SPY   0001425200Y
28899945XAK27GA00014K001000
28899945XBK27GA0000W0001000
28899947ABK27GA0000W1B001000SSO   0000764300Y
28899950XAK27GA0000F5000500
28899950AAK27GA0000F5B000500SPY   0001425600Y
28899951AAK27GA00014LS001000SDS   0000548900Y
28899951XBK27GA0000W1001000
28899952ABK27GA0000W2B001000SSO   0000764400Y
28899959XAK27GA0000F5000500
28899959AAK27GA0000F5B000500SPY   0001425200Y
28899969XAK27GA00014L001000
28899970XBK27GA0000W2001000
28899972ABK27GA0000W3B001000SSO   0000764300Y
28899996XAK27GA0000F5000500
28899996AAK27GA0000F5B000500SPY   0001425600Y
28899997AAK27GA00014MS001000SDS   0000548900Y
28899998ABK27GA0000W4B001000SSO   0000764400Y
28899998XBK27GA0000W3001000
28899999XAK27GA0000F5000500
28899999AAK27GA0000F5B000500SPY   0001425200Y
28900010XAK27GA00014M001000
28900010XBK27GA0000W4001000
28900012ABK27GA0000W5B001000SSO   0000764300Y
28900382X5K27GA00006O002000
28900385A7K27GA000065B002000LMT   0000293300Y
28900390A8K27G600004XB002000NTAP  0000246500Y
28900405A8K27G600004YB002000NEM   0000472800Y
28900422A8K27G600004ZS002000NEM   0000504800Y
28900422A8K27G6000050S002000NTAP  0000278000Y
28900435ABK27GA0000W6B002000TGT   0000520000Y
28900436A8K27G6000051B002000NTRS  0000653200Y
28900452A8K27G6000052S002000NTRS  0000783000Y
28900454ABK27GA0000W7S002000TGT   0000627800Y
28900468A8K27G6000053B002000NVTL  0000079900Y
28900469ABK27GA0000W8B002000TXN   0000308400Y
28900490ABK27GA0000W9S002000TXN   0000334300Y
28900491A8K27G6000054S002000NVTL  0000117200Y
28900507ABK27GA0000WAB002000TYC   0000439100Y
28900509A8K27G6000055B002000OSIP  0000340300Y
28900531ABK27GA0000WBS002000TYC   0000495800Y
28900540ABK27GA0000WCB002000UTX   0000192300Y
28900586XAK27GA0000O8000500
28900586AAK27GA0000O8S000500SPY   0001426100Y
28900589XAK27GA0000F5000500
28900589AAK27GA0000F5B000500SPY   0001425600Y
28900591AAK27GA00014NS001000SDS   0000548900Y
28900591XBK27GA0000W5001000
28900591ABK27GA0000WDB001000SSO   0000764400Y
28900859A4K27GA0000HCS000100DRYS  0001078300Y
28901244XAK27GA0000O8000500
28901244AAK27GA0000O8S000500SPY   0001425700Y
28901244XAK27GA0000F5000500
28901244AAK27GA0000F5B000500SPY   0001425200Y
28901246XAK27GA000145002000
28901247AAK27GA00014OS000500SPY   0001425900Y
28901247XAK27GA00014E000500
28901247AAK27GA00014PS002500SPY   0001425900Y
28901247XAK27GA00014F002500
28901247XAK27GA00014G005000
28901247AAK27GA00014QB005000SPY   0001425200Y
28901248XAK27GA00014H005000
28901250XAK27GA00014N001000
28901250AAK27GA00014RS000500SPY   0001426000Y
28901250XBK27GA0000WD001000
28901252ABK27GA0000WEB001000SSO   0000764300Y
28901256AAK27GA00014SB000500SPY   0001425400Y
28901258X6K27GA00002B000500
28901258A6K27GA00002BS000500IWM   0000736800Y
28901261ABK27GA0000WFS000100UWM   0000543500Y
28901261ABK27GA0000WGB000100TWM   0000700800Y
28901261ABK27GA0000WHB000100TWM   0000700900Y
28901261X6K27GA0000AV002000
28901266AAK27GA00014TB000500SPY   0001424900Y
28901269AAK27GA00014UB000500SPY   0001425100Y
28901361AAK27GA00014VB000500SPY   0001424600Y
28901362AAK27GA00014WB000500SPY   0001424400Y
28901373A5K27GA00006PS002000FNM   0001526300Y
28901376X3K27G60000A2002000
28901380X7K27GA000065002000
28901381A8K27G6000056S002000OSIP  0000367000Y
28901388XBK27GA0000WC002000
28901402ABK27GA0000WIS002000UTX   0001657100Y
28901405A8K27G6000057B002000OVTI  0000149700Y
28901434A8K27G6000058B002000PAYX  0000342700Y
28901433ACK27GA000046B002000VZ    0000373800Y
28901454ACK27GA000047S002000VZ    0000407200Y
28901458A8K27G6000059S002000PAYX  0000389000Y
28901486A9K27G60000QXB002000PCAR  0000471200Y
28901488ACK27GA000048B002000WLP   0000500500Y
28901507A9K27G60000QYS002000PCAR  0000532900Y
28901512ACK27GA000049S002000WLP   0000527800Y
28901530A9K27G60000QZB002000PDLI  0000028800Y
28901534ACK27GA00004AB002000WMT   0000539500Y
28901553A9K27G60000R0S002000PDLI  0000106900Y
28901554ACK27GA00004BS002000WMT   0000582000Y
28901588ACK27GA00004CB002000WYE   0000113500Y
28901598ACK27GA00004DS002000WYE   0000473900Y
28901670AAK27GA00014XS005000SPY   0001426000Y
28901709X4K27GA000062000200
28901709A4K27GA000062B000200DIA   0001298400Y
28901711X3K27G60000A0000100
28901718X9K27G60000G8002000
28901718A9K27G60000G8B002000QQQQ  0000495200Y
28901718X6K27GA0000AE000500
28901718A6K27GA0000AEB000500IWM   0000736200Y
28901723AAK27GA00014YS000500SPY   0001426700Y
28901724AAK27GA00014ZS000500SPY   0001427000Y
28901724X6K27GA0000AE000500
28901724A6K27GA0000AEB000500IWM   0000736600Y
28901725XBK27GA0000VV000100
28901726XBK27GA0000VW000100
28901725AAK27GA000150S001000SPY   0001426000Y
28901727X8K27G600004R000500
28901727X8K27G600004S000100
28901727ABK27GA0000WJB000100UWM   0000542500Y
28901727ABK27GA0000WKS000100TWM   0000702200Y
28901729A8K27G600005AS000500MZZ   0000493900Y
28901729A8K27G600005BB000100MVV   0000806200Y
28901728AAK27GA000151S000500SPY   0001426500Y
28901733X6K27GA0000AE000500
28901733A6K27GA0000AEB000500IWM   0000736200Y
28901740AAK27GA000152S000500SPY   0001426200Y
28901754X6K27GA0000AE000500
28901754A6K27GA0000AEB000500IWM   0000736600Y
28901755XBK27GA0000WJ000100
28901755XBK27GA0000WK000100
28901757ABK27GA0000WLB000100UWM   0000542500Y
28901755A6K27GA0000B1B000100IWM   0000736100Y
28901757ABK27GA0000WMS000100TWM   0000702200Y
28901756X6K27GA0000B1000100
28901763X6K27GA0000AE000500
28901763A6K27GA0000AEB000500IWM   0000736200Y
28901774X6K27GA0000AE000500
28901774A6K27GA0000AEB000500IWM   0000736600Y
28901775XBK27GA0000WL000100
28901775XBK27GA0000WM000100
28901777ABK27GA0000WNB000100UWM   0000542500Y
28901777ABK27GA0000WOS000100TWM   0000702200Y
28901784X6K27GA0000AE000500
28901784A6K27GA0000AEB000500IWM   0000736200Y
28901791A4K27GA0000HDB000100DOG   0000597100Y
28901792A3K27G60000A4S000100DDM   0000802400Y
28901792X4K27GA0000H9000200
28901794X6K27GA0000AE000500
28901794A6K27GA0000AEB000500IWM   0000736600Y
28901795XBK27GA0000WN000100
28901795XBK27GA0000WO000100
28901795A6K27GA0000B2B000100IWM   0000736100Y
28901797ABK27GA0000WPB000100UWM   0000542500Y
28901796X6K27GA0000B2000100
28901797ABK27GA0000WQS000100TWM   0000702200Y
28901803X6K27GA0000AE000500
28901803A6K27GA0000AEB000500IWM   0000736200Y
28901814X6K27GA0000AE000500
28901814A6K27GA0000AEB000500IWM   0000736600Y
28901815XBK27GA0000WP000100
28901815XBK27GA0000WQ000100
28901816A4K27GA0000HES000200DIA   0001298800Y
28901817ABK27GA0000WRB000100UWM   0000542500Y
28901817ABK27GA0000WSS000100TWM   0000702200Y
28901823X6K27GA0000AE000500
28901823A6K27GA0000AEB000500IWM   0000736200Y
28901834X6K27GA0000AE000500
28901834A6K27GA0000AEB000500IWM   0000736600Y
28901835XBK27GA0000WR000100
28901835XBK27GA0000WS000100
28901836A6K27GA0000B3B000100IWM   0000736100Y
28901837ABK27GA0000WTS000100TWM   0000702200Y
28901837ABK27GA0000WUB000100UWM   0000542500Y
28901836X6K27GA0000B3000100
28901839AAK27GA000153S000500SPY   0001425800Y
28901840XAK27GA00014O000500
28901843X6K27GA0000AE000500
28901843A6K27GA0000AEB000500IWM   0000736200Y
28901846X6K27GA0000AE000500
28901846A6K27GA0000AEB000500IWM   0000736600Y
28901853X6K27GA0000AE000500
28901853A6K27GA0000AEB000500IWM   0000736200Y
28901859X6K27GA0000AE000500
28901859A6K27GA0000AEB000500IWM   0000736600Y
28901863X6K27GA0000AE000500
28901863A6K27GA0000AEB000500IWM   0000736200Y
28901869X6K27GA0000AE000500
28901869A6K27GA0000AEB000500IWM   0000736600Y
28901873X6K27GA0000AE000500
28901873A6K27GA0000AEB000500IWM   0000736200Y
28901875XBK27GA0000WU000100
28901875XBK27GA0000WT000100
28901875A6K27GA0000B4B000100IWM   0000736100Y
28901875X6K27GA0000B4000100
28901877ABK27GA0000WVS000100TWM   0000702400Y
28901948XAK27GA000149001000
28901948XAK27GA0000NZ000500
28901948AAK27GA0000NZS000500SPY   0001425700Y
28901949AAK27GA000154S001000SPY   0001425600Y
28901949XAK27GA000146001000
28901950AAK27GA000155B001000SDS   0000547600Y
28901951ABK27GA0000WWS001000SSO   0000765200Y
28901951XBK27GA0000VU001000
28901960A6K27GA0000B5S002000IWM   0000737100Y
28901970X6K27GA0000AU002000
28902005X4K27GA0000GQ000100
28902005A4K27GA0000HFB000100DRYS  0001068100Y
28902024AAK27GA000156B001000SPY   0001425100Y
28902024X4K27GA0000HF000100
28902035A4K27GA0000HGB000100DRYS  0001068100Y
28902054X4K27GA0000HG000100
28902064A4K27GA0000HHB000100DRYS  0001075100Y
28902078AAK27GA000157S005000SPY   0001425900Y
28902080XAK27GA00014X005000
28902169X8K27G600005A000500
28902169X8K27G600005B000100
28902186XAK27GA00014S000500
28902188XAK27GA00014W000500
28902188XAK27GA00014V000500
28902188XAK27GA00014U000500
28902188XAK27GA00014T000500
28902202XAK27GA00014R000500
28902202XAK27GA000152000500
28902202XAK27GA000151000500
28902202XAK27GA00014Z000500
28902202XAK27GA00014Y000500
28902348XAK27GA00014D002000
28902367A3K27G60000A5B002000CTSH  0000079000Y
28902367X5K27GA00006P002000
28902395A9K27G60000R1B002000PETM  0000208100Y
28902396XBK27GA0000WI002000
28902406XCK27GA00004C002000
28902419A9K27G60000R2S002000PETM  0000263200Y
28902425A7K27GA000066B002000LMT   0000299300Y
28902437A9K27G60000R3B002000PLCM  0000229800Y
28902440ABK27GA0000WXB002000UTX   0000196300Y
28902441X4K27GA0000HH000100
28902444A1K27GA00008DB002000A     0000345300Y
28902446P4K27GA0000HHB000100DRYS  0001075100000N4AQ00009
28902458A9K27G60000R4S002000PLCM  0000273800Y
28902465X4K27GA0000GR000100
28902465A4K27GA0000HIB000100DRYS  0001070100Y
28902465A1K27GA00008ES002000A     0000372200Y
28902477A9K27G60000R5B002000PSUN  0000087100Y
28902486A1K27GA00008FB002000ABT   0000147800Y
28902498A9K27G60000R6S002000PSUN  0000124900Y
28902515A1K27GA00008GS002000ABT   0000568000Y
28902522AAK27GA000158B002000SBUX  0000158700Y
28902539A1K27GA00008HB002000ABX   0000393000Y
28902556A1K27GA00008IS002000ABX   0000426500Y
28902644A1K27GA00008JB002000ACE   0000586400Y
28902654A1K27GA00008KS002000ACE   0000641400Y
28902663A1K27GA00008LB002000ACF   0000119500Y
28902782X3K27G60000A4000100
28902781X4K27GA0000HD000100
28903082X4K27GA0000HE000200
28903086A4K27GA0000HJS000200DIA   0001299100Y
28903086XAK27GA0000NZ000500
28903086AAK27GA0000NZS000500SPY   0001426100Y
28903086AAK27GA000159B002000SPY   0001425500Y
28903086XAK27GA0000O8000500
28903086AAK27GA0000O8S000500SPY   0001426100Y
28903086XAK27GA0000FG000500
28903086AAK27GA0000FGB000500SPY   0001425500Y
28903086XAK27GA000154001000
28903086XAK27GA000156001000
28903087X4K27GA000062000200
28903087A4K27GA000062B000200DIA   0001298700Y
28903087AAK27GA00015AB001000SPY   0001425500Y
28903087XAK27GA0000F5000500
28903087AAK27GA0000F5B000500SPY   0001425500Y
28903088AAK27GA00015BS001000SPY   0001426000Y
28903088AAK27GA00015CS001000SDS   0000548900Y
28903089XBK27GA0000WE001000
28903089ABK27GA0000WYB001000SSO   0000764400Y
28903089XBK27GA0000WW001000
28903089XAK27GA00014P002500
28903089XAK27GA000157005000
28903089A3K27G60000A6B000100DDM   0000801100Y
28903089AAK27GA00015DS002500SPY   0001426000Y
28903089AAK27GA00015ES005000SPY   0001426200Y
28903090XAK27GA000155001000
28903090XAK27GA000153000500
28903091ABK27GA0000WZS001000SSO   0000765300Y
28903091AAK27GA00015FS000500SPY   0001426000Y
28903100X6K27GA0000B5002000
28903104XAK27GA000150001000
28903110X6K27GA0000AE000500
28903111A6K27GA0000B6B000500IWM   0000736600Y
28903111A6K27GA0000B7B002000IWM   0000736500Y
28903113ABK27GA0000X0B000100UWM   0000542500Y
28903113XBK27GA0000WV000100
28903113ABK27GA0000X1S000100TWM   0000702200Y
28903114X6K27GA0000B6000500
28903114A6K27GA0000B6B000500IWM   0000736200Y
28903119X9K27G60000G8002000
28903119A9K27G60000G8B002000QQQQ  0000495700Y
28903119X4K27GA0000GC000200
28903118X6K27GA0000B6000500
28903118A6K27GA0000B6B000500IWM   0000736600Y
28903121A4K27GA0000HKS000200DIA   0001299200Y
28903146X4K27GA0000HK000200
28903146X4K27GA000062000200
28903146A4K27GA000062B000200DIA   0001298400Y
28903151A4K27GA0000HLS000200DIA   0001298800Y
28903151X4K27GA0000HJ000200
28903152X3K27G60000A6000100
28903152X4K27GA000062000200
28903152A4K27GA000062B000200DIA   0001298700Y
28903154A3K27G60000A7B000100DDM   0000801100Y
28903161X4K27GA0000HL000200
28903161A4K27GA0000HLS000200DIA   0001298900Y
28903163XAK27GA0000F5000500
28903163AAK27GA0000F5B000500SPY   0001425600Y
28903171A4K27GA0000HMS000200DIA   0001299100Y
28903172X4K27GA000062000200
28903172A4K27GA000062B000200DIA   0001298400Y
28903175X4K27GA0000HM000200
28903175A4K27GA0000HNS000047DIA   0001298800Y
28903176X4K27GA000062000200
28903176A4K27GA000062B000200DIA   0001298700Y
28903181X4K27GA0000HN000047
28903188A4K27GA0000HOS000200DIA   0001299100Y
28903311A8K27G600005CS000500MZZ   0000493900Y
28903311A8K27G600005DB000100MVV   0000806200Y
28903371X7K27GA000066002000
28903379XBK27GA0000WX002000
28903383X1K27GA00007X002000
28903386A5K27GA00006QS002000FNM   0001516800Y
28903389X6K27GA00009C002000
28903401XAK27GA00014I002000
28903411X1K27GA00008F002000
28903426X1K27GA00007R002000
28903429AAK27GA00015GB002000SHLD  0000760600Y
28903430ABK27GA0000X2S002000UTX   0001650100Y
28903444AAK27GA00015HS002000SBUX  0000181300Y
28903461ACK27GA00004EB002000WYE   0000115900Y
28903464AAK27GA00015IB002000SEPR  0000177600Y
28903481A1K27GA00008MB002000ACN   0000356600Y
28903487AAK27GA00015JS002000SEPR  0000231000Y
28903502A1K27GA00008NS002000ACN   0000409200Y
28903514AAK27GA00015KB002000SHPGY 0000516500Y
28903530A1K27GA00008OB002000AFL   0000183300Y
28903543AAK27GA00015LS002000SHPGY 0000537800Y
28903557A1K27GA00008PS002000AFL   0001640700Y
28903583A1K27GA00008QB002000ALL   0000483400Y
28903584A1K27GA00008RS002000ALL   0000526000Y
28903591AAK27GA00015MB002000SLAB  0000352200Y
28903595A1K27GA00008SB002000ANF   0000722000Y
28903612AAK27GA00015NS002000SLAB  0000387900Y
28903802XAK27GA00014Q005000
28904359X3K27G60000A1002000
28904360X5K27GA00006Q002000
28904368A1K27GA00008TS002000AMGN  0000484900Y
28904395XBK27GA0000W7002000
28904405A6K27GA0000B8B002000IMCL  0000347600Y
28904406A7K27GA000067B002000LMT   0000305300Y
28904411XBK27GA0000X2002000
28904421XCK27GA00004E002000
28904432AAK27GA00015OB002000SPLS  0000056200Y
28904433ABK27GA0000X3B002000UTX   0000200300Y
28904450A1K27GA00008US002000APOL  0000534200Y
28904453X1K27GA00008O002000
28904457X1K27GA00008P002000
28904472AAK27GA00015PB002000SNDK  0000236100Y
28904480A1K27GA00008VB002000ABT   0000150900Y
28904490A1K27GA00008WS002000ANF   0000773400Y
28904505AAK27GA00015QS002000SNDK  0000313000Y
28904511A1K27GA00008XB002000ANN   0000258600Y
28904512A8K27G600005ES000500MZZ   0000493800Y
28904512A8K27G600005FB000100MVV   0000806300Y
28904533A1K27GA00008YS002000ANN   0000303500Y
28904535ABK27GA0000X4B002000TASR  0000064100Y
28904552ABK27GA0000X5B002000TECD  0000349200Y
28904554A1K27GA00008ZB002000AOC   0000442300Y
28904575ABK27GA0000X6S002000TECD  0000384500Y
28904638A1K27GA000090S002000AOC   0000499700Y
28904647A1K27GA000091B002000APC   0000764300Y
28904656A1K27GA000092S002000APC   0000793700Y
28904665A1K27GA000093B002000ARO   0000297600Y
28904850E5K27GA00006N00010000005AQ00004
28904852A5K27GA00006SB000100FXP   0000652300Y
28905368X7K27GA000067002000
28905368X3K27G60000A5002000
28905382XBK27GA0000X3002000
28905384A3K27G60000A8B002000CELG  0000490300Y
28905389X1K27GA00008V002000
28905399A5K27GA00006TS002000FNM   0001507300Y
28905409ABK27GA0000X7B002000TEVA  0000448200Y
28905415ABK27GA0000X8S002000TGT   0000626400Y
28905427ABK27GA0000X9S002000TEVA  0000487600Y
28905434ABK27GA0000XAS002000UTX   0001643200Y
28905444ACK27GA00004FB002000WYE   0000118300Y
28905456ABK27GA0000XBB002000THQI  0000175300Y
28905462A1K27GA000094B002000AFL   0000187000Y
28905469A1K27GA000095S002000AFL   0001633600Y
28905472ABK27GA0000XCS002000THQI  0000210800Y
28905491ABK27GA0000XDB002000UNTD  0000098500Y
28905496A1K27GA000096S002000ARO   0000369800Y
28905529ABK27GA0000XES002000UNTD  0000140400Y
28905531A2K27G600007JB002000AVP   0000358000Y
28905548ABK27GA0000XFB002000URBN  0000290200Y
28905553A2K27G600007KS002000AVP   0000415200Y
28905570A2K27G600007LB002000AXP   0000413400Y
28905579A2K27G600007MS002000AXP   0000500800Y
28906356A3K27G60000A9B002000CTSH  0000082500Y
28906364X5K27GA00006T002000
28906379XBK27GA0000XA002000
28906381A1K27GA000097B002000AA    0000432300Y
28906397XCK27GA00004F002000
28906402ABK27GA0000XGS002000URBN  0000314800Y
28906402X1K27GA000094002000
28906408X1K27GA000095002000
28906437A7K27GA000068B002000LMT   0000311300Y
28906439A1K27GA000098S002000AA    0000461200Y
28906447ABK27GA0000XHB002000UTSI  0000035700Y
28906488ABK27GA0000XIB002000UTX   0000204300Y
28906486ACK27GA00004GB002000VECO  0000169200Y
28906496A1K27GA000099B002000ADI   0000340700Y
28906510X4K27GA0000HL000200
28906515A4K27GA0000HPS000200DIA   0001298900Y
28906521X4K27GA0000GB000100
28906522X3K27G600009I000100
28906521ACK27GA00004HS002000VECO  0000204900Y
28906527X4K27GA0000HP000200
28906531A4K27GA0000HQS000200DIA   0001299200Y
28906534A1K27GA00009AB002000ABT   0000154000Y
28906542X4K27GA0000HQ000200
28906542X4K27GA000062000200
28906542A4K27GA000062B000200DIA   0001298400Y
28906543A1K27GA00009BS002000ADI   0000366000Y
28906551A4K27GA0000HRS000200DIA   0001298900Y
28906552X3K27G60000A7000100
28906562A3K27G60000AAB000100DDM   0000801100Y
28906561ACK27GA00004IB002000VRSN  0000381200Y
28906570X4K27GA0000HO000200
28906571A4K27GA0000HSS000047DIA   0001298800Y
28906571X3K27G60000AA000100
28906572A3K27G60000ABS000100DDM   0000802500Y
28906572A4K27GA0000HTB000100DXD   0000499500Y
28906577X4K27GA0000HS000047
28906578X4K27GA0000HT000100
28906578X3K27G60000AB000100
28906581A4K27GA0000HUS000200DIA   0001299100Y
28906582A3K27G60000ACB000100DDM   0000801100Y
28906581X4K27GA0000HR000200
28906583A1K27GA00009CB002000ADP   0000420200Y
28906585A1K27GA00009DS002000ADP   0000445800Y
28906591A4K27GA0000HVS000200DIA   0001299200Y
28906594A2K27G600007NB002000AZN   0000420200Y
28906612X4K27GA0000HV000200
28906614A4K27GA0000HWS000200DIA   0001298900Y
28906615A1K27GA00009EB002000AIG   0000373400Y
28906622X3K27G60000AC000100
28906627A2K27G600007OS002000AZN   0000475600Y
28906631A4K27GA0000HXB000100DXD   0000499500Y
28906632A3K27G60000ADS000100DDM   0000802500Y
28906632A3K27G60000AEB000100DDM   0000801100Y
28906631ACK27GA00004JS002000VRSN  0000417400Y
28906638X4K27GA0000HU000200
28906640A4K27GA0000HYS000200DIA   0001298800Y
28906641X4K27GA0000HX000100
28906642X3K27G60000AD000100
28906642X3K27G60000AE000100
28906642X4K27GA0000HY000200
28906643A4K27GA0000HZB000100DXD   0000499500Y
28906643A3K27G60000AFS000100DDM   0000802500Y
28906645A1K27GA00009FS002000AIG   0000399300Y
28906647A4K27GA0000I0S000200DIA   0001299100Y
28906651X4K27GA0000HZ000100
28906651X3K27G60000AF000100
28906651X4K27GA0000HW000200
28906652A3K27G60000AGB000100DDM   0000801100Y
28906654A4K27GA0000I1S000200DIA   0001299200Y
28906660A2K27G600007PB002000BA    0000853900Y
28906671A4K27GA0000I2B000100DXD   0000499500Y
28906671A3K27G60000AHS000100DDM   0000802500Y
28906679A1K27GA00009GB002000APA   0001429200Y
28906680X4K27GA0000I1000200
28906682A2K27G600007QS002000BA    0001678400Y
28906683X4K27GA0000I0000200
28906683A4K27GA0000I3S000200DIA   0001298800Y
28906687A1K27GA00009HS002000APA   0001480100Y
28906690A4K27GA0000I4S000200DIA   0001298900Y
28906691A2K27G600007RB002000BAX   0000587000Y
28906691X3K27G60000AG000100
28906691X4K27GA0000I3000200
28906693X4K27GA0000I2000100
28906694X3K27G60000AH000100
28906701A4K27GA0000I5S000200DIA   0001299100Y
28906701A4K27GA0000I6B000100DXD   0000499500Y
28906701X4K27GA0000I6000100
28906702A3K27G60000AIS000100DDM   0000802500Y
28906702A3K27G60000AJB000100DDM   0000801100Y
28906702X3K27G60000AI000100
28906706X4K27GA0000I5000200
28906707A2K27G600007SS002000BAX   0000639100Y
28906709A4K27GA0000I7S000200DIA   0001298800Y
28906711A4K27GA0000I8B000100DXD   0000499500Y
28906711A3K27G60000AKS000100DDM   0000802500Y
28906711X4K27GA0000I7000200
28906712X3K27G60000AJ000100
28906719A4K27GA0000I9S000200DIA   0001299100Y
28906722A3K27G60000ALB000100DDM   0000801100Y
28906726X4K27GA0000I4000200
28906731A4K27GA0000IAS000200DIA   0001299200Y
28906731X4K27GA0000I8000100
28906732X3K27G60000AK000100
28906738X4K27GA0000IA000200
28906741A4K27GA0000IBS000200DIA   0001298900Y
28906741A4K27GA0000ICB000100DXD   0000499500Y
28906742A3K27G60000AMS000100DDM   0000802500Y
28906751X3K27G60000AL000100
28906754X4K27GA0000IB000200
28906761A4K27GA0000IDS000200DIA   0001299200Y
28906761A3K27G60000ANB000100DDM   0000801100Y
28906761X4K27GA0000IC000100
28906762X3K27G60000AM000100
28906938X4K27GA000062000200
28906938A4K27GA0000IEB000200DIA   0001298700Y
28907344X6K27GA0000AO002000
28907350XAK27GA00015G002000
28907390A2K27G600007TB002000BAC   0000348700Y
28907403X7K27GA000068002000
28907408XBK27GA0000XI002000
28907413A5K27GA00006US002000FNM   0001497700Y
28907425A2K27G600007US002000BAC   0000371900Y
28907434X1K27GA00009A002000
28907445ABK27GA0000XJS002000UTX   0001636300Y
28907449A2K27G600007VB002000BMY   0000057200Y
28907459ACK27GA00004KB002000WYE   0000120700Y
28907473X2K27G600007Q002000
28907473A2K27G600007WS002000BMY   0000234000Y
28907494A1K27GA00009IB002000AFL   0000190800Y
28907498A2K27G600007XB002000C     0000219400Y
28907501A1K27GA00009JS002000AFL   0001626400Y
28907516A2K27G600007YS002000C     0000238000Y
28907518A2K27G600007ZB002000BBT   0000092700Y
28907541A3K27G60000AOB002000COF   0000496000Y
28907541XAK27GA0000E6001000
28907541AAK27GA0000E6S001000SPY   0001426100Y
28907544A2K27G6000080S002000BBT   0001514800Y
28907545XAK27GA00012W001000
28907545XAK27GA00012X001000
28907546AAK27GA00015RB000400SPY   0001425600Y
28907548ABK27GA0000XKB001000SSO   0000764200Y
28907548XBK27GA0000VQ001000
28907548AAK27GA00015SS001000SPY   0001426100Y
28907549XAK27GA0000ZC000100
28907550XBK27GA0000WZ001000
28907552ABK27GA0000XLS001000SSO   0000765500Y
28907561A2K27G6000081B002000BBY   0000423100Y
28907562A3K27G60000APS002000COF   0000524500Y
28907564AAK27GA00015TS002000SPY   0001426000Y
28907564XAK27GA0000QB000500
28907564AAK27GA0000QBS000500SPY   0001426200Y
28907565XAK27GA00010P001000
28907565XAK27GA00010O001000
28907565XAK27GA0000EW000500
28907565XAK27GA0000E9001000
28907565AAK27GA0000E9S001000SPY   0001426200Y
28907565XAK27GA0000E8001000
28907565AAK27GA0000E8B001000SPY   0001425600Y
28907565AAK27GA00015UB001000SPY   0001425600Y
28907565XAK27GA0000NY000500
28907565AAK27GA0000NYS000500SPY   0001426200Y
28907565XAK27GA0000FI000500
28907565AAK27GA0000FIB000500SPY   0001425600Y
28907566AAK27GA00015VS001000SPY   0001426200Y
28907567AAK27GA00015WS001000SDS   0000548800Y
28907567ABK27GA0000XMB001000SSO   0000764500Y
28907567XBK27GA0000WY001000
28907567XAK27GA0000EX000500
28907567AAK27GA0000EXB000500SPY   0001425600Y
28907567XAK27GA000110001000
28907568XAK27GA0000E7001000
28907568AAK27GA0000E7B001000SPY   0001425600Y
28907568XAK27GA00013M001000
28907569AAK27GA00015XB001000SPY   0001425600Y
28907569ABK27GA0000XNB001000SSO   0000764600Y
28907569XBK27GA0000XM001000
28907569AAK27GA00015YS001000SPY   0001426300Y
28907570XAK27GA0000XS001000
28907570XBK27GA0000XL001000
28907570AAK27GA00015ZS000100SH    0000618800Y
28907570AAK27GA000160S001000SDS   0000548700Y
28907571AAK27GA000161B001000SDS   0000547400Y
28907572ABK27GA0000XOS001000SSO   0000765600Y
28907588XAK27GA00015D002500
28907589AAK27GA000162B002500SPY   0001425500Y
28907590XAK27GA000142002500
28907605A4K27GA0000IFB002000DNA   0000687500Y
28907607X4K27GA00007C000200
28907607A4K27GA00007CB000200DIA   0001298800Y
28907608XAK27GA0000ZM000500
28907609A4K27GA0000IGS000100DOG   0000598300Y
28907610A3K27G60000AQB000100DDM   0000801200Y
28907610X3K27G600009T000100
28907609X4K27GA0000GV000100
28907609A4K27GA0000IHS000100DXD   0000500100Y
28907610AAK27GA000163B005000SPY   0001425400Y
28907613XAK27GA000162002500
28907616A4K27GA0000IIS002000DNA   0000719500Y
28907643A2K27G6000082S002000BBY   0000458300Y
28907655A6K27GA0000B9B002000IWM   0000736600Y
28907656X6K27GA00002B000500
28907656A6K27GA00002BS000500IWM   0000737200Y
28907665XBK27GA0000WF000100
28907665XBK27GA0000WG000100
28907665XBK27GA0000WH000100
28907672A2K27G6000083B002000BDX   0000771200Y
28907682A2K27G6000084S002000BDX   0000901100Y
28907687XAK27GA00015U001000
28907687AAK27GA00015UB001000SPY   0001425700Y
28907687XAK27GA0000EX000500
28907687AAK27GA0000EXB000500SPY   0001425700Y
28907687XAK27GA0000E7001000
28907687AAK27GA0000E7B001000SPY   0001425700Y
28907687XAK27GA00015X001000
28907687AAK27GA00015XB001000SPY   0001425700Y
28907690ABK27GA0000XPB001000SSO   0000764700Y
28907690XBK27GA0000XN001000
28907693XAK27GA0000K1001000
28907693AAK27GA0000K1S001000SPY   0001426300Y
28907693X4K27GA0000GX000200
28907693XAK27GA0000O2000500
28907693AAK27GA0000O2S000500SPY   0001426300Y
28907701A4K27GA0000IJS000200DIA   0001299300Y
28907702XAK27GA0000FE000500
28907702AAK27GA0000FEB000500SPY   0001425700Y
28907711A4K27GA0000IKB000100DRYS  0001068100Y
28907798XAK27GA00013I001000
28907798XAK27GA00013J001000
28907798AAK27GA000164B001000SPY   0001425400Y
28908149AAK27GA000165S002500SPY   0001426000Y
28908395XAK27GA00015O002000
28908401A6K27GA0000BAS002000IMCL  0000515500Y
28908408A4K27GA0000ILB002000DVN   0001209300Y
28908430AAK27GA000166B002000SHLD  0000763500Y
28908437A4K27GA0000IMS002000DVN   0001239800Y
28908440X5K27GA00006U002000
28908454XBK27GA0000XJ002000
28908461XCK27GA00004K002000
28908471X1K27GA00009I002000
28908476X1K27GA00009J002000
28908478A4K27GA0000INB002000EMR   0000555500Y
28908484X2K27G6000080002000
28908504A4K27GA0000IOS002000EMR   0000601500Y
28908505A7K27GA000069B002000LMT   0000317300Y
28908520ABK27GA0000XQB002000UTX   0000208300Y
28908525A5K27GA00006VB002000FNM   0000277000Y
28908526A1K27GA00009KB002000ABT   0000157000Y
28908545A2K27G6000085S002000BA    0001672200Y
28908550A5K27GA00006WS002000FNM   0001492200Y
28908558A2K27G6000086B002000BHI   0000842700Y
28908584A9K27G60000R7B000500QQQQ  0000495300Y
28908584A9K27G60000R8B001000QQQQ  0000495300Y
28908585A5K27GA00006XB002000GG    0000386600Y
28908593X1K27GA00000V000100
28908597A5K27GA00006YS002000GG    0000435400Y
28908598P1K27GA00000VB000100AAPL  0001830000000N1AQ00005
28908607A5K27GA00006ZB002000GM    0000179000Y
28908616A5K27GA000070S002000GM    0000227900Y
28908660A2K27G6000087S002000BHI   0000874700Y
28908672A2K27G6000088B002000BJS   0000300300Y
28908682A2K27G6000089S002000BJS   0000328100Y
28908692A2K27G600008AB002000BK    0000427800Y
28908701A2K27G600008BS002000BK    0000477700Y
28908710A2K27G600008CB002000BMC   0000364800Y
28908720X4K27GA0000HA000100
28908720X4K27GA0000HC000100
28909355X3K27G60000A9002000
28909357AAK27GA000167B002000SPLS  0000059300Y
28909405X2K27G600007V002000
28909421X5K27GA00006W002000
28909444A5K27GA000071B002000GS    0001819700Y
28909450X7K27GA000069002000
28909455XBK27GA0000XQ002000
28909460X1K27GA00009K002000
28909469X2K27G6000085002000
28909473X2K27G600007Z002000
28909481A5K27GA000072S002000GS    0001862100Y
28909497A6K27GA0000BBB002000IBM   0001247400Y
28909527A6K27GA0000BCS002000IBM   0001273900Y
28909544A6K27GA0000BDB002000JNJ   0000643100Y
28909560A5K27GA000073S002000FNM   0001488200Y
28909573A6K27GA0000BES002000JNJ   0000689500Y
28909586A7K27GA00006AB002000KSS   0000458000Y
28909605ABK27GA0000XRS002000UTX   0001629400Y
28909606A7K27GA00006BS002000KSS   0000505300Y
28909612ACK27GA00004LB002000WYE   0000123200Y
28909624A7K27GA00006CB002000LMT   0000321100Y
28909627A1K27GA00009LB002000AFL   0000194500Y
28909641A7K27GA00006DS002000LMT   0001128000Y
28909645A1K27GA00009MS002000AFL   0001619200Y
28909654A2K27G600008DS002000BBT   0001505600Y
28909875A4K27GA0000IPS000100DRYS  0001074900Y
28909875A4K27GA0000IQS000100DRYS  0001074900Y
28910367X7K27GA00006C002000
28910395A3K27G60000ARB002000CTSH  0000085900Y
28910404A2K27G600008EB002000BMY   0000059000Y
28910420X5K27GA000073002000
28910449A5K27GA000074S002000FNM   0001482700Y
28910468XBK27GA0000X8002000
28910472XBK27GA0000XR002000
28910477A7K27GA00006EB002000MDT   0000479800Y
28910479XCK27GA00004L002000
28910488X1K27GA00009L002000
28910493X1K27GA00009M002000
28910496X2K27G600007L002000
28910498X9K27G60000QS000700
28910498A9K27G60000R9S001000QID   0000382000Y
28910498A9K27G60000RAB001000QLD   0000889100Y
28910499A9K27G60000RBS001000QID   0000381900Y
28910499X9K27G60000RA001000
28910499A9K27G60000RCB001000QLD   0000889200Y
28910508X2K27G600008D002000
28910512A7K27GA00006FS002000MDT   0000506900Y
28910528A9K27G60000RDB001000QLD   0000889300Y
28910528X9K27G60000RC001000
28910530A9K27G60000REB001000QQQQ  0000495400Y
28910535A7K27GA00006GB002000MMM   0000765100Y
28910536X9K27G60000RE001000
28910561A7K27GA00006HS002000MMM   0000815300Y
28910564A7K27GA00006IB002000LMT   0000323300Y
28910671ABK27GA0000XSB002000UTX   0000212300Y
28910680A1K27GA00009NB002000ABT   0000160100Y
28910686A2K27G600008FS002000BA    0001666000Y
28910691A2K27G600008GB002000BBT   0000095500Y
28910705A2K27G600008HS002000BMC   0000391200Y
28910708A7K27GA00006JB002000MO    0000212400Y
28910724A2K27G600008IB002000BNI   0001061100Y
28910727A7K27GA00006KS002000MO    0000238400Y
28910743A2K27G600008JS002000BNI   0001129800Y
28910748A8K27G600005GB002000NBR   0000403600Y
28910760A2K27G600008KB002000BP    0000738400Y
28910772A8K27G600005HS002000NBR   0000428200Y
28911348X3K27G60000A8002000
28911352X9K27G60000QZ002000
28911386X5K27GA000074002000
28911411X7K27GA00006I002000
28911430A7K27GA00006LB002000LMT   0000327100Y
28911435XBK27GA0000XS002000
28911443A8K27G600005IB002000NEM   0000473600Y
28911443X1K27GA00009N002000
28911451X2K27G600008F002000
28911468A8K27G600005JS002000NEM   0000503800Y
28911482A5K27GA000075S002000FNM   0001478700Y
28911488ABK27GA0000XTB002000TGT   0000521300Y
28911505ABK27GA0000XUS002000TGT   0000624000Y
28911525ABK27GA0000XVB002000TXN   0000309200Y
28911545ABK27GA0000XWS002000TXN   0000333500Y
28911550ABK27GA0000XXS002000TGT   0000624800Y
28911582ABK27GA0000XYB002000TYC   0000439900Y
28911592ABK27GA0000XZS002000TYC   0000495000Y
28911601ABK27GA0000Y0B002000UTX   0000215100Y
28911612ABK27GA0000Y1S002000UTX   0001621700Y
28911634ABK27GA0000Y2S002000UTX   0001622500Y
28911642ACK27GA00004MB002000WYE   0000125600Y
28911651A1K27GA00009OB002000AFL   0000198200Y
28911657A1K27GA00009PS002000AFL   0001612100Y
28911666A2K27G600008LB002000AXP   0000414700Y
28911832X8K27G600004L000500
28911832X8K27G600004M000100
28911835A8K27G600005KS000100MVV   0000809600Y
28911835X8K27G600005K000100
28911841A8K27G600005LS000100MVV   0000809600Y
28912107XAK27GA0000F2000500
28912107AAK27GA0000F2B000500SPY   0001425800Y
28912107XAK27GA0000Z5003000
28912107XAK27GA0000Z4003000
28912107XAK27GA00015T002000
28912107XAK27GA0000NZ000500
28912107XAK27GA0000Z1003000
28912107XAK27GA00014C001000
28912107AAK27GA000168B003000SPY   0001425700Y
28912107XAK27GA0000O6000500
28912107AAK27GA0000O6S000500SPY   0001426400Y
28912107AAK27GA000169B003000SPY   0001425700Y
28912107XAK27GA0000E4001000
28912107AAK27GA0000E4B001000SPY   0001425800Y
28912107AAK27GA00016AB002000SPY   0001425600Y
28912107XAK27GA00013U002000
28912107XAK27GA0000Z3003000
28912109ABK27GA0000Y3B001000SSO   0000764500Y
28912109AAK27GA00016BS003000SPY   0001426600Y
28912109XAK27GA0000FD000500
28912109AAK27GA0000FDB000500SPY   0001425800Y
28912110AAK27GA00016CS003000SPY   0001426600Y
28912110AAK27GA00016DS005000SPY   0001426100Y
28912110XAK27GA000165002500
28912111XAK27GA00015E005000
28912111AAK27GA00016EB002500SPY   0001425600Y
28912111X4K27GA0000ES000100
28912111X4K27GA0000ER000100
28912112X3K27G600007P000100
28912112XAK27GA00015F000500
28912112AAK27GA00016FB000500SPY   0001425600Y
28912113XAK27GA000141000500
28912114A4K27GA0000IRB000100DXD   0000499100Y
28912114A3K27G60000ASS000100DDM   0000802700Y
28912121X6K27GA000099002000
28912124X6K27GA00009T002000
28912124A6K27GA0000BFS002000IWM   0000737700Y
28912132XAK27GA000168003000
28912132AAK27GA00016GS002000SPY   0001426000Y
28912132XAK27GA000169003000
28912132XAK27GA0000E4001000
28912132AAK27GA0000E4B001000SPY   0001425400Y
28912132XAK27GA0000FD000500
28912132AAK27GA0000FDB000500SPY   0001425400Y
28912132XAK27GA0000O6000500
28912132AAK27GA0000O6S000500SPY   0001426000Y
28912133XAK27GA0000F2000500
28912133AAK27GA0000F2B000500SPY   0001425400Y
28912133XAK27GA00016E002500
28912134AAK27GA00016HB003000SPY   0001425600Y
28912134AAK27GA00016IB003000SPY   0001425600Y
28912135XAK27GA00016C003000
28912135XAK27GA00016F000500
28912135XAK27GA00016B003000
28912136AAK27GA00016JS003000SPY   0001426000Y
28912136AAK27GA00016KS003000SPY   0001426000Y
28912141XAK27GA00016A002000
28912141XBK27GA0000Y3001000
28912141A3K27G60000ATS000100DDM   0000802600Y
28912141A4K27GA0000ISB000100DOG   0000597000Y
28912141A4K27GA0000ITB000100DXD   0000499400Y
28912141A4K27GA0000IUS000047DIA   0001299000Y
28912141X4K27GA0000IJ000200
28912141AAK27GA00016LS001000SPY   0001426200Y
28912141XAK27GA00014B001000
28912142X9K27G60000F6003200
28912142A9K27G60000F6S003200QQQQ  0000496400Y
28912142X9K27G60000QN005000
28912142X9K27G60000QJ005000
28912142A9K27G60000RFB005000QQQQ  0000495800Y
28912143A9K27G60000RGB005000QQQQ  0000495800Y
28912143AAK27GA00016MB001000SPY   0001425400Y
28912143A9K27G60000RHB001000QLD   0000889200Y
28912143AAK27GA00016NS001000SPY   0001426200Y
28912144X4K27GA0000IU000047
28912146X6K27GA00007U000500
28912146A6K27GA00007UB000500IWM   0000736700Y
28912148XAK27GA00016K003000
28912148XAK27GA0000O6000500
28912148AAK27GA0000O6S000500SPY   0001426400Y
28912148XAK27GA00016J003000
28912148XAK27GA0000F2000500
28912148AAK27GA0000F2B000500SPY   0001425800Y
28912148A4K27GA0000IVS000200DIA   0001299300Y
28912147A6K27GA0000BGB002000IWM   0000736600Y
28912148AAK27GA00016OB001000SPY   0001425600Y
28912148XAK27GA0000E4001000
28912148AAK27GA0000E4B001000SPY   0001425800Y
28912148XAK27GA00016M001000
28912147X6K27GA00007U000500
28912147A6K27GA00007UB000500IWM   0000736300Y
28912149ABK27GA0000Y4B000100UWM   0000542700Y
28912150ABK27GA0000Y5S000100TWM   0000702000Y
28912150XBK27GA0000X1000100
28912150ABK27GA0000Y6B001000SSO   0000764500Y
28912150AAK27GA00016PS003000SPY   0001426600Y
28912150AAK27GA00016QS003000SPY   0001426600Y
28912151XAK27GA00016G002000
28912151X4K27GA0000IS000100
28912151X4K27GA0000IT000100
28912152X3K27G60000AT000100
28912152X6K27GA00007U000500
28912152A6K27GA00007UB000500IWM   0000736700Y
28912154XBK27GA0000Y4000100
28912154XBK27GA0000Y5000100
28912155ABK27GA0000Y7B000100UWM   0000542700Y
28912155ABK27GA0000Y8S000100TWM   0000702000Y
28912160X6K27GA00007U000500
28912160A6K27GA00007UB000500IWM   0000736300Y
28912164X6K27GA00007U000500
28912164A6K27GA00007UB000500IWM   0000736700Y
28912169X6K27GA00007U000500
28912169A6K27GA00007UB000500IWM   0000736300Y
28912170XAK27GA00016N001000
28912173X6K27GA00007U000500
28912173A6K27GA00007UB000500IWM   0000736700Y
28912175XBK27GA0000Y7000100
28912175XBK27GA0000Y8000100
28912177ABK27GA0000Y9B000100UWM   0000542700Y
28912177ABK27GA0000YAS000100TWM   0000702000Y
28912179X4K27GA0000DX000200
28912179A4K27GA0000DXB000200DIA   0001298800Y
28912184X4K27GA0000DX000200
28912184A4K27GA0000DXB000200DIA   0001298900Y
28912186X4K27GA0000E3000100
28912186A3K27G60000AUB000100DDM   0000801300Y
28912186A4K27GA0000IWS000100DXD   0000500000Y
28912186X3K27G600009U000100
28912222XAK27GA000103000100
28912222AAK27GA00016RB000100SPY   0001424600Y
28912229XAK27GA000161001000
28912231AAK27GA00016SB001000SDS   0000547300Y
28912235XBK27GA0000IW001000
28912282XAK27GA0000FD000500
28912282AAK27GA0000FDB000500SPY   0001425800Y
28912283AAK27GA00016TB001000SPY   0001425600Y
28912289XBK27GA0000XO001000
28912289XAK27GA0000U6000100
28912290AAK27GA00016UB000100SH    0000618100Y
28912291ABK27GA0000YBS001000SSO   0000765700Y
28912311AAK27GA00016VB000100SH    0000618200Y
28912311AAK27GA00016WB001000SDS   0000547400Y
28912311ABK27GA0000YCS001000SSO   0000765600Y
28912311XBK27GA0000YB001000
28912313AAK27GA00016XB000500SPY   0001425600Y
28912324X8K27G600004P000100
28912324A8K27G600005MB000100MVV   0000806400Y
28912326XAK27GA00016T001000
28912341X1K27GA00008T002000
28912370A3K27G60000AVB002000CELG  0000492800Y
28912369X5K27GA000075002000
28912374X2K27G600008E002000
28912414X5K27GA00006F002000
28912429XAK27GA000166002000
28912436X7K27GA00006L002000
28912460X3K27G6000096002000
28912482A5K27GA000076S002000FNM   0001473200Y
28912496XBK27GA0000Y0002000
28912500A9K27G60000RIB002000PDLI  0000031100Y
28912510XBK27GA0000Y1002000
28912511XBK27GA0000Y2002000
28912516X6K27GA000026000500
28912516A6K27GA000026S000500IWM   0000737300Y
28912519A6K27GA0000BHB002000IWM   0000736700Y
28912520X6K27GA00009U002000
28912524XCK27GA00004M002000
28912524X6K27GA000027000500
28912524A6K27GA000027B000500IWM   0000736800Y
28912527ABK27GA0000YDS000100TWM   0000701800Y
28912527ABK27GA0000YEB000100UWM   0000542800Y
28912527XBK27GA0000EN000100
28912527XBK27GA0000YA000100
28912526X6K27GA000027000500
28912526A6K27GA000027B000500IWM   0000736400Y
28912528X6K27GA000027000500
28912528A6K27GA000027B000500IWM   0000736800Y
28912530XBK27GA0000YD000100
28912530XBK27GA0000YE000100
28912532ABK27GA0000YFS000100TWM   0000701800Y
28912532ABK27GA0000YGB000100UWM   0000542800Y
28912533X1K27GA00009O002000
28912533X6K27GA000027000500
28912533A6K27GA000027B000500IWM   0000736400Y
28912535XBK27GA0000J0000100
28912535XBK27GA0000J1000100
28912535XBK27GA0000J2000100
28912534A6K27GA0000BIS002000IWM   0000737300Y
28912537XBK27GA0000YG000100
28912537XBK27GA0000YF000100
28912537ABK27GA0000YHB000100TWM   0000700400Y
28912539ABK27GA0000YIS000100TWM   0000702000Y
28912541X1K27GA00009P002000
28912540X6K27GA000027000500
28912540A6K27GA000027B000500IWM   0000736800Y
28912541A6K27GA0000BJB002000IWM   0000736700Y
28912541X6K27GA00005B002000
28912543ABK27GA0000YJB000100UWM   0000542800Y
28912543ABK27GA0000YKS000100TWM   0000701800Y
28912543XBK27GA0000YI000100
28912544A8K27G600005NS000500MZZ   0000493700Y
28912544X8K27G600004Q000100
28912544A8K27G600005OB000100MVV   0000806500Y
28912560AAK27GA00016YB002500SPY   0001425600Y
28912563X2K27G600008G002000
28912584A9K27G60000RJB002000QQQQ  0000495800Y
28912602X9K27G60000QG005000
28912602X9K27G60000QH005000
28912602X9K27G60000EO002000
28912602A9K27G60000EOB002000QQQQ  0000495800Y
28912602X9K27G60000QI002000
28912603X9K27G60000QW002000
28912603A9K27G60000RKB002000QQQQ  0000495600Y
28912603A9K27G60000RLS005000QQQQ  0000496300Y
28912604A9K27G60000RMS005000QQQQ  0000496300Y
28912608X9K27G60000ET002000
28912608A9K27G60000ETS002000QQQQ  0000496200Y
28912608ACK27GA00004NB002000VZ    0000374600Y
28912611A9K27G60000RNB002000QQQQ  0000495600Y
28912611X6K27GA00006R002000
28912619X2K27G6000083002000
28912619X9K27G60000G3002000
28912619A9K27G60000G3S002000QQQQ  0000496400Y
28912622ACK27GA00004OS002000VZ    0000406200Y
28912629X8K27G600004J000500
28912629X8K27G600005L000100
28912629X8K27G600004K000100
28912630A8K27G600005PB000500MZZ   0000491300Y
28912631A8K27G600005QS000100MVV   0000809800Y
28912641ACK27GA00004PB002000WLP   0000501300Y
28912645X8K27G600003C000500
28912654A7K27GA00006MB002000LMT   0000329300Y
28912662ACK27GA00004QS002000WLP   0000527000Y
28912686X9K27G60000OV000200
28912697ACK27GA00004RB002000WMT   0000540900Y
28912708A9K27G60000ROS002000QQQQ  0000496100Y
28912710ABK27GA0000YLB002000UTX   0000216300Y
28912720ACK27GA00004SS002000WMT   0000580900Y
28912738A1K27GA00009QB002000ABT   0000163100Y
28912738ACK27GA00004TB002000WYE   0000127600Y
28912760A2K27G600008MS002000BA    0001659800Y
28912760ACK27GA00004US002000WYE   0000472500Y
28912779A2K27G600008NS002000BBT   0001491900Y
28912800A2K27G600008OS002000BP    0000760300Y
28912812A2K27G600008PB002000BR    0000190800Y
28912839X9K27G60000F5003200
28912839A9K27G60000F5B003200QQQQ  0000495800Y
28912948X8K27G600005D000100
28912948A8K27G600005RB000100MVV   0000806600Y
28913011AAK27GA00016ZS002500SPY   0001426100Y
28913347A1K27GA00009RS002000AMGN  0000482600Y
28913373X5K27GA000076002000
28913400XAK27GA000167002000
28913401A5K27GA000077S002000FNM   0001469200Y
28913405X7K27GA00006M002000
28913411X3K27G60000AR002000
28913413A2K27G600008QB002000BMY   0000060900Y
28913419XAK27GA00015P002000
28913452A5K27GA000078B002000GM    0000178600Y
28913452AAK27GA000170B002000SHLD  0000766400Y
28913461XCK27GA00004T002000
28913500A3K27G60000AWS002000CMCSK 0000272400Y
28913502XBK27GA0000YL002000
28913526X1K27GA00009Q002000
28913528A7K27GA00006NB002000LMT   0000333100Y
28913542X2K27G600008M002000
28913549X2K27G600008N002000
28913556ABK27GA0000YMB002000UTX   0000219100Y
28913728ABK27GA0000YNS002000UTX   0001614800Y
28913730ABK27GA0000YOS002000UTX   0001615600Y
28913732A1K27GA00009SB002000A     0000346200Y
28913745ACK27GA00004VB002000WYE   0000128000Y
28913750A1K27GA00009TS002000A     0000371400Y
28913757A1K27GA00009UB002000AFL   0000201900Y
28913771A1K27GA00009VS002000AFL   0001604900Y
28913771A1K27GA00009WB002000ABT   0000165500Y
28913796A1K27GA00009XS002000ABT   0000567200Y
28913798A2K27G600008RB002000BBT   0000098400Y
28913813A2K27G600008SB002000BDX   0000772500Y
28913830A1K27GA00009YB002000ABX   0000393800Y
28913850A1K27GA00009ZS002000ABX   0000425700Y
28913860A1K27GA0000A0B002000ACE   0000587200Y
28914200AAK27GA000171S002000SPY   0001426700Y
28914246AAK27GA000172B002000SPY   0001424900Y
28914362X5K27GA000077002000
28914375X7K27GA00006N002000
28914375AAK27GA000173B002000SPLS  0000062400Y
28914395XBK27GA0000YM002000
28914405XBK27GA0000YN002000
28914426XBK27GA0000YO002000
28914432X1K27GA00009W002000
28914457A3K27G60000AXB002000CTSH  0000089300Y
28914458A5K27GA000079S002000FNM   0001463700Y
28914460XAK27GA00016L001000
28914460AAK27GA000174S001000SPY   0001426300Y
28914462AAK27GA000175S001000SPY   0001426300Y
28914466XCK27GA00004V002000
28914470AAK27GA000176S002000SPY   0001426200Y
28914475AAK27GA000177S002000SPY   0001426500Y
28914483AAK27GA000178B002000SPY   0001425400Y
28914484X1K27GA00009U002000
28914484AAK27GA000179B002000SNDK  0000238600Y
28914484AAK27GA00017AB002000SPY   0001425100Y
28914493AAK27GA00017BB001000SPY   0001425600Y
28914499XAK27GA00017B001000
28914505X1K27GA00009V002000
28914520ACK27GA00004WB002000WYE   0000130000Y
28914526A7K27GA00006OB002000LMT   0000335300Y
28914532A1K27GA0000A1S002000ACE   0000640600Y
28914551A1K27GA0000A2B002000ACF   0000120500Y
28914554ABK27GA0000YPB002000UTX   0000220300Y
28914571A1K27GA0000A3B002000ACN   0000357400Y
28914593A1K27GA0000A4S002000ACN   0000407900Y
28914602A1K27GA0000A5B002000ABT   0000166200Y
28914604A1K27GA0000A6B002000AFL   0000204600Y
28914616A2K27G600008TS002000BA    0001653600Y
28914622A1K27GA0000A7S002000AFL   0001600500Y
28914626A2K27G600008US002000BBT   0001482700Y
28914640A1K27GA0000A8B002000ALL   0000484200Y
28914655A2K27G600008VS002000BR    0000248200Y
28914659A1K27GA0000A9S002000ALL   0000524800Y
28914673A2K27G600008WB002000BSX   0000118600Y
28914695A2K27G600008XS002000BSX   0000153200Y
28914715A2K27G600008YB002000CA    0000227900Y
28915162XAK27GA00016R000100
28915162AAK27GA00017CB000100SPY   0001425000Y
28915344X1K27GA00007P002000
28915403X7K27GA00006O002000
28915404X2K27G600008Q002000
28915408XBK27GA0000YP002000
28915422X5K27GA000079002000
28915424X1K27GA0000A5002000
28915441A7K27GA00006PB002000LMT   0000339100Y
28915462X2K27G600008T002000
28915470X2K27G600008R002000
28915473ABK27GA0000YQB002000UTX   0000223100Y
28915479X2K27G600008U002000
28915488A5K27GA00007AS002000FNM   0001459700Y
28915494ABK27GA0000YRS002000UTX   0001607800Y
28915507XCK27GA00004W002000
28915521ABK27GA0000YSS002000UTX   0001608600Y
28915523A1K27GA0000AAB002000ABT   0000168600Y
28915540X1K27GA0000A6002000
28915564X1K27GA0000A7002000
28915572ACK27GA00004XB002000WYE   0000130400Y
28915598A1K27GA0000ABB002000ANF   0000723200Y
28915598A1K27GA0000ACB002000AFL   0000205600Y
28915615A1K27GA0000ADS002000AFL   0001597700Y
28915617A1K27GA0000AES002000ANF   0000772300Y
28915641A1K27GA0000AFB002000ANN   0000259600Y
28915646A2K27G600008ZS002000CA    0000254000Y
28915670A1K27GA0000AGS002000ANN   0000302700Y
28915708A1K27GA0000AHB002000AOC   0000443100Y
28915720A1K27GA0000AIS002000AOC   0000498900Y
28916350X1K27GA00008U002000
28916353A1K27GA0000AJB002000APOL  0000412300Y
28916378A2K27G6000090B002000BMY   0000062700Y
28916378X5K27GA00007A002000
28916413XBK27GA0000XX002000
28916419XBK27GA0000YS002000
28916441A5K27GA00007BS002000FNM   0001454200Y
28916440XCK27GA00004X002000
28916450X1K27GA0000AC002000
28916456X1K27GA0000AD002000
28916461X7K27GA00006P002000
28916474XBK27GA0000XU002000
28916478XBK27GA0000YQ002000
28916479X2K27G600008L002000
28916488XBK27GA0000YR002000
28916495X1K27GA0000AA002000
28916497A7K27GA00006QB002000LMT   0000341300Y
28916506ABK27GA0000YTB002000UTX   0000224300Y
28916508ACK27GA00004YB002000WYE   0000132400Y
28916523A1K27GA0000AKB002000AFL   0000208300Y
28916526A1K27GA0000ALB002000ABT   0000169300Y
28916538A1K27GA0000AMS002000AFL   0001593300Y
28916553A1K27GA0000ANB002000APC   0000765400Y
28916568A1K27GA0000AOS002000APC   0000792900Y
28916579A1K27GA0000APB002000ARO   0000299300Y
28916589A1K27GA0000AQS002000ARO   0000369000Y
28916599A2K27G6000091B002000AVP   0000358800Y
28916642A2K27G6000092S002000BA    0001647500Y
28916647A2K27G6000093B002000BBT   0000101200Y
28916659A2K27G6000094S002000BBT   0001473600Y
28916662A2K27G6000095B002000CAG   0000066300Y
28916672A2K27G6000096S002000CAG   0001439400Y
28916716XAK27GA00016O001000
28916716AAK27GA00017DS002000SPY   0001426100Y
28916716XAK27GA00016H003000
28916716AAK27GA00017ES003000SPY   0001426000Y
28916716AAK27GA00017FS003000SPY   0001426000Y
28916716XAK27GA00016P003000
28916716XAK27GA0000FD000500
28916716AAK27GA0000FDB000500SPY   0001425400Y
28916716XAK27GA0000O6000500
28916716AAK27GA0000O6S000500SPY   0001426000Y
28916716XAK27GA00016I003000
28916717XAK27GA00016Q003000
28916717XAK27GA0000E4001000
28916717AAK27GA0000E4B001000SPY   0001425400Y
28916717XAK27GA0000F2000500
28916717AAK27GA0000F2B000500SPY   0001425400Y
28916717AAK27GA00017GB002000SPY   0001424600Y
28916717AAK27GA00017HS002000SPY   0001427000Y
28916717AAK27GA00017IB002000SPY   0001424400Y
28916717AAK27GA00017JB001000SPY   0001425500Y
28916718XAK27GA00016D005000
28916718AAK27GA00017KB003000SPY   0001425000Y
28916718AAK27GA00017LB003000SPY   0001425000Y
28916719AAK27GA00017MS005000SPY   0001426200Y
28916719XAK27GA00016Y002500
28916719XBK27GA0000Y6001000
28916719XAK27GA00016X000500
28916720AAK27GA00017NS000500SPY   0001426000Y
28916720AAK27GA00017OS002500SPY   0001426000Y
28916720XAK27GA00016Z002500
28916733X9K27G60000G3002000
28916733A9K27G60000G3S002000QQQQ  0000495900Y
28916734X9K27G60000RN002000
28916751X9K27G60000RK002000
28916754A6K27GA0000BKS002000IWM   0000737200Y
28916758XBK27GA0000XP001000
28916760ABK27GA0000YUB001000SSO   0000764600Y
28916776X6K27GA000027000500
28916776A6K27GA000027B000500IWM   0000736400Y
28916785XBK27GA0000YK000100
28916785XBK27GA0000YJ000100
28916786ABK27GA0000YVS000100TWM   0000702000Y
28916802X6K27GA0000BJ002000
28916816A8K27G600005SB000500MZZ   0000491400Y
28916816A8K27G600005TS000100MVV   0000809600Y
28916920AAK27GA00017PB000500SPY   0001425400Y
28917361XAK27GA000170002000
28917361A1K27GA0000ARS002000APOL  0000531900Y
28917364X3K27G60000AX002000
28917364X7K27GA00006Q002000
28917398X5K27GA00007B002000
28917402XBK27GA0000YT002000
28917425XCK27GA00004Y002000
28917446X1K27GA0000AL002000
28917455X1K27GA0000AK002000
28917474X1K27GA0000AM002000
28917480X2K27G6000092002000
28917486X2K27G6000094002000
28917495X2K27G6000096002000
28917495A7K27GA00006RB002000LMT   0000345100Y
28917504A5K27GA00007CS002000FNM   0001450200Y
28917512ABK27GA0000YWS002000TGT   0000622400Y
28917524ABK27GA0000YXS002000TGT   0000623200Y
28917531ABK27GA0000YYB002000UTX   0000227100Y
28917533ABK27GA0000YZS002000UTX   0001601700Y
28917554ABK27GA0000Z0S002000UTX   0001600900Y
28917559ACK27GA00004ZB002000WYE   0000132800Y
28917575A1K27GA0000ASB002000AFL   0000209300Y
28917584A1K27GA0000ATB002000ABT   0000171600Y
28917584A1K27GA0000AUS002000AFL   0001590600Y
28917602A2K27G6000097S002000AVP   0000414400Y
28917621A2K27G6000098B002000AXP   0000416800Y
28917630A2K27G6000099B002000AXP   0000416000Y
28917642A2K27G600009AS002000AXP   0000500000Y
28917661A2K27G600009BB002000AZN   0000421600Y
28917665A2K27G600009CB002000CAH   0000543500Y
28917691A2K27G600009DS002000AZN   0000474700Y
28917710A2K27G600009EB002000BA    0000855000Y
28917745XAK27GA0000F2000500
28917745AAK27GA0000F2B000500SPY   0001425800Y
28917746XAK27GA00017E003000
28917746XAK27GA00017F003000
28917746XAK27GA00017K003000
28917746XAK27GA00017L003000
28917746XAK27GA00017D002000
28917746AAK27GA00017QB003000SPY   0001425600Y
28917746AAK27GA00017RB003000SPY   0001425600Y
28917746XAK27GA000164001000
28917746AAK27GA00017SB002000SPY   0001425600Y
28917746XAK27GA0000E4001000
28917746AAK27GA0000E4B001000SPY   0001425800Y
28917746AAK27GA00017TS002000SPY   0001427200Y
28917747XBK27GA0000YU001000
28917747ABK27GA0000Z1B001000SSO   0000764700Y
28917748AAK27GA00017US002000SPY   0001426200Y
28917748AAK27GA00017VS003000SPY   0001426600Y
28917748AAK27GA00017WS003000SPY   0001426600Y
28917749ABK27GA0000Z2B001000SSO   0000764500Y
28917749AAK27GA00017XS005000SPY   0001426100Y
28917749XAK27GA00017M005000
28917749XAK27GA00017O002500
28917750AAK27GA00017YB002500SPY   0001425600Y
28917751XAK27GA00017N000500
28917751AAK27GA00017ZB000500SPY   0001425600Y
28917751XAK27GA00017P000500
28917754X6K27GA000027000500
28917754A6K27GA000027B000500IWM   0000736800Y
28917755A6K27GA0000BLB002000IWM   0000736700Y
28917758ABK27GA0000Z3B000100UWM   0000542800Y
28917758XBK27GA0000YV000100
28917758ABK27GA0000Z4S000100TWM   0000701800Y
28917758X6K27GA000027000500
28917758A6K27GA000027B000500IWM   0000736400Y
28917761XBK27GA0000Z3000100
28917761XBK27GA0000Z4000100
28917763ABK27GA0000Z5S000100TWM   0000702000Y
28917762X6K27GA000027000500
28917762A6K27GA000027B000500IWM   0000736800Y
28917765ABK27GA0000Z6B000100UWM   0000542800Y
28917765XBK27GA0000Z5000100
28917765ABK27GA0000Z7S000100TWM   0000701800Y
28917766XAK27GA0000E4001000
28917766AAK27GA0000E4B001000SPY   0001425400Y
28917766XAK27GA0000F2000500
28917766AAK27GA0000F2B000500SPY   0001425400Y
28917766X4K27GA0000DX000200
28917766A4K27GA0000DXB000200DIA   0001298600Y
28917767XAK27GA00017S002000
28917768XBK27GA0000Z2001000
28917768X4K27GA0000IW000100
28917769X3K27G60000AU000100
28917769XAK27GA00017W003000
28917769XBK27GA0000Z1001000
28917769XAK27GA00017Y002500
28917769XAK27GA00017V003000
28917769AAK27GA000180S003000SPY   0001426000Y
28917770AAK27GA000181S003000SPY   0001426000Y
28917771ABK27GA0000Z8B001000SSO   0000764600Y
28917773X6K27GA000027000500
28917773A6K27GA000027B000500IWM   0000736400Y
28917776XAK27GA00017Z000500
28917777X6K27GA000027000500
28917777A6K27GA000027B000500IWM   0000736800Y
28917779XAK27GA00017U001000
28917779X6K27GA000027000500
28917779A6K27GA000027B000500IWM   0000736400Y
28917783X6K27GA000027000500
28917783A6K27GA000027B000500IWM   0000736800Y
28917785XBK27GA0000Z6000100
28917785XBK27GA0000Z7000100
28917785X6K27GA000027000500
28917785A6K27GA000027B000500IWM   0000736400Y
28917787ABK27GA0000Z9S000100TWM   0000701800Y
28917787ABK27GA0000ZAB000100UWM   0000542800Y
28917787X6K27GA000027000500
28917787A6K27GA000027B000500IWM   0000736800Y
28917788XBK27GA0000ZA000100
28917788XBK27GA0000Z9000100
28917790ABK27GA0000ZBB000100UWM   0000542800Y
28917790ABK27GA0000ZCS000100TWM   0000701800Y
28917793X6K27GA000027000500
28917793A6K27GA000027B000500IWM   0000736400Y
28917796XBK27GA0000ZC000100
28917796XBK27GA0000ZB000100
28917798ABK27GA0000ZDS000100TWM   0000702000Y
28917798X6K27GA000027000500
28917798A6K27GA000027B000500IWM   0000736800Y
28917800AAK27GA000182B001000SPY   0001425400Y
28917800ABK27GA0000ZEB000100UWM   0000542800Y
28917800XBK27GA0000ZD000100
28917800ABK27GA0000ZFS000100TWM   0000701800Y
28917800XAK27GA00017J001000
28917802AAK27GA000183B001000SPY   0001425400Y
28917803X6K27GA000027000500
28917803A6K27GA000027B000500IWM   0000736400Y
28917804X6K27GA000027000500
28917804A6K27GA000027B000500IWM   0000736800Y
28917806XBK27GA0000ZE000100
28917806XBK27GA0000ZF000100
28917808ABK27GA0000ZGS000100TWM   0000701800Y
28917808ABK27GA0000ZHB000100UWM   0000542800Y
28917810XAK27GA00017U001000
28917811X4K27GA0000DX000200
28917811A4K27GA0000DXB000200DIA   0001298900Y
28917813A4K27GA0000IXS000100DXD   0000500000Y
28917814A3K27G60000AYB000100DDM   0000801300Y
28917813X6K27GA000027000500
28917813A6K27GA000027B000500IWM   0000736400Y
28917823X6K27GA000027000500
28917823A6K27GA000027B000500IWM   0000736800Y
28917824XBK27GA0000ZH000100
28917824XBK27GA0000ZG000100
28917825A6K27GA0000BMB000100IWM   0000736300Y
28917826ABK27GA0000ZIS000100TWM   0000702000Y
28917825X6K27GA0000BM000100
28917833X6K27GA000027000500
28917833A6K27GA000027B000500IWM   0000736400Y
28917835ABK27GA0000ZJS000100TWM   0000701800Y
28917835ABK27GA0000ZKB000100UWM   0000542800Y
28917835XBK27GA0000ZI000100
28917838X6K27GA000027000500
28917838A6K27GA000027B000500IWM   0000736800Y
28917843X6K27GA000027000500
28917843A6K27GA000027B000500IWM   0000736400Y
28917854XBK27GA0000ZK000100
28917855XBK27GA0000ZJ000100
28917855X6K27GA000027000500
28917855A6K27GA000027B000500IWM   0000736800Y
28917855A6K27GA0000BNB000100IWM   0000736300Y
28917855X6K27GA0000BN000100
28917857ABK27GA0000ZLS000100TWM   0000702000Y
28917863X6K27GA000027000500
28917863A6K27GA000027B000500IWM   0000736400Y
28917864ABK27GA0000ZMB000100UWM   0000542800Y
28917865XBK27GA0000ZL000100
28917865ABK27GA0000ZNS000100TWM   0000701800Y
28917873X6K27GA000027000500
28917873A6K27GA000027B000500IWM   0000736800Y
28917875XBK27GA0000ZM000100
28917875XBK27GA0000ZN000100
28917877ABK27GA0000ZOS000100TWM   0000702000Y
28917883X6K27GA000027000500
28917883A6K27GA000027B000500IWM   0000736400Y
28917885ABK27GA0000ZPB000100UWM   0000542800Y
28917885XBK27GA0000ZO000100
28917885ABK27GA0000ZQS000100TWM   0000701800Y
28917887XAK27GA000180003000
28917887XAK27GA000181003000
28917887XAK27GA0000F2000500
28917887AAK27GA0000F2B000500SPY   0001425800Y
28917888AAK27GA000184B001000SPY   0001425600Y
28917888XAK27GA000183001000
28917889XAK27GA0000E4001000
28917889AAK27GA0000E4B001000SPY   0001425800Y
28917889AAK27GA000185S003000SPY   0001426600Y
28917890ABK27GA0000ZRB001000SSO   0000764700Y
28917890XBK27GA0000Z8001000
28917891AAK27GA000186S003000SPY   0001426600Y
28917891ABK27GA0000ZSB001000SSO   0000764500Y
28917893X6K27GA000027000500
28917893A6K27GA000027B000500IWM   0000736800Y
28917894XBK27GA0000ZP000100
28917894XBK27GA0000ZQ000100
28917896ABK27GA0000ZTS000100TWM   0000702000Y
28917901X6K27GA000027000500
28917901A6K27GA000027B000500IWM   0000736400Y
28917902X6K27GA000027000500
28917902A6K27GA000027B000500IWM   0000736800Y
28917910X6K27GA000027000500
28917910A6K27GA000027B000500IWM   0000736400Y
28917914X6K27GA000027000500
28917914A6K27GA000027B000500IWM   0000736800Y
28917919X6K27GA0000BK002000
28917924ABK27GA0000ZUB000100UWM   0000542800Y
28917925ABK27GA0000ZVS000100TWM   0000701800Y
28917925XBK27GA0000ZT000100
28917953AAK27GA000187B000500SPY   0001425600Y
28918103X9K27G60000G3002000
28918103A9K27G60000G3S002000QQQQ  0000496400Y
28918177AAK27GA000188B002500SPY   0001425600Y
28918341X3K27G60000AV002000
28918346X6K27GA0000BA002000
28918361A9K27G60000RPS001000QID   0000381800Y
28918361X9K27G60000PG001000
28918361A9K27G60000RQB001000QLD   0000889500Y
28918362A9K27G60000RRS000100QID   0000382100Y
28918362X9K27G60000RQ001000
28918363A9K27G60000RSB001000QLD   0000889600Y
28918365A9K27G60000RTB001000QQQQ  0000495500Y
28918365A9K27G60000RUB001000QQQQ  0000495400Y
28918374X9K27G60000RT001000
28918374X9K27G60000RU001000
28918409XAK27GA000173002000
28918413X5K27GA00007C002000
28918416X2K27G6000090002000
28918432AAK27GA000189B002000SHLD  0000769300Y
28918444X7K27GA00006R002000
28918445XBK27GA0000YZ002000
28918451XBK27GA0000YY002000
28918458XCK27GA00004Z002000
28918471XBK27GA0000Z0002000
28918476X1K27GA0000AT002000
28918481X1K27GA0000AS002000
28918494X1K27GA0000AU002000
28918496A5K27GA00007DS002000FNM   0001444600Y
28918497A3K27G60000AZB002000CTSH  0000092800Y
28918510X1K27GA000093002000
28918542X2K27G6000093002000
28918551X2K27G6000095002000
28918558ACK27GA000050B002000WYE   0000134800Y
28918567A7K27GA00006SB002000LMT   0000347300Y
28918576A1K27GA0000AVB002000AFL   0000212000Y
28918585ABK27GA0000ZWB002000UTX   0000228300Y
28918596A1K27GA0000AWB002000ABT   0000172300Y
28918605A1K27GA0000AXS002000AFL   0001586200Y
28918635A2K27G600009FS002000BA    0001640500Y
28918652A2K27G600009GS002000BA    0001641300Y
28918655A2K27G600009HB002000BAX   0000587800Y
28918660AAK27GA00018AS002500SPY   0001426100Y
28918662A2K27G600009IS002000BBT   0001464400Y
28918675A2K27G600009JS002000BAX   0000638000Y
28918676A2K27G600009KS002000CAG   0001429600Y
28918693A2K27G600009LB002000BBT   0000103900Y
28918698A2K27G600009MS002000CAH   0000571300Y
28918710A2K27G600009NS002000BBT   0001463600Y
28918715A2K27G600009OB002000CAT   0000819000Y
28919108XAK27GA000128002000
28919349A3K27G60000B0B002000CELG  0000495300Y
28919381X5K27GA00007D002000
28919398X7K27GA00006S002000
28919406XCK27GA000050002000
28919416A6K27GA0000BOS002000IMCL  0000513100Y
28919417XBK27GA0000ZW002000
28919419X1K27GA0000AV002000
28919432X1K27GA0000AX002000
28919432X1K27GA0000AW002000
28919433XAK27GA00012N001000
28919437AAK27GA00018BB000800SPY   0001419800Y
28919442X2K27G600009G002000
28919464X2K27G600009I002000
28919469X2K27G600008S002000
28919470X2K27G600009F002000
28919474X2K27G600009K002000
28919473AAK27GA00018CB002000SPLS  0000065600Y
28919480A5K27GA00007ES002000FNM   0001440700Y
28919491X2K27G600009N002000
28919521A2K27G600009PB002000BMY   0000064500Y
28919541ABK27GA0000ZXS002000UTX   0001594800Y
28919541A7K27GA00006TB002000LMT   0000351100Y
28919554ACK27GA000051B002000WYE   0000135200Y
28919560ABK27GA0000ZYB002000UTX   0000231100Y
28919569A1K27GA0000AYB002000AFL   0000213000Y
28919577A1K27GA0000AZS002000AFL   0001583400Y
28919588A1K27GA0000B0B002000ARO   0000298700Y
28919606ABK27GA0000ZZS002000UTX   0001594000Y
28919624A1K27GA0000B1B002000ABT   0000174700Y
28919629XAK27GA0000E4001000
28919629AAK27GA0000E4B001000SPY   0001425400Y
28919629XAK27GA000186003000
28919629XAK27GA000185003000
28919629XAK27GA0000F2000500
28919629AAK27GA0000F2B000500SPY   0001425400Y
28919630XAK27GA000184001000
28919630AAK27GA00018DS002000SPY   0001426100Y
28919630XAK27GA00017Q003000
28919630XAK27GA00017R003000
28919630AAK27GA00018ES003000SPY   0001426000Y
28919630AAK27GA00018FS003000SPY   0001426000Y
28919632AAK27GA00018GB001000SPY   0001425500Y
28919632XBK27GA0000ZS001000
28919633A2K27G600009QB002000BBT   0000104100Y
28919632AAK27GA00018HB003000SPY   0001425000Y
28919632AAK27GA00018IB003000SPY   0001425000Y
28919633XAK27GA00017X005000
28919633XAK27GA000188002500
28919633AAK27GA00018JS005000SPY   0001426200Y
28919633AAK27GA00018KS002500SPY   0001426000Y
28919634XAK27GA00018A002500
28919634XAK27GA000187000500
28919634AAK27GA00018LS000500SPY   0001426000Y
28919639XBK27GA0000ZR001000
28919640A2K27G600009RB002000BBY   0000424000Y
28919641ABK27GA000100B001000SSO   0000764600Y
28919649A2K27G600009SB002000CAG   0000068300Y
28919658A2K27G600009TS002000BBY   0000457500Y
28919659X9K27G60000G3002000
28919659A9K27G60000G3S002000QQQQ  0000496000Y
28919662X6K27GA000027000500
28919662A6K27GA000027B000500IWM   0000736400Y
28919663A6K27GA0000BPS002000IWM   0000737200Y
28919667X9K27G60000RS001000
28919669A9K27G60000RVB001000QLD   0000889500Y
28919669A9K27G60000RWB001000QQQQ  0000495500Y
28919669A9K27G60000RXB001000QQQQ  0000495400Y
28919674X9K27G60000RW001000
28919674X9K27G60000RX001000
28919673X6K27GA000027000500
28919673A6K27GA000027B000500IWM   0000736800Y
28919674XBK27GA0000ZU000100
28919675XBK27GA0000ZV000100
28919676ABK27GA000101B000100UWM   0000542800Y
28919676ABK27GA000102S000100TWM   0000701800Y
28919680A2K27G600009UB002000BDX   0000774500Y
28919683X6K27GA000027000500
28919683A6K27GA000027B000500IWM   0000736400Y
28919690X6K27GA000027000500
28919690A6K27GA000027B000500IWM   0000736800Y
28919693X6K27GA000027000500
28919693A6K27GA000027B000500IWM   0000736400Y
28919695X6K27GA000027000500
28919695A6K27GA000027B000500IWM   0000736800Y
28919704X6K27GA000027000500
28919704A6K27GA000027B000500IWM   0000736400Y
28919706A2K27G600009VS002000BDX   0000899900Y
28919713X6K27GA000027000500
28919713A6K27GA000027B000500IWM   0000736800Y
28919715XBK27GA000101000100
28919715XBK27GA000102000100
28919715X6K27GA000027000500
28919715A6K27GA000027B000500IWM   0000736400Y
28919717ABK27GA000103B000100UWM   0000542800Y
28919717ABK27GA000104S000100TWM   0000701800Y
28919718A2K27G600009WB002000BHI   0000843500Y
28919723X6K27GA000027000500
28919723A6K27GA000027B000500IWM   0000736800Y
28919727A2K27G600009XS002000BHI   0000873900Y
28919734X6K27GA000027000500
28919734A6K27GA000027B000500IWM   0000736400Y
28919753X6K27GA000027000500
28919753A6K27GA000027B000500IWM   0000736800Y
28919763X6K27GA000027000500
28919763A6K27GA000027B000500IWM   0000736400Y
28919773X6K27GA000027000500
28919773A6K27GA000027B000500IWM   0000736800Y
28919784XBK27GA000103000100
28919784XBK27GA000104000100
28919783X6K27GA000027000500
28919783A6K27GA000027B000500IWM   0000736400Y
28919786ABK27GA000105S000100TWM   0000702000Y
28919794ABK27GA000106B000100UWM   0000542800Y
28919794XBK27GA000105000100
28919795ABK27GA000107S000100TWM   0000701800Y
28919793X6K27GA000027000500
28919793A6K27GA000027B000500IWM   0000736800Y
28919804XBK27GA000106000100
28919804XBK27GA000107000100
28919803X6K27GA000027000500
28919803A6K27GA000027B000500IWM   0000736400Y
28919806ABK27GA000108S000100TWM   0000702000Y
28919814ABK27GA000109B000100UWM   0000542800Y
28919815ABK27GA00010AS000100TWM   0000701800Y
28919815XBK27GA000108000100
28919824XBK27GA000109000100
28919824XBK27GA00010A000100
28919826ABK27GA00010BS000100TWM   0000702000Y
28919858AAK27GA00018MB000500SPY   0001425400Y
28920153X6K27GA000027000500
28920154A6K27GA0000BQB000500IWM   0000736300Y
28920163X6K27GA0000BQ000500
28920163A6K27GA0000BQB000500IWM   0000736400Y
28920173X6K27GA0000BQ000500
28920173A6K27GA0000BQB000500IWM   0000736800Y
28920176ABK27GA00010CB000100UWM   0000542800Y
28920176XBK27GA00010B000100
28920176ABK27GA00010DS000100TWM   0000701800Y
28920183X6K27GA0000BQ000500
28920183A6K27GA0000BQB000500IWM   0000736400Y
28920186XBK27GA00010C000100
28920186XBK27GA00010D000100
28920186A6K27GA0000BRB000100IWM   0000736300Y
28920188ABK27GA00010ES000100TWM   0000702000Y
28920186X6K27GA0000BR000100
28920187X6K27GA0000BQ000500
28920187A6K27GA0000BQB000500IWM   0000736800Y
28920190ABK27GA00010FB000100UWM   0000542800Y
28920189X6K27GA0000BQ000500
28920189A6K27GA0000BQB000500IWM   0000736400Y
28920191ABK27GA00010GS000100TWM   0000701800Y
28920191XBK27GA00010E000100
28920193XBK27GA00010G000100
28920193XBK27GA00010F000100
28920194ABK27GA00010HS000100TWM   0000702000Y
28920193A6K27GA0000BSB000100IWM   0000736300Y
28920193X6K27GA0000BS000100
28920193X6K27GA0000BQ000500
28920193A6K27GA0000BQB000500IWM   0000736800Y
28920197ABK27GA00010IB000100UWM   0000542800Y
28920197XBK27GA00010H000100
28920197ABK27GA00010JS000100TWM   0000701800Y
28920196X6K27GA0000BQ000500
28920196A6K27GA0000BQB000500IWM   0000736400Y
28920199XBK27GA00010I000100
28920199XBK27GA00010J000100
28920199A6K27GA0000BTB000100IWM   0000736300Y
28920201ABK27GA00010KS000100TWM   0000702000Y
28920199X6K27GA0000BT000100
28920203X6K27GA0000BQ000500
28920203A6K27GA0000BQB000500IWM   0000736800Y
28920207ABK27GA00010LB000100UWM   0000542800Y
28920207ABK27GA00010MS000100TWM   0000701800Y
28920207XBK27GA00010K000100
28920213X6K27GA0000BQ000500
28920213A6K27GA0000BQB000500IWM   0000736400Y
28920217XBK27GA00010L000100
28920217XBK27GA00010M000100
28920219ABK27GA00010NS000100TWM   0000702000Y
28920223X6K27GA0000BQ000500
28920223A6K27GA0000BQB000500IWM   0000736800Y
28920227ABK27GA00010OB000100UWM   0000542800Y
28920227ABK27GA00010PS000100TWM   0000701800Y
28920227XBK27GA00010N000100
28920234X6K27GA0000BQ000500
28920234A6K27GA0000BQB000500IWM   0000736400Y
28920237XBK27GA00010P000100
28920237XBK27GA00010O000100
28920239ABK27GA00010QS000100TWM   0000702000Y
28920243X6K27GA0000BQ000500
28920243A6K27GA0000BQB000500IWM   0000736800Y
28920247ABK27GA00010RB000100UWM   0000542800Y
28920247XBK27GA00010Q000100
28920247ABK27GA00010SS000100TWM   0000701800Y
28920255X6K27GA0000BQ000500
28920255A6K27GA0000BQB000500IWM   0000736400Y
28920259XBK27GA00010R000100
28920259XBK27GA00010S000100
28920261ABK27GA00010TS000100TWM   0000702000Y
28920263X6K27GA0000BQ000500
28920263A6K27GA0000BQB000500IWM   0000736800Y
28920267ABK27GA00010UB000100UWM   0000542800Y
28920267ABK27GA00010VS000100TWM   0000701800Y
28920267XBK27GA00010T000100
28920273X6K27GA0000BQ000500
28920273A6K27GA0000BQB000500IWM   0000736400Y
28920276XBK27GA00010U000100
28920276XBK27GA00010V000100
28920278ABK27GA00010WS000100TWM   0000702000Y
28920277X6K27GA0000BQ000500
28920277A6K27GA0000BQB000500IWM   0000736800Y
28920279X6K27GA0000BQ000500
28920279A6K27GA0000BQB000500IWM   0000736400Y
28920283X6K27GA0000BQ000500
28920283A6K27GA0000BQB000500IWM   0000736800Y
28920293X6K27GA0000BQ000500
28920293A6K27GA0000BQB000500IWM   0000736400Y
28920303X6K27GA0000BQ000500
28920303A6K27GA0000BQB000500IWM   0000736800Y
28920305X6K27GA0000BQ000500
28920305A6K27GA0000BQB000500IWM   0000736400Y
28920313X6K27GA0000BQ000500
28920313A6K27GA0000BQB000500IWM   0000736800Y
28920323X6K27GA0000BQ000500
28920323A6K27GA0000BQB000500IWM   0000736400Y
28920343X6K27GA0000B8002000
28920347X7K27GA00005O002000
28920384X5K27GA00007E002000
28920387XBK27GA0000ZX002000
28920393XCK27GA000051002000
28920398XCK27GA00004D002000
28920403X1K27GA0000AY002000
28920407X1K27GA0000AZ002000
28920429A7K27GA00006UB002000LMT   0000353300Y
28920436ABK27GA00010XB002000UTX   0000232300Y
28920441A1K27GA0000B2B002000ABT   0000175400Y
28920455A2K27G600009YS002000BA    0001635100Y
28920466A2K27G600009ZS002000BBT   0001455200Y
28920473A2K27G60000A0B002000BDX   0000773900Y
28920483A2K27G60000A1S002000CAG   0001419900Y
28920490A2K27G60000A2S002000CAT   0000868300Y
28920507X7K27GA00006T002000
28920511A3K27G60000B1B002000CCE   0000192600Y
28920526XBK27GA0000ZY002000
28920537XBK27GA0000ZZ002000
28920549X1K27GA0000B1002000
28920551A3K27G60000B2S002000CCE   0000241000Y
28920559A5K27GA00007FS002000FNM   0001435100Y
28920572A3K27G60000B3B002000CCL   0000380300Y
28920581X2K27G600009L002000
28920594ACK27GA000052B002000WYE   0000137300Y
28920616A1K27GA0000B3B002000AFL   0000215700Y
28920629A1K27GA0000B4S002000AFL   0001579000Y
28920639A2K27G60000A3S002000BA    0001634300Y
28920648A2K27G60000A4S002000BBT   0001454400Y
28920657X6K27GA0000BQ000500
28920657A6K27GA0000BQB000500IWM   0000736800Y
28920658X6K27GA0000BP002000
28920660ABK27GA00010YB000100UWM   0000542800Y
28920660XBK27GA00010W000100
28920660ABK27GA00010ZS000100TWM   0000701800Y
28920664A2K27G60000A5B002000BJS   0000301100Y
28920663X6K27GA0000BQ000500
28920663A6K27GA0000BQB000500IWM   0000736400Y
28920673A2K27G60000A6S002000BJS   0000327300Y
28920673X6K27GA0000BQ000500
28920673A6K27GA0000BQB000500IWM   0000736800Y
28920674XBK27GA00010Y000100
28920674XBK27GA00010Z000100
28920676ABK27GA000110B000100UWM   0000542800Y
28920675A6K27GA0000BUB000100IWM   0000736300Y
28920675X6K27GA0000BU000100
28920676ABK27GA000111S000100TWM   0000701800Y
28920676X6K27GA0000BQ000500
28920676A6K27GA0000BQB000500IWM   0000736400Y
28920682A2K27G60000A7B002000BK    0000429300Y
28920683X6K27GA0000BQ000500
28920683A6K27GA0000BQB000500IWM   0000736800Y
28920685XBK27GA000110000100
28920685XBK27GA000111000100
28920687ABK27GA000112B000100UWM   0000542800Y
28920685A6K27GA0000BVB000100IWM   0000736300Y
28920687ABK27GA000113S000100TWM   0000701800Y
28920686X6K27GA0000BV000100
28920692A2K27G60000A8S002000BK    0000476300Y
28920693X6K27GA0000BQ000500
28920693A6K27GA0000BQB000500IWM   0000736400Y
28920697A6K27GA0000BWS002000IWM   0000737200Y
28920704XBK27GA000112000100
28920704XBK27GA000113000100
28920705A6K27GA0000BXB000100IWM   0000736300Y
28920706ABK27GA000114S000100TWM   0000702000Y
28920705X6K27GA0000BX000100
28921172XAK27GA00018D002000
28921172AAK27GA00018NB002000SPY   0001425600Y
28921172XAK27GA000182001000
28921172XAK27GA00018F003000
28921172XAK27GA00018H003000
28921173XAK27GA0000F2000500
28921173AAK27GA0000F2B000500SPY   0001425800Y
28921173XAK27GA00018I003000
28921173AAK27GA00018OB003000SPY   0001425600Y
28921173XAK27GA0000E4001000
28921173AAK27GA0000E4B001000SPY   0001425800Y
28921173XAK27GA00018E003000
28921173AAK27GA00018PB003000SPY   0001425600Y
28921174AAK27GA00018QS002000SPY   0001426200Y
28921174ABK27GA000115B001000SSO   0000764700Y
28921174XBK27GA000100001000
28921176AAK27GA00018RS003000SPY   0001426600Y
28921176AAK27GA00018SS003000SPY   0001426600Y
28921176AAK27GA00018TS005000SPY   0001426100Y
28921176XAK27GA00018J005000
28921177ABK27GA000116B001000SSO   0000764500Y
28921177XAK27GA00018K002500
28921177XAK27GA00018L000500
28921177AAK27GA00018UB002500SPY   0001425600Y
28921178AAK27GA00018VB000500SPY   0001425600Y
28921178XAK27GA00018M000500
28921181X6K27GA0000BQ000500
28921181A6K27GA0000BQB000500IWM   0000736800Y
28921181X6K27GA0000BW002000
28921183X6K27GA0000BQ000500
28921183A6K27GA0000BQB000500IWM   0000736400Y
28921184X9K27G60000G3002000
28921184A9K27G60000G3S002000QQQQ  0000496400Y
28921184ABK27GA000117B000100UWM   0000542800Y
28921184XBK27GA000114000100
28921184ABK27GA000118S000100TWM   0000701800Y
28921186XBK27GA000118000100
28921186XBK27GA000117000100
28921188ABK27GA000119S000100TWM   0000702000Y
28921187X6K27GA0000BQ000500
28921187A6K27GA0000BQB000500IWM   0000736800Y
28921190ABK27GA00011AB000100UWM   0000542800Y
28921190XBK27GA000119000100
28921190ABK27GA00011BS000100TWM   0000701800Y
28921189X6K27GA0000BQ000500
28921189A6K27GA0000BQB000500IWM   0000736400Y
28921192X9K27G60000RV001000
28921192A9K27G60000RYB001000QLD   0000889600Y
28921192XBK27GA00011A000100
28921192XBK27GA00011B000100
28921194ABK27GA00011CB000100UWM   0000542800Y
28921195ABK27GA00011DS000100TWM   0000701800Y
28921193X6K27GA0000BQ000500
28921193A6K27GA0000BQB000500IWM   0000736800Y
28921195A9K27G60000RZB001000QQQQ  0000495500Y
28921195A9K27G60000S0B001000QQQQ  0000495400Y
28921198X6K27GA0000BQ000500
28921198A6K27GA0000BQB000500IWM   0000736400Y
28921199XAK27GA00018Q001000
28921202XAK27GA0000E4001000
28921202AAK27GA0000E4B001000SPY   0001425400Y
28921202XAK27GA0000F2000500
28921202AAK27GA0000F2B000500SPY   0001425400Y
28921202X4K27GA0000DX000200
28921202A4K27GA0000DXB000200DIA   0001298600Y
28921203XAK27GA00018N002000
28921204X9K27G60000S0001000
28921204X9K27G60000RZ001000
28921204XAK27GA00018R003000
28921204XAK27GA00018S003000
28921204XAK27GA00018U002500
28921204AAK27GA00018WS003000SPY   0001426000Y
28921205XBK27GA000116001000
28921205X3K27G60000AY000100
28921204AAK27GA00018XS003000SPY   0001426000Y
28921204X4K27GA0000IX000100
28921203X6K27GA0000BQ000500
28921203A6K27GA0000BQB000500IWM   0000736800Y
28921206XAK27GA00018V000500
28921209XBK27GA000115001000
28921211ABK27GA00011EB001000SSO   0000764600Y
28921213X6K27GA0000BQ000500
28921213A6K27GA0000BQB000500IWM   0000736400Y
28921217XAK27GA00018Q001000
28921216X6K27GA0000BQ000500
28921216A6K27GA0000BQB000500IWM   0000736800Y
28921218XBK27GA00011C000100
28921219XBK27GA00011D000100
28921220ABK27GA00011FB000100UWM   0000542800Y
28921220ABK27GA00011GS000100TWM   0000701800Y
28921220X6K27GA0000BQ000500
28921220A6K27GA0000BQB000500IWM   0000736400Y
28921223X6K27GA0000BQ000500
28921223A6K27GA0000BQB000500IWM   0000736800Y
28921232XAK27GA00018G001000
28921232AAK27GA00018YB001000SPY   0001425400Y
28921234X6K27GA0000BQ000500
28921234A6K27GA0000BQB000500IWM   0000736400Y
28921236AAK27GA00018ZB001000SPY   0001425400Y
28921242X6K27GA0000BQ000500
28921242A6K27GA0000BQB000500IWM   0000736800Y
28921243XBK27GA00011F000100
28921243XBK27GA00011G000100
28921245ABK27GA00011HB000100UWM   0000542800Y
28921245ABK27GA00011IS000100TWM   0000701800Y
28921245X6K27GA00009Q002000
28921245A6K27GA0000BYS002000IWM   0000737800Y
28921246X6K27GA0000BQ000500
28921246A6K27GA0000BQB000500IWM   0000736400Y
28921249X9K27G60000RY001000
28921251A9K27G60000S1B001000QLD   0000889500Y
28921251A9K27G60000S2B001000QQQQ  0000495400Y
28921251A9K27G60000S3B001000QQQQ  0000495500Y
28921251X6K27GA0000BQ000500
28921251A6K27GA0000BQB000500IWM   0000736800Y
28921253X9K27G60000G3002000
28921253A9K27G60000G3S002000QQQQ  0000496000Y
28921254X9K27G60000S3001000
28921254X9K27G60000S2001000
28921253X6K27GA0000BQ000500
28921253A6K27GA0000BQB000500IWM   0000736400Y
28921254XAK27GA00018Z001000
28921261X6K27GA0000BQ000500
28921261A6K27GA0000BQB000500IWM   0000736800Y
28921263AAK27GA000190B001000SPY   0001425400Y
28921263X6K27GA0000BQ000500
28921263A6K27GA0000BQB000500IWM   0000736400Y
28921264XBK27GA00011H000100
28921264XBK27GA00011I000100
28921266ABK27GA00011JS000100TWM   0000702000Y
28921265X6K27GA0000BQ000500
28921265A6K27GA0000BQB000500IWM   0000736800Y
28921273X6K27GA0000BQ000500
28921273A6K27GA0000BQB000500IWM   0000736400Y
28921283X6K27GA0000BQ000500
28921283A6K27GA0000BQB000500IWM   0000736800Y
28921284ABK27GA00011KB000100UWM   0000542800Y
28921284ABK27GA00011LS000100TWM   0000701800Y
28921284XBK27GA00011J000100
28921293X6K27GA0000BQ000500
28921293A6K27GA0000BQB000500IWM   0000736400Y
28921294XBK27GA00011K000100
28921294XBK27GA00011L000100
28921296ABK27GA00011MS000100TWM   0000702000Y
28921314ABK27GA00011NB000100UWM   0000542800Y
28921314XBK27GA00011M000100
28921314ABK27GA00011OS000100TWM   0000701800Y
28921324XBK27GA00011N000100
28921324XBK27GA00011O000100
28921326ABK27GA00011PS000100TWM   0000702000Y
28921344ABK27GA00011QB000100UWM   0000542800Y
28921344ABK27GA00011RS000100TWM   0000701800Y
28921344XBK27GA00011P000100
28921354XBK27GA00011Q000100
28921355XBK27GA00011R000100
28921356ABK27GA00011SS000100TWM   0000702000Y
28921375ABK27GA00011TB000100UWM   0000542800Y
28921375XBK27GA00011S000100
28921375ABK27GA00011US000100TWM   0000701800Y
28921382AAK27GA000191B000500SPY   0001425400Y
28921384XBK27GA00011T000100
28921384XBK27GA00011U000100
28921386ABK27GA00011VS000100TWM   0000702000Y
28921385A6K27GA0000BZB002000IMCL  0000349800Y
28921389X2K27G600007B002000
28921389X2K27G600009P002000
28921392X3K27G60000AZ002000
28921404ABK27GA00011WB000100UWM   0000542800Y
28921405XBK27GA00011V000100
28921405ABK27GA00011XS000100TWM   0000701800Y
28921413X7K27GA00006U002000
28921413X5K27GA00007F002000
28921414XBK27GA00011W000100
28921414XBK27GA00011X000100
28921416XBK27GA00010X002000
28921416ABK27GA00011YS000100TWM   0000702000Y
28921422XCK27GA00004A002000
28921430XCK27GA000052002000
28921434X1K27GA0000B2002000
28921438X1K27GA0000B3002000
28921439X2K27G600009Y002000
28921449A7K27GA00006VB002000LPNT  0000207100Y
28921449X1K27GA0000B4002000
28921450X2K27G600009Q002000
28921460X2K27G60000A3002000
28921460X2K27G600009Z002000
28921492X2K27G600009S002000
28921496X2K27G60000A1002000
28921503A5K27GA00007GS002000FNM   0001431200Y
28921505X2K27G60000A4002000
28921517A7K27GA00006WB002000LMT   0000357100Y
28921531ABK27GA00011ZS002000UTX   0001587900Y
28921535ABK27GA000120B002000UTX   0000235100Y
28921549ABK27GA000121S002000UTX   0001587100Y
28921548ACK27GA000053B002000WYE   0000137700Y
28921561ACK27GA000054S002000WYE   0000472800Y
28921585A1K27GA0000B5B002000ABT   0000177800Y
28921585A1K27GA0000B6B002000AFL   0000216700Y
28921590A2K27G60000A9B002000BBT   0000106800Y
28921598AAK27GA000192S002500SPY   0001426100Y
28921602A1K27GA0000B7S002000AFL   0001576200Y
28921625A2K27G60000AAB002000BMC   0000365700Y
28921633X6K27GA0000BQ000500
28921633A6K27GA0000C0B000500IWM   0000736300Y
28921636X6K27GA0000C0000500
28921636A6K27GA0000C0B000500IWM   0000736400Y
28921643X6K27GA0000C0000500
28921643A6K27GA0000C0B000500IWM   0000736800Y
28921646ABK27GA000122B000100UWM   0000542800Y
28921646XBK27GA00011Y000100
28921646ABK27GA000123S000100TWM   0000701800Y
28921653A2K27G60000ABS002000BMC   0000390400Y
28921653X6K27GA0000C0000500
28921653A6K27GA0000C0B000500IWM   0000736400Y
28921656XBK27GA000122000100
28921656XBK27GA000123000100
28921658ABK27GA000124S000100TWM   0000702000Y
28921657X6K27GA0000C0000500
28921657A6K27GA0000C0B000500IWM   0000736800Y
28921660ABK27GA000125B000100UWM   0000542800Y
28921661ABK27GA000126S000100TWM   0000701800Y
28921661XBK27GA000124000100
28921663X6K27GA0000C0000500
28921663A6K27GA0000C0B000500IWM   0000736400Y
28921666XBK27GA000125000100
28921666XBK27GA000126000100
28921668ABK27GA000127S000100TWM   0000702000Y
28921671X6K27GA0000C0000500
28921671A6K27GA0000C0B000500IWM   0000736800Y
28921673X6K27GA0000C0000500
28921673A6K27GA0000C0B000500IWM   0000736400Y
28921674ABK27GA000128B000100UWM   0000542800Y
28921674XBK27GA000127000100
28921675ABK27GA000129S000100TWM   0000701800Y
28921676A2K27G60000ACB002000BNI   0001062500Y
28921676XBK27GA000128000100
28921676XBK27GA000129000100
28921678ABK27GA00012AS000100TWM   0000702000Y
28921683X6K27GA0000C0000500
28921683A6K27GA0000C0B000500IWM   0000736800Y
28921686ABK27GA00012BB000100UWM   0000542800Y
28921686ABK27GA00012CS000100TWM   0000701800Y
28921686XBK27GA00012A000100
28921694A2K27G60000ADS002000BNI   0001128600Y
28921693X6K27GA0000C0000500
28921693A6K27GA0000C0B000500IWM   0000736400Y
28921696XBK27GA00012B000100
28921696XBK27GA00012C000100
28921698ABK27GA00012DS000100TWM   0000702000Y
28921697X6K27GA0000C0000500
28921697A6K27GA0000C0B000500IWM   0000736800Y
28921700ABK27GA00012EB000100UWM   0000542800Y
28921700XBK27GA00012D000100
28921701ABK27GA00012FS000100TWM   0000701800Y
28921703X6K27GA0000C0000500
28921703A6K27GA0000C0B000500IWM   0000736400Y
28921706XBK27GA00012E000100
28921706XBK27GA00012F000100
28921708ABK27GA00012GS000100TWM   0000702000Y
28921706A6K27GA0000C1B000100IWM   0000736300Y
28921707X6K27GA0000C1000100
28921707X6K27GA0000C0000500
28921707A6K27GA0000C0B000500IWM   0000736800Y
28921710ABK27GA00012HB000100UWM   0000542800Y
28921710XBK27GA00012G000100
28921710ABK27GA00012IS000100TWM   0000701800Y
28921713X6K27GA0000C0000500
28921713A6K27GA0000C0B000500IWM   0000736400Y
28921715A2K27G60000AEB002000BP    0000739200Y
28921716XBK27GA00012H000100
28921716XBK27GA00012I000100
28921718ABK27GA00012JS000100TWM   0000702000Y
28921721X6K27GA0000C0000500
28921721A6K27GA0000C0B000500IWM   0000736800Y
28921722X6K27GA0000C0000500
28921722A6K27GA0000C0B000500IWM   0000736400Y
28921724ABK27GA00012KB000100UWM   0000542800Y
28921724XBK27GA00012J000100
28921724ABK27GA00012LS000100TWM   0000701800Y
28921726XBK27GA00012K000100
28921726XBK27GA00012L000100
28921728ABK27GA00012MS000100TWM   0000702000Y
28921734X6K27GA0000C0000500
28921734A6K27GA0000C0B000500IWM   0000736800Y
28921743X6K27GA0000C0000500
28921743A6K27GA0000C0B000500IWM   0000736400Y
28921753X6K27GA0000C0000500
28921753A6K27GA0000C0B000500IWM   0000736800Y
28921763X6K27GA0000C0000500
28921763A6K27GA0000C0B000500IWM   0000736400Y
28921773X6K27GA0000C0000500
28921773A6K27GA0000C0B000500IWM   0000736800Y
28921783X6K27GA0000C0000500
28921783A6K27GA0000C0B000500IWM   0000736400Y
28921793X6K27GA0000C0000500
28921793A6K27GA0000C0B000500IWM   0000736800Y
28921803X6K27GA0000C0000500
28921803A6K27GA0000C0B000500IWM   0000736400Y
28921823X6K27GA0000C0000500
28921823A6K27GA0000C0B000500IWM   0000736800Y
28921833X6K27GA0000C0000500
28921833A6K27GA0000C0B000500IWM   0000736400Y
28921843X6K27GA0000C0000500
28921843A6K27GA0000C0B000500IWM   0000736800Y
28921853X6K27GA0000C0000500
28921853A6K27GA0000C0B000500IWM   0000736400Y
28921863X6K27GA0000C0000500
28921863A6K27GA0000C0B000500IWM   0000736800Y
28921873X6K27GA0000C0000500
28921873A6K27GA0000C0B000500IWM   0000736400Y
28921883X6K27GA0000C0000500
28921883A6K27GA0000C0B000500IWM   0000736800Y
28921893X6K27GA0000C0000500
28921893A6K27GA0000C0B000500IWM   0000736400Y
28921903X6K27GA0000C0000500
28921903A6K27GA0000C0B000500IWM   0000736800Y
28921913X6K27GA0000C0000500
28921913A6K27GA0000C0B000500IWM   0000736400Y
28921923X6K27GA0000C0000500
28921923A6K27GA0000C0B000500IWM   0000736800Y
28921933X6K27GA0000C0000500
28921933A6K27GA0000C0B000500IWM   0000736400Y
28921943X6K27GA0000C0000500
28921943A6K27GA0000C0B000500IWM   0000736800Y
28921953X6K27GA0000C0000500
28921953A6K27GA0000C0B000500IWM   0000736400Y
28921963X6K27GA0000C0000500
28921963A6K27GA0000C0B000500IWM   0000736800Y
28921973X6K27GA0000C0000500
28921973A6K27GA0000C0B000500IWM   0000736400Y
28921983X6K27GA0000C0000500
28921983A6K27GA0000C0B000500IWM   0000736800Y
28921993X6K27GA0000C0000500
28921993A6K27GA0000C0B000500IWM   0000736400Y
28922003X6K27GA0000C0000500
28922003A6K27GA0000C0B000500IWM   0000736800Y
28922013X6K27GA0000C0000500
28922013A6K27GA0000C0B000500IWM   0000736400Y
28922023X6K27GA0000C0000500
28922023A6K27GA0000C0B000500IWM   0000736800Y
28922033X6K27GA0000C0000500
28922033A6K27GA0000C0B000500IWM   0000736400Y
28922035XAK27GA000191000500
28922043X6K27GA0000C0000500
28922043A6K27GA0000C0B000500IWM   0000736800Y
28922055X6K27GA0000C0000500
28922055A6K27GA0000C0B000500IWM   0000736400Y
28922063X6K27GA0000C0000500
28922063A6K27GA0000C0B000500IWM   0000736800Y
28922073X6K27GA0000C0000500
28922073A6K27GA0000C0B000500IWM   0000736400Y
28922083X6K27GA0000C0000500
28922083A6K27GA0000C0B000500IWM   0000736800Y
28922093X6K27GA0000C0000500
28922093A6K27GA0000C0B000500IWM   0000736400Y
28922341X1K27GA00009R002000
28922362XAK27GA000189002000
28922378X7K27GA00006W002000
28922381X9K27G60000RI002000
28922405XBK27GA0000YW002000
28922415A3K27G60000B4B002000CTSH  0000096200Y
28922414ACK27GA000055B000737ZVZZT 0000000100Y
28922415XCK27GA000055000737
28922415ACK27GA000055B000737ZVZZT 0000000100Y
28922416XBK27GA000120002000
28922415XCK27GA000055000737
28922433XBK27GA000121002000
28922443X6K27GA0000C0000500
28922443A6K27GA0000C2B000500IWM   0000736300Y
28922453X6K27GA0000C2000500
28922453A6K27GA0000C2B000500IWM   0000736400Y
28922456X1K27GA0000B5002000
28922463X6K27GA0000C2000500
28922463A6K27GA0000C2B000500IWM   0000736800Y
28922466X2K27G6000098002000
28922466ABK27GA00012NB000100UWM   0000542800Y
28922466XBK27GA00012M000100
28922466ABK27GA00012OS000100TWM   0000701800Y
28922473X6K27GA0000C2000500
28922473A6K27GA0000C2B000500IWM   0000736400Y
28922476XBK27GA00012N000100
28922476XBK27GA00012O000100
28922476A6K27GA0000C3B000100IWM   0000736300Y
28922478ABK27GA00012PS000100TWM   0000702000Y
28922476X6K27GA0000C3000100
28922477X6K27GA0000C2000500
28922477A6K27GA0000C2B000500IWM   0000736800Y
28922480ABK27GA00012QB000100UWM   0000542800Y
28922480XBK27GA00012P000100
28922480ABK27GA00012RS000100TWM   0000701800Y
28922483X6K27GA0000C2000500
28922483A6K27GA0000C2B000500IWM   0000736400Y
28922486XBK27GA00012Q000100
28922486XBK27GA00012R000100
28922488A2K27G60000AFB002000BMY   0000066400Y
28922488ABK27GA00012SS000100TWM   0000702000Y
28922493X6K27GA0000C2000500
28922493A6K27GA0000C2B000500IWM   0000736800Y
28922496ABK27GA00012TB000100UWM   0000542800Y
28922496ABK27GA00012US000100TWM   0000701800Y
28922496XBK27GA00012S000100
28922500A5K27GA00007HS002000FNM   0001425600Y
28922503X6K27GA0000C2000500
28922503A6K27GA0000C2B000500IWM   0000736400Y
28922506XBK27GA00012T000100
28922506XBK27GA00012U000100
28922508ABK27GA00012VS000100TWM   0000702000Y
28922507X6K27GA0000C2000500
28922507A6K27GA0000C2B000500IWM   0000736800Y
28922510ABK27GA00012WB000100UWM   0000542800Y
28922510ABK27GA00012XS000100TWM   0000701800Y
28922511XBK27GA00012V000100
28922511X5K27GA00007G002000
28922512A2K27G60000AGB002000BRL   0000375200Y
28922513X6K27GA0000C2000500
28922513A6K27GA0000C2B000500IWM   0000736400Y
28922516XBK27GA00012W000100
28922516XBK27GA00012X000100
28922516A6K27GA0000C4B000100IWM   0000736300Y
28922518ABK27GA00012YS000100TWM   0000702000Y
28922516X6K27GA0000C4000100
28922517X6K27GA0000C2000500
28922517A6K27GA0000C2B000500IWM   0000736800Y
28922520ABK27GA00012ZB000100UWM   0000542800Y
28922520XBK27GA00012Y000100
28922520ABK27GA000130S000100TWM   0000701800Y
28922523X6K27GA0000C2000500
28922523A6K27GA0000C2B000500IWM   0000736400Y
28922525XBK27GA0000YX002000
28922526XBK27GA00012Z000100
28922526XBK27GA000130000100
28922526A6K27GA0000C5B000100IWM   0000736300Y
28922528ABK27GA000131S000100TWM   0000702000Y
28922526X6K27GA0000C5000100
28922527X6K27GA0000C2000500
28922527A6K27GA0000C2B000500IWM   0000736800Y
28922530ABK27GA000132B000100UWM   0000542800Y
28922530XBK27GA000131000100
28922530ABK27GA000133S000100TWM   0000701800Y
28922532XBK27GA00011Z002000
28922533X6K27GA0000C2000500
28922533A6K27GA0000C2B000500IWM   0000736400Y
28922536XBK27GA000132000100
28922536XBK27GA000133000100
28922535ACK27GA000056B002000WYE   0000139700Y
28922536A6K27GA0000C6B000100IWM   0000736300Y
28922538ABK27GA000134S000100TWM   0000702000Y
28922536X6K27GA0000C6000100
28922537X6K27GA0000C2000500
28922537A6K27GA0000C2B000500IWM   0000736800Y
28922540ABK27GA000135B000100UWM   0000542800Y
28922540XBK27GA000134000100
28922540ABK27GA000136S000100TWM   0000701800Y
28922542XCK27GA000053002000
28922543X6K27GA0000C2000500
28922543A6K27GA0000C2B000500IWM   0000736400Y
28922546XBK27GA000135000100
28922546XBK27GA000136000100
28922548ABK27GA000137S000100TWM   0000702000Y
28922548A1K27GA0000B8B002000AFL   0000219400Y
28922551X6K27GA0000C2000500
28922551A6K27GA0000C2B000500IWM   0000736800Y
28922553X6K27GA0000C2000500
28922553A6K27GA0000C2B000500IWM   0000736400Y
28922563X6K27GA0000C2000500
28922563A6K27GA0000C2B000500IWM   0000736800Y
28922564X1K27GA0000B6002000
28922572A1K27GA0000B9S002000AFL   0001571800Y
28922573X6K27GA0000C2000500
28922573A6K27GA0000C2B000500IWM   0000736400Y
28922578X1K27GA0000B7002000
28922588X2K27G6000099002000
28922592X6K27GA0000C2000500
28922592A6K27GA0000C2B000500IWM   0000736800Y
28922597A2K27G60000AHS002000BA    0001628100Y
28922603X6K27GA0000C2000500
28922603A6K27GA0000C2B000500IWM   0000736400Y
28922613X6K27GA0000C2000500
28922613A6K27GA0000C2B000500IWM   0000736800Y
28922616A2K27G60000AIS002000BBT   0001445300Y
28922623X6K27GA0000C2000500
28922623A6K27GA0000C2B000500IWM   0000736400Y
28922633X6K27GA0000C2000500
28922633A6K27GA0000C2B000500IWM   0000736800Y
28922643X6K27GA0000C2000500
28922643A6K27GA0000C2B000500IWM   0000736400Y
28922647A7K27GA00006XB002000LMT   0000359300Y
28922648A2K27G60000AJS002000BP    0000759500Y
28922653X6K27GA0000C2000500
28922653A6K27GA0000C2B000500IWM   0000736800Y
28922657ABK27GA000138B002000UTX   0000236300Y
28922663X6K27GA0000C2000500
28922663A6K27GA0000C2B000500IWM   0000736400Y
28922667A2K27G60000AKB002000BR    0000191600Y
28922666ACK27GA000057B002000WMT   0000540700Y
28922674A1K27GA0000BAB002000ABT   0000178400Y
28922673X6K27GA0000C2000500
28922673A6K27GA0000C2B000500IWM   0000736800Y
28922683X6K27GA0000C2000500
28922683A6K27GA0000C2B000500IWM   0000736400Y
28922685A2K27G60000ALS002000BA    0001628900Y
28922685A2K27G60000AMS002000BR    0000247400Y
28922693A2K27G60000ANB002000BBT   0000106900Y
28922693XAK27GA00018W003000
28922693XAK27GA00018X003000
28922693X6K27GA0000C2000500
28922693A6K27GA0000C2B000500IWM   0000736800Y
28922698AAK27GA000193S003000SPY   0001426600Y
28922698AAK27GA000194S003000SPY   0001426600Y
28922701A2K27G60000AOB002000BSX   0000119500Y
28922703X6K27GA0000C2000500
28922703A6K27GA0000C2B000500IWM   0000736400Y
28922712A2K27G60000APS002000BBT   0001446100Y
28922713X6K27GA0000C2000500
28922713A6K27GA0000C2B000500IWM   0000736800Y
28922722X6K27GA0000C2000500
28922722A6K27GA0000C2B000500IWM   0000736400Y
28922733X6K27GA0000C2000500
28922733A6K27GA0000C2B000500IWM   0000736800Y
28922737A2K27G60000AQB002000CAG   0000070200Y
28922743A2K27G60000ARS002000CAG   0001410100Y
28922742X6K27GA0000C2000500
28922742A6K27GA0000C2B000500IWM   0000736400Y
28922753A3K27G60000B5S002000CCL   0000402200Y
28922752X6K27GA0000C2000500
28922752A6K27GA0000C2B000500IWM   0000736800Y
28922762A3K27G60000B6B002000CCU   0000336200Y
28922763X6K27GA0000C2000500
28922763A6K27GA0000C2B000500IWM   0000736400Y
28922771A3K27G60000B7B002000CFC   0000037300Y
28922773X6K27GA0000C2000500
28922773A6K27GA0000C2B000500IWM   0000736800Y
28922783X6K27GA0000C2000500
28922783A6K27GA0000C2B000500IWM   0000736400Y
28922793X6K27GA0000C2000500
28922793A6K27GA0000C2B000500IWM   0000736800Y
28922803X6K27GA0000C2000500
28922803A6K27GA0000C2B000500IWM   0000736400Y
28922813X6K27GA0000C2000500
28922813A6K27GA0000C2B000500IWM   0000736800Y
28922823X6K27GA0000C2000500
28922823A6K27GA0000C2B000500IWM   0000736400Y
28922842X6K27GA0000C2000500
28922842A6K27GA0000C2B000500IWM   0000736800Y
28922853X6K27GA0000C2000500
28922853A6K27GA0000C2B000500IWM   0000736400Y
28922863X6K27GA0000C2000500
28922863A6K27GA0000C2B000500IWM   0000736800Y
28922873X6K27GA0000C2000500
28922873A6K27GA0000C2B000500IWM   0000736400Y
28922883X6K27GA0000C2000500
28922883A6K27GA0000C2B000500IWM   0000736800Y
28922893X6K27GA0000C2000500
28922893A6K27GA0000C2B000500IWM   0000736400Y
28922903X6K27GA0000C2000500
28922903A6K27GA0000C2B000500IWM   0000736800Y
28922913X6K27GA0000C2000500
28922913A6K27GA0000C2B000500IWM   0000736400Y
28923232XAK27GA000193003000
28923232X4K27GA0000IV000200
28923232XAK27GA00015Y001000
28923232XAK27GA000194003000
28923232XAK27GA0000O2000500
28923232AAK27GA0000O2S000500SPY   0001425900Y
28923232XAK27GA0000FE000500
28923232AAK27GA0000FEB000500SPY   0001425300Y
28923233XAK27GA00018O003000
28923233AAK27GA000195S001000SPY   0001425900Y
