28923233AAK27GA000196S003000SPY   0001426000Y
28923233XAK27GA00018P003000
28923233AAK27GA000197S003000SPY   0001426000Y
28923234AAK27GA000198B000500SPY   0001425400Y
28923235AAK27GA000199B003000SPY   0001425000Y
28923235AAK27GA00019AB003000SPY   0001425000Y
28923263X6K27GA0000C2000500
28923263A6K27GA0000C7B000500IWM   0000736300Y
28923272X6K27GA0000C7000500
28923272A6K27GA0000C7B000500IWM   0000736400Y
28923282X6K27GA0000C7000500
28923282A6K27GA0000C7B000500IWM   0000736800Y
28923286ABK27GA000139B000100UWM   0000542800Y
28923286ABK27GA00013AS000100TWM   0000701800Y
28923286XBK27GA000137000100
28923293X6K27GA0000C7000500
28923293A6K27GA0000C7B000500IWM   0000736400Y
28923296XBK27GA000139000100
28923296XBK27GA00013A000100
28923298ABK27GA00013BS000100TWM   0000702000Y
28923297X6K27GA0000C7000500
28923297A6K27GA0000C7B000500IWM   0000736800Y
28923300ABK27GA00013CB000100UWM   0000542800Y
28923301ABK27GA00013DS000100TWM   0000701800Y
28923301XBK27GA00013B000100
28923303X6K27GA0000C7000500
28923303A6K27GA0000C7B000500IWM   0000736400Y
28923306XBK27GA00013C000100
28923306XBK27GA00013D000100
28923306A6K27GA0000C8B000100IWM   0000736300Y
28923308ABK27GA00013ES000100TWM   0000702000Y
28923306X6K27GA0000C8000100
28923307X6K27GA0000C7000500
28923307A6K27GA0000C7B000500IWM   0000736800Y
28923310ABK27GA00013FB000100UWM   0000542800Y
28923310XBK27GA00013E000100
28923310ABK27GA00013GS000100TWM   0000701800Y
28923313X6K27GA0000C7000500
28923313A6K27GA0000C7B000500IWM   0000736400Y
28923316XBK27GA00013G000100
28923316XBK27GA00013F000100
28923318ABK27GA00013HS000100TWM   0000702000Y
28923323X6K27GA0000C7000500
28923323A6K27GA0000C7B000500IWM   0000736800Y
28923326ABK27GA00013IB000100UWM   0000542800Y
28923326ABK27GA00013JS000100TWM   0000701800Y
28923326XBK27GA00013H000100
28923333A4K27GA0000IYS000200DIA   0001299000Y
28923332X6K27GA0000C7000500
28923332A6K27GA0000C7B000500IWM   0000736400Y
28923336XBK27GA00013I000100
28923336XBK27GA00013J000100
28923336A6K27GA0000C9B000100IWM   0000736300Y
28923338ABK27GA00013KS000100TWM   0000702000Y
28923336X6K27GA0000C9000100
28923337X6K27GA0000C7000500
28923337A6K27GA0000C7B000500IWM   0000736800Y
28923340ABK27GA00013LB000100UWM   0000542800Y
28923340ABK27GA00013MS000100TWM   0000701800Y
28923340XBK27GA00013K000100
28923341X6K27GA0000C7000500
28923341A6K27GA0000C7B000500IWM   0000736400Y
28923342A6K27GA0000CAS002000IWM   0000737200Y
28923344XBK27GA00013L000100
28923344XBK27GA00013M000100
28923346ABK27GA00013NS000100TWM   0000702000Y
28923345A6K27GA0000CBS002000IWM   0000737300Y
28923401X5K27GA00007H002000
28923402X2K27G600007C002000
28923410X5K27GA00006Z002000
28923410XAK27GA00018C002000
28923416X6K27GA0000AY002000
28923417XAK27GA000179002000
28923420X6K27GA0000AZ002000
28923423X7K27GA00005P002000
28923436X7K27GA00006X002000
28923441XBK27GA000138002000
28923441A1K27GA0000BBS002000AMGN  0000480000Y
28923453XCK27GA000056002000
28923460X1K27GA0000BA002000
28923474X1K27GA0000B8002000
28923479X2K27G60000AL002000
28923495X2K27G60000AP002000
28923503AAK27GA00019BB002000SHLD  0000772200Y
28923512X1K27GA0000B9002000
28923537X2K27G60000AH002000
28923549A9K27G60000S4B002000PDLI  0000033400Y
28923558X2K27G60000A9002000
28923567X2K27G60000AR002000
28923577X2K27G60000AI002000
28923578A5K27GA00007IS002000FNM   0001421700Y
28923590A7K27GA00006YB002000LMT   0000363100Y
28923605ABK27GA00013OS002000TGT   0000621700Y
28923609ABK27GA00013PS002000TGT   0000620900Y
28923616ABK27GA00013QS002000UTX   0001581000Y
28923625ABK27GA00013RB002000UTX   0000239100Y
28923632ACK27GA000058B002000WYE   0000140100Y
28923645ABK27GA00013SS002000UTX   0001580200Y
28923666A1K27GA0000BCB002000AFL   0000220500Y
28923667A1K27GA0000BDB002000ABT   0000180800Y
28923685A1K27GA0000BES002000AFL   0001569100Y
28923698A2K27G60000ASB002000AXP   0000417400Y
28923702A2K27G60000ATB002000AXP   0000418200Y
28923746A2K27G60000AUS002000BSX   0000152100Y
28923768A2K27G60000AVB002000CA    0000228700Y
28923771A3K27G60000B8S002000CFC   0000059600Y
28923807A2K27G60000AWS002000CA    0000253200Y
28923984XAK27GA0000O2000500
28923984AAK27GA0000O2S000500SPY   0001426300Y
28924156AAK27GA00019CS001000SPY   0001426100Y
28924156XAK27GA0000FE000500
28924156AAK27GA0000FEB000500SPY   0001425700Y
28924161A4K27GA0000IZS000100DXD   0000500000Y
28924161A3K27G60000B9B000100DDM   0000801300Y
28924163AAK27GA00019DS000500SPY   0001426000Y
28924163AAK27GA00019ES002500SPY   0001426000Y
28924164XAK27GA00018T005000
28924164XAK27GA000192002500
28924164AAK27GA00019FS005000SPY   0001426200Y
28924183XAK27GA000190001000
28924183AAK27GA00019GB001000SPY   0001425500Y
28924196X4K27GA0000DX000200
28924196A4K27GA0000DXB000200DIA   0001298900Y
28924196X4K27GA0000IY000200
28924197XAK27GA000199003000
28924197XAK27GA00019C001000
28924197XAK27GA000196003000
28924197XAK27GA000195001000
28924197XAK27GA000197003000
28924197XAK27GA00019A003000
28924197AAK27GA00019HB003000SPY   0001425700Y
28924197AAK27GA00019IS001000SPY   0001426200Y
28924197AAK27GA00019JB003000SPY   0001425600Y
28924198XAK27GA00019G001000
28924198AAK27GA00019KB001000SPY   0001425600Y
28924199AAK27GA00019LS001000SPY   0001426200Y
28924199XAK27GA00019E002500
28924199AAK27GA00019MS003000SPY   0001426600Y
28924199AAK27GA00019NS001000SPY   0001426300Y
28924200AAK27GA00019OS003000SPY   0001426600Y
28924200A4K27GA0000J0S000200DIA   0001299300Y
28924200XAK27GA00019D000500
28924208X9K27G60000G3002000
28924208A9K27G60000G3S002000QQQQ  0000496400Y
28924209X6K27GA0000C7000500
28924209A6K27GA0000C7B000500IWM   0000736800Y
28924210X6K27GA0000CA002000
28924212ABK27GA00013TB000100UWM   0000542800Y
28924212XBK27GA00013N000100
28924212ABK27GA00013US000100TWM   0000701800Y
28924212XBK27GA00013T000100
28924212XBK27GA00013U000100
28924214ABK27GA00013VB000100UWM   0000542800Y
28924213A6K27GA0000CCB000100IWM   0000736300Y
28924214ABK27GA00013WS000100TWM   0000701800Y
28924213X6K27GA0000CC000100
28924213X6K27GA0000C7000500
28924213A6K27GA0000C7B000500IWM   0000736400Y
28924217X9K27G60000G3002000
28924217A9K27G60000G3S002000QQQQ  0000496000Y
28924217XAK27GA00019H003000
28924217XAK27GA00019N001000
28924217X4K27GA0000DX000200
28924217A4K27GA0000DXB000200DIA   0001298600Y
28924216X6K27GA0000C7000500
28924216A6K27GA0000C7B000500IWM   0000736800Y
28924217AAK27GA00019PS001000SPY   0001425900Y
28924217XAK27GA00019K001000
28924218XAK27GA00019L001000
28924218XAK27GA00019O003000
28924219X4K27GA0000IZ000100
28924219X3K27G60000B9000100
28924219XAK27GA00019M003000
28924219AAK27GA00019QB003000SPY   0001425600Y
28924219AAK27GA00019RB001000SPY   0001425500Y
28924219AAK27GA00019SS003000SPY   0001426000Y
28924220X9K27G60000F8003200
28924220A9K27G60000F8S003200QQQQ  0000496500Y
28924220AAK27GA00019TS003000SPY   0001426000Y
28924223X6K27GA0000C7000500
28924223A6K27GA0000C7B000500IWM   0000736400Y
28924225X4K27GA0000J0000200
28924226A4K27GA0000J1S000047DIA   0001299400Y
28924227X6K27GA0000C7000500
28924227A6K27GA0000C7B000500IWM   0000736800Y
28924229X4K27GA0000J1000047
28924234A4K27GA0000J2S000200DIA   0001299300Y
28924234X6K27GA0000C7000500
28924234A6K27GA0000C7B000500IWM   0000736400Y
28924239X4K27GA0000DX000200
28924239A4K27GA0000DXB000200DIA   0001298900Y
28924241XAK27GA00019Q003000
28924241XAK27GA00019J003000
28924241A4K27GA0000J3S000100DXD   0000500000Y
28924242A3K27G60000BAB000100DDM   0000801300Y
28924244AAK27GA00019UB003000SPY   0001425000Y
28924244AAK27GA00019VB003000SPY   0001425000Y
28924243X6K27GA0000C7000500
28924243A6K27GA0000C7B000500IWM   0000736800Y
28924245XBK27GA00013V000100
28924245XBK27GA00013W000100
28924247ABK27GA00013XS000100TWM   0000701800Y
28924247ABK27GA00013YB000100UWM   0000542800Y
28924247X6K27GA0000C7000500
28924247A6K27GA0000C7B000500IWM   0000736400Y
28924249XAK27GA00019R001000
28924254X9K27G60000F8003200
28924254A9K27G60000F8S003200QQQQ  0000496000Y
28924253X6K27GA0000C7000500
28924253A6K27GA0000C7B000500IWM   0000736800Y
28924255XBK27GA00013Y000100
28924255XBK27GA00013X000100
28924257ABK27GA00013ZB000100UWM   0000542800Y
28924257ABK27GA000140S000100TWM   0000701800Y
28924257X6K27GA0000C7000500
28924257A6K27GA0000C7B000500IWM   0000736400Y
28924259X6K27GA0000C7000500
28924259A6K27GA0000C7B000500IWM   0000736800Y
28924261XBK27GA00013Z000100
28924261XBK27GA000140000100
28924263ABK27GA000141B000100UWM   0000542800Y
28924261A6K27GA0000CDB000100IWM   0000736300Y
28924263ABK27GA000142S000100TWM   0000701800Y
28924261X6K27GA0000CD000100
28924262X6K27GA0000C7000500
28924262A6K27GA0000C7B000500IWM   0000736400Y
28924265X6K27GA0000C7000500
28924265A6K27GA0000C7B000500IWM   0000736800Y
28924267X6K27GA0000CB002000
28924269X6K27GA0000C7000500
28924269A6K27GA0000C7B000500IWM   0000736400Y
28924274XBK27GA000141000100
28924274XBK27GA000142000100
28924273X6K27GA0000C7000500
28924273A6K27GA0000C7B000500IWM   0000736800Y
28924275AAK27GA00019WB001000SPY   0001425500Y
28924276ABK27GA000143S000100TWM   0000702000Y
28924284ABK27GA000144B000100UWM   0000542800Y
28924284ABK27GA000145S000100TWM   0000701800Y
28924284XBK27GA000143000100
28924283X6K27GA0000C7000500
28924283A6K27GA0000C7B000500IWM   0000736400Y
28924287A6K27GA0000CES002000IWM   0000737300Y
28924294XBK27GA000144000100
28924295XBK27GA000145000100
28924293X6K27GA0000C7000500
28924293A6K27GA0000C7B000500IWM   0000736800Y
28924295A6K27GA0000CFB000100IWM   0000736300Y
28924295X6K27GA0000CF000100
28924296ABK27GA000146S000100TWM   0000702000Y
28924296X6K27GA0000C7000500
28924296A6K27GA0000C7B000500IWM   0000736400Y
28924304ABK27GA000147B000100UWM   0000542800Y
28924304XBK27GA000146000100
28924304XBK27GA000147000100
28924304ABK27GA000148S000100TWM   0000701800Y
28924304XBK27GA000148000100
28924303X6K27GA0000C7000500
28924303A6K27GA0000C7B000500IWM   0000736800Y
28924306ABK27GA000149S000100TWM   0000702000Y
28924311X6K27GA0000C7000500
28924311A6K27GA0000C7B000500IWM   0000736400Y
28924314ABK27GA00014AB000100UWM   0000542800Y
28924314ABK27GA00014BS000100TWM   0000701800Y
28924314XBK27GA000149000100
28924313X6K27GA0000C7000500
28924313A6K27GA0000C7B000500IWM   0000736800Y
28924324XBK27GA00014A000100
28924324XBK27GA00014B000100
28924323X6K27GA0000C7000500
28924323A6K27GA0000C7B000500IWM   0000736400Y
28924326ABK27GA00014CS000100TWM   0000702000Y
28924334ABK27GA00014DB000100UWM   0000542800Y
28924334ABK27GA00014ES000100TWM   0000701800Y
28924334XBK27GA00014C000100
28924333X6K27GA0000C7000500
28924333A6K27GA0000C7B000500IWM   0000736800Y
28924344XBK27GA00014D000100
28924344XBK27GA00014E000100
28924343X6K27GA0000C7000500
28924343A6K27GA0000C7B000500IWM   0000736400Y
28924346ABK27GA00014FS000100TWM   0000702000Y
28924353X6K27GA0000C7000500
28924353A6K27GA0000C7B000500IWM   0000736800Y
28924356X2K27G60000AF002000
28924363X6K27GA0000C7000500
28924363A6K27GA0000C7B000500IWM   0000736400Y
28924373X6K27GA0000C7000500
28924373A6K27GA0000C7B000500IWM   0000736800Y
28924383X6K27GA0000C7000500
28924383A6K27GA0000C7B000500IWM   0000736400Y
28924392AAK27GA00019XB002000SPLS  0000068700Y
28924393X5K27GA00007I002000
28924393X6K27GA0000C7000500
28924393A6K27GA0000C7B000500IWM   0000736800Y
28924403X6K27GA0000C7000500
28924403A6K27GA0000C7B000500IWM   0000736400Y
28924410XBK27GA0000W6002000
28924413A5K27GA00007JS002000FNM   0001416100Y
28924413X6K27GA0000C7000500
28924413A6K27GA0000C7B000500IWM   0000736800Y
28924415XBK27GA00013Q002000
28924421XCK27GA000058002000
28924423X6K27GA0000C7000500
28924423A6K27GA0000C7B000500IWM   0000736400Y
28924428AAK27GA00019YB002000SNDK  0000241000Y
28924430X1K27GA0000BC002000
28924434X1K27GA0000BE002000
28924433X6K27GA0000C7000500
28924433A6K27GA0000C7B000500IWM   0000736800Y
28924443X6K27GA0000C7000500
28924443A6K27GA0000C7B000500IWM   0000736400Y
28924451A5K27GA00007KB002000GM    0000180200Y
28924453X2K27G60000AN002000
28924453X6K27GA0000C7000500
28924453A6K27GA0000C7B000500IWM   0000736800Y
28924463X6K27GA0000C7000500
28924463A6K27GA0000C7B000500IWM   0000736400Y
28924465AAK27GA00019ZS000500SPY   0001426000Y
28924473X6K27GA0000C7000500
28924473A6K27GA0000C7B000500IWM   0000736800Y
28924483X6K27GA0000C7000500
28924483A6K27GA0000C7B000500IWM   0000736400Y
28924486X2K27G60000AQ002000
28924492X7K27GA00006Y002000
28924493X6K27GA0000C7000500
28924493A6K27GA0000C7B000500IWM   0000736800Y
28924497A2K27G60000AXS002000BRL   0000423800Y
28924503XBK27GA00013R002000
28924503X6K27GA0000C7000500
28924503A6K27GA0000C7B000500IWM   0000736400Y
28924513XBK27GA00013S002000
28924519A6K27GA0000CGB002000JNJ   0000643000Y
28924525ACK27GA000059B002000WYE   0000142100Y
28924526A6K27GA0000CHS002000JNJ   0000689700Y
28924534X1K27GA0000BD002000
28924541A7K27GA00006ZB002000KSS   0000457800Y
28924548A1K27GA0000BFB002000AFL   0000223100Y
28924550A7K27GA000070B002000LMT   0000365300Y
28924560ABK27GA00014GB002000UTX   0000240300Y
28924561A1K27GA0000BGS002000AFL   0001564700Y
28924574A1K27GA0000BHB002000ABT   0000181500Y
28924586A2K27G60000AYS002000BA    0001621900Y
28924590A2K27G60000AZS002000BA    0001622700Y
28924600A2K27G60000B0B002000BBT   0000109600Y
28924607A2K27G60000B1S002000BBT   0001436900Y
28924620A2K27G60000B2S002000BBT   0001436100Y
28924646AAK27GA0001A0S002500SPY   0001426000Y
28924656A2K27G60000B3B002000CAG   0000072300Y
28924680A2K27G60000B4S002000CAG   0001399600Y
28924689A2K27G60000B5S002000CAG   0001400400Y
28924702A2K27G60000B6B002000CAH   0000544300Y
28925093XAK27GA00019V003000
28925093X4K27GA0000DX000200
28925093A4K27GA0000DXB000200DIA   0001298600Y
28925093XAK27GA00019U003000
28925093XAK27GA00019I001000
28925093AAK27GA0001A1B003000SPY   0001425600Y
28925093AAK27GA0001A2B003000SPY   0001425600Y
28925095X4K27GA0000J3000100
28925095X3K27G60000BA000100
28925096XAK27GA0001A0002500
28925096AAK27GA0001A3S005000SPY   0001426100Y
28925096AAK27GA0001A4S002500SPY   0001426100Y
28925096XAK27GA00019Z000500
28925096XAK27GA00019F005000
28925103X6K27GA0000C7000500
28925104A6K27GA0000CIB000500IWM   0000736300Y
28925106ABK27GA00014HB000100UWM   0000542800Y
28925106ABK27GA00014IS000100TWM   0000701800Y
28925106XBK27GA00014F000100
28925106X6K27GA0000CE002000
28925107X6K27GA0000CI000500
28925107A6K27GA0000CIB000500IWM   0000736400Y
28925109XBK27GA00014H000100
28925109XBK27GA00014I000100
28925111ABK27GA00014JS000100TWM   0000702000Y
28925109A6K27GA0000CJB000100IWM   0000736300Y
28925110X6K27GA0000CJ000100
28925110X6K27GA0000CI000500
28925110A6K27GA0000CIB000500IWM   0000736800Y
28925113ABK27GA00014KB000100UWM   0000542800Y
28925113XBK27GA00014J000100
28925113ABK27GA00014LS000100TWM   0000701800Y
28925113XAK27GA00019W001000
28925113X6K27GA0000CI000500
28925113A6K27GA0000CIB000500IWM   0000736400Y
28925124XBK27GA00014K000100
28925124XBK27GA00014L000100
28925123X6K27GA0000CI000500
28925123A6K27GA0000CIB000500IWM   0000736800Y
28925126ABK27GA00014MB000100UWM   0000542800Y
28925125A6K27GA0000CKB000100IWM   0000736300Y
28925125X6K27GA0000CK000100
28925127ABK27GA00014NS000100TWM   0000701800Y
28925132AAK27GA0001A5B001000SPY   0001425400Y
28925133X6K27GA0000CI000500
28925133A6K27GA0000CIB000500IWM   0000736400Y
28925143X6K27GA0000CI000500
28925143A6K27GA0000CIB000500IWM   0000736800Y
28925144XBK27GA00014M000100
28925144XBK27GA00014N000100
28925146ABK27GA00014OB000100UWM   0000542800Y
28925146ABK27GA00014PS000100TWM   0000701800Y
28925153X6K27GA0000CI000500
28925153A6K27GA0000CIB000500IWM   0000736400Y
28925162X6K27GA0000CI000500
28925162A6K27GA0000CIB000500IWM   0000736800Y
28925164XBK27GA00014O000100
28925164XBK27GA00014P000100
28925166ABK27GA00014QB000100UWM   0000542800Y
28925166ABK27GA00014RS000100TWM   0000701800Y
28925172X6K27GA0000CI000500
28925172A6K27GA0000CIB000500IWM   0000736400Y
28925180X6K27GA0000CI000500
28925180A6K27GA0000CIB000500IWM   0000736800Y
28925183X6K27GA0000CI000500
28925183A6K27GA0000CIB000500IWM   0000736400Y
28925193X6K27GA0000CI000500
28925193A6K27GA0000CIB000500IWM   0000736800Y
28925194XBK27GA00014Q000100
28925194XBK27GA00014R000100
28925196ABK27GA00014SB000100UWM   0000542800Y
28925196ABK27GA00014TS000100TWM   0000701800Y
28925203X6K27GA0000CI000500
28925203A6K27GA0000CIB000500IWM   0000736400Y
28925214XBK27GA00014S000100
28925212X6K27GA0000CI000500
28925212A6K27GA0000CIB000500IWM   0000736800Y
28925214XBK27GA00014T000100
28925214A6K27GA0000CLB000100IWM   0000736300Y
28925216ABK27GA00014US000100TWM   0000701800Y
28925214X6K27GA0000CL000100
28925216ABK27GA00014VB000100UWM   0000542800Y
28925222X6K27GA0000CI000500
28925222A6K27GA0000CIB000500IWM   0000736400Y
28925228X6K27GA0000CI000500
28925228A6K27GA0000CIB000500IWM   0000736800Y
28925232X6K27GA0000CI000500
28925232A6K27GA0000CIB000500IWM   0000736400Y
28925244XBK27GA00014V000100
28925244XBK27GA00014U000100
28925242X6K27GA0000CI000500
28925242A6K27GA0000CIB000500IWM   0000736800Y
28925244A6K27GA0000CMB000100IWM   0000736300Y
28925246ABK27GA00014WS000100TWM   0000702000Y
28925245X6K27GA0000CM000100
28925252X6K27GA0000CI000500
28925252A6K27GA0000CIB000500IWM   0000736400Y
28925254ABK27GA00014XB000100UWM   0000542800Y
28925254XBK27GA00014W000100
28925254ABK27GA00014YS000100TWM   0000701800Y
28925262X6K27GA0000CI000500
28925262A6K27GA0000CIB000500IWM   0000736800Y
28925264XBK27GA00014X000100
28925264XBK27GA00014Y000100
28925266ABK27GA00014ZS000100TWM   0000702000Y
28925272X6K27GA0000CI000500
28925272A6K27GA0000CIB000500IWM   0000736400Y
28925282X6K27GA0000CI000500
28925282A6K27GA0000CIB000500IWM   0000736800Y
28925293X6K27GA0000CI000500
28925293A6K27GA0000CIB000500IWM   0000736400Y
28925302X6K27GA0000CI000500
28925302A6K27GA0000CIB000500IWM   0000736800Y
28925312X6K27GA0000CI000500
28925312A6K27GA0000CIB000500IWM   0000736400Y
28925322X6K27GA0000CI000500
28925322A6K27GA0000CIB000500IWM   0000736800Y
28925333X6K27GA0000CI000500
28925333A6K27GA0000CIB000500IWM   0000736400Y
28925343X6K27GA0000CI000500
28925343A6K27GA0000CIB000500IWM   0000736800Y
28925347X3K27G60000B0002000
28925352X3K27G60000B4002000
28925352X6K27GA0000CI000500
28925352A6K27GA0000CIB000500IWM   0000736400Y
28925363X6K27GA0000CI000500
28925363A6K27GA0000CIB000500IWM   0000736800Y
28925374X6K27GA0000CI000500
28925374A6K27GA0000CIB000500IWM   0000736400Y
28925383X6K27GA0000CI000500
28925383A6K27GA0000CIB000500IWM   0000736800Y
28925393X6K27GA0000CI000500
28925393A6K27GA0000CIB000500IWM   0000736400Y
28925403X6K27GA0000CI000500
28925403A6K27GA0000CIB000500IWM   0000736800Y
28925407X7K27GA000070002000
28925413X6K27GA0000CI000500
28925413A6K27GA0000CIB000500IWM   0000736400Y
28925421X5K27GA00007J002000
28925423XBK27GA00014G002000
28925441XCK27GA000059002000
28925443X1K27GA0000BH002000
28925450X1K27GA0000BF002000
28925459X1K27GA0000BG002000
28925469X2K27G60000AZ002000
28925472X2K27G60000AY002000
28925475X2K27G60000B1002000
28925486X2K27G60000B2002000
28925488X2K27G60000B5002000
28925493A5K27GA00007LS002000FNM   0001412200Y
28925498X2K27G600009U002000
28925507X2K27G60000B4002000
28925515A2K27G60000B7B002000BMY   0000068200Y
28925518ABK27GA000150B002000TGT   0000521100Y
28925527ABK27GA000151S002000UTX   0001574100Y
28925537A7K27GA000071B002000LMT   0000369100Y
28925539ACK27GA00005AB002000WYE   0000142500Y
28925556A1K27GA0000BIB002000AFL   0000224200Y
28925558ABK27GA000152B002000UTX   0000243100Y
28925568ABK27GA000153S002000UTX   0001573300Y
28925573A1K27GA0000BJS002000AFL   0001561900Y
28925581A1K27GA0000BKB002000ABT   0000183900Y
28925590A2K27G60000B8B002000BBT   0000109800Y
28925618A2K27G60000B9S002000CAH   0000570500Y
28925618A2K27G60000BAB002000CAG   0000072200Y
28925625A2K27G60000BBB002000CAT   0000820200Y
28925627A3K27G60000BBB002000CHS   0000060900Y
28925644A3K27G60000BCS002000CHS   0000090900Y
28925645A2K27G60000BCS002000CAT   0000867300Y
28925663A3K27G60000BDB002000CL    0000692100Y
28925663A3K27G60000BEB002000CCE   0000193600Y
28925689A3K27G60000BFS002000CCE   0000240100Y
28925863X6K27GA000097000100
28925863X6K27GA000098000100
28925864XBK27GA0000RT000100
28926276X4K27GA0000DX000200
28926276A4K27GA0000DXB000200DIA   0001298900Y
28926276XAK27GA00019P001000
28926277AAK27GA0001A6S001000SPY   0001426200Y
28926277AAK27GA0001A7S001000SPY   0001426300Y
28926278AAK27GA0001A8S000500SPY   0001426000Y
28926278A4K27GA0000J4S000100DXD   0000500000Y
28926279A3K27G60000BGB000100DDM   0000801300Y
28926278AAK27GA0001A9S002500SPY   0001426000Y
28926279XAK27GA0001A3005000
28926279XAK27GA0001A4002500
28926279AAK27GA0001AAS005000SPY   0001426200Y
28926289A6K27GA0000CNS002000IWM   0000737300Y
28926299XAK27GA0001A6001000
28926299XAK27GA00019T003000
28926299XAK27GA00019S003000
28926300XAK27GA0001A5001000
28926300AAK27GA0001ABB001000SPY   0001425500Y
28926301XAK27GA0000F2000500
28926301AAK27GA0000F2B000500SPY   0001425800Y
28926301AAK27GA0001ACS003000SPY   0001426600Y
28926301AAK27GA0001ADS003000SPY   0001426600Y
28926301XAK27GA0001A9002500
28926301XAK27GA0001A8000500
28926301XBK27GA00011E001000
28926301ABK27GA000154B001000SSO   0000764700Y
28926303ABK27GA000155B001000SSO   0000764500Y
28926313X4K27GA0000DX000200
28926313A4K27GA0000DXB000200DIA   0001298600Y
28926313XAK27GA0000F2000500
28926313AAK27GA0000F2B000500SPY   0001425400Y
28926314XBK27GA000155001000
28926315X4K27GA0000J4000100
28926315X3K27G60000BG000100
28926315X6K27GA0000CI000500
28926315A6K27GA0000CIB000500IWM   0000736800Y
28926318ABK27GA000156B000100UWM   0000542800Y
28926318XBK27GA00014Z000100
28926318ABK27GA000157S000100TWM   0000701800Y
28926318XBK27GA000154001000
28926317X6K27GA0000CN002000
28926318XAK27GA0001AD003000
28926318XAK27GA0001AC003000
28926318AAK27GA0001AES003000SPY   0001426000Y
28926319AAK27GA0001AFS003000SPY   0001426000Y
28926318X6K27GA0000CI000500
28926318A6K27GA0000CIB000500IWM   0000736400Y
28926320ABK27GA000158B001000SSO   0000764600Y
28926321XBK27GA000156000100
28926322XBK27GA000157000100
28926321X6K27GA0000CI000500
28926321A6K27GA0000CIB000500IWM   0000736800Y
28926323ABK27GA000159S000100TWM   0000702000Y
28926324X9K27G60000F8003200
28926324A9K27G60000F8S003200QQQQ  0000496500Y
28926324ABK27GA00015AB000100UWM   0000542800Y
28926324ABK27GA00015BS000100TWM   0000701800Y
28926324XBK27GA000159000100
28926326X4K27GA0000DX000200
28926326A4K27GA0000DXB000200DIA   0001298900Y
28926326X9K27G60000G3002000
28926326A9K27G60000G3S002000QQQQ  0000496400Y
28926326AAK27GA0001AGS001000SPY   0001426200Y
28926328X9K27G60000S1001000
28926328A9K27G60000S5B001000QLD   0000889600Y
28926328A3K27G60000BHB000100DDM   0000801300Y
28926328A4K27GA0000J5S000100DXD   0000500000Y
28926329XAK27GA0001AB001000
28926329X9K27G60000F8003200
28926329A9K27G60000F8S003200QQQQ  0000496000Y
28926329XAK27GA0001A2003000
28926329XAK27GA0001A1003000
28926330A9K27G60000S6B001000QQQQ  0000495500Y
28926330A9K27G60000S7B001000QQQQ  0000495400Y
28926330X9K27G60000S5001000
28926332A9K27G60000S8B001000QLD   0000889500Y
28926332AAK27GA0001AHB003000SPY   0001425000Y
28926332AAK27GA0001AIB003000SPY   0001425000Y
28926334X9K27G60000S6001000
28926334X9K27G60000S7001000
28926332X6K27GA0000CI000500
28926332A6K27GA0000CIB000500IWM   0000736400Y
28926343X6K27GA0000CI000500
28926343A6K27GA0000CIB000500IWM   0000736800Y
28926348X6K27GA0000CI000500
28926348A6K27GA0000CIB000500IWM   0000736400Y
28926354A3K27G60000BIB002000CELG  0000497800Y
28926354XBK27GA00015A000100
28926354XBK27GA00015B000100
28926355AAK27GA0001AJB001000SPY   0001425500Y
28926356ABK27GA00015CS000100TWM   0000702000Y
28926356X6K27GA0000CI000500
28926356A6K27GA0000CIB000500IWM   0000736800Y
28926358ABK27GA00015DB000100UWM   0000542800Y
28926358XBK27GA00015C000100
28926358ABK27GA00015ES000100TWM   0000701800Y
28926362X6K27GA0000CI000500
28926362A6K27GA0000CIB000500IWM   0000736400Y
28926374XBK27GA00015D000100
28926374XBK27GA00015E000100
28926373X6K27GA0000CI000500
28926373A6K27GA0000CIB000500IWM   0000736800Y
28926376ABK27GA00015FS000100TWM   0000702000Y
28926377ABK27GA00015GB000100UWM   0000542800Y
28926377XBK27GA00015F000100
28926377ABK27GA00015HS000100TWM   0000701800Y
28926377X6K27GA0000CI000500
28926377A6K27GA0000CIB000500IWM   0000736400Y
28926385XBK27GA00015G000100
28926385XBK27GA00015H000100
28926387ABK27GA00015IS000100TWM   0000702000Y
28926387X6K27GA0000CI000500
28926387A6K27GA0000CIB000500IWM   0000736800Y
28926390ABK27GA00015JB000100UWM   0000542800Y
28926390ABK27GA00015KS000100TWM   0000701800Y
28926390XBK27GA00015I000100
28926392X6K27GA0000CI000500
28926392A6K27GA0000CIB000500IWM   0000736400Y
28926395X4K27GA0000H5002000
28926398X7K27GA000071002000
28926403X6K27GA0000CI000500
28926403A6K27GA0000CIB000500IWM   0000736800Y
28926405XBK27GA00015J000100
28926405XBK27GA00015K000100
28926407ABK27GA00015LS000100TWM   0000701800Y
28926407ABK27GA00015MB000100UWM   0000542800Y
28926407X6K27GA0000CI000500
28926407A6K27GA0000CIB000500IWM   0000736400Y
28926410XBK27GA00015M000100
28926410XBK27GA00015L000100
28926412ABK27GA00015NS000100TWM   0000702000Y
28926413X5K27GA00007L002000
28926417X6K27GA0000CI000500
28926417A6K27GA0000CIB000500IWM   0000736800Y
28926419XBK27GA000152002000
28926424ABK27GA00015OB000100UWM   0000542800Y
28926424XBK27GA00015N000100
28926424ABK27GA00015PS000100TWM   0000701800Y
28926424X6K27GA0000CI000500
28926424A6K27GA0000CIB000500IWM   0000736400Y
28926428A3K27G60000BJB002000CTSH  0000099700Y
28926428XBK27GA000151002000
28926428XBK27GA000153002000
28926430XCK27GA00005A002000
28926434XBK27GA00015O000100
28926434XBK27GA00015P000100
28926435X1K27GA0000BK002000
28926436ABK27GA00015QS000100TWM   0000702000Y
28926445X1K27GA0000BI002000
28926446X2K27G60000B0002000
28926454X2K27G60000B3002000
28926457X1K27GA0000BJ002000
28926468X2K27G600007N002000
28926468X9K27G60000G3002000
28926468A9K27G60000G3S002000QQQQ  0000496000Y
28926469A9K27G60000S9S002000QQQQ  0000496000Y
28926472X2K27G60000A0002000
28926475A5K27GA00007MS002000FNM   0001406600Y
28926487AAK27GA0001AKS000500SPY   0001426000Y
28926489A6K27GA0000COS002000IWM   0000737200Y
28926491A6K27GA0000CPS002000IWM   0000737300Y
28926495A7K27GA000072B002000LMT   0000371300Y
28926502ACK27GA00005BB002000WYE   0000144500Y
28926509ABK27GA00015RB002000UTX   0000244300Y
28926519A1K27GA0000BLB002000AFL   0000226800Y
28926527A1K27GA0000BMB002000ABT   0000184600Y
28926537A1K27GA0000BNS002000AFL   0001557500Y
28926554A2K27G60000BDS002000BA    0001616500Y
28926554A2K27G60000BES002000BA    0001615700Y
28926569A2K27G60000BFS002000BBT   0001427700Y
28926587A2K27G60000BGS002000BBT   0001426900Y
28926604A2K27G60000BHB002000BDX   0000775900Y
28926604A2K27G60000BIS002000CAG   0001390600Y
28926620A2K27G60000BJS002000CAG   0001389800Y
28926624A3K27G60000BKS002000CL    0000747400Y
28926634A3K27G60000BLB002000CCL   0000381100Y
28926645A3K27G60000BMB002000CNX   0000929700Y
28926652A3K27G60000BNS002000CCL   0000401400Y
28926726AAK27GA0001ALS002500SPY   0001426000Y
28927283X9K27G60000S9002000
28927295X6K27GA0000CO002000
28927347A9K27G60000SAS002000QQQQ  0000496000Y
28927348XAK27GA00019B002000
28927386AAK27GA0001AMS001000SPY   0001426100Y
28927386XAK27GA0001AG001000
28927390X5K27GA00006G002000
28927391X2K27G60000B7002000
28927400XAK27GA000175001000
28927406X7K27GA000072002000
28927413X5K27GA00007M002000
28927416XBK27GA00013O002000
28927416XBK27GA00015R002000
28927424XBK27GA00013P002000
28927444XCK27GA00005B002000
28927453X1K27GA0000BM002000
28927463X1K27GA0000BL002000
28927468X1K27GA0000BN002000
28927477X2K27G60000BE002000
28927485X2K27G60000BG002000
28927487X1K27GA00008N002000
28927501X2K27G60000BJ002000
28927501X2K27G60000BD002000
28927508X2K27G60000B8002000
28927517X2K27G60000BF002000
28927524X2K27G60000BA002000
28927523A7K27GA000073B002000LMT   0000375100Y
28927526X2K27G60000BI002000
28927549ABK27GA00015SB002000UTX   0000247100Y
28927551A4K27GA0000J6B002000EMR   0000555400Y
28927558A5K27GA00007NS002000FNM   0001402700Y
28927561ABK27GA00015TS002000UTX   0001566300Y
28927599A1K27GA0000BOB002000ABT   0000186900Y
28927605A2K27G60000BKB002000BBT   0000112500Y
28927615A2K27G60000BLB002000CAG   0000074300Y
28927636A3K27G60000BOB002000CCU   0000337000Y
28927639ABK27GA00015US002000UTX   0001567100Y
28927647ACK27GA00005CB002000WYE   0000144900Y
28927656A3K27G60000BPB002000CFC   0000038100Y
28927656A1K27GA0000BPB002000AFL   0000227900Y
28927667A1K27GA0000BQS002000AFL   0001554700Y
28927673A3K27G60000BQS002000CFC   0000058800Y
28927681A2K27G60000BMB002000AZN   0000421300Y
28927687A2K27G60000BNB002000BDX   0000775300Y
28927694A3K27G60000BRB002000CHS   0000061700Y
28927709A3K27G60000BSS002000CNX   0000994800Y
28927713A3K27G60000BTS002000CHS   0000090100Y
28927723A3K27G60000BUB002000COH   0000117400Y
28927754A3K27G60000BVS002000COH   0001432000Y
28927767A3K27G60000BWB002000COP   0000915200Y
28927775A3K27G60000BXS002000COP   0000939700Y
28927851XAK27GA00018Y001000
28927888X4K27GA0000DX000200
28927888A4K27GA0000DXB000200DIA   0001298600Y
28927891X4K27GA0000J5000100
28927891X3K27G60000BH000100
28928298X4K27GA0000DX000200
28928298A4K27GA0000DXB000200DIA   0001298900Y
28928298XAK27GA0001AM001000
28928298XAK27GA0001AI003000
28928298XAK27GA0001AH003000
28928298XAK27GA0001AF003000
28928298XAK27GA0000F2000500
28928298AAK27GA0000F2B000500SPY   0001425800Y
28928298XAK27GA0001AE003000
28928298AAK27GA0001ANB003000SPY   0001425700Y
28928298AAK27GA0001AOB003000SPY   0001425700Y
28928298AAK27GA0001APS001000SPY   0001426200Y
28928298AAK27GA0001AQB001000SPY   0001425600Y
28928298XAK27GA0000E4001000
28928298AAK27GA0000E4B001000SPY   0001425800Y
28928299XBK27GA000158001000
28928299ABK27GA00015VB001000SSO   0000764700Y
28928300AAK27GA0001ARS001000SPY   0001426200Y
28928300A4K27GA0000J7S000100DXD   0000500000Y
28928301A3K27G60000BYB000100DDM   0000801300Y
28928300AAK27GA0001ASS003000SPY   0001426600Y
28928300AAK27GA0001ATS003000SPY   0001426600Y
28928300AAK27GA0001AUS005000SPY   0001426100Y
28928301ABK27GA00015WB001000SSO   0000764500Y
28928301XAK27GA0001AA005000
28928301XAK27GA0001AL002500
28928302AAK27GA0001AVB002500SPY   0001425600Y
28928302XAK27GA0001AK000500
28928303AAK27GA0001AWB000500SPY   0001425600Y
28928303XAK27GA000198000500
28928310XAK27GA0001AQ001000
28928311X6K27GA0000CI000500
28928312A6K27GA0000CQB000500IWM   0000736800Y
28928314ABK27GA00015XB000100UWM   0000542800Y
28928314XBK27GA00015Q000100
28928314ABK27GA00015YS000100TWM   0000701800Y
28928318X4K27GA0000DX000200
28928318A4K27GA0000DXB000200DIA   0001298600Y
28928318XAK27GA0000E4001000
28928318AAK27GA0000E4B001000SPY   0001425400Y
28928318XAK27GA0001AO003000
28928318XAK27GA0001AN003000
28928318XAK27GA0000F2000500
28928318AAK27GA0000F2B000500SPY   0001425400Y
28928318X6K27GA0000CQ000500
28928318A6K27GA0000CQB000500IWM   0000736400Y
28928320X4K27GA0000J7000100
28928320AAK27GA0001AXB003000SPY   0001425600Y
28928320X3K27G60000BY000100
28928320AAK27GA0001AYB003000SPY   0001425600Y
28928320XAK27GA0001AR001000
28928321XBK27GA00015W001000
28928320XAK27GA0001AT003000
28928320XAK27GA0001AS003000
28928321XAK27GA0001AW000500
28928321XAK27GA0001AV002500
28928321AAK27GA0001AZS003000SPY   0001426000Y
28928321AAK27GA0001B0S003000SPY   0001426000Y
28928322XBK27GA00015X000100
28928322XBK27GA00015Y000100
28928324ABK27GA00015ZS000100TWM   0000702000Y
28928322X6K27GA0000CQ000500
28928322A6K27GA0000CQB000500IWM   0000736800Y
28928325ABK27GA000160B000100UWM   0000542800Y
28928325XBK27GA00015Z000100
28928325ABK27GA000161S000100TWM   0000701800Y
28928328XBK27GA00015V001000
28928330ABK27GA000162B001000SSO   0000764600Y
28928332X6K27GA0000CQ000500
28928332A6K27GA0000CQB000500IWM   0000736400Y
28928335X4K27GA0000DX000200
28928335A4K27GA0000DXB000200DIA   0001298900Y
28928336AAK27GA0001B1S001000SPY   0001426100Y
28928336XAK27GA000174001000
28928336XAK27GA0001AU005000
28928336A4K27GA0000J8S000100DXD   0000500000Y
28928337A3K27G60000BZB000100DDM   0000801300Y
28928337XAK27GA0001AX003000
28928337XAK27GA0001AY003000
28928339A6K27GA0000CRS002000IWM   0000737200Y
28928340AAK27GA0001B2B003000SPY   0001425000Y
28928341AAK27GA0001B3B003000SPY   0001425000Y
28928344XBK27GA000160000100
28928344XBK27GA000161000100
28928345A6K27GA0000CSB000100IWM   0000736300Y
28928346ABK27GA000163S000100TWM   0000702000Y
28928345X6K27GA0000CS000100
28928350XAK27GA00019X002000
28928354X6K27GA0000CQ000500
28928354A6K27GA0000CQB000500IWM   0000736800Y
28928356XAK27GA0001AJ001000
28928355X6K27GA0000CR002000
28928357ABK27GA000164B000100UWM   0000542800Y
28928356X6K27GA0000CQ000500
28928356A6K27GA0000CQB000500IWM   0000736400Y
28928357XBK27GA000163000100
28928357ABK27GA000165S000100TWM   0000701800Y
28928358AAK27GA0001B4B001000SPY   0001425400Y
28928359XBK27GA000165000100
28928359XBK27GA000164000100
28928361ABK27GA000166S000100TWM   0000702000Y
28928363AAK27GA0001B5S001000SPY   0001426100Y
28928362A6K27GA0000CTS002000IWM   0000737200Y
28928363X4K27GA0000DX000200
28928363A4K27GA0000DXB000200DIA   0001298600Y
28928364ABK27GA000167B000100UWM   0000542800Y
28928364XBK27GA000166000100
28928364ABK27GA000168S000100TWM   0000701800Y
28928364XBK27GA000168000100
28928364XBK27GA000167000100
28928365X4K27GA0000J8000100
28928366X3K27G60000BZ000100
28928366ABK27GA000169S000100TWM   0000702000Y
28928379AAK27GA0001B6B001000SPY   0001425500Y
28928396XAK27GA0001B4001000
28928401X5K27GA00007N002000
28928401AAK27GA0001B7B002000SHLD  0000775100Y
28928402A2K27G60000BOB002000BMY   0000070100Y
28928404X5K27GA000078002000
28928419XBK27GA00015U002000
28928423XCK27GA00005C002000
28928439X1K27GA0000BP002000
28928439X1K27GA0000BQ002000
28928444X1K27GA00008R002000
28928449X2K27G60000AS002000
28928458A5K27GA00007OS002000FNM   0001397100Y
28928474X7K27GA000073002000
28928493X3K27G60000BV002000
28928497ABK27GA00016AS002000TGT   0000619500Y
28928506A5K27GA00007PS002000GM    0000228000Y
28928514XBK27GA00015S002000
28928515A7K27GA000074B002000LMT   0000377300Y
28928516AAK27GA0001B8B000500SPY   0001425400Y
28928526XBK27GA00015T002000
28928527ABK27GA00016BS002000TGT   0000620300Y
28928535ABK27GA00016CB002000UTX   0000248300Y
28928546ACK27GA00005DB002000WYE   0000146900Y
28928560X1K27GA0000BO002000
28928585A1K27GA0000BRB002000AFL   0000230500Y
28928596A1K27GA0000BSS002000AFL   0001550300Y
28928604A1K27GA0000BTB002000ABT   0000187600Y
28928615X2K27G60000AT002000
28928623A1K27GA0000BUS002000ACN   0000408100Y
28928634A2K27G60000BPS002000BA    0001609500Y
28928644A2K27G60000BQS002000BA    0001610300Y
28928652A2K27G60000BRS002000BBT   0001417800Y
28928663A2K27G60000BSB002000BBT   0000112600Y
28928670A2K27G60000BTS002000CAG   0001380100Y
28928680A2K27G60000BUS002000BBT   0001418600Y
28928699A2K27G60000BVB002000CAG   0000074100Y
28928707A2K27G60000BWS002000CAG   0001380900Y
28928718AAK27GA0001B9S005000SPY   0001426200Y
28928719AAK27GA0001BAS000500SPY   0001426000Y
28928719AAK27GA0001BBS002500SPY   0001426000Y
28929238XAK27GA0001A7001000
28929239AAK27GA0001BCS001000SPY   0001425900Y
28929343X6K27GA0000BO002000
28929398X7K27GA000074002000
28929398X5K27GA00007O002000
28929415X1K27GA0000AR002000
28929418XBK27GA00016C002000
28929432XCK27GA00005D002000
28929434X3K27G60000BJ002000
28929444X1K27GA0000BT002000
28929447AAK27GA0001BDB002000SOHU  0000797200Y
28929459X2K27G60000BQ002000
28929475X2K27G60000BU002000
28929481X1K27GA0000BR002000
28929495X2K27G600008A002000
28929497X1K27GA0000BS002000
28929499X2K27G60000BW002000
28929503X2K27G60000BP002000
28929513X3K27G60000BU002000
28929513AAK27GA0001BEB002000SPLS  0000071800Y
28929515X2K27G60000BK002000
28929525X2K27G60000BR002000
28929531A5K27GA00007QS002000FNM   0001393200Y
28929540X2K27G60000BL002000
28929549X2K27G60000BT002000
28929581A7K27GA000075B002000LMT   0000381100Y
28929591ABK27GA00016DB002000UTX   0000251100Y
28929596A5K27GA00007RB002000GM    0000179700Y
28929598ABK27GA00016ES002000UTX   0001559400Y
28929606A1K27GA0000BVB002000ABT   0000190000Y
28929623A2K27G60000BXB002000AXP   0000419500Y
28929626ABK27GA00016FS002000UTX   0001560200Y
28929645ACK27GA00005EB002000WYE   0000147300Y
28929656A3K27G60000C0B002000CL    0000692900Y
28929656A1K27GA0000BWB002000AFL   0000231600Y
28929663A1K27GA0000BXS002000AFL   0001547600Y
28929672A3K27G60000C1S002000CL    0000746600Y
28929674A1K27GA0000BYS002000ALL   0000524900Y
28929683A2K27G60000BYB002000AXP   0000418700Y
28929690A3K27G60000C2B002000CNX   0000930500Y
28929705A3K27G60000C3S002000CNX   0000994000Y
28929724A3K27G60000C4B002000COH   0000120200Y
28929741A3K27G60000C5S002000COH   0001422200Y
28929971AAK27GA0001BFB002500SPY   0001425500Y
28929972XAK27GA0001B8000500
28929972AAK27GA0001BGB005000SPY   0001425500Y
28929973XAK27GA000163005000
28929979X6K27GA0000CQ000500
28929979A6K27GA0000CQB000500IWM   0000736800Y
28929980X6K27GA0000CT002000
28929983ABK27GA00016GB000100UWM   0000542800Y
28929983XBK27GA000169000100
28929983ABK27GA00016HS000100TWM   0000701800Y
28929982X6K27GA0000CQ000500
28929982A6K27GA0000CQB000500IWM   0000736400Y
28929987XAK27GA0001BC001000
28929992X6K27GA0000CQ000500
28929992A6K27GA0000CQB000500IWM   0000736800Y
28929994XBK27GA00016G000100
28929994AAK27GA0001BHS001000SPY   0001426300Y
28929994XBK27GA00016H000100
28929996ABK27GA00016IB000100UWM   0000542800Y
28929996ABK27GA00016JS000100TWM   0000701800Y
28930002X6K27GA0000CQ000500
28930002A6K27GA0000CQB000500IWM   0000736400Y
28930012X6K27GA0000CQ000500
28930012A6K27GA0000CQB000500IWM   0000736800Y
28930014XBK27GA00016I000100
28930014XBK27GA00016J000100
28930016ABK27GA00016KS000100TWM   0000701800Y
28930016ABK27GA00016LB000100UWM   0000542800Y
28930022X6K27GA0000CQ000500
28930022A6K27GA0000CQB000500IWM   0000736400Y
28930032X6K27GA0000CQ000500
28930032A6K27GA0000CQB000500IWM   0000736800Y
28930034XBK27GA00016L000100
28930034XBK27GA00016K000100
28930037ABK27GA00016MS000100TWM   0000701800Y
28930037ABK27GA00016NB000100UWM   0000542800Y
28930042X6K27GA0000CQ000500
28930042A6K27GA0000CQB000500IWM   0000736400Y
28930052X6K27GA0000CQ000500
28930052A6K27GA0000CQB000500IWM   0000736800Y
28930054XBK27GA00016N000100
28930054XBK27GA00016M000100
28930056ABK27GA00016OB000100UWM   0000542800Y
28930054A6K27GA0000CUB000100IWM   0000736300Y
28930056ABK27GA00016PS000100TWM   0000701800Y
28930055X6K27GA0000CU000100
28930062X6K27GA0000CQ000500
28930062A6K27GA0000CQB000500IWM   0000736400Y
28930072X6K27GA0000CQ000500
28930072A6K27GA0000CQB000500IWM   0000736800Y
28930074XBK27GA00016O000100
28930074XBK27GA00016P000100
28930076ABK27GA00016QS000100TWM   0000701800Y
28930076ABK27GA00016RB000100UWM   0000542800Y
28930082X6K27GA0000CQ000500
28930082A6K27GA0000CQB000500IWM   0000736400Y
28930092X6K27GA0000CQ000500
28930092A6K27GA0000CQB000500IWM   0000736800Y
28930094XBK27GA00016R000100
28930094XBK27GA00016Q000100
28930096ABK27GA00016SB000100UWM   0000542800Y
28930096ABK27GA00016TS000100TWM   0000701800Y
28930102X6K27GA0000CQ000500
28930102A6K27GA0000CQB000500IWM   0000736400Y
28930112X6K27GA0000CQ000500
28930112A6K27GA0000CQB000500IWM   0000736800Y
28930114XBK27GA00016S000100
28930114XBK27GA00016T000100
28930116ABK27GA00016US000100TWM   0000702000Y
28930122X6K27GA0000CQ000500
28930122A6K27GA0000CQB000500IWM   0000736400Y
28930132X6K27GA0000CQ000500
28930132A6K27GA0000CQB000500IWM   0000736800Y
28930142X6K27GA0000CQ000500
28930142A6K27GA0000CQB000500IWM   0000736400Y
28930152X6K27GA0000CQ000500
28930152A6K27GA0000CQB000500IWM   0000736800Y
28930163X6K27GA0000CQ000500
28930163A6K27GA0000CQB000500IWM   0000736400Y
28930172X6K27GA0000CQ000500
28930172A6K27GA0000CQB000500IWM   0000736800Y
28930182X6K27GA0000CQ000500
28930182A6K27GA0000CQB000500IWM   0000736400Y
28930192X6K27GA0000CQ000500
28930192A6K27GA0000CQB000500IWM   0000736800Y
28930202X6K27GA0000CQ000500
28930202A6K27GA0000CQB000500IWM   0000736400Y
28930212X6K27GA0000CQ000500
28930212A6K27GA0000CQB000500IWM   0000736800Y
28930222X6K27GA0000CQ000500
28930222A6K27GA0000CQB000500IWM   0000736400Y
28930233X6K27GA0000CQ000500
28930233A6K27GA0000CQB000500IWM   0000736800Y
28930242X6K27GA0000CQ000500
28930242A6K27GA0000CQB000500IWM   0000736400Y
28930252X6K27GA0000CQ000500
28930252A6K27GA0000CQB000500IWM   0000736800Y
28930262X6K27GA0000CQ000500
28930262A6K27GA0000CQB000500IWM   0000736400Y
28930272X6K27GA0000CQ000500
28930272A6K27GA0000CQB000500IWM   0000736800Y
28930282X6K27GA0000CQ000500
28930282A6K27GA0000CQB000500IWM   0000736400Y
28930292X6K27GA0000CQ000500
28930292A6K27GA0000CQB000500IWM   0000736800Y
28930302X6K27GA0000CQ000500
28930302A6K27GA0000CQB000500IWM   0000736400Y
28930312X6K27GA0000CQ000500
28930312A6K27GA0000CQB000500IWM   0000736800Y
28930322X6K27GA0000CQ000500
28930322A6K27GA0000CQB000500IWM   0000736400Y
28930332X6K27GA0000CQ000500
28930332A6K27GA0000CQB000500IWM   0000736800Y
28930342X6K27GA0000CQ000500
28930342A6K27GA0000CQB000500IWM   0000736400Y
28930349X5K27GA00007Q002000
28930352X6K27GA0000CQ000500
28930352A6K27GA0000CQB000500IWM   0000736800Y
28930362X6K27GA0000CQ000500
28930362A6K27GA0000CQB000500IWM   0000736400Y
28930373X6K27GA0000CQ000500
28930373A6K27GA0000CQB000500IWM   0000736800Y
28930392X6K27GA0000CQ000500
28930392A6K27GA0000CQB000500IWM   0000736400Y
28930394X9K27G60000SA002000
28930395A9K27G60000SBB002000QQQQ  0000495600Y
28930402X6K27GA0000CQ000500
28930402A6K27GA0000CQB000500IWM   0000736800Y
28930413X2K27G60000BO002000
28930414A6K27GA0000CVS002000IMCL  0000510600Y
28930418XBK27GA00016F002000
28930422X6K27GA0000CQ000500
28930422A6K27GA0000CQB000500IWM   0000736400Y
28930432X6K27GA0000CQ000500
28930432A6K27GA0000CQB000500IWM   0000736800Y
28930442XCK27GA00005E002000
28930442X6K27GA0000CQ000500
28930442A6K27GA0000CQB000500IWM   0000736400Y
28930446X7K27GA000075002000
28930446X1K27GA0000BW002000
28930447X1K27GA0000BX002000
28930449XBK27GA00016D002000
28930460XBK27GA00016E002000
28930461X2K27G60000BS002000
28930460A1K27GA0000BZS002000APOL  0000529600Y
28930460X1K27GA0000BV002000
28930464X2K27G600008B002000
28930492X2K27G600008I002000
28930492X2K27G60000BV002000
28930497X3K27G60000C5002000
28930502A5K27GA00007SS002000FNM   0001387600Y
28930514A3K27G60000C6B002000CTSH  0000103100Y
28930531A7K27GA000076B002000LMT   0000383300Y
28930559ACK27GA00005FB002000WYE   0000149300Y
28930561ABK27GA00016VB002000UTX   0000252300Y
28930597A1K27GA0000C0B002000ABT   0000190700Y
28930621A1K27GA0000C1B002000AFL   0000234300Y
28930629A2K27G60000BZS002000BA    0001604100Y
28930642A1K27GA0000C2S002000AFL   0001543200Y
28930646A2K27G60000C0S002000BBT   0001409400Y
28930658A2K27G60000C1S002000BA    0001603300Y
28930665A2K27G60000C2B002000BK    0000428900Y
28930676A2K27G60000C3B002000BBT   0000115300Y
28930678A2K27G60000C4S002000CAG   0001371100Y
28930693A2K27G60000C5S002000BBT   0001408600Y
28930695A3K27G60000C7B002000COH   0000120400Y
28930709A3K27G60000C8S002000COH   0001418500Y
28930713A2K27G60000C6B002000CAG   0000076200Y
28930736A2K27G60000C7S002000CAG   0001370300Y
28931064X6K27GA0000CQ000500
28931064A6K27GA0000CWB000500IWM   0000736800Y
28931067XBK27GA00016U000100
28931067ABK27GA00016WS000100TWM   0000701800Y
28931067ABK27GA00016XB000100UWM   0000542800Y
28931068X6K27GA0000CP002000
28931069X6K27GA0000CW000500
28931069A6K27GA0000CWB000500IWM   0000736400Y
28931073X6K27GA0000CW000500
28931073A6K27GA0000CWB000500IWM   0000736800Y
28931083X6K27GA0000CW000500
28931083A6K27GA0000CWB000500IWM   0000736400Y
28931093X6K27GA0000CW000500
28931093A6K27GA0000CWB000500IWM   0000736800Y
28931103X6K27GA0000CW000500
28931103A6K27GA0000CWB000500IWM   0000736400Y
28931113X6K27GA0000CW000500
28931113A6K27GA0000CWB000500IWM   0000736800Y
28931123X6K27GA0000CW000500
28931123A6K27GA0000CWB000500IWM   0000736400Y
28931133X6K27GA0000CW000500
28931133A6K27GA0000CWB000500IWM   0000736800Y
28931143X6K27GA0000CW000500
28931143A6K27GA0000CWB000500IWM   0000736400Y
28931153X6K27GA0000CW000500
28931153A6K27GA0000CWB000500IWM   0000736800Y
28931163X6K27GA0000CW000500
28931163A6K27GA0000CWB000500IWM   0000736400Y
28931173X6K27GA0000CW000500
28931173A6K27GA0000CWB000500IWM   0000736800Y
28931183X6K27GA0000CW000500
28931183A6K27GA0000CWB000500IWM   0000736400Y
28931186XBK27GA00016X000100
28931186XBK27GA00016W000100
28931186X6K27GA0000CW000500
28931186A6K27GA0000CWB000500IWM   0000736800Y
28931188ABK27GA00016YS000100TWM   0000702000Y
28931188X6K27GA0000CW000500
28931188A6K27GA0000CWB000500IWM   0000736400Y
28931193X6K27GA0000CW000500
28931193A6K27GA0000CWB000500IWM   0000736800Y
28931203X6K27GA0000CW000500
28931203A6K27GA0000CWB000500IWM   0000736400Y
28931213X6K27GA0000CW000500
28931213A6K27GA0000CWB000500IWM   0000736800Y
28931223X6K27GA0000CW000500
28931223A6K27GA0000CWB000500IWM   0000736400Y
28931233X6K27GA0000CW000500
28931233A6K27GA0000CWB000500IWM   0000736800Y
28931243X6K27GA0000CW000500
28931243A6K27GA0000CWB000500IWM   0000736400Y
28931253X6K27GA0000CW000500
28931253A6K27GA0000CWB000500IWM   0000736800Y
28931263X6K27GA0000CW000500
28931263A6K27GA0000CWB000500IWM   0000736400Y
28931273X6K27GA0000CW000500
28931273A6K27GA0000CWB000500IWM   0000736800Y
28931283X6K27GA0000CW000500
28931283A6K27GA0000CWB000500IWM   0000736400Y
28931293X6K27GA0000CW000500
28931293A6K27GA0000CWB000500IWM   0000736800Y
28931303X6K27GA0000CW000500
28931303A6K27GA0000CWB000500IWM   0000736400Y
28931313X6K27GA0000CW000500
28931313A6K27GA0000CWB000500IWM   0000736800Y
28931323X6K27GA0000CW000500
28931323A6K27GA0000CWB000500IWM   0000736400Y
28931333X6K27GA0000CW000500
28931333A6K27GA0000CWB000500IWM   0000736800Y
28931343X6K27GA0000CW000500
28931343A6K27GA0000CWB000500IWM   0000736400Y
28931353X6K27GA0000CW000500
28931353A6K27GA0000CWB000500IWM   0000736800Y
28931359X5K27GA00007S002000
28931363X6K27GA0000CW000500
28931363A6K27GA0000CWB000500IWM   0000736400Y
28931372X6K27GA0000CW000500
28931372A6K27GA0000CWB000500IWM   0000736800Y
28931382X6K27GA0000CW000500
28931382A6K27GA0000CWB000500IWM   0000736400Y
28931392X6K27GA0000CW000500
28931392A6K27GA0000CWB000500IWM   0000736800Y
28931395X7K27GA00005Q002000
28931398X7K27GA000076002000
28931400XBK27GA00016V002000
28931403X6K27GA0000CW000500
28931403A6K27GA0000CWB000500IWM   0000736400Y
28931407A2K27G60000C8B002000BMY   0000071900Y
28931413X6K27GA0000CW000500
28931413A6K27GA0000CWB000500IWM   0000736800Y
28931423X6K27GA0000CW000500
28931423A6K27GA0000CWB000500IWM   0000736400Y
28931424X1K27GA0000C0002000
28931432X6K27GA0000CW000500
28931432A6K27GA0000CWB000500IWM   0000736800Y
28931437X2K27G60000BZ002000
28931443X6K27GA0000CW000500
28931443A6K27GA0000CWB000500IWM   0000736400Y
28931448A7K27GA000077B002000LMT   0000387100Y
28931450X2K27G60000C0002000
28931452X6K27GA0000CW000500
28931452A6K27GA0000CWB000500IWM   0000736800Y
28931464X2K27G60000C4002000
28931462X6K27GA0000CW000500
28931462A6K27GA0000CWB000500IWM   0000736400Y
28931466X3K27G60000C8002000
28931482X6K27GA0000CW000500
28931482A6K27GA0000CWB000500IWM   0000736800Y
28931484XCK27GA00004R002000
28931485A5K27GA00007TS002000FNM   0001383600Y
28931493X6K27GA0000CW000500
28931493A6K27GA0000CWB000500IWM   0000736400Y
28931498XCK27GA00005F002000
28931502X6K27GA0000CW000500
28931502A6K27GA0000CWB000500IWM   0000736800Y
28931506XCK27GA00004U002000
28931513X6K27GA0000CW000500
28931513A6K27GA0000CWB000500IWM   0000736400Y
28931523X6K27GA0000CW000500
28931523A6K27GA0000CWB000500IWM   0000736800Y
28931525ABK27GA00016ZS002000UTX   0001553300Y
28931525ABK27GA000170B002000UTX   0000255100Y
28931533X6K27GA0000CW000500
28931533A6K27GA0000CWB000500IWM   0000736400Y
28931535X1K27GA0000C1002000
28931535X6K27GA0000CW000500
28931535A6K27GA0000CWB000500IWM   0000736800Y
28931535ACK27GA00005GB002000WYE   0000149700Y
28931543X6K27GA0000CW000500
28931543A6K27GA0000CWB000500IWM   0000736400Y
28931546A1K27GA0000C3B002000AFL   0000235300Y
28931552X1K27GA0000C2002000
28931555A1K27GA0000C4S002000AFL   0001540400Y
28931561ABK27GA000171S002000UTX   0001552500Y
28931585A2K27G60000C9B002000BBT   0000115400Y
28931592A2K27G60000CAS002000BK    0000476600Y
28931596A2K27G60000CBB002000BNI   0001062200Y
28931600X1K27GA0000AP002000
28931601A2K27G60000CCB002000CAG   0000076100Y
28931610X2K27G60000C1002000
28931619P7K27GA000078B000100MDT   0000495000000I000HV2MT
28931623X2K27G60000C5002000
28931631X2K27G60000C7002000
28931639A1K27GA0000C5B002000ABT   0000193100Y
28931646X3K27G60000C4002000
28931698A3K27G60000C9S002000COH   0001413200Y
28931701A3K27G60000CAB002000CTX   0000217400Y
28931711A3K27G60000CBB002000COP   0000916000Y
28931741A3K27G60000CCS002000COP   0000938900Y
28931752A3K27G60000CDB002000CTX   0000218200Y
28931762A3K27G60000CES002000CTX   0000239700Y
28931771A3K27G60000CFB002000CVC   0000231000Y
28932346X1K27GA0000BB002000
28932365X3K27G60000BI002000
28932365X5K27GA00007T002000
28932381XAK27GA0001B7002000
28932385X5K27GA00006E002000
28932400X3K27G60000AW002000
28932421A5K27GA00007US002000FNM   0001378100Y
28932437XBK27GA00016Z002000
28932437X4K27GA0000DX000200
28932437A4K27GA0000DXB000200DIA   0001298900Y
28932439A4K27GA0000J9S000100DXD   0000500000Y
28932440A3K27G60000CGB000100DDM   0000801300Y
28932445XCK27GA00005G002000
28932449X3K27G6000097002000
28932453X1K27GA0000C3002000
28932458X1K27GA0000C4002000
28932481X7K27GA000077002000
28932483X3K27G60000C7002000
28932496XBK27GA000170002000
28932513A7K27GA000079S002000KSS   0000505300Y
28932515XBK27GA000171002000
28932521A7K27GA00007AB002000LMT   0000389300Y
28932533ABK27GA000172B002000UTX   0000256300Y
28932542ACK27GA00005HB002000WMT   0000542000Y
28932560A1K27GA0000C6B002000ABT   0000193700Y
28932593X6K27GA0000CW000500
28932593ACK27GA00005IB002000WYE   0000151800Y
28932593A6K27GA0000CXB000500IWM   0000736800Y
28932595ABK27GA000173B000100UWM   0000542800Y
28932595XBK27GA00016Y000100
28932596ABK27GA000174S000100TWM   0000701800Y
28932603ACK27GA00005JS002000WYE   0000471400Y
28932609X1K27GA0000C5002000
28932609A6K27GA0000CYB002000IWM   0000736800Y
28932609X6K27GA00009S002000
28932616X8K27G600005S000500
28932616X8K27G600005T000100
28932618X6K27GA000028000500
28932618A6K27GA000028S000500IWM   0000737400Y
28932624XBK27GA0000I0000100
28932624XBK27GA0000YH000100
28932624XBK27GA0000VX000100
28932623A6K27GA0000CZS002000IWM   0000737400Y
28932630ABK27GA000175B000100TWM   0000700300Y
28932638A1K27GA0000C7B002000AFL   0000238000Y
28932643A2K27G60000CDS002000BA    0001597900Y
28932658A1K27GA0000C8S002000AFL   0001536000Y
28932665A2K27G60000CES002000BBT   0001400200Y
28932676A1K27GA0000C9B002000ARO   0000300500Y
28932690A2K27G60000CFS002000CAG   0001361400Y
28932699A2K27G60000CGS002000BA    0001597100Y
28932702A3K27G60000CHS002000COH   0001409500Y
28932710X2K27G60000C3002000
28932728A3K27G60000CIS002000CTX   0000240500Y
28932734A2K27G60000CHS002000BBT   0001399400Y
28932743X2K27G60000BH002000
28932755A3K27G60000CJB002000CVC   0000230200Y
28932755X2K27G60000C6002000
28932767X3K27G60000C9002000
28933356A1K27GA0000CAS002000AMGN  0000477500Y
28933361X2K27G60000C8002000
28933413X7K27GA00007A002000
28933420XBK27GA00016B002000
28933422X5K27GA00007U002000
28933435XBK27GA000172002000
28933436X6K27GA0000BD002000
28933439A3K27G60000CKB002000CELG  0000500300Y
28933466XBK27GA00016A002000
28933473X1K27GA0000C6002000
28933480XAK27GA0001BE002000
28933494X3K27G60000C6002000
28933503X9K27G60000S4002000
28933507XAK27GA00019Y002000
28933510XCK27GA00005I002000
28933524AAK27GA0001BIB002000SHLD  0000778000Y
28933525X2K27G60000CD002000
28933538A7K27GA00007BB002000LMT   0000393100Y
28933542X2K27G60000C9002000
28933551X2K27G60000CE002000
28933560X2K27G60000BN002000
28933566X2K27G60000CC002000
28933595X2K27G60000CF002000
28933595X3K27G60000CH002000
28933599A5K27GA00007VS002000FNM   0001374100Y
28933602A3K27G60000CLS002000CMCSK 0000270100Y
28933611A5K27GA00007WS002000GG    0000435400Y
28933620A3K27G60000CMB002000COST  0000699400Y
28933627X1K27GA0000C7002000
28933640X1K27GA0000C8002000
28933647X2K27G60000CG002000
28933647ABK27GA000176S002000UTX   0001546400Y
28933663ACK27GA00005KB002000WYE   0000152200Y
28933666ABK27GA000177B002000UTX   0000259100Y
28933671A1K27GA0000CBB002000AFL   0000239000Y
28933679X2K27G60000CH002000
28933687A1K27GA0000CCS002000AFL   0001533200Y
28933692ABK27GA000178S002000UTX   0001545600Y
28933699A1K27GA0000CDB002000ABT   0000196100Y
28933715A2K27G60000CIB002000BBT   0000118100Y
28933719A3K27G60000CNB002000COH   0000123300Y
28933736A2K27G60000CJB002000BDX   0000777300Y
28933758A2K27G60000CKB002000CAG   0000078200Y
28933765A3K27G60000COS002000CVC   0000260900Y
28933778A2K27G60000CLS002000CAG   0001355700Y
28933787A3K27G60000CPB002000CVS   0000148500Y
28933814A3K27G60000CQB002000COH   0000124100Y
28933818A3K27G60000CRS002000CVS   0001429100Y
28933832A3K27G60000CSS002000COH   0001404100Y
28933861A3K27G60000CTS002000CVC   0000260100Y
28934350X4K27GA0000FR002000
28934385X5K27GA00007V002000
28934388X7K27GA00007B002000
28934410XBK27GA0000XT002000
28934410AAK27GA0001BJB002000SPLS  0000075000Y
28934412XBK27GA000176002000
28934420XCK27GA00005K002000
28934436X1K27GA0000CB002000
28934436X1K27GA0000CC002000
28934436XBK27GA000177002000
28934449XBK27GA000178002000
28934452X1K27GA0000B0002000
28934456A3K27G60000CUB002000CTSH  0000106600Y
28934458X1K27GA0000CD002000
28934461X2K27G60000BY002000
28934503A9K27G60000SCB002000PDLI  0000035800Y
28934504A2K27G60000CMB002000BMY   0000073700Y
28934513X3K27G60000CP002000
28934529X3K27G60000CR002000
28934528AAK27GA0001BKB002000SNDK  0000243500Y
28934542A5K27GA00007XS002000FNM   0001368600Y
28934560A7K27GA00007CB002000LMT   0000395300Y
28934589X2K27G60000BX002000
28934593X2K27G60000CL002000
28934599X3K27G60000CS002000
28934604ABK27GA000179S002000TGT   0000618700Y
28934606A6K27GA0000D0B002000JNJ   0000644200Y
28934610ABK27GA00017AB002000UTX   0000260300Y
28934625ABK27GA00017BS002000TGT   0000617900Y
28934654A1K27GA0000CEB002000ABT   0000196800Y
28934656ACK27GA00005LB002000WYE   0000154200Y
28934682A1K27GA0000CFB002000AFL   0000241700Y
28934684A2K27G60000CNS002000BA    0001591700Y
28934698A1K27GA0000CGS002000AFL   0001528800Y
28934701A2K27G60000COB002000BBT   0000118300Y
28934715A2K27G60000CPS002000BBT   0001391100Y
28934717A2K27G60000CQS002000BA    0001590900Y
28934732A2K27G60000CRB002000BDX   0000776700Y
28934732A2K27G60000CSS002000BBT   0001390300Y
28934735A2K27G60000CTB002000CAG   0000078000Y
28934747A2K27G60000CUS002000CAG   0001351600Y
28935065X5K27GA00003P000100
28935065A5K27GA00003PS000100GOOG  0005792000Y
28935135X4K27GA0000IP000100
28935353X1K27GA000072002000
28935356X5K27GA00007X002000
28935405X6K27GA0000BE002000
28935408X7K27GA00007C002000
28935410A4K27GA0000JAS002000EBAY  0000328000Y
28935419X7K27GA00006A002000
28935434XBK27GA00017A002000
28935460XCK27GA00005L002000
28935462X1K27GA0000CE002000
28935476X2K27G60000CN002000
28935478X1K27GA0000CF002000
28935488X1K27GA0000CG002000
28935491X2K27G60000CP002000
28935500X2K27G60000CQ002000
28935511X2K27G60000CI002000
28935518X2K27G60000CS002000
28935521X2K27G60000CU002000
28935524X3K27G60000CN002000
28935528X2K27G60000CK002000
28935532X3K27G60000CQ002000
28935540A5K27GA00007YS002000FNM   0001364600Y
28935544A7K27GA00007DB002000LMT   0000399100Y
28935560ABK27GA00017CS002000UTX   0001539500Y
28935560ABK27GA00017DB002000TGT   0000522400Y
28935589ACK27GA00005MB002000WYE   0000154600Y
28935597A1K27GA0000CHB002000AFL   0000242700Y
28935600A1K27GA0000CIS002000AFL   0001526100Y
28935612A1K27GA0000CJB002000ARO   0000299900Y
28935618ABK27GA00017EB002000UTX   0000263100Y
28935620A2K27G60000CVB002000AXP   0000420000Y
28935630ABK27GA00017FS002000UTX   0001538700Y
28935639A1K27GA0000CKB002000ABT   0000199200Y
28935643A3K27G60000CVS002000COH   0001395900Y
28935653A2K27G60000CWB002000AXP   0000420800Y
28935670A2K27G60000CXS002000CAG   0001345900Y
28935670A3K27G60000CWB002000CVS   0000150900Y
28935681A3K27G60000CXS002000CVS   0001420500Y
28935687A3K27G60000CYS002000COH   0001395100Y
28935695A3K27G60000CZB002000DAL   0000017300Y
28935702A3K27G60000D0B002000CVS   0000151700Y
28935712A3K27G60000D1S002000DAL   0000085300Y
28935723A3K27G60000D2S002000CVS   0001419700Y
28935744A3K27G60000D3B002000DAL   0000018100Y
28936288ABK27GA00017GB001000SSO   0000764700Y
28936288XBK27GA000162001000
28936350A1K27GA0000CLB002000AMZN  0000802100Y
28936394X5K27GA00007Y002000
28936400X2K27G60000CM002000
28936409X7K27GA000062002000
28936409X4K27GA0000IN002000
28936413XBK27GA00017C002000
28936421XCK27GA00005M002000
28936436X1K27GA0000CH002000
28936437A5K27GA00007ZS002000FNM   0001359100Y
28936437X1K27GA0000CI002000
28936440X2K27G60000CO002000
28936439X1K27GA00008S002000
28936447X2K27G60000CT002000
28936452X3K27G60000CV002000
28936452A6K27GA0000D1S002000JNJ   0000688400Y
28936462X3K27G60000CW002000
28936464X3K27G60000CX002000
28936478X7K27GA00007D002000
28936487XBK27GA00017E002000
28936492A7K27GA00007EB002000LMT   0000401300Y
28936505XBK27GA00017F002000
28936505A7K27GA00007FB002000KSS   0000459100Y
28936512ABK27GA00017HB002000UTX   0000264300Y
28936536X1K27GA0000CK002000
28936542A1K27GA0000CMB002000ABT   0000199900Y
28936550ACK27GA00005NB002000WYE   0000156600Y
28936605A1K27GA0000CNB002000AFL   0000245400Y
28936610A2K27G60000CYS002000BA    0001585500Y
28936626A1K27GA0000COS002000AFL   0001521700Y
28936645A2K27G60000CZS002000BA    0001584700Y
28936645A2K27G60000D0S002000BBT   0001381900Y
28936675A2K27G60000D1B002000BBT   0000121000Y
28936683A2K27G60000D2S002000CAG   0001341900Y
28936690X2K27G60000CX002000
28936696A3K27G60000D4B002000COH   0000126300Y
28936703X3K27G60000CY002000
28936710X3K27G60000D0002000
28936719X3K27G60000D2002000
28936732A2K27G60000D3S002000BBT   0001381100Y
28937259X4K27GA0000IK000100
28937259A4K27GA0000JBS000100DRYS  0001073400Y
28937263A4K27GA0000JCB000100DRYS  0001070100Y
28937346XAK27GA0001BI002000
28937388X3K27G60000CU002000
28937395X5K27GA00007Z002000
28937412X5K27GA000070002000
28937430X7K27GA00007E002000
28937441XBK27GA00017H002000
28937446XCK27GA00005N002000
28937462X1K27GA0000CM002000
28937464X1K27GA0000CN002000
28937478X1K27GA0000CO002000
28937485X2K27G60000CY002000
28937487X2K27G600009B002000
28937498X2K27G60000CZ002000
28937499X2K27G60000D0002000
28937502X2K27G60000D3002000
28937510X2K27G60000D2002000
28937521A2K27G60000D4B002000BMY   0000075600Y
28937525A5K27GA000080S002000FNM   0001355100Y
28937537A4K27GA0000JDB002000EMR   0000556600Y
28937543A7K27GA00007GS002000MMM   0000815400Y
28937555ABK27GA00017IS002000UTX   0001532600Y
28937557A7K27GA00007HB002000LMT   0000405100Y
28937570ACK27GA00005OB002000WYE   0000157000Y
28937578A1K27GA0000CPB002000AFL   0000246400Y
28937581A1K27GA0000CQS002000AFL   0001518900Y
28937587A1K27GA0000CRB002000ANF   0000723100Y
28937594ABK27GA00017JB002000UTX   0000267100Y
28937596A2K27G60000D5B002000BBT   0000121100Y
28937606A2K27G60000D6B002000CAG   0000080000Y
28937607ABK27GA00017KS002000UTX   0001531800Y
28937616A1K27GA0000CSB002000ABT   0000202200Y
28937616A3K27G60000D5S002000COH   0001386900Y
28937627A2K27G60000D7B002000CAG   0000080800Y
28937632A3K27G60000D6B002000CVS   0000153200Y
28937640A3K27G60000D7S002000CVS   0001411800Y
28937645A2K27G60000D8S002000CAG   0001336200Y
28937658A3K27G60000D8B002000COH   0000128100Y
28937668A3K27G60000D9B002000DD    0000462000Y
28937675A3K27G60000DAS002000COH   0001386100Y
28937688A3K27G60000DBS002000DD    0001434800Y
28937690A3K27G60000DCB002000CVS   0000154000Y
28937709A3K27G60000DDS002000CVS   0001411000Y
28938256AAK27GA0001BLS005000SPY   0001426100Y
28938256XAK27GA0001B9005000
28938351X6K27GA0000BZ002000
28938354XAK27GA0001BJ002000
28938401AAK27GA0001BMB002000SHLD  0000780900Y
28938413X5K27GA000080002000
28938430A5K27GA000081S002000FNM   0001349600Y
28938430XBK27GA00017I002000
28938438XCK27GA00005O002000
28938446X1K27GA0000CP002000
28938463X1K27GA0000CQ002000
28938464A3K27G60000DEB002000CTSH  0000110000Y
28938479X3K27G60000D4002000
28938481X7K27GA00007H002000
28938496XBK27GA00017J002000
28938501X3K27G60000D5002000
28938505A5K27GA000082S002000GM    0000226800Y
28938512X3K27G60000D6002000
28938519X3K27G60000D7002000
28938521XBK27GA00017K002000
28938531X3K27G60000DB002000
28938556A7K27GA00007IB002000LMT   0000407300Y
28938561X1K27GA0000CS002000
28938597ACK27GA00005PB002000WYE   0000159000Y
28938612A1K27GA0000CTB002000AFL   0000249100Y
28938619ABK27GA00017LB002000UTX   0000268300Y
28938632X1K27GA0000A9002000
28938657A1K27GA0000CUS002000AFL   0001514500Y
28938661A1K27GA0000CVB002000ABT   0000202900Y
28938678A2K27G60000D9B002000AZN   0000422700Y
28938694X2K27G60000D1002000
28938700A2K27G60000DAS002000BA    0001579300Y
28938710A2K27G60000DBS002000BA    0001578500Y
28938716A2K27G60000DCS002000BBT   0001372700Y
28938720X2K27G60000D8002000
28938731X3K27G60000DA002000
28938738A2K27G60000DDS002000CAG   0001332100Y
28938745X3K27G60000DC002000
28938750A2K27G60000DES002000BBT   0001371900Y
28938759X3K27G60000DD002000
28938782A3K27G60000DFS002000DAL   0000084500Y
28938788A3K27G60000DGB002000DE    0000793600Y
28939194XAK27GA0000E4001000
28939194AAK27GA0000E4B001000SPY   0001425800Y
28939194XAK27GA0001B2003000
28939194XAK27GA0000F2000500
28939194AAK27GA0000F2B000500SPY   0001425800Y
28939194X4K27GA0000I9000200
28939194AAK27GA0001BNB003000SPY   0001425700Y
28939194XAK27GA0001AZ003000
28939194XAK27GA0001B3003000
28939194XAK27GA0000FD000500
28939194AAK27GA0000FDB000500SPY   0001425800Y
28939194XAK27GA0000E5001000
28939194AAK27GA0000E5S001000SPY   0001426400Y
28939194XAK27GA0000O6000500
28939194AAK27GA0000O6S000500SPY   0001426400Y
28939194XAK27GA0001B0003000
28939194AAK27GA0001BOB003000SPY   0001425700Y
28939194XAK27GA00015B001000
28939194XAK27GA0001B5001000
28939194XAK27GA0001B1001000
28939195AAK27GA0001BPB002000SPY   0001425600Y
28939195AAK27GA0001BQS000500SPY   0001426300Y
28939195X9K27G60000G6002000
28939195A9K27G60000G6B002000QQQQ  0000495800Y
28939195X9K27G60000G3002000
28939195A9K27G60000G3S002000QQQQ  0000496400Y
28939196AAK27GA0001BRS003000SPY   0001426600Y
28939196X4K27GA0000ID000200
28939196A4K27GA0000IDS000200DIA   0001299400Y
28939196AAK27GA0001BSS003000SPY   0001426600Y
28939196ABK27GA00017MB001000SSO   0000764500Y
28939196AAK27GA0001BTS001000SPY   0001426400Y
28939196AAK27GA0001BUS001000SPY   0001426200Y
28939197AAK27GA0001BVS000500SPY   0001426400Y
28939197XAK27GA0001BB002500
28939198XAK27GA0001BA000500
28939198AAK27GA0001BWB000500SPY   0001425600Y
28939198AAK27GA0001BXB002500SPY   0001425600Y
28939198XAK27GA0001BF002500
28939198XAK27GA0001BL005000
28939198AAK27GA0001BYS000500SPY   0001426100Y
28939199XAK27GA0000E5001000
28939199AAK27GA0000E5S001000SPY   0001426000Y
28939199AAK27GA0001BZS005000SPY   0001426200Y
28939200X4K27GA0000DB000100
28939200A4K27GA0000JES000200DIA   0001299500Y
28939201X3K27G60000AS000100
28939202A4K27GA0000JFB000100DXD   0000499000Y
28939202A3K27G60000DHS000100DDM   0000802800Y
28939206A6K27GA0000D2B002000IWM   0000736800Y
28939206X6K27GA00008L002000
28939224X6K27GA00005F000500
28939224A6K27GA00005FB000500IWM   0000736900Y
28939224X6K27GA0000BI002000
28939227XBK27GA0000VR000100
28939227ABK27GA00017NB000100UWM   0000543000Y
28939227XBK27GA000174000100
28939227ABK27GA00017OS000100TWM   0000701600Y
28939227AAK27GA0001C0B002000SPY   0001425600Y
28939228A9K27G60000SDB002000QQQQ  0000495600Y
28939228XAK27GA0000F7000500
28939228AAK27GA0000F7B000500SPY   0001425800Y
28939228XAK27GA0001BY000500
28939228AAK27GA0001BYS000500SPY   0001426500Y
28939228XAK27GA0000E5001000
28939228AAK27GA0000E5S001000SPY   0001426400Y
28939229XAK27GA00016S001000
28939228X6K27GA00009H002000
28939228A6K27GA0000D3S002000IWM   0000737900Y
28939230X9K27G60000S8001000
28939230A9K27G60000SEB001000QLD   0000889600Y
28939229X6K27GA00005F000500
28939229A6K27GA00005FB000500IWM   0000736500Y
28939230XAK27GA00015A001000
28939230XAK27GA0001BY000500
28939230AAK27GA0001BYS000500SPY   0001426100Y
28939230AAK27GA0001C1B001000SPY   0001425800Y
28939232XBK27GA00017G001000
28939231XAK27GA0000QA001000
28939231AAK27GA0001C2S001000SDS   0000548600Y
28939232ABK27GA00017PB001000SSO   0000764800Y
28939232XBK27GA00017N000100
28939232XBK27GA00017O000100
28939232A9K27G60000SFB001000QQQQ  0000495400Y
28939232A9K27G60000SGB001000QQQQ  0000495500Y
28939233X9K27G60000SF001000
28939233X9K27G60000SG001000
28939234ABK27GA00017QS000100TWM   0000701800Y
28939232X6K27GA00005F000500
28939232A6K27GA00005FB000500IWM   0000736900Y
28939234ABK27GA00017RB000100UWM   0000543000Y
28939235XBK27GA00017Q000100
28939235ABK27GA00017SS000100TWM   0000701600Y
28939239X9K27G60000SE001000
28939239XBK27GA0000YC001000
28939239A9K27G60000SHB001000QLD   0000889700Y
28939239A9K27G60000SIS000100QID   0000382000Y
28939239A9K27G60000SJB001000QQQQ  0000495500Y
28939239XAK27GA00016V000100
28939239A9K27G60000SKB001000QQQQ  0000495400Y
28939239XAK27GA00016W001000
28939240XAK27GA0001BU001000
28939241ABK27GA00017TS001000SSO   0000765700Y
28939241AAK27GA0001C3B001000SDS   0000547300Y
28939243X9K27G60000SJ001000
28939243X9K27G60000SK001000
28939242X6K27GA00005F000500
28939242A6K27GA00005FB000500IWM   0000736500Y
28939250X9K27G60000PE002000
28939250X9K27G60000F8003200
28939250A9K27G60000F8S003200QQQQ  0000496500Y
28939249X6K27GA00005F000500
28939249A6K27GA00005FB000500IWM   0000736900Y
28939251A9K27G60000SLB002000QQQQ  0000495900Y
28939252X9K27G60000RD001000
28939250X6K27GA00005F000500
28939250A6K27GA00005FB000500IWM   0000736500Y
28939252A9K27G60000SMB001000QLD   0000889600Y
28939254A9K27G60000SNB001000QQQQ  0000495400Y
28939252X6K27GA00005F000500
28939252A6K27GA00005FB000500IWM   0000736900Y
28939254X9K27G60000SN001000
28939256A9K27G60000SOB001000QQQQ  0000495400Y
28939255X6K27GA00005F000500
28939255A6K27GA00005FB000500IWM   0000736500Y
28939262XAK27GA0001AP001000
28939262AAK27GA0001C4S001000SPY   0001426300Y
28939261X6K27GA00005F000500
28939261A6K27GA00005FB000500IWM   0000736900Y
28939261X6K27GA00002A000500
28939261A6K27GA00002AS000500IWM   0000737500Y
28939263X9K27G60000SO001000
28939264AAK27GA0001C5S001000SPY   0001426300Y
28939263X6K27GA00002A000500
28939263A6K27GA00002AS000500IWM   0000737100Y
28939270X6K27GA00003L000100
28939271ABK27GA00017US000100UWM   0000544000Y
28939278XBK27GA00017M001000
28939278ABK27GA00017VB001000SSO   0000764600Y
28939292A8K27G600005US000500MZZ   0000493600Y
28939292X8K27G600005F000100
28939292A8K27G600005VB000100MVV   0000806700Y
28939336XAK27GA0000F7000500
28939336AAK27GA0000F7B000500SPY   0001425900Y
28939336XAK27GA0001C1001000
28939336AAK27GA0001C1B001000SPY   0001425900Y
28939344X6K27GA00002A000500
28939344A6K27GA00002AS000500IWM   0000737500Y
28939349X3K27G60000CK002000
28939354X9K27G60000R1002000
28939384XBK27GA00017U000100
28939384XBK27GA000175000100
28939383A6K27GA0000D4S002000IWM   0000737500Y
28939386ABK27GA00017WS000100UWM   0000544100Y
28939384A6K27GA0000D5S000100IWM   0000737700Y
28939389X6K27GA0000D5000100
28939400X4K27GA0000IE000200
28939400A4K27GA0000IEB000200DIA   0001299000Y
28939399A6K27GA0000D6B002000IWM   0000736900Y
28939400X6K27GA00009O002000
28939401A4K27GA0000JGS000100DOG   0000598200Y
28939401A4K27GA0000JHS000100DXD   0000499900Y
28939401X4K27GA0000DW000100
28939402X3K27G600009W000100
28939402A3K27G60000DIB000100DDM   0000801500Y
28939409A6K27GA0000D7B002000IMCL  0000352100Y
28939424X2K27G60000D4002000
28939439X7K27GA00007I002000
28939440A8K27G600005WS000500MZZ   0000493500Y
28939440X8K27G600005M000100
28939440X8K27G600003O000500
28939440A8K27G600005XB000100MVV   0000806800Y
28939444X5K27GA000081002000
28939452XBK27GA000179002000
28939456XBK27GA00017B002000
28939463AAK27GA0001C6B002000SPLS  0000078100Y
28939466XBK27GA00017L002000
28939483AAK27GA0001C7B000500SPY   0001425700Y
28939483XAK27GA0001BW000500
28939484XCK27GA00004B002000
28939490XCK27GA00005P002000
28939509X1K27GA0000CV002000
28939529X2K27G60000DA002000
28939532X1K27GA0000A4002000
28939539X2K27G60000D5002000
28939546X2K27G60000DC002000
28939548X1K27GA0000CT002000
28939554X2K27G60000D6002000
28939558X2K27G60000DD002000
28939558X1K27GA0000CU002000
28939564X2K27G600009O002000
28939589X2K27G60000DB002000
28939589X2K27G60000DE002000
28939589X2K27G60000CJ002000
28939595X2K27G60000D7002000
28939607X3K27G60000D8002000
28939607AAK27GA0001C8B002500SPY   0001425700Y
28939607AAK27GA0001C9B005000SPY   0001425700Y
28939608XAK27GA0001BX002500
28939608XAK27GA0001BG005000
28939623A5K27GA000083S002000FNM   0001345600Y
28939622A7K27GA00007JB002000LMT   0000411100Y
28939640X5K27GA00006S000100
28939642A5K27GA000084B000100FXP   0000652100Y
28939643ABK27GA00017XB002000UTX   0000271100Y
28939645ABK27GA00017YS002000UTX   0001525600Y
28939651ABK27GA00017ZS002000UTX   0001524800Y
28939666ACK27GA00005QB002000WYE   0000159400Y
28939671A1K27GA0000CWB002000ABT   0000205300Y
28939675A1K27GA0000CXB002000AFL   0000250200Y
28939682A1K27GA0000CYS002000ALL   0000523700Y
28939686A1K27GA0000CZS002000AFL   0001511700Y
28939704A2K27G60000DFB002000BBT   0000123800Y
28939716A3K27G60000DJB002000COH   0000129300Y
28939724A2K27G60000DGS002000CAG   0001326400Y
28939730A3K27G60000DKS002000COH   0001377900Y
28939731AAK27GA0001CAS000500SPY   0001426200Y
28939736A3K27G60000DLS002000COH   0001377100Y
28939742A3K27G60000DMB002000CVS   0000155600Y
28939750A3K27G60000DNB002000CVS   0000156400Y
28939753A3K27G60000DOS002000CVS   0001403100Y
28939762A3K27G60000DPS002000CVS   0001402300Y
28939769A3K27G60000DQS002000DD    0001426500Y
28939784A3K27G60000DRS002000DE    0000837600Y
28939784A3K27G60000DSB002000DD    0000463000Y
28939883XAK27GA0001C3001000
28939883XBK27GA00017T001000
28939885AAK27GA0001CBB001000SDS   0000547200Y
28939885ABK27GA000180S001000SSO   0000765800Y
28940046AAK27GA0001CCS002500SPY   0001426200Y
28940060X5K27GA000084000100
28940062A5K27GA000085B000100FXP   0000651800Y
28940347X9K27G60000F8003200
28940347A9K27G60000F8S003200QQQQ  0000496000Y
28940351X6K27GA0000CV002000
28940356X1K27GA0000AJ002000
28940362A3K27G60000DTB002000CELG  0000502800Y
28940378A2K27G60000DHB002000BMY   0000077400Y
28940377X5K27GA000083002000
28940430A9K27G60000SPB002000PETM  0000210200Y
28940453X5K27GA00007K002000
28940459XBK27GA00017Y002000
28940465XCK27GA00005Q002000
28940469XCK27GA000054002000
28940473X1K27GA0000CX002000
28940476X7K27GA00006B002000
28940476X1K27GA0000CZ002000
28940489X7K27GA00007J002000
28940492X2K27G60000CV002000
28940496X2K27G60000CR002000
28940495A5K27GA000086S002000FNM   0001340100Y
28940496X3K27G60000DK002000
28940503X3K27G60000DM002000
28940512X3K27G60000DO002000
28940516X3K27G60000DQ002000
28940521A7K27GA00007KB002000LMT   0000413300Y
28940524ABK27GA000181S002000TGT   0000616400Y
28940531XBK27GA00017X002000
28940533ABK27GA000182S002000TGT   0000617200Y
28940542ABK27GA000183B002000UTX   0000272300Y
28940544X5K27GA000085000100
28940545XBK27GA00017Z002000
28940546A5K27GA000087B000100FXP   0000651000Y
28940561ACK27GA00005RS002000WMT   0000580900Y
28940590A1K27GA0000D0B002000ABT   0000206000Y
28940595AAK27GA0001CDS002500SPY   0001426100Y
28940596XAK27GA0001CC002500
28940608ACK27GA00005SB002000WYE   0000161400Y
28940617X1K27GA0000CW002000
28940621A2K27G60000DIS002000BA    0001573100Y
28940634A2K27G60000DJB002000BBT   0000124000Y
28940640A1K27GA0000D1S002000ACN   0000406800Y
28940648A2K27G60000DKS002000BBT   0001363600Y
28940661A2K27G60000DLB002000CAG   0000081900Y
28940661A1K27GA0000D2B002000AFL   0000252800Y
28940667A2K27G60000DMS002000CAG   0001322400Y
28940682A2K27G60000DNB002000CAT   0000820100Y
28940681A1K27GA0000D3S002000AFL   0001507300Y
28940689X2K27G60000CW002000
28940734A2K27G60000DOS002000BA    0001572300Y
28940742A2K27G60000DPS002000BBT   0001362800Y
28940745X2K27G60000DG002000
28940750X3K27G60000DL002000
28940754X3K27G60000DN002000
28940759X3K27G60000DP002000
28940810A9K27G60000SQB001000QQQQ  0000495400Y
28940810A9K27G60000SRB001000QQQQ  0000495500Y
28941034ABK27GA000184B000500TSEM  0000011500Y
28941251X4K27GA0000JB000100
28941251A4K27GA0000JIS000100DRYS  0001074900Y
28941277X4K27GA0000JI000100
28941277P4K27GA0000JKB000100DRYS  0001074000000A101NJERG
28941361A6K27GA0000D8S002000IMCL  0000508200Y
28941367X5K27GA000086002000
28941416A5K27GA000088S002000FNM   0001336100Y
28941426X3K27G6000098002000
28941431X5K27GA00006H002000
28941433A5K27GA000089B002000GM    0000181400Y
28941434X7K27GA00007K002000
28941437X3K27G60000DE002000
28941456XBK27GA000183002000
28941470X1K27GA0000D0002000
28941471A1K27GA0000D4B002000APOL  0000414500Y
28941492A7K27GA00007LS002000KSS   0000504200Y
28941497X2K27G600007P002000
28941509X2K27G60000DI002000
28941516X2K27G60000DK002000
28941519X2K27G6000084002000
28941525X2K27G60000DM002000
28941536A7K27GA00007MB002000LMT   0000417100Y
28941553XCK27GA00005S002000
28941556X3K27G60000DJ002000
28941582X3K27G60000CZ002000
28941592ABK27GA000185S002000UTX   0001518700Y
28941601ACK27GA00005TB002000WYE   0000161800Y
28941607ABK27GA000186B002000UTX   0000275100Y
28941609ACK27GA00005US002000WYE   0000471700Y
28941615X1K27GA0000D2002000
28941621A1K27GA0000D5B002000AFL   0000253900Y
28941621X1K27GA0000D3002000
28941632A1K27GA0000D6S002000AFL   0001504600Y
28941637ABK27GA000187S002000UTX   0001517900Y
28941646A2K27G60000DQB002000AXP   0000421300Y
28941645A1K27GA0000D7B002000ABT   0000208400Y
28941656X2K27G60000DO002000
28941662X2K27G60000DF002000
28941665A2K27G60000DRB002000BDX   0000778100Y
28941674X2K27G60000DP002000
28941689A3K27G60000DUS002000COH   0001368800Y
28941691A2K27G60000DSB002000AXP   0000422100Y
28941697X2K27G60000A8002000
28941703A3K27G60000DVB002000CVS   0000157900Y
28941711A2K27G60000DTB002000BDX   0000778900Y
28941711XAK27GA00018B000800
28941716A3K27G60000DWS002000CVS   0001394500Y
28941716AAK27GA0001CEB000700SPY   0001419900Y
28941730A3K27G60000DXS002000DD    0001418100Y
28941730A2K27G60000DUB002000CAG   0000083400Y
28941752A3K27G60000DYB002000DHI   0000137800Y
28941753A2K27G60000DVS002000CAG   0001316700Y
28941768A3K27G60000DZB002000COH   0000132100Y
28941797X3K27G60000D3002000
28941806A3K27G60000E0S002000COH   0001368000Y
28941845A1K27GA0000D8B000100AAPL  0001828700Y
28942347X1K27GA0000CA002000
28942363XAK27GA0001BM002000
28942366X2K27G60000DH002000
28942368X9K27G60000HG001000
28942380X1K27GA0000BZ002000
28942380X5K27GA00006Y002000
28942416X5K27GA000088002000
28942415X7K27GA00006V002000
28942423X7K27GA00007M002000
28942449XBK27GA000185002000
28942455XBK27GA000186002000
28942476A3K27G60000E1S002000COST  0000743600Y
28942476XBK27GA000187002000
28942475XCK27GA000057002000
28942482XCK27GA00005T002000
28942499X1K27GA0000D7002000
28942501X1K27GA0000D5002000
28942510X1K27GA0000D6002000
28942523A3K27G60000E2B002000CTSH  0000113500Y
28942524X2K27G60000DJ002000
28942535A5K27GA00008AS002000FNM   0001330500Y
28942537X2K27G600008J002000
28942547X2K27G60000DL002000
28942554X3K27G60000DU002000
28942564X3K27G60000DV002000
28942608ACK27GA00005VB002000WYE   0000163800Y
28942628X3K27G60000DW002000
28942630A1K27GA0000D9B002000AFL   0000256500Y
28942632X3K27G60000DX002000
28942644X2K27G60000A7002000
28942653A5K27GA00008BB002000GS    0001819700Y
28942659A7K27GA00007NB002000LMT   0000419300Y
28942667X2K27G60000AC002000
28942675X2K27G60000DV002000
28942682A1K27GA0000DAS002000AFL   0001500200Y
28942684ABK27GA000188B002000UTX   0000276300Y
28942688X3K27G60000E0002000
28942711A1K27GA0000DBB002000ABT   0000209000Y
28942712A2K27G60000DWS002000BA    0001566100Y
28942727A2K27G60000DXB002000BBT   0000126700Y
28942739A2K27G60000DYB002000BA    0000855000Y
28942750A2K27G60000DZS002000BBT   0001353600Y
28942750A2K27G60000E0S002000BA    0001566900Y
28942762A2K27G60000E1S002000BBT   0001354400Y
28942762A2K27G60000E2S002000BK    0000475200Y
28942775A2K27G60000E3S002000BDX   0000900000Y
28942776A3K27G60000E3B002000CVS   0000159900Y
28942789A2K27G60000E4S002000CAG   0001312600Y
28942797A3K27G60000E4S002000CVS   0001389300Y
28942801A3K27G60000E5B002000COH   0000132300Y
28943361XAK27GA0001C6002000
28943362X5K27GA00008A002000
28943396X7K27GA00007N002000
28943404A2K27G60000E5B002000BMY   0000079200Y
28943405XBK27GA000188002000
28943424X1K27GA00007S002000
28943427X1K27GA0000DB002000
28943437XAK27GA0001BK002000
28943446X2K27G60000E0002000
28943455A1K27GA0000DCS002000AMGN  0000475000Y
28943463X2K27G60000E1002000
28943483A5K27GA00008CS002000GG    0000434300Y
28943490X2K27G60000E4002000
28943491AAK27GA0001CFS000500SPY   0001426100Y
28943491XAK27GA0001CA000500
28943492AAK27GA0001CGB002000SHLD  0000783800Y
28943492XCK27GA00005V002000
28943503A5K27GA00008DS002000FNM   0001326600Y
28943509X9K27G60000F8003200
28943509A9K27G60000F8S003200QQQQ  0000496500Y
28943510X9K27G60000EU002000
28943510A9K27G60000EUB002000QQQQ  0000495900Y
28943528A1K27GA0000DDS002000APOL  0000527400Y
28943529A7K27GA00007OB002000LMT   0000423100Y
28943540X1K27GA0000D9002000
28943554X1K27GA0000DA002000
28943562A7K27GA00007PB002000LPNT  0000209200Y
28943581X2K27G60000DW002000
28943596X2K27G60000DZ002000
28943595ABK27GA000189B002000UTX   0000279100Y
28943597ABK27GA00018AS002000UTX   0001511800Y
28943598ABK27GA00018BS002000UTX   0001511000Y
28943618ACK27GA00005WB002000WMT   0000541900Y
28943634ACK27GA00005XB002000WYE   0000164200Y
28943635A1K27GA0000DEB002000ABT   0000211400Y
28943653X2K27G60000DU002000
28943664A1K27GA0000DFB002000AFL   0000257600Y
28943675A1K27GA0000DGS002000AFL   0001497400Y
28943685X3K27G60000DZ002000
28943697A2K27G60000E6B002000BK    0000430400Y
28943717A2K27G60000E7B002000BBT   0000126800Y
28943722X3K27G60000E3002000
28943731X3K27G60000E4002000
28943732A4K27GA0000JLB000100DXD   0000499300Y
28943739A2K27G60000E8B002000BNI   0001063600Y
28943741A2K27G60000E9S002000BNI   0001128700Y
28943743A2K27G60000EAB002000CAG   0000083900Y
28943754A3K27G60000E6S002000COH   0001359800Y
28943755A2K27G60000EBS002000CAG   0001306900Y
28943770A3K27G60000E7S002000COH   0001359000Y
28943770A3K27G60000E8B002000CVS   0000160300Y
28943785A3K27G60000E9S002000CVS   0001385800Y
28943785A3K27G60000EAB002000DAL   0000019700Y
28943835ABK27GA00018CS001000SSO   0000765700Y
28943835XBK27GA000180001000
28943835AAK27GA0001CHB001000SDS   0000547300Y
28943835XAK27GA0001CB001000
28943840E4K27GA0000HI00010000004AQ0000A
28943840E4K27GA0000JC00010000004AQ0000B
28943841A4K27GA0000JNS000100DRYS  0001074900Y
28944359X5K27GA00008D002000
28944402XAK27GA000125002000
28944403A5K27GA00008ES002000FNM   0001321000Y
28944406X4K27GA0000GO002000
28944417X5K27GA00007R002000
28944426X9K27G60000SC002000
28944428XBK27GA000182002000
28944429X7K27GA00007O002000
28944433XBK27GA00018A002000
28944448XCK27GA00005X002000
28944449XBK27GA000181002000
28944449AAK27GA0001CIB002000SPLS  0000081300Y
28944453X1K27GA0000DF002000
28944462X1K27GA0000DG002000
28944465XBK27GA000189002000
28944480XAK27GA0001B6001000
28944480AAK27GA0001CJB001000SPY   0001425700Y
28944485XBK27GA00018B002000
28944488X3K27G60000E5002000
28944489A1K27GA0000DHB002000APPX  0000097900Y
28944499X3K27G60000E6002000
28944516X3K27G60000E8002000
28944519X3K27G60000E9002000
28944533A7K27GA00007QB002000LMT   0000425300Y
28944532ACK27GA00005YB002000WYE   0000166300Y
28944540AAK27GA0001CKB002000SNDK  0000245900Y
28944547X1K27GA0000DE002000
28944586A1K27GA0000DIB002000AFL   0000260200Y
28944593X2K27G60000DX002000
28944599X2K27G60000EB002000
28944603X3K27G60000E7002000
28944610A1K27GA0000DJS002000AFL   0001493000Y
28944620A2K27G60000ECS002000BA    0001559900Y
28944629A2K27G60000EDS002000BBT   0001344400Y
28944640A2K27G60000EEB002000CAG   0000085300Y
28944649A3K27G60000EBB002000COH   0000135100Y
28944653P4K27GA0000JOS000100DXD   0000499800000I000HV2O9
28944658A3K27G60000ECB002000CVS   0000162300Y
28944665A3K27G60000EDS002000CVS   0001380700Y
28944675ABK27GA00018DB002000UTX   0000280300Y
28944697A1K27GA0000DKB002000ABT   0000212100Y
28944723A2K27G60000EFS002000BA    0001560700Y
28944733A2K27G60000EGS002000BBT   0001345200Y
28944745A2K27G60000EHS002000CAG   0001302900Y
28944764A3K27G60000EEB002000DAL   0000019100Y
28944775A3K27G60000EFS002000DD    0001405600Y
28944782A3K27G60000EGS002000DHI   0000159900Y
28945112XAK27GA0000EB001000
28945112AAK27GA0000EBB001000SPY   0001425900Y
28945112XAK27GA0001BY000500
28945112AAK27GA0001BYS000500SPY   0001426500Y
28945112XAK27GA000176002000
28945113XAK27GA0001CH001000
28945113XBK27GA00018C001000
28945113XAK27GA0001BY000500
28945113AAK27GA0001BYS000500SPY   0001426100Y
28945114XAK27GA0001BZ005000
28945114AAK27GA0001CLS005000SPY   0001426400Y
28945114AAK27GA0001CMB001000SDS   0000547200Y
28945114XAK27GA0001CF000500
28945115ABK27GA00018ES001000SSO   0000765800Y
28945115XAK27GA0001CD002500
28945115AAK27GA0001CNS000500SPY   0001426200Y
28945115XAK27GA0001BY000500
28945115AAK27GA0001BYS000500SPY   0001426500Y
28945115AAK27GA0001COS002500SPY   0001426200Y
28945116XAK27GA0001C8002500
28945127A6K27GA0000D9B002000IWM   0000736900Y
28945127X6K27GA0000B7002000
28945136X9K27G60000OM005000
28945136X9K27G60000OL005000
28945136A9K27G60000SSB005000QQQQ  0000495900Y
28945136A9K27G60000STB005000QQQQ  0000495900Y
28945136X4K27GA0000BT000100
28945136X4K27GA0000JL000100
28945137X3K27G60000DH000100
28945142XAK27GA00010S003000
28945142XAK27GA00013L002000
28945142AAK27GA00013LB002000SPY   0001425900Y
28945142XAK27GA0000O8000500
28945142AAK27GA0000O8S000500SPY   0001426500Y
28945143XAK27GA0000E6001000
28945143AAK27GA0000E6S001000SPY   0001426500Y
28945143XAK27GA0000FG000500
28945143AAK27GA0000FGB000500SPY   0001425900Y
28945143XAK27GA0000Q5003000
28945143X9K27G60000G5002000
28945143A9K27G60000G5S002000QQQQ  0000496500Y
28945143XAK27GA0000F5000500
28945143AAK27GA0000F5B000500SPY   0001426000Y
28945143XAK27GA0000FI000500
28945143AAK27GA0000FIB000500SPY   0001426000Y
28945143XAK27GA0000QB000500
28945143AAK27GA0000QBS000500SPY   0001426600Y
28945143XAK27GA0000NY000500
28945143AAK27GA0000NYS000500SPY   0001426600Y
28945143XAK27GA00010T003000
28945143XAK27GA00015R000400
28945143XAK27GA0000E8001000
28945143AAK27GA0000E8B001000SPY   0001426000Y
28945143XAK27GA00015S001000
28945143XAK27GA00013T002000
28945143AAK27GA00013TB002000SPY   0001426000Y
28945143AAK27GA0001CPB001000SPY   0001426000Y
28945143AAK27GA0001CQB003000SPY   0001425900Y
28945143XAK27GA0000Q3003000
28945143AAK27GA0001CRB003000SPY   0001425900Y
28945143AAK27GA0001CSS002000SPY   0001427500Y
28945144AAK27GA0001CTS003000SPY   0001426800Y
28945145XAK27GA0001CO002500
28945145XAK27GA0001CN000500
28945145XAK27GA00015V001000
28945145AAK27GA0001CUS003000SPY   0001426800Y
28945145AAK27GA0001CVS001000SPY   0001426500Y
28945146A3K27G60000EHS000100DDM   0000803000Y
28945146X8K27G600005P000500
28945145XAK27GA0001C5001000
28945145XAK27GA0000PX000100
28945146XBK27GA00017P001000
28945146X8K27G600005Q000100
28945145X4K27GA0000ID000200
28945146X4K27GA00007C000200
28945146A4K27GA00007CB000200DIA   0001299000Y
28945146X4K27GA0000J2000200
28945146ABK27GA00018FB001000SSO   0000764900Y
28945146XAK27GA0001BP001000
28945146XAK27GA0001C4001000
28945146AAK27GA0001CWB002000SPY   0001425800Y
28945146AAK27GA0001CXS000100SH    0000618700Y
28945147AAK27GA0001CYS001000SPY   0001426600Y
28945148X3K27G60000AN000100
28945146X6K27GA0000B6000500
28945146A6K27GA0000B6B000500IWM   0000737000Y
28945148A3K27G60000EIB000100DDM   0000801600Y
28945147XAK27GA0000E9001000
28945147AAK27GA0000E9S001000SPY   0001426600Y
28945147AAK27GA0001CZS001000SPY   0001426400Y
28945148A8K27G600005YB000500MZZ   0000491200Y
28945148XBK27GA00017V001000
28945148ABK27GA00018GB001000SSO   0000764700Y
28945148AAK27GA0001D0S001000SPY   0001426400Y
28945149A8K27G600005ZS000100MVV   0000809900Y
28945148A4K27GA0000JPS000200DIA   0001299600Y
28945149XBK27GA0000X0000100
28945149ABK27GA00018HB000100UWM   0000543100Y
28945149XBK27GA00017S000100
28945149ABK27GA00018IS000100TWM   0000701400Y
28945150X4K27GA000093000100
28945150X3K27G60000EH000100
28945150A4K27GA0000JQS000200DIA   0001299700Y
28945152A3K27G60000EJS000100DDM   0000803100Y
28945152A4K27GA0000JRB000100DXD   0000498900Y
28945152X6K27GA0000B6000500
28945152A6K27GA0000B6B000500IWM   0000736600Y
28945154X6K27GA0000B6000500
28945154A6K27GA0000B6B000500IWM   0000737000Y
28945157X4K27GA00007C000200
28945157A4K27GA00007CB000200DIA   0001299100Y
28945173X9K27G60000G4002000
28945173A9K27G60000G4B002000QQQQ  0000495900Y
28945174X9K27G60000M5002000
28945174X9K27G60000EN002000
28945174A9K27G60000ENS002000QQQQ  0000496300Y
28945175A9K27G60000SUB004000QQQQ  0000495700Y
28945175X9K27G60000JH002000
28945173X6K27GA0000CZ002000
28945175X9K27G60000JI002000
28945175AAK27GA0001D1B002000SPY   0001425900Y
28945180X4K27GA0000BF000100
28945180X4K27GA0000IR000100
28945180X3K27G60000EJ000100
28945181A4K27GA0000JSB000100DOG   0000596700Y
28945181A4K27GA0000JTB000100DXD   0000498800Y
28945182A3K27G60000EKS000100DDM   0000803200Y
28945200X6K27GA00002B000500
28945200A6K27GA00002BS000500IWM   0000737600Y
28945202XAK27GA0001CZ001000
28945202XAK27GA0001D0001000
28945204A8K27G6000060B000100MVV   0000807000Y
28945204X8K27G600005O000100
28945204AAK27GA0001D2S001000SPY   0001426500Y
28945205X6K27GA00009R002000
28945206X4K27GA0000DX000200
28945206A4K27GA0000DXB000200DIA   0001299200Y
28945205A6K27GA0000DAS002000IWM   0000738000Y
28945208A4K27GA0000JUS000100DXD   0000499800Y
28945208X3K27G60000AQ000100
28945208X4K27GA0000GW000100
28945208A3K27G60000ELB000100DDM   0000801700Y
28945213XBK27GA00017W000100
28945213A6K27GA0000DBB002000IWM   0000737000Y
28945213X6K27GA0000BG002000
28945215ABK27GA00018JS000100UWM   0000544300Y
28945222X8K27G600005Z000100
28945223A8K27G6000061S000100MVV   0000810000Y
28945263XAK27GA0001D2001000
28945264AAK27GA0001D3S001000SPY   0001426600Y
28945265AAK27GA0001D4S001000SPY   0001426600Y
28945276X4K27GA0000IE000200
28945276A4K27GA0000IEB000200DIA   0001299300Y
28945278A4K27GA0000JVS000100DXD   0000499800Y
28945278A4K27GA0000JWS000100DOG   0000598100Y
28945278X4K27GA00008V000100
28945279A3K27G60000EMB000100DDM   0000801800Y
28945279X3K27G60000CG000100
28945278X4K27GA0000H1000100
28945280E4K27GA0000IE00007600004AQ0000C
28945286X9K27G60000F0005000
28945296A9K27G60000SVS005000QQQQ  0000496400Y
28945310X9K27G60000FM005000
28945310X9K27G60000F3003200
28945310A9K27G60000F3B003200QQQQ  0000495900Y
28945311X9K27G60000P9002000
28945312A9K27G60000SWS005000QQQQ  0000496400Y
28945315AAK27GA0001D5B000500SPY   0001425900Y
28945315XAK27GA0001C7000500
28945320X6K27GA00007U000500
28945320A6K27GA00007UB000500IWM   0000737100Y
28945324XBK27GA00018I000100
28945324ABK27GA00018KB000100UWM   0000543300Y
28945324XBK27GA0000Y9000100
28945324ABK27GA00018LS000100TWM   0000701200Y
28945325X4K27GA0000JV000100
28945325A4K27GA0000JVS000100DXD   0000499700Y
28945352AAK27GA0001D6S002000SINA  0000555400Y
28945359XAK27GA00015U001000
28945359XAK27GA00016U000100
28945359XAK27GA0001CM001000
28945360XBK27GA00018E001000
28945360AAK27GA0001D7B001000SPY   0001426000Y
28945359A6K27GA0000DCB002000IWM   0000737000Y
28945359X6K27GA00009J002000
28945361XAK27GA0000QF001000
28945362X2K27G60000E5002000
28945361AAK27GA0001D8S001000SDS   0000548500Y
28945361XBK27GA00018F001000
28945361AAK27GA0001D9B000100SH    0000618000Y
28945361ABK27GA00018MB001000SSO   0000765000Y
28945361AAK27GA0001DAB001000SDS   0000547100Y
28945362ABK27GA00018NS001000SSO   0000766000Y
28945374X3K27G60000E2002000
28945394X8K27G600005C000500
28945394A8K27G6000062S000500MZZ   0000493400Y
28945395X8K27G600005R000100
28945395A8K27G6000063B000100MVV   0000807100Y
28945406XAK27GA0001D7001000
28945406AAK27GA0001D7B001000SPY   0001426100Y
28945408XBK27GA00018G001000
28945408ABK27GA00018OB001000SSO   0000764800Y
28945410X7K27GA00007Q002000
28945419X7K27GA000061002000
28945426XBK27GA00018D002000
28945441A4K27GA0000JYB002000FITB  0000182300Y
28945442X5K27GA00008E002000
28945458X1K27GA0000DK002000
28945470A7K27GA00007RB002000LMT   0000429100Y
28945472X1K27GA00008W002000
28945482X2K27G60000EF002000
28945497X2K27G60000E7002000
28945499A9K27G60000SXB002000PDLI  0000038100Y
28945506X2K27G60000EG002000
28945517AAK27GA0001DBS000500SPY   0001426400Y
28945519X2K27G60000EA002000
28945518AAK27GA0001DCS005000SPY   0001426300Y
28945518XAK27GA0001CL005000
28945519AAK27GA0001DDB002500SPY   0001426000Y
28945527ABK27GA00018PS002000TGT   0000615000Y
28945531X2K27G60000EH002000
28945553X3K27G60000EF002000
28945566ABK27GA00018QB002000UTX   0000283100Y
28945566A5K27GA00008FS002000FNM   0001317100Y
28945594XCK27GA00005Y002000
28945603X1K27GA0000DI002000
28945607X1K27GA0000DJ002000
28945613X2K27G60000EC002000
28945623X2K27G60000ED002000
28945633ABK27GA00018RS002000UTX   0001504100Y
28945641A1K27GA0000DLB002000ABT   0000214500Y
28945643A5K27GA00008GB002000GM    0000180900Y
28945656A2K27G60000EIB002000BBT   0000129500Y
28945660X3K27G60000EC002000
28945659ABK27GA00018SS002000TGT   0000615800Y
28945669X3K27G60000ED002000
28945673ABK27GA00018TS002000UTX   0001504900Y
28945683A2K27G60000EJS002000CAG   0001297200Y
28945683ACK27GA00005ZB002000WYE   0000166600Y
28945694A1K27GA0000DMB002000AFL   0000261300Y
28945701A3K27G60000ENS002000COH   0001350000Y
28945703A1K27GA0000DNS002000AFL   0001490200Y
28945732A3K27G60000EOS002000DD    0001400700Y
28945732A3K27G60000EPB002000COH   0000135200Y
28945743A3K27G60000EQS002000COH   0001350800Y
28945751A3K27G60000ERB002000DE    0000794500Y
28945760A3K27G60000ESB002000CVS   0000162700Y
28945770A3K27G60000ETS002000DE    0000836300Y
28945772A3K27G60000EUS002000CVS   0001377100Y
28945785A3K27G60000EVB002000DHR   0000762500Y
28945840P4K27GA0000JZS000100DIS   0000345700000I000HV2OE
28946025AAK27GA0001DES002500SPY   0001426400Y
28946142P9K27G60000SYB000400PTR   0001430000000I000HV2OK
28946326X1K27GA0000D8000100
28946326A1K27GA0000D8B000100AAPL  0001830100Y
28946348X3K27G60000DT002000
28946355A3K27G60000EWB002000CTSH  0000116900Y
28946373X5K27GA00008F002000
28946381X7K27GA00007R002000
28946431XBK27GA00018T002000
28946433XCK27GA00005Z002000
28946436XBK27GA00018Q002000
28946437X1K27GA0000DM002000
28946439X1K27GA0000DN002000
28946442XBK27GA00018R002000
28946446X2K27G60000DQ002000
28946449A2K27G60000EKB002000BMY   0000081100Y
28946449X2K27G60000BM002000
28946457X1K27GA0000DL002000
28946462X3K27G60000B1002000
28946465X3K27G60000EQ002000
28946472X3K27G60000ES002000
28946476X3K27G60000EU002000
28946477AAK27GA0001DFB000500SPY   0001426000Y
28946477XAK27GA0001D5000500
28946483A7K27GA00007SB002000LMT   0000431300Y
28946485A5K27GA00008HS002000FNM   0001311500Y
28946492A7K27GA00007TB002000MMM   0000765200Y
28946502ABK27GA00018UB002000UTX   0000284300Y
28946532X2K27G60000DS002000
28946537A1K27GA0000DOB002000ABT   0000215200Y
28946548ACK27GA000060B002000WYE   0000168700Y
28946592A1K27GA0000DPB002000AFL   0000263900Y
28946600X2K27G60000EE002000
28946609X2K27G60000EJ002000
28946614X3K27G60000EB002000
28946620X3K27G60000EN002000
28946623A1K27GA0000DQS002000ANF   0000772300Y
28946633A2K27G60000ELS002000BA    0001554500Y
28946640A1K27GA0000DRS002000AFL   0001485800Y
28946648A2K27G60000EMB002000BBT   0000129700Y
28946661X3K27G60000EO002000
28946664A2K27G60000ENS002000BBT   0001336100Y
28946679A2K27G60000EOS002000BA    0001553700Y
28946696A2K27G60000EPS002000BBT   0001335300Y
28946696A2K27G60000EQB002000CAG   0000085800Y
28946711A2K27G60000ERS002000CAG   0001293100Y
28946711A3K27G60000EXB002000CVS   0000164600Y
28946729A3K27G60000EYS002000CVS   0001372000Y
28947350A3K27G60000EZB002000CELG  0000505300Y
28947381XAK27GA0001CG002000
28947383X5K27GA00008H002000
28947384X7K27GA00007S002000
28947430XBK27GA000150002000
28947434XBK27GA00018U002000
28947453XCK27GA000060002000
28947459X1K27GA0000DO002000
28947473X2K27G60000EL002000
28947473X1K27GA0000DP002000
28947479X1K27GA0000DR002000
28947484X2K27G600007S002000
28947490X2K27G60000EN002000
28947495X2K27G60000DR002000
28947497X2K27G60000EO002000
28947500X2K27G60000ER002000
28947511X2K27G60000EI002000
28947512X3K27G60000EP002000
28947512X2K27G60000EP002000
28947513X2K27G60000DT002000
28947518A5K27GA00008IS002000FNM   0001307600Y
28947527X2K27G60000BB002000
28947541A7K27GA00007UB002000LMT   0000435100Y
28947552ABK27GA00018VS002000UTX   0001498000Y
28947559ABK27GA00018WB002000UTX   0000287100Y
28947560ACK27GA000061B002000WYE   0000169100Y
28947581ABK27GA00018XS002000UTX   0001497200Y
28947584X3K27G60000EX002000
28947590X3K27G60000EY002000
28947595A1K27GA0000DSB002000ABT   0000217500Y
28947601A2K27G60000ESB002000AXP   0000423400Y
28947626A2K27G60000ETB002000CAG   0000087300Y
28947637A2K27G60000EUS002000CAG   0001287400Y
28947645A3K27G60000F0B002000COH   0000138000Y
28947654A1K27GA0000DTB002000AFL   0000265000Y
28947661A1K27GA0000DUS002000AFL   0001483100Y
28947662A3K27G60000F1S002000COH   0001340900Y
28947669A2K27G60000EVB002000AXP   0000422600Y
28947676A2K27G60000EWB002000AZN   0000422400Y
28947680A3K27G60000F2S002000DD    0001392300Y
28947680X6K27GA0000D4002000
28947689A3K27G60000F3B002000CCE   0000193700Y
28947693X9K27G60000SU002000
28947696A3K27G60000F4S002000COH   0001341700Y
28947699A3K27G60000F5B002000DHI   0000138600Y
28947709A3K27G60000F6B002000CVS   0000165000Y
28947727A3K27G60000F7S002000CVS   0001368500Y
28947750A3K27G60000F8S002000DD    0001393100Y
28947765A3K27G60000F9S002000DHR   0000814800Y
28947837A9K27G60000SZB002000QQQQ  0000495700Y
28948367X2K27G60000EK002000
28948367XAK27GA0001CI002000
28948384X2K27G60000AG002000
28948395X5K27GA00008I002000
28948409AAK27GA0001DGB002000SHLD  0000786700Y
28948410X7K27GA00007U002000
28948414XBK27GA00018V002000
28948421XCK27GA000061002000
28948429XBK27GA00018W002000
28948452A5K27GA00008JS002000FNM   0001302000Y
28948454X1K27GA0000DT002000
28948465X1K27GA0000DU002000
28948471X2K27G60000EM002000
28948471XBK27GA00018X002000
28948477X2K27G60000EQ002000
28948484X3K27G60000F4002000
28948494X3K27G60000F6002000
28948496X3K27G60000F7002000
28948499X3K27G60000F8002000
28948512ACK27GA000062B002000WYE   0000171100Y
28948518A7K27GA00007VB002000LMT   0000437300Y
28948518X1K27GA0000DS002000
28948528ABK27GA00018YB002000TGT   0000522200Y
28948540ABK27GA00018ZB002000UTX   0000288300Y
28948553A1K27GA0000DVB002000AFL   0000267700Y
28948621X1K27GA0000AB002000
28948625X1K27GA0000C9002000
28948629A1K27GA0000DWS002000AFL   0001478700Y
28948639A2K27G60000EXS002000BA    0001547500Y
28948647A2K27G60000EYB002000BBT   0000132400Y
28948658A1K27GA0000DXB002000ABT   0000218200Y
28948672A4K27GA0000K0B000100DRYS  0001070100Y
28948672A4K27GA0000K1B000100DRYS  0001070100Y
28948684A2K27G60000EZS002000BBT   0001326100Y
28948688A2K27G60000F0S002000BA    0001548300Y
28948699A2K27G60000F1B002000BDX   0000780300Y
28948702A2K27G60000F2S002000BAX   0000638000Y
28948707X2K27G60000EU002000
28948718A2K27G60000F3S002000BBT   0001326900Y
28948734A2K27G60000F4B002000BDX   0000779500Y
28948740A2K27G60000F5B002000CAT   0000821300Y
28948746X3K27G60000F1002000
28948753A2K27G60000F6S002000CAG   0001283400Y
28948771A3K27G60000FAB002000COH   0000138200Y
28948776X3K27G60000F2002000
28948780A3K27G60000FBB002000CVS   0000167000Y
28949081X9K27G60000HI000500
28949081X9K27G60000HJ000500
28949081X9K27G60000HH001000
28949083A9K27G60000T0S001000QQQQ  0000496500Y
28949350X3K27G60000EW002000
28949395X6K27GA0000CG002000
28949396AAK27GA0001DHB002000SPLS  0000084400Y
28949408X5K27GA00008J002000
28949409X6K27GA0000CH002000
28949416X7K27GA00007V002000
28949429XBK27GA00018Z002000
28949433XCK27GA000062002000
28949452X1K27GA0000DX002000
28949454X1K27GA0000DV002000
28949459X1K27GA0000DW002000
28949471X2K27G60000F0002000
28949473X2K27G60000EX002000
28949480XAK27GA0001DC005000
28949481AAK27GA0001DIB005000SPY   0001425900Y
28949481XAK27GA0000E7001000
28949481AAK27GA0000E7B001000SPY   0001426100Y
28949481XAK27GA0001C9005000
28949489X2K27G60000F3002000
28949489X2K27G60000EZ002000
28949491X2K27G60000ET002000
28949492X2K27G600008X002000
28949496X2K27G60000F6002000
28949495X6K27GA00009X002000
28949496A6K27GA0000DDS002000IWM   0000738100Y
28949499X3K27G60000F0002000
28949515X3K27G60000FB002000
28949519A2K27G60000F7B002000BRL   0000376300Y
28949519X3K27G60000EA002000
28949526A2K27G60000F8B002000BMY   0000082900Y
28949537A5K27GA00008KS002000FNM   0001298100Y
28949550A7K27GA00007WB002000LMT   0000441100Y
28949559ABK27GA000190S002000UTX   0001491100Y
28949601X8K27G600005V000100
28949601A8K27G6000064B000100MVV   0000807200Y
28949602ABK27GA000191B002000UTX   0000291100Y
28949609ABK27GA000192S002000UTX   0001490300Y
28949613A1K27GA0000DYB002000ABT   0000220600Y
28949623A1K27GA0000DZB002000ANF   0000724300Y
28949633A1K27GA0000E0B002000ARO   0000301700Y
28949640ACK27GA000063B002000WYE   0000171500Y
28949655A1K27GA0000E1B002000AFL   0000268700Y
28949656A2K27G60000F9S002000CAG   0001277700Y
28949665A1K27GA0000E2S002000AFL   0001475900Y
28949671A3K27G60000FCS002000COH   0001331900Y
28949684A2K27G60000FAB002000BBT   0000132500Y
28949691A3K27G60000FDS002000CVS   0001359000Y
28949698A2K27G60000FBB002000CAG   0000087800Y
28949706A3K27G60000FES002000COH   0001332700Y
28949729A3K27G60000FFB002000CVS   0000167400Y
28949742A3K27G60000FGS002000CVS   0001359800Y
28949756A3K27G60000FHS002000DD    0001384800Y
28949884AAK27GA0001DJS005000SPY   0001426400Y
28950352A3K27G60000FIB002000CTSH  0000120400Y
28950403X5K27GA00008K002000
28950405X7K27GA00006Z002000
28950407X7K27GA00007W002000
28950422X7K27GA00006H002000
28950424XBK27GA00018S002000
28950426XBK27GA000190002000
28950428XCK27GA000063002000
28950433X1K27GA0000E1002000
28950435X1K27GA0000E2002000
28950439XBK27GA00018P002000
28950445X1K27GA0000CJ002000
28950455XBK27GA000191002000
28950458XBK27GA000192002000
28950462X2K27G60000A2002000
28950463XCK27GA00005H002000
28950468X3K27G60000FA002000
28950472X3K27G60000FE002000
28950470XCK27GA00004S002000
28950479X3K27G60000FF002000
28950486X1K27GA0000DY002000
28950489X3K27G60000FG002000
28950496X2K27G60000EY002000
28950502X3K27G60000EE002000
28950505X3K27G60000FH002000
28950513X2K27G60000F9002000
28950516X3K27G60000BE002000
28950519E4K27GA0000K000010000004AQ0000D
28950519E4K27GA0000K100010000004AQ0000E
28950531X3K27G60000FC002000
28950533A6K27GA0000DEB002000JNJ   0000644100Y
28950536P4K27GA0000K3S000100DRYS  0001070700000I000HV2PK
28950537P4K27GA0000K3S000100DRYS  0001070600000I000HV2PL
28950557X3K27G60000FD002000
28950555A6K27GA0000DFS002000JNJ   0000688600Y
28950584A5K27GA00008LS002000FNM   0001292500Y
28950597A7K27GA00007XB002000LMT   0000443300Y
28950606ACK27GA000064B002000WYE   0000173500Y
28950608X8K27G6000061000100
28950608X8K27G600005Y000500
28950609ABK27GA000193B002000UTX   0000292300Y
28950610A8K27G6000065S000100MVV   0000810100Y
28950610A8K27G6000066B000500MZZ   0000491100Y
28950612X8K27G6000065000100
28950614A8K27G6000067S000100MVV   0000810200Y
28950632A1K27GA0000E3B002000AFL   0000271400Y
28950641A1K27GA0000E4B002000ABT   0000221300Y
28950647A1K27GA0000E5S002000AFL   0001471500Y
28950662A2K27G60000FCS002000BA    0001541300Y
28950665A2K27G60000FDS002000BA    0001542100Y
28950675A2K27G60000FES002000BBT   0001316900Y
28950679A2K27G60000FFS002000BBT   0001317700Y
28950688A2K27G60000FGB002000CAG   0000089200Y
28950695A2K27G60000FHS002000BSX   0000152100Y
28950702A2K27G60000FIS002000CAG   0001273600Y
28950705A3K27G60000FJB002000COH   0000141000Y
28950731A3K27G60000FKB002000CVS   0000169400Y
28950738A3K27G60000FLB002000DAL   0000021100Y
28950744A3K27G60000FMS002000DD    0001379800Y
28950759A3K27G60000FNS002000DHI   0000159100Y
28951181XAK27GA0000EX000500
28951181AAK27GA0000EXB000500SPY   0001426100Y
28951181XAK27GA0000FE000500
28951181AAK27GA0000FEB000500SPY   0001426100Y
28951184XAK27GA0001DJ005000
28951184AAK27GA0001DKS005000SPY   0001426600Y
28951190X6K27GA000026000500
28951190A6K27GA000026S000500IWM   0000737700Y
28951193A6K27GA0000DGB002000IWM   0000737100Y
28951193X6K27GA0000AR002000
28951196XAK27GA0001BP001000
28951196AAK27GA0001DLB001000SPY   0001425900Y
28951196XAK27GA0001CJ001000
28951210A6K27GA0000DHB002000IWM   0000737100Y
28951210X6K27GA0000BL002000
28951234XBK27GA00018J000100
28951235ABK27GA000194S000100UWM   0000544400Y
28951299X8K27G600005E000500
28951299X8K27G6000062000500
28951299X8K27G6000063000100
28951299X8K27G6000060000100
28951299X8K27G6000064000100
28951301A8K27G6000068S000500MZZ   0000493400Y
28951301A8K27G6000069B000100MVV   0000807100Y
28951345X1K27GA0000DC002000
28951352X6K27GA0000D8002000
28951370X2K27G60000F8002000
28951410A5K27GA00008MS002000FNM   0001288600Y
28951413X5K27GA00008L002000
28951436X7K27GA00007X002000
28951439XBK27GA000193002000
28951439A7K27GA00007YB002000LMT   0000447100Y
28951445X1K27GA0000E4002000
28951450X1K27GA00008L002000
28951460X2K27G60000FD002000
28951469X2K27G60000FA002000
28951470A7K27GA00007ZS002000MMM   0000814200Y
28951477X2K27G60000FF002000
28951483X2K27G60000C2002000
28951486X2K27G60000CB002000
28951490X2K27G60000FB002000
28951497X2K27G60000FI002000
28951507A8K27G600006AB000100MVV   0000807200Y
28951513X3K27G60000D9002000
28951513ABK27GA000195S002000TGT   0000613400Y
28951516A7K27GA000080B002000KSS   0000458900Y
28951527ABK27GA000196S002000TGT   0000614200Y
28951527ABK27GA000197B002000UTX   0000295100Y
28951541ABK27GA000198S002000UTX   0001484100Y
28951542XCK27GA000064002000
28951548XCK27GA00005J002000
28951555ACK27GA000065B002000WYE   0000173900Y
28951557ABK27GA000199S002000UTX   0001483300Y
28951562A1K27GA0000E6B002000AFL   0000272400Y
28951589A1K27GA0000E7S002000AFL   0001468700Y
28951593A1K27GA0000E8B002000ARO   0000301000Y
28951612A2K27G60000FJS002000CAT   0000867200Y
28951615A3K27G60000FOB002000COH   0000141200Y
28951616ACK27GA000066B002000WMT   0000543100Y
28951623X1K27GA0000E3002000
28951629X1K27GA0000E5002000
28951635A3K27G60000FPS002000COH   0001323700Y
28951635X2K27G600009E002000
28951653X2K27G60000FC002000
28951658A3K27G60000FQB002000CVS   0000169700Y
28951671A3K27G60000FRS002000CVS   0001351100Y
28951671ACK27GA000067S002000WMT   0000579800Y
28951679X2K27G60000FE002000
28951708A1K27GA0000E9B002000ABT   0000223700Y
28951716A2K27G60000FKB002000BBT   0000135200Y
28951722X3K27G60000FK002000
28951726X3K27G60000FM002000
28951732A2K27G60000FLS002000CAG   0001267900Y
28951740A3K27G60000FSB002000CCE   0000194700Y
28952058A8K27G600006BB000100MVV   0000807300Y
28952058A8K27G600006CS000500MZZ   0000493300Y
28952202A5K27GA00008NS000100FXP   0000656800Y
28952210X5K27GA00008N000100
28952399XAK27GA0001DG002000
28952410X2K27G60000AX002000
28952412X7K27GA00007Y002000
28952413X3K27G60000CL002000
28952423X8K27G6000053002000
28952425X5K27GA00008M002000
28952426XBK27GA000197002000
28952439A1K27GA0000EAS002000AMGN  0000472700Y
28952442XBK27GA000199002000
28952457X1K27GA0000E9002000
28952473X2K27G60000ES002000
28952474A6K27GA0000DIS002000IMCL  0000505700Y
28952488X2K27G60000FG002000
28952491XBK27GA000198002000
28952502X2K27G60000FL002000
28952512XCK27GA000065002000
28952516X3K27G60000FJ002000
28952528X1K27GA0000BU002000
28952530X1K27GA0000E6002000
28952532X1K27GA0000E7002000
28952533A2K27G60000FMB002000BMY   0000084800Y
28952537X2K27G60000EV002000
28952545X3K27G60000FP002000
28952555X3K27G60000FQ002000
28952560X3K27G60000FR002000
28952563A5K27GA00008OS002000FNM   0001283000Y
28952583A7K27GA000081B002000LMT   0000449300Y
28952589ABK27GA00019AB002000UTX   0000296300Y
28952607A1K27GA0000EBB002000ABT   0000224300Y
28952609ACK27GA000068B002000WYE   0000175900Y
28952620A1K27GA0000ECB002000ACF   0000120600Y
28952623ACK27GA000069S002000WYE   0000470300Y
28952644A2K27G60000FNS002000BA    0001536000Y
28952646A1K27GA0000EDB002000AFL   0000275100Y
28952658A1K27GA0000EES002000AFL   0001464300Y
28952660A2K27G60000FOB002000BBT   0000135400Y
28952670A2K27G60000FPB002000BA    0000856100Y
28952687A2K27G60000FQS002000BBT   0001308600Y
28952695A2K27G60000FRS002000BA    0001535200Y
28952701A2K27G60000FSB002000BK    0000430000Y
28952707A2K27G60000FTB002000BNI   0001063300Y
28952710A2K27G60000FUS002000BBT   0001307800Y
28952710A2K27G60000FVB002000CAG   0000089700Y
28952720A3K27G60000FTS002000COH   0001318400Y
28952720A2K27G60000FWS002000CAG   0001263900Y
28952736A3K27G60000FUB002000CVS   0000171700Y
28952740A3K27G60000FVB002000DAL   0000020700Y
28952746A3K27G60000FWB002000DD    0000463200Y
28952753A3K27G60000FXS002000DD    0001372300Y
28952771X9K27G60000NA002000
28952771A9K27G60000T1S002000QQQQ  0000496300Y
28952773A9K27G60000T2S002000QQQQ  0000496300Y
28952845AAK27GA0001DMB001000SDS   0000547200Y
28952846XBK27GA00018N001000
28952846ABK27GA00019BS001000SSO   0000765900Y
28952901X6K27GA0000BB002000
28952910X6K27GA0000AW002000
28953142A4K27GA0000K4B000100DRYS  0001070100Y
28953360X3K27G60000EZ002000
28953362X5K27GA00008O002000
28953412X7K27GA000081002000
28953413X5K27GA000071002000
28953420XAK27GA0001DH002000
28953442X8K27G600004Z002000
28953443X3K27G60000FI002000
28953446XBK27GA00019A002000
28953454X4K27GA0000GK002000
28953455XCK27GA000068002000
28953462XAK27GA0001CK002000
28953468X1K27GA0000ED002000
28953473AAK27GA0001DNB002000SHLD  0000789600Y
28953474X1K27GA0000EB002000
28953488X1K27GA0000EE002000
28953489X2K27G60000FN002000
28953495X2K27G60000FQ002000
28953508X2K27G60000CA002000
28953518X2K27G60000FW002000
28953533A3K27G60000FYS002000CMCSK 0000267900Y
28953533X3K27G60000B2002000
28953543X3K27G60000FO002000
28953550A7K27GA000082B002000LMT   0000453100Y
28953581A8K27G600006DB002000NVTL  0000082000Y
28953594X2K27G60000FR002000
28953599X2K27G60000FK002000
28953603X2K27G60000FU002000
28953610X3K27G60000FX002000
28953616ABK27GA00019CB002000UTX   0000299100Y
28953622A2K27G60000FXS002000BRL   0000422700Y
28953630ABK27GA00019DS002000UTX   0001476400Y
28953635A5K27GA00008PS002000FNM   0001279100Y
28953648A1K27GA0000EFB002000ABT   0000226700Y
28953673X3K27G60000FT002000
28953673ABK27GA00019ES002000UTX   0001477200Y
28953684X3K27G60000FU002000
28953686A2K27G60000FYB002000AXP   0000424700Y
28953693ACK27GA00006AB002000WYE   0000176300Y
28953711A1K27GA0000EGS002000ACN   0000407000Y
28953711X3K27G60000DS002000
28953719A1K27GA0000EHB002000AFL   0000276100Y
28953724A2K27G60000FZB002000CAG   0000091200Y
28953730A1K27GA0000EIS002000AFL   0001461600Y
28953742A2K27G60000G0S002000CAG   0001258200Y
28953745A2K27G60000G1B002000AXP   0000423900Y
28953754A3K27G60000FZB002000COH   0000144000Y
28953761A3K27G60000G0S002000COH   0001314700Y
28953774A3K27G60000G1B002000CVS   0000172100Y
28953778A3K27G60000G2S002000CVS   0001341700Y
28953785A3K27G60000G3S002000CVS   0001342500Y
28953829X6K27GA0000DH002000
28954319X4K27GA0000K4000100
28954324P4K27GA0000K4B000100DRYS  0001070100000N4AQ0000F
28954344E1K27GA0000D8000005000N1AQ00006
28954351A3K27G60000G4B002000CELG  0000507800Y
28954405X5K27GA00008P002000
28954407X2K27G60000FM002000
28954433XBK27GA00019E002000
28954443XCK27GA00006A002000
28954460AAK27GA0001DOB002000SPLS  0000087500Y
28954461A5K27GA00008QS002000FNM   0001273500Y
28954467X1K27GA0000EH002000
28954483X1K27GA0000EI002000
28954486A5K27GA00008RB002000GS    0001820800Y
28954498X1K27GA0000BY002000
28954498X1K27GA000091002000
28954507A3K27G60000G5B002000CTSH  0000123800Y
28954519X2K27G60000FO002000
28954529X7K27GA000082002000
28954537X2K27G60000F4002000
28954538X2K27G60000FV002000
28954544A4K27GA0000K5B002000FFIV  0000267600Y
28954545X3K27G60000G0002000
28954562X3K27G60000G1002000
28954576X7K27GA00006G002000
28954591XBK27GA00019C002000
28954591XBK27GA00019D002000
28954593X3K27G60000G3002000
28954602A9K27G60000T3S002000QQQQ  0000496100Y
28954606AAK27GA0001DPB002000SNDK  0000248400Y
28954610X3K27G60000DR002000
28954617ACK27GA00006BB002000WYE   0000178300Y
28954624A7K27GA000083B002000LMT   0000455300Y
28954636X1K27GA0000EF002000
28954643A1K27GA0000EJB002000AFL   0000278800Y
28954651A8K27G600006ES002000NEM   0000503700Y
28954658A1K27GA0000EKS002000AFL   0001457200Y
28954664ABK27GA00019FB002000UTX   0000300300Y
28954670A2K27G60000G2S002000BA    0001529000Y
28954688A2K27G60000G3B002000BBT   0000138000Y
28954688A1K27GA0000ELB002000ABT   0000227400Y
28954702A2K27G60000G4S002000BA    0001529800Y
28954709A2K27G60000G5S002000BBT   0001298600Y
28954713A2K27G60000G6S002000BBT   0001299400Y
28954722X2K27G60000F1002000
28954727A2K27G60000G7S002000BK    0000475500Y
28954734X2K27G600009V002000
28954743X2K27G60000AD002000
28954751A2K27G60000G8S002000CAG   0001254100Y
28954755X2K27G60000G0002000
28954763A3K27G60000G6S002000COH   0001309300Y
28954780A3K27G60000G7S002000CCE   0000239900Y
28954782A3K27G60000G8B002000CVS   0000174100Y
28954787A3K27G60000G9B002000COH   0000144200Y
28954799X3K27G60000G2002000
28954819A3K27G60000GAB002000DD    0000464200Y
28954838A3K27G60000GBS002000DD    0001363200Y
28954845A3K27G60000GCS002000DD    0001364000Y
28954857A4K27GA0000K6B002000DIS   0000331800Y
28955356X1K27GA0000DD002000
28955378X9K27G60000T3002000
28955399X4K27GA0000J6002000
28955404A5K27GA00008SS002000FNM   0001269500Y
28955413X9K27G60000SX002000
28955415X5K27GA00008Q002000
28955425XAK27GA0001DL001000
28955426AAK27GA0001DQS001000SPY   0001426500Y
28955434X7K27GA000083002000
28955437XAK27GA0001DQ001000
28955449AAK27GA0001DRS005000SPY   0001426400Y
28955449XAK27GA0001DK005000
28955454XBK27GA00019F002000
28955457XAK27GA0001DR005000
28955465XCK27GA00006B002000
28955469X1K27GA0000EL002000
28955471X1K27GA0000EJ002000
28955480X1K27GA0000EK002000
28955490X2K27G60000G4002000
28955494X2K27G60000G6002000
28955504X2K27G60000G2002000
28955509X2K27G60000G8002000
28955511X2K27G60000G5002000
28955526X2K27G60000FZ002000
28955527X3K27G60000GC002000
28955537X3K27G60000FZ002000
28955543X3K27G60000G6002000
28955547X3K27G60000G8002000
28955555X3K27G60000GB002000
28955565A2K27G60000G9B002000BMY   0000086600Y
28955594A7K27GA000084B002000LMT   0000459100Y
28955602A7K27GA000085B002000MMM   0000766200Y
28955616ABK27GA00019GS002000UTX   0001470300Y
28955628ACK27GA00006CB002000WYE   0000178700Y
28955630ABK27GA00019HB002000UTX   0000303100Y
28955643ABK27GA00019IS002000UTX   0001469500Y
28955649A1K27GA0000EMB002000AFL   0000279900Y
28955658A1K27GA0000ENB002000ABT   0000229800Y
28955663A1K27GA0000EOS002000AFL   0001454400Y
28955685A1K27GA0000EPS002000ALL   0000523800Y
28955691A1K27GA0000EQB002000APC   0000765400Y
28955697A2K27G60000GAB002000BDX   0000781700Y
28955709A2K27G60000GBB002000BBT   0000138200Y
28955717A2K27G60000GCS002000BDX   0000898800Y
28955731A2K27G60000GDB002000BDX   0000780900Y
28955736A2K27G60000GEB002000CAG   0000091700Y
28955740A2K27G60000GFS002000BNI   0001127500Y
28955747A3K27G60000GDS002000COH   0001305600Y
28955762A2K27G60000GGS002000CAG   0001248400Y
28955761A3K27G60000GEB002000CVS   0000174500Y
28955853AAK27GA0001DSS005000SPY   0001426600Y
28956082EBK27GA00006Z0001000000BAQ00001
28956082ABK27GA00019LS000100UYG   0000322000Y
28956083XAK27GA0000FB000100
28956083PBK27GA00019JS000100UYG   0000320300000I000HV2QM
28956084PBK27GA00019JS000200UYG   0000320300000I000HV2QN
28956084ABK27GA00019MS000100UYG   0000321900Y
28956083A6K27GA0000DJS000100IYF   0000859400Y
28956084X6K27GA00002D000100
28956084A6K27GA0000DKS000100IYF   0000859300Y
28956084X6K27GA000021000100
28956086ABK27GA00019NB000100UYG   0000319700Y
28956085A6K27GA0000DLS000100IYF   0000859200Y
28956085X6K27GA0000DJ000100
28956090XBK27GA00019N000100
28956089X6K27GA00002E000100
28956090AAK27GA0001DTB000100SKF   0001027400Y
28956089A6K27GA0000DMS000100IYF   0000857000Y
28956090A6K27GA0000DNS000100IYF   0000857900Y
28956352X6K27GA0000D7002000
28956405X5K27GA00008S002000
28956405X5K27GA000089002000
28956413X5K27GA00007P002000
28956422X7K27GA000084002000
28956422A1K27GA0000ERS002000APOL  0000525100Y
28956428XBK27GA000196002000
28956431XBK27GA000195002000
28956439XBK27GA00019G002000
28956450XBK27GA00019H002000
28956460XCK27GA00006C002000
28956462XBK27GA00019I002000
28956467X4K27GA0000JQ000200
28956469A4K27GA0000K7S000123DIA   0001299400Y
28956470X1K27GA0000EM002000
28956483X1K27GA0000EN002000
28956484A9K27G60000T4B002000PDLI  0000040400Y
28956483X1K27GA0000EO002000
28956498X1K27GA0000AE002000
28956506X3K27G60000G9002000
28956510X3K27G60000GD002000
28956529X2K27G60000G3002000
28956532X3K27G60000GE002000
28956543X2K27G60000GG002000
28956550X2K27G60000BC002000
28956554A4K27GA0000K8B002000EMR   0000556500Y
28956562X3K27G60000BF002000
28956587X3K27G60000FL002000
28956592A5K27GA00008TS002000FNM   0001264000Y
28956607A7K27GA000086B002000LMT   0000461300Y
28956614ACK27GA00006DB002000WYE   0000180800Y
28956620ABK27GA00019OB002000UTX   0000304300Y
28956633A1K27GA0000ESB002000AFL   0000282500Y
28956636A1K27GA0000ETB002000ABT   0000230500Y
28956646A1K27GA0000EUS002000AFL   0001450000Y
28956664A2K27G60000GHS002000BA    0001522800Y
28956665A2K27G60000GIS002000BA    0001523600Y
28956677A2K27G60000GJS002000BBT   0001289400Y
28956692A2K27G60000GKS002000BBT   0001290200Y
28956693A2K27G60000GLB002000CAG   0000093100Y
28956712A2K27G60000GMS002000CAG   0001244300Y
28956711A3K27G60000GFB002000COH   0000147000Y
28956725A3K27G60000GGS002000COH   0001300300Y
28956732A3K27G60000GHS002000CVS   0001329500Y
28956735A3K27G60000GIB002000CVS   0000176400Y
28956754A3K27G60000GJS002000CVS   0001328700Y
28956763A3K27G60000GKS002000DD    0001355600Y
28956780X4K27GA0000IE000124
28956781X4K27GA0000JW000100
28956782X4K27GA0000JV000100
28956782X3K27G60000EM000100
28957041A4K27GA0000K9B000200DIA   0001299000Y
28957173X6K27GA000026000500
28957173A6K27GA000026S000500IWM   0000737300Y
28957177ABK27GA00019PS000100UWM   0000544300Y
28957176X6K27GA0000DG002000
28957187X8K27G600006B000100
28957187X8K27G600006C000500
28957187X8K27G600005N000500
28957187X8K27G600006A000100
28957189A8K27G600006FB000100MVV   0000807200Y
28957199P2K27G60000GNS000210BAC   0000359000000I000HV2QS
28957344X5K27GA00005R002000
28957357A6K27GA0000DOB002000IMCL  0000354400Y
28957370X2K27G60000G9002000
28957404XAK27GA0001DN002000
28957407X5K27GA00008T002000
28957413X3K27G60000G5002000
28957414A5K27GA00008US002000FNM   0001260000Y
28957438X5K27GA00006D002000
28957439X7K27GA000086002000
28957443X8K27G600004W002000
28957443A5K27GA00008VB002000GM    0000182500Y
28957464XBK27GA00019O002000
28957467X1K27GA0000ET002000
28957470X2K27G60000GI002000
28957473X2K27G60000GB002000
28957479A7K27GA000087B002000LMT   0000465100Y
28957484X2K27G60000GK002000
28957499X2K27G60000GE002000
28957501AAK27GA0001DUB001000SPY   0001425900Y
28957503X2K27G60000GM002000
28957503XCK27GA00006D002000
28957512ABK27GA00019QS002000TGT   0000611800Y
28957517X3K27G60000GH002000
28957520X3K27G60000GK002000
28957536A5K27GA00008WS002000GM    0000226900Y
28957540X1K27GA0000ES002000
28957553X1K27GA0000EU002000
28957555ABK27GA00019RB002000UTX   0000307100Y
28957557ABK27GA00019SS002000TGT   0000612600Y
28957591ABK27GA00019TS002000UTX   0001462600Y
28957591X2K27G60000GH002000
28957598A1K27GA0000EVB002000ABT   0000232800Y
28957605X2K27G60000GJ002000
28957614A1K27GA0000EWS002000ANF   0000771200Y
28957624A2K27G60000GOB002000BBT   0000140900Y
28957625X3K27G60000GG002000
28957631X3K27G60000GI002000
28957634X3K27G60000GJ002000
28957656A2K27G60000GPS002000CAG   0001238700Y
28957663A2K27G60000GQS002000CAT   0000866200Y
28957670ABK27GA00019US002000UTX   0001463400Y
28957679A3K27G60000GLS002000CCE   0000239000Y
28957684ACK27GA00006EB002000WYE   0000181100Y
28957699A1K27GA0000EXB002000AFL   0000283600Y
28957711A1K27GA0000EYS002000AFL   0001447200Y
28957729A3K27G60000GMB002000COH   0000147200Y
28957734A3K27G60000GNS002000COH   0001296600Y
28957741A3K27G60000GOB002000CVS   0000176800Y
28957752A3K27G60000GPS002000DE    0000836300Y
28957867X4K27GA0000IQ000100
28957867X4K27GA0000JN000100
28957867A4K27GA0000KAB000100DRYS  0001068100Y
28958409X5K27GA00008U002000
28958409A5K27GA00008XS002000IACI  0000263300Y
28958410A2K27G60000GRB002000BMY   0000088400Y
28958431XBK27GA00019U002000
28958438XAK27GA0001DO002000
28958444X6K27GA0000D0002000
28958454XCK27GA00006E002000
28958473X7K27GA000087002000
28958475AAK27GA0001DVB002000SHLD  0000792500Y
28958485X1K27GA0000EX002000
28958488XBK27GA00017D002000
28958490X1K27GA0000EY002000
28958509X2K27G60000G1002000
28958510XBK27GA00019R002000
28958522A3K27G60000GQB002000CTSH  0000127300Y
28958526XBK27GA00019T002000
28958542A5K27GA00008YS002000FNM   0001254500Y
28958544X3K27G60000GN002000
28958550X3K27G60000GO002000
28958562X3K27G60000FV002000
28958575A5K27GA00008ZB002000GG    0000386700Y
28958579A7K27GA000088B002000LMT   0000467300Y
28958587A8K27G600006GS002000NBR   0000428100Y
28958590ABK27GA00019VB002000UTX   0000308300Y
28958597X1K27GA0000EV002000
28958602A4K27GA0000KBS000100DRYS  0001071900Y
28958602A4K27GA0000KCS000100DRYS  0001071900Y
28958602A1K27GA0000EZB002000ABT   0000233500Y
28958607ACK27GA00006FB002000WYE   0000183200Y
28958630A2K27G60000GSS002000BA    0001517400Y
28958639A1K27GA0000F0B002000AFL   0000286200Y
28958646A2K27G60000GTB002000BBT   0000141000Y
28958653X2K27G60000FY002000
28958663X2K27G60000D9002000
28958668A2K27G60000GUS002000BBT   0001281100Y
28958672A1K27GA0000F1S002000AFL   0001442800Y
28958686X2K27G600009J002000
28958699A2K27G60000GVS002000BA    0001516600Y
28958708A2K27G60000GWB002000CAG   0000093600Y
28958720X2K27G60000GL002000
28958725A2K27G60000GXS002000CAG   0001234600Y
28958728X2K27G60000GP002000
28958739A2K27G60000GYS002000BBT   0001280300Y
28958744A3K27G60000GRS002000CVS   0001320800Y
28958754X3K27G60000GF002000
28958756A3K27G60000GSS002000DD    0001347300Y
28958766A4K27GA0000KDS002000DIS   0000362400Y
28958783A3K27G60000GTS002000COH   0001291300Y
28958808A3K27G60000GUB002000CVS   0000178800Y
28958815A3K27G60000GVS002000CVS   0001320000Y
28958824A3K27G60000GWB002000DAL   0000022700Y
28958828A3K27G60000GXS002000DD    0001346500Y
28959351AAK27GA0001DWB002000SPLS  0000090700Y
28959360XAK27GA00015J002000
28959366X5K27GA00008Y002000
28959392XBK27GA0000X9002000
28959401X7K27GA000088002000
28959426A6K27GA0000DPB002000JNJ   0000645300Y
28959441XBK27GA00019V002000
28959444X1K27GA0000EZ002000
28959450X2K27G60000GS002000
28959459X2K27G60000GU002000
28959474X2K27G60000GX002000
28959474A7K27GA000089B002000LMT   0000471100Y
28959489X3K27G60000GM002000
28959504X3K27G60000GR002000
28959506ABK27GA00019WB002000TGT   0000523500Y
28959511X3K27G60000GS002000
28959516A5K27GA000090S002000FNM   0001250500Y
28959533ABK27GA00019XB002000UTX   0000311100Y
28959537XCK27GA00006F002000
28959559ABK27GA00019YS002000UTX   0001455700Y
28959569X1K27GA0000F0002000
28959580X1K27GA0000F1002000
28959586A1K27GA0000F2B002000ABT   0000235900Y
28959606A2K27G60000GZB002000AXP   0000426100Y
28959610X2K27G60000GV002000
28959622X2K27G60000GO002000
28959634X2K27G60000GY002000
28959640ABK27GA00019ZS002000UTX   0001456500Y
28959649X2K27G60000AU002000
28959662X3K27G60000GT002000
28959668ACK27GA00006GB002000WYE   0000183600Y
28959675X3K27G60000GU002000
28959684X3K27G60000GV002000
28959690X3K27G60000GX002000
28959696A2K27G60000H0B002000AZN   0000423800Y
28959703XAK27GA0000EX000500
28959703AAK27GA0000EXB000500SPY   0001425700Y
28959703XAK27GA0000FE000500
28959703AAK27GA0000FEB000500SPY   0001425700Y
28959704XAK27GA0000E7001000
28959704AAK27GA0000E7B001000SPY   0001425700Y
28959705A1K27GA0000F3B002000AFL   0000287300Y
28959715A2K27G60000H1S002000BAX   0000636900Y
28959718A1K27GA0000F4S002000AFL   0001440100Y
28959742A2K27G60000H2B002000AXP   0000425300Y
28959756A3K27G60000GYS002000COH   0001287600Y
28959761A3K27G60000GZB002000CVS   0000179200Y
28960353X3K27G60000G4002000
28960393X2K27G60000GR002000
28960394X5K27GA000090002000
28960437XAK27GA000124002000
28960438X5K27GA00008G002000
28960438X7K27GA000089002000
28960441XBK27GA00019X002000
28960456XBK27GA00019Z002000
28960465XCK27GA00006G002000
28960479AAK27GA0001DXS002000SEPR  0000228900Y
28960486X1K27GA0000F3002000
28960489XBK27GA00019Y002000
28960497X1K27GA0000F4002000
28960502X1K27GA0000F2002000
28960515X1K27GA0000A2002000
28960516X2K27G60000GT002000
28960520XAK27GA00013T002000
28960520XAK27GA0000FI000500
28960520AAK27GA0000FIB000500SPY   0001425600Y
28960520XAK27GA0000NY000500
28960520AAK27GA0000NYS000500SPY   0001426200Y
28960520XAK27GA0000E9001000
28960520AAK27GA0000E9S001000SPY   0001426200Y
28960520X4K27GA0000JP000200
28960520XAK27GA0000QB000500
28960520AAK27GA0000QBS000500SPY   0001426200Y
28960520XAK27GA0001D1002000
28960521X4K27GA0000DX000200
28960521A4K27GA0000DXB000200DIA   0001298900Y
28960521A4K27GA0000KES000123DIA   0001299300Y
28960522XAK27GA0001DF000500
28960523XAK27GA0000F5000500
28960523AAK27GA0000F5B000500SPY   0001425600Y
28960523XAK27GA0001DD002500
28960523XAK27GA0001DI005000
28960523A4K27GA0000KFB000100DOG   0000596800Y
28960523AAK27GA0001DYB000500SPY   0001425900Y
28960524X3K27G60000EK000100
28960523A4K27GA0000KGB000100DXD   0000499100Y
28960523AAK27GA0001DZB002500SPY   0001425900Y
28960524A3K27G60000H0S000100DDM   0000803100Y
28960523AAK27GA0001E0B005000SPY   0001425700Y
28960524XAK27GA0001DS005000
28960526ABK27GA0001A0S002000TEVA  0000485500Y
28960527XBK27GA00018O001000
28960535XAK27GA0001DU001000
28960536XAK27GA00013L002000
28960536XAK27GA0001CY001000
28960537AAK27GA0001E1S001000SPY   0001426200Y
28960538X2K27G60000GD002000
28960540X3K27G60000EL000100
28960539X4K27GA0000JU000100
28960541XAK27GA0001CT003000
28960541XAK27GA0001CQ003000
28960541XAK27GA0001D7001000
28960542AAK27GA0001E2S002000SPY   0001426200Y
28960542X9K27G60000G4002000
28960542A9K27G60000G4B002000QQQQ  0000495400Y
28960542X9K27G60000G5002000
28960542A9K27G60000G5S002000QQQQ  0000496000Y
28960542XAK27GA0000F7000500
28960542AAK27GA0000F7B000500SPY   0001425500Y
28960542XAK27GA0000FG000500
28960542AAK27GA0000FGB000500SPY   0001425500Y
28960542XAK27GA0001CW001000
28960542XAK27GA0001CR003000
28960542XAK27GA0001CU003000
28960542AAK27GA0001E3S002000SPY   0001426300Y
28960542AAK27GA0001E4S003000SPY   0001426200Y
28960542XAK27GA0000E8001000
28960542AAK27GA0000E8B001000SPY   0001425600Y
28960542AAK27GA0001E5S003000SPY   0001426200Y
28960542X4K27GA00007C000200
28960542A4K27GA00007CB000200DIA   0001298800Y
28960543X2K27G60000GW002000
28960543XAK27GA0001BY000500
28960543AAK27GA0001BYS000500SPY   0001426200Y
28960543AAK27GA0001E6B000100SH    0000618100Y
28960543AAK27GA0001E7B000900SPY   0001425700Y
28960543AAK27GA0001E8B003000SPY   0001425200Y
28960543AAK27GA0001E9B003000SPY   0001425200Y
28960544ABK27GA0001A1S001000SSO   0000765800Y
28960544XBK27GA00019B001000
28960543XAK27GA0000O8000500
28960543AAK27GA0000O8S000500SPY   0001426200Y
28960544XBK27GA00018M001000
28960544ABK27GA0001A2B001000SSO   0000764700Y
28960544XAK27GA0000E6001000
28960544AAK27GA0000E6S001000SPY   0001426200Y
28960546ABK27GA0001A3B001000SSO   0000764900Y
28960545XAK27GA0001DZ002500
28960546XAK27GA0001D8001000
28960547XAK27GA0001CV001000
28960547XAK27GA0001DY000500
28960548AAK27GA0001EAS001000SPY   0001426200Y
28960550XAK27GA0001CW001000
28960550AAK27GA0001EBB001000SPY   0001425700Y
28960552AAK27GA0001ECB001000SPY   0001425700Y
28960556X3K27G60000GY002000
28960556XBK27GA0001A2001000
28960557A5K27GA000091S002000FNM   0001245000Y
28960557X6K27GA00007U000500
28960557A6K27GA00007UB000500IWM   0000736700Y
28960559X3K27G60000GZ002000
28960558A6K27GA0000DQS002000IWM   0000737500Y
28960559XAK27GA0001EC001000
28960559A6K27GA0000DRS002000IWM   0000737600Y
28960563XBK27GA00018K000100
28960563XBK27GA00018L000100
28960564ABK27GA0001A4S000100TWM   0000701400Y
28960574A7K27GA00008AB002000LMT   0000473300Y
28960575AAK27GA0001EDS002000SPY   0001426200Y
28960575X6K27GA0000DB002000
28960577A8K27G600006HB000500MZZ   0000491200Y
28960577A8K27G600006IS000100MVV   0000809900Y
28960580X3K27G60000EI000100
28960580ABK27GA0001A5B002000UTX   0000312300Y
28960591A1K27GA0000F5B002000ABT   0000236600Y
28960593ACK27GA00006HB002000WYE   0000185600Y
28960595X9K27G60000SZ002000
28960596XAK27GA0001ED002000
28960605A2K27G60000H3S002000BA    0001511200Y
28960605A1K27GA0000F6B002000AFL   0000289900Y
28960606XAK27GA0001EB001000
28960606AAK27GA0001EEB001000SPY   0001425600Y
28960608X8K27G6000068000500
28960608X8K27G6000069000100
28960608X8K27G600006F000100
28960608AAK27GA0001EFB001000SPY   0001425600Y
28960610A8K27G600006JS000500MZZ   0000493400Y
28960610A8K27G600006KB000100MVV   0000807100Y
28960617A1K27GA0000F7S002000AFL   0001435700Y
28960620A2K27G60000H4S002000BBT   0001271900Y
28960621A9K27G60000T5B002000QQQQ  0000495700Y
28960622X9K27G60000T5002000
28960629A2K27G60000H5S002000BA    0001510400Y
28960641A2K27G60000H6S002000CAG   0001224800Y
28960643X9K27G60000F3003200
28960643A9K27G60000F3B003200QQQQ  0000495400Y
28960648XAK27GA0001BY000500
28960648AAK27GA0001BYS000500SPY   0001426100Y
28960648XAK27GA0000O8000500
28960648AAK27GA0000O8S000500SPY   0001426100Y
28960648XAK27GA0000E6001000
28960648AAK27GA0000E6S001000SPY   0001426100Y
28960648XAK27GA0001EA001000
28960648AAK27GA0001EAS001000SPY   0001426100Y
28960649X9K27G60000F3003200
28960649A9K27G60000F3B003200QQQQ  0000495900Y
28960649X4K27GA0000JE000200
28960650A4K27GA0000KHS000123DIA   0001299200Y
28960650A4K27GA0000KIB000100DXD   0000499200Y
28960651A3K27G60000H1S000100DDM   0000803000Y
28960650X6K27GA00002B000500
28960650A6K27GA00002BS000500IWM   0000737200Y
28960652AAK27GA0001EGS002000SPY   0001426200Y
28960653ABK27GA0001A6S000100UWM   0000544100Y
28960652X6K27GA0000DC002000
28960656X2K27G60000GA002000
28960667A3K27G60000H2B002000COH   0000150100Y
28960666X6K27GA0000B6000500
28960666A6K27GA0000B6B000500IWM   0000736600Y
28960671A2K27G60000H7B002000BBT   0000143700Y
28960673XBK27GA00018H000100
28960671X6K27GA0000B6000500
28960671A6K27GA0000B6B000500IWM   0000737000Y
28960673XBK27GA0001A4000100
28960675ABK27GA0001A7B000100UWM   0000543100Y
28960675ABK27GA0001A8S000100TWM   0000701400Y
28960678X6K27GA0000B6000500
28960678A6K27GA0000B6B000500IWM   0000736600Y
28960681XBK27GA0001A7000100
28960682XBK27GA0001A8000100
28960681X6K27GA0000B6000500
28960681A6K27GA0000B6B000500IWM   0000737000Y
28960683ABK27GA0001A9B000100UWM   0000543100Y
28960683ABK27GA0001AAS000100TWM   0000701400Y
28960682X6K27GA0000B6000500
28960682A6K27GA0000B6B000500IWM   0000736600Y
28960686XBK27GA0001A9000100
28960686XBK27GA0001AA000100
28960688ABK27GA0001ABS000100TWM   0000701600Y
28960689A2K27G60000H8S002000BBT   0001271100Y
28960689X6K27GA0000B6000500
28960689A6K27GA0000B6B000500IWM   0000737000Y
28960691A3K27G60000H3S002000CVS   0001312100Y
28960691ABK27GA0001ACB000100UWM   0000543100Y
28960691ABK27GA0001ADS000100TWM   0000701400Y
28960691XBK27GA0001AB000100
28960691X6K27GA0000B6000500
28960691A6K27GA0000B6B000500IWM   0000736600Y
28960702A3K27G60000H4B002000DAL   0000022300Y
28960702XBK27GA0001AC000100
28960701X6K27GA0000B6000500
28960701A6K27GA0000B6B000500IWM   0000737000Y
28960702XBK27GA0001AD000100
28960704ABK27GA0001AES000100TWM   0000701400Y
28960704ABK27GA0001AFB000100UWM   0000543100Y
28960706X6K27GA0000B6000500
28960706A6K27GA0000B6B000500IWM   0000736600Y
28960709A3K27G60000H5S002000DD    0001339000Y
28960709X6K27GA0000B6000500
28960709A6K27GA0000B6B000500IWM   0000737000Y
28960711A2K27G60000H9S002000BSX   0000151000Y
28960710A6K27GA0000DSB002000IWM   0000736500Y
28960711X6K27GA0000B6000500
28960711A6K27GA0000B6B000500IWM   0000736600Y
28960721X6K27GA0000B6000500
28960721A6K27GA0000B6B000500IWM   0000737000Y
28960722XBK27GA0001AF000100
28960723XBK27GA0001AE000100
28960724ABK27GA0001AGB000100UWM   0000543100Y
28960723A6K27GA0000DTB000100IWM   0000736500Y
28960723X6K27GA0000DT000100
28960725ABK27GA0001AHS000100TWM   0000701400Y
28960731X6K27GA0000B6000500
28960731A6K27GA0000B6B000500IWM   0000736600Y
28960733A2K27G60000HAB002000CAG   0000095700Y
28960734XBK27GA0001AG000100
28960734XBK27GA0001AH000100
28960736ABK27GA0001AIS000100TWM   0000701600Y
28960735X6K27GA0000B6000500
28960735A6K27GA0000B6B000500IWM   0000737000Y
28960737ABK27GA0001AJB000100UWM   0000543100Y
28960738ABK27GA0001AKS000100TWM   0000701400Y
28960738XBK27GA0001AI000100
28960740A4K27GA0000KJB002000DOW   0000401200Y
28960741X6K27GA0000B6000500
28960741A6K27GA0000B6B000500IWM   0000736600Y
28960744XBK27GA0001AJ000100
28960745XBK27GA0001AK000100
28960746ABK27GA0001ALS000100TWM   0000701600Y
28960746X6K27GA0000B6000500
28960746A6K27GA0000B6B000500IWM   0000737000Y
28960751X6K27GA0000B6000500
28960751A6K27GA0000B6B000500IWM   0000736600Y
28960757AAK27GA0001EHB000500SPY   0001425700Y
28960758XAK27GA0001DB000500
28960758X9K27G60000F3003200
28960758A9K27G60000F3B003200QQQQ  0000495400Y
28960761X6K27GA0000B6000500
28960761A6K27GA0000B6B000500IWM   0000737000Y
28960762ABK27GA0001AMB000100UWM   0000543100Y
28960763XBK27GA0001AL000100
28960763ABK27GA0001ANS000100TWM   0000701400Y
28960772XBK27GA0001AM000100
28960771X6K27GA0000B6000500
28960771A6K27GA0000B6B000500IWM   0000736600Y
28960772XBK27GA0001AN000100
28960773A6K27GA0000DUB000100IWM   0000736500Y
28960774ABK27GA0001AOS000100TWM   0000701600Y
28960773X6K27GA0000DU000100
28960773X6K27GA0000B6000500
28960773A6K27GA0000B6B000500IWM   0000737000Y
28960781X6K27GA0000B6000500
28960781A6K27GA0000B6B000500IWM   0000736600Y
28960783ABK27GA0001APB000100UWM   0000543100Y
28960783XBK27GA0001AP000100
28960783XBK27GA0001AO000100
28960783ABK27GA0001AQS000100TWM   0000701400Y
28960783XBK27GA0001AQ000100
28960785ABK27GA0001ARS000100TWM   0000701600Y
28960789A2K27G60000HBS002000CAG   0001224000Y
28960791X8K27G600006J000500
28960791X8K27G600005U000500
28960791X8K27G600005W000500
28960791X8K27G600005X000100
28960791X8K27G600006K000100
28960793A8K27G600006LS000500MZZ   0000493500Y
28960793A8K27G600006MB000100MVV   0000807000Y
28960791X6K27GA0000B6000500
28960791A6K27GA0000B6B000500IWM   0000737000Y
28960793ABK27GA0001ASB000100UWM   0000543100Y
28960793XBK27GA0001AR000100
28960793ABK27GA0001ATS000100TWM   0000701400Y
28960799A3K27G60000H6B002000COH   0000150900Y
28960801X6K27GA0000B6000500
28960801A6K27GA0000B6B000500IWM   0000736600Y
28960803XBK27GA0001AS000100
28960803XBK27GA0001AT000100
28960804ABK27GA0001AUS000100TWM   0000701600Y
28960811X6K27GA0000B6000500
28960811A6K27GA0000B6B000500IWM   0000737000Y
28960812ABK27GA0001AVB000100UWM   0000543100Y
28960813XBK27GA0001AU000100
28960813ABK27GA0001AWS000100TWM   0000701400Y
28960821X6K27GA0000B6000500
28960821A6K27GA0000B6B000500IWM   0000736600Y
28960823XBK27GA0001AV000100
28960823XBK27GA0001AW000100
28960823A6K27GA0000DVB000100IWM   0000736500Y
28960825ABK27GA0001AXS000100TWM   0000701600Y
28960823X6K27GA0000DV000100
28960824X6K27GA0000B6000500
28960824A6K27GA0000B6B000500IWM   0000737000Y
28960831X6K27GA0000B6000500
28960831A6K27GA0000B6B000500IWM   0000736600Y
28960841X6K27GA0000B6000500
28960841A6K27GA0000B6B000500IWM   0000737000Y
28960851X6K27GA0000B6000500
28960851A6K27GA0000B6B000500IWM   0000736600Y
28960857X9K27G60000F3003200
28960857A9K27G60000F3B003200QQQQ  0000495900Y
28960861X6K27GA0000B6000500
28960861A6K27GA0000B6B000500IWM   0000737000Y
28960871X6K27GA0000B6000500
28960871A6K27GA0000B6B000500IWM   0000736600Y
28960881X6K27GA0000B6000500
28960881A6K27GA0000B6B000500IWM   0000737000Y
28960891X6K27GA0000B6000500
28960891A6K27GA0000B6B000500IWM   0000736600Y
28960901X6K27GA0000B6000500
28960901A6K27GA0000B6B000500IWM   0000737000Y
28960911X6K27GA0000B6000500
28960911A6K27GA0000B6B000500IWM   0000736600Y
28960921X6K27GA0000B6000500
28960921A6K27GA0000B6B000500IWM   0000737000Y
28960931XAK27GA0001CP001000
28960931X6K27GA0000B6000500
28960931A6K27GA0000B6B000500IWM   0000736600Y
28960933AAK27GA0001EIB000900SPY   0001425600Y
28960933AAK27GA0001EJS005000SPY   0001426200Y
28960933XBK27GA0001A3001000
28960933ABK27GA0001AYB001000SSO   0000764600Y
28960934AAK27GA0001EKB002500SPY   0001425700Y
28960934XAK27GA0001DE002500
28960935ABK27GA0001AZB001000SSO   0000764800Y
28960936XAK27GA0001CX000100
28960941X6K27GA0000B6000500
28960941A6K27GA0000B6B000500IWM   0000737000Y
28960949X9K27G60000F3003200
28960949A9K27G60000F3B003200QQQQ  0000495400Y
28960950XAK27GA0000EB001000
28960950AAK27GA0000EBB001000SPY   0001425500Y
28960951X6K27GA0000B6000500
28960951A6K27GA0000B6B000500IWM   0000736600Y
28960961AAK27GA0001ELS000500SPY   0001426100Y
28960962XAK27GA0001BV000500
28960962AAK27GA0001BVS000500SPY   0001426100Y
28960961X6K27GA0000B6000500
28960961A6K27GA0000B6B000500IWM   0000737000Y
28960964AAK27GA0001EMB001000SDS   0000547300Y
28960964XAK27GA0001DM001000
28960964ABK27GA0001B0S001000SSO   0000765700Y
28960964XBK27GA0001A1001000
28960965XAK27GA0001BV000500
28960965AAK27GA0001BVS000500SPY   0001426400Y
28960966XAK27GA0001EM001000
28960967XBK27GA0001B0001000
28960968AAK27GA0001ENB001000SDS   0000547200Y
28960969ABK27GA0001B1S001000SSO   0000765800Y
28960972X6K27GA0000B6000500
28960972A6K27GA0000B6B000500IWM   0000736600Y
28960976XAK27GA0001BV000500
28960976AAK27GA0001BVS000500SPY   0001426100Y
28960977XAK27GA0001EN001000
28960977AAK27GA0001EOB001000SDS   0000547300Y
28960977ABK27GA0001B2S001000SSO   0000765700Y
28960977XBK27GA0001B1001000
28960981X6K27GA0000B6000500
28960981A6K27GA0000B6B000500IWM   0000737000Y
28960986XAK27GA0001BV000500
28960986AAK27GA0001BVS000500SPY   0001426400Y
28960986XAK27GA0001EO001000
28960987XBK27GA0001B2001000
28960988AAK27GA0001EPB001000SDS   0000547200Y
28960989ABK27GA0001B3S001000SSO   0000765800Y
28960989XAK27GA0001BV000500
28960989AAK27GA0001BVS000500SPY   0001426100Y
28960990XAK27GA0001EP001000
28960990AAK27GA0001EQB001000SDS   0000547300Y
28960990ABK27GA0001B4S001000SSO   0000765700Y
28960990XBK27GA0001B3001000
28960992X6K27GA0000B6000500
28960992A6K27GA0000B6B000500IWM   0000736600Y
28960996XAK27GA0001BV000500
28960996AAK27GA0001BVS000500SPY   0001426400Y
28960996XAK27GA0001EQ001000
28960997XBK27GA0001B4001000
28960999ABK27GA0001B5S001000SSO   0000765800Y
28960999ABK27GA0001B6S001000SSO   0000766900Y
28960998AAK27GA0001ERB001000SDS   0000547200Y
28961002X6K27GA0000B6000500
28961002A6K27GA0000B6B000500IWM   0000737000Y
28961006XAK27GA0001BV000500
28961006AAK27GA0001BVS000500SPY   0001426100Y
28961007XAK27GA0001ER001000
28961007AAK27GA0001ESB001000SDS   0000547300Y
28961007XBK27GA0001B5001000
28961007ABK27GA0001B7S001000SSO   0000765700Y
28961012X6K27GA0000B6000500
28961012A6K27GA0000B6B000500IWM   0000736600Y
28961015XAK27GA0001BV000500
28961015AAK27GA0001BVS000500SPY   0001426400Y
28961016XAK27GA0001ES001000
28961017XBK27GA0001B7001000
28961018AAK27GA0001ETB001000SDS   0000547200Y
28961019ABK27GA0001B8S001000SSO   0000765800Y
28961021X6K27GA0000B6000500
28961021A6K27GA0000B6B000500IWM   0000737000Y
28961025XAK27GA0001BV000500
28961025AAK27GA0001BVS000500SPY   0001426100Y
28961026AAK27GA0001EUB001000SDS   0000547300Y
28961027XAK27GA0001ET001000
28961027XBK27GA0001B8001000
28961027ABK27GA0001B9S001000SSO   0000765700Y
28961035XAK27GA0001BV000500
28961035AAK27GA0001BVS000500SPY   0001426400Y
28961036XAK27GA0001EU001000
28961037XBK27GA0001B9001000
28961038AAK27GA0001EVB001000SDS   0000547200Y
28961039ABK27GA0001BAS001000SSO   0000765800Y
28961046XAK27GA0001BV000500
28961046AAK27GA0001BVS000500SPY   0001426000Y
28961047AAK27GA0001EWB001000SDS   0000547300Y
28961047XBK27GA0001BA001000
28961047ABK27GA0001BBS001000SSO   0000765700Y
28961047XAK27GA0001EV001000
28961055XAK27GA0001BV000500
28961055AAK27GA0001BVS000500SPY   0001426400Y
28961057XAK27GA0001EW001000
28961058XBK27GA0001BB001000
28961059X9K27G60000F3003200
28961059A9K27G60000F3B003200QQQQ  0000495900Y
28961059AAK27GA0001EXB001000SDS   0000547200Y
28961059ABK27GA0001BCS001000SSO   0000765800Y
28961066XAK27GA0001BV000500
28961066AAK27GA0001BVS000500SPY   0001426000Y
28961067XBK27GA0001BC001000
28961067AAK27GA0001EYB001000SDS   0000547300Y
28961067XAK27GA0001EX001000
28961067ABK27GA0001BDS001000SSO   0000765700Y
28961076XAK27GA0001BV000500
28961076AAK27GA0001BVS000500SPY   0001426400Y
28961078XAK27GA0001EY001000
28961078XBK27GA0001BD001000
28961080ABK27GA0001BES001000SSO   0000765800Y
28961079AAK27GA0001EZB001000SDS   0000547200Y
28961086XAK27GA0001BV000500
28961086AAK27GA0001BVS000500SPY   0001426000Y
28961088AAK27GA0001F0B001000SDS   0000547300Y
28961088XAK27GA0001EZ001000
28961088ABK27GA0001BFS001000SSO   0000765700Y
28961088XBK27GA0001BE001000
28961093XAK27GA0001BV000500
28961093AAK27GA0001BVS000500SPY   0001426400Y
28961095XAK27GA0001BV000500
28961095AAK27GA0001BVS000500SPY   0001426000Y
28961098XAK27GA0001F0001000
28961098XBK27GA0001BF001000
28961100ABK27GA0001BGS001000SSO   0000765700Y
28961100AAK27GA0001F1B001000SDS   0000547300Y
28961103XAK27GA0001BV000500
28961103AAK27GA0001BVS000500SPY   0001426400Y
28961105XAK27GA0001F1001000
28961105XBK27GA0001BG001000
28961106XAK27GA0001BV000500
28961106AAK27GA0001BVS000500SPY   0001426000Y
28961107ABK27GA0001BHS001000SSO   0000765800Y
28961107AAK27GA0001F2B001000SDS   0000547200Y
28961107XAK27GA0001F2001000
28961107AAK27GA0001F3B001000SDS   0000547300Y
28961108XBK27GA0001BH001000
28961108ABK27GA0001BIS001000SSO   0000765700Y
28961116XAK27GA0001BV000500
28961116AAK27GA0001BVS000500SPY   0001426400Y
28961117XAK27GA0001F3001000
28961118XBK27GA0001BI001000
28961119AAK27GA0001F4B001000SDS   0000547200Y
28961120ABK27GA0001BJS001000SSO   0000765800Y
28961123ABK27GA0001BKB000100UWM   0000543100Y
28961123ABK27GA0001BLS000100TWM   0000701400Y
28961123XBK27GA0001AX000100
28961126XAK27GA0001BV000500
28961126AAK27GA0001BVS000500SPY   0001426000Y
28961127XAK27GA0001F4001000
28961127AAK27GA0001F5B001000SDS   0000547300Y
28961128XBK27GA0001BJ001000
28961128ABK27GA0001BMS001000SSO   0000765700Y
28961136XAK27GA0001BV000500
28961136AAK27GA0001BVS000500SPY   0001426400Y
28961137XAK27GA0001F5001000
28961139AAK27GA0001F6B001000SDS   0000547200Y
28961138XBK27GA0001BM001000
28961140ABK27GA0001BNS001000SSO   0000765800Y
28961146XAK27GA0001BV000500
28961146AAK27GA0001BVS000500SPY   0001426000Y
28961147AAK27GA0001F7B001000SDS   0000547300Y
28961148XBK27GA0001BN001000
28961147XAK27GA0001F6001000
28961148ABK27GA0001BOS001000SSO   0000765700Y
28961156XAK27GA0001BV000500
28961156AAK27GA0001BVS000500SPY   0001426400Y
28961158XAK27GA0001F7001000
28961158XBK27GA0001BO001000
28961159AAK27GA0001F8B001000SDS   0000547200Y
28961160ABK27GA0001BPS001000SSO   0000765800Y
28961166XAK27GA0001BV000500
28961166AAK27GA0001BVS000500SPY   0001426000Y
28961176XAK27GA0001BV000500
28961176AAK27GA0001BVS000500SPY   0001426400Y
28961186XAK27GA0001BV000500
28961186AAK27GA0001BVS000500SPY   0001426000Y
28961196XAK27GA0001BV000500
28961196AAK27GA0001BVS000500SPY   0001426400Y
28961205XAK27GA0001BV000500
28961205AAK27GA0001BVS000500SPY   0001426000Y
28961216XAK27GA0001BV000500
28961216AAK27GA0001BVS000500SPY   0001426400Y
28961226XAK27GA0001BV000500
28961226AAK27GA0001BVS000500SPY   0001426000Y
28961235XAK27GA0001BV000500
28961235AAK27GA0001BVS000500SPY   0001426400Y
28961245XAK27GA0001BV000500
28961245AAK27GA0001BVS000500SPY   0001426000Y
28961255XAK27GA0001BV000500
28961255AAK27GA0001BVS000500SPY   0001426400Y
28961265XAK27GA0001BV000500
28961265AAK27GA0001BVS000500SPY   0001426000Y
28961275XAK27GA0001BV000500
28961275AAK27GA0001BVS000500SPY   0001426400Y
28961286XAK27GA0001BV000500
28961286AAK27GA0001BVS000500SPY   0001426000Y
28961296XAK27GA0001BV000500
28961296AAK27GA0001BVS000500SPY   0001426400Y
28961306XAK27GA0001BV000500
28961306AAK27GA0001BVS000500SPY   0001426000Y
28961316XAK27GA0001BV000500
28961316AAK27GA0001BVS000500SPY   0001426400Y
28961325XAK27GA0001BV000500
28961325AAK27GA0001BVS000500SPY   0001426000Y
28961334AAK27GA0001F9S002500SPY   0001426100Y
28961335XAK27GA0001BV000500
28961335AAK27GA0001BVS000500SPY   0001426400Y
28961346XAK27GA0001BV000500
28961346AAK27GA0001BVS000500SPY   0001426000Y
28961351X1K27GA0000EA002000
28961355XAK27GA0001BV000500
28961355AAK27GA0001BVS000500SPY   0001426400Y
28961360X3K27G60000GQ002000
28961365XAK27GA0001BV000500
28961365AAK27GA0001BVS000500SPY   0001426000Y
28961375XAK27GA0001BV000500
28961375AAK27GA0001BVS000500SPY   0001426400Y
28961385XAK27GA0001BV000500
28961385AAK27GA0001BVS000500SPY   0001426000Y
28961391X6K27GA0000B6000500
28961394X7K27GA00008A002000
28961394XBK27GA0001BK000100
28961394XBK27GA0001BL000100
28961396XAK27GA0001BV000500
28961396AAK27GA0001BVS000500SPY   0001426400Y
28961396ABK27GA0001BQS000100TWM   0000701600Y
28961395A6K27GA0000DWB000500IWM   0000737000Y
28961399XBK27GA0001BQ000100
28961399ABK27GA0001BRB000100UWM   0000543100Y
28961399ABK27GA0001BSS000100TWM   0000701400Y
28961401X6K27GA0000DW000500
28961401A6K27GA0000DWB000500IWM   0000736600Y
28961404XBK27GA0001BR000100
28961404XBK27GA0001BS000100
28961405XAK27GA0001BV000500
28961405AAK27GA0001BVS000500SPY   0001426000Y
28961406ABK27GA0001BTS000100TWM   0000701600Y
28961411X6K27GA0000DW000500
28961411A6K27GA0000DWB000500IWM   0000737000Y
28961413A2K27G60000HCB002000BMY   0000090300Y
28961414XBK27GA0001BT000100
28961414ABK27GA0001BUB000100UWM   0000543100Y
28961414ABK27GA0001BVS000100TWM   0000701400Y
28961415XBK27GA0001A5002000
28961416XAK27GA0001BV000500
28961416AAK27GA0001BVS000500SPY   0001426400Y
28961421X6K27GA0000DW000500
28961421A6K27GA0000DWB000500IWM   0000736600Y
28961424XBK27GA0001BU000100
28961424XBK27GA0001BV000100
28961423XCK27GA00005U002000
28961425XAK27GA0001BV000500
28961425AAK27GA0001BVS000500SPY   0001426000Y
28961426ABK27GA0001BWS000100TWM   0000701600Y
28961425X6K27GA0000DW000500
28961425A6K27GA0000DWB000500IWM   0000737000Y
28961427A3K27G60000H7B002000CELG  0000510400Y
28961426A6K27GA0000DXB000100IWM   0000736500Y
28961426X6K27GA0000DX000100
28961428ABK27GA0001BXB000100UWM   0000543100Y
28961428XBK27GA0001BW000100
28961428ABK27GA0001BYS000100TWM   0000701400Y
28961431X6K27GA0000DW000500
28961431A6K27GA0000DWB000500IWM   0000736600Y
28961433X1K27GA0000F5002000
28961434XBK27GA0001BX000100
28961434XBK27GA0001BY000100
28961436ABK27GA0001BZS000100TWM   0000701600Y
28961439X6K27GA0000DW000500
28961439A6K27GA0000DWB000500IWM   0000737000Y
28961442X9K27G60000F3003200
28961442A9K27G60000F3B003200QQQQ  0000495400Y
28961441X6K27GA0000DW000500
28961441A6K27GA0000DWB000500IWM   0000736600Y
28961442ABK27GA0001C0B000100UWM   0000543100Y
28961442XBK27GA0001BZ000100
28961443ABK27GA0001C1S000100TWM   0000701400Y
28961444XBK27GA0001C0000100
28961444XBK27GA0001C1000100
28961444A6K27GA0000DYB000100IWM   0000736500Y
28961446ABK27GA0001C2S000100TWM   0000701600Y
28961445X6K27GA0000DY000100
28961445X6K27GA0000DW000500
28961445A6K27GA0000DWB000500IWM   0000737000Y
28961449ABK27GA0001C3B000100UWM   0000543100Y
28961449XBK27GA0001C2000100
28961449ABK27GA0001C4S000100TWM   0000701400Y
28961451X6K27GA0000DW000500
28961451A6K27GA0000DWB000500IWM   0000736600Y
28961454XBK27GA0001C3000100
28961454XBK27GA0001C4000100
28961456X2K27G60000H3002000
28961456ABK27GA0001C5S000100TWM   0000701600Y
28961461X6K27GA0000DW000500
28961461A6K27GA0000DWB000500IWM   0000737000Y
28961464ABK27GA0001C6B000100UWM   0000543100Y
28961465XBK27GA0001C5000100
28961465ABK27GA0001C7S000100TWM   0000701400Y
28961471X6K27GA0000DW000500
28961471A6K27GA0000DWB000500IWM   0000736600Y
28961474XBK27GA0001C6000100
28961474XBK27GA0001C7000100
28961474A6K27GA0000DZB000100IWM   0000736500Y
28961476ABK27GA0001C8S000100TWM   0000701600Y
28961475X6K27GA0000DZ000100
28961476AAK27GA0001FAB002000SINA  0000511900Y
28961475X6K27GA0000DW000500
28961475A6K27GA0000DWB000500IWM   0000737000Y
28961478ABK27GA0001C9B000100UWM   0000543100Y
28961479ABK27GA0001CAS000100TWM   0000701400Y
28961479XBK27GA0001C8000100
28961479X5K27GA000091002000
28961480X2K27G60000H4002000
28961481X6K27GA0000DW000500
28961481A6K27GA0000DWB000500IWM   0000736600Y
28961484XBK27GA0001C9000100
28961484XBK27GA0001CA000100
28961486X2K27G60000H6002000
28961484A6K27GA0000E0B000100IWM   0000736500Y
28961486ABK27GA0001CBS000100TWM   0000701600Y
28961485X6K27GA0000E0000100
28961494X9K27G60000F3003200
28961494A9K27G60000F3B003200QQQQ  0000495900Y
28961498X2K27G60000DN002000
28961497X6K27GA0000D1002000
28961514X7K27GA00007F002000
28961517X3K27G60000H3002000
28961518XAK27GA0001F8001000
28961518AAK27GA0001FBB001000SDS   0000547300Y
28961518XBK27GA0001BP001000
28961518ABK27GA0001CCS001000SSO   0000765700Y
28961530X3K27G60000H5002000
28961535A7K27GA00008BB002000LMT   0000477100Y
28961542A5K27GA000092S002000FNM   0001241000Y
28961561X9K27G60000F3003200
28961561A9K27G60000F3B003200QQQQ  0000495400Y
28961568ABK27GA0001CDB002000UTX   0000315100Y
28961579ABK27GA0001CES002000UTX   0001448800Y
28961586XCK27GA00006H002000
28961592A5K27GA000093B002000GM    0000182000Y
28961605A1K27GA0000F8B002000ABT   0000239000Y
28961612A8K27G600006NB000500MZZ   0000491400Y
28961612A8K27G600006OS000100MVV   0000809700Y
28961623ABK27GA0001CFS002000UTX   0001449600Y
28961623A1K27GA0000F9B002000ACF   0000121600Y
28961637X1K27GA0000F6002000
28961638ACK27GA00006IB002000WYE   0000186000Y
28961648X1K27GA0000F7002000
28961659X2K27G60000H5002000
28961664A1K27GA0000FAB002000AFL   0000291000Y
28961671X2K27G60000H8002000
28961679A1K27GA0000FBS002000AFL   0001432900Y
28961685A2K27G60000HDB002000BDX   0000783000Y
28961698X2K27G60000HB002000
28961700X3K27G60000H0000100
28961716A3K27G60000H8S002000COH   0001277800Y
28961721A2K27G60000HEB002000BBT   0000143900Y
28961725X9K27G60000SV005000
28961725X9K27G60000SW005000
28961726A9K27G60000T6S005000QQQQ  0000496000Y
28961726A9K27G60000T7S005000QQQQ  0000496000Y
28961726X9K27G60000SU002000
28961726A9K27G60000T8S002000QQQQ  0000496000Y
28961734A2K27G60000HFB002000BDX   0000782200Y
28961737A3K27G60000H9B002000CVS   0000182400Y
28961738A2K27G60000HGB002000CAG   0000095600Y
28961751A3K27G60000HAS002000COH   0001278600Y
28961763A3K27G60000HBS002000CVS   0001307000Y
28961768A3K27G60000HCB002000CVS   0000181600Y
28961777X3K27G60000ET002000
28962195X9K27G60000EN002000
28962195A9K27G60000ENS002000QQQQ  0000496000Y
28962358A1K27GA0000FCS002000AMGN  0000470100Y
28962393X5K27GA000092002000
28962402XBK27GA00019S002000
28962404X7K27GA00008B002000
28962404X6K27GA0000DI002000
28962421XAK27GA0001DV002000
28962421XBK27GA00019Q002000
28962423XBK27GA0001CF002000
28962430XCK27GA00006I002000
28962437XBK27GA0001CD002000
28962440A3K27G60000HDB002000CTSH  0000130700Y
28962446XBK27GA0001CE002000
28962449X1K27GA0000FA002000
28962465X1K27GA0000FB002000
28962477X1K27GA0000F8002000
28962488X3K27G60000H2002000
28962499X2K27G60000H7002000
28962504A1K27GA0000FDB000100AAPL  0001830100Y
28962506X3K27G60000HA002000
28962510X1K27GA0000FD000100
28962511A1K27GA0000FEB000020AAPL  0001831000Y
28962517X2K27G60000HA002000
28962528X3K27G60000HC002000
28962528X3K27G60000H6002000
28962531X3K27G60000H8002000
28962531X3K27G60000H9002000
28962535X3K27G60000HB002000
28962537A7K27GA00008CB002000LMT   0000479300Y
28962540X1K27GA0000FE000020
28962540A1K27GA0000FEB000020AAPL  0001831100Y
28962547A5K27GA000094S002000FNM   0001235500Y
28962563A6K27GA0000E1S002000JNJ   0000687300Y
28962564ABK27GA0001CGB002000UTX   0000316300Y
28962573ACK27GA00006JS002000WYE   0000470500Y
28962579A1K27GA0000FFB002000ABT   0000239600Y
28962598A7K27GA00008DB002000KSS   0000460200Y
28962608A2K27G60000HHS002000BA    0001505000Y
28962629A2K27G60000HIS002000BBT   0001262700Y
28962637ACK27GA00006KB002000WYE   0000188000Y
28962650A2K27G60000HJS002000CAG   0001215100Y
28962658A1K27GA0000FGB002000AFL   0000293600Y
28962662A2K27G60000HKB002000CAT   0000821200Y
28962671A1K27GA0000FHS002000AFL   0001428500Y
28962680A3K27G60000HES002000CVS   0001303500Y
28962686A2K27G60000HLS002000BA    0001504200Y
28962698A3K27G60000HFS002000DD    0001330600Y
28962702X9K27G60000T7005000
28962702X9K27G60000T6005000
28962702X9K27G60000F3003200
28962702A9K27G60000F3B003200QQQQ  0000495900Y
28962703A9K27G60000T9S005000QQQQ  0000496400Y
28962704A9K27G60000TAS005000QQQQ  0000496400Y
28962704A2K27G60000HMS002000BBT   0001261900Y
28962705X9K27G60000EN002000
28962705A9K27G60000ENS002000QQQQ  0000496300Y
28962706X9K27G60000T8002000
28962735A2K27G60000HNS002000CAG   0001214300Y
28962753A3K27G60000HGS002000DD    0001329800Y
28962808A9K27G60000TBB002000QQQQ  0000495700Y
28963351A6K27GA0000E2S002000IMCL  0000503300Y
28963363X2K27G60000HC002000
28963374XAK27GA0001DW002000
28963396X1K27GA000080002000
28963399XAK27GA0001DP002000
28963406X5K27GA000094002000
28963408AAK27GA0001FCB002000SHLD  0000795400Y
28963423X7K27GA00008C002000
28963439XAK27GA0001DT000100
28963438X6K27GA0000DM000100
28963440XBK27GA0001CG002000
28963441AAK27GA0001FDS000100SKF   0001028100Y
28963440A6K27GA0000E3B000100IYF   0000856300Y
28963440A6K27GA0000E4B000100IYF   0000856200Y
28963440A6K27GA0000E5B000100IYF   0000856900Y
28963440A6K27GA0000E6B000100IYF   0000856900Y
28963440X6K27GA000022000100
28963442ABK27GA0001CHS000100UYG   0000321200Y
28963442XBK27GA00000T000100
28963442A6K27GA0000E7S000100IYF   0000858300Y
28963450XBK27GA0001CH000100
28963448X6K27GA0000DN000100
28963450X6K27GA0000E7000100
28963452A6K27GA0000E8S000100IYF   0000858800Y
28963452X6K27GA0000DK000100
28963458X6K27GA0000E8000100
28963458A6K27GA0000E9B002000IBM   0001242200Y
28963461A6K27GA0000EAS000100IYF   0000859300Y
28963472XCK27GA00005W002000
28963479X1K27GA0000FF002000
28963488X1K27GA00008X002000
28963494X2K27G60000HH002000
28963494A7K27GA00008EB002000LMT   0000483100Y
28963502X2K27G60000HE002000
28963512X2K27G60000HI002000
28963516ABK27GA0001CIS002000TGT   0000610300Y
28963520X2K27G60000HG002000
28963519X6K27GA0000E5000100
28963519A6K27GA0000E5B000100IYF   0000857000Y
28963519X6K27GA0000E6000100
28963519A6K27GA0000E6B000100IYF   0000857000Y
28963526X2K27G60000HJ002000
28963541X3K27G60000HE002000
28963545X3K27G60000HF002000
28963552ABK27GA0001CJB002000UTX   0000319100Y
28963553A5K27GA000095S002000FNM   0001231500Y
28963556XCK27GA00006K002000
28963575ABK27GA0001CKS002000UTX   0001441800Y
28963591X1K27GA0000D1002000
28963594A6K27GA0000EBB002000IBM   0001241400Y
28963597X1K27GA0000FG002000
28963607X1K27GA0000FH002000
28963618X1K27GA0000CY002000
28963624ABK27GA0001CLS002000TGT   0000611100Y
28963630X2K27G60000HL002000
28963634A1K27GA0000FIB002000ABT   0000242000Y
28963641ABK27GA0001CMS002000UTX   0001442600Y
28963656ACK27GA00006LB002000WYE   0000188400Y
28963659X2K27G60000HM002000
28963665X2K27G60000E8002000
28963679A2K27G60000HOB002000BBT   0000146600Y
28963685A1K27GA0000FJB002000AFL   0000294700Y
28963698A1K27GA0000FKS002000AFL   0001425700Y
28963699X2K27G60000HN002000
28963706A2K27G60000HPB002000CAG   0000097700Y
28963734A3K27G60000HHB002000COH   0000153900Y
28800011AAK27GA0000DTS000100SH    0000619200Y
28800012ABK27GA00000KB001000SSO   0000763800Y
28800012ABK27GA00000LB001000SSO   0000763600Y
28800012ABK27GA00000MS001000SSO   0000764800Y
28800012AAK27GA0000DUS001000SDS   0000549300Y
28800012AAK27GA0000DVB001000SDS   0000548000Y
28800012AAK27GA0000DWB000100SPY   0001424100Y
28800012AAK27GA0000DXS000100SPY   0001426300Y
28800012AAK27GA0000DYB000100SH    0000618500Y
28800015AAK27GA0000DZB001000SDS   0000547800Y
28800075ABK27GA00000NS000100UWM   0000542900Y
28800075ABK27GA00000OB000100TWM   0000701400Y
28800075ABK27GA00000PB000100TWM   0000701600Y
28800075ABK27GA00000QB000100UWM   0000542000Y
28800075ABK27GA00000RS000100TWM   0000702600Y
28800075ABK27GA00000SB000100TWM   0000701500Y
28800136A4K27GA00002RS000100DOG   0000598500Y
28800137A3K27G6000006S000100DDM   0000802100Y
28800136A4K27GA00002SS000100DXD   0000501300Y
28800136A4K27GA00002TS000100DXD   0000501100Y
28800136A4K27GA00002US000100DXD   0000501200Y
28800136A4K27GA00002VB000100DXD   0000500400Y
28800136A4K27GA00002WB000100DOG   0000597200Y
28800137A3K27G6000007B000100DDM   0000800700Y
28800161A4K27GA00002XB000100DIG   0001235800Y
28800161A4K27GA00002YS000100DIG   0001244400Y
28800160A6K27GA00001IB000100IYE   0001530500Y
28800160A6K27GA00001JS000100IYE   0001539100Y
28800162A1K27GA00000VB000100AAPL  0001828600Y
28800162A1K27GA00000WS000100AAPL  0001834800Y
28800162A1K27GA00000XB000100AAPL  0001828600Y
28800162A1K27GA00000YS000100AAPL  0001834800Y
28800164A9K27G60000CZS001000QID   0000382200Y
28800164A9K27G60000D0S001000QLD   0000889800Y
28800164A9K27G60000D1B001000QLD   0000888500Y
28800164A9K27G60000D2B001000QLD   0000888400Y
28800164A9K27G60000D3B001000QQQQ  0000495100Y
28800164A9K27G60000D4B001000QID   0000380900Y
28800165A9K27G60000D5B000500QQQQ  0000495000Y
28800165A9K27G60000D6B000500QQQQ  0000494900Y
28800165A9K27G60000D7B000500QQQQ  0000494400Y
28800166A9K27G60000D8B000500QQQQ  0000493800Y
28800166A9K27G60000D9B000500QQQQ  0000494300Y
28800166A9K27G60000DAB000500QQQQ  0000495100Y
28800166A9K27G60000DBB000500QQQQ  0000493700Y
28800166A9K27G60000DCS000500QQQQ  0000496700Y
28800166A9K27G60000DDS000500QQQQ  0000497300Y
28800166A9K27G60000DEB000500QQQQ  0000494800Y
28800166A9K27G60000DFB000500QQQQ  0000494700Y
28800166A9K27G60000DGB000500QQQQ  0000494100Y
28800166A9K27G60000DHS000500QQQQ  0000496800Y
28800166A9K27G60000DIS000500QQQQ  0000497400Y
28800166A9K27G60000DJB000500QQQQ  0000494500Y
28800166A9K27G60000DKB000500QQQQ  0000493900Y
28800166A9K27G60000DLS000500QQQQ  0000496600Y
28800166A9K27G60000DMS000500QQQQ  0000497200Y
28800166A9K27G60000DNB000500QQQQ  0000494600Y
28800166A9K27G60000DOB000500QQQQ  0000494000Y
28800166A9K27G60000DPS000500QQQQ  0000496400Y
28800166A9K27G60000DQS000500QQQQ  0000497000Y
28800166A9K27G60000DRS000500QQQQ  0000497600Y
28800166A9K27G60000DSB000500QQQQ  0000494200Y
28800166A9K27G60000DTS000500QQQQ  0000496300Y
28800166A9K27G60000DUS000500QQQQ  0000496900Y
28800166A9K27G60000DVS000500QQQQ  0000496500Y
28800166A9K27G60000DWS000500QQQQ  0000497100Y
28800166A9K27G60000DXS000500QQQQ  0000497700Y
28800166A9K27G60000DYS000500QQQQ  0000497500Y
28800167A4K27GA00002ZB000100DRYS  0001052600Y
28800168X1K27GA00000Y000100
28800168A1K27GA00000YS000100AAPL  0001831900Y
28800168X1K27GA00000V000100
28800168A1K27GA00000VB000100AAPL  0001826100Y
28800168X1K27GA00000W000100
28800168A1K27GA00000WS000100AAPL  0001831900Y
28800172A9K27G60000DZB001000QQQQ  0000495200Y
28800172A9K27G60000E0B001000QQQQ  0000495300Y
28800172A9K27G60000E1B000500QQQQ  0000495200Y
28800172A9K27G60000E2B000500QQQQ  0000495300Y
28800173A5K27GA00000JS000100FXP   0000658400Y
28800174A5K27GA00000KB000100FXP   0000654400Y
28800174X5K27GA00000K000100
28800176A5K27GA00000LB000100FXP   0000654200Y
28800179X5K27GA00000J000100
28800179A5K27GA00000MB000100FXP   0000656600Y
28800180X1K27GA00000V000100
28800180A1K27GA00000VB000100AAPL  0001828600Y
28800180X1K27GA00000Y000100
28800180A1K27GA00000YS000100AAPL  0001834800Y
28800180X1K27GA00000X000100
28800180A1K27GA00000XB000100AAPL  0001830100Y
28800180XAK27GA0000DW000100
28800181X4K27GA00002X000100
28800179X6K27GA00001I000100
28800181X1K27GA00000Y000100
28800181A1K27GA00000YS000100AAPL  0001833400Y
28800182A9K27G60000E3B001000QQQQ  0000495500Y
28800182X1K27GA00000Y000100
28800182A1K27GA00000YS000100AAPL  0001831900Y
28800183A4K27GA000030B000100DIG   0001235600Y
28800183AAK27GA0000E0B000100SPY   0001423700Y
28800182A6K27GA00001KB000100IYE   0001530300Y
28800185A4K27GA000031B000100DIG   0001237700Y
28800185X4K27GA000030000100
28800184A6K27GA00001LB000100IYE   0001531500Y
28800190ABK27GA00000TS000100UYG   0000322900Y
28800190A4K27GA000032S000100DRYS  0001071400Y
28800189A6K27GA00001MS000100IYF   0000860000Y
28800189A6K27GA00001NS000100IYF   0000859900Y
28800191A6K27GA00001OB000100IYF   0000853100Y
28800196A6K27GA00001PS000100IYM   0000877000Y
28800196A6K27GA00001QB000100IYM   0000869800Y
28800212A4K27GA000033S000100EEV   0000611400Y
28800212A4K27GA000034S000100EEM   0001541800Y
28800272A6K27GA00001RS000100IYR   0000713000Y
28800274ABK27GA00000UB000100URE   0000371000Y
28800274ABK27GA00000VS000100URE   0000385600Y
28800272A6K27GA00001SB000100IYR   0000699000Y
28800277A9K27G60000E4B001000QLD   0000888600Y
28800277X9K27G60000D0001000
28800277X9K27G60000D2001000
28800277X9K27G60000E3001000
28800279X9K27G60000E2000500
28800279X9K27G60000E1000500
28800279X9K27G60000E0001000
28800279X9K27G60000DZ001000
28800279A9K27G60000E5S001000QLD   0000890300Y
28800279A9K27G60000E6B001000QQQQ  0000495200Y
28800279A9K27G60000E7S001000QQQQ  0000496100Y
28800279A9K27G60000E8S001000QQQQ  0000496000Y
28800279X9K27G60000E8001000
28800279X9K27G60000E7001000
28800279A9K27G60000E9B001000QQQQ  0000495300Y
28800281A9K27G60000EAS000100QID   0000382400Y
28800282X9K27G60000E6001000
28800282X9K27G60000D3001000
28800283A9K27G60000EBS001000QLD   0000890400Y
28800283X9K27G60000DA000500
28800283A8K27G6000001S000500MZZ   0000494100Y
28800284A8K27G6000002B000500MZZ   0000491700Y
28800284A8K27G6000003S000100MVV   0000809000Y
28800284A8K27G6000004B000100MVV   0000805900Y
28800283X4K27GA00002V000100
28800283A4K27GA000035B000100DXD   0000499600Y
28800283A4K27GA000036B000100DXD   0000499500Y
28800285X3K27G6000006000100
28800285A9K27G60000ECB000500QQQQ  0000493600Y
28800285A4K27GA000037B000100DXD   0000499700Y
28800287A3K27G6000008S000100DDM   0000802200Y
28800297X1K27GA00000Y000100
28800297A1K27GA00000YS000100AAPL  0001833400Y
28800301ABK27GA00000WB000100URE   0000372200Y
28800300X6K27GA00001S000100
28800300A6K27GA00001TB000100IYR   0000700500Y
28800311X6K27GA00001T000100
28800311A6K27GA00001UB000100IYR   0000707000Y
28800312ABK27GA00000XB000100URE   0000379200Y
28800318E1K27GA00000X00010000001AQ00001
28800319X1K27GA00000Y000100
28800319A1K27GA00000YS000100AAPL  0001831900Y
28800324X4K27GA00002Z000100
28800326A4K27GA000038B015000ENCY  0000023300Y
28800327A4K27GA000039S010930ENCY  0000023500Y
28800330A8K27G6000005B000500MZZ   0000491800Y
28800330A3K27G6000009B000100DELL  0000010000Y
28800340A4K27GA00003AB000100DRYS  0001060800Y
28800377A6K27GA00001VB000100IYF   0000854200Y
28800378A6K27GA00001WB000100IYF   0000854100Y
28800395X5K27GA00000M000100
28800397A5K27GA00000NB000100FXP   0000656100Y
28800455X9K27G60000D1001000
28800457A9K27G60000EDB001000QQQQ  0000495200Y
28800461X9K27G60000ED001000
28800499X9K27G60000E4001000
28800501A9K27G60000EEB001000QLD   0000888400Y
28800501A9K27G60000EFB001000QQQQ  0000495200Y
28800511X9K27G60000EF001000
28800520A9K27G60000EGS000100QLD   0000889700Y
28800520A9K27G60000EHS001000QQQQ  0000495800Y
28800520A9K27G60000EIS000500QQQQ  0000496000Y
28800520A9K27G60000EJS000500QQQQ  0000495900Y
28800520A9K27G60000EKS000500QQQQ  0000495800Y
28800531X9K27G60000EI000500
28800531A9K27G60000ELS001000QQQQ  0000496000Y
28800531X9K27G60000EH001000
28800533A9K27G60000EMS001000QQQQ  0000495900Y
28800561AAK27GA0000E1S000100SKF   0001033900Y
28800560A6K27GA00001XB000100IYF   0000855100Y
28800561A6K27GA00001YB000100IYF   0000854900Y
28800562A6K27GA00001ZB000100IYF   0000854800Y
28800562X6K27GA00001O000100
28800582X5K27GA00000N000100
28800583A5K27GA00000OB000100FXP   0000655800Y
28800728XAK27GA0000E1000100
28800727A6K27GA000020B000100IYF   0000855000Y
28800728AAK27GA0000E2S000100SKF   0001031700Y
28800728A6K27GA000021B000100IYF   0000855800Y
28800728X6K27GA00001W000100
28800729A6K27GA000022B000100IYF   0000855700Y
28800729X6K27GA00001V000100
28800758X5K27GA00000O000100
28800758A5K27GA00000PS000100FXP   0000657300Y
28801017A6K27GA000023S000100IYF   0000858900Y
28801018XAK27GA0000E0000100
28801019AAK27GA0000E3B000100SPY   0001423800Y
28801019ABK27GA00000YS000100UYG   0000322200Y
28801018A6K27GA000024S000100IYF   0000860000Y
28801036AAK27GA0000E4B001000SPY   0001425000Y
28801036AAK27GA0000E5S001000SPY   0001425200Y
28801098AAK27GA0000E6S001000SPY   0001425300Y
28801098AAK27GA0000E7B001000SPY   0001424900Y
28801105AAK27GA0000E8B001000SPY   0001424800Y
28801105AAK27GA0000E9S001000SPY   0001425400Y
28801117AAK27GA0000EAS001000SPY   0001425500Y
28801117AAK27GA0000EBB001000SPY   0001424700Y
28801337AAK27GA0000ECB001000SPY   0001425000Y
28801337AAK27GA0000EDS001000SPY   0001425200Y
28801435AAK27GA0000EES001000SPY   0001425300Y
28801435AAK27GA0000EFB001000SPY   0001424900Y
28801436AAK27GA0000EGS001000SPY   0001425400Y
28801536AAK27GA0000EHB001000SPY   0001424800Y
28801537AAK27GA0000EIS001000SPY   0001425500Y
28801560A9K27G60000ENS002000QQQQ  0000495700Y
28801560A9K27G60000EOB002000QQQQ  0000495500Y
28801574AAK27GA0000EJB001000SPY   0001424700Y
28801660A9K27G60000EPB002000QQQQ  0000495400Y
28801660A9K27G60000EQS002000QQQQ  0000495800Y
28801697A9K27G60000ERB005000QQQQ  0000495500Y
28801697A9K27G60000ESS005000QQQQ  0000495700Y
28801761A9K27G60000ETS002000QQQQ  0000495900Y
28801761A9K27G60000EUB002000QQQQ  0000495300Y
28801797A9K27G60000EVS005000QQQQ  0000495800Y
28801797A9K27G60000EWB005000QQQQ  0000495400Y
28801897A9K27G60000EXB005000QQQQ  0000495300Y
28801897A9K27G60000EYS005000QQQQ  0000495900Y
28801914A1K27GA000011B000100AAPL  0001828600Y
28801997A9K27G60000EZB005000QQQQ  0000495200Y
28801997A9K27G60000F0S005000QQQQ  0000496000Y
28802100X1K27GA000011000100
28802100A1K27GA000011B000100AAPL  0001830100Y
28802322A9K27G60000F1B003200QQQQ  0000495500Y
28802322A9K27G60000F2S003200QQQQ  0000495700Y
28802408A6K27GA000025B000500IWM   0000736200Y
28802408A6K27GA000026S000500IWM   0000736500Y
28802424A9K27G60000F3B003200QQQQ  0000495400Y
28802424A9K27G60000F4S003200QQQQ  0000495800Y
28802439A6K27GA000027B000500IWM   0000736100Y
28802439A6K27GA000028S000500IWM   0000736600Y
28802465A9K27G60000F5B003200QQQQ  0000495300Y
28802465A9K27G60000F6S003200QQQQ  0000495900Y
28802465X1K27GA000011000100
28802465A1K27GA000011B000100AAPL  0001828600Y
28802520X4K27GA00003A000100
28802522A9K27G60000F7B003200QQQQ  0000495200Y
28802522A9K27G60000F8S003200QQQQ  0000496000Y
28802537A4K27GA00003BB000100DRYS  0001065100Y
28802568X4K27GA00002T000100
28802568X4K27GA000037000100
28802568A4K27GA00003CS000100DXD   0000500400Y
28802570A4K27GA00003DB000100DXD   0000499400Y
28802575X4K27GA00002W000100
28802576A4K27GA00003EB000100DOG   0000597100Y
28802623A9K27G60000F9B003200QQQQ  0000495100Y
28802623A9K27G60000FAS003200QQQQ  0000496100Y
28802661XAK27GA0000E5001000
28802661AAK27GA0000E5S001000SPY   0001425600Y
28802666XAK27GA0000DV001000
28802667XBK27GA00000M001000
28802668AAK27GA0000EKB001000SDS   0000547900Y
28802669ABK27GA00000ZS001000SSO   0000764900Y
28802672A6K27GA000029B000500IWM   0000736000Y
28802672A6K27GA00002AS000500IWM   0000736700Y
28802676A6K27GA00002BS000500IWM   0000736800Y
28802676A6K27GA00002CB000500IWM   0000735900Y
28802682A9K27G60000FBB001000QLD   0000888600Y
28802682X9K27G60000EE001000
28802685A9K27G60000FCB001000QQQQ  0000495200Y
28802688X9K27G60000F2003200
28802688A9K27G60000F2S003200QQQQ  0000496200Y
28802688X9K27G60000EZ005000
28802690A9K27G60000FDB001000QLD   0000888500Y
28802694A9K27G60000FEB005000QQQQ  0000495600Y
28802694X9K27G60000FC001000
28802858AAK27GA0000ELB003000SPY   0001424900Y
28802858AAK27GA0000EMS003000SPY   0001425400Y
28802864AAK27GA0000ENB003000SPY   0001424700Y
28802864AAK27GA0000EOS003000SPY   0001425600Y
28802866AAK27GA0000EPB003000SPY   0001424500Y
28802866AAK27GA0000EQS003000SPY   0001425800Y
28802903XAK27GA0000ED001000
28802917XAK27GA0000EB001000
28802917AAK27GA0000EBB001000SPY   0001425100Y
28802917XAK27GA0000EJ001000
28802918AAK27GA0000ERS001000SPY   0001425600Y
28802918AAK27GA0000ESB000900SPY   0001425100Y
28802918AAK27GA0000ETB003000SPY   0001424900Y
28802918AAK27GA0000EUS003000SPY   0001425400Y
28802919AAK27GA0000EVS000100SH    0000619100Y
28802920XBK27GA00000K001000
28802920ABK27GA000010B001000SSO   0000763900Y
28802922XBK27GA00000L001000
28802922ABK27GA000011B001000SSO   0000763700Y
28802926AAK27GA0000EWS000500SPY   0001425300Y
28802926AAK27GA0000EXB000500SPY   0001425000Y
28802926AAK27GA0000EYS003000SPY   0001425600Y
28802926AAK27GA0000EZB003000SPY   0001424700Y
28802953AAK27GA0000F0S003000SPY   0001425800Y
28802953AAK27GA0000F1B003000SPY   0001424500Y
28802953AAK27GA0000F2B000500SPY   0001424900Y
28802953AAK27GA0000F3S000500SPY   0001425400Y
28802980AAK27GA0000F4S000500SPY   0001425500Y
28802980AAK27GA0000F5B000500SPY   0001424800Y
28802995AAK27GA0000F6S000500SPY   0001425600Y
28802995AAK27GA0000F7B000500SPY   0001424700Y
28803036XAK27GA0000DY000100
28803036XAK27GA0000EK001000
28803036XBK27GA00000Z001000
28803037AAK27GA0000F8B000100SH    0000618400Y
28803038AAK27GA0000F9B001000SDS   0000547800Y
28803038ABK27GA000012S001000SSO   0000765000Y
28803047XAK27GA0000DZ001000
28803219A4K27GA00003FS000100DXD   0000500500Y
28803219A4K27GA00003GS000200DIA   0001298500Y
28803219A4K27GA00003HB000200DIA   0001298300Y
28803221A4K27GA00003IS000100DXD   0000500600Y
28803221A4K27GA00003JB000100DOG   0000597200Y
28803221A3K27G600000AS000100DDM   0000802100Y
28803221A4K27GA00003KB000100DXD   0000499700Y
28803222A4K27GA00003LB000200DIA   0001298200Y
28803222A4K27GA00003MS000200DIA   0001298600Y
28803224X3K27G6000008000100
28803224X3K27G600000A000100
28803224E4K27GA00003G00007700004AQ00001
28803224E4K27GA00003G00007600004AQ00002
28803225X4K27GA00003J000100
28803226A3K27G600000BS000100DDM   0000802200Y
28803226X4K27GA00003K000100
28803228A4K27GA00003PB000100DXD   0000499700Y
28803234X4K27GA00003P000100
28803238X4K27GA00003G000047
28803238A4K27GA00003QB000200DIA   0001298100Y
28803240P4K27GA00003PB000100DXD   0000499600000N4AQ00003
28803247X4K27GA00003C000100
28803247X3K27G6000007000100
28803247X4K27GA00002R000100
28803248A4K27GA00003RS000100DXD   0000500700Y
28803249A3K27G600000CB000100DDM   0000800600Y
28803249A4K27GA00003SS000100DOG   0000598600Y
28803685XAK27GA0000F7000500
28803685AAK27GA0000F7B000500SPY   0001425100Y
28803869A9K27G60000FFS005000QQQQ  0000495700Y
28803869A9K27G60000FGB005000QQQQ  0000495500Y
28803968A9K27G60000FHB005000QQQQ  0000495400Y
28803968A9K27G60000FIS005000QQQQ  0000495800Y
28804068A9K27G60000FJB005000QQQQ  0000495300Y
28804068A9K27G60000FKS005000QQQQ  0000495900Y
28804168A9K27G60000FLB005000QQQQ  0000495200Y
28804168A9K27G60000FMS005000QQQQ  0000496000Y
28804485A4K27GA00003TS000100DOG   0000598500Y
28804485X4K27GA00002S000100
28804485A4K27GA00003US000100DXD   0000500400Y
28804485A3K27G600000DB000100DDM   0000800700Y
28804999XAK27GA0000EW000500
28804999AAK27GA0000EWS000500SPY   0001425700Y
28805083A9K27G60000FNS002000QQQQ  0000495700Y
28805083A9K27G60000FOB002000QQQQ  0000495500Y
28805183A9K27G60000FPS002000QQQQ  0000495800Y
28805614XAK27GA0000EW000500
28805614AAK27GA0000EWS000500SPY   0001425300Y
28805824A9K27G60000FQB002000QQQQ  0000495600Y
28805824X9K27G60000FL005000
28805825A9K27G60000FRB005000QQQQ  0000495600Y
28805826X9K27G60000EU002000
28805826A9K27G60000EUB002000QQQQ  0000495600Y
28805962A8K27G6000006B002000MSFT  0000282700Y
28806390A1K27GA000012B002000AMAT  0000182900Y
28806429A1K27GA000013B002000AMGN  0000413600Y
28806448A1K27GA000014B002000AMZN  0000796800Y
28806466A2K27G600000FB002000BRCM  0000259400Y
28806486A3K27G600000EB002000CELG  0000454800Y
28806510A3K27G600000FB002000CHKP  0000231700Y
28806531A3K27G600000GB002000CREE  0000237300Y
28806556A3K27G600000HB002000CYMI  0000285200Y
28806574A4K27GA00003VB002000DISH  0000320300Y
28806603A4K27GA00003WB002000DRIV  0000358300Y
28806794AAK27GA0000FAB000600SPY   0001419600Y
28806923AAK27GA0000FBS000100SKF   0001031400Y
28806923XAK27GA0000E2000100
28806922A6K27GA00002DB000100IYF   0000855300Y
28806922X6K27GA00001X000100
28806923X6K27GA00001Z000100
28806923A6K27GA00002EB000100IYF   0000855900Y
28806925AAK27GA0000FCS000500SPY   0001425400Y
28806925AAK27GA0000FDB000500SPY   0001425000Y
28806927AAK27GA0000FEB000500SPY   0001424900Y
28806927AAK27GA0000FFS000500SPY   0001425500Y
28806928AAK27GA0000FGB000500SPY   0001424800Y
28806928AAK27GA0000FHS000500SPY   0001425600Y
28806930AAK27GA0000FIB000500SPY   0001424700Y
28806930AAK27GA0000FJS000500SPY   0001425700Y
28806960X1K27GA000011000100
28806960A1K27GA000011B000100AAPL  0001830100Y
28807196E5K27GA00000L00002000005AQ00001
28807197X5K27GA00000P000100
28807197X5K27GA00000L000080
28807197A5K27GA00000RS000100FXP   0000657100Y
28807199A5K27GA00000SB000100FXP   0000654100Y
28807216E5K27GA00000S00010000005AQ00002
28807218A5K27GA00000UB000100FXP   0000652500Y
28807220X5K27GA00000U000100
28807222A5K27GA00000VB000100FXP   0000652500Y
28807224X5K27GA00000V000100
28807225A5K27GA00000WB000100FXP   0000651400Y
28807226A5K27GA00000XB000100FXP   0000652500Y
28807239E5K27GA00000X00010000005AQ00003
28807241X5K27GA00000W000100
28807242A5K27GA00000ZB000100FXP   0000652300Y
28807274A4K27GA00003XS000200DIA   0001298700Y
28807386A4K27GA00003YB002000EBAY  0000292900Y
28807423A4K27GA00003ZB002000ENZN  0000069500Y
28807440A5K27GA000010B002000GILD  0000515700Y
28807456A5K27GA000011B002000IACI  0000220300Y
28807472A6K27GA00002FB002000IMCL  0000285600Y
28807478A6K27GA00002GB002000INTC  0000237800Y
28807492A6K27GA00002HB002000INTU  0000256400Y
28807506A7K27GA00000KB002000MRVL  0000135200Y
28807520A8K27G6000007B002000NFLX  0000308000Y
28807528PCK27GA000016B000177ZVZZT 0020000000000I000HV1PJ
28807529PCK27GA000016B000100ZVZZT 0020000000000I000HV1PK
28807529PCK27GA000016B000100ZVZZT 0020000000000I000HV1PL
28807959AAK27GA0000FKB002000SAP   0000470900Y
28807982A1K27GA000015B002000A     0000345100Y
28808228X9K27G60000ES005000
28808228X9K27G60000FF005000
28808229X9K27G60000EN002000
28808229A9K27G60000ENS002000QQQQ  0000496000Y
28808230A9K27G60000FSS005000QQQQ  0000496100Y
28808230A9K27G60000FTS005000QQQQ  0000496100Y
28808393A1K27GA000016B002000AA    0000431500Y
28808420A9K27G60000FUB002000QCOM  0000457300Y
28808443A1K27GA000017B002000ADI   0000339700Y
28808446A4K27GA000040S000047DIA   0001298800Y
28808453A9K27G60000FVB002000QLGC  0000144200Y
28808485A1K27GA000018B002000ADP   0000419000Y
28808495AAK27GA0000FLB002000SHLD  0000604900Y
28808513A1K27GA000019B002000AIG   0000371800Y
28808528AAK27GA0000FMB002000SINA  0000507400Y
28808550AAK27GA0000FNB002000SMTC  0000162200Y
28808553A1K27GA00001AB002000APA   0001428400Y
28808590AAK27GA0000FOB002000SOHU  0000796000Y
28808605A2K27G600000GB002000BAC   0000347300Y
28808623ABK27GA000013B002000SYMC  0000195200Y
28808633A2K27G600000HB002000BRL   0000370400Y
28808654ABK27GA000014B002000TTWO  0000254000Y
28808666A2K27G600000IB002000C     0000218900Y
28808720A3K27G600000IB002000COF   0000495200Y
28808736A4K27GA000041B002000DNA   0000685300Y
28809385X6K27GA00002F002000
28809418XAK27GA0000FL002000
28809425A4K27GA000042B002000DVN   0001208500Y
28809462ACK27GA000017B002000VSEA  0000373100Y
28809489A4K27GA000043B002000EMR   0000551000Y
28809502ACK27GA000018B002000WFMI  0000275300Y
28809539A5K27GA000012B002000FNM   0000275800Y
28809539A1K27GA00001BB002000AA    0000432300Y
28809550ACK27GA000019B002000XLNX  0000254400Y
28809581A5K27GA000013B002000GG    0000384100Y
28809606A1K27GA00001CB002000ADI   0000340500Y
28809644A5K27GA000014B002000GM    0000171100Y
28809649ACK27GA00001AB002000YHOO  0000265100Y
28809671A1K27GA00001DB002000ADP   0000419800Y
28809707A1K27GA00001EB002000AAPL  0001816400Y
28809708A5K27GA000015B002000GS    0001816500Y
28809744A1K27GA00001FB002000AIG   0000372600Y
28809755A6K27GA00002IB002000IBM   0001246600Y
28809791A1K27GA00001GB002000ADSK  0000384200Y
28809807A1K27GA00001HB002000APA   0001429200Y
28809830A6K27GA00002JB002000JNJ   0000638000Y
28809840A1K27GA00001IB002000ADTN  0000228200Y
28809877A7K27GA00000LB002000KSS   0000453000Y
28809892A2K27G600000JB002000BAC   0000348200Y
28809901A1K27GA00001JB002000ALTR  0000211400Y
28809928A7K27GA00000MB002000LMT   0000020300Y
28809989A2K27G600000KB002000C     0000219700Y
28810016A3K27G600000JB002000COF   0000496000Y
28810038A4K27GA000044B002000DNA   0000686100Y
28810393X7K27GA00000M002000
28810459A7K27GA00000NB002000MDT   0000477800Y
28810459A4K27GA000045B002000DVN   0001209300Y
28810461A6K27GA00002KB002000IMCL  0000288900Y
28810470A7K27GA00000OB002000MMM   0000762000Y
28810482AAK27GA0000FPS001000SPY   0001425400Y
28810482AAK27GA0000FQB001000SPY   0001424900Y
28810482AAK27GA0000FRB002000SHLD  0000610000Y
28810494A4K27GA000046B002000EMR   0000551800Y
28810536A7K27GA00000PB002000MO    0000211600Y
28810538A1K27GA00001KB002000APOL  0000403200Y
28810579A1K27GA00001LB002000APPX  0000092400Y
28810581A8K27G6000008B002000NBR   0000402800Y
28810581A5K27GA000016B002000FNM   0000276600Y
28810624A2K27G600000LB002000BBBY  0000307500Y
28810642A5K27GA000017B002000GG    0000384900Y
28810656A2K27G600000MB002000CAKE  0000193900Y
28810683A5K27GA000018B002000GM    0000172000Y
28810685A3K27G600000KB002000CECO  0000107600Y
28810728A3K27G600000LB002000CEPH  0000645200Y
28810728A8K27G6000009B002000NEM   0000472800Y
28810728A5K27GA000019B002000GS    0001817300Y
28810742A9K27G60000FWB004000QQQQ  0000495400Y
28810742A9K27G60000FXB004000QQQQ  0000495300Y
28810742A9K27G60000FYS002000QQQQ  0000495800Y
28810743A9K27G60000FZS004000QQQQ  0000495900Y
28810744A9K27G60000G0B002000QQQQ  0000495600Y
28810744A9K27G60000G1S002000QQQQ  0000495800Y
28810746A9K27G60000G2B002000QQQQ  0000495500Y
28810746A9K27G60000G3S002000QQQQ  0000495900Y
28810747A9K27G60000G4B002000QQQQ  0000495400Y
28810747A9K27G60000G5S002000QQQQ  0000496000Y
28810749A9K27G60000G6B002000QQQQ  0000495300Y
28810749A9K27G60000G7S002000QQQQ  0000496100Y
28810751A9K27G60000G8B002000QQQQ  0000495200Y
28810751A9K27G60000G9S002000QQQQ  0000496200Y
28810783ABK27GA000015B002000TGT   0000515800Y
28810792A6K27GA00002LB002000IBM   0001247400Y
28810841ABK27GA000016B002000TXN   0000308200Y
28810877A6K27GA00002MB002000JNJ   0000638900Y
28810890ABK27GA000017B002000TYC   0000439100Y
28810906A7K27GA00000QB002000KSS   0000453800Y
28810928ABK27GA000018B002000UTX   0000012300Y
28810958ACK27GA00001BB002000VZ    0000373300Y
28811393XAK27GA0000FR002000
28811489A3K27G600000MB002000CCMP  0000354200Y
28811488A7K27GA00000RB002000LMT   0000027100Y
28811528A3K27G600000NB002000CMCSA 0000192100Y
28811547X9K27G60000F9003200
28811547A9K27G60000F9B003200QQQQ  0000495600Y
28811549XBK27GA000018002000
28811550X9K27G60000FN002000
28811554A9K27G60000GAS002000QQQQ  0000495900Y
28811554X9K27G60000EB001000
28811556A9K27G60000GBS001000QQQQ  0000495900Y
28811556X9K27G60000EL001000
28811557A7K27GA00000SB002000MDT   0000478600Y
28811560X9K27G60000GB001000
28811562A9K27G60000GCS001000QQQQ  0000496000Y
28811582A3K27G600000OB002000COST  0000693000Y
28811594A7K27GA00000TB002000LMT   0000026300Y
28811616A3K27G600000PB002000CSCO  0000251300Y
28811629ACK27GA00001CB002000WLP   0000500100Y
28811644A3K27G600000QB002000CTAS  0000281600Y
28811659A7K27GA00000UB002000MMM   0000762800Y
28811659ACK27GA00001DB002000WMT   0000534300Y
28811685A3K27G600000RB002000CYBX  0000139900Y
28811707A1K27GA00001MB002000ABX   0000393000Y
28811707A7K27GA00000VB002000MO    0000212400Y
28811763XAK27GA0000FP001000
28811765AAK27GA0000FSS001000SPY   0001425500Y
28811772A8K27G600000AB002000NBR   0000403600Y
28811775A1K27GA00001NB002000ACE   0000586400Y
28811800A8K27G600000BB002000NEM   0000473600Y
28811806A1K27GA00001OB002000ACF   0000117400Y
28811826ABK27GA000019B002000TGT   0000516700Y
28811832A1K27GA00001PB002000ACN   0000356600Y
28811860ABK27GA00001AB002000TXN   0000309000Y
28811863A1K27GA00001QB002000AFL   0000012600Y
28811890ABK27GA00001BB002000TYC   0000439900Y
28812226A6K27GA00002NB002000IWM   0000736100Y
28812226A6K27GA00002OB002000IWM   0000736000Y
28812227A6K27GA00002PS002000IWM   0000736600Y
28812228X9K27G60000FW002000
28812227A6K27GA00002QS002000IWM   0000736700Y
28812244A9K27G60000GDB002000QQQQ  0000495400Y
28812276X9K27G60000GD002000
28812376X3K27G600000E002000
28812389X7K27GA00000R002000
28812416ABK27GA00001CB002000UTX   0000017100Y
28812425AAK27GA0000FTS001000SPY   0001425400Y
28812469X6K27GA00002K002000
28812493AAK27GA0000FUB002000SHLD  0000615100Y
28812497ACK27GA00001EB002000VZ    0000374100Y
28812535X9K27G60000GC001000
28812535A9K27G60000GES001000QQQQ  0000495900Y
28812542A3K27G600000SB002000DELL  0000192700Y
28812557ACK27GA00001FB002000WLP   0000500900Y
28812568X9K27G60000F9003200
28812568A9K27G60000F9B003200QQQQ  0000495100Y
28812595A4K27GA000047B002000ESRX  0000648000Y
28812610ACK27GA00001GB002000WMT   0000535200Y
28812632AAK27GA0000FVB001000SDS   0000547800Y
28812639A1K27GA00001RB002000A     0000345900Y
28812682X7K27GA00000T002000
28812701A1K27GA00001SB002000ABT   0000011000Y
28812720A4K27GA000048B002000EXPD  0000442600Y
28812736ABK27GA00001DB002000UTX   0000016300Y
28812754A1K27GA00001TB002000ABX   0000393800Y
28812767A1K27GA00001UB002000ABT   0000010100Y
28812792A4K27GA000049B002000FFIV  0000262500Y
28812795X1K27GA00001Q002000
28812824A1K27GA00001VB002000ACE   0000587200Y
28812835A4K27GA00004AB002000FISV  0000500200Y
28812848A1K27GA00001WB002000ALL   0000483400Y
28812922A1K27GA00001XB002000ANF   0000719100Y
28813063XAK27GA0000EP003000
28813063XAK27GA0000EM003000
28813063AAK27GA0000FWB002000SPY   0001425100Y
28813063XAK27GA0000E6001000
28813063AAK27GA0000E6S001000SPY   0001425700Y
28813063XAK27GA0000FC000500
28813063AAK27GA0000FCS000500SPY   0001425800Y
28813063XAK27GA0000E8001000
28813063AAK27GA0000E8B001000SPY   0001425200Y
28813063XAK27GA0000FI000500
28813063AAK27GA0000FIB000500SPY   0001425200Y
28813063AAK27GA0000FXB003000SPY   0001425200Y
28813064X9K27G60000G8002000
28813064A9K27G60000G8B002000QQQQ  0000495600Y
28813063X4K27GA00003M000200
28813063X4K27GA00003Q000200
28813063A4K27GA00003QB000200DIA   0001298500Y
28813063X4K27GA00003L000200
28813063A4K27GA00003LB000200DIA   0001298400Y
28813063X4K27GA00003X000200
28813063XAK27GA0000EH001000
28813063XAK27GA0000F5000500
28813063AAK27GA0000F5B000500SPY   0001425200Y
28813063XAK27GA0000F1003000
28813063XAK27GA0000EW000500
28813063AAK27GA0000EWS000500SPY   0001425700Y
28813064XAK27GA0000F4000500
28813064AAK27GA0000F4S000500SPY   0001425800Y
28813064XAK27GA0000F3000500
28813064XAK27GA0000EU003000
28813064XAK27GA0000FT001000
28813064AAK27GA0000FYB000900SPY   0001424700Y
28813064XAK27GA0000EG001000
28813064XAK27GA0000EE001000
28813064XAK27GA0000FG000500
28813064AAK27GA0000FGB000500SPY   0001425100Y
28813064XAK27GA0000E9001000
28813064AAK27GA0000E9S001000SPY   0001425800Y
28813064XAK27GA0000FF000500
28813064AAK27GA0000FFS000500SPY   0001425900Y
28813064AAK27GA0000FZB003000SPY   0001425200Y
28813064AAK27GA0000G0B002000SPY   0001425100Y
28813065X9K27G60000D4001000
28813064AAK27GA0000G1S003000SPY   0001426000Y
28813065X9K27G60000E5001000
28813064AAK27GA0000G2B002000SPY   0001425200Y
28813065AAK27GA0000G3S001000SDS   0000549200Y
28813065ABK27GA00001EB001000SSO   0000764000Y
28813065XBK27GA000010001000
28813065A4K27GA00004BS000200DIA   0001298900Y
28813065AAK27GA0000G4S000500SPY   0001425500Y
28813066X4K27GA00002U000100
28813066A3K27G600000TB000100DDM   0000800800Y
28813066A4K27GA00004CS000100DXD   0000500300Y
28813066AAK27GA0000G5S003000SPY   0001426000Y
28813066XAK27GA0000FY000900
28813066AAK27GA0000G6S001000SPY   0001425700Y
28813066XAK27GA0000FF000500
28813066AAK27GA0000FFS000500SPY   0001425500Y
28813066AAK27GA0000G7B000900SPY   0001425200Y
28813067A9K27G60000GFS001000QQQQ  0000496000Y
28813067XBK27GA000011001000
28813067ABK27GA00001FB001000SSO   0000763800Y
28813067XAK27GA0000F2000500
28813067AAK27GA0000F2B000500SPY   0001425200Y
28813068AAK27GA0000G8S001000SPY   0001425800Y
28813068AAK27GA0000G9S000100SH    0000619000Y
28813068AAK27GA0000GAS001000SDS   0000549100Y
28813068XBK27GA00001E001000
28813068ABK27GA00001GB001000SSO   0000764100Y
28813069XAK27GA0000F2000500
28813069AAK27GA0000F2B000500SPY   0001424900Y
28813069XAK27GA0000E7001000
28813069AAK27GA0000E7B001000SPY   0001425200Y
28813070XAK27GA0000EF001000
28813070AAK27GA0000GBB000900SPY   0001425200Y
28813070X9K27G60000GF001000
28813071XBK27GA00001F001000
28813071ABK27GA00001HB001000SSO   0000763900Y
28813074X9K27G60000G8002000
28813074A9K27G60000G8B002000QQQQ  0000495200Y
28813074A4K27GA00004DS000200DIA   0001299000Y
28813076XBK27GA000012001000
28813076XAK27GA0000F9001000
28813078AAK27GA0000GCB001000SDS   0000547700Y
28813081XAK27GA0000FE000500
28813081AAK27GA0000FEB000500SPY   0001425200Y
28813086XAK27GA0000FV001000
28813094X4K27GA000040000047
28813096X9K27G60000F9003200
28813096A9K27G60000F9B003200QQQQ  0000495600Y
28813097X9K27G60000FY002000
28813097A9K27G60000GGS002000QQQQ  0000496000Y
28813097A9K27G60000GHB002000QQQQ  0000495400Y
28813097X6K27GA00002C000500
28813097A6K27GA00002CB000500IWM   0000736300Y
28813099A9K27G60000GIS002000QQQQ  0000496000Y
28813098A4K27GA00004ES000047DIA   0001298800Y
28813101X8K27G6000001000500
28813099X6K27GA00002P002000
28813101X8K27G6000004000100
28813101ABK27GA00001IB000100UWM   0000542100Y
28813101ABK27GA00001JS000100TWM   0000702400Y
28813101X8K27G6000005000500
28813101XBK27GA00000R000100
28813101X8K27G6000003000100
28813101X4K27GA00004E000047
28813103A8K27G600000CS000500MZZ   0000494200Y
28813103A8K27G600000DB000100MVV   0000805800Y
28813103A8K27G600000ES000100MVV   0000809100Y
28813104A4K27GA00004FS000047DIA   0001299100Y
28813104X4K27GA000035000100
28813105X3K27G600000B000100
28813105X4K27GA00003E000100
28813105X4K27GA000036000100
28813106A4K27GA00004GB000100DXD   0000499200Y
28813107A3K27G600000US000100DDM   0000802600Y
28813105X6K27GA000026000500
28813105A6K27GA000026S000500IWM   0000736900Y
28813107A4K27GA00004HB000100DOG   0000597000Y
28813107A4K27GA00004IB000100DXD   0000499300Y
28813108XAK27GA0000FS001000
28813110AAK27GA0000GDS001000SPY   0001425600Y
28813112X9K27G60000F4003200
28813112A9K27G60000F4S003200QQQQ  0000496300Y
28813116X9K27G60000FB001000
28813116A9K27G60000GJB001000QLD   0000888700Y
28813116X9K27G60000GJ001000
28813116A9K27G60000GKB001000QLD   0000888800Y
28813116A9K27G60000GLS001000QID   0000382100Y
28813117A3K27G600000VS000100DDM   0000802500Y
28813118A9K27G60000GMB001000QQQQ  0000495200Y
28813120X9K27G60000F4003200
28813120A9K27G60000F4S003200QQQQ  0000495800Y
28813127X9K27G60000GM001000
28813127X3K27G600000V000100
28813127A8K27G600000FS000500MZZ   0000494000Y
28813127A8K27G600000GB000100MVV   0000806000Y
28813134X9K27G60000GK001000
28813134A9K27G60000GNB001000QLD   0000888900Y
28813135A9K27G60000GOS000100QID   0000382300Y
28813136A9K27G60000GPB001000QQQQ  0000495200Y
28813136XAK27GA0000FF000500
28813136AAK27GA0000FFS000500SPY   0001425900Y
28813140X9K27G60000GP001000
28813142X4K27GA00003H000200
28813142A4K27GA00003HB000200DIA   0001298600Y
28813144A4K27GA00004JS000100DOG   0000598400Y
28813144X4K27GA00003R000100
28813144A4K27GA00004KS000100DXD   0000500200Y
28813145A3K27G600000WB000100DDM   0000801000Y
28813149X9K27G60000F4003200
28813149A9K27G60000F4S003200QQQQ  0000496300Y
28813151X4K27GA00003L000200
28813151A4K27GA00003LB000200DIA   0001298700Y
28813151X4K27GA00004B000200
28813151XAK27GA0000GD001000
28813151XAK27GA0000E7001000
28813151AAK27GA0000E7B001000SPY   0001425300Y
28813151XAK27GA0000GB000900
28813151AAK27GA0000GBB000900SPY   0001425300Y
28813151XAK27GA0000FE000500
28813151AAK27GA0000FEB000500SPY   0001425300Y
28813150A6K27GA00002RB002000IWM   0000736200Y
28813153AAK27GA0000GES001000SPY   0001425700Y
28813154A3K27G600000XB000100DDM   0000801100Y
28813154X3K27G600000C000100
28813154A4K27GA00004LS000200DIA   0001299200Y
28813170X4K27GA00004L000200
28813174X4K27GA00003L000200
28813174A4K27GA00003LB000200DIA   0001298400Y
28813174A4K27GA00004MS000200DIA   0001298900Y
28813176X3K27G600000X000100
28813185X9K27G60000F4003200
28813185A9K27G60000F4S003200QQQQ  0000495800Y
28813187XAK27GA0000F2000500
28813187AAK27GA0000F2B000500SPY   0001425300Y
28813210AAK27GA0000GFB001000SPY   0001425200Y
28813210XAK27GA0000FQ001000
28813215XAK27GA0000F8000100
28813217XAK27GA0000DX000100
28813217AAK27GA0000GGB000100SH    0000618300Y
28813221AAK27GA0000GHS000100SPY   0001426900Y
28813224XAK27GA0000EY003000
28813224XAK27GA0000EO003000
28813224AAK27GA0000GIB002000SPY   0001425300Y
28813224XAK27GA0000EA001000
28813224AAK27GA0000EAS001000SPY   0001425900Y
28813225XAK27GA0000EI001000
28813225AAK27GA0000GJS003000SPY   0001426200Y
28813230AAK27GA0000GKS001000SPY   0001425900Y
28813230AAK27GA0000GLS003000SPY   0001426200Y
28813246X6K27GA000029000500
28813246A6K27GA000029B000500IWM   0000736300Y
28813247X6K27GA000028000500
28813247A6K27GA000028S000500IWM   0000737000Y
28813248ABK27GA00001KB000100UWM   0000542300Y
28813249ABK27GA00001LS000100TWM   0000702200Y
28813249XBK27GA00001J000100
28813249X6K27GA000029000500
28813249A6K27GA000029B000500IWM   0000736000Y
28813249X6K27GA000028000500
28813249A6K27GA000028S000500IWM   0000736600Y
28813251XBK27GA00001K000100
28813251XBK27GA00001L000100
28813253ABK27GA00001MS000100TWM   0000702400Y
28813259X4K27GA00003L000200
28813259A4K27GA00003LB000200DIA   0001298700Y
28813259X4K27GA00004M000200
28813262A3K27G600000YB000100DDM   0000801100Y
28813264X4K27GA00003L000200
28813264A4K27GA00003LB000200DIA   0001298400Y
28813264X4K27GA00003D000100
28813264A4K27GA00004NS000200DIA   0001298900Y
28813264X4K27GA00004H000100
28813265X3K27G600000U000100
28813266A4K27GA00004OB000100DXD   0000499400Y
28813266A4K27GA00004PB000100DOG   0000597000Y
28813267X3K27G600000Y000100
28813267A3K27G600000ZS000100DDM   0000802600Y
28813268X6K27GA000029000500
28813268A6K27GA000029B000500IWM   0000736300Y
28813271ABK27GA00001NB000100UWM   0000542300Y
28813271XBK27GA00001M000100
28813271ABK27GA00001OS000100TWM   0000702200Y
28813270X6K27GA000029000500
28813270A6K27GA000029B000500IWM   0000736000Y
28813272XBK27GA00001N000100
28813272XBK27GA00001O000100
28813274ABK27GA00001PS000100TWM   0000702400Y
28813289XBK27GA00000N000100
28813289XBK27GA00000O000100
28813289XBK27GA00000S000100
28813289XBK27GA00000P000100
28813288A6K27GA00002SS002000IWM   0000736800Y
28813291ABK27GA00001QS000100UWM   0000543200Y
28813290A6K27GA00002TS000100IWM   0000737000Y
28813290X6K27GA00002T000100
28813290A6K27GA00002US000100IWM   0000736900Y
28813295X6K27GA00002U000100
28813300X9K27G60000EJ000500
28813300X9K27G60000EK000500
28813300X9K27G60000EG000100
28813300A9K27G60000GQB001000QID   0000380800Y
28813300X9K27G60000EM001000
28813301X9K27G60000GE001000
28813302A9K27G60000GRS001000QQQQ  0000496300Y
28813303A9K27G60000GSS001000QQQQ  0000496000Y
28813310X9K27G60000GS001000
28813323XAK27GA0000EC001000
28813324AAK27GA0000GMB000900SPY   0001425400Y
28813325AAK27GA0000GNS001000SDS   0000549000Y
28813325XBK27GA00001G001000
28813325ABK27GA00001RB001000SSO   0000764200Y
28813326AAK27GA0000GOS001000SDS   0000549500Y
28813327XBK27GA00001H001000
28813327ABK27GA00001SB001000SSO   0000764000Y
28813432XAK27GA0000FU002000
28813433XBK27GA00001C002000
28813441A3K27G6000010B002000CELG  0000457300Y
28813458X9K27G60000EX005000
28813458X9K27G60000FJ005000
28813458X9K27G60000F4003200
28813458A9K27G60000F4S003200QQQQ  0000496300Y
28813459A9K27G60000GTB005000QQQQ  0000495700Y
28813459A9K27G60000GUB005000QQQQ  0000495700Y
28813461A9K27G60000GVB001000QLD   0000888800Y
28813474A9K27G60000GWB002000QQQQ  0000495700Y
28813481X1K27GA00001S002000
28813486X9K27G60000G1002000
28813486A9K27G60000G1S002000QQQQ  0000496300Y
28813486X9K27G60000EP002000
28813486A9K27G60000EPB002000QQQQ  0000495700Y
28813496A7K27GA00000WB002000LMT   0000033100Y
28813497XBK27GA00001D002000
28813535X1K27GA00001U002000
28813547A6K27GA00002VB002000IMCL  0000292100Y
28813555X6K27GA00002Q002000
28813557A6K27GA00002WS002000IWM   0000736900Y
28813573X6K27GA000029000500
28813573A6K27GA000029B000500IWM   0000736400Y
28813576ABK27GA00001TB000100UWM   0000542300Y
28813576ABK27GA00001US000100TWM   0000702200Y
28813576XBK27GA00001P000100
28813576X6K27GA000029000500
28813576A6K27GA000029B000500IWM   0000736000Y
28813578X6K27GA000029000500
28813578A6K27GA000029B000500IWM   0000736400Y
28813583A1K27GA00001YB002000ACF   0000118300Y
28813585X6K27GA000029000500
28813585A6K27GA000029B000500IWM   0000736000Y
28813588X8K27G6000002000500
28813588X8K27G600000E000100
28813587X6K27GA000029000500
28813587A6K27GA000029B000500IWM   0000736400Y
28813589XBK27GA00001T000100
28813589XBK27GA00001U000100
28813590A8K27G600000HB000500MZZ   0000491600Y
28813588X6K27GA000029000500
28813588A6K27GA000029B000500IWM   0000736000Y
28813590A8K27G600000IS000100MVV   0000809300Y
28813591ABK27GA00001VB000100UWM   0000542300Y
28813591ABK27GA00001WS000100TWM   0000702200Y
28813591X6K27GA000029000500
28813591A6K27GA000029B000500IWM   0000736400Y
28813592XBK27GA00001V000100
28813592XBK27GA00001W000100
28813592A4K27GA00004QB002000FITB  0000176600Y
28813594X8K27G600000F000500
28813594X8K27G600000G000100
28813594ABK27GA00001XB000100UWM   0000542300Y
28813594ABK27GA00001YS000100TWM   0000702200Y
28813596A8K27G600000JS000500MZZ   0000494100Y
28813596A8K27G600000KB000100MVV   0000805900Y
28813596X6K27GA000029000500
28813596A6K27GA000029B000500IWM   0000736000Y
28813598X6K27GA000029000500
28813598A6K27GA000029B000500IWM   0000736400Y
28813600XBK27GA00001X000100
28813600XBK27GA00001Y000100
28813602ABK27GA00001ZS000100TWM   0000702200Y
28813602ABK27GA000020B000100UWM   0000542300Y
28813609A8K27G600000LS000500MZZ   0000494000Y
28813609A8K27G600000MB000100MVV   0000806100Y
28813615A6K27GA00002XB002000INSP  0000076500Y
28813638A1K27GA00001ZB002000ACN   0000357400Y
28813650A6K27GA00002YB002000ISIL  0000274200Y
28813668A1K27GA000020B002000AFL   0000017100Y
28813686A6K27GA00002ZB002000JNPR  0000272800Y
28813713A1K27GA000021B002000ALL   0000484200Y
28813733A7K27GA00000XB002000LMT   0000032300Y
28813761A7K27GA00000YB002000KLAC  0000444200Y
28813772A1K27GA000022B002000ANF   0000719900Y
28813780A9K27G60000GXB000500QQQQ  0000495100Y
28813787ABK27GA000021B000100TWM   0000701200Y
28813787ABK27GA000022B000100TWM   0000701000Y
28813787ABK27GA000023B000100TWM   0000701100Y
28813812A1K27GA000023B002000ANN   0000257800Y
28813837A1K27GA000024B002000AFL   0000016300Y
28813841A1K27GA000025B002000AOC   0000443100Y
28813857A1K27GA000026B002000ANN   0000257000Y
28813867A3K27G6000011S000100DDM   0000802500Y
28813868A4K27GA00004RB000100DOG   0000597100Y
28813868A3K27G6000012S000100DDM   0000802400Y
28813868A4K27GA00004SB000100DXD   0000499500Y
28813868X4K27GA00004R000100
28813868X4K27GA00004S000100
28813869X3K27G6000012000100
28813879A1K27GA000027B002000AOC   0000442300Y
28813905A1K27GA000028B002000APC   0000762000Y
28813928A1K27GA000029B002000ARO   0000291100Y
28814280X9K27G60000FI005000
28814280X9K27G60000EV005000
28814281X9K27G60000G8002000
28814281A9K27G60000G8B002000QQQQ  0000495700Y
28814282A9K27G60000GYB004000QQQQ  0000495500Y
28814282X9K27G60000EQ002000
28814282A9K27G60000EQS002000QQQQ  0000496100Y
28814282A9K27G60000GZS005000QQQQ  0000496200Y
28814282A9K27G60000H0S005000QQQQ  0000496200Y
28814383X7K27GA00000X002000
28814399X7K27GA00000W002000
28814405X1K27GA000020002000
28814427AAK27GA0000GPB002000SHLD  0000620200Y
28814432ABK27GA000024B002000UTX   0000021100Y
28814474X9K27G60000F7003200
28814474A9K27G60000F7B003200QQQQ  0000495700Y
28814482A1K27GA00002AB002000ABT   0000014000Y
28814484X9K27G60000FP002000
28814512ABK27GA000025B002000UTX   0000020300Y
28814523A7K27GA00000ZB002000LAMR  0000381700Y
28814548A1K27GA00002BB002000APC   0000762900Y
28814564A9K27G60000H1S002000QQQQ  0000496000Y
28814564X9K27G60000GQ001000
28814564A9K27G60000H2S001000QQQQ  0000496400Y
28814566A7K27GA000010B002000LLTC  0000353400Y
28814608A7K27GA000011B002000LNCR  0000236100Y
28814609A1K27GA00002CB002000ABT   0000013200Y
28814624A1K27GA00002DB002000ARO   0000291900Y
28814654A7K27GA000012B002000LPNT  0000171200Y
28814667XAK27GA0000GJ003000
28814675AAK27GA0000GQS003000SPY   0001425600Y
28814678A2K27G600000NB002000AVP   0000358800Y
28814678XAK27GA0000GL003000
28814678AAK27GA0000GRS003000SPY   0001425600Y
28814691XAK27GA0000GR003000
28814691XAK27GA0000GQ003000
28814692X1K27GA000024002000
28814695AAK27GA0000GSS003000SPY   0001426200Y
28814695AAK27GA0000GTS003000SPY   0001426200Y
28814711A7K27GA000013B002000LRCX  0000392200Y
28814740A2K27G600000OB002000AXP   0000394300Y
28814782A2K27G600000PB002000AVP   0000358000Y
28814789A2K27G600000QB002000AZN   0000416400Y
28814814A2K27G600000RB002000BA    0000851800Y
28814827A2K27G600000SB002000AXP   0000393500Y
28814872A2K27G600000TB002000AZN   0000415600Y
28814887A2K27G600000UB002000BA    0000851000Y
28814965A5K27GA00001AB000100FXP   0000654000Y
28815011X4K27GA00004F000047
28815032A4K27GA00004TS000047DIA   0001298800Y
28815095X9K27G60000H0005000
28815095X9K27G60000F7003200
28815095A9K27G60000F7B003200QQQQ  0000495200Y
28815096A9K27G60000H3S005000QQQQ  0000495800Y
28815096X9K27G60000GY002000
28815098A9K27G60000H4B001000QID   0000380800Y
28815194X6K27GA000029000500
28815194A6K27GA000029B000500IWM   0000736000Y
28815198X6K27GA000029000500
28815198A6K27GA000029B000500IWM   0000736400Y
28815200XBK27GA000020000100
28815200XBK27GA00001Z000100
28815200X6K27GA000029000500
28815200A6K27GA000029B000500IWM   0000736000Y
28815202ABK27GA000026B000100UWM   0000542300Y
28815202ABK27GA000027S000100TWM   0000702200Y
28815202X6K27GA000029000500
28815202A6K27GA000029B000500IWM   0000736400Y
28815204XBK27GA000026000100
28815204XBK27GA000027000100
28815205ABK27GA000028B000100UWM   0000542300Y
28815206ABK27GA000029S000100TWM   0000702200Y
28815206X6K27GA000029000500
28815206A6K27GA000029B000500IWM   0000736000Y
28815210XBK27GA000028000100
28815210XBK27GA000029000100
28815212ABK27GA00002AB000100UWM   0000542300Y
28815212ABK27GA00002BS000100TWM   0000702200Y
28815218X6K27GA000029000500
28815218A6K27GA000029B000500IWM   0000736400Y
28815221XBK27GA00002A000100
28815221XBK27GA00002B000100
28815222ABK27GA00002CB000100UWM   0000542300Y
28815222ABK27GA00002DS000100TWM   0000702200Y
28815228X6K27GA000029000500
28815228A6K27GA000029B000500IWM   0000736000Y
28815240XBK27GA00002C000100
28815240XBK27GA00002D000100
28815240X6K27GA000029000500
28815240A6K27GA000029B000500IWM   0000736400Y
28815242ABK27GA00002ES000100TWM   0000702400Y
28815243ABK27GA00002FB000100UWM   0000542300Y
28815243XBK27GA00002E000100
28815243ABK27GA00002GS000100TWM   0000702200Y
28815242X6K27GA000029000500
28815242A6K27GA000029B000500IWM   0000736000Y
28815246X6K27GA000029000500
28815246A6K27GA000029B000500IWM   0000736400Y
28815248XBK27GA00002F000100
28815248XBK27GA00002G000100
28815248X6K27GA000029000500
28815248A6K27GA000029B000500IWM   0000736000Y
28815250ABK27GA00002HB000100UWM   0000542300Y
28815250ABK27GA00002IS000100TWM   0000702200Y
28815251XBK27GA00002I000100
28815251XBK27GA00002H000100
28815253ABK27GA00002JS000100TWM   0000702400Y
28815253X6K27GA000029000500
28815253A6K27GA000029B000500IWM   0000736400Y
28815256ABK27GA00002KB000100UWM   0000542300Y
28815256ABK27GA00002LS000100TWM   0000702200Y
28815256XBK27GA00002J000100
28815257X6K27GA000029000500
28815257A6K27GA000029B000500IWM   0000736000Y
28815266X6K27GA000029000500
28815266A6K27GA000029B000500IWM   0000736400Y
28815277X6K27GA000029000500
28815277A6K27GA000029B000500IWM   0000736000Y
28815279XBK27GA00002L000100
28815279XBK27GA00002K000100
28815281ABK27GA00002MB000100UWM   0000542300Y
28815281ABK27GA00002NS000100TWM   0000702200Y
28815280X6K27GA000029000500
28815280A6K27GA000029B000500IWM   0000736400Y
28815286X6K27GA000029000500
28815286A6K27GA000029B000500IWM   0000736000Y
28815287X6K27GA000029000500
28815287A6K27GA000029B000500IWM   0000736400Y
28815299XBK27GA00002M000100
28815299XBK27GA00002N000100
28815298X6K27GA000029000500
28815298A6K27GA000029B000500IWM   0000736000Y
28815301ABK27GA00002OB000100UWM   0000542300Y
28815301ABK27GA00002PS000100TWM   0000702200Y
28815301X6K27GA000029000500
28815301A6K27GA000029B000500IWM   0000736400Y
28815306X6K27GA000029000500
28815306A6K27GA000029B000500IWM   0000736000Y
28815317X6K27GA000029000500
28815317A6K27GA000029B000500IWM   0000736400Y
28815319XBK27GA00002O000100
28815319XBK27GA00002P000100
28815319A6K27GA000030B000100IWM   0000735900Y
28815319X6K27GA000030000100
28815321ABK27GA00002QS000100TWM   0000702400Y
28815320X6K27GA000029000500
28815320A6K27GA000029B000500IWM   0000736000Y
28815326X6K27GA000029000500
28815326A6K27GA000029B000500IWM   0000736400Y
28815327X6K27GA000029000500
28815327A6K27GA000029B000500IWM   0000736000Y
28815329ABK27GA00002RB000100UWM   0000542300Y
28815329ABK27GA00002SS000100TWM   0000702200Y
28815329XBK27GA00002Q000100
28815329XBK27GA00002R000100
28815329XBK27GA00002S000100
28815331ABK27GA00002TS000100TWM   0000702400Y
28815330X6K27GA000029000500
28815330A6K27GA000029B000500IWM   0000736400Y
28815336X6K27GA000029000500
28815336A6K27GA000029B000500IWM   0000736000Y
28815337X6K27GA000029000500
28815337A6K27GA000029B000500IWM   0000736400Y
28815349ABK27GA00002UB000100UWM   0000542300Y
28815349ABK27GA00002VS000100TWM   0000702200Y
28815349XBK27GA00002T000100
28815348X6K27GA000029000500
28815348A6K27GA000029B000500IWM   0000736000Y
28815351X6K27GA000029000500
28815351A6K27GA000029B000500IWM   0000736400Y
28815356X6K27GA000029000500
28815356A6K27GA000029B000500IWM   0000736000Y
28815358X6K27GA000029000500
28815358A6K27GA000029B000500IWM   0000736400Y
28815361A5K27GA00001BB000100GOOG  0005760100Y
28815364X6K27GA00002V002000
28815369XBK27GA00002U000100
28815369XBK27GA00002V000100
28815368X6K27GA000029000500
28815368A6K27GA000029B000500IWM   0000736000Y
28815371ABK27GA00002WS000100TWM   0000702400Y
28815378X6K27GA000029000500
28815378A6K27GA000029B000500IWM   0000736400Y
28815388X6K27GA000029000500
28815388A6K27GA000029B000500IWM   0000736000Y
28815398X6K27GA000029000500
28815398A6K27GA000029B000500IWM   0000736400Y
28815399XAK27GA0000GP002000
28815401A7K27GA000014B002000LMT   0000039100Y
28815408X6K27GA000029000500
28815408A6K27GA000029B000500IWM   0000736000Y
28815420XBK27GA000025002000
28815428X6K27GA000029000500
28815428A6K27GA000029B000500IWM   0000736400Y
28815430A7K27GA000015B002000LMT   0000038300Y
28815451A7K27GA000016B002000MNST  0000247700Y
28815463X1K27GA00002C002000
28815466XBK27GA000024002000
28815492ACK27GA00001HB002000WYE   0000010400Y
28815497A8K27G600000NB002000NPSP  0000030200Y
28815521X1K27GA00002A002000
28815549ABK27GA00002XB000100UWM   0000542300Y
28815549XBK27GA00002W000100
28815549ABK27GA00002YS000100TWM   0000702200Y
28815549A1K27GA00002EB002000AFL   0000020800Y
28815592A2K27G600000VB002000BAX   0000587800Y
28815617A2K27G600000WB002000BBY   0000423100Y
28815632A2K27G600000XB002000BDX   0000753400Y
28815652A5K27GA00001CB000100FXP   0000656300Y
28815652X5K27GA00000R000100
28815654A2K27G600000YB002000BHI   0000843500Y
28815656A5K27GA00001DS000100FXP   0000658300Y
28815662XAK27GA0000GF001000
28815665A5K27GA00001ES000100FXP   0000657600Y
28815665X5K27GA00001D000100
28815665X5K27GA00001E000100
28815677A8K27G600000OB002000NTAP  0000245400Y
28815718A2K27G600000ZB002000BJS   0000301100Y
28815729A1K27GA00002FB002000AFL   0000020000Y
28815739A8K27G600000PB002000NTRS  0000653200Y
28815777A2K27G6000010B002000BAX   0000587000Y
28815782A8K27G600000QB002000NVTL  0000076500Y
28815788X6K27GA000029000500
28815791XBK27GA00002X000100
28815791XBK27GA00002Y000100
28815790A6K27GA000031B000500IWM   0000736400Y
28815793ABK27GA00002ZS000100TWM   0000702400Y
28815792X6K27GA000031000500
28815792A6K27GA000031B000500IWM   0000736000Y
28815794ABK27GA000030B000100UWM   0000542300Y
28815794XBK27GA00002Z000100
28815794ABK27GA000031S000100TWM   0000702200Y
28815796XBK27GA000030000100
28815796XBK27GA000031000100
28815796X6K27GA000031000500
28815796A6K27GA000031B000500IWM   0000736400Y
28815797ABK27GA000032S000100TWM   0000702400Y
28815799ABK27GA000033B000100UWM   0000542300Y
28815799XBK27GA000032000100
28815799ABK27GA000034S000100TWM   0000702200Y
28815798X6K27GA000031000500
28815798A6K27GA000031B000500IWM   0000736000Y
28815801XBK27GA000033000100
28815801XBK27GA000034000100
28815803ABK27GA000035S000100TWM   0000702400Y
28815806X6K27GA000031000500
28815806A6K27GA000031B000500IWM   0000736400Y
28815809ABK27GA000036B000100UWM   0000542300Y
28815809XBK27GA000035000100
28815809ABK27GA000037S000100TWM   0000702200Y
28815808X6K27GA000031000500
28815808A6K27GA000031B000500IWM   0000736000Y
28815811XBK27GA000036000100
28815811XBK27GA000037000100
28815810X6K27GA000031000500
28815810A6K27GA000031B000500IWM   0000736400Y
28815813ABK27GA000038S000100TWM   0000702400Y
28815813ABK27GA000039B000100UWM   0000542300Y
28815813XBK27GA000038000100
28815812X6K27GA000031000500
28815812A6K27GA000031B000500IWM   0000736000Y
28815814ABK27GA00003AS000100TWM   0000702200Y
28815816A2K27G6000011B002000BBY   0000422300Y
28815815XBK27GA000039000100
28815815XBK27GA00003A000100
28815816A6K27GA000032B000100IWM   0000735900Y
28815817ABK27GA00003BS000100TWM   0000702400Y
28815816X6K27GA000031000500
28815816A6K27GA000031B000500IWM   0000736400Y
28815816X6K27GA000032000100
28815818X6K27GA000031000500
28815818A6K27GA000031B000500IWM   0000736000Y
28815821ABK27GA00003CS000100TWM   0000702200Y
28815821ABK27GA00003DB000100UWM   0000542300Y
28815821XBK27GA00003B000100
28815821XBK27GA00003D000100
28815821XBK27GA00003C000100
28815820X6K27GA000031000500
28815820A6K27GA000031B000500IWM   0000736400Y
28815823ABK27GA00003ES000100TWM   0000702400Y
28815823ABK27GA00003FS000100TWM   0000702200Y
28815823XBK27GA00003E000100
28815822X6K27GA000031000500
28815822A6K27GA000031B000500IWM   0000736000Y
28815823ABK27GA00003GB000100UWM   0000542300Y
28815825XBK27GA00003G000100
28815825XBK27GA00003F000100
28815824X6K27GA000031000500
28815824A6K27GA000031B000500IWM   0000736400Y
28815827ABK27GA00003HS000100TWM   0000702400Y
28815827X6K27GA000031000500
28815827A6K27GA000031B000500IWM   0000736000Y
28815829X6K27GA000031000500
28815829A6K27GA000031B000500IWM   0000736400Y
28815831X6K27GA000031000500
28815831A6K27GA000031B000500IWM   0000736000Y
28815833X6K27GA000031000500
28815833A6K27GA000031B000500IWM   0000736400Y
28815835X6K27GA000031000500
28815835A6K27GA000031B000500IWM   0000736000Y
28815839A2K27G6000012B002000BDX   0000752600Y
28815837X6K27GA000031000500
28815837A6K27GA000031B000500IWM   0000736400Y
28815840X6K27GA000031000500
28815840A6K27GA000031B000500IWM   0000736000Y
28815843X6K27GA000031000500
28815843A6K27GA000031B000500IWM   0000736400Y
28815845X6K27GA000031000500
28815845A6K27GA000031B000500IWM   0000736000Y
28815847X6K27GA000031000500
28815847A6K27GA000031B000500IWM   0000736400Y
28815849XAK27GA0000FK002000
28815849X6K27GA000031000500
28815849A6K27GA000031B000500IWM   0000736000Y
28815851X6K27GA000031000500
28815851A6K27GA000031B000500IWM   0000736400Y
28815858A2K27G6000013B002000BHI   0000842700Y
28815858X6K27GA000031000500
28815858A6K27GA000031B000500IWM   0000736000Y
28815868X6K27GA000031000500
28815868A6K27GA000031B000500IWM   0000736400Y
28815878X6K27GA000031000500
28815878A6K27GA000031B000500IWM   0000736000Y
28815888X6K27GA000031000500
28815888A6K27GA000031B000500IWM   0000736400Y
28815898X6K27GA000031000500
28815898A6K27GA000031B000500IWM   0000736000Y
28815908X6K27GA000031000500
28815908A6K27GA000031B000500IWM   0000736400Y
28815918X6K27GA000031000500
28815918A6K27GA000031B000500IWM   0000736000Y
28815928X6K27GA000031000500
28815928A6K27GA000031B000500IWM   0000736400Y
28815938X6K27GA000031000500
28815938A6K27GA000031B000500IWM   0000736000Y
28815948X6K27GA000031000500
28815948A6K27GA000031B000500IWM   0000736400Y
28815958X6K27GA000031000500
28815958A6K27GA000031B000500IWM   0000736000Y
28815968X6K27GA000031000500
28815968A6K27GA000031B000500IWM   0000736400Y
28815970X6K27GA000031000500
28815970A6K27GA000031B000500IWM   0000736000Y
28815978X6K27GA000031000500
28815978A6K27GA000031B000500IWM   0000736400Y
28815980X6K27GA000031000500
28815980A6K27GA000031B000500IWM   0000736000Y
28815982X6K27GA000031000500
28815982A6K27GA000031B000500IWM   0000736400Y
28815987X6K27GA000031000500
28815987A6K27GA000031B000500IWM   0000736000Y
28815989X6K27GA000031000500
28815989A6K27GA000031B000500IWM   0000736400Y
28815997X6K27GA000031000500
28815997A6K27GA000031B000500IWM   0000736000Y
28815999X6K27GA000031000500
28815999A6K27GA000031B000500IWM   0000736400Y
28816007X6K27GA000031000500
