28800011AAK27GA0000DTS000100SH    0000619200Y
28800012ABK27GA00000KB001000SSO   0000763800Y
28800012ABK27GA00000LB001000SSO   0000763600Y
28800012ABK27GA00000MS001000SSO   0000764800Y
28800012AAK27GA0000DUS001000SDS   0000549300Y
28800012AAK27GA0000DVB001000SDS   0000548000Y
28800012AAK27GA0000DWB000100SPY   0001424100Y
28800012AAK27GA0000DXS000100SPY   0001426300Y
28800012AAK27GA0000DYB000100SH    0000618500Y
28800015AAK27GA0000DZB001000SDS   0000547800Y
28800075ABK27GA00000NS000100UWM   0000542900Y
28800075ABK27GA00000OB000100TWM   0000701400Y
28800075ABK27GA00000PB000100TWM   0000701600Y
28800075ABK27GA00000QB000100UWM   0000542000Y
28800075ABK27GA00000RS000100TWM   0000702600Y
28800075ABK27GA00000SB000100TWM   0000701500Y
28800136A4K27GA00002RS000100DOG   0000598500Y
28800137A3K27G6000006S000100DDM   0000802100Y
28800136A4K27GA00002SS000100DXD   0000501300Y
28800136A4K27GA00002TS000100DXD   0000501100Y
28800136A4K27GA00002US000100DXD   0000501200Y
28800136A4K27GA00002VB000100DXD   0000500400Y
28800136A4K27GA00002WB000100DOG   0000597200Y
28800137A3K27G6000007B000100DDM   0000800700Y
28800161A4K27GA00002XB000100DIG   0001235800Y
28800161A4K27GA00002YS000100DIG   0001244400Y
28800160A6K27GA00001IB000100IYE   0001530500Y
28800160A6K27GA00001JS000100IYE   0001539100Y
28800162A1K27GA00000VB000100AAPL  0001828600Y
28800162A1K27GA00000WS000100AAPL  0001834800Y
28800162A1K27GA00000XB000100AAPL  0001828600Y
28800162A1K27GA00000YS000100AAPL  0001834800Y
28800164A9K27G60000CZS001000QID   0000382200Y
28800164A9K27G60000D0S001000QLD   0000889800Y
28800164A9K27G60000D1B001000QLD   0000888500Y
28800164A9K27G60000D2B001000QLD   0000888400Y
28800164A9K27G60000D3B001000QQQQ  0000495100Y
28800164A9K27G60000D4B001000QID   0000380900Y
28800165A9K27G60000D5B000500QQQQ  0000495000Y
28800165A9K27G60000D6B000500QQQQ  0000494900Y
28800165A9K27G60000D7B000500QQQQ  0000494400Y
28800166A9K27G60000D8B000500QQQQ  0000493800Y
28800166A9K27G60000D9B000500QQQQ  0000494300Y
28800166A9K27G60000DAB000500QQQQ  0000495100Y
28800166A9K27G60000DBB000500QQQQ  0000493700Y
28800166A9K27G60000DCS000500QQQQ  0000496700Y
28800166A9K27G60000DDS000500QQQQ  0000497300Y
28800166A9K27G60000DEB000500QQQQ  0000494800Y
28800166A9K27G60000DFB000500QQQQ  0000494700Y
28800166A9K27G60000DGB000500QQQQ  0000494100Y
28800166A9K27G60000DHS000500QQQQ  0000496800Y
28800166A9K27G60000DIS000500QQQQ  0000497400Y
28800166A9K27G60000DJB000500QQQQ  0000494500Y
28800166A9K27G60000DKB000500QQQQ  0000493900Y
28800166A9K27G60000DLS000500QQQQ  0000496600Y
28800166A9K27G60000DMS000500QQQQ  0000497200Y
28800166A9K27G60000DNB000500QQQQ  0000494600Y
28800166A9K27G60000DOB000500QQQQ  0000494000Y
28800166A9K27G60000DPS000500QQQQ  0000496400Y
28800166A9K27G60000DQS000500QQQQ  0000497000Y
28800166A9K27G60000DRS000500QQQQ  0000497600Y
28800166A9K27G60000DSB000500QQQQ  0000494200Y
28800166A9K27G60000DTS000500QQQQ  0000496300Y
28800166A9K27G60000DUS000500QQQQ  0000496900Y
28800166A9K27G60000DVS000500QQQQ  0000496500Y
28800166A9K27G60000DWS000500QQQQ  0000497100Y
28800166A9K27G60000DXS000500QQQQ  0000497700Y
28800166A9K27G60000DYS000500QQQQ  0000497500Y
28800167A4K27GA00002ZB000100DRYS  0001052600Y
28800168X1K27GA00000Y000100
28800168A1K27GA00000YS000100AAPL  0001831900Y
28800168X1K27GA00000V000100
28800168A1K27GA00000VB000100AAPL  0001826100Y
28800168X1K27GA00000W000100
28800168A1K27GA00000WS000100AAPL  0001831900Y
28800172A9K27G60000DZB001000QQQQ  0000495200Y
28800172A9K27G60000E0B001000QQQQ  0000495300Y
28800172A9K27G60000E1B000500QQQQ  0000495200Y
28800172A9K27G60000E2B000500QQQQ  0000495300Y
28800173A5K27GA00000JS000100FXP   0000658400Y
28800174A5K27GA00000KB000100FXP   0000654400Y
28800174X5K27GA00000K000100
28800176A5K27GA00000LB000100FXP   0000654200Y
28800179X5K27GA00000J000100
28800179A5K27GA00000MB000100FXP   0000656600Y
28800180X1K27GA00000V000100
28800180A1K27GA00000VB000100AAPL  0001828600Y
28800180X1K27GA00000Y000100
28800180A1K27GA00000YS000100AAPL  0001834800Y
28800180X1K27GA00000X000100
28800180A1K27GA00000XB000100AAPL  0001830100Y
28800180XAK27GA0000DW000100
28800181X4K27GA00002X000100
28800179X6K27GA00001I000100
28800181X1K27GA00000Y000100
28800181A1K27GA00000YS000100AAPL  0001833400Y
28800182A9K27G60000E3B001000QQQQ  0000495500Y
28800182X1K27GA00000Y000100
28800182A1K27GA00000YS000100AAPL  0001831900Y
28800183A4K27GA000030B000100DIG   0001235600Y
28800183AAK27GA0000E0B000100SPY   0001423700Y
28800182A6K27GA00001KB000100IYE   0001530300Y
28800185A4K27GA000031B000100DIG   0001237700Y
28800185X4K27GA000030000100
28800184A6K27GA00001LB000100IYE   0001531500Y
28800190ABK27GA00000TS000100UYG   0000322900Y
28800190A4K27GA000032S000100DRYS  0001071400Y
28800189A6K27GA00001MS000100IYF   0000860000Y
28800189A6K27GA00001NS000100IYF   0000859900Y
28800191A6K27GA00001OB000100IYF   0000853100Y
28800196A6K27GA00001PS000100IYM   0000877000Y
28800196A6K27GA00001QB000100IYM   0000869800Y
28800212A4K27GA000033S000100EEV   0000611400Y
28800212A4K27GA000034S000100EEM   0001541800Y
28800272A6K27GA00001RS000100IYR   0000713000Y
28800274ABK27GA00000UB000100URE   0000371000Y
28800274ABK27GA00000VS000100URE   0000385600Y
28800272A6K27GA00001SB000100IYR   0000699000Y
28800277A9K27G60000E4B001000QLD   0000888600Y
28800277X9K27G60000D0001000
28800277X9K27G60000D2001000
28800277X9K27G60000E3001000
28800279X9K27G60000E2000500
28800279X9K27G60000E1000500
28800279X9K27G60000E0001000
28800279X9K27G60000DZ001000
28800279A9K27G60000E5S001000QLD   0000890300Y
28800279A9K27G60000E6B001000QQQQ  0000495200Y
28800279A9K27G60000E7S001000QQQQ  0000496100Y
28800279A9K27G60000E8S001000QQQQ  0000496000Y
28800279X9K27G60000E8001000
28800279X9K27G60000E7001000
28800279A9K27G60000E9B001000QQQQ  0000495300Y
28800281A9K27G60000EAS000100QID   0000382400Y
28800282X9K27G60000E6001000
28800282X9K27G60000D3001000
28800283A9K27G60000EBS001000QLD   0000890400Y
28800283X9K27G60000DA000500
28800283A8K27G6000001S000500MZZ   0000494100Y
28800284A8K27G6000002B000500MZZ   0000491700Y
28800284A8K27G6000003S000100MVV   0000809000Y
28800284A8K27G6000004B000100MVV   0000805900Y
28800283X4K27GA00002V000100
28800283A4K27GA000035B000100DXD   0000499600Y
28800283A4K27GA000036B000100DXD   0000499500Y
28800285X3K27G6000006000100
28800285A9K27G60000ECB000500QQQQ  0000493600Y
28800285A4K27GA000037B000100DXD   0000499700Y
28800287A3K27G6000008S000100DDM   0000802200Y
28800297X1K27GA00000Y000100
28800297A1K27GA00000YS000100AAPL  0001833400Y
28800301ABK27GA00000WB000100URE   0000372200Y
28800300X6K27GA00001S000100
28800300A6K27GA00001TB000100IYR   0000700500Y
28800311X6K27GA00001T000100
28800311A6K27GA00001UB000100IYR   0000707000Y
28800312ABK27GA00000XB000100URE   0000379200Y
28800318E1K27GA00000X00010000001AQ00001
28800319X1K27GA00000Y000100
28800319A1K27GA00000YS000100AAPL  0001831900Y
28800324X4K27GA00002Z000100
28800326A4K27GA000038B015000ENCY  0000023300Y
28800327A4K27GA000039S010930ENCY  0000023500Y
28800330A8K27G6000005B000500MZZ   0000491800Y
28800330A3K27G6000009B000100DELL  0000010000Y
28800340A4K27GA00003AB000100DRYS  0001060800Y
28800377A6K27GA00001VB000100IYF   0000854200Y
28800378A6K27GA00001WB000100IYF   0000854100Y
28800395X5K27GA00000M000100
28800397A5K27GA00000NB000100FXP   0000656100Y
28800455X9K27G60000D1001000
28800457A9K27G60000EDB001000QQQQ  0000495200Y
28800461X9K27G60000ED001000
28800499X9K27G60000E4001000
28800501A9K27G60000EEB001000QLD   0000888400Y
28800501A9K27G60000EFB001000QQQQ  0000495200Y
28800511X9K27G60000EF001000
28800520A9K27G60000EGS000100QLD   0000889700Y
28800520A9K27G60000EHS001000QQQQ  0000495800Y
28800520A9K27G60000EIS000500QQQQ  0000496000Y
28800520A9K27G60000EJS000500QQQQ  0000495900Y
28800520A9K27G60000EKS000500QQQQ  0000495800Y
28800531X9K27G60000EI000500
28800531A9K27G60000ELS001000QQQQ  0000496000Y
28800531X9K27G60000EH001000
28800533A9K27G60000EMS001000QQQQ  0000495900Y
28800561AAK27GA0000E1S000100SKF   0001033900Y
28800560A6K27GA00001XB000100IYF   0000855100Y
28800561A6K27GA00001YB000100IYF   0000854900Y
28800562A6K27GA00001ZB000100IYF   0000854800Y
28800562X6K27GA00001O000100
28800582X5K27GA00000N000100
28800583A5K27GA00000OB000100FXP   0000655800Y
28800728XAK27GA0000E1000100
28800727A6K27GA000020B000100IYF   0000855000Y
28800728AAK27GA0000E2S000100SKF   0001031700Y
28800728A6K27GA000021B000100IYF   0000855800Y
28800728X6K27GA00001W000100
28800729A6K27GA000022B000100IYF   0000855700Y
28800729X6K27GA00001V000100
28800758X5K27GA00000O000100
28800758A5K27GA00000PS000100FXP   0000657300Y
28801017A6K27GA000023S000100IYF   0000858900Y
28801018XAK27GA0000E0000100
28801019AAK27GA0000E3B000100SPY   0001423800Y
28801019ABK27GA00000YS000100UYG   0000322200Y
28801018A6K27GA000024S000100IYF   0000860000Y
28801036AAK27GA0000E4B001000SPY   0001425000Y
28801036AAK27GA0000E5S001000SPY   0001425200Y
28801098AAK27GA0000E6S001000SPY   0001425300Y
28801098AAK27GA0000E7B001000SPY   0001424900Y
28801105AAK27GA0000E8B001000SPY   0001424800Y
28801105AAK27GA0000E9S001000SPY   0001425400Y
28801117AAK27GA0000EAS001000SPY   0001425500Y
28801117AAK27GA0000EBB001000SPY   0001424700Y
28801337AAK27GA0000ECB001000SPY   0001425000Y
28801337AAK27GA0000EDS001000SPY   0001425200Y
28801435AAK27GA0000EES001000SPY   0001425300Y
28801435AAK27GA0000EFB001000SPY   0001424900Y
28801436AAK27GA0000EGS001000SPY   0001425400Y
28801536AAK27GA0000EHB001000SPY   0001424800Y
28801537AAK27GA0000EIS001000SPY   0001425500Y
28801560A9K27G60000ENS002000QQQQ  0000495700Y
28801560A9K27G60000EOB002000QQQQ  0000495500Y
28801574AAK27GA0000EJB001000SPY   0001424700Y
28801660A9K27G60000EPB002000QQQQ  0000495400Y
28801660A9K27G60000EQS002000QQQQ  0000495800Y
28801697A9K27G60000ERB005000QQQQ  0000495500Y
28801697A9K27G60000ESS005000QQQQ  0000495700Y
28801761A9K27G60000ETS002000QQQQ  0000495900Y
28801761A9K27G60000EUB002000QQQQ  0000495300Y
28801797A9K27G60000EVS005000QQQQ  0000495800Y
28801797A9K27G60000EWB005000QQQQ  0000495400Y
28801897A9K27G60000EXB005000QQQQ  0000495300Y
28801897A9K27G60000EYS005000QQQQ  0000495900Y
28801914A1K27GA000011B000100AAPL  0001828600Y
28801997A9K27G60000EZB005000QQQQ  0000495200Y
28801997A9K27G60000F0S005000QQQQ  0000496000Y
28802100X1K27GA000011000100
28802100A1K27GA000011B000100AAPL  0001830100Y
28802322A9K27G60000F1B003200QQQQ  0000495500Y
28802322A9K27G60000F2S003200QQQQ  0000495700Y
28802408A6K27GA000025B000500IWM   0000736200Y
28802408A6K27GA000026S000500IWM   0000736500Y
28802424A9K27G60000F3B003200QQQQ  0000495400Y
28802424A9K27G60000F4S003200QQQQ  0000495800Y
28802439A6K27GA000027B000500IWM   0000736100Y
28802439A6K27GA000028S000500IWM   0000736600Y
28802465A9K27G60000F5B003200QQQQ  0000495300Y
28802465A9K27G60000F6S003200QQQQ  0000495900Y
28802465X1K27GA000011000100
28802465A1K27GA000011B000100AAPL  0001828600Y
28802520X4K27GA00003A000100
28802522A9K27G60000F7B003200QQQQ  0000495200Y
28802522A9K27G60000F8S003200QQQQ  0000496000Y
28802537A4K27GA00003BB000100DRYS  0001065100Y
28802568X4K27GA00002T000100
28802568X4K27GA000037000100
28802568A4K27GA00003CS000100DXD   0000500400Y
28802570A4K27GA00003DB000100DXD   0000499400Y
28802575X4K27GA00002W000100
28802576A4K27GA00003EB000100DOG   0000597100Y
28802623A9K27G60000F9B003200QQQQ  0000495100Y
28802623A9K27G60000FAS003200QQQQ  0000496100Y
28802661XAK27GA0000E5001000
28802661AAK27GA0000E5S001000SPY   0001425600Y
28802666XAK27GA0000DV001000
28802667XBK27GA00000M001000
28802668AAK27GA0000EKB001000SDS   0000547900Y
28802669ABK27GA00000ZS001000SSO   0000764900Y
28802672A6K27GA000029B000500IWM   0000736000Y
28802672A6K27GA00002AS000500IWM   0000736700Y
28802676A6K27GA00002BS000500IWM   0000736800Y
28802676A6K27GA00002CB000500IWM   0000735900Y
28802682A9K27G60000FBB001000QLD   0000888600Y
28802682X9K27G60000EE001000
28802685A9K27G60000FCB001000QQQQ  0000495200Y
28802688X9K27G60000F2003200
28802688A9K27G60000F2S003200QQQQ  0000496200Y
28802688X9K27G60000EZ005000
28802690A9K27G60000FDB001000QLD   0000888500Y
28802694A9K27G60000FEB005000QQQQ  0000495600Y
28802694X9K27G60000FC001000
28802858AAK27GA0000ELB003000SPY   0001424900Y
28802858AAK27GA0000EMS003000SPY   0001425400Y
28802864AAK27GA0000ENB003000SPY   0001424700Y
28802864AAK27GA0000EOS003000SPY   0001425600Y
28802866AAK27GA0000EPB003000SPY   0001424500Y
28802866AAK27GA0000EQS003000SPY   0001425800Y
28802903XAK27GA0000ED001000
28802917XAK27GA0000EB001000
28802917AAK27GA0000EBB001000SPY   0001425100Y
28802917XAK27GA0000EJ001000
28802918AAK27GA0000ERS001000SPY   0001425600Y
28802918AAK27GA0000ESB000900SPY   0001425100Y
28802918AAK27GA0000ETB003000SPY   0001424900Y
28802918AAK27GA0000EUS003000SPY   0001425400Y
28802919AAK27GA0000EVS000100SH    0000619100Y
28802920XBK27GA00000K001000
28802920ABK27GA000010B001000SSO   0000763900Y
28802922XBK27GA00000L001000
28802922ABK27GA000011B001000SSO   0000763700Y
28802926AAK27GA0000EWS000500SPY   0001425300Y
28802926AAK27GA0000EXB000500SPY   0001425000Y
28802926AAK27GA0000EYS003000SPY   0001425600Y
28802926AAK27GA0000EZB003000SPY   0001424700Y
28802953AAK27GA0000F0S003000SPY   0001425800Y
28802953AAK27GA0000F1B003000SPY   0001424500Y
28802953AAK27GA0000F2B000500SPY   0001424900Y
28802953AAK27GA0000F3S000500SPY   0001425400Y
28802980AAK27GA0000F4S000500SPY   0001425500Y
28802980AAK27GA0000F5B000500SPY   0001424800Y
28802995AAK27GA0000F6S000500SPY   0001425600Y
28802995AAK27GA0000F7B000500SPY   0001424700Y
28803036XAK27GA0000DY000100
28803036XAK27GA0000EK001000
28803036XBK27GA00000Z001000
28803037AAK27GA0000F8B000100SH    0000618400Y
28803038AAK27GA0000F9B001000SDS   0000547800Y
28803038ABK27GA000012S001000SSO   0000765000Y
28803047XAK27GA0000DZ001000
28803219A4K27GA00003FS000100DXD   0000500500Y
28803219A4K27GA00003GS000200DIA   0001298500Y
28803219A4K27GA00003HB000200DIA   0001298300Y
28803221A4K27GA00003IS000100DXD   0000500600Y
28803221A4K27GA00003JB000100DOG   0000597200Y
28803221A3K27G600000AS000100DDM   0000802100Y
28803221A4K27GA00003KB000100DXD   0000499700Y
28803222A4K27GA00003LB000200DIA   0001298200Y
28803222A4K27GA00003MS000200DIA   0001298600Y
28803224X3K27G6000008000100
28803224X3K27G600000A000100
28803224E4K27GA00003G00007700004AQ00001
28803224E4K27GA00003G00007600004AQ00002
28803225X4K27GA00003J000100
28803226A3K27G600000BS000100DDM   0000802200Y
28803226X4K27GA00003K000100
28803228A4K27GA00003PB000100DXD   0000499700Y
28803234X4K27GA00003P000100
28803238X4K27GA00003G000047
28803238A4K27GA00003QB000200DIA   0001298100Y
28803240P4K27GA00003PB000100DXD   0000499600000N4AQ00003
28803247X4K27GA00003C000100
28803247X3K27G6000007000100
28803247X4K27GA00002R000100
28803248A4K27GA00003RS000100DXD   0000500700Y
28803249A3K27G600000CB000100DDM   0000800600Y
28803249A4K27GA00003SS000100DOG   0000598600Y
28803685XAK27GA0000F7000500
28803685AAK27GA0000F7B000500SPY   0001425100Y
28803869A9K27G60000FFS005000QQQQ  0000495700Y
28803869A9K27G60000FGB005000QQQQ  0000495500Y
28803968A9K27G60000FHB005000QQQQ  0000495400Y
28803968A9K27G60000FIS005000QQQQ  0000495800Y
28804068A9K27G60000FJB005000QQQQ  0000495300Y
28804068A9K27G60000FKS005000QQQQ  0000495900Y
28804168A9K27G60000FLB005000QQQQ  0000495200Y
28804168A9K27G60000FMS005000QQQQ  0000496000Y
28804485A4K27GA00003TS000100DOG   0000598500Y
28804485X4K27GA00002S000100
28804485A4K27GA00003US000100DXD   0000500400Y
28804485A3K27G600000DB000100DDM   0000800700Y
28804999XAK27GA0000EW000500
28804999AAK27GA0000EWS000500SPY   0001425700Y
28805083A9K27G60000FNS002000QQQQ  0000495700Y
28805083A9K27G60000FOB002000QQQQ  0000495500Y
28805183A9K27G60000FPS002000QQQQ  0000495800Y
28805614XAK27GA0000EW000500
28805614AAK27GA0000EWS000500SPY   0001425300Y
28805824A9K27G60000FQB002000QQQQ  0000495600Y
28805824X9K27G60000FL005000
28805825A9K27G60000FRB005000QQQQ  0000495600Y
28805826X9K27G60000EU002000
28805826A9K27G60000EUB002000QQQQ  0000495600Y
28805962A8K27G6000006B002000MSFT  0000282700Y
28806390A1K27GA000012B002000AMAT  0000182900Y
28806429A1K27GA000013B002000AMGN  0000413600Y
28806448A1K27GA000014B002000AMZN  0000796800Y
28806466A2K27G600000FB002000BRCM  0000259400Y
28806486A3K27G600000EB002000CELG  0000454800Y
28806510A3K27G600000FB002000CHKP  0000231700Y
28806531A3K27G600000GB002000CREE  0000237300Y
28806556A3K27G600000HB002000CYMI  0000285200Y
28806574A4K27GA00003VB002000DISH  0000320300Y
28806603A4K27GA00003WB002000DRIV  0000358300Y
28806794AAK27GA0000FAB000600SPY   0001419600Y
28806923AAK27GA0000FBS000100SKF   0001031400Y
28806923XAK27GA0000E2000100
28806922A6K27GA00002DB000100IYF   0000855300Y
28806922X6K27GA00001X000100
28806923X6K27GA00001Z000100
28806923A6K27GA00002EB000100IYF   0000855900Y
28806925AAK27GA0000FCS000500SPY   0001425400Y
28806925AAK27GA0000FDB000500SPY   0001425000Y
28806927AAK27GA0000FEB000500SPY   0001424900Y
28806927AAK27GA0000FFS000500SPY   0001425500Y
28806928AAK27GA0000FGB000500SPY   0001424800Y
28806928AAK27GA0000FHS000500SPY   0001425600Y
28806930AAK27GA0000FIB000500SPY   0001424700Y
28806930AAK27GA0000FJS000500SPY   0001425700Y
28806960X1K27GA000011000100
28806960A1K27GA000011B000100AAPL  0001830100Y
28807196E5K27GA00000L00002000005AQ00001
28807197X5K27GA00000P000100
28807197X5K27GA00000L000080
28807197A5K27GA00000RS000100FXP   0000657100Y
28807199A5K27GA00000SB000100FXP   0000654100Y
28807216E5K27GA00000S00010000005AQ00002
28807218A5K27GA00000UB000100FXP   0000652500Y
28807220X5K27GA00000U000100
28807222A5K27GA00000VB000100FXP   0000652500Y
28807224X5K27GA00000V000100
28807225A5K27GA00000WB000100FXP   0000651400Y
28807226A5K27GA00000XB000100FXP   0000652500Y
28807239E5K27GA00000X00010000005AQ00003
28807241X5K27GA00000W000100
28807242A5K27GA00000ZB000100FXP   0000652300Y
28807274A4K27GA00003XS000200DIA   0001298700Y
28807386A4K27GA00003YB002000EBAY  0000292900Y
28807423A4K27GA00003ZB002000ENZN  0000069500Y
28807440A5K27GA000010B002000GILD  0000515700Y
28807456A5K27GA000011B002000IACI  0000220300Y
28807472A6K27GA00002FB002000IMCL  0000285600Y
28807478A6K27GA00002GB002000INTC  0000237800Y
28807492A6K27GA00002HB002000INTU  0000256400Y
28807506A7K27GA00000KB002000MRVL  0000135200Y
28807520A8K27G6000007B002000NFLX  0000308000Y
28807528PCK27GA000016B000177ZVZZT 0020000000000I000HV1PJ
28807529PCK27GA000016B000100ZVZZT 0020000000000I000HV1PK
28807529PCK27GA000016B000100ZVZZT 0020000000000I000HV1PL
28807959AAK27GA0000FKB002000SAP   0000470900Y
28807982A1K27GA000015B002000A     0000345100Y
28808228X9K27G60000ES005000
28808228X9K27G60000FF005000
28808229X9K27G60000EN002000
28808229A9K27G60000ENS002000QQQQ  0000496000Y
28808230A9K27G60000FSS005000QQQQ  0000496100Y
28808230A9K27G60000FTS005000QQQQ  0000496100Y
28808393A1K27GA000016B002000AA    0000431500Y
28808420A9K27G60000FUB002000QCOM  0000457300Y
28808443A1K27GA000017B002000ADI   0000339700Y
28808446A4K27GA000040S000047DIA   0001298800Y
28808453A9K27G60000FVB002000QLGC  0000144200Y
28808485A1K27GA000018B002000ADP   0000419000Y
28808495AAK27GA0000FLB002000SHLD  0000604900Y
28808513A1K27GA000019B002000AIG   0000371800Y
28808528AAK27GA0000FMB002000SINA  0000507400Y
28808550AAK27GA0000FNB002000SMTC  0000162200Y
28808553A1K27GA00001AB002000APA   0001428400Y
28808590AAK27GA0000FOB002000SOHU  0000796000Y
28808605A2K27G600000GB002000BAC   0000347300Y
28808623ABK27GA000013B002000SYMC  0000195200Y
28808633A2K27G600000HB002000BRL   0000370400Y
28808654ABK27GA000014B002000TTWO  0000254000Y
28808666A2K27G600000IB002000C     0000218900Y
28808720A3K27G600000IB002000COF   0000495200Y
28808736A4K27GA000041B002000DNA   0000685300Y
28809385X6K27GA00002F002000
28809418XAK27GA0000FL002000
28809425A4K27GA000042B002000DVN   0001208500Y
28809462ACK27GA000017B002000VSEA  0000373100Y
28809489A4K27GA000043B002000EMR   0000551000Y
28809502ACK27GA000018B002000WFMI  0000275300Y
28809539A5K27GA000012B002000FNM   0000275800Y
28809539A1K27GA00001BB002000AA    0000432300Y
28809550ACK27GA000019B002000XLNX  0000254400Y
28809581A5K27GA000013B002000GG    0000384100Y
28809606A1K27GA00001CB002000ADI   0000340500Y
28809644A5K27GA000014B002000GM    0000171100Y
28809649ACK27GA00001AB002000YHOO  0000265100Y
28809671A1K27GA00001DB002000ADP   0000419800Y
28809707A1K27GA00001EB002000AAPL  0001816400Y
28809708A5K27GA000015B002000GS    0001816500Y
28809744A1K27GA00001FB002000AIG   0000372600Y
28809755A6K27GA00002IB002000IBM   0001246600Y
28809791A1K27GA00001GB002000ADSK  0000384200Y
28809807A1K27GA00001HB002000APA   0001429200Y
28809830A6K27GA00002JB002000JNJ   0000638000Y
28809840A1K27GA00001IB002000ADTN  0000228200Y
28809877A7K27GA00000LB002000KSS   0000453000Y
28809892A2K27G600000JB002000BAC   0000348200Y
28809901A1K27GA00001JB002000ALTR  0000211400Y
28809928A7K27GA00000MB002000LMT   0000020300Y
28809989A2K27G600000KB002000C     0000219700Y
28810016A3K27G600000JB002000COF   0000496000Y
28810038A4K27GA000044B002000DNA   0000686100Y
28810393X7K27GA00000M002000
28810459A7K27GA00000NB002000MDT   0000477800Y
28810459A4K27GA000045B002000DVN   0001209300Y
28810461A6K27GA00002KB002000IMCL  0000288900Y
28810470A7K27GA00000OB002000MMM   0000762000Y
28810482AAK27GA0000FPS001000SPY   0001425400Y
28810482AAK27GA0000FQB001000SPY   0001424900Y
28810482AAK27GA0000FRB002000SHLD  0000610000Y
28810494A4K27GA000046B002000EMR   0000551800Y
28810536A7K27GA00000PB002000MO    0000211600Y
28810538A1K27GA00001KB002000APOL  0000403200Y
28810579A1K27GA00001LB002000APPX  0000092400Y
28810581A8K27G6000008B002000NBR   0000402800Y
28810581A5K27GA000016B002000FNM   0000276600Y
28810624A2K27G600000LB002000BBBY  0000307500Y
28810642A5K27GA000017B002000GG    0000384900Y
28810656A2K27G600000MB002000CAKE  0000193900Y
28810683A5K27GA000018B002000GM    0000172000Y
28810685A3K27G600000KB002000CECO  0000107600Y
28810728A3K27G600000LB002000CEPH  0000645200Y
28810728A8K27G6000009B002000NEM   0000472800Y
28810728A5K27GA000019B002000GS    0001817300Y
28810742A9K27G60000FWB004000QQQQ  0000495400Y
28810742A9K27G60000FXB004000QQQQ  0000495300Y
28810742A9K27G60000FYS002000QQQQ  0000495800Y
28810743A9K27G60000FZS004000QQQQ  0000495900Y
28810744A9K27G60000G0B002000QQQQ  0000495600Y
28810744A9K27G60000G1S002000QQQQ  0000495800Y
28810746A9K27G60000G2B002000QQQQ  0000495500Y
28810746A9K27G60000G3S002000QQQQ  0000495900Y
28810747A9K27G60000G4B002000QQQQ  0000495400Y
28810747A9K27G60000G5S002000QQQQ  0000496000Y
28810749A9K27G60000G6B002000QQQQ  0000495300Y
28810749A9K27G60000G7S002000QQQQ  0000496100Y
28810751A9K27G60000G8B002000QQQQ  0000495200Y
28810751A9K27G60000G9S002000QQQQ  0000496200Y
28810783ABK27GA000015B002000TGT   0000515800Y
28810792A6K27GA00002LB002000IBM   0001247400Y
28810841ABK27GA000016B002000TXN   0000308200Y
28810877A6K27GA00002MB002000JNJ   0000638900Y
28810890ABK27GA000017B002000TYC   0000439100Y
28810906A7K27GA00000QB002000KSS   0000453800Y
28810928ABK27GA000018B002000UTX   0000012300Y
28810958ACK27GA00001BB002000VZ    0000373300Y
28811393XAK27GA0000FR002000
28811489A3K27G600000MB002000CCMP  0000354200Y
28811488A7K27GA00000RB002000LMT   0000027100Y
28811528A3K27G600000NB002000CMCSA 0000192100Y
28811547X9K27G60000F9003200
28811547A9K27G60000F9B003200QQQQ  0000495600Y
28811549XBK27GA000018002000
28811550X9K27G60000FN002000
28811554A9K27G60000GAS002000QQQQ  0000495900Y
28811554X9K27G60000EB001000
28811556A9K27G60000GBS001000QQQQ  0000495900Y
28811556X9K27G60000EL001000
28811557A7K27GA00000SB002000MDT   0000478600Y
28811560X9K27G60000GB001000
28811562A9K27G60000GCS001000QQQQ  0000496000Y
28811582A3K27G600000OB002000COST  0000693000Y
28811594A7K27GA00000TB002000LMT   0000026300Y
28811616A3K27G600000PB002000CSCO  0000251300Y
28811629ACK27GA00001CB002000WLP   0000500100Y
28811644A3K27G600000QB002000CTAS  0000281600Y
28811659A7K27GA00000UB002000MMM   0000762800Y
28811659ACK27GA00001DB002000WMT   0000534300Y
28811685A3K27G600000RB002000CYBX  0000139900Y
28811707A1K27GA00001MB002000ABX   0000393000Y
28811707A7K27GA00000VB002000MO    0000212400Y
28811763XAK27GA0000FP001000
28811765AAK27GA0000FSS001000SPY   0001425500Y
28811772A8K27G600000AB002000NBR   0000403600Y
28811775A1K27GA00001NB002000ACE   0000586400Y
28811800A8K27G600000BB002000NEM   0000473600Y
28811806A1K27GA00001OB002000ACF   0000117400Y
28811826ABK27GA000019B002000TGT   0000516700Y
28811832A1K27GA00001PB002000ACN   0000356600Y
28811860ABK27GA00001AB002000TXN   0000309000Y
28811863A1K27GA00001QB002000AFL   0000012600Y
28811890ABK27GA00001BB002000TYC   0000439900Y
28812226A6K27GA00002NB002000IWM   0000736100Y
28812226A6K27GA00002OB002000IWM   0000736000Y
28812227A6K27GA00002PS002000IWM   0000736600Y
28812228X9K27G60000FW002000
28812227A6K27GA00002QS002000IWM   0000736700Y
28812244A9K27G60000GDB002000QQQQ  0000495400Y
28812276X9K27G60000GD002000
28812376X3K27G600000E002000
28812389X7K27GA00000R002000
28812416ABK27GA00001CB002000UTX   0000017100Y
28812425AAK27GA0000FTS001000SPY   0001425400Y
28812469X6K27GA00002K002000
28812493AAK27GA0000FUB002000SHLD  0000615100Y
28812497ACK27GA00001EB002000VZ    0000374100Y
28812535X9K27G60000GC001000
28812535A9K27G60000GES001000QQQQ  0000495900Y
28812542A3K27G600000SB002000DELL  0000192700Y
28812557ACK27GA00001FB002000WLP   0000500900Y
28812568X9K27G60000F9003200
28812568A9K27G60000F9B003200QQQQ  0000495100Y
28812595A4K27GA000047B002000ESRX  0000648000Y
28812610ACK27GA00001GB002000WMT   0000535200Y
28812632AAK27GA0000FVB001000SDS   0000547800Y
28812639A1K27GA00001RB002000A     0000345900Y
28812682X7K27GA00000T002000
28812701A1K27GA00001SB002000ABT   0000011000Y
28812720A4K27GA000048B002000EXPD  0000442600Y
28812736ABK27GA00001DB002000UTX   0000016300Y
28812754A1K27GA00001TB002000ABX   0000393800Y
28812767A1K27GA00001UB002000ABT   0000010100Y
28812792A4K27GA000049B002000FFIV  0000262500Y
28812795X1K27GA00001Q002000
28812824A1K27GA00001VB002000ACE   0000587200Y
28812835A4K27GA00004AB002000FISV  0000500200Y
28812848A1K27GA00001WB002000ALL   0000483400Y
28812922A1K27GA00001XB002000ANF   0000719100Y
28813063XAK27GA0000EP003000
28813063XAK27GA0000EM003000
28813063AAK27GA0000FWB002000SPY   0001425100Y
28813063XAK27GA0000E6001000
28813063AAK27GA0000E6S001000SPY   0001425700Y
28813063XAK27GA0000FC000500
28813063AAK27GA0000FCS000500SPY   0001425800Y
28813063XAK27GA0000E8001000
28813063AAK27GA0000E8B001000SPY   0001425200Y
28813063XAK27GA0000FI000500
28813063AAK27GA0000FIB000500SPY   0001425200Y
28813063AAK27GA0000FXB003000SPY   0001425200Y
28813064X9K27G60000G8002000
28813064A9K27G60000G8B002000QQQQ  0000495600Y
28813063X4K27GA00003M000200
28813063X4K27GA00003Q000200
28813063A4K27GA00003QB000200DIA   0001298500Y
28813063X4K27GA00003L000200
28813063A4K27GA00003LB000200DIA   0001298400Y
28813063X4K27GA00003X000200
28813063XAK27GA0000EH001000
28813063XAK27GA0000F5000500
28813063AAK27GA0000F5B000500SPY   0001425200Y
28813063XAK27GA0000F1003000
28813063XAK27GA0000EW000500
28813063AAK27GA0000EWS000500SPY   0001425700Y
28813064XAK27GA0000F4000500
28813064AAK27GA0000F4S000500SPY   0001425800Y
28813064XAK27GA0000F3000500
28813064XAK27GA0000EU003000
28813064XAK27GA0000FT001000
28813064AAK27GA0000FYB000900SPY   0001424700Y
28813064XAK27GA0000EG001000
28813064XAK27GA0000EE001000
28813064XAK27GA0000FG000500
28813064AAK27GA0000FGB000500SPY   0001425100Y
28813064XAK27GA0000E9001000
28813064AAK27GA0000E9S001000SPY   0001425800Y
28813064XAK27GA0000FF000500
28813064AAK27GA0000FFS000500SPY   0001425900Y
28813064AAK27GA0000FZB003000SPY   0001425200Y
28813064AAK27GA0000G0B002000SPY   0001425100Y
28813065X9K27G60000D4001000
28813064AAK27GA0000G1S003000SPY   0001426000Y
28813065X9K27G60000E5001000
28813064AAK27GA0000G2B002000SPY   0001425200Y
28813065AAK27GA0000G3S001000SDS   0000549200Y
28813065ABK27GA00001EB001000SSO   0000764000Y
28813065XBK27GA000010001000
28813065A4K27GA00004BS000200DIA   0001298900Y
28813065AAK27GA0000G4S000500SPY   0001425500Y
28813066X4K27GA00002U000100
28813066A3K27G600000TB000100DDM   0000800800Y
28813066A4K27GA00004CS000100DXD   0000500300Y
28813066AAK27GA0000G5S003000SPY   0001426000Y
28813066XAK27GA0000FY000900
28813066AAK27GA0000G6S001000SPY   0001425700Y
28813066XAK27GA0000FF000500
28813066AAK27GA0000FFS000500SPY   0001425500Y
28813066AAK27GA0000G7B000900SPY   0001425200Y
28813067A9K27G60000GFS001000QQQQ  0000496000Y
28813067XBK27GA000011001000
28813067ABK27GA00001FB001000SSO   0000763800Y
28813067XAK27GA0000F2000500
28813067AAK27GA0000F2B000500SPY   0001425200Y
28813068AAK27GA0000G8S001000SPY   0001425800Y
28813068AAK27GA0000G9S000100SH    0000619000Y
28813068AAK27GA0000GAS001000SDS   0000549100Y
28813068XBK27GA00001E001000
28813068ABK27GA00001GB001000SSO   0000764100Y
28813069XAK27GA0000F2000500
28813069AAK27GA0000F2B000500SPY   0001424900Y
28813069XAK27GA0000E7001000
28813069AAK27GA0000E7B001000SPY   0001425200Y
28813070XAK27GA0000EF001000
28813070AAK27GA0000GBB000900SPY   0001425200Y
28813070X9K27G60000GF001000
28813071XBK27GA00001F001000
28813071ABK27GA00001HB001000SSO   0000763900Y
28813074X9K27G60000G8002000
28813074A9K27G60000G8B002000QQQQ  0000495200Y
28813074A4K27GA00004DS000200DIA   0001299000Y
28813076XBK27GA000012001000
28813076XAK27GA0000F9001000
28813078AAK27GA0000GCB001000SDS   0000547700Y
28813081XAK27GA0000FE000500
28813081AAK27GA0000FEB000500SPY   0001425200Y
28813086XAK27GA0000FV001000
28813094X4K27GA000040000047
28813096X9K27G60000F9003200
28813096A9K27G60000F9B003200QQQQ  0000495600Y
28813097X9K27G60000FY002000
28813097A9K27G60000GGS002000QQQQ  0000496000Y
28813097A9K27G60000GHB002000QQQQ  0000495400Y
28813097X6K27GA00002C000500
28813097A6K27GA00002CB000500IWM   0000736300Y
28813099A9K27G60000GIS002000QQQQ  0000496000Y
28813098A4K27GA00004ES000047DIA   0001298800Y
28813101X8K27G6000001000500
28813099X6K27GA00002P002000
28813101X8K27G6000004000100
28813101ABK27GA00001IB000100UWM   0000542100Y
28813101ABK27GA00001JS000100TWM   0000702400Y
28813101X8K27G6000005000500
28813101XBK27GA00000R000100
28813101X8K27G6000003000100
28813101X4K27GA00004E000047
28813103A8K27G600000CS000500MZZ   0000494200Y
28813103A8K27G600000DB000100MVV   0000805800Y
28813103A8K27G600000ES000100MVV   0000809100Y
28813104A4K27GA00004FS000047DIA   0001299100Y
28813104X4K27GA000035000100
28813105X3K27G600000B000100
28813105X4K27GA00003E000100
28813105X4K27GA000036000100
28813106A4K27GA00004GB000100DXD   0000499200Y
28813107A3K27G600000US000100DDM   0000802600Y
28813105X6K27GA000026000500
28813105A6K27GA000026S000500IWM   0000736900Y
28813107A4K27GA00004HB000100DOG   0000597000Y
28813107A4K27GA00004IB000100DXD   0000499300Y
28813108XAK27GA0000FS001000
28813110AAK27GA0000GDS001000SPY   0001425600Y
28813112X9K27G60000F4003200
28813112A9K27G60000F4S003200QQQQ  0000496300Y
28813116X9K27G60000FB001000
28813116A9K27G60000GJB001000QLD   0000888700Y
28813116X9K27G60000GJ001000
28813116A9K27G60000GKB001000QLD   0000888800Y
28813116A9K27G60000GLS001000QID   0000382100Y
28813117A3K27G600000VS000100DDM   0000802500Y
28813118A9K27G60000GMB001000QQQQ  0000495200Y
28813120X9K27G60000F4003200
28813120A9K27G60000F4S003200QQQQ  0000495800Y
28813127X9K27G60000GM001000
28813127X3K27G600000V000100
28813127A8K27G600000FS000500MZZ   0000494000Y
28813127A8K27G600000GB000100MVV   0000806000Y
28813134X9K27G60000GK001000
28813134A9K27G60000GNB001000QLD   0000888900Y
28813135A9K27G60000GOS000100QID   0000382300Y
28813136A9K27G60000GPB001000QQQQ  0000495200Y
28813136XAK27GA0000FF000500
28813136AAK27GA0000FFS000500SPY   0001425900Y
28813140X9K27G60000GP001000
28813142X4K27GA00003H000200
28813142A4K27GA00003HB000200DIA   0001298600Y
28813144A4K27GA00004JS000100DOG   0000598400Y
28813144X4K27GA00003R000100
28813144A4K27GA00004KS000100DXD   0000500200Y
28813145A3K27G600000WB000100DDM   0000801000Y
28813149X9K27G60000F4003200
28813149A9K27G60000F4S003200QQQQ  0000496300Y
28813151X4K27GA00003L000200
28813151A4K27GA00003LB000200DIA   0001298700Y
28813151X4K27GA00004B000200
28813151XAK27GA0000GD001000
28813151XAK27GA0000E7001000
28813151AAK27GA0000E7B001000SPY   0001425300Y
28813151XAK27GA0000GB000900
28813151AAK27GA0000GBB000900SPY   0001425300Y
28813151XAK27GA0000FE000500
28813151AAK27GA0000FEB000500SPY   0001425300Y
28813150A6K27GA00002RB002000IWM   0000736200Y
28813153AAK27GA0000GES001000SPY   0001425700Y
28813154A3K27G600000XB000100DDM   0000801100Y
28813154X3K27G600000C000100
28813154A4K27GA00004LS000200DIA   0001299200Y
28813170X4K27GA00004L000200
28813174X4K27GA00003L000200
28813174A4K27GA00003LB000200DIA   0001298400Y
28813174A4K27GA00004MS000200DIA   0001298900Y
28813176X3K27G600000X000100
28813185X9K27G60000F4003200
28813185A9K27G60000F4S003200QQQQ  0000495800Y
28813187XAK27GA0000F2000500
28813187AAK27GA0000F2B000500SPY   0001425300Y
28813210AAK27GA0000GFB001000SPY   0001425200Y
28813210XAK27GA0000FQ001000
28813215XAK27GA0000F8000100
28813217XAK27GA0000DX000100
28813217AAK27GA0000GGB000100SH    0000618300Y
28813221AAK27GA0000GHS000100SPY   0001426900Y
28813224XAK27GA0000EY003000
28813224XAK27GA0000EO003000
28813224AAK27GA0000GIB002000SPY   0001425300Y
28813224XAK27GA0000EA001000
28813224AAK27GA0000EAS001000SPY   0001425900Y
28813225XAK27GA0000EI001000
28813225AAK27GA0000GJS003000SPY   0001426200Y
28813230AAK27GA0000GKS001000SPY   0001425900Y
28813230AAK27GA0000GLS003000SPY   0001426200Y
28813246X6K27GA000029000500
28813246A6K27GA000029B000500IWM   0000736300Y
28813247X6K27GA000028000500
28813247A6K27GA000028S000500IWM   0000737000Y
28813248ABK27GA00001KB000100UWM   0000542300Y
28813249ABK27GA00001LS000100TWM   0000702200Y
28813249XBK27GA00001J000100
28813249X6K27GA000029000500
28813249A6K27GA000029B000500IWM   0000736000Y
28813249X6K27GA000028000500
28813249A6K27GA000028S000500IWM   0000736600Y
28813251XBK27GA00001K000100
28813251XBK27GA00001L000100
28813253ABK27GA00001MS000100TWM   0000702400Y
28813259X4K27GA00003L000200
28813259A4K27GA00003LB000200DIA   0001298700Y
28813259X4K27GA00004M000200
28813262A3K27G600000YB000100DDM   0000801100Y
28813264X4K27GA00003L000200
28813264A4K27GA00003LB000200DIA   0001298400Y
28813264X4K27GA00003D000100
28813264A4K27GA00004NS000200DIA   0001298900Y
28813264X4K27GA00004H000100
28813265X3K27G600000U000100
28813266A4K27GA00004OB000100DXD   0000499400Y
28813266A4K27GA00004PB000100DOG   0000597000Y
28813267X3K27G600000Y000100
28813267A3K27G600000ZS000100DDM   0000802600Y
28813268X6K27GA000029000500
28813268A6K27GA000029B000500IWM   0000736300Y
28813271ABK27GA00001NB000100UWM   0000542300Y
28813271XBK27GA00001M000100
28813271ABK27GA00001OS000100TWM   0000702200Y
28813270X6K27GA000029000500
28813270A6K27GA000029B000500IWM   0000736000Y
28813272XBK27GA00001N000100
28813272XBK27GA00001O000100
28813274ABK27GA00001PS000100TWM   0000702400Y
28813289XBK27GA00000N000100
28813289XBK27GA00000O000100
28813289XBK27GA00000S000100
28813289XBK27GA00000P000100
28813288A6K27GA00002SS002000IWM   0000736800Y
28813291ABK27GA00001QS000100UWM   0000543200Y
28813290A6K27GA00002TS000100IWM   0000737000Y
28813290X6K27GA00002T000100
28813290A6K27GA00002US000100IWM   0000736900Y
28813295X6K27GA00002U000100
28813300X9K27G60000EJ000500
28813300X9K27G60000EK000500
28813300X9K27G60000EG000100
28813300A9K27G60000GQB001000QID   0000380800Y
28813300X9K27G60000EM001000
28813301X9K27G60000GE001000
28813302A9K27G60000GRS001000QQQQ  0000496300Y
28813303A9K27G60000GSS001000QQQQ  0000496000Y
28813310X9K27G60000GS001000
28813323XAK27GA0000EC001000
28813324AAK27GA0000GMB000900SPY   0001425400Y
28813325AAK27GA0000GNS001000SDS   0000549000Y
28813325XBK27GA00001G001000
28813325ABK27GA00001RB001000SSO   0000764200Y
28813326AAK27GA0000GOS001000SDS   0000549500Y
28813327XBK27GA00001H001000
28813327ABK27GA00001SB001000SSO   0000764000Y
28813432XAK27GA0000FU002000
28813433XBK27GA00001C002000
28813441A3K27G6000010B002000CELG  0000457300Y
28813458X9K27G60000EX005000
28813458X9K27G60000FJ005000
28813458X9K27G60000F4003200
28813458A9K27G60000F4S003200QQQQ  0000496300Y
28813459A9K27G60000GTB005000QQQQ  0000495700Y
28813459A9K27G60000GUB005000QQQQ  0000495700Y
28813461A9K27G60000GVB001000QLD   0000888800Y
28813474A9K27G60000GWB002000QQQQ  0000495700Y
28813481X1K27GA00001S002000
28813486X9K27G60000G1002000
28813486A9K27G60000G1S002000QQQQ  0000496300Y
28813486X9K27G60000EP002000
28813486A9K27G60000EPB002000QQQQ  0000495700Y
28813496A7K27GA00000WB002000LMT   0000033100Y
28813497XBK27GA00001D002000
28813535X1K27GA00001U002000
28813547A6K27GA00002VB002000IMCL  0000292100Y
28813555X6K27GA00002Q002000
28813557A6K27GA00002WS002000IWM   0000736900Y
28813573X6K27GA000029000500
28813573A6K27GA000029B000500IWM   0000736400Y
28813576ABK27GA00001TB000100UWM   0000542300Y
28813576ABK27GA00001US000100TWM   0000702200Y
28813576XBK27GA00001P000100
28813576X6K27GA000029000500
28813576A6K27GA000029B000500IWM   0000736000Y
28813578X6K27GA000029000500
28813578A6K27GA000029B000500IWM   0000736400Y
28813583A1K27GA00001YB002000ACF   0000118300Y
28813585X6K27GA000029000500
28813585A6K27GA000029B000500IWM   0000736000Y
28813588X8K27G6000002000500
28813588X8K27G600000E000100
28813587X6K27GA000029000500
28813587A6K27GA000029B000500IWM   0000736400Y
28813589XBK27GA00001T000100
28813589XBK27GA00001U000100
28813590A8K27G600000HB000500MZZ   0000491600Y
28813588X6K27GA000029000500
28813588A6K27GA000029B000500IWM   0000736000Y
28813590A8K27G600000IS000100MVV   0000809300Y
28813591ABK27GA00001VB000100UWM   0000542300Y
28813591ABK27GA00001WS000100TWM   0000702200Y
28813591X6K27GA000029000500
28813591A6K27GA000029B000500IWM   0000736400Y
28813592XBK27GA00001V000100
28813592XBK27GA00001W000100
28813592A4K27GA00004QB002000FITB  0000176600Y
28813594X8K27G600000F000500
28813594X8K27G600000G000100
28813594ABK27GA00001XB000100UWM   0000542300Y
28813594ABK27GA00001YS000100TWM   0000702200Y
28813596A8K27G600000JS000500MZZ   0000494100Y
28813596A8K27G600000KB000100MVV   0000805900Y
28813596X6K27GA000029000500
28813596A6K27GA000029B000500IWM   0000736000Y
28813598X6K27GA000029000500
28813598A6K27GA000029B000500IWM   0000736400Y
28813600XBK27GA00001X000100
28813600XBK27GA00001Y000100
28813602ABK27GA00001ZS000100TWM   0000702200Y
28813602ABK27GA000020B000100UWM   0000542300Y
28813609A8K27G600000LS000500MZZ   0000494000Y
28813609A8K27G600000MB000100MVV   0000806100Y
28813615A6K27GA00002XB002000INSP  0000076500Y
28813638A1K27GA00001ZB002000ACN   0000357400Y
28813650A6K27GA00002YB002000ISIL  0000274200Y
28813668A1K27GA000020B002000AFL   0000017100Y
28813686A6K27GA00002ZB002000JNPR  0000272800Y
28813713A1K27GA000021B002000ALL   0000484200Y
28813733A7K27GA00000XB002000LMT   0000032300Y
28813761A7K27GA00000YB002000KLAC  0000444200Y
28813772A1K27GA000022B002000ANF   0000719900Y
28813780A9K27G60000GXB000500QQQQ  0000495100Y
28813787ABK27GA000021B000100TWM   0000701200Y
28813787ABK27GA000022B000100TWM   0000701000Y
28813787ABK27GA000023B000100TWM   0000701100Y
28813812A1K27GA000023B002000ANN   0000257800Y
28813837A1K27GA000024B002000AFL   0000016300Y
28813841A1K27GA000025B002000AOC   0000443100Y
28813857A1K27GA000026B002000ANN   0000257000Y
28813867A3K27G6000011S000100DDM   0000802500Y
28813868A4K27GA00004RB000100DOG   0000597100Y
28813868A3K27G6000012S000100DDM   0000802400Y
28813868A4K27GA00004SB000100DXD   0000499500Y
28813868X4K27GA00004R000100
28813868X4K27GA00004S000100
28813869X3K27G6000012000100
28813879A1K27GA000027B002000AOC   0000442300Y
28813905A1K27GA000028B002000APC   0000762000Y
28813928A1K27GA000029B002000ARO   0000291100Y
28814280X9K27G60000FI005000
28814280X9K27G60000EV005000
28814281X9K27G60000G8002000
28814281A9K27G60000G8B002000QQQQ  0000495700Y
28814282A9K27G60000GYB004000QQQQ  0000495500Y
28814282X9K27G60000EQ002000
28814282A9K27G60000EQS002000QQQQ  0000496100Y
28814282A9K27G60000GZS005000QQQQ  0000496200Y
28814282A9K27G60000H0S005000QQQQ  0000496200Y
28814383X7K27GA00000X002000
28814399X7K27GA00000W002000
28814405X1K27GA000020002000
28814427AAK27GA0000GPB002000SHLD  0000620200Y
28814432ABK27GA000024B002000UTX   0000021100Y
28814474X9K27G60000F7003200
28814474A9K27G60000F7B003200QQQQ  0000495700Y
28814482A1K27GA00002AB002000ABT   0000014000Y
28814484X9K27G60000FP002000
28814512ABK27GA000025B002000UTX   0000020300Y
28814523A7K27GA00000ZB002000LAMR  0000381700Y
28814548A1K27GA00002BB002000APC   0000762900Y
28814564A9K27G60000H1S002000QQQQ  0000496000Y
28814564X9K27G60000GQ001000
28814564A9K27G60000H2S001000QQQQ  0000496400Y
28814566A7K27GA000010B002000LLTC  0000353400Y
28814608A7K27GA000011B002000LNCR  0000236100Y
28814609A1K27GA00002CB002000ABT   0000013200Y
28814624A1K27GA00002DB002000ARO   0000291900Y
28814654A7K27GA000012B002000LPNT  0000171200Y
28814667XAK27GA0000GJ003000
28814675AAK27GA0000GQS003000SPY   0001425600Y
28814678A2K27G600000NB002000AVP   0000358800Y
28814678XAK27GA0000GL003000
28814678AAK27GA0000GRS003000SPY   0001425600Y
28814691XAK27GA0000GR003000
28814691XAK27GA0000GQ003000
28814692X1K27GA000024002000
28814695AAK27GA0000GSS003000SPY   0001426200Y
28814695AAK27GA0000GTS003000SPY   0001426200Y
28814711A7K27GA000013B002000LRCX  0000392200Y
28814740A2K27G600000OB002000AXP   0000394300Y
28814782A2K27G600000PB002000AVP   0000358000Y
28814789A2K27G600000QB002000AZN   0000416400Y
28814814A2K27G600000RB002000BA    0000851800Y
28814827A2K27G600000SB002000AXP   0000393500Y
28814872A2K27G600000TB002000AZN   0000415600Y
28814887A2K27G600000UB002000BA    0000851000Y
28814965A5K27GA00001AB000100FXP   0000654000Y
28815011X4K27GA00004F000047
28815032A4K27GA00004TS000047DIA   0001298800Y
28815095X9K27G60000H0005000
28815095X9K27G60000F7003200
28815095A9K27G60000F7B003200QQQQ  0000495200Y
28815096A9K27G60000H3S005000QQQQ  0000495800Y
28815096X9K27G60000GY002000
28815098A9K27G60000H4B001000QID   0000380800Y
28815194X6K27GA000029000500
28815194A6K27GA000029B000500IWM   0000736000Y
28815198X6K27GA000029000500
28815198A6K27GA000029B000500IWM   0000736400Y
28815200XBK27GA000020000100
28815200XBK27GA00001Z000100
28815200X6K27GA000029000500
28815200A6K27GA000029B000500IWM   0000736000Y
28815202ABK27GA000026B000100UWM   0000542300Y
28815202ABK27GA000027S000100TWM   0000702200Y
28815202X6K27GA000029000500
28815202A6K27GA000029B000500IWM   0000736400Y
28815204XBK27GA000026000100
28815204XBK27GA000027000100
28815205ABK27GA000028B000100UWM   0000542300Y
28815206ABK27GA000029S000100TWM   0000702200Y
28815206X6K27GA000029000500
28815206A6K27GA000029B000500IWM   0000736000Y
28815210XBK27GA000028000100
28815210XBK27GA000029000100
28815212ABK27GA00002AB000100UWM   0000542300Y
28815212ABK27GA00002BS000100TWM   0000702200Y
28815218X6K27GA000029000500
28815218A6K27GA000029B000500IWM   0000736400Y
28815221XBK27GA00002A000100
28815221XBK27GA00002B000100
28815222ABK27GA00002CB000100UWM   0000542300Y
28815222ABK27GA00002DS000100TWM   0000702200Y
28815228X6K27GA000029000500
28815228A6K27GA000029B000500IWM   0000736000Y
28815240XBK27GA00002C000100
28815240XBK27GA00002D000100
28815240X6K27GA000029000500
28815240A6K27GA000029B000500IWM   0000736400Y
28815242ABK27GA00002ES000100TWM   0000702400Y
28815243ABK27GA00002FB000100UWM   0000542300Y
28815243XBK27GA00002E000100
28815243ABK27GA00002GS000100TWM   0000702200Y
28815242X6K27GA000029000500
28815242A6K27GA000029B000500IWM   0000736000Y
28815246X6K27GA000029000500
28815246A6K27GA000029B000500IWM   0000736400Y
28815248XBK27GA00002F000100
28815248XBK27GA00002G000100
28815248X6K27GA000029000500
28815248A6K27GA000029B000500IWM   0000736000Y
28815250ABK27GA00002HB000100UWM   0000542300Y
28815250ABK27GA00002IS000100TWM   0000702200Y
28815251XBK27GA00002I000100
28815251XBK27GA00002H000100
28815253ABK27GA00002JS000100TWM   0000702400Y
28815253X6K27GA000029000500
28815253A6K27GA000029B000500IWM   0000736400Y
28815256ABK27GA00002KB000100UWM   0000542300Y
28815256ABK27GA00002LS000100TWM   0000702200Y
28815256XBK27GA00002J000100
28815257X6K27GA000029000500
28815257A6K27GA000029B000500IWM   0000736000Y
28815266X6K27GA000029000500
28815266A6K27GA000029B000500IWM   0000736400Y
28815277X6K27GA000029000500
28815277A6K27GA000029B000500IWM   0000736000Y
28815279XBK27GA00002L000100
28815279XBK27GA00002K000100
28815281ABK27GA00002MB000100UWM   0000542300Y
28815281ABK27GA00002NS000100TWM   0000702200Y
28815280X6K27GA000029000500
28815280A6K27GA000029B000500IWM   0000736400Y
28815286X6K27GA000029000500
28815286A6K27GA000029B000500IWM   0000736000Y
28815287X6K27GA000029000500
28815287A6K27GA000029B000500IWM   0000736400Y
28815299XBK27GA00002M000100
28815299XBK27GA00002N000100
28815298X6K27GA000029000500
28815298A6K27GA000029B000500IWM   0000736000Y
28815301ABK27GA00002OB000100UWM   0000542300Y
28815301ABK27GA00002PS000100TWM   0000702200Y
28815301X6K27GA000029000500
28815301A6K27GA000029B000500IWM   0000736400Y
28815306X6K27GA000029000500
28815306A6K27GA000029B000500IWM   0000736000Y
28815317X6K27GA000029000500
28815317A6K27GA000029B000500IWM   0000736400Y
28815319XBK27GA00002O000100
28815319XBK27GA00002P000100
28815319A6K27GA000030B000100IWM   0000735900Y
28815319X6K27GA000030000100
28815321ABK27GA00002QS000100TWM   0000702400Y
28815320X6K27GA000029000500
28815320A6K27GA000029B000500IWM   0000736000Y
28815326X6K27GA000029000500
28815326A6K27GA000029B000500IWM   0000736400Y
28815327X6K27GA000029000500
28815327A6K27GA000029B000500IWM   0000736000Y
28815329ABK27GA00002RB000100UWM   0000542300Y
28815329ABK27GA00002SS000100TWM   0000702200Y
28815329XBK27GA00002Q000100
28815329XBK27GA00002R000100
28815329XBK27GA00002S000100
28815331ABK27GA00002TS000100TWM   0000702400Y
28815330X6K27GA000029000500
28815330A6K27GA000029B000500IWM   0000736400Y
28815336X6K27GA000029000500
28815336A6K27GA000029B000500IWM   0000736000Y
28815337X6K27GA000029000500
28815337A6K27GA000029B000500IWM   0000736400Y
28815349ABK27GA00002UB000100UWM   0000542300Y
28815349ABK27GA00002VS000100TWM   0000702200Y
28815349XBK27GA00002T000100
28815348X6K27GA000029000500
28815348A6K27GA000029B000500IWM   0000736000Y
28815351X6K27GA000029000500
28815351A6K27GA000029B000500IWM   0000736400Y
28815356X6K27GA000029000500
28815356A6K27GA000029B000500IWM   0000736000Y
28815358X6K27GA000029000500
28815358A6K27GA000029B000500IWM   0000736400Y
28815361A5K27GA00001BB000100GOOG  0005760100Y
28815364X6K27GA00002V002000
28815369XBK27GA00002U000100
28815369XBK27GA00002V000100
28815368X6K27GA000029000500
28815368A6K27GA000029B000500IWM   0000736000Y
28815371ABK27GA00002WS000100TWM   0000702400Y
28815378X6K27GA000029000500
28815378A6K27GA000029B000500IWM   0000736400Y
28815388X6K27GA000029000500
28815388A6K27GA000029B000500IWM   0000736000Y
28815398X6K27GA000029000500
28815398A6K27GA000029B000500IWM   0000736400Y
28815399XAK27GA0000GP002000
28815401A7K27GA000014B002000LMT   0000039100Y
28815408X6K27GA000029000500
28815408A6K27GA000029B000500IWM   0000736000Y
28815420XBK27GA000025002000
28815428X6K27GA000029000500
28815428A6K27GA000029B000500IWM   0000736400Y
28815430A7K27GA000015B002000LMT   0000038300Y
28815451A7K27GA000016B002000MNST  0000247700Y
28815463X1K27GA00002C002000
28815466XBK27GA000024002000
28815492ACK27GA00001HB002000WYE   0000010400Y
28815497A8K27G600000NB002000NPSP  0000030200Y
28815521X1K27GA00002A002000
28815549ABK27GA00002XB000100UWM   0000542300Y
28815549XBK27GA00002W000100
28815549ABK27GA00002YS000100TWM   0000702200Y
28815549A1K27GA00002EB002000AFL   0000020800Y
28815592A2K27G600000VB002000BAX   0000587800Y
28815617A2K27G600000WB002000BBY   0000423100Y
28815632A2K27G600000XB002000BDX   0000753400Y
28815652A5K27GA00001CB000100FXP   0000656300Y
28815652X5K27GA00000R000100
28815654A2K27G600000YB002000BHI   0000843500Y
28815656A5K27GA00001DS000100FXP   0000658300Y
28815662XAK27GA0000GF001000
28815665A5K27GA00001ES000100FXP   0000657600Y
28815665X5K27GA00001D000100
28815665X5K27GA00001E000100
28815677A8K27G600000OB002000NTAP  0000245400Y
28815718A2K27G600000ZB002000BJS   0000301100Y
28815729A1K27GA00002FB002000AFL   0000020000Y
28815739A8K27G600000PB002000NTRS  0000653200Y
28815777A2K27G6000010B002000BAX   0000587000Y
28815782A8K27G600000QB002000NVTL  0000076500Y
28815788X6K27GA000029000500
28815791XBK27GA00002X000100
28815791XBK27GA00002Y000100
28815790A6K27GA000031B000500IWM   0000736400Y
28815793ABK27GA00002ZS000100TWM   0000702400Y
28815792X6K27GA000031000500
28815792A6K27GA000031B000500IWM   0000736000Y
28815794ABK27GA000030B000100UWM   0000542300Y
28815794XBK27GA00002Z000100
28815794ABK27GA000031S000100TWM   0000702200Y
28815796XBK27GA000030000100
28815796XBK27GA000031000100
28815796X6K27GA000031000500
28815796A6K27GA000031B000500IWM   0000736400Y
28815797ABK27GA000032S000100TWM   0000702400Y
28815799ABK27GA000033B000100UWM   0000542300Y
28815799XBK27GA000032000100
28815799ABK27GA000034S000100TWM   0000702200Y
28815798X6K27GA000031000500
28815798A6K27GA000031B000500IWM   0000736000Y
28815801XBK27GA000033000100
28815801XBK27GA000034000100
28815803ABK27GA000035S000100TWM   0000702400Y
28815806X6K27GA000031000500
28815806A6K27GA000031B000500IWM   0000736400Y
28815809ABK27GA000036B000100UWM   0000542300Y
28815809XBK27GA000035000100
28815809ABK27GA000037S000100TWM   0000702200Y
28815808X6K27GA000031000500
28815808A6K27GA000031B000500IWM   0000736000Y
28815811XBK27GA000036000100
28815811XBK27GA000037000100
28815810X6K27GA000031000500
28815810A6K27GA000031B000500IWM   0000736400Y
28815813ABK27GA000038S000100TWM   0000702400Y
28815813ABK27GA000039B000100UWM   0000542300Y
28815813XBK27GA000038000100
28815812X6K27GA000031000500
28815812A6K27GA000031B000500IWM   0000736000Y
28815814ABK27GA00003AS000100TWM   0000702200Y
28815816A2K27G6000011B002000BBY   0000422300Y
28815815XBK27GA000039000100
28815815XBK27GA00003A000100
28815816A6K27GA000032B000100IWM   0000735900Y
28815817ABK27GA00003BS000100TWM   0000702400Y
28815816X6K27GA000031000500
28815816A6K27GA000031B000500IWM   0000736400Y
28815816X6K27GA000032000100
28815818X6K27GA000031000500
28815818A6K27GA000031B000500IWM   0000736000Y
28815821ABK27GA00003CS000100TWM   0000702200Y
28815821ABK27GA00003DB000100UWM   0000542300Y
28815821XBK27GA00003B000100
28815821XBK27GA00003D000100
28815821XBK27GA00003C000100
28815820X6K27GA000031000500
28815820A6K27GA000031B000500IWM   0000736400Y
28815823ABK27GA00003ES000100TWM   0000702400Y
28815823ABK27GA00003FS000100TWM   0000702200Y
28815823XBK27GA00003E000100
28815822X6K27GA000031000500
28815822A6K27GA000031B000500IWM   0000736000Y
28815823ABK27GA00003GB000100UWM   0000542300Y
28815825XBK27GA00003G000100
28815825XBK27GA00003F000100
28815824X6K27GA000031000500
28815824A6K27GA000031B000500IWM   0000736400Y
28815827ABK27GA00003HS000100TWM   0000702400Y
28815827X6K27GA000031000500
28815827A6K27GA000031B000500IWM   0000736000Y
28815829X6K27GA000031000500
28815829A6K27GA000031B000500IWM   0000736400Y
28815831X6K27GA000031000500
28815831A6K27GA000031B000500IWM   0000736000Y
28815833X6K27GA000031000500
28815833A6K27GA000031B000500IWM   0000736400Y
28815835X6K27GA000031000500
28815835A6K27GA000031B000500IWM   0000736000Y
28815839A2K27G6000012B002000BDX   0000752600Y
28815837X6K27GA000031000500
28815837A6K27GA000031B000500IWM   0000736400Y
28815840X6K27GA000031000500
28815840A6K27GA000031B000500IWM   0000736000Y
28815843X6K27GA000031000500
28815843A6K27GA000031B000500IWM   0000736400Y
28815845X6K27GA000031000500
28815845A6K27GA000031B000500IWM   0000736000Y
28815847X6K27GA000031000500
28815847A6K27GA000031B000500IWM   0000736400Y
28815849XAK27GA0000FK002000
28815849X6K27GA000031000500
28815849A6K27GA000031B000500IWM   0000736000Y
28815851X6K27GA000031000500
28815851A6K27GA000031B000500IWM   0000736400Y
28815858A2K27G6000013B002000BHI   0000842700Y
28815858X6K27GA000031000500
28815858A6K27GA000031B000500IWM   0000736000Y
28815868X6K27GA000031000500
28815868A6K27GA000031B000500IWM   0000736400Y
28815878X6K27GA000031000500
28815878A6K27GA000031B000500IWM   0000736000Y
28815888X6K27GA000031000500
28815888A6K27GA000031B000500IWM   0000736400Y
28815898X6K27GA000031000500
28815898A6K27GA000031B000500IWM   0000736000Y
28815908X6K27GA000031000500
28815908A6K27GA000031B000500IWM   0000736400Y
28815918X6K27GA000031000500
28815918A6K27GA000031B000500IWM   0000736000Y
28815928X6K27GA000031000500
28815928A6K27GA000031B000500IWM   0000736400Y
28815938X6K27GA000031000500
28815938A6K27GA000031B000500IWM   0000736000Y
28815948X6K27GA000031000500
28815948A6K27GA000031B000500IWM   0000736400Y
28815958X6K27GA000031000500
28815958A6K27GA000031B000500IWM   0000736000Y
28815968X6K27GA000031000500
28815968A6K27GA000031B000500IWM   0000736400Y
28815970X6K27GA000031000500
28815970A6K27GA000031B000500IWM   0000736000Y
28815978X6K27GA000031000500
28815978A6K27GA000031B000500IWM   0000736400Y
28815980X6K27GA000031000500
28815980A6K27GA000031B000500IWM   0000736000Y
28815982X6K27GA000031000500
28815982A6K27GA000031B000500IWM   0000736400Y
28815987X6K27GA000031000500
28815987A6K27GA000031B000500IWM   0000736000Y
28815989X6K27GA000031000500
28815989A6K27GA000031B000500IWM   0000736400Y
28815997X6K27GA000031000500
28815997A6K27GA000031B000500IWM   0000736000Y
28815999X6K27GA000031000500
28815999A6K27GA000031B000500IWM   0000736400Y
28816007X6K27GA000031000500
28816007A6K27GA000031B000500IWM   0000736000Y
28816017X6K27GA000031000500
28816017A6K27GA000031B000500IWM   0000736400Y
28816020X6K27GA000031000500
28816020A6K27GA000031B000500IWM   0000736000Y
28816021X6K27GA000031000500
28816021A6K27GA000031B000500IWM   0000736400Y
28816027X6K27GA000031000500
28816027A6K27GA000031B000500IWM   0000736000Y
28816038X6K27GA000031000500
28816038A6K27GA000031B000500IWM   0000736400Y
28816040X6K27GA000031000500
28816040A6K27GA000031B000500IWM   0000736000Y
28816140A4K27GA00004UB000100DXD   0000499500Y
28816332XAK27GA0000E3000100
28816332AAK27GA0000GUB000100SPY   0001424100Y
28816360X7K27GA000015002000
28816362A6K27GA000033B002000IMCL  0000295400Y
28816372ABK27GA00003IB002000UTX   0000024300Y
28816388X6K27GA000031000500
28816397A6K27GA000034B000500IWM   0000736400Y
28816400ABK27GA00003JB000100UWM   0000542300Y
28816401ABK27GA00003KS000100TWM   0000702200Y
28816401XBK27GA00003H000100
28816402X6K27GA000034000500
28816402A6K27GA000034B000500IWM   0000736000Y
28816405XBK27GA00003J000100
28816405XBK27GA00003K000100
28816406X7K27GA000014002000
28816407ABK27GA00003LS000100TWM   0000702400Y
28816406X6K27GA000034000500
28816406A6K27GA000034B000500IWM   0000736400Y
28816407X6K27GA000034000500
28816407A6K27GA000034B000500IWM   0000736000Y
28816409ABK27GA00003MB000100UWM   0000542300Y
28816409XBK27GA00003L000100
28816409ABK27GA00003NS000100TWM   0000702200Y
28816410XBK27GA00003M000100
28816410XBK27GA00003N000100
28816412ABK27GA00003OS000100TWM   0000702400Y
28816416X6K27GA000034000500
28816416A6K27GA000034B000500IWM   0000736400Y
28816421ABK27GA00003PS000100TWM   0000702200Y
28816421ABK27GA00003QB000100UWM   0000542300Y
28816421XBK27GA00003O000100
28816420X6K27GA000034000500
28816420A6K27GA000034B000500IWM   0000736000Y
28816424XBK27GA00003Q000100
28816424XBK27GA00003P000100
28816425ABK27GA00003RS000100TWM   0000702400Y
28816426X6K27GA000034000500
28816426A6K27GA000034B000500IWM   0000736400Y
28816427X6K27GA000034000500
28816427A6K27GA000034B000500IWM   0000736000Y
28816429ABK27GA00003SB000100UWM   0000542300Y
28816429XBK27GA00003R000100
28816429ABK27GA00003TS000100TWM   0000702200Y
28816430XBK27GA00003S000100
28816430XBK27GA00003T000100
28816432ABK27GA00003US000100TWM   0000702400Y
28816434A4K27GA00004VB000100DRYS  0001065100Y
28816434A4K27GA00004WS000100DRYS  0001071400Y
28816436X6K27GA000034000500
28816436A6K27GA000034B000500IWM   0000736400Y
28816439ABK27GA00003VB000100UWM   0000542300Y
28816439ABK27GA00003WS000100TWM   0000702200Y
28816440XBK27GA00003U000100
28816440X6K27GA000034000500
28816440A6K27GA000034B000500IWM   0000736000Y
28816443XBK27GA00003V000100
28816443XBK27GA00003W000100
28816445ABK27GA00003XS000100TWM   0000702400Y
28816445XCK27GA00001H002000
28816446X6K27GA000034000500
28816446A6K27GA000034B000500IWM   0000736400Y
28816447X6K27GA000034000500
28816447A6K27GA000034B000500IWM   0000736000Y
28816449ABK27GA00003YB000100UWM   0000542300Y
28816449XBK27GA00003X000100
28816449ABK27GA00003ZS000100TWM   0000702200Y
28816450XBK27GA00003Y000100
28816450XBK27GA00003Z000100
28816452ABK27GA000040S000100TWM   0000702400Y
28816456X6K27GA000034000500
28816456A6K27GA000034B000500IWM   0000736400Y
28816459ABK27GA000041B000100UWM   0000542300Y
28816459ABK27GA000042S000100TWM   0000702200Y
28816460XBK27GA000040000100
28816461X6K27GA000034000500
28816461A6K27GA000034B000500IWM   0000736000Y
28816464XBK27GA000041000100
28816464XBK27GA000042000100
28816466ABK27GA000043S000100TWM   0000702400Y
28816466X6K27GA000034000500
28816466A6K27GA000034B000500IWM   0000736400Y
28816467ACK27GA00001IB002000WYE   0000010800Y
28816468AAK27GA0000GVB002000SHLD  0000625300Y
28816469X6K27GA000034000500
28816469A6K27GA000034B000500IWM   0000736000Y
28816478X6K27GA000034000500
28816478A6K27GA000034B000500IWM   0000736400Y
28816488X6K27GA000034000500
28816488A6K27GA000034B000500IWM   0000736000Y
28816491X1K27GA00002E002000
28816498A8K27G600000RB002000OSIP  0000340300Y
28816498X6K27GA000034000500
28816498A6K27GA000034B000500IWM   0000736400Y
28816508X6K27GA000034000500
28816508A6K27GA000034B000500IWM   0000736000Y
28816515A1K27GA00002GB002000ABT   0000016200Y
28816516ABK27GA000044B002000UTX   0000025100Y
28816518X6K27GA000034000500
28816518A6K27GA000034B000500IWM   0000736400Y
28816528X6K27GA000034000500
28816528A6K27GA000034B000500IWM   0000736000Y
28816538X6K27GA000034000500
28816538A6K27GA000034B000500IWM   0000736400Y
28816548X6K27GA000034000500
28816548A6K27GA000034B000500IWM   0000736000Y
28816558X6K27GA000034000500
28816558A6K27GA000034B000500IWM   0000736400Y
28816568X6K27GA000034000500
28816568A6K27GA000034B000500IWM   0000736000Y
28816571A8K27G600000SB002000OVTI  0000149700Y
28816570X1K27GA00002F002000
28816578X6K27GA000034000500
28816578A6K27GA000034B000500IWM   0000736400Y
28816583A1K27GA00002HB002000ABT   0000017100Y
28816588X6K27GA000034000500
28816588A6K27GA000034B000500IWM   0000736000Y
28816598X6K27GA000034000500
28816598A6K27GA000034B000500IWM   0000736400Y
28816608X6K27GA000034000500
28816608A6K27GA000034B000500IWM   0000736000Y
28816616A8K27G600000TB002000PAYX  0000340300Y
28816618X6K27GA000034000500
28816618A6K27GA000034B000500IWM   0000736400Y
28816621A2K27G6000014B002000BK    0000424100Y
28816628X6K27GA000034000500
28816628A6K27GA000034B000500IWM   0000736000Y
28816638X6K27GA000034000500
28816638A6K27GA000034B000500IWM   0000736400Y
28816648X6K27GA000034000500
28816648A6K27GA000034B000500IWM   0000736000Y
28816658X6K27GA000034000500
28816658A6K27GA000034B000500IWM   0000736400Y
28816668X6K27GA000034000500
28816668A6K27GA000034B000500IWM   0000736000Y
28816673A9K27G60000H5B002000PCAR  0000471200Y
28816675A2K27G6000015B002000BMC   0000365000Y
28816678X6K27GA000034000500
28816678A6K27GA000034B000500IWM   0000736400Y
28816688X6K27GA000034000500
28816688A6K27GA000034B000500IWM   0000736000Y
28816698X6K27GA000034000500
28816698A6K27GA000034B000500IWM   0000736400Y
28816708X6K27GA000034000500
28816708A6K27GA000034B000500IWM   0000736000Y
28816718X6K27GA000034000500
28816718A6K27GA000034B000500IWM   0000736400Y
28816730A2K27G6000016B002000BNI   0001056100Y
28816728X6K27GA000034000500
28816728A6K27GA000034B000500IWM   0000736000Y
28816735X1K27GA000011000100
28816738X6K27GA000034000500
28816738A6K27GA000034B000500IWM   0000736400Y
28816741P1K27GA000011B000100AAPL  0001830100000N1AQ00002
28816748X6K27GA000034000500
28816748A6K27GA000034B000500IWM   0000736000Y
28816758X6K27GA000034000500
28816758A6K27GA000034B000500IWM   0000736400Y
28816768X6K27GA000034000500
28816768A6K27GA000034B000500IWM   0000736000Y
28816774A2K27G6000017B002000BP    0000739100Y
28816778X6K27GA000034000500
28816778A6K27GA000034B000500IWM   0000736400Y
28816788X6K27GA000034000500
28816788A6K27GA000034B000500IWM   0000736000Y
28816798X6K27GA000034000500
28816798A6K27GA000034B000500IWM   0000736400Y
28816802A2K27G6000018B002000BJS   0000300300Y
28816807X6K27GA000034000500
28816807A6K27GA000034B000500IWM   0000736000Y
28816817X6K27GA000034000500
28816817A6K27GA000034B000500IWM   0000736400Y
28816827A2K27G6000019B002000BR    0000191600Y
28816827X6K27GA000034000500
28816827A6K27GA000034B000500IWM   0000736000Y
28816840X9K27G60000GX000500
28816851A2K27G600001AB002000BK    0000423300Y
28816872A2K27G600001BB002000BSX   0000118800Y
28816878A2K27G600001CB002000BMC   0000364200Y
28816913A2K27G600001DB002000BNI   0001055300Y
28816945X9K27G60000GZ005000
28816945X9K27G60000G8002000
28816945A9K27G60000G8B002000QQQQ  0000495200Y
28816945X9K27G60000G1002000
28816945A9K27G60000G1S002000QQQQ  0000495800Y
28816945A9K27G60000H6S005000QQQQ  0000495800Y
28816945X9K27G60000GT005000
28816945X9K27G60000GU005000
28816946A9K27G60000H7S002000QQQQ  0000495800Y
28816946X9K27G60000GY002000
28816947X9K27G60000EQ002000
28816947A9K27G60000EQS002000QQQQ  0000495800Y
28816947A9K27G60000H8B005000QQQQ  0000495300Y
28816947A9K27G60000H9B005000QQQQ  0000495300Y
28816967AAK27GA0000GWB001000SPY   0001425200Y
28816970X9K27G60000H8005000
28816970X9K27G60000H9005000
28816970A9K27G60000HAB005000QQQQ  0000495700Y
28816970A9K27G60000HBB005000QQQQ  0000495700Y
28817104XAK27GA0000E4001000
28817104AAK27GA0000E4B001000SPY   0001425400Y
28817177X6K27GA000034000500
28817178A6K27GA000035B000500IWM   0000735900Y
28817187X6K27GA000035000500
28817187A6K27GA000035B000500IWM   0000736000Y
28817197X6K27GA000035000500
28817197A6K27GA000035B000500IWM   0000736400Y
28817202ABK27GA000045B000100UWM   0000542300Y
28817202XBK27GA000043000100
28817202ABK27GA000046S000100TWM   0000702200Y
28817203X6K27GA000035000500
28817203A6K27GA000035B000500IWM   0000736000Y
28817205X6K27GA000035000500
28817205A6K27GA000035B000500IWM   0000736400Y
28817207XBK27GA000045000100
28817207XBK27GA000046000100
28817208ABK27GA000047B000100UWM   0000542300Y
28817208ABK27GA000048S000100TWM   0000702200Y
28817208X6K27GA000035000500
28817208A6K27GA000035B000500IWM   0000736000Y
28817211XBK27GA000047000100
28817211XBK27GA000048000100
28817211A6K27GA000036B000100IWM   0000735900Y
28817213ABK27GA000049S000100TWM   0000702400Y
28817212X6K27GA000036000100
28817216X6K27GA000035000500
28817216A6K27GA000035B000500IWM   0000736400Y
28817218X6K27GA000035000500
28817218A6K27GA000035B000500IWM   0000736000Y
28817221XBK27GA000049000100
28817221ABK27GA00004AB000100UWM   0000542300Y
28817221ABK27GA00004BS000100TWM   0000702200Y
28817221XBK27GA00004A000100
28817221XBK27GA00004B000100
28817221X6K27GA000035000500
28817221A6K27GA000035B000500IWM   0000736400Y
28817223ABK27GA00004CS000100TWM   0000702400Y
28817225ABK27GA00004DB000100UWM   0000542300Y
28817225ABK27GA00004ES000100TWM   0000702200Y
28817225XBK27GA00004C000100
28817226X6K27GA000035000500
28817226A6K27GA000035B000500IWM   0000736000Y
28817230XBK27GA00004D000100
28817230XBK27GA00004E000100
28817230A6K27GA000037B000100IWM   0000735900Y
28817232ABK27GA00004FS000100TWM   0000702400Y
28817230X6K27GA000037000100
28817231X6K27GA000035000500
28817231A6K27GA000035B000500IWM   0000736400Y
28817234ABK27GA00004GS000100TWM   0000702200Y
28817234XBK27GA00004F000100
28817234ABK27GA00004HB000100UWM   0000542300Y
28817236X6K27GA000035000500
28817236A6K27GA000035B000500IWM   0000736000Y
28817237X6K27GA000035000500
28817237A6K27GA000035B000500IWM   0000736400Y
28817239XBK27GA00004H000100
28817239XBK27GA00004G000100
28817241ABK27GA00004IB000100UWM   0000542300Y
28817239A6K27GA000038B000100IWM   0000735900Y
28817240X6K27GA000038000100
28817241ABK27GA00004JS000100TWM   0000702200Y
28817240X6K27GA000035000500
28817240A6K27GA000035B000500IWM   0000736000Y
28817244XBK27GA00004I000100
28817244XBK27GA00004J000100
28817245ABK27GA00004KS000100TWM   0000702400Y
28817246X6K27GA000035000500
28817246A6K27GA000035B000500IWM   0000736400Y
28817247X6K27GA000035000500
28817247A6K27GA000035B000500IWM   0000736000Y
28817249ABK27GA00004LB000100UWM   0000542300Y
28817249ABK27GA00004MS000100TWM   0000702200Y
28817249XBK27GA00004K000100
28817251XBK27GA00004L000100
28817251XBK27GA00004M000100
28817251A6K27GA000039B000100IWM   0000735900Y
28817251X6K27GA000039000100
28817253ABK27GA00004NS000100TWM   0000702400Y
28817256X6K27GA000035000500
28817256A6K27GA000035B000500IWM   0000736400Y
28817267X6K27GA000035000500
28817267A6K27GA000035B000500IWM   0000736000Y
28817277X6K27GA000035000500
28817277A6K27GA000035B000500IWM   0000736400Y
28817287X6K27GA000035000500
28817287A6K27GA000035B000500IWM   0000736000Y
28817297X6K27GA000035000500
28817297A6K27GA000035B000500IWM   0000736400Y
28817299X6K27GA000035000500
28817299A6K27GA000035B000500IWM   0000736000Y
28817308X6K27GA000035000500
28817308A6K27GA000035B000500IWM   0000736400Y
28817318X6K27GA000035000500
28817318A6K27GA000035B000500IWM   0000736000Y
28817328X6K27GA000035000500
28817328A6K27GA000035B000500IWM   0000736400Y
28817338X6K27GA000035000500
28817338A6K27GA000035B000500IWM   0000736000Y
28817348XAK27GA0000GV002000
28817348X6K27GA000035000500
28817348A6K27GA000035B000500IWM   0000736400Y
28817358X6K27GA000035000500
28817358A6K27GA000035B000500IWM   0000736000Y
28817366X9K27G60000HB005000
28817368X6K27GA000035000500
28817368A6K27GA000035B000500IWM   0000736400Y
28817378X6K27GA000035000500
28817378A6K27GA000035B000500IWM   0000736000Y
28817388X6K27GA000035000500
28817388A6K27GA000035B000500IWM   0000736400Y
28817398X6K27GA000035000500
28817398A6K27GA000035B000500IWM   0000736000Y
28817407XBK27GA000044002000
28817407A7K27GA000017B002000LMT   0000044300Y
28817408X6K27GA000035000500
28817408A6K27GA000035B000500IWM   0000736400Y
28817419XBK27GA00003I002000
28817418X6K27GA000035000500
28817418A6K27GA000035B000500IWM   0000736000Y
28817420A9K27G60000HCB002000PETM  0000203300Y
28817428A7K27GA000018B002000LMT   0000045100Y
28817428X6K27GA000035000500
28817428A6K27GA000035B000500IWM   0000736400Y
28817434XCK27GA00001I002000
28817438X6K27GA000035000500
28817438A6K27GA000035B000500IWM   0000736000Y
28817443XAK27GA0000G4000500
28817443AAK27GA0000G4S000500SPY   0001425900Y
28817445XAK27GA0000GC001000
28817447AAK27GA0000GXB001000SDS   0000547600Y
28817448X6K27GA000035000500
28817448A6K27GA000035B000500IWM   0000736400Y
28817455XAK27GA0000G4000500
28817455AAK27GA0000G4S000500SPY   0001425500Y
28817455X1K27GA00002G002000
28817455XAK27GA0000FD000500
28817455AAK27GA0000FDB000500SPY   0001425400Y
28817457AAK27GA0000GYB001000SDS   0000547700Y
28817457XAK27GA0000GX001000
28817457X6K27GA000035000500
28817457A6K27GA000035B000500IWM   0000736000Y
28817461XAK27GA0000G4000500
28817461AAK27GA0000G4S000500SPY   0001425900Y
28817462X4K27GA00004T000047
28817462XAK27GA0000GY001000
28817464AAK27GA0000GZB001000SDS   0000547600Y
28817465XAK27GA0000G4000500
28817465AAK27GA0000G4S000500SPY   0001425500Y
28817465A9K27G60000HDB005000QQQQ  0000495300Y
28817466XAK27GA0000GZ001000
28817467AAK27GA0000H0B001000SDS   0000547700Y
28817467X6K27GA000035000500
28817467A6K27GA000035B000500IWM   0000736400Y
28817469XAK27GA0000G4000500
28817469AAK27GA0000G4S000500SPY   0001425900Y
28817469A4K27GA00004XS000047DIA   0001299100Y
28817470XAK27GA0000H0001000
28817472AAK27GA0000H1B001000SDS   0000547600Y
28817473XAK27GA0000G4000500
28817473AAK27GA0000G4S000500SPY   0001425500Y
28817474XAK27GA0000H1001000
28817475AAK27GA0000H2B001000SDS   0000547700Y
28817474X6K27GA000035000500
28817474A6K27GA000035B000500IWM   0000736000Y
28817476XAK27GA0000G4000500
28817476AAK27GA0000G4S000500SPY   0001425900Y
28817476XAK27GA0000H2001000
28817478AAK27GA0000H3B001000SDS   0000547600Y
28817478X6K27GA000035000500
28817478A6K27GA000035B000500IWM   0000736400Y
28817485XAK27GA0000G4000500
28817485AAK27GA0000G4S000500SPY   0001425500Y
28817486XAK27GA0000H3001000
28817486AAK27GA0000H4B001000SDS   0000547700Y
28817486X6K27GA000035000500
28817486A6K27GA000035B000500IWM   0000736000Y
28817488X6K27GA000035000500
28817488A6K27GA000035B000500IWM   0000736400Y
28817491X1K27GA00002H002000
28817494XAK27GA0000G4000500
28817494AAK27GA0000G4S000500SPY   0001425900Y
28817493X6K27GA000035000500
28817493A6K27GA000035B000500IWM   0000736000Y
28817495X6K27GA000035000500
28817495A6K27GA000035B000500IWM   0000736400Y
28817496XAK27GA0000H4001000
28817498AAK27GA0000H5B001000SDS   0000547600Y
28817497X6K27GA000035000500
28817497A6K27GA000035B000500IWM   0000736000Y
28817503X6K27GA000035000500
28817503A6K27GA000035B000500IWM   0000736400Y
28817505A9K27G60000HEB002000PLCM  0000229800Y
28817505XAK27GA0000G4000500
28817505AAK27GA0000G4S000500SPY   0001425500Y
28817506XAK27GA0000H5001000
28817506AAK27GA0000H6B001000SDS   0000547700Y
28817507X6K27GA000035000500
28817507A6K27GA000035B000500IWM   0000736000Y
28817513X6K27GA000035000500
28817513A6K27GA000035B000500IWM   0000736400Y
28817515XAK27GA0000G4000500
28817515AAK27GA0000G4S000500SPY   0001425900Y
28817517XAK27GA0000H6001000
28817518AAK27GA0000H7B001000SDS   0000547600Y
28817517X6K27GA000035000500
28817517A6K27GA000035B000500IWM   0000736000Y
28817524XAK27GA0000G4000500
28817524AAK27GA0000G4S000500SPY   0001425500Y
28817524X6K27GA000035000500
28817524A6K27GA000035B000500IWM   0000736400Y
28817526XAK27GA0000H7001000
28817526AAK27GA0000H8B001000SDS   0000547700Y
28817526X6K27GA000035000500
28817526A6K27GA000035B000500IWM   0000736000Y
28817534XAK27GA0000G4000500
28817534AAK27GA0000G4S000500SPY   0001425900Y
28817536XAK27GA0000H8001000
28817538AAK27GA0000H9B001000SDS   0000547600Y
28817539XAK27GA0000H9001000
28817539AAK27GA0000HAB001000SDS   0000547700Y
28817542ACK27GA00001JB002000WYE   0000012800Y
28817545XAK27GA0000HA001000
28817546A1K27GA00002IB002000AFL   0000023700Y
28817546AAK27GA0000HBB001000SDS   0000547600Y
28817566A9K27G60000HFB002000PSUN  0000087100Y
28817570ABK27GA00004OB000100UWM   0000542300Y
28817570XBK27GA00004N000100
28817570ABK27GA00004PS000100TWM   0000702200Y
28817579XBK27GA00004O000100
28817579XBK27GA00004P000100
28817581ABK27GA00004QS000100TWM   0000702400Y
28817589ABK27GA00004RB000100UWM   0000542300Y
28817589XBK27GA00004Q000100
28817589ABK27GA00004SS000100TWM   0000702200Y
28817589XBK27GA00004S000100
28817589XBK27GA00004R000100
28817591ABK27GA00004TS000100TWM   0000702400Y
28817605AAK27GA0000HCB002000SBUX  0000158300Y
28817628A1K27GA00002JB002000AFL   0000024500Y
28817629ABK27GA00004UB000100UWM   0000542300Y
28817629XBK27GA00004T000100
28817629ABK27GA00004VS000100TWM   0000702200Y
28817639XBK27GA00004U000100
28817639XBK27GA00004V000100
28817641ABK27GA00004WB000100UWM   0000542300Y
28817639A6K27GA00003AB000100IWM   0000735900Y
28817641ABK27GA00004XS000100TWM   0000702200Y
28817639X6K27GA00003A000100
28817649XBK27GA00004W000100
28817649XBK27GA00004X000100
28817651ABK27GA00004YB000100UWM   0000542300Y
28817651ABK27GA00004ZS000100TWM   0000702200Y
28817659XBK27GA00004Y000100
28817659XBK27GA00004Z000100
28817659A6K27GA00003BB000100IWM   0000735900Y
28817659X6K27GA00003B000100
28817661ABK27GA000050S000100TWM   0000702400Y
28817665A2K27G600001EB002000CA    0000228700Y
28817668XAK27GA0000GU000100
28817668AAK27GA0000HDB000100SPY   0001425000Y
28817669ABK27GA000051B001000SSO   0000763700Y
28817669ABK27GA000052B000100UWM   0000542300Y
28817669XBK27GA000050000100
28817669ABK27GA000053S000100TWM   0000702200Y
28817679XBK27GA000052000100
28817679XBK27GA000053000100
28817681ABK27GA000054S000100TWM   0000702400Y
28817699ABK27GA000055B000100UWM   0000542300Y
28817699ABK27GA000056S000100TWM   0000702200Y
28817699XBK27GA000054000100
28817709XBK27GA000055000100
28817709XBK27GA000056000100
28817711A2K27G600001FB002000CAH   0000544300Y
28817711ABK27GA000057B000100UWM   0000542300Y
28817711ABK27GA000058S000100TWM   0000702200Y
28817719XBK27GA000057000100
28817719XBK27GA000058000100
28817720XAK27GA0000G4000500
28817720AAK27GA0000G4S000500SPY   0001425500Y
28817719A6K27GA00003CB000100IWM   0000735900Y
28817719X6K27GA00003C000100
28817722AAK27GA0000HEB001000SDS   0000547700Y
28817722XAK27GA0000HB001000
28817733X9K27G60000EP002000
28817733A9K27G60000EPB002000QQQQ  0000495400Y
28817735A2K27G600001GB002000CAT   0000814700Y
28817767A3K27G6000013B002000CCE   0000189100Y
28817773A2K27G600001HB002000BP    0000738300Y
28817798A2K27G600001IB002000BR    0000190800Y
28817821A2K27G600001JB002000BSX   0000118000Y
28817835A2K27G600001KB002000CA    0000227900Y
28817867X6K27GA000035000500
28817867A6K27GA00003DB000500IWM   0000736400Y
28817871ABK27GA000059B000100UWM   0000542300Y
28817871ABK27GA00005AS000100TWM   0000702200Y
28817872X6K27GA00003D000500
28817872A6K27GA00003DB000500IWM   0000736000Y
28817875XBK27GA000059000100
28817875XBK27GA00005A000100
28817875X6K27GA00003D000500
28817875A6K27GA00003DB000500IWM   0000736400Y
28817876A6K27GA00003EB000100IWM   0000735900Y
28817876X6K27GA00003E000100
28817877X6K27GA00003D000500
28817877A6K27GA00003DB000500IWM   0000736000Y
28817879ABK27GA00005BB000100UWM   0000542300Y
28817879ABK27GA00005CS000100TWM   0000702200Y
28817881XBK27GA00005C000100
28817881XBK27GA00005B000100
28817882X6K27GA00003D000500
28817882A6K27GA00003DB000500IWM   0000736400Y
28817885ABK27GA00005DS000100TWM   0000702400Y
28817886ABK27GA00005EB000100UWM   0000542300Y
28817886XBK27GA00005D000100
28817886ABK27GA00005FS000100TWM   0000702200Y
28817886X6K27GA00003D000500
28817886A6K27GA00003DB000500IWM   0000736000Y
28817889XBK27GA00005E000100
28817889XBK27GA00005F000100
28817889XAK27GA0000G4000500
28817889AAK27GA0000G4S000500SPY   0001425900Y
28817888X6K27GA00003D000500
28817888A6K27GA00003DB000500IWM   0000736400Y
28817891ABK27GA00005GS000100TWM   0000702400Y
28817892ABK27GA00005HB000100UWM   0000542300Y
28817892XBK27GA00005G000100
28817892ABK27GA00005IS000100TWM   0000702200Y
28817895XAK27GA0000HE001000
28817896AAK27GA0000HFB001000SDS   0000547600Y
28817896X6K27GA00003D000500
28817896A6K27GA00003DB000500IWM   0000736000Y
28817900XBK27GA00005H000100
28817900XBK27GA00005I000100
28817900A6K27GA00003FB000100IWM   0000735900Y
28817902ABK27GA00005JS000100TWM   0000702400Y
28817900X6K27GA00003F000100
28817902X6K27GA00003D000500
28817902A6K27GA00003DB000500IWM   0000736400Y
28817905ABK27GA00005KB000100UWM   0000542300Y
28817905XBK27GA00005J000100
28817905ABK27GA00005LS000100TWM   0000702200Y
28817906X6K27GA00003D000500
28817906A6K27GA00003DB000500IWM   0000736000Y
28817910XBK27GA00005K000100
28817910XBK27GA00005L000100
28817910A6K27GA00003GB000100IWM   0000735900Y
28817910X6K27GA00003G000100
28817912ABK27GA00005MS000100TWM   0000702400Y
28817915X6K27GA00003D000500
28817915A6K27GA00003DB000500IWM   0000736400Y
28817918ABK27GA00005NB000100UWM   0000542300Y
28817916X6K27GA00003D000500
28817916A6K27GA00003DB000500IWM   0000736000Y
28817918ABK27GA00005OS000100TWM   0000702200Y
28817918XBK27GA00005M000100
28817918X6K27GA00003D000500
28817918A6K27GA00003DB000500IWM   0000736400Y
28817920XBK27GA00005O000100
28817920XBK27GA00005N000100
28817922ABK27GA00005PB000100UWM   0000542300Y
28817922ABK27GA00005QS000100TWM   0000702200Y
28817923X6K27GA00003D000500
28817923A6K27GA00003DB000500IWM   0000736000Y
28817924X6K27GA00003D000500
28817924A6K27GA00003DB000500IWM   0000736400Y
28817926XBK27GA00005P000100
28817926XBK27GA00005Q000100
28817926X6K27GA00003D000500
28817926A6K27GA00003DB000500IWM   0000736000Y
28817928ABK27GA00005RS000100TWM   0000702400Y
28817931X6K27GA00003D000500
28817931A6K27GA00003DB000500IWM   0000736400Y
28817936X6K27GA00003D000500
28817936A6K27GA00003DB000500IWM   0000736000Y
28817948X6K27GA00003D000500
28817948A6K27GA00003DB000500IWM   0000736400Y
28817964XAK27GA0000FA000600
28817968X6K27GA00003D000500
28817968A6K27GA00003DB000500IWM   0000736000Y
28817969AAK27GA0000HGB001000SPY   0001419600Y
28817973X6K27GA00003D000500
28817973A6K27GA00003DB000500IWM   0000736400Y
28817976X6K27GA00003D000500
28817976A6K27GA00003DB000500IWM   0000736000Y
28817978X6K27GA00003D000500
28817978A6K27GA00003DB000500IWM   0000736400Y
28817988X6K27GA00003D000500
28817988A6K27GA00003DB000500IWM   0000736000Y
28817990A9K27G60000HGS001000QQQQ  0000496200Y
28817990A9K27G60000HHS001000QQQQ  0000496100Y
28817990A9K27G60000HIS000500QQQQ  0000496100Y
28817990A9K27G60000HJS000500QQQQ  0000496200Y
28817991X9K27G60000HA005000
28817993A9K27G60000HKB005000QQQQ  0000495300Y
28817993X6K27GA00003D000500
28817993A6K27GA00003DB000500IWM   0000736400Y
28817998X6K27GA00003D000500
28817998A6K27GA00003DB000500IWM   0000736000Y
28818008X6K27GA00003D000500
28818008A6K27GA00003DB000500IWM   0000736400Y
28818018X6K27GA00003D000500
28818018A6K27GA00003DB000500IWM   0000736000Y
28818038X6K27GA00003D000500
28818038A6K27GA00003DB000500IWM   0000736400Y
28818048X6K27GA00003D000500
28818048A6K27GA00003DB000500IWM   0000736000Y
28818058X6K27GA00003D000500
28818058A6K27GA00003DB000500IWM   0000736400Y
28818068X6K27GA00003D000500
28818068A6K27GA00003DB000500IWM   0000736000Y
28818078X6K27GA00003D000500
28818078A6K27GA00003DB000500IWM   0000736400Y
28818085X6K27GA00003D000500
28818085A6K27GA00003DB000500IWM   0000736000Y
28818087X6K27GA00003D000500
28818087A6K27GA00003DB000500IWM   0000736400Y
28818093X6K27GA00003D000500
28818093A6K27GA00003DB000500IWM   0000736000Y
28818095X6K27GA00003D000500
28818095A6K27GA00003DB000500IWM   0000736400Y
28818097X6K27GA00003D000500
28818097A6K27GA00003DB000500IWM   0000736000Y
28818103X6K27GA00003D000500
28818103A6K27GA00003DB000500IWM   0000736400Y
28818107X6K27GA00003D000500
28818107A6K27GA00003DB000500IWM   0000736000Y
28818111X6K27GA00003D000500
28818111A6K27GA00003DB000500IWM   0000736400Y
28818117X6K27GA00003D000500
28818117A6K27GA00003DB000500IWM   0000736000Y
28818123X6K27GA00003D000500
28818123A6K27GA00003DB000500IWM   0000736400Y
28818125X6K27GA00003D000500
28818125A6K27GA00003DB000500IWM   0000736000Y
28818127X6K27GA00003D000500
28818127A6K27GA00003DB000500IWM   0000736400Y
28818137X6K27GA00003D000500
28818137A6K27GA00003DB000500IWM   0000736000Y
28818139X6K27GA00003D000500
28818139A6K27GA00003DB000500IWM   0000736400Y
28818147X6K27GA00003D000500
28818147A6K27GA00003DB000500IWM   0000736000Y
28818150X6K27GA00003D000500
28818150A6K27GA00003DB000500IWM   0000736400Y
28818157X6K27GA00003D000500
28818157A6K27GA00003DB000500IWM   0000736000Y
28818163X6K27GA00003D000500
28818163A6K27GA00003DB000500IWM   0000736400Y
28818167X6K27GA00003D000500
28818167A6K27GA00003DB000500IWM   0000736000Y
28818184X1K27GA00000V000100
28818184A1K27GA00000VB000100AAPL  0001830100Y
28818374X7K27GA000017002000
28818375X4K27GA00003L000200
28818375A4K27GA00003LB000200DIA   0001298700Y
28818378A3K27G6000014B000100DDM   0000801100Y
28818400X7K27GA000018002000
28818399X6K27GA000033002000
28818409X7K27GA000012002000
28818421XCK27GA00001J002000
28818430AAK27GA0000HHB002000SHLD  0000630400Y
28818440A9K27G60000HLB000500QQQQ  0000495100Y
28818444ABK27GA00005SB002000UTX   0000028300Y
28818457AAK27GA0000HIB002000SEPR  0000177400Y
28818473X1K27GA00002J002000
28818488ABK27GA00005TB002000UTX   0000029100Y
28818501ACK27GA00001KB002000WYE   0000013200Y
28818508X6K27GA00003D000500
28818517A6K27GA00003HB000500IWM   0000736400Y
28818519XAK27GA0000FH000500
28818519AAK27GA0000FHS000500SPY   0001426000Y
28818519X4K27GA00004N000200
28818521ABK27GA00005UB000100UWM   0000542300Y
28818521XBK27GA00005R000100
28818521ABK27GA00005VS000100TWM   0000702200Y
28818521XAK27GA0000E5001000
28818521AAK27GA0000E5S001000SPY   0001426000Y
28818522A4K27GA00004YS000200DIA   0001299200Y
28818522XAK27GA0000EX000500
28818522AAK27GA0000EXB000500SPY   0001425400Y
28818522XAK27GA0000EN003000
28818522XAK27GA0000FW002000
28818522AAK27GA0000FWB002000SPY   0001425400Y
28818522XAK27GA0000ER001000
28818522XAK27GA0000EZ003000
28818522AAK27GA0000HJB000900SPY   0001425500Y
28818522XAK27GA0000ES000900
28818522AAK27GA0000HKB003000SPY   0001425400Y
28818522AAK27GA0000HLB003000SPY   0001425400Y
28818522XAK27GA0000F6000500
28818522AAK27GA0000F6S000500SPY   0001426000Y
28818522AAK27GA0000HMB001000SPY   0001425300Y
28818522XAK27GA0000G0002000
28818522AAK27GA0000HNS000100SH    0000618900Y
28818523XBK27GA00001R001000
28818523ABK27GA00005WB001000SSO   0000764200Y
28818523XAK27GA0000EB001000
28818523AAK27GA0000EBB001000SPY   0001425500Y
28818522X6K27GA00003H000500
28818522A6K27GA00003HB000500IWM   0000736000Y
28818524AAK27GA0000HOB002000SHPGY 0000516300Y
28818524ABK27GA00005XS001000SSO   0000765300Y
28818524XBK27GA00005W001000
28818524ABK27GA00005YB001000SSO   0000764200Y
28818525XBK27GA00005X001000
28818524AAK27GA0000HPS001000SPY   0001426000Y
28818525ABK27GA00005ZS001000SSO   0000765200Y
28818525XBK27GA00005Y001000
28818526XBK27GA00005U000100
28818526XBK27GA00005V000100
28818526AAK27GA0000HQB001000SDS   0000547500Y
28818526ABK27GA000060B001000SSO   0000764100Y
28818526AAK27GA0000HRB001000SDS   0000547400Y
28818526XAK27GA0000GO001000
28818527ABK27GA000061B001000SSO   0000764200Y
28818527XBK27GA00001S001000
28818526X6K27GA00003H000500
28818526A6K27GA00003HB000500IWM   0000736400Y
28818528ABK27GA000062S000100TWM   0000702400Y
28818527X6K27GA00003H000500
28818527A6K27GA00003HB000500IWM   0000736000Y
28818529ABK27GA000063B000100UWM   0000542300Y
28818529ABK27GA000064S000100TWM   0000702200Y
28818529XBK27GA000062000100
28818531XBK27GA000063000100
28818531XBK27GA000064000100
28818533ABK27GA000065S000100TWM   0000702400Y
28818534X6K27GA00003H000500
28818534A6K27GA00003HB000500IWM   0000736400Y
28818535A6K27GA00003IB002000IWM   0000736300Y
28818537ABK27GA000066B000100UWM   0000542300Y
28818537XBK27GA000065000100
28818537ABK27GA000067S000100TWM   0000702200Y
28818537A1K27GA00002KB002000ABT   0000020100Y
28818541XBK27GA000061001000
28818541ABK27GA000061B001000SSO   0000764300Y
28818545XAK27GA0000F6000500
28818545AAK27GA0000F6S000500SPY   0001425600Y
28818546XAK27GA0000EB001000
28818546AAK27GA0000EBB001000SPY   0001425100Y
28818546XAK27GA0000HL003000
28818546XAK27GA0000HK003000
28818547X9K27G60000HK005000
28818547X9K27G60000HD005000
28818547A9K27G60000HMB005000QQQQ  0000495700Y
28818547A9K27G60000HNB005000QQQQ  0000495700Y
28818546XAK27GA0000HM001000
28818547X9K27G60000G1002000
28818547A9K27G60000G1S002000QQQQ  0000496300Y
28818548X9K27G60000EP002000
28818548A9K27G60000EPB002000QQQQ  0000495700Y
28818547AAK27GA0000HSB003000SPY   0001424700Y
28818547AAK27GA0000HTB003000SPY   0001424700Y
28818548AAK27GA0000HUB001000SPY   0001425200Y
28818549XBK27GA000051001000
28818549ABK27GA000068B001000SSO   0000763800Y
28818554A1K27GA00002LB002000ABT   0000019300Y
28818564X4K27GA00004U000100
28818565X3K27G6000011000100
28818569AAK27GA0000HVB002000SLAB  0000352200Y
28818573X9K27G60000HM005000
28818574X9K27G60000HN005000
28818574X9K27G60000G1002000
28818574A9K27G60000G1S002000QQQQ  0000495800Y
28818575A9K27G60000HOB005000QQQQ  0000495300Y
28818575A9K27G60000HPB005000QQQQ  0000495300Y
28818579A3K27G6000015B002000CCL   0000380800Y
28818595X1K27GA00002I002000
28818599XAK27GA0000FW002000
28818602X9K27G60000HO005000
28818602X9K27G60000HP005000
28818603A9K27G60000HQB005000QQQQ  0000495700Y
28818603A9K27G60000HRB005000QQQQ  0000495700Y
28818614XAK27GA0000HU001000
28818619A3K27G6000016B002000CCU   0000337000Y
28818647X9K27G60000HQ005000
28818649A9K27G60000HSB005000QQQQ  0000495300Y
28818657A3K27G6000017B002000CFC   0000038000Y
28818671AAK27GA0000HWB002000SNDK  0000215000Y
28818680A2K27G600001LB002000CAH   0000543500Y
28818696A3K27G6000018B002000CHS   0000061700Y
28818709ABK27GA000069B002000TASR  0000063800Y
28818712A2K27G600001MB002000CAT   0000814000Y
28818766A3K27G6000019B002000CCE   0000188300Y
28818768A3K27G600001AB002000CL    0000692900Y
28818786A3K27G600001BB002000CCL   0000380000Y
28818895X9K27G60000HR005000
28818995A9K27G60000HTB005000QQQQ  0000495300Y
28819068XAK27GA0000E5001000
28819068AAK27GA0000E5S001000SPY   0001425600Y
28819068XAK27GA0000GT003000
28819069XAK27GA0000FH000500
28819069AAK27GA0000FHS000500SPY   0001425600Y
28819069XAK27GA0000FD000500
28819069AAK27GA0000FDB000500SPY   0001425000Y
28819069XAK27GA0000EX000500
28819069AAK27GA0000EXB000500SPY   0001425000Y
28819069X4K27GA00004Y000200
28819070X4K27GA00003L000200
28819070A4K27GA00003LB000200DIA   0001298400Y
28819070AAK27GA0000HXS003000SPY   0001425600Y
28819070XAK27GA0000GS003000
28819070AAK27GA0000HYS003000SPY   0001425600Y
28819070XAK27GA0000HP001000
28819071AAK27GA0000HZS001000SPY   0001425600Y
28819072XAK27GA0000HJ000900
28819072XBK27GA000060001000
28819074A4K27GA00004ZS000200DIA   0001298900Y
28819075AAK27GA0000I0B000400SPY   0001425100Y
28819078X6K27GA00003H000500
28819078A6K27GA00003HB000500IWM   0000736000Y
28819079X6K27GA00003I002000
28819085X3K27G6000014000100
28819084X6K27GA00003H000500
28819084A6K27GA00003HB000500IWM   0000736400Y
28819085X6K27GA00003H000500
28819085A6K27GA00003HB000500IWM   0000736000Y
28819088X6K27GA00003H000500
28819088A6K27GA00003HB000500IWM   0000736400Y
28819096XAK27GA0000HN000100
28819095X6K27GA00003H000500
28819095A6K27GA00003HB000500IWM   0000736000Y
28819097XBK27GA000061001000
28819097ABK27GA00006AB001000SSO   0000764000Y
28819099ABK27GA00006BB001000SSO   0000764200Y
28819098X6K27GA00003H000500
28819098A6K27GA00003HB000500IWM   0000736400Y
28819108X6K27GA00003H000500
28819108A6K27GA00003HB000500IWM   0000736000Y
28819110X6K27GA00003H000500
28819110A6K27GA00003HB000500IWM   0000736400Y
28819111XBK27GA000066000100
28819111XBK27GA000067000100
28819113ABK27GA00006CS000100TWM   0000702200Y
28819113ABK27GA00006DB000100UWM   0000542300Y
28819115AAK27GA0000I1S000100SH    0000618900Y
28819113X6K27GA00003H000500
28819113A6K27GA00003HB000500IWM   0000736000Y
28819115ABK27GA00006EB001000SSO   0000764300Y
28819115XBK27GA00006B001000
28819116X6K27GA00003H000500
28819116A6K27GA00003HB000500IWM   0000736400Y
28819118XBK27GA00006D000100
28819118XBK27GA00006C000100
28819123XAK27GA0000HY003000
28819124XAK27GA0000HX003000
28819125AAK27GA0000I2S003000SPY   0001426200Y
28819125AAK27GA0000I3S003000SPY   0001426200Y
28819128ABK27GA00006FS000100TWM   0000702200Y
28819128ABK27GA00006GB000100UWM   0000542300Y
28819127X4K27GA00003L000200
28819127A4K27GA00003LB000200DIA   0001298700Y
28819130A3K27G600001CB000100DDM   0000801100Y
28819133XAK27GA0000I0000400
28819133AAK27GA0000I4B000400SPY   0001425500Y
28819134XAK27GA0000EX000500
28819134AAK27GA0000EXB000500SPY   0001425400Y
28819138A6K27GA00003JB002000IWM   0000736300Y
28819147XAK27GA0000EX000500
28819147AAK27GA0000EXB000500SPY   0001425000Y
28819349X3K27G6000010002000
28819397XAK27GA0000FD000500
28819397AAK27GA0000FDB000500SPY   0001425400Y
28819398XBK27GA00006A001000
28819398ABK27GA00006HB001000SSO   0000764100Y
28819404XAK27GA0000HH002000
28819420A7K27GA000019B002000LMT   0000050300Y
28819420XAK27GA0000E5001000
28819420AAK27GA0000E5S001000SPY   0001426000Y
28819420A7K27GA00001AB002000LMT   0000051100Y
28819420XAK27GA0000HZ001000
28819425AAK27GA0000I5S001000SPY   0001426000Y
28819428A6K27GA00003KB002000IMCL  0000298600Y
28819437XBK27GA00005S002000
28819470XCK27GA00001K002000
28819484XAK27GA0000GE001000
28819486AAK27GA0000I6S001000SPY   0001425800Y
28819490X1K27GA00002L002000
28819495XBK27GA00005T002000
28819498XAK27GA0000I6001000
28819500AAK27GA0000I7S001000SPY   0001425900Y
28819511A7K27GA00001BB002000LPNT  0000174500Y
28819517XAK27GA0000EB001000
28819517AAK27GA0000EBB001000SPY   0001425500Y
28819517XAK27GA0000HS003000
28819517XAK27GA0000HT003000
28819518X9K27G60000G1002000
28819518A9K27G60000G1S002000QQQQ  0000496300Y
28819517XAK27GA0000F6000500
28819517AAK27GA0000F6S000500SPY   0001426000Y
28819517XAK27GA0000EX000500
28819517AAK27GA0000EXB000500SPY   0001425400Y
28819517AAK27GA0000I8B002000SPY   0001425500Y
28819517X4K27GA00004Z000200
28819518X4K27GA00003Q000200
28819518A4K27GA00003QB000200DIA   0001298800Y
28819518XAK27GA0000FH000500
28819518AAK27GA0000FHS000500SPY   0001426000Y
28819518XAK27GA0000FG000500
28819518AAK27GA0000FGB000500SPY   0001425500Y
28819518XAK27GA0000FJ000500
28819518AAK27GA0000I9B003000SPY   0001425400Y
28819518AAK27GA0000IAB003000SPY   0001425400Y
28819519X4K27GA00004D000200
28819519A4K27GA00004DS000200DIA   0001299200Y
28819519AAK27GA0000IBS000500SPY   0001426100Y
28819520A4K27GA000050S000100DOG   0000598300Y
28819520X4K27GA00003I000100
28819520A4K27GA000051S000100DXD   0000500100Y
28819520A3K27G600001DB000100DDM   0000801200Y
28819520X3K27G600000D000100
28819519ACK27GA00001LB002000WYE   0000015200Y
28819521XAK27GA0000F7000500
28819521AAK27GA0000F7B000500SPY   0001425500Y
28819522XAK27GA0000E6001000
28819522AAK27GA0000E6S001000SPY   0001426100Y
28819524A4K27GA000052S000200DIA   0001299300Y
28819525XAK27GA0000HF001000
28819525XBK27GA00005Z001000
28819527XAK27GA0000HR001000
28819527AAK27GA0000ICB001000SDS   0000547500Y
28819527ABK27GA00006IS001000SSO   0000765300Y
28819529AAK27GA0000IDB001000SDS   0000547400Y
28819574X1K27GA00002K002000
28819578X2K27G600000S002000
28819579A1K27GA00002MB002000AFL   0000027400Y
28819583ABK27GA00006JB002000TECD  0000349200Y
28819610A1K27GA00002NB002000AFL   0000028200Y
28819655X2K27G600000O002000
28819675ABK27GA00006KB002000TEVA  0000448200Y
28819688A2K27G600001NB002000BBT   0000010100Y
28819734A3K27G600001EB002000CNX   0000930500Y
28819749A3K27G600001FB002000CCU   0000336200Y
28819774X4K27GA000052000200
28819776ABK27GA00006LB002000THQI  0000175200Y
28819809A3K27G600001GB002000COH   0000011000Y
28819816A3K27G600001HB002000CFC   0000037200Y
28819871A3K27G600001IB002000CHS   0000060900Y
28819890A3K27G600001JB002000CL    0000692100Y
28819895A3K27G600001KB002000COP   0000916000Y
28819927A3K27G600001LB002000CTX   0000218200Y
28820058XAK27GA0000I8002000
28820059X9K27G60000G1002000
28820059A9K27G60000G1S002000QQQQ  0000495800Y
28820059XAK27GA0000EB001000
28820059AAK27GA0000EBB001000SPY   0001425100Y
28820059XAK27GA0000IB000500
28820059AAK27GA0000IBS000500SPY   0001425600Y
28820059XAK27GA0000FG000500
28820059AAK27GA0000FGB000500SPY   0001425100Y
28820059XAK27GA0000E6001000
28820059AAK27GA0000E6S001000SPY   0001425700Y
28820059XAK27GA0000I4000400
28820059XAK27GA0000F6000500
28820059AAK27GA0000F6S000500SPY   0001425600Y
28820059XAK27GA0000F7000500
28820059AAK27GA0000F7B000500SPY   0001425100Y
28820059A4K27GA000053S000200DIA   0001298900Y
28820059X4K27GA00003Q000200
28820059A4K27GA00003QB000200DIA   0001298500Y
28820059XAK27GA0000FH000500
28820059AAK27GA0000FHS000500SPY   0001425700Y
28820059XAK27GA0000EX000500
28820059AAK27GA0000EXB000500SPY   0001425000Y
28820061X9K27G60000H6005000
28820061X9K27G60000HS005000
28820061X9K27G60000HT005000
28820060AAK27GA0000IEB001000SDS   0000547600Y
28820061A9K27G60000HUB005000QQQQ  0000495700Y
28820061A9K27G60000HVB005000QQQQ  0000495700Y
28820062A9K27G60000HWS005000QQQQ  0000496200Y
28820062X9K27G60000G1002000
28820062A9K27G60000G1S002000QQQQ  0000496300Y
28820062AAK27GA0000IFB001000SPY   0001425100Y
28820062XAK27GA0000I5001000
28820062AAK27GA0000IGS001000SPY   0001425600Y
28820061ABK27GA00006MS001000SSO   0000765200Y
28820061XBK27GA00006I001000
28820064X9K27G60000EQ002000
28820064A9K27G60000EQS002000QQQQ  0000496100Y
28820064X4K27GA00004D000200
28820064X4K27GA000050000100
28820064X4K27GA000051000100
28820065X3K27G600001D000100
28820065XBK27GA00006H001000
28820073A4K27GA000054S000200DIA   0001299000Y
28820078X9K27G60000H7002000
28820079X9K27G60000H3005000
28820080X9K27G60000H4001000
28820081XAK27GA0000IB000500
28820081AAK27GA0000IBS000500SPY   0001426000Y
28820081XAK27GA0000I9003000
28820081XAK27GA0000IA003000
28820082AAK27GA0000IHS001000SPY   0001425800Y
28820082XAK27GA0000I7001000
28820083AAK27GA0000IIB003000SPY   0001424700Y
28820083AAK27GA0000IJB003000SPY   0001424700Y
28820083A9K27G60000HXS005000QQQQ  0000496200Y
28820164XAK27GA0000F6000500
28820164AAK27GA0000F6S000500SPY   0001426000Y
28820165XAK27GA0000EX000500
28820165AAK27GA0000EXB000500SPY   0001425400Y
28820225X9K27G60000HX005000
28820266A9K27G60000HYS005000QQQQ  0000495800Y
28820340A3K27G600001MB002000CELG  0000459800Y
28820409X7K27GA000019002000
28820412X7K27GA00001A002000
28820419XCK27GA00001L002000
28820424X1K27GA00002M002000
28820432ABK27GA00006NB002000UTX   0000032300Y
28820436X1K27GA00002N002000
28820441AAK27GA0000IKB002000SHLD  0000635500Y
28820448ABK27GA00006OB002000UTX   0000033100Y
28820462ACK27GA00001MB002000WYE   0000015600Y
28820470ABK27GA00006PB002000UNTD  0000098500Y
28820482PCK27GA00001NB000100ZVZZT 0020000000000I000HV1Z0
28820483PCK27GA00001NB000100ZVZZT 0020002500000I000HV1Z1
28820492A1K27GA00002OB002000ABT   0000023200Y
28820506A1K27GA00002PB002000ABT   0000022300Y
28820508ABK27GA00006QB002000URBN  0000290200Y
28820555A2K27G600001OB002000AXP   0000395600Y
28820572ABK27GA00006RB002000UTSI  0000035300Y
28820576X6K27GA00002S002000
28820591X6K27GA000028000500
28820591A6K27GA000028S000500IWM   0000737000Y
28820599XBK27GA00001Q000100
28820599XBK27GA000021000100
28820597A6K27GA00003LS000100IWM   0000737200Y
28820601A2K27G600001PB002000AXP   0000394800Y
28820600ABK27GA00006SS000100UWM   0000543400Y
28820599A6K27GA00003MS000100IWM   0000737100Y
28820599X6K27GA00003M000100
28820601ABK27GA00006TB000100TWM   0000700900Y
28820601A6K27GA00003NS000100IWM   0000737100Y
28820601A6K27GA00003OS002000IWM   0000737000Y
28820604ACK27GA00001OB002000VECO  0000169200Y
28820605X6K27GA00003N000100
28820611A2K27G600001QB002000BBT   0000010200Y
28820625A3K27G600001NB002000CVC   0000231000Y
28820654A3K27G600001OB002000CVS   0000015900Y
28820659A3K27G600001PB002000CNX   0000929700Y
28820678A3K27G600001QB002000DD    0000453300Y
28820688A3K27G600001RB002000COH   0000011100Y
28820693XAK27GA0000IG001000
28820693XAK27GA0000IF001000
28820694AAK27GA0000ILB001000SPY   0001425500Y
28820695AAK27GA0000IMS001000SPY   0001426000Y
28820695ABK27GA00006UB001000SSO   0000764100Y
28820707A3K27G600001SB002000DE    0000791700Y
28820710A3K27G600001TB002000COP   0000915200Y
28820728XAK27GA0000IH001000
28820730AAK27GA0000INS001000SPY   0001425900Y
28820737A3K27G600001UB002000CTX   0000217400Y
28820743XAK27GA0000IN001000
28820743AAK27GA0000IOS001000SPY   0001425800Y
28820745X4K27GA00003B000100
28820745X4K27GA00004V000100
28820749A4K27GA000055B000100DRYS  0001066500Y
28820749A4K27GA000056B000100DRYS  0001066500Y
28820774A3K27G600001VB002000CVC   0000230200Y
28821094A6K27GA00003PS002000IWM   0000736800Y
28821096X5K27GA00001C000100
28821098A5K27GA00001FB000100FXP   0000655100Y
28821104A5K27GA00001GS000100FXP   0000657100Y
28821142XAK27GA0000IJ003000
28821144AAK27GA0000IPB003000SPY   0001425400Y
28821144AAK27GA0000IQB003000SPY   0001425400Y
28821144XAK27GA0000II003000
28821155XBK27GA00006M001000
28821155XAK27GA0000IE001000
28821156XAK27GA0000ID001000
28821157ABK27GA00006VS001000SSO   0000765300Y
28821158AAK27GA0000IRB001000SDS   0000547400Y
28821163XAK27GA0000IP003000
28821163XAK27GA0000IQ003000
28821164XAK27GA0000IO001000
28821164AAK27GA0000ISS001000SPY   0001425700Y
28821165AAK27GA0000ITB003000SPY   0001424700Y
28821166AAK27GA0000IUB003000SPY   0001424700Y
28821166X6K27GA00003P002000
28821173XAK27GA0000IS001000
28821174AAK27GA0000IVS001000SPY   0001425700Y
28821176AAK27GA0000IWB001000SDS   0000547600Y
28821182A6K27GA00003QS002000IWM   0000736800Y
28821185XBK27GA00006V001000
28821185ABK27GA00006WS001000SSO   0000765200Y
28821199XAK27GA0000IV001000
28821201AAK27GA0000IXS001000SPY   0001425800Y
28821204X9K27G60000G1002000
28821204A9K27G60000G1S002000QQQQ  0000495800Y
28821204AAK27GA0000IYS001000SPY   0001425700Y
28821274X6K27GA000028000500
28821274A6K27GA000028S000500IWM   0000736600Y
28821277ABK27GA00006XS000100UWM   0000543200Y
28821277ABK27GA00006YB000100TWM   0000701200Y
28821357X6K27GA00003K002000
28821369XAK27GA0000IK002000
28821418XBK27GA00006N002000
28821420A9K27G60000HZB002000PDLI  0000010100Y
28821420A7K27GA00001CB002000LMT   0000057100Y
28821443XCK27GA00001M002000
28821449XBK27GA00006O002000
28821451X1K27GA00002P002000
28821499ACK27GA00001PB002000WYE   0000017700Y
28821540ACK27GA00001QB002000VRSN  0000381200Y
28821542X1K27GA00002O002000
28821557X2K27G6000012002000
28821590A1K27GA00002QB002000AFL   0000031900Y
28821602X2K27G600001N002000
28821617X2K27G600000X002000
28821622A7K27GA00001DB002000LMT   0000056300Y
28821624X3K27G600001G002000
28821637X3K27G600001O002000
28821657A3K27G600001WB002000DHI   0000138600Y
28821664A1K27GA00002RB002000AFL   0000031100Y
28821681X4K27GA00003L000200
28821681A4K27GA00003LB000200DIA   0001298400Y
28821685A3K27G600001XB002000DHR   0000758900Y
28821718A3K27G600001YB002000CVS   0000016300Y
28821718A4K27GA000057B002000DIS   0000327000Y
28821733A3K27G600001ZB002000DD    0000452600Y
28821744A4K27GA000058B002000DOW   0000397200Y
28821756A3K27G6000020B002000DE    0000790900Y
28821773A4K27GA000059B002000DOX   0000302400Y
28821782A3K27G6000021B002000DHI   0000137800Y
28821814A3K27G6000022B002000DHR   0000758100Y
28822021X4K27GA00003L000200
28822021A4K27GA00003LB000200DIA   0001298700Y
28822025A6K27GA00003RB000100IYF   0000856600Y
28822025X6K27GA00001Y000100
28822027ABK27GA00006ZB000100UYG   0000320200Y
28822271X9K27G60000HU005000
28822271X9K27G60000HV005000
28822271X9K27G60000HW005000
28822271A9K27G60000I0S005000QQQQ  0000495800Y
28822271A9K27G60000I1S002000QQQQ  0000495800Y
28822272X9K27G60000EQ002000
28822272A9K27G60000EQS002000QQQQ  0000495800Y
28822272A9K27G60000I2B005000QQQQ  0000495300Y
28822273A9K27G60000I3B005000QQQQ  0000495300Y
28822366X7K27GA00001C002000
28822369X7K27GA00001D002000
28822396A6K27GA00003SB002000IMCL  0000301900Y
28822414ABK27GA000070B002000UTX   0000036300Y
28822424ABK27GA000071B002000UTX   0000037100Y
28822427AAK27GA0000IZB002000SHLD  0000640600Y
28822447A3K27G6000023B002000CTSH  0000010000Y
28822467XCK27GA00001P002000
28822471ACK27GA00001RB002000WYE   0000018100Y
28822500A1K27GA00002SB002000ABT   0000026300Y
28822504A1K27GA00002TB002000ABT   0000025400Y
28822514X1K27GA00002R002000
28822521X1K27GA00002Q002000
28822524X4K27GA00003L000200
28822524A4K27GA00003LB000200DIA   0001298400Y
28822525X2K27G600001Q002000
28822524XAK27GA0000E5001000
28822524AAK27GA0000E5S001000SPY   0001425600Y
28822529XAK27GA0000F6000500
28822529AAK27GA0000F6S000500SPY   0001425600Y
28822539X3K27G600001R002000
28822548X3K27G600001Y002000
28822572A2K27G600001RB002000BBT   0000012900Y
28822589A2K27G600001SB002000BDX   0000754100Y
28822613A2K27G600001TB002000BDX   0000754900Y
28822613A4K27GA00005AB002000DIS   0000326300Y
28822638A4K27GA00005BB002000DOW   0000396400Y
28822643A3K27G6000024B002000COH   0000013900Y
28822660A4K27GA00005CB002000DOX   0000301600Y
28822669A3K27G6000025B002000CVS   0000018300Y
28822763X6K27GA000028000500
28822763A6K27GA000028S000500IWM   0000737000Y
28822764X6K27GA00003Q002000
28822769XBK27GA00006Y000100
28822769XBK27GA00006X000100
28822769A6K27GA00003TS000100IWM   0000737100Y
28822775X6K27GA00003T000100
28823203A5K27GA00001HB000100FSLR  0002930500Y
28823357XAK27GA0000IZ002000
28823388X4K27GA000055000100
28823388A4K27GA00005DB000100DRYS  0001065100Y
28823398X7K27GA00001B002000
28823399XBK27GA000070002000
28823411XBK27GA000071002000
28823416XCK27GA00001R002000
28823432X1K27GA00002S002000
28823434X1K27GA00002T002000
28823442X3K27G6000025002000
28823460A7K27GA00001EB002000LMT   0000063100Y
28823485ACK27GA00001SB002000WYE   0000020100Y
28823487A7K27GA00001FB002000LMT   0000062300Y
28823506A1K27GA00002UB002000AFL   0000034800Y
28823520A1K27GA00002VB002000AFL   0000035600Y
28823527A2K27G600001UB002000BBT   0000013100Y
28823529A4K27GA00005EB002000DUK   0000161900Y
28823561A4K27GA00005FB002000EAT   0000197300Y
28823567A3K27G6000026B002000COH   0000014100Y
28823578X4K27GA000056000100
28823579A4K27GA00005GB000100DRYS  0001065100Y
28823582A4K27GA00005HB002000EDS   0000226000Y
28823589X4K27GA00005G000100
28823597A4K27GA00005IB002000EIX   0000022000Y
28823599X4K27GA00005D000100
28823599A4K27GA00005JB000100DRYS  0001067100Y
28823609A4K27GA00005KB000100DRYS  0001065100Y
28823609A4K27GA00005LB002000EK    0000145400Y
28823619X4K27GA00005K000100
28823629A4K27GA00005MB000100DRYS  0001067100Y
28823638X4K27GA00005M000100
28823639A4K27GA00005NB000100DRYS  0001065100Y
28823648A3K27G6000027B002000CVS   0000018600Y
28823649X4K27GA00005N000100
28823659A4K27GA00005OB000100DRYS  0001067100Y
28823670A4K27GA00005PB002000DUK   0000161100Y
28823680A4K27GA00005QB002000EAT   0000196500Y
28823692A4K27GA00005RB002000EDS   0000225200Y
28823719X4K27GA00005O000100
28823719A4K27GA00005SB000100DRYS  0001065100Y
28823719X4K27GA00005J000100
28823719A4K27GA00005TB000100DRYS  0001065100Y
28824349X6K27GA00003S002000
28824392X5K27GA000014002000
28824395AAK27GA0000J0B002000SHLD  0000645700Y
28824395X7K27GA00001F002000
28824397X7K27GA00001E002000
28824403X1K27GA00002U002000
28824402XCK27GA00001S002000
28824415X3K27G6000027002000
28824447A7K27GA00001GB002000LPNT  0000177900Y
28824450X1K27GA00002V002000
28824463X2K27G600001R002000
28824487ABK27GA000072B002000UTX   0000040300Y
28824496X3K27G6000024002000
28824512X4K27GA00005I002000
28824522ACK27GA00001TB002000WYE   0000020500Y
28824542ABK27GA000073B002000UTX   0000041100Y
28824548A1K27GA00002WB002000ABT   0000028500Y
28824568A1K27GA00002XB002000ABT   0000029300Y
28824608A4K27GA00005UB002000EIX   0000022600Y
28824622A3K27G6000028B002000CVS   0000020600Y
28824631A4K27GA00005VB002000EK    0000144700Y
28824643A4K27GA00005WB002000EL    0000451200Y
28824654A4K27GA00005XB002000EL    0000450400Y
28824669A4K27GA00005YB002000ELN   0000225900Y
28824701A4K27GA00005ZB002000ELX   0000128700Y
28824716A4K27GA000060B002000EMC   0000167000Y
28824769XAK27GA0000IM001000
28824769X4K27GA00004X000047
28824770AAK27GA0000J1S001000SPY   0001425600Y
28824772XAK27GA0000GI002000
28824774X3K27G600001C000100
28824774A4K27GA000061S000047DIA   0001298800Y
28824785X6K27GA000028000500
28824785A6K27GA000028S000500IWM   0000736600Y
28824788ABK27GA000074S000100UWM   0000543200Y
28824786A6K27GA00003US002000IWM   0000736800Y
28824788ABK27GA000075B000100TWM   0000701200Y
28824789X9K27G60000F4003200
28824789A9K27G60000F4S003200QQQQ  0000495800Y
28824795XAK27GA0000E4001000
28824795AAK27GA0000E4B001000SPY   0001425000Y
28824795XAK27GA0000I2003000
28824795XAK27GA0000FD000500
28824795AAK27GA0000FDB000500SPY   0001425000Y
28824795XAK27GA0000IB000500
28824795AAK27GA0000IBS000500SPY   0001425600Y
28824796X8K27G600000M000100
28824795XAK27GA0000EX000500
28824795AAK27GA0000EXB000500SPY   0001425000Y
28824795XAK27GA0000I3003000
28824795AAK27GA0000J2S002000SPY   0001425600Y
28824795XAK27GA0000IL001000
28824795XAK27GA0000G2002000
28824795X4K27GA00003Q000200
28824795X4K27GA00003H000200
28824795A4K27GA00003HB000200DIA   0001298300Y
28824795AAK27GA0000J3S003000SPY   0001425600Y
28824795AAK27GA0000J4S003000SPY   0001425600Y
28824796XAK27GA0000G4000500
28824796XBK27GA00006U001000
28824796AAK27GA0000J5S000500SPY   0001425600Y
28824798A8K27G600000UB000100MVV   0000806000Y
28824797AAK27GA0000J6B001000SPY   0001425100Y
28824800A8K27G600000VB000500MZZ   0000491700Y
28824800A8K27G600000WS000100MVV   0000809100Y
28824803XAK27GA0000J5000500
28824803AAK27GA0000J5S000500SPY   0001425900Y
28824804A4K27GA000062B000200DIA   0001298200Y
28824804A4K27GA000063B000100DXD   0000499500Y
28824805A3K27G6000029S000100DDM   0000802500Y
28824804XAK27GA0000IY001000
28824805XBK27GA00006E001000
28824805ABK27GA000076B001000SSO   0000764000Y
28824805AAK27GA0000J7B001000SPY   0001425100Y
28824805XAK27GA0000GW001000
28824806XAK27GA0000I1000100
28824806AAK27GA0000J8S001000SPY   0001425800Y
28824807ABK27GA000077B001000SSO   0000764200Y
28824807AAK27GA0000J9B001000SPY   0001425100Y
28824807AAK27GA0000JAS000100SH    0000618900Y
28824809XAK27GA0000F2000500
28824809AAK27GA0000F2B000500SPY   0001424900Y
28824809XAK27GA0000FX003000
28824809X9K27G60000G0002000
28824809A9K27G60000G0B002000QQQQ  0000495100Y
28824809XAK27GA0000FE000500
28824809AAK27GA0000FEB000500SPY   0001424900Y
28824809XAK27GA0000FZ003000
28824809XAK27GA0000E7001000
28824809AAK27GA0000E7B001000SPY   0001424900Y
28824809XAK27GA0000GM000900
28824809X4K27GA00003L000200
28824809A4K27GA00003LB000200DIA   0001298100Y
28824810XAK27GA0000J5000500
28824810AAK27GA0000J5S000500SPY   0001425600Y
28824810XAK27GA0000JA000100
28824810XAK27GA0000F4000500
28824810AAK27GA0000F4S000500SPY   0001425600Y
28824810XAK27GA0000F5000500
28824810AAK27GA0000F5B000500SPY   0001424800Y
28824811XBK27GA000076001000
28824810AAK27GA0000JBB003000SPY   0001424500Y
28824811AAK27GA0000JCB003000SPY   0001424500Y
28824811AAK27GA0000JDB001000SPY   0001425000Y
28824811XAK27GA0000J9001000
28824811AAK27GA0000JES001000SPY   0001425600Y
28824811XAK27GA0000GN001000
28824812XAK27GA0000F4000500
28824813AAK27GA0000JFS001000SPY   0001425600Y
28824813XAK27GA0000JE001000
28824813XAK27GA0000F5000500
28824813AAK27GA0000F5B000500SPY   0001425200Y
28824813AAK27GA0000JGS000100SH    0000618900Y
28824813XAK27GA0000JG000100
28824813XAK27GA0000E7001000
28824813AAK27GA0000E7B001000SPY   0001425300Y
28824814X4K27GA00004J000100
28824814X4K27GA00004K000100
28824814X3K27G600000W000100
28824814XAK27GA0000F5000500
28824814AAK27GA0000F5B000500SPY   0001424800Y
28824815AAK27GA0000JHS001000SPY   0001425600Y
28824814X6K27GA00003H000500
28824814A6K27GA00003HB000500IWM   0000736000Y
28824815XAK27GA0000E7001000
28824815AAK27GA0000E7B001000SPY   0001424900Y
28824814X6K27GA00003J002000
28824816XAK27GA0000FH000500
28824816XAK27GA0000IB000500
28824816XAK27GA0000FC000500
28824816XAK27GA0000FF000500
28824816ABK27GA000078B001000SSO   0000763900Y
28824816XBK27GA000077001000
28824817XAK27GA0000F5000500
28824817AAK27GA0000F5B000500SPY   0001425200Y
28824818ABK27GA000079B001000SSO   0000764100Y
28824818XAK27GA0000E7001000
28824818AAK27GA0000E7B001000SPY   0001425300Y
28824817X6K27GA00003H000500
28824817A6K27GA00003HB000500IWM   0000736400Y
28824819XBK27GA00006G000100
28824819XBK27GA00006F000100
28824820XAK27GA0000E7001000
28824820AAK27GA0000E7B001000SPY   0001424900Y
28824820X6K27GA00003H000500
28824820A6K27GA00003HB000500IWM   0000736000Y
28824822ABK27GA00007AS000100TWM   0000702200Y
28824822ABK27GA00007BB000100UWM   0000542300Y
28824822XAK27GA0000E7001000
28824822AAK27GA0000E7B001000SPY   0001425300Y
28824823XBK27GA00007B000100
28824823XBK27GA00007A000100
28824825ABK27GA00007CS000100TWM   0000702400Y
28824826X6K27GA00003H000500
28824826A6K27GA00003HB000500IWM   0000736400Y
28824828ABK27GA00007DB000100UWM   0000542300Y
28824828XBK27GA00007C000100
28824828ABK27GA00007ES000100TWM   0000702200Y
28824829X6K27GA00003H000500
28824829A6K27GA00003HB000500IWM   0000736000Y
28824834XAK27GA0000J7001000
28824834AAK27GA0000JIB001000SPY   0001425000Y
28824833X6K27GA00003H000500
28824833A6K27GA00003HB000500IWM   0000736400Y
28824834XBK27GA00007D000100
28824835XBK27GA00007E000100
28824834XAK27GA0000E7001000
28824834AAK27GA0000E7B001000SPY   0001424900Y
28824834X6K27GA00003H000500
28824834A6K27GA00003HB000500IWM   0000736000Y
28824835AAK27GA0000JJB001000SPY   0001425100Y
28824836XAK27GA0000E7001000
28824836AAK27GA0000E7B001000SPY   0001425300Y
28824836ABK27GA00007FB000100UWM   0000542300Y
28824836ABK27GA00007GS000100TWM   0000702200Y
28824838XBK27GA00007F000100
28824838XBK27GA00007G000100
28824838XAK27GA0000E7001000
28824838AAK27GA0000E7B001000SPY   0001424900Y
28824840ABK27GA00007HB000100UWM   0000542300Y
28824839A6K27GA00003VB000100IWM   0000735900Y
28824840ABK27GA00007IS000100TWM   0000702200Y
28824839X6K27GA00003V000100
28824844XAK27GA0000E7001000
28824844AAK27GA0000E7B001000SPY   0001425300Y
28824847XAK27GA0000JJ001000
28824848A8K27G600000XB000500MZZ   0000491800Y
28824849A8K27G600000YS000100MVV   0000809000Y
28824848XBK27GA00007H000100
28824849XBK27GA00007I000100
28824850ABK27GA00007JS000100TWM   0000702400Y
28824853X4K27GA000054000200
28824854X8K27G600000L000500
28824854X8K27G600000U000100
28824855AAK27GA0000JKB001000SDS   0000547700Y
28824855XBK27GA00006W001000
28824855ABK27GA00007KS001000SSO   0000765100Y
28824856AAK27GA0000JLB001000SDS   0000547600Y
28824856XAK27GA0000IR001000
28824858A4K27GA000064S000200DIA   0001298700Y
28824858XAK27GA0000E7001000
28824858AAK27GA0000E7B001000SPY   0001424900Y
28824859AAK27GA0000JMB001000SDS   0000547400Y
28824858A6K27GA00003WS002000IWM   0000736700Y
28824859XAK27GA0000J5000500
28824859AAK27GA0000J5S000500SPY   0001425500Y
28824860A4K27GA000065B000100DOG   0000597100Y
28824861A3K27G600002AS000100DDM   0000802400Y
28824861XAK27GA0000E7001000
28824861AAK27GA0000E7B001000SPY   0001425300Y
28824866X4K27GA00003L000200
28824866A4K27GA00003LB000200DIA   0001298400Y
28824869XAK27GA0000EA001000
28824869AAK27GA0000EAS001000SPY   0001425500Y
28824869XAK27GA0000E7001000
28824869AAK27GA0000E7B001000SPY   0001424900Y
28824869XAK27GA0000GK001000
28824870AAK27GA0000JNS001000SPY   0001425500Y
28824871XAK27GA0000E7001000
28824871AAK27GA0000E7B001000SPY   0001425300Y
28824874XAK27GA0000J5000500
28824879XAK27GA0000E7001000
28824879AAK27GA0000E7B001000SPY   0001424900Y
28824882XAK27GA0000E7001000
28824882AAK27GA0000E7B001000SPY   0001425300Y
28824885AAK27GA0000JOB000100SH    0000618400Y
28824885AAK27GA0000JPB001000SDS   0000547800Y
28824885ABK27GA00007LS001000SSO   0000765000Y
28824885XBK27GA00007K001000
28824886AAK27GA0000JQB001000SDS   0000547700Y
28824886XAK27GA0000GH000100
28824886AAK27GA0000JRS000100SPY   0001426600Y
28824888XAK27GA0000JI001000
28824890AAK27GA0000JSB001000SPY   0001424900Y
28824890XAK27GA0000E7001000
28824890AAK27GA0000E7B001000SPY   0001424900Y
28824892XAK27GA0000JN001000
28824892XAK27GA0000J1001000
28824892XAK27GA0000JD001000
28824892XAK27GA0000E7001000
28824892AAK27GA0000E7B001000SPY   0001425300Y
28824892AAK27GA0000JTB001000SPY   0001425400Y
28824893AAK27GA0000JUS001000SDS   0000549000Y
28824894XBK27GA000079001000
28824894ABK27GA00007MB001000SSO   0000764200Y
28824894AAK27GA0000JVS001000SPY   0001425600Y
28824896XBK27GA000078001000
28824896ABK27GA00007NB001000SSO   0000764000Y
28824903XAK27GA0000E7001000
28824903AAK27GA0000E7B001000SPY   0001424900Y
28824903XAK27GA0000JT001000
28824903XBK27GA00007N001000
28824903AAK27GA0000JWS001000SPY   0001425500Y
28824904XAK27GA0000JV001000
28824905XBK27GA00007M001000
28824905XAK27GA0000JU001000
28824905ABK27GA00007OB001000SSO   0000763900Y
28824906AAK27GA0000JXS001000SPY   0001425600Y
28824906AAK27GA0000JYB001000SPY   0001425000Y
28824906XAK27GA0000E7001000
28824906AAK27GA0000E7B001000SPY   0001425300Y
28824907ABK27GA00007PB001000SSO   0000764100Y
28824914XAK27GA0000JK001000
28824917XAK27GA0000EA001000
28824917XAK27GA0000JW001000
28824919XAK27GA0000E7001000
28824919AAK27GA0000E7B001000SPY   0001424900Y
28824923PAK27GA0000EAS000500SPY   0001425500000NAAQ00001
28824923PAK27GA0000JWS000500SPY   0001425500000NAAQ00004
28824923PAK27GA0000EAS000500SPY   0001425500000NAAQ00002
28824923PAK27GA0000JWS000500SPY   0001425500000NAAQ00003
28824931X9K27G60000F4003200
28824931A9K27G60000F4S003200QQQQ  0000496300Y
28824931X9K27G60000I2005000
28824931X9K27G60000I3005000
28824931A9K27G60000I4B005000QQQQ  0000495700Y
28824932A9K27G60000I5B005000QQQQ  0000495700Y
28824932XBK27GA000068001000
28824934ABK27GA00007QB001000SSO   0000763700Y
28824945AAK27GA0000JZS001000SDS   0000549000Y
28824945ABK27GA00007RB001000SSO   0000764200Y
28824945XBK27GA00007P001000
28824946XAK27GA0000F2000500
28824946AAK27GA0000F2B000500SPY   0001425300Y
28824946XAK27GA0000JX001000
28824946XAK27GA0000JY001000
28824946XAK27GA0000E7001000
28824946AAK27GA0000E7B001000SPY   0001425300Y
28824946AAK27GA0000K0B001000SPY   0001425300Y
28824947AAK27GA0000K1S001000SPY   0001425900Y
28824948AAK27GA0000K2S001000SPY   0001425600Y
28824951AAK27GA0000K3S001000SPY   0001425900Y
28824951XAK27GA0000F2000500
28824951AAK27GA0000F2B000500SPY   0001424900Y
28824951XAK27GA0000K0001000
28824952XAK27GA0000JZ001000
28824952XBK27GA00007R001000
28824952AAK27GA0000K4B001000SPY   0001425000Y
28824953XAK27GA0000F2000500
28824953AAK27GA0000F2B000500SPY   0001425300Y
28824954ABK27GA00007SB001000SSO   0000764200Y
28824954XAK27GA0000K4001000
28824954AAK27GA0000K5S001000SDS   0000549000Y
28824954XAK27GA0000JP001000
28824955XAK27GA0000JO000100
28824955XBK27GA00007L001000
28824954X6K27GA000026000500
28824954A6K27GA000026S000500IWM   0000736500Y
28824956XAK27GA0000HQ001000
28824956XAK27GA0000JM001000
28824957ABK27GA00007TS001000SSO   0000765100Y
28824956AAK27GA0000K6B001000SDS   0000547700Y
28824957ABK27GA00007US000100UWM   0000543100Y
28824958ABK27GA00007VB000100TWM   0000701400Y
28824958ABK27GA00007WB000100TWM   0000701300Y
28824966XAK27GA0000JQ001000
28824966AAK27GA0000K7B001000SPY   0001425300Y
28824966XAK27GA0000K3001000
28824967AAK27GA0000K8S001000SPY   0001425500Y
28824968XAK27GA0000K2001000
28824969XAK27GA0000K8001000
28824973X9K27G60000I5005000
28824974AAK27GA0000K9S001000SPY   0001425600Y
28824975A9K27G60000I6B005000QQQQ  0000495300Y
28824974AAK27GA0000KAB000100SH    0000618400Y
28824974AAK27GA0000KBB001000SDS   0000547800Y
28824975XBK27GA00007T001000
28824975ABK27GA00007XS001000SSO   0000765000Y
28824976AAK27GA0000KCS001000SPY   0001425900Y
28824976AAK27GA0000KDB001000SDS   0000547700Y
28824980XAK27GA0000KC001000
28824980XAK27GA0000K7001000
28824980AAK27GA0000KES001000SPY   0001425600Y
28824981XBK27GA00007S001000
28824980XAK27GA0000K5001000
28824981XAK27GA0000F2000500
28824981AAK27GA0000F2B000500SPY   0001424900Y
28824983ABK27GA00007YB001000SSO   0000764100Y
28824984X9K27G60000I6005000
28824984XAK27GA0000F2000500
28824984AAK27GA0000F2B000500SPY   0001425300Y
28824985A9K27G60000I7B005000QQQQ  0000495700Y
28824985AAK27GA0000KFB001000SPY   0001425000Y
28824988XAK27GA0000F2000500
28824988AAK27GA0000F2B000500SPY   0001424900Y
28824989X9K27G60000G0002000
28824989A9K27G60000G0B002000QQQQ  0000495600Y
28824988XAK27GA0000JB003000
28824988X4K27GA000062000200
28824988A4K27GA000062B000200DIA   0001298500Y
28824988XAK27GA0000JC003000
28824988AAK27GA0000KGB003000SPY   0001425100Y
28824988AAK27GA0000KHB003000SPY   0001425100Y
28824995XAK27GA0000KE001000
28824995AAK27GA0000KES001000SPY   0001425500Y
28824999X9K27G60000I7005000
28824999X9K27G60000I4005000
28824999X9K27G60000G0002000
28824999A9K27G60000G0B002000QQQQ  0000495100Y
28825000A9K27G60000I8B005000QQQQ  0000495300Y
28825001A9K27G60000I9B005000QQQQ  0000495300Y
28825008XAK27GA0000F2000500
28825008AAK27GA0000F2B000500SPY   0001425300Y
28825008XAK27GA0000JS001000
28825009AAK27GA0000KIB001000SPY   0001425000Y
28825009XAK27GA0000JH001000
28825018AAK27GA0000KJB002000SPY   0001425100Y
28825023X9K27G60000I9005000
28825023X9K27G60000I8005000
28825023A9K27G60000IAB005000QQQQ  0000495700Y
28825023A9K27G60000IBB005000QQQQ  0000495700Y
28825040X9K27G60000G0002000
28825040A9K27G60000G0B002000QQQQ  0000495600Y
28825039XAK27GA0000J4003000
28825039XAK27GA0000J3003000
28825041AAK27GA0000KKS003000SPY   0001426200Y
28825041AAK27GA0000KLS003000SPY   0001426200Y
28825045XAK27GA0000FE000500
28825045AAK27GA0000FEB000500SPY   0001425300Y
28825047XAK27GA0000K6001000
28825065XAK27GA0000KL003000
28825065XAK27GA0000KK003000
28825066AAK27GA0000KMS003000SPY   0001425600Y
28825066AAK27GA0000KNS003000SPY   0001425600Y
28825072X6K27GA000026000500
28825072A6K27GA000026S000500IWM   0000736900Y
28825073X6K27GA00003W002000
28825077XBK27GA00007X001000
28825079XBK27GA00007U000100
28825079XBK27GA00007V000100
28825079XBK27GA00007W000100
28825079XAK27GA0000JL001000
28825080ABK27GA00007ZS001000SSO   0000765100Y
28825079A6K27GA00003XS000100IWM   0000737000Y
28825081AAK27GA0000KOB001000SDS   0000547600Y
28825083X9K27G60000IB005000
28825083X9K27G60000IA005000
28825086XAK27GA0000KD001000
28825085X6K27GA00003X000100
28825088X6K27GA00003H000500
28825088A6K27GA00003HB000500IWM   0000736400Y
28825091ABK27GA000080B000100UWM   0000542300Y
28825091XBK27GA00007J000100
28825089X6K27GA00003H000500
28825089A6K27GA00003HB000500IWM   0000736000Y
28825091ABK27GA000081S000100TWM   0000702200Y
28825093A9K27G60000ICB005000QQQQ  0000495300Y
28825093A9K27G60000IDB005000QQQQ  0000495300Y
28825092X6K27GA00003H000500
28825092A6K27GA00003HB000500IWM   0000736400Y
28825094XBK27GA000080000100
28825094XBK27GA000081000100
28825096ABK27GA000082S000100TWM   0000702200Y
28825096ABK27GA000083B000100UWM   0000542300Y
28825095X6K27GA00003H000500
28825095A6K27GA00003HB000500IWM   0000736000Y
28825097X6K27GA00003H000500
28825097A6K27GA00003HB000500IWM   0000736400Y
28825099XBK27GA000083000100
28825099XBK27GA000082000100
28825100ABK27GA000084B000100UWM   0000542300Y
28825099A6K27GA00003YB000100IWM   0000735900Y
28825100ABK27GA000085S000100TWM   0000702200Y
28825099X6K27GA00003Y000100
28825107X6K27GA00003H000500
28825107A6K27GA00003HB000500IWM   0000736000Y
28825109X6K27GA00003H000500
28825109A6K27GA00003HB000500IWM   0000736400Y
28825160X8K27G600000X000500
28825160X8K27G600000W000100
28825160X8K27G600000Y000100
28825162A8K27G600000ZS000100MVV   0000809100Y
28825169X8K27G600000J000500
28825169X8K27G600000D000100
28825170X8K27G600000K000100
28825171A8K27G6000010B000100MVV   0000805800Y
28825188A8K27G6000011S000500MZZ   0000494000Y
28825188A8K27G6000012B000100MVV   0000806000Y
28825194XAK27GA0000KA000100
28825194XAK27GA0000KB001000
28825196AAK27GA0000KPB001000SDS   0000547700Y
28825319X4K27GA00005T000100
28825319X4K27GA00005S000100
28825362XAK27GA0000J0002000
28825395XBK27GA000072002000
28825395X3K27G6000023002000
28825400XCK27GA00001T002000
28825408A6K27GA00003ZB002000IMCL  0000305100Y
28825429X1K27GA00002W002000
28825438XBK27GA000073002000
28825458X1K27GA00002X002000
28825460A5K27GA00001IB002000GM    0000172200Y
28825469A1K27GA00002YB000095AAPL  0001830100Y
28825485X2K27G600001O002000
28825495X2K27G600001P002000
28825496A7K27GA00001HB002000LMT   0000069100Y
28825505X2K27G600001U002000
28825510A7K27GA00001IB002000LMT   0000068300Y
28825515ACK27GA00001UB002000WYE   0000022500Y
28825517X3K27G6000026002000
28825541A1K27GA00002ZB002000AFL   0000038600Y
28825546X3K27G6000028002000
28825555A1K27GA000030B002000AFL   0000039400Y
28825560A3K27G600002BB002000CVS   0000021000Y
28825571X4K27GA00005U002000
28825576A2K27G600001VB002000BBT   0000015700Y
28825599A3K27G600002CB002000COH   0000016900Y
28825625A4K27GA000066B002000EIX   0000024800Y
28825660A4K27GA000067B002000ELN   0000225200Y
28825666A4K27GA000068B002000EOG   0001386000Y
28825689A4K27GA000069B002000ELX   0000127900Y
28825705A4K27GA00006AB002000EMC   0000166200Y
28825720A4K27GA00006BB002000EOG   0001385200Y
28825938XAK27GA0000F6000500
28825940ABK27GA000086B001000SSO   0000764200Y
28825940XBK27GA00007Y001000
28825944AAK27GA0000KQS001000SDS   0000549000Y
28826278XAK27GA0000KN003000
28826278XAK27GA0000KM003000
28826284AAK27GA0000KRS003000SPY   0001426200Y
28826284AAK27GA0000KSS003000SPY   0001426200Y
28826355X3K27G600001M002000
28826380X7K27GA00001I002000
28826383X5K27GA000018002000
28826397AAK27GA0000KTB002000SHLD  0000650800Y
28826398X7K27GA00001H002000
28826423ABK27GA000087B002000UTX   0000044300Y
28826440A3K27G600002DB002000CTSH  0000013500Y
28826445ABK27GA000088B002000UTX   0000045100Y
28826474XCK27GA00001U002000
28826489X1K27GA00002Z002000
28826492AAK27GA0000KUS001000SPY   0001425600Y
28826493XAK27GA0000KR003000
28826493XAK27GA0000KS003000
28826494AAK27GA0000KVS003000SPY   0001425600Y
28826495AAK27GA0000KWS003000SPY   0001425600Y
28826499ACK27GA00001VB002000WYE   0000022900Y
28826513A1K27GA000031B002000ABT   0000032400Y
28826517A4K27GA00006CB000100DRYS  0001067100Y
28826517X4K27GA00004W000100
28826517A4K27GA00006DB000100DRYS  0001067100Y
28826520X1K27GA000030002000
28826530A1K27GA000032B002000ABT   0000031500Y
28826561A2K27G600001WB002000AXP   0000396900Y
28826563A2K27G600001XB002000AXP   0000396100Y
28826578X3K27G600002B002000
28826585A2K27G600001YB002000BBT   0000015900Y
28826591A6K27GA000040S000100IYF   0000859000Y
28826602A3K27G600002EB002000COH   0000017100Y
28826602A3K27G600002FB002000CVS   0000023000Y
28826613X4K27GA000066002000
28826636A4K27GA00006EB002000EIX   0000025400Y
28826645A4K27GA00006FB002000ESI   0000615400Y
28826666A4K27GA00006GB002000ESI   0000614600Y
28826672A4K27GA00006HB002000ESV   0000727300Y
28826687A4K27GA00006IB002000ESV   0000726500Y
28826697A4K27GA00006JB002000EXC   0000857100Y
28826710X9K27G60000IC005000
28826710X9K27G60000ID005000
28826711A9K27G60000IEB005000QQQQ  0000495700Y
28826711A9K27G60000IFB005000QQQQ  0000495700Y
28826760XAK27GA0000KJ001000
28826767XAK27GA0000KQ001000
28826767XBK27GA000086001000
28826769ABK27GA000089B001000SSO   0000764100Y
28826780XAK27GA0000KG003000
28826780XAK27GA0000KJ001000
28826780XAK27GA0000KI001000
28826780XAK27GA0000KH003000
28826782AAK27GA0000KXB003000SPY   0001424500Y
28826782AAK27GA0000KYB003000SPY   0001424500Y
28826782AAK27GA0000KZB001000SPY   0001424900Y
28826782AAK27GA0000L0B001000SPY   0001424900Y
28826784XAK27GA0000F2000500
28826784AAK27GA0000F2B000500SPY   0001424900Y
28826785XAK27GA0000FE000500
28826785AAK27GA0000FEB000500SPY   0001424900Y
28826787AAK27GA0000L1B000100SH    0000618400Y
28826787XAK27GA0000KP001000
28826787AAK27GA0000L2B001000SDS   0000547800Y
28826794X4K27GA000062000200
28826794A4K27GA000062B000200DIA   0001298200Y
28826800X6K27GA00003H000500
28826800A6K27GA00003HB000500IWM   0000736000Y
28826802X6K27GA00003H000500
28826802A6K27GA00003HB000500IWM   0000736400Y
28826805XBK27GA00007Z001000
28826805ABK27GA00008AS001000SSO   0000765000Y
28826806AAK27GA0000L3B001000SDS   0000547700Y
28826807X6K27GA00003H000500
28826807A6K27GA00003HB000500IWM   0000736000Y
28826810XBK27GA000084000100
28826810XBK27GA000085000100
28826809X6K27GA00003H000500
28826809A6K27GA00003HB000500IWM   0000736400Y
28826812ABK27GA00008BB000100UWM   0000542300Y
28826812ABK27GA00008CS000100TWM   0000702200Y
28826811X6K27GA00003H000500
28826811A6K27GA00003HB000500IWM   0000736000Y
28826814XBK27GA00008B000100
28826814XBK27GA00008C000100
28826817ABK27GA00008DS000100TWM   0000702400Y
28826818ABK27GA00008EB000100UWM   0000542300Y
28826819ABK27GA00008FS000100TWM   0000702200Y
28826819XBK27GA00008D000100
28826822XAK27GA0000L0001000
28826852X8K27G6000011000500
28826852X8K27G6000012000100
28826858A8K27G6000013S000500MZZ   0000494100Y
28826858A8K27G6000014B000100MVV   0000805900Y
28826863A8K27G6000015B000500MZZ   0000491800Y
28826863A8K27G6000016S000100MVV   0000809000Y
28826862XAK27GA0000FE000500
28826862AAK27GA0000FEB000500SPY   0001425300Y
28826862XAK27GA0000F2000500
28826862AAK27GA0000F2B000500SPY   0001425300Y
28826863XAK27GA0000KX003000
28826863XAK27GA0000KY003000
28826863AAK27GA0000L4B003000SPY   0001425100Y
28826863AAK27GA0000L5B003000SPY   0001425100Y
28826863XAK27GA0000KZ001000
28826863AAK27GA0000L6B001000SPY   0001425000Y
28826867XBK27GA00008A001000
28826869XAK27GA0000KO001000
28826869ABK27GA00008GS001000SSO   0000765100Y
28826869XAK27GA0000L1000100
28826869XAK27GA0000L2001000
28826870AAK27GA0000L7B001000SDS   0000547600Y
28826871AAK27GA0000L8B001000SDS   0000547700Y
28826876XAK27GA0000L3001000
28826885X4K27GA000062000200
28826885A4K27GA000062B000200DIA   0001298500Y
28826887X6K27GA00003H000500
28826887A6K27GA00003HB000500IWM   0000736400Y
28826888X6K27GA00003H000500
28826888A6K27GA00003HB000500IWM   0000736000Y
28826890X6K27GA00003H000500
28826890A6K27GA00003HB000500IWM   0000736400Y
28826895X9K27G60000G0002000
28826895A9K27G60000G0B002000QQQQ  0000495100Y
28826895XAK27GA0000FE000500
28826895AAK27GA0000FEB000500SPY   0001424900Y
28826895XAK27GA0000L6001000
28826897AAK27GA0000L9B001000SPY   0001424900Y
28826897X6K27GA00003H000500
28826897A6K27GA00003HB000500IWM   0000736000Y
28826907X6K27GA00003H000500
28826907A6K27GA00003HB000500IWM   0000736400Y
28826908XBK27GA00008E000100
28826908XBK27GA00008F000100
28826910ABK27GA00008HB000100UWM   0000542300Y
28826910ABK27GA00008IS000100TWM   0000702200Y
28826910X6K27GA00003H000500
28826910A6K27GA00003HB000500IWM   0000736000Y
28826913XBK27GA00008H000100
28826913XBK27GA00008I000100
28826915ABK27GA00008JS000100TWM   0000702400Y
28826914X6K27GA00003H000500
28826914A6K27GA00003HB000500IWM   0000736400Y
28826917ABK27GA00008KB000100UWM   0000542300Y
28826917XBK27GA00008J000100
28826917ABK27GA00008LS000100TWM   0000702200Y
28826917X6K27GA00003H000500
28826917A6K27GA00003HB000500IWM   0000736000Y
28826919XAK27GA0000FE000500
28826919AAK27GA0000FEB000500SPY   0001425300Y
28826920A6K27GA000041S002000IWM   0000736700Y
28826920X6K27GA00003U002000
28826925AAK27GA0000LAB000100SH    0000618400Y
28826925AAK27GA0000LBB001000SDS   0000547800Y
28826926ABK27GA00008MS001000SSO   0000765000Y
28826926XBK27GA00008G001000
28826926AAK27GA0000LCB001000SDS   0000547700Y
28826928XBK27GA00008L000100
28826928XBK27GA00008K000100
28826928A6K27GA000042S002000IWM   0000736800Y
28826930ABK27GA00008NS000100TWM   0000702400Y
28826932X9K27G60000IE005000
28826937X4K27GA000064000200
28826939A4K27GA00006KS000200DIA   0001298700Y
28826943A9K27G60000IGB005000QQQQ  0000495300Y
28826943X9K27G60000EP002000
28826943A9K27G60000EPB002000QQQQ  0000495400Y
28826943X6K27GA000041002000
28826952XAK27GA0000L4003000
28826953XAK27GA0000L5003000
28826957X9K27G60000IF005000
28826963A9K27G60000IHB005000QQQQ  0000495300Y
28826969AAK27GA0000LDB003000SPY   0001424500Y
28826969AAK27GA0000LEB003000SPY   0001424500Y
28826968A6K27GA000043S002000IWM   0000736700Y
28826989XAK27GA0000F2000500
28826989AAK27GA0000F2B000500SPY   0001424900Y
28826994XAK27GA0000FE000500
28826994AAK27GA0000FEB000500SPY   0001424900Y
28827355X6K27GA00003Z002000
28827361XAK27GA0000KT002000
28827404XAK27GA0000HW002000
28827407XBK27GA000088002000
28827419XBK27GA000087002000
28827422A3K27G600002GB002000CELG  0000462300Y
28827423X1K27GA000031002000
28827424XCK27GA00001V002000
28827447X1K27GA000032002000
28827453X2K27G600001V002000
28827468X2K27G6000016002000
28827477X2K27G600001D002000
28827486X4K27GA00006E002000
28827495A7K27GA00001JB002000LMT   0000074300Y
28827508X3K27G600002C002000
28827518X3K27G600002F002000
28827520X9K27G60000F4003200
28827520A9K27G60000F4S003200QQQQ  0000495800Y
28827531A5K27GA00001JB002000GM    0000173200Y
28827537A1K27GA000033B002000AFL   0000042300Y
28827564A3K27G600002HB002000CVS   0000023400Y
28827569A7K27GA00001KB002000LMT   0000075100Y
28827602ACK27GA00001WB002000WYE   0000024900Y
28827616A1K27GA000034B002000AFL   0000043100Y
28827622A4K27GA00006LB002000EIX   0000027600Y
28827640A4K27GA00006MB002000FCX   0001223100Y
28827700A4K27GA00006NB002000EXC   0000856300Y
28827711A4K27GA00006OB002000FCX   0001222300Y
28827721A4K27GA00006PB002000FDO   0000181000Y
28827948A4K27GA00006QS000100DRYS  0001069800Y
28828018A4K27GA00006RB000100DXD   0000499600Y
28828019A3K27G600002IS000100DDM   0000802200Y
28828030XAK27GA0000J8001000
28828031AAK27GA0000LFS001000SPY   0001425500Y
28828031XAK27GA0000IX001000
28828043XAK27GA0000E7001000
28828043AAK27GA0000E7B001000SPY   0001424900Y
28828043XAK27GA0000G8001000
28828044AAK27GA0000LGS001000SPY   0001425400Y
28828359X7K27GA00001K002000
28828375X7K27GA00001J002000
28828374XCK27GA00001W002000
28828418X7K27GA00001G002000
28828426A6K27GA000044B002000IMCL  0000308400Y
28828434ABK27GA00008OB002000UTX   0000048300Y
28828453X1K27GA000034002000
28828459ABK27GA00008PB002000UTX   0000049100Y
28828460AAK27GA0000LHB002000SHLD  0000655900Y
28828475X1K27GA00002D002000
28828479AAK27GA0000LIB002000SNDK  0000217400Y
28828492ACK27GA00001XB002000WYE   0000025300Y
28828513X4K27GA00006C000100
28828514X4K27GA00006D000100
28828519A4K27GA00006SB000100DRYS  0001067400Y
28828519A4K27GA00006TB000100DRYS  0001067400Y
28828528A1K27GA000035B002000ABT   0000035400Y
28828529X1K27GA000033002000
28828532A1K27GA000036B002000ABT   0000034600Y
28828545X2K27G600001T002000
28828554X1K27GA000029002000
28828573X2K27G600001Y002000
28828573X2K27G600001S002000
28828597A2K27G600001ZB002000BBT   0000018600Y
28828613A2K27G6000020B002000BNI   0001057300Y
28828622X3K27G600002E002000
28828623A2K27G6000021B002000BNI   0001056500Y
28828629X3K27G600002H002000
28828646X4K27GA00006L002000
28828660A3K27G600002JB002000COH   0000019900Y
28828667A4K27GA00006UB002000EIX   0000028200Y
28828683A3K27G600002KB002000CVS   0000025300Y
28828711A4K27GA00006VB002000FDX   0000875900Y
28828795XAK27GA0000K1001000
28828795AAK27GA0000K1S001000SPY   0001425500Y
28828817X4K27GA000062000200
28828817A4K27GA000062B000200DIA   0001298200Y
28828844AAK27GA0000LJS001000SPY   0001425500Y
28828919XAK27GA0000GB000900
28828921XBK27GA00007O001000
28828922AAK27GA0000LKB000900SPY   0001424900Y
28828926XAK27GA0000GA001000
28828926ABK27GA00008QB001000SSO   0000763800Y
28828926XBK27GA000089001000
28828928ABK27GA00008RB001000SSO   0000764000Y
28828934XAK27GA0000G9000100
28828947ABK27GA00008SS001000SSO   0000764900Y
28828947XBK27GA00008M001000
28828948AAK27GA0000LLB001000SDS   0000547800Y
28829278X9K27G60000GW002000
28829279X9K27G60000GV001000
28829282A9K27G60000IIB001000QQQQ  0000495200Y
28829283X9K27G60000GL001000
28829283X9K27G60000GN001000
28829285A9K27G60000IJB001000QLD   0000888700Y
28829289X9K27G60000GO000100
28829290X9K27G60000II001000
28829295X9K27G60000IJ001000
28829295A9K27G60000IKB001000QQQQ  0000495100Y
28829296A9K27G60000ILB001000QLD   0000888600Y
28829297A9K27G60000IMB001000QQQQ  0000495200Y
28829299X9K27G60000IM001000
28829304X9K27G60000GH002000
28829304X4K27GA00004C000100
28829304X3K27G600000T000100
28829305X9K27G60000G9002000
28829305A9K27G60000G9S002000QQQQ  0000495700Y
28829306A4K27GA00006WS000100DXD   0000500600Y
28829306A3K27G600002LB000100DDM   0000800700Y
28829306A9K27G60000INS001000QLD   0000890400Y
28829307X9K27G60000IN001000
28829307A9K27G60000IOS001000QLD   0000890300Y
28829313A9K27G60000IPS001000QLD   0000890400Y
28829320A9K27G60000IQS002000QQQQ  0000495800Y
28829352X9K27G60000IQ002000
28829383XAK27GA0000LH002000
28829393X3K27G600002D002000
28829402XBK27GA00008O002000
28829411X9K27G60000HZ002000
28829413XBK27GA00008P002000
28829426XCK27GA00001X002000
28829449X1K27GA000035002000
28829457X1K27GA000036002000
28829489A7K27GA00001LB002000LMT   0000081100Y
28829490A7K27GA00001MB002000LPNT  0000181200Y
28829503X4K27GA00006U002000
28829518ACK27GA00001YB002000WYE   0000027300Y
28829527XAK27GA0000G1003000
28829527XAK27GA0000G5003000
28829527XAK27GA0000FI000500
28829527AAK27GA0000FIB000500SPY   0001424800Y
28829527XAK27GA0000F5000500
28829527AAK27GA0000F5B000500SPY   0001424800Y
28829528AAK27GA0000LMS003000SPY   0001425400Y
28829528AAK27GA0000LNS003000SPY   0001425400Y
28829531A7K27GA00001NB002000LMT   0000080300Y
28829540X4K27GA000053000200
28829542A4K27GA00006XS000200DIA   0001298600Y
28829549AAK27GA0000LOB001000SPY   0001424800Y
28829549XAK27GA0000L9001000
28829551AAK27GA0000LPB001000SPY   0001424800Y
28829552X4K27GA00003L000200
28829552A4K27GA00003LB000200DIA   0001298100Y
28829560AAK27GA0000LQS002000SPY   0001425300Y
28829561A1K27GA000037B002000AFL   0000046000Y
28829562A1K27GA000038B002000AFL   0000046800Y
28829564XAK27GA0000E8001000
28829564AAK27GA0000E8B001000SPY   0001424800Y
28829570X4K27GA00003L000200
28829570A4K27GA00003LB000200DIA   0001298400Y
28829570A4K27GA00006YB000100DOG   0000597200Y
28829571X4K27GA00004G000100
28829571A4K27GA00006ZB000100DXD   0000499700Y
28829571A3K27G600002MS000100DDM   0000802100Y
28829571X3K27G600000Z000100
28829574A1K27GA000039B002000ARO   0000292200Y
28829578A1K27GA00003AB002000ARO   0000293000Y
28829583A2K27G6000022B002000BBT   0000018700Y
28829593A2K27G6000023B002000BDX   0000755500Y
28829601X3K27G600002K002000
28829602A3K27G600002NB002000COH   0000020100Y
28829624A3K27G600002OB002000CVS   0000025700Y
28829634A2K27G6000024B002000BDX   0000756300Y
28829652A2K27G6000025B002000CAG   0000010600Y
28829661A4K27GA000070B002000FE    0000751600Y
28829678A4K27GA000071B002000EIX   0000030400Y
28829681AAK27GA0000LRS001000SPY   0001425400Y
28829681XAK27GA0000JF001000
28829681XAK27GA0000KU001000
28829700A9K27G60000IRS002000QQQQ  0000495800Y
28829706A4K27GA000072B002000FDO   0000181800Y
28830378X6K27GA000044002000
28830384X7K27GA00001L002000
28830398XCK27GA00001Y002000
28830403X7K27GA00001N002000
28830424AAK27GA0000LSB002000SHLD  0000661000Y
28830426X1K27GA000038002000
28830428XCK27GA00001D002000
28830436X2K27G600001Z002000
28830440X1K27GA000037002000
28830455X3K27G600002J002000
28830477A3K27G600002PB002000CTSH  0000016900Y
28830489X4K27GA000071002000
28830489X3K27G600002O002000
28830512A2K27G6000026B002000BMY   0000010000Y
28830522A9K27G60000ISB002000PDLI  0000012500Y
28830531ABK27GA00008TB002000UTX   0000052300Y
28830568ACK27GA00001ZB002000WYE   0000027700Y
28830576ABK27GA00008UB002000UTX   0000053100Y
28830600A1K27GA00003BB002000ABT   0000037700Y
28830600A1K27GA00003CB002000ABT   0000038500Y
28830624A2K27G6000027B002000CAG   0000010400Y
28830624A3K27G600002QB002000CVS   0000027700Y
28830640A4K27GA000073B002000EIX   0000031000Y
28830654A4K27GA000074B002000FDX   0000876700Y
28830656A5K27GA00001KB002000FL    0000110200Y
28830674A4K27GA000075B002000FE    0000752400Y
28830681A5K27GA00001LB002000FRE   0000252000Y
28830697A5K27GA00001MB002000FL    0000111000Y
28830700A5K27GA00001NB002000G     0000107700Y
28830983XAK27GA0000E9001000
28830983AAK27GA0000E9S001000SPY   0001425400Y
28830983X4K27GA00003L000200
28830983A4K27GA00003LB000200DIA   0001298100Y
28830983XAK27GA0000G6001000
28830983XAK27GA0000G7000900
28830984AAK27GA0000LTS001000SPY   0001425300Y
28830985XBK27GA00008Q001000
28830985AAK27GA0000LUB000900SPY   0001424800Y
28830994XAK27GA0000G3001000
28830994XBK27GA00008R001000
28830994ABK27GA00008VB001000SSO   0000763700Y
28830996ABK27GA00008WB001000SSO   0000763900Y
28831009X4K27GA000061000047
28831014A4K27GA000076S000047DIA   0001298500Y
28831013X6K27GA000026000500
28831013A6K27GA000026S000500IWM   0000736500Y
28831016ABK27GA00008XS000100UWM   0000543100Y
28831016ABK27GA00008YB000100TWM   0000701300Y
28831016ABK27GA00008ZB000100TWM   0000701400Y
28831017XAK27GA0000F7000500
28831017AAK27GA0000F7B000500SPY   0001424700Y
28831023X8K27G6000013000500
28831023X8K27G6000014000100
28831023X8K27G6000010000100
28831024X4K27GA00003T000100
28831024X4K27GA00003U000100
28831025X3K27G600002L000100
28831025A8K27G6000017B000100MVV   0000805800Y
28831026A4K27GA000077S000100DXD   0000500700Y
28831026A3K27G600002RB000100DDM   0000800600Y
28831040A8K27G6000018B000500MZZ   0000491900Y
28831040A8K27G6000019S000100MVV   0000808800Y
28831108X4K27GA00006S000100
28831108X4K27GA00006T000100
28831108A4K27GA000078B000100DRYS  0001065100Y
28831108A4K27GA000079B000100DRYS  0001065100Y
28831364X6K27GA00002C000500
28831364A6K27GA00002CB000500IWM   0000735900Y
28831366XAK27GA0000FG000500
28831366AAK27GA0000FGB000500SPY   0001424700Y
28831367XAK27GA0000J6001000
28831367XAK27GA0000E6001000
28831367AAK27GA0000E6S001000SPY   0001425300Y
28831367XAK27GA0000EB001000
28831367AAK27GA0000EBB001000SPY   0001424700Y
28831367XAK27GA0000EL003000
28831367XAK27GA0000ET003000
28831367XAK27GA0000EQ003000
28831367XAK27GA0000K9001000
28831367XAK27GA0000EX000500
28831367AAK27GA0000EXB000500SPY   0001424600Y
28831367XAK27GA0000F0003000
28831365A6K27GA000045B002000IMCL  0000311600Y
28831366X6K27GA00002C000500
28831366A6K27GA00002CB000500IWM   0000736300Y
28831367X4K27GA000062000200
28831367A4K27GA000062B000200DIA   0001297900Y
28831367X4K27GA00006K000200
28831367X4K27GA00003H000200
28831367A4K27GA00003HB000200DIA   0001298000Y
28831367AAK27GA0000LVS001000SPY   0001425200Y
28831367AAK27GA0000LWS003000SPY   0001425200Y
28831367XAK27GA0000LO001000
28831368XAK27GA0000LP001000
28831368XAK27GA0000LJ001000
28831368AAK27GA0000LXS002000SPY   0001425300Y
28831368AAK27GA0000LYS003000SPY   0001425200Y
28831368AAK27GA0000LZB000100SH    0000618500Y
28831368ABK27GA000090S001000SSO   0000764800Y
28831368AAK27GA0000M0B001000SDS   0000547900Y
28831368XBK27GA00008S001000
28831368AAK27GA0000M1B000900SPY   0001424700Y
28831369AAK27GA0000M2B003000SPY   0001424300Y
28831369AAK27GA0000M3B003000SPY   0001424300Y
28831369AAK27GA0000M4B001000SPY   0001424700Y
28831369AAK27GA0000M5B001000SPY   0001424700Y
28831374A4K27GA00007AS000200DIA   0001298400Y
28831374A4K27GA00007BB000100DXD   0000499800Y
28831374X4K27GA00004I000100
28831374X3K27G6000029000100
28831374A3K27G600002SS000100DDM   0000802000Y
28831377X6K27GA00002C000500
28831377A6K27GA00002CB000500IWM   0000735900Y
28831378XAK27GA0000LS002000
28831380XBK27GA00001I000100
28831380XBK27GA00008N000100
28831383ABK27GA000091S000100TWM   0000702600Y
28831382X6K27GA00002C000500
28831382A6K27GA00002CB000500IWM   0000736300Y
28831384ABK27GA000092B000100UWM   0000542100Y
28831384XBK27GA000091000100
28831384ABK27GA000093S000100TWM   0000702400Y
28831383X6K27GA00002C000500
28831383A6K27GA00002CB000500IWM   0000735900Y
28831386X9K27G60000G2002000
28831386A9K27G60000G2B002000QQQQ  0000495000Y
28831386XBK27GA000092000100
28831387XBK27GA000093000100
28831387X9K27G60000F9003200
28831387A9K27G60000F9B003200QQQQ  0000495100Y
28831385X6K27GA00002C000500
28831385A6K27GA00002CB000500IWM   0000736300Y
28831388ABK27GA000094B000100UWM   0000542100Y
28831388ABK27GA000095S000100TWM   0000702400Y
28831397X6K27GA00002C000500
28831397A6K27GA00002CB000500IWM   0000735900Y
28831399X9K27G60000FS005000
28831400X6K27GA00002C000500
28831400A6K27GA00002CB000500IWM   0000736300Y
28831401A9K27G60000ITS005000QQQQ  0000495700Y
28831407X6K27GA00002C000500
28831407A6K27GA00002CB000500IWM   0000735900Y
28831410XAK27GA0000M5001000
28831411XAK27GA0000EX000500
28831411AAK27GA0000EXB000500SPY   0001425000Y
28831410X6K27GA00002C000500
28831410A6K27GA00002CB000500IWM   0000736300Y
28831412X6K27GA00002C000500
28831412A6K27GA00002CB000500IWM   0000735900Y
28831415X9K27G60000FT005000
28831416A9K27G60000IUS005000QQQQ  0000495700Y
28831416X9K27G60000FW002000
28831417A9K27G60000IVB002000QQQQ  0000495200Y
28831417X6K27GA00002C000500
28831417A6K27GA00002CB000500IWM   0000736300Y
28831418A9K27G60000IWB002000QQQQ  0000495200Y
28831419XBK27GA000094000100
28831419XBK27GA000095000100
28831419A7K27GA00001OB002000LMT   0000086300Y
28831418X6K27GA00002C000500
28831418A6K27GA00002CB000500IWM   0000735900Y
28831420ABK27GA000096B000100UWM   0000542100Y
28831421ABK27GA000097S000100TWM   0000702400Y
28831420X6K27GA00002C000500
28831420A6K27GA00002CB000500IWM   0000736300Y
28831423XBK27GA000097000100
28831423XBK27GA000096000100
28831423A9K27G60000IXB002000QQQQ  0000495400Y
28831425ABK27GA000098S000100TWM   0000702600Y
28831425X6K27GA00002C000500
28831425A6K27GA00002CB000500IWM   0000735900Y
28831426AAK27GA0000M6B001000SPY   0001424600Y
28831426XAK27GA0000M4001000
28831427X6K27GA00002C000500
28831427A6K27GA00002CB000500IWM   0000736300Y
28831428ABK27GA000099B000100UWM   0000542100Y
28831428AAK27GA0000M7B001000SPY   0001424600Y
28831429XBK27GA000098000100
28831429ABK27GA00009AS000100TWM   0000702400Y
28831429XBK27GA00009A000100
28831429XBK27GA000099000100
28831430XBK27GA00008U002000
28831429A6K27GA000046B000100IWM   0000735800Y
28831431ABK27GA00009BS000100TWM   0000702600Y
28831429X6K27GA000046000100
28831430X6K27GA00002C000500
28831430A6K27GA00002CB000500IWM   0000735900Y
28831435X6K27GA00002R002000
28831437X4K27GA000062000200
28831437A4K27GA000062B000200DIA   0001298200Y
28831438XAK27GA0000FD000500
28831438AAK27GA0000FDB000500SPY   0001424600Y
28831438XAK27GA0000EX000500
28831438AAK27GA0000EXB000500SPY   0001424600Y
28831438XAK27GA0000LX001000
28831438XAK27GA0000LX001000
28831439X4K27GA000062000200
28831439A4K27GA000062B000200DIA   0001297900Y
28831439X4K27GA00003L000200
28831440AAK27GA0000M8S001000SPY   0001425400Y
28831443A4K27GA00007CB000200DIA   0001297800Y
28831444X4K27GA00003F000100
28831444X3K27G600002R000100
28831445X9K27G60000IX002000
28831446A4K27GA00007DS000100DXD   0000500800Y
28831446A3K27G600002TB000100DDM   0000800500Y
28831448AAK27GA0000M9S002000SPY   0001425200Y
28831450XBK27GA00008W001000
28831450ABK27GA00009CB001000SSO   0000763600Y
28831451X4K27GA00007C000200
28831451A4K27GA00007CB000200DIA   0001298100Y
28831452XBK27GA00008V001000
28831452ABK27GA00009DB001000SSO   0000763800Y
28831452XBK27GA00008T002000
28831451XCK27GA00001G002000
28831456XAK27GA0000LF001000
28831456AAK27GA0000MAS002000SPY   0001425300Y
28831458X6K27GA00002B000500
28831458A6K27GA00002BS000500IWM   0000736400Y
28831461ABK27GA00009ES000100UWM   0000542900Y
28831461ABK27GA00009FB000100TWM   0000701600Y
28831461XBK27GA000022000100
28831461ABK27GA00009GB000100TWM   0000701500Y
28831461XBK27GA00006T000100
28831464X6K27GA000025000500
28831464A6K27GA000025B000500IWM   0000735800Y
28831465AAK27GA0000MBB002000SPLS  0000010400Y
28831465X6K27GA00002N002000
28831468X8K27G6000017000100
28831466A6K27GA000047B002000IWM   0000735900Y
28831467X6K27GA000025000500
28831467A6K27GA000025B000500IWM   0000736200Y
28831469XBK27GA00000Q000100
28831469XBK27GA00009B000100
28831469A8K27G600001AB000100MVV   0000805700Y
28831471ABK27GA00009HB000100UWM   0000542000Y
28831471ABK27GA00009IS000100TWM   0000702600Y
28831476X1K27GA00003C002000
28831477X6K27GA000025000500
28831477A6K27GA000025B000500IWM   0000735800Y
28831482XAK27GA0000E6001000
28831482AAK27GA0000E6S001000SPY   0001425700Y
28831482XAK27GA0000LW003000
28831482XAK27GA0000M2003000
28831482X9K27G60000G2002000
28831482A9K27G60000G2B002000QQQQ  0000495500Y
28831482XAK27GA0000EX000500
28831482AAK27GA0000EXB000500SPY   0001425000Y
28831482XAK27GA0000M9002000
28831482XAK27GA0000M3003000
28831482XAK27GA0000FD000500
28831482AAK27GA0000FDB000500SPY   0001425000Y
28831482XAK27GA0000LY003000
28831482X4K27GA00007A000200
28831482X4K27GA000062000200
28831482A4K27GA000062B000200DIA   0001298200Y
28831483AAK27GA0000MCB003000SPY   0001424900Y
28831483AAK27GA0000MDB003000SPY   0001424900Y
28831483XAK27GA0000M7001000
28831483AAK27GA0000MEB002000SPY   0001424800Y
28831483XAK27GA0000EB001000
28831483AAK27GA0000EBB001000SPY   0001425100Y
28831483AAK27GA0000MFS003000SPY   0001425800Y
28831484X9K27G60000H1002000
28831484XBK27GA00009D001000
28831484ABK27GA00009JB001000SSO   0000763900Y
28831484AAK27GA0000MGS003000SPY   0001425800Y
28831484A4K27GA00007ES000200DIA   0001298700Y
28831485A9K27G60000IYS002000QQQQ  0000495700Y
28831485A4K27GA00007FS000100DXD   0000500500Y
28831485A3K27G600002UB000100DDM   0000800600Y
28831486X9K27G60000EN002000
28831486A9K27G60000ENS002000QQQQ  0000495700Y
28831488XBK27GA00009H000100
28831488XBK27GA00009I000100
28831487X6K27GA000025000500
28831487A6K27GA000025B000500IWM   0000736200Y
28831490ABK27GA00009KB000100UWM   0000542000Y
28831488A6K27GA000048B000100IWM   0000735700Y
28831489X6K27GA000048000100
28831490ABK27GA00009LS000100TWM   0000702600Y
28831493X8K27G600000C000500
28831493X8K27G600001A000100
28831493X8K27G600000V000500
28831493X8K27G6000018000500
28831493X8K27G6000015000500
28831493X8K27G600000H000500
28831493A7K27GA00001PS000100MDY   0001606300Y
28831494X8K27G6000019000100
28831494X8K27G6000016000100
28831494X8K27G600000Z000100
28831494X8K27G600000I000100
28831494X4K27GA00007B000100
28831494X3K27G600002S000100
28831495A8K27G600001BB000100MVV   0000805600Y
28831495A8K27G600001CS000500MZZ   0000494300Y
28831495A8K27G600001DB000500MZZ   0000491900Y
28831496A8K27G600001ES000100MVV   0000808900Y
28831497X6K27GA000025000500
28831497A6K27GA000025B000500IWM   0000735800Y
28831499XAK27GA0000MA001000
28831500X2K27G600001W002000
28831503X6K27GA000025000500
28831503A6K27GA000025B000500IWM   0000736200Y
28831504A6K27GA000049B002000IWM   0000736100Y
28831519A7K27GA00001QB002000LMT   0000087100Y
28831519XAK27GA0000M1000900
28831520AAK27GA0000MHB000900SPY   0001425100Y
28831521ABK27GA00009MB001000SSO   0000763700Y
28831521XBK27GA00009C001000
28831527XCK27GA00001Z002000
28831539X8K27G600001D000500
28831539X8K27G600001E000100
28831541A8K27G600001FB000500MZZ   0000491700Y
28831541A8K27G600001GS000100MVV   0000809100Y
28831543X9K27G60000EU002000
28831543A9K27G60000EUB002000QQQQ  0000495300Y
28831543X9K27G60000FR005000
28831543X9K27G60000FE005000
28831543X9K27G60000G2002000
28831543A9K27G60000G2B002000QQQQ  0000495000Y
28831543X1K27GA00003B002000
28831545XBK27GA00007Q001000
28831547ABK27GA00009NB001000SSO   0000763600Y
28831546ACK27GA000020B002000WMT   0000535500Y
28831549X2K27G6000025002000
28831552XAK27GA0000M8001000
28831552XAK27GA0000MA001000
28831553A9K27G60000IZB005000QQQQ  0000495200Y
28831553A9K27G60000J0B005000QQQQ  0000495200Y
28831570X9K27G60000FX002000
28831572ACK27GA000021B002000WYE   0000029700Y
28831588A1K27GA00003DB002000AFL   0000049700Y
28831591X9K27G60000J0005000
28831591X9K27G60000IZ005000
28831592A9K27G60000J1B005000QQQQ  0000495600Y
28831592A9K27G60000J2B005000QQQQ  0000495600Y
28831592A9K27G60000J3B002000QQQQ  0000495300Y
28831592X9K27G60000G2002000
28831592A9K27G60000G2B002000QQQQ  0000495500Y
28831598X2K27G600001X002000
28831601X2K27G6000022002000
28831635XAK27GA0000JR000100
28831637AAK27GA0000MIS000100SPY   0001426900Y
28831642X3K27G600002N002000
28831672XAK27GA0000F7000500
28831672AAK27GA0000F7B000500SPY   0001425100Y
28831672XAK27GA0000LV001000
28831673X4K27GA000073002000
28831675XBK27GA000090001000
28831675X3K27G600002Q002000
28831675XAK27GA0000L7001000
28831676ABK27GA00009OS001000SSO   0000764900Y
28831678AAK27GA0000MJB001000SDS   0000547600Y
28831683AAK27GA0000MKS001000SPY   0001425600Y
28831683XAK27GA0000F7000500
28831683AAK27GA0000F7B000500SPY   0001424700Y
28831684XAK27GA0000LZ000100
28831684XAK27GA0000M0001000
28831699A1K27GA00003EB002000AFL   0000050500Y
28831714A3K27G600002VB002000CVS   0000028100Y
28831720A2K27G6000028B002000BBT   0000021400Y
28831744A3K27G600002WB002000COH   0000022900Y
28831758A5K27GA00001OB002000GE    0000297100Y
28831766XAK27GA0000MI000100
28831766AAK27GA0000MLS000100SPY   0001426600Y
28831769A4K27GA00007GB002000EIX   0000033200Y
28831776A5K27GA00001PB002000GGP   0000401900Y
28831790A5K27GA00001QB002000FRE   0000252800Y
28831798A5K27GA00001RB002000GIS   0000591900Y
28831813A5K27GA00001SB002000G     0000108500Y
28831818A5K27GA00001TB002000GPS   0000171300Y
28831840A5K27GA00001UB002000GE    0000297900Y
28831923X9K27G60000EU002000
28831923A9K27G60000EUB002000QQQQ  0000495600Y
28832126A8K27G600001HB000500MZZ   0000491800Y
28832126A8K27G600001IS000100MVV   0000809000Y
28832209X4K27GA00003H000200
28832209A4K27GA00003HB000200DIA   0001298300Y
28832226XAK27GA0000MK001000
28832226AAK27GA0000MMS001000SPY   0001425200Y
28832227AAK27GA0000MNB000100SH    0000618500Y
28832227AAK27GA0000MOB001000SDS   0000547900Y
28832228ABK27GA00009PS001000SSO   0000764800Y
28832228XBK27GA00009O001000
28832350AAK27GA0000MPB002000SHLD  0000666100Y
28832405X7K27GA00001O002000
28832414X2K27G6000026002000
28832417X1K27GA00003D002000
28832424X2K27G6000027002000
28832428X3K27G600002V002000
28832429X7K27GA00001Q002000
28832436XCK27GA000021002000
28832448X1K27GA00003E002000
28832453ABK27GA00009QB002000UTX   0000056300Y
28832462X4K27GA00007G002000
28832470ACK27GA000022B002000WYE   0000030100Y
28832482ABK27GA00009RB002000UTX   0000057100Y
28832490A1K27GA00003FB002000ABT   0000040700Y
28832507ACK27GA000023B002000WMT   0000536300Y
28832517A2K27G6000029B002000AXP   0000397400Y
28832526A2K27G600002AB002000BBT   0000021600Y
28832543A3K27G600002XB002000COH   0000023100Y
28832547A1K27GA00003GB002000ABT   0000041600Y
28832565A4K27GA00007HB002000EIX   0000033800Y
28832572A2K27G600002BB002000AXP   0000398200Y
28832590A2K27G600002CB002000CAG   0000012500Y
28832596XAK27GA0000F7000500
28832596AAK27GA0000F7B000500SPY   0001425100Y
28832597XAK27GA0000MM001000
28832598XAK27GA0000F7000500
28832598AAK27GA0000F7B000500SPY   0001424700Y
28832599XBK27GA00009P001000
28832599AAK27GA0000MQS001000SPY   0001425600Y
28832600XAK27GA0000MJ001000
28832601XAK27GA0000LC001000
28832601ABK27GA00009SS001000SSO   0000764900Y
28832603AAK27GA0000MRB001000SDS   0000547700Y
28832603AAK27GA0000MSB001000SDS   0000547600Y
28832604XAK27GA0000MN000100
28832604XAK27GA0000MO001000
28832607X4K27GA00003H000200
28832607A4K27GA00003HB000200DIA   0001298000Y
28832614A3K27G600002YB002000CVS   0000030100Y
28832613X4K27GA00006Y000100
28832614X3K27G600002M000100
28832624A4K27GA00007IB000100DOG   0000597200Y
28832624A3K27G600002ZS000100DDM   0000802100Y
28832645A5K27GA00001VB002000GGP   0000402700Y
28833396XAK27GA0000E6001000
28833396AAK27GA0000E6S001000SPY   0001425300Y
28833396XAK27GA0000MQ001000
28833396XAK27GA0000EB001000
28833396AAK27GA0000EBB001000SPY   0001424700Y
28833397XAK27GA0000MD003000
28833397XAK27GA0000MF003000
28833397X9K27G60000G2002000
28833397A9K27G60000G2B002000QQQQ  0000495000Y
28833397AAK27GA0000MTS003000SPY   0001425200Y
28833397XAK27GA0000MH000900
28833397AAK27GA0000MUS001000SPY   0001425200Y
28833397XAK27GA0000MC003000
28833397XAK27GA0000MG003000
28833397AAK27GA0000MVS003000SPY   0001425200Y
28833398XAK27GA0000ME002000
28833398AAK27GA0000MWS002000SPY   0001425300Y
28833398AAK27GA0000MXB000100SH    0000618500Y
28833398AAK27GA0000MYB001000SDS   0000547900Y
28833398XBK27GA00009S001000
28833398AAK27GA0000MZB003000SPY   0001424300Y
28833399ABK27GA00009TS001000SSO   0000764800Y
28833398AAK27GA0000N0B000900SPY   0001424700Y
28833399XBK27GA00009M001000
28833399AAK27GA0000N1B003000SPY   0001424300Y
28833400AAK27GA0000N2B002000SPY   0001424700Y
28833404XBK27GA00009J001000
28833404ABK27GA00009UB001000SSO   0000763600Y
28833404XAK27GA0000EV000100
28833404AAK27GA0000N3B001000SPY   0001424500Y
28833406ABK27GA00009VB001000SSO   0000763800Y
28833408X6K27GA00002J002000
28833410X9K27G60000J3002000
28833412X3K27G600002G002000
28833414XAK27GA0000FD000500
28833414AAK27GA0000FDB000500SPY   0001424600Y
28833414XAK27GA0000EX000500
28833414AAK27GA0000EXB000500SPY   0001424600Y
28833414X4K27GA00007E000200
28833414X4K27GA000062000200
28833414A4K27GA000062B000200DIA   0001297900Y
28833415XAK27GA0000E5001000
28833415AAK27GA0000E5S001000SPY   0001425200Y
28833415XAK27GA0000MW002000
28833415XAK27GA0000N2001000
28833416A4K27GA00007JS000200DIA   0001298400Y
28833416AAK27GA0000N4S001000SPY   0001425400Y
28833418A3K27G6000030S000100DDM   0000802000Y
28833418A4K27GA00007KB000100DXD   0000499800Y
28833421XAK27GA0000E5001000
28833421AAK27GA0000E5S001000SPY   0001425600Y
28833424A2K27G600002DB002000BMY   0000011900Y
28833424X3K27G600002U000100
28833424X4K27GA00007F000100
28833426XAK27GA0000ML000100
28833426AAK27GA0000N5S000100SPY   0001426500Y
28833426X6K27GA000045002000
28833428XBK27GA000015002000
28833429XAK27GA0000FD000500
28833429AAK27GA0000FDB000500SPY   0001425000Y
28833429XAK27GA0000EX000500
28833429AAK27GA0000EXB000500SPY   0001425000Y
28833430X4K27GA000062000200
28833430A4K27GA000062B000200DIA   0001298200Y
28833431AAK27GA0000N6S000100SH    0000619100Y
28833431X4K27GA00007J000200
28833433XAK27GA0000N6000100
28833433AAK27GA0000N7B001000SDS   0000548000Y
28833434XBK27GA00009T001000
28833434ABK27GA00009WS001000SSO   0000764700Y
28833434A4K27GA00007LS000200DIA   0001298700Y
28833435X3K27G6000030000100
28833434A4K27GA00007MS000100DXD   0000500500Y
28833434X4K27GA00007K000100
28833435A3K27G6000031B000100DDM   0000800600Y
28833435XAK27GA0000MS001000
28833435AAK27GA0000N8B001000SDS   0000547900Y
28833435X9K27G60000EU002000
28833435A9K27G60000EUB002000QQQQ  0000495300Y
28833435X9K27G60000J2005000
28833435AAK27GA0000N9S000100SH    0000619100Y
28833437XBK27GA00009Q002000
28833437A9K27G60000J4B005000QQQQ  0000495200Y
28833436X6K27GA000025000500
28833436A6K27GA000025B000500IWM   0000735800Y
28833437X6K27GA000049002000
28833444XAK27GA0000N9000100
28833445XAK27GA0000MP002000
28833446X6K27GA000025000500
28833446A6K27GA000025B000500IWM   0000736200Y
28833448XBK27GA00009K000100
28833448XBK27GA00009L000100
28833450ABK27GA00009XS000100TWM   0000702600Y
28833450ABK27GA00009YB000100UWM   0000542000Y
28833449X6K27GA000025000500
28833449A6K27GA000025B000500IWM   0000735800Y
28833452XBK27GA00009Y000100
28833453XBK27GA00009X000100
28833453X6K27GA000025000500
28833453A6K27GA000025B000500IWM   0000736200Y
28833455ABK27GA00009ZB000100UWM   0000541800Y
28833455ABK27GA0000A0S000100TWM   0000702800Y
28833455ABK27GA0000A1B000100UWM   0000542000Y
28833455XBK27GA0000A0000100
28833455ABK27GA0000A2S000100TWM   0000702600Y
28833455X6K27GA000025000500
28833455A6K27GA000025B000500IWM   0000735800Y
28833458XBK27GA0000A1000100
28833457X6K27GA000025000500
28833457A6K27GA000025B000500IWM   0000736200Y
28833458XBK27GA0000A2000100
28833460ABK27GA0000A3S000100TWM   0000702600Y
28833460XAK27GA0000N2001000
28833460AAK27GA0000NAS001000SPY   0001425300Y
28833460ABK27GA0000A4B000100UWM   0000542000Y
28833462AAK27GA0000NBB001000SPY   0001424600Y
28833461XCK27GA000022002000
28833466X3K27G600002P002000
28833466X1K27GA00003F002000
28833466X6K27GA000025000500
28833466A6K27GA000025B000500IWM   0000735800Y
28833472X7K27GA00001M002000
28833474X4K27GA00007H002000
28833474A7K27GA00001RB002000LMT   0000093100Y
28833478XBK27GA0000A4000100
28833476X6K27GA000025000500
28833476A6K27GA000025B000500IWM   0000736200Y
28833478XBK27GA0000A3000100
28833480ABK27GA0000A5B000100UWM   0000542000Y
28833480ABK27GA0000A6S000100TWM   0000702600Y
28833479X6K27GA000025000500
28833479A6K27GA000025B000500IWM   0000735800Y
28833482XBK27GA0000A5000100
28833482XBK27GA0000A6000100
28833484ABK27GA0000A7S000100TWM   0000702800Y
28833485X6K27GA000025000500
28833485A6K27GA000025B000500IWM   0000736200Y
28833488ABK27GA0000A8B000100UWM   0000542000Y
28833488ABK27GA0000A9S000100TWM   0000702600Y
28833488XBK27GA0000A7000100
28833490XAK27GA0000FD000500
28833490AAK27GA0000FDB000500SPY   0001424600Y
28833490XBK27GA00009R002000
28833490XAK27GA0000E4001000
28833490AAK27GA0000E4B001000SPY   0001424600Y
28833490XAK27GA0000E5001000
28833490AAK27GA0000E5S001000SPY   0001425200Y
28833490XAK27GA0000EX000500
28833490AAK27GA0000EXB000500SPY   0001424600Y
28833490X4K27GA00007L000200
28833490X4K27GA000062000200
28833490A4K27GA000062B000200DIA   0001297900Y
28833492AAK27GA0000NCS002000SPY   0001425100Y
28833494XAK27GA0000MV003000
28833494XAK27GA0000MT003000
28833494A4K27GA00007NS000200DIA   0001298400Y
28833494X4K27GA00007M000100
28833494A4K27GA00007OB000100DXD   0000499800Y
28833495X3K27G6000031000100
28833495A3K27G6000032S000100DDM   0000802000Y
28833496AAK27GA0000NDS003000SPY   0001425800Y
28833496AAK27GA0000NES003000SPY   0001425800Y
28833497X6K27GA000025000500
28833497A6K27GA000025B000500IWM   0000735800Y
28833502X6K27GA000025000500
28833502A6K27GA000025B000500IWM   0000736200Y
28833507X6K27GA000025000500
28833507A6K27GA000025B000500IWM   0000735800Y
28833518XBK27GA0000A8000100
28833518XBK27GA0000A9000100
28833517X6K27GA000025000500
28833517A6K27GA000025B000500IWM   0000736200Y
28833518A6K27GA00004AB000100IWM   0000735700Y
28833519X6K27GA00004A000100
28833521ABK27GA0000AAS000100TWM   0000702800Y
28833528ABK27GA0000ABB000100UWM   0000542000Y
28833528XBK27GA0000AA000100
28833528ABK27GA0000ACS000100TWM   0000702600Y
28833531A7K27GA00001SB002000LMT   0000092300Y
28833532ACK27GA000024B002000WYE   0000032200Y
28833560X1K27GA00003G002000
28833602A1K27GA00003HB002000AFL   0000053400Y
28833606A2K27G600002EB002000CAG   0000012400Y
28833616A3K27G6000033B002000CVS   0000030400Y
28833627A1K27GA00003IB002000AFL   0000054200Y
28833631A5K27GA00001WB002000HAL   0000478000Y
28833637X2K27G6000028002000
28833649X3K27G600002W002000
28833658A5K27GA00001XB002000HD    0000273100Y
28833660X3K27G600002Y002000
28833674X3K27G600001Q002000
28833674X4K27GA000078000100
28833674X4K27GA000079000100
28833678A4K27GA00007PB000100DRYS  0001066900Y
28833678A4K27GA00007QB000100DRYS  0001066900Y
28833692A5K27GA00001YB002000HIG   0000675300Y
28833694A4K27GA00007RB002000EIX   0000036000Y
28833716A5K27GA00001ZB002000HMY   0000082700Y
28833717A5K27GA000020B002000GIS   0000592700Y
28833737A5K27GA000021B002000HMA   0000062900Y
28833747XAK27GA0000E4001000
28833747AAK27GA0000E4B001000SPY   0001425000Y
28833747XAK27GA0000NC002000
28833747XAK27GA0000E5001000
28833747AAK27GA0000E5S001000SPY   0001425600Y
28833747XAK27GA0000FD000500
28833747AAK27GA0000FDB000500SPY   0001425000Y
28833747X4K27GA000062000200
28833747A4K27GA000062B000200DIA   0001298200Y
28833747XAK27GA0000EX000500
28833747AAK27GA0000EXB000500SPY   0001425000Y
28833747X4K27GA00007N000200
28833748X9K27G60000FQ002000
28833748A5K27GA000022B002000GPS   0000172100Y
28833749X9K27G60000J1005000
28833748XAK27GA0000MY001000
28833749AAK27GA0000NFS001000SPY   0001425300Y
28833750X9K27G60000FD001000
28833750A4K27GA00007SS000200DIA   0001298700Y
28833750A9K27G60000J5B005000QQQQ  0000495200Y
28833751XAK27GA0000ND003000
28833751XAK27GA0000NE003000
28833751AAK27GA0000NGS003000SPY   0001425200Y
28833751AAK27GA0000NHS003000SPY   0001425200Y
28833753X9K27G60000IL001000
28833753A9K27G60000J6B001000QQQQ  0000495200Y
28833754XAK27GA0000N7001000
28833754XBK27GA00009W001000
28833755A9K27G60000J7B001000QLD   0000888400Y
28833755XAK27GA0000MR001000
28833756XAK27GA0000LL001000
28833756AAK27GA0000NIB001000SDS   0000548000Y
28833756ABK27GA0000ADS001000SSO   0000764700Y
28833757AAK27GA0000NJB001000SDS   0000547800Y
28833758AAK27GA0000NKB001000SDS   0000547700Y
28833759X9K27G60000J6001000
28833760X4K27GA00007O000100
28833761A3K27G6000034B000100DDM   0000800600Y
28833761X3K27G6000032000100
28833761A4K27GA00007TS000100DXD   0000500500Y
28833765XAK27GA0000NK001000
28833767AAK27GA0000NLB001000SDS   0000547700Y
28833770X9K27G60000F2003200
28833770A9K27G60000F2S003200QQQQ  0000495700Y
28833772A5K27GA000023B002000HAL   0000478800Y
28833773A9K27G60000J8B002000QQQQ  0000495400Y
28833773X9K27G60000CZ001000
28833775A9K27G60000J9S001000QID   0000382300Y
28833783A5K27GA000024B002000HD    0000273900Y
28833806X9K27G60000J9001000
28833806X9K27G60000J7001000
28833807A9K27G60000JAS001000QID   0000382400Y
28833808A9K27G60000JBB001000QQQQ  0000495200Y
28833809X9K27G60000JB001000
28833820X9K27G60000G7002000
28833820A9K27G60000G7S002000QQQQ  0000495700Y
28833869X9K27G60000FX002000
28833869A9K27G60000JCB002000QQQQ  0000495100Y
28833868X6K27GA000025000500
28833868A6K27GA000025B000500IWM   0000735800Y
28833869A6K27GA00004BS002000IWM   0000736600Y
28833869X6K27GA00003O002000
28833871A9K27G60000JDB002000QQQQ  0000495100Y
28833870X6K27GA000025000500
28833870A6K27GA000025B000500IWM   0000736200Y
28833872X6K27GA000025000500
28833872A6K27GA000025B000500IWM   0000735800Y
28833876X6K27GA000025000500
28833876A6K27GA000025B000500IWM   0000736200Y
28833886X6K27GA000025000500
28833886A6K27GA000025B000500IWM   0000735800Y
28833890XBK27GA0000AB000100
28833890XBK27GA0000AC000100
28833892ABK27GA0000AES000100TWM   0000702800Y
28833891X6K27GA000025000500
28833891A6K27GA000025B000500IWM   0000736200Y
28833893ABK27GA0000AFB000100UWM   0000542000Y
28833894XBK27GA0000AE000100
28833894ABK27GA0000AGS000100TWM   0000702600Y
28833895X6K27GA000025000500
28833895A6K27GA000025B000500IWM   0000735800Y
28833898XBK27GA0000AF000100
28833897X6K27GA000025000500
28833897A6K27GA000025B000500IWM   0000736200Y
28833898XBK27GA0000AG000100
28833900ABK27GA0000AHB000100UWM   0000542000Y
28833900ABK27GA0000AIS000100TWM   0000702600Y
28833900X6K27GA000025000500
28833900A6K27GA000025B000500IWM   0000735800Y
28833903XBK27GA0000AH000100
28833903XBK27GA0000AI000100
28833905ABK27GA0000AJS000100TWM   0000702800Y
28833905X6K27GA000025000500
28833905A6K27GA000025B000500IWM   0000736200Y
28833907ABK27GA0000AKB000100UWM   0000542000Y
28833907XBK27GA0000AJ000100
28833907ABK27GA0000ALS000100TWM   0000702600Y
28833908X9K27G60000IK001000
28833907X6K27GA000025000500
28833907A6K27GA000025B000500IWM   0000735800Y
28833910XBK27GA0000AK000100
28833910XBK27GA0000AL000100
28833912ABK27GA0000AMS000100TWM   0000702800Y
28833915X6K27GA000025000500
28833915A6K27GA000025B000500IWM   0000736200Y
28833918ABK27GA0000ANB000100UWM   0000542000Y
28833918ABK27GA0000AOS000100TWM   0000702600Y
28833918XBK27GA0000AM000100
28833920X6K27GA000025000500
28833920A6K27GA000025B000500IWM   0000735800Y
28833926X6K27GA000025000500
28833926A6K27GA000025B000500IWM   0000736200Y
28833927X6K27GA000025000500
28833927A6K27GA000025B000500IWM   0000735800Y
28833931A9K27G60000JEB002000QQQQ  0000495300Y
28833938XBK27GA0000AN000100
28833938XBK27GA0000AO000100
28833937X6K27GA000025000500
28833937A6K27GA000025B000500IWM   0000736200Y
28833940ABK27GA0000APS000100TWM   0000702800Y
28833940X6K27GA000025000500
28833940A6K27GA000025B000500IWM   0000735800Y
28833945X6K27GA000025000500
28833945A6K27GA000025B000500IWM   0000736200Y
28833947X6K27GA000025000500
28833947A6K27GA000025B000500IWM   0000735800Y
28833950X6K27GA000025000500
28833950A6K27GA000025B000500IWM   0000736200Y
28833951XAK27GA0000LR001000
28833951AAK27GA0000NMS001000SPY   0001425200Y
28833951XAK27GA0000N4001000
28833953X6K27GA000025000500
28833953A6K27GA000025B000500IWM   0000735800Y
28833955X6K27GA000025000500
28833955A6K27GA000025B000500IWM   0000736200Y
28833959X9K27G60000JE002000
28833957X6K27GA000025000500
28833957A6K27GA000025B000500IWM   0000735800Y
28833960XAK27GA0000E5001000
28833960AAK27GA0000E5S001000SPY   0001425200Y
28833964X4K27GA00007T000100
28833964X3K27G6000034000100
28833968ABK27GA0000AQB000100UWM   0000542000Y
28833968XBK27GA0000AP000100
28833968X4K27GA00007S000200
28833968ABK27GA0000ARS000100TWM   0000702600Y
28833967X6K27GA000025000500
28833967A6K27GA000025B000500IWM   0000736200Y
28833970X6K27GA000025000500
28833970A6K27GA000025B000500IWM   0000735800Y
28833976X6K27GA000025000500
28833976A6K27GA000025B000500IWM   0000736200Y
28833986X6K27GA000025000500
28833986A6K27GA000025B000500IWM   0000735800Y
28833988XBK27GA0000AQ000100
28833988XBK27GA0000AR000100
28833990A9K27G60000JFB002000QQQQ  0000495300Y
28833990ABK27GA0000ASS000100TWM   0000702800Y
28833990X6K27GA000025000500
28833990A6K27GA000025B000500IWM   0000736200Y
28833995X6K27GA000025000500
28833995A6K27GA000025B000500IWM   0000735800Y
28833997X6K27GA000025000500
28833997A6K27GA000025B000500IWM   0000736200Y
28834006X6K27GA000025000500
28834006A6K27GA000025B000500IWM   0000735800Y
28834008ABK27GA0000ATB000100UWM   0000542000Y
28834008XBK27GA0000AS000100
28834008ABK27GA0000AUS000100TWM   0000702600Y
28834023A9K27G60000JGS002000QQQQ  0000495800Y
28834028XBK27GA0000AT000100
28834028XBK27GA0000AU000100
28834030X9K27G60000JF002000
28834030ABK27GA0000AVS000100TWM   0000702800Y
28834048ABK27GA0000AWB000100UWM   0000542000Y
28834048XBK27GA0000AV000100
28834048ABK27GA0000AXS000100TWM   0000702600Y
28834051XAK27GA0000FD000500
28834051AAK27GA0000FDB000500SPY   0001424600Y
28834051A4K27GA00007US000200DIA   0001298400Y
28834053A4K27GA00007VB000100DXD   0000499800Y
28834053A3K27G6000035S000100DDM   0000802000Y
28834057XBK27GA00009N001000
28834057XAK27GA0000HD000100
28834057XAK27GA0000N5000100
28834057AAK27GA0000NNS000100SPY   0001426300Y
28834059AAK27GA0000NOB000100SPY   0001424100Y
28834068XBK27GA0000AW000100
28834068XBK27GA0000AX000100
28834069A6K27GA00004CB000100IWM   0000735700Y
28834069X6K27GA00004C000100
28834070ABK27GA0000AYS000100TWM   0000702800Y
28834078ABK27GA0000AZB000100UWM   0000542000Y
28834078XBK27GA0000AY000100
28834078XBK27GA0000AZ000100
28834078ABK27GA0000B0S000100TWM   0000702600Y
28834078XBK27GA0000B0000100
28834080ABK27GA0000B1S000100TWM   0000702800Y
28834108ABK27GA0000B2B000100UWM   0000542000Y
28834108ABK27GA0000B3S000100TWM   0000702600Y
28834108XBK27GA0000B1000100
28834130XBK27GA0000B3000100
28834130XBK27GA0000B2000100
28834131XAK27GA0000FD000500
28834131AAK27GA0000FDB000500SPY   0001425000Y
28834132ABK27GA0000B4S000100TWM   0000702800Y
28834138ABK27GA0000B5B000100UWM   0000542000Y
28834138ABK27GA0000B6S000100TWM   0000702600Y
28834138XBK27GA0000B4000100
28834148XBK27GA0000B5000100
28834148XBK27GA0000B6000100
28834150ABK27GA0000B7B000100UWM   0000542000Y
28834150ABK27GA0000B8S000100TWM   0000702600Y
28834158XBK27GA0000B7000100
28834158XBK27GA0000B8000100
28834160ABK27GA0000B9S000100TWM   0000702800Y
28834158A6K27GA00004DB000100IWM   0000735700Y
28834159X6K27GA00004D000100
28834305XAK27GA0000NN000100
28834307AAK27GA0000NPS000100SPY   0001426900Y
28834324X6K27GA00002B000500
28834324A6K27GA00002BS000500IWM   0000736800Y
28834326A6K27GA00004EB002000IWM   0000736100Y
28834326X6K27GA00004B002000
28834329XBK27GA00009E000100
28834329XBK27GA00009F000100
28834329XBK27GA00009G000100
28834329A6K27GA00004FS000100IWM   0000736900Y
28834333ABK27GA0000BAB000100UWM   0000542100Y
28834333ABK27GA0000BBS000100TWM   0000702400Y
28834334X6K27GA00004F000100
28834337XBK27GA0000BA000100
28834337XBK27GA0000BB000100
28834339ABK27GA0000BCB000100UWM   0000542100Y
28834339XBK27GA0000B9000100
28834339ABK27GA0000BDS000100TWM   0000702400Y
28834345X6K27GA000025000500
28834345A6K27GA00004GB000500IWM   0000736300Y
28834347X6K27GA00002C000500
28834347A6K27GA00002CB000500IWM   0000736200Y
28834350X6K27GA00004G000500
28834350A6K27GA00004GB000500IWM   0000735900Y
28834353XBK27GA0000BC000100
28834354XBK27GA0000BD000100
28834355ABK27GA0000BEB000100UWM   0000542000Y
28834354A6K27GA00004HB000100IWM   0000735800Y
28834355ABK27GA0000BFS000100TWM   0000702600Y
28834354X6K27GA00002B000500
28834354A6K27GA00002BS000500IWM   0000736400Y
28834354X6K27GA00004H000100
28834357ABK27GA0000BGS000100UWM   0000542900Y
28834357ABK27GA0000BHB000100TWM   0000701600Y
28834357ABK27GA0000BIB000100TWM   0000701500Y
28834365A3K27G6000036B002000CELG  0000464800Y
28834368X2K27G600000H002000
28834393X7K27GA00001R002000
28834395X7K27GA00001S002000
28834394X6K27GA00004E002000
28834405XAK27GA0000NP000100
28834406AAK27GA0000NQS000100SPY   0001426300Y
28834407X1K27GA00001K002000
28834412A6K27GA00004IB002000JNJ   0000639100Y
28834441A6K27GA00004JB002000IMCL  0000314900Y
28834442ABK27GA0000BJB002000UTX   0000061100Y
28834444ABK27GA0000BKB002000TGT   0000516900Y
28834466ABK27GA0000BLB002000UTX   0000060300Y
28834481AAK27GA0000NRB002000SHLD  0000671200Y
28834483XCK27GA000024002000
28834508A1K27GA00003JB002000ABT   0000044600Y
28834510A3K27G6000037B002000CTSH  0000020400Y
28834518A9K27G60000JHB002000QQQQ  0000495300Y
28834520ACK27GA000025B002000WYE   0000032600Y
28834538X1K27GA00003I002000
28834552A7K27GA00001TB002000LPNT  0000184500Y
28834564A1K27GA00003KB002000ABT   0000043800Y
28834573X1K27GA00003H002000
28834574A2K27G600002FB002000BBT   0000024300Y
28834590X2K27G600002C002000
28834613X4K27GA00007R002000
28834620A3K27G6000038B002000COH   0000025800Y
28834636A3K27G6000039B002000CVS   0000032400Y
28834647A3K27G600003AB002000DD    0000454400Y
28834661X6K27GA00001Q000100
28834661A6K27GA00004KS000100IYM   0000872800Y
28834664X2K27G600002A002000
28834667A6K27GA00004LB000100IYM   0000868400Y
28834674X6K27GA00004L000100
28834676A6K27GA00004MB000100IYM   0000867400Y
28834676X6K27GA00004M000100
28834676A6K27GA00004NB000100IYM   0000868600Y
28834681X3K27G600002X002000
28834683A5K27GA000025B002000HIG   0000676100Y
28834684X3K27G6000033002000
28834712A4K27GA00007WB002000EIX   0000036600Y
28834758A6K27GA00004OB002000IWM   0000736100Y
28834938XAK27GA0000E5001000
28834938AAK27GA0000E5S001000SPY   0001425600Y
28834938X4K27GA00007U000200
28834939XAK27GA0000LQ002000
28834939XAK27GA0000NG003000
28834939XAK27GA0000MZ003000
28834940X9K27G60000G7002000
28834940A9K27G60000G7S002000QQQQ  0000496100Y
28834939XAK27GA0000NH003000
28834939XAK27GA0000N1003000
28834940X4K27GA00007V000100
28834940X3K27G6000035000100
28834940AAK27GA0000NSB002000SPY   0001424800Y
28834940AAK27GA0000NTB003000SPY   0001424900Y
28834940AAK27GA0000NUB003000SPY   0001424900Y
28834941AAK27GA0000NVS003000SPY   0001425800Y
28834941AAK27GA0000NWB002000SPY   0001425000Y
28834941X4K27GA00003H000200
28834941A4K27GA00003HB000200DIA   0001298300Y
28834941AAK27GA0000NXS003000SPY   0001425800Y
28834941A4K27GA00007XS000200DIA   0001298700Y
28834941AAK27GA0000NYS000500SPY   0001425400Y
28834941AAK27GA0000NZS000500SPY   0001425400Y
28834942XAK27GA0000EW000500
28834942AAK27GA0000EWS000500SPY   0001425500Y
28834942A4K27GA00007YS000100DXD   0000500500Y
28834942A3K27G600003BB000100DDM   0000800600Y
28834942XAK27GA0000F7000500
28834942AAK27GA0000F7B000500SPY   0001425000Y
28834943AAK27GA0000O0S000100SH    0000619100Y
28834943XAK27GA0000MU001000
28834943XBK27GA00009V001000
28834943ABK27GA0000BMB001000SSO   0000763900Y
28834943XAK27GA0000EB001000
28834943AAK27GA0000EBB001000SPY   0001425000Y
28834943AAK27GA0000O1S000500SPY   0001425300Y
28834943AAK27GA0000O2S000500SPY   0001425500Y
28834943XAK27GA0000N0000900
28834943AAK27GA0000O3B001000SPY   0001425000Y
28834944AAK27GA0000O4S001000SPY   0001425600Y
28834944XAK27GA0000F7000500
28834944AAK27GA0000F7B000500SPY   0001424700Y
28834945XAK27GA0000NI001000
28834945XBK27GA0000AD001000
28834945AAK27GA0000O5S000500SPY   0001425600Y
28834945AAK27GA0000O6S000500SPY   0001425600Y
28834946XAK27GA0000NL001000
28834946AAK27GA0000O7B001000SDS   0000547900Y
28834947XAK27GA0000NJ001000
28834947ABK27GA0000BNS001000SSO   0000764800Y
28834947AAK27GA0000O8S000500SPY   0001425700Y
28834948AAK27GA0000O9B001000SDS   0000547800Y
28834956XAK27GA0000N8001000
28834956X9K27G60000JG002000
28834957XAK27GA0000NM001000
28834958XAK27GA0000NF001000
28834967X9K27G60000G2002000
28834967A9K27G60000G2B002000QQQQ  0000495500Y
28834969A9K27G60000JIB002000QQQQ  0000495300Y
28834967X6K27GA00002B000500
28834967A6K27GA00002BS000500IWM   0000736800Y
28834970A9K27G60000JJS001000QID   0000382200Y
28834970A9K27G60000JKB001000QLD   0000888500Y
28834970XBK27GA00009U001000
28834970ABK27GA0000BOB001000SSO   0000763700Y
28834971X6K27GA00004G000500
28834971A6K27GA00004GB000500IWM   0000736300Y
28834973A9K27G60000JLB001000QLD   0000888600Y
28834973X9K27G60000JK001000
28834973X4K27GA000076000047
28834974ABK27GA0000BPB000100UWM   0000542100Y
28834974ABK27GA0000BQS000100TWM   0000702400Y
28834974XBK27GA0000BF000100
28834975A4K27GA00007ZS000047DIA   0001298800Y
28834975X6K27GA00004G000500
28834975A6K27GA00004GB000500IWM   0000735900Y
28834977XAK27GA0000NA001000
28834978XBK27GA0000BG000100
28834978XBK27GA0000BH000100
28834978XBK27GA0000BI000100
28834979A9K27G60000JMB001000QQQQ  0000495200Y
28834979X9K27G60000JM001000
28834978X6K27GA00004G000500
28834978A6K27GA00004GB000500IWM   0000736300Y
28834979AAK27GA0000OAS001000SPY   0001425400Y
28834979A6K27GA00004PS000100IWM   0000736900Y
28834980X6K27GA00004G000500
28834980A6K27GA00004GB000500IWM   0000735900Y
28834983X4K27GA00007I000100
28834984X4K27GA00006Z000100
28834984X3K27G600002Z000100
28834984X6K27GA00004G000500
28834984A6K27GA00004GB000500IWM   0000736300Y
28834984X6K27GA00004P000100
28834986X9K27G60000J4005000
28834986X9K27G60000F2003200
28834986A9K27G60000F2S003200QQQQ  0000496200Y
28834986X9K27G60000J5005000
28834987A9K27G60000JNB005000QQQQ  0000495600Y
28834987A9K27G60000JOB005000QQQQ  0000495600Y
28834988A9K27G60000JPB001000QLD   0000888500Y
28834986X6K27GA00004G000500
28834986A6K27GA00004GB000500IWM   0000735900Y
28834990X6K27GA00004G000500
28834990A6K27GA00004GB000500IWM   0000736300Y
28834993XAK27GA0000FG000500
28834993AAK27GA0000FGB000500SPY   0001425000Y
28834993X6K27GA00004G000500
28834993A6K27GA00004GB000500IWM   0000735900Y
28834997X6K27GA00004G000500
28834997A6K27GA00004GB000500IWM   0000736300Y
28834999XBK27GA0000BP000100
28834999XBK27GA0000BQ000100
28835000A9K27G60000JQB002000QQQQ  0000495600Y
28835001ABK27GA0000BRB000100UWM   0000542100Y
28834999X6K27GA00004G000500
28834999A6K27GA00004GB000500IWM   0000735900Y
28834999A6K27GA00004QB000100IWM   0000735800Y
28835000X6K27GA00004Q000100
28835001ABK27GA0000BSS000100TWM   0000702400Y
28835001X6K27GA00004G000500
28835001A6K27GA00004GB000500IWM   0000736300Y
28835003XBK27GA0000BR000100
28835003XBK27GA0000BS000100
28835005ABK27GA0000BTB000100UWM   0000542100Y
28835005ABK27GA0000BUS000100TWM   0000702400Y
28835004X6K27GA00004G000500
28835004A6K27GA00004GB000500IWM   0000735900Y
28835006XAK27GA0000OA001000
28835008A8K27G600001JS000500MZZ   0000494200Y
28835008A8K27G600001KB000100MVV   0000805800Y
28835008XBK27GA0000BT000100
28835008XBK27GA0000BU000100
28835008AAK27GA0000OBS001000SPY   0001425500Y
28835007X6K27GA00004G000500
28835007A6K27GA00004GB000500IWM   0000736300Y
28835010ABK27GA0000BVS000100TWM   0000702600Y
28835008A6K27GA00004RB000100IWM   0000735800Y
28835009X6K27GA00004R000100
28835010AAK27GA0000OCS001000SPY   0001425600Y
28835011ABK27GA0000BWB000100UWM   0000542100Y
28835011XBK27GA0000BV000100
28835010XAK27GA0000OB001000
28835011ABK27GA0000BXS000100TWM   0000702400Y
28835010X6K27GA00004G000500
28835010A6K27GA00004GB000500IWM   0000735900Y
28835012AAK27GA0000ODS001000SPY   0001425600Y
28835013XBK27GA0000BW000100
28835013XBK27GA0000BX000100
28835012X6K27GA00004G000500
28835012A6K27GA00004GB000500IWM   0000736300Y
28835013A6K27GA00004SB000100IWM   0000735800Y
28835015ABK27GA0000BYS000100TWM   0000702600Y
28835014X6K27GA00004S000100
28835015XAK27GA0000MX000100
28835014X6K27GA00004G000500
28835014A6K27GA00004GB000500IWM   0000735900Y
28835016XBK27GA0000BN001000
28835016XAK27GA0000O7001000
28835018ABK27GA0000BZS001000SSO   0000764900Y
28835016X6K27GA00004G000500
28835016A6K27GA00004GB000500IWM   0000736300Y
28835018XBK27GA0000BY000100
28835018ABK27GA0000C0S000100TWM   0000702400Y
28835018ABK27GA0000C1B000100UWM   0000542100Y
28835018XBK27GA0000C1000100
28835019XBK27GA0000C0000100
28835020ABK27GA0000C2S000100TWM   0000702600Y
28835039XAK27GA0000EB001000
28835039AAK27GA0000EBB001000SPY   0001425100Y
28835039XAK27GA0000O3001000
28835039AAK27GA0000O3B001000SPY   0001425100Y
28835039XAK27GA0000FG000500
28835039AAK27GA0000FGB000500SPY   0001425100Y
28835048XAK27GA0000NW002000
28835059X9K27G60000EU002000
28835059A9K27G60000EUB002000QQQQ  0000495600Y
28835060X6K27GA00004G000500
28835060A6K27GA00004GB000500IWM   0000735900Y
28835068ABK27GA0000C3B000100UWM   0000542100Y
28835068ABK27GA0000C4S000100TWM   0000702400Y
28835068XBK27GA0000C2000100
28835067X6K27GA00004G000500
28835067A6K27GA00004GB000500IWM   0000736300Y
28835070X6K27GA00004G000500
28835070A6K27GA00004GB000500IWM   0000735900Y
28835076X6K27GA00004G000500
28835076A6K27GA00004GB000500IWM   0000736300Y
28835081X6K27GA00004G000500
28835081A6K27GA00004GB000500IWM   0000735900Y
28835088XBK27GA0000C3000100
28835088XBK27GA0000C4000100
28835087X6K27GA00004G000500
28835087A6K27GA00004GB000500IWM   0000736300Y
28835090ABK27GA0000C5S000100TWM   0000702600Y
28835090X6K27GA00004G000500
28835090A6K27GA00004GB000500IWM   0000735900Y
28835094X9K27G60000JO005000
28835094X9K27G60000JN005000
28835095A9K27G60000JRB005000QQQQ  0000495200Y
28835096A9K27G60000JSB005000QQQQ  0000495200Y
28835095X6K27GA00004G000500
28835095A6K27GA00004GB000500IWM   0000736300Y
28835097X6K27GA00004G000500
28835097A6K27GA00004GB000500IWM   0000735900Y
28835103X9K27G60000EU002000
28835103A9K27G60000EUB002000QQQQ  0000495300Y
28835107X6K27GA00004G000500
28835107A6K27GA00004GB000500IWM   0000736300Y
28835119ABK27GA0000C6B000100UWM   0000542100Y
28835119XBK27GA0000C5000100
28835119ABK27GA0000C7S000100TWM   0000702400Y
28835117X6K27GA00004G000500
28835117A6K27GA00004GB000500IWM   0000735900Y
28835126X6K27GA00004G000500
28835126A6K27GA00004GB000500IWM   0000736300Y
28835128XBK27GA0000C6000100
28835128XBK27GA0000C7000100
28835130ABK27GA0000C8S000100TWM   0000702600Y
28835135X6K27GA00004G000500
28835135A6K27GA00004GB000500IWM   0000735900Y
28835138ABK27GA0000C9B000100UWM   0000542100Y
28835138ABK27GA0000CAS000100TWM   0000702400Y
28835138XBK27GA0000C8000100
28835140X6K27GA00004G000500
28835140A6K27GA00004GB000500IWM   0000736300Y
28835146X6K27GA00004G000500
28835146A6K27GA00004GB000500IWM   0000735900Y
28835148XBK27GA0000C9000100
28835148XBK27GA0000CA000100
28835150ABK27GA0000CBB000100UWM   0000542100Y
28835150ABK27GA0000CCS000100TWM   0000702400Y
28835150X6K27GA00004G000500
28835150A6K27GA00004GB000500IWM   0000736300Y
28835155X6K27GA00004G000500
28835155A6K27GA00004GB000500IWM   0000735900Y
28835157X6K27GA00004G000500
28835157A6K27GA00004GB000500IWM   0000736300Y
28835168XBK27GA0000CB000100
28835168XBK27GA0000CC000100
28835167X6K27GA00004G000500
28835167A6K27GA00004GB000500IWM   0000735900Y
28835170ABK27GA0000CDS000100TWM   0000702600Y
28835170X6K27GA00004G000500
28835170A6K27GA00004GB000500IWM   0000736300Y
28835176X6K27GA00004G000500
28835176A6K27GA00004GB000500IWM   0000735900Y
28835177X6K27GA00004G000500
28835177A6K27GA00004GB000500IWM   0000736300Y
28835186X6K27GA00004G000500
28835186A6K27GA00004GB000500IWM   0000735900Y
28835196X6K27GA00004G000500
28835196A6K27GA00004GB000500IWM   0000736300Y
28835198ABK27GA0000CEB000100UWM   0000542100Y
28835198ABK27GA0000CFS000100TWM   0000702400Y
28835198XBK27GA0000CD000100
28835200X6K27GA00004G000500
28835200A6K27GA00004GB000500IWM   0000735900Y
28835204X9K27G60000JR005000
28835204X9K27G60000JS005000
28835204A9K27G60000JTB005000QQQQ  0000495600Y
28835204A9K27G60000JUB005000QQQQ  0000495600Y
28835206X6K27GA00004G000500
28835206A6K27GA00004GB000500IWM   0000736300Y
28835208XBK27GA0000CE000100
28835208XBK27GA0000CF000100
28835210ABK27GA0000CGB000100UWM   0000542100Y
28835210ABK27GA0000CHS000100TWM   0000702400Y
28835209X6K27GA00004G000500
28835209A6K27GA00004GB000500IWM   0000735900Y
28835213X9K27G60000EU002000
28835213A9K27G60000EUB002000QQQQ  0000495600Y
28835215X6K27GA00004G000500
28835215A6K27GA00004GB000500IWM   0000736300Y
28835216X6K27GA00004G000500
28835216A6K27GA00004GB000500IWM   0000735900Y
28835218XBK27GA0000CG000100
28835218XBK27GA0000CH000100
28835220ABK27GA0000CIS000100TWM   0000702600Y
28835219X6K27GA00004G000500
28835219A6K27GA00004GB000500IWM   0000736300Y
28835221X6K27GA00004G000500
28835221A6K27GA00004GB000500IWM   0000735900Y
28835226X6K27GA00004G000500
28835226A6K27GA00004GB000500IWM   0000736300Y
28835227X6K27GA00004G000500
28835227A6K27GA00004GB000500IWM   0000735900Y
28835286X9K27G60000JT005000
28835286X9K27G60000JU005000
28835288A9K27G60000JVB005000QQQQ  0000495200Y
28835288A9K27G60000JWB005000QQQQ  0000495200Y
28835293X9K27G60000EU002000
28835293A9K27G60000EUB002000QQQQ  0000495300Y
28835395XAK27GA0000NR002000
28835400X7K27GA00000L002000
28835407XAK27GA0000MB002000
28835414X2K27G600002D002000
28835418A2K27G600002GB002000BRL   0000371500Y
28835430X7K27GA00000Q002000
28835460XBK27GA0000BL002000
28835461XBK27GA000019002000
28835466A1K27GA00003LB002000APOL  0000405400Y
28835481XBK27GA0000BJ002000
28835482XCK27GA000025002000
28835501X1K27GA00003K002000
28835511A7K27GA00001UB002000LMT   0000098300Y
28835522A7K27GA00001VB002000LMT   0000099100Y
28835527X1K27GA00003J002000
28835539X2K27G6000023002000
28835543X2K27G600002E002000
28835554X3K27G600001Z002000
28835558X4K27GA00007W002000
28835557ACK27GA000026B002000WYE   0000034600Y
28835586X2K27G6000024002000
28835588A1K27GA00003MB002000AFL   0000057100Y
28835593X4K27GA00007P000100
28835594X4K27GA00007Q000100
28835598A2K27G600002HB002000BBT   0000024400Y
28835598A4K27GA000080B000100DRYS  0001067100Y
28835598A4K27GA000081B000100DRYS  0001067100Y
28835609A3K27G600003CB002000COH   0000026000Y
28835619A3K27G600003DB002000CVS   0000032800Y
28835645A1K27GA00003NB002000AFL   0000057900Y
28835652X3K27G6000039002000
28835655A5K27GA000026B002000HNZ   0000035000Y
28835678A5K27GA000027B002000HON   0000595300Y
28835691A2K27G600002IB002000CAG   0000014500Y
28835702A5K27GA000028B002000HOT   0000035600Y
28835731A4K27GA000082B002000EIX   0000038800Y
28835758A5K27GA000029B002000HMY   0000083700Y
28835776A5K27GA00002AB002000HMA   0000063800Y
28835788A5K27GA00002BB002000HNZ   0000035800Y
28835793X9K27G60000JV005000
28835800A5K27GA00002CB002000HON   0000596100Y
28835892A9K27G60000JXB005000QQQQ  0000495600Y
28835955X9K27G60000JX005000
28835992A9K27G60000JYB005000QQQQ  0000495200Y
28836109X9K27G60000JY005000
28836109X9K27G60000IU005000
28836109X9K27G60000IT005000
28836109X9K27G60000JW005000
28836109A9K27G60000JZB005000QQQQ  0000495600Y
28836109A9K27G60000K0B005000QQQQ  0000495600Y
28836110X9K27G60000EU002000
28836110A9K27G60000EUB002000QQQQ  0000495600Y
28836110A9K27G60000K1S005000QQQQ  0000496100Y
28836110A9K27G60000K2S005000QQQQ  0000496100Y
28836191X9K27G60000K0005000
28836191X9K27G60000K2005000
28836191X9K27G60000K1005000
28836191A9K27G60000K3S005000QQQQ  0000495700Y
28836191A9K27G60000K4S005000QQQQ  0000495700Y
28836192A9K27G60000K5B005000QQQQ  0000495200Y
28836203X9K27G60000EU002000
28836203A9K27G60000EUB002000QQQQ  0000495300Y
28836354X6K27GA00004J002000
28836389AAK27GA0000OEB002000SHLD  0000676300Y
28836394X7K27GA00001U002000
28836416A2K27G600002JB002000BMY   0000013700Y
28836418X1K27GA00003M002000
28836428X3K27G600003D002000
28836445X6K27GA00002M002000
28836462X5K27GA000026002000
28836471AAK27GA0000OFB002000SPLS  0000013500Y
28836472X5K27GA000028002000
28836483A7K27GA00001WB002000KSS   0000454100Y
28836501A7K27GA00001XB002000KSS   0000454900Y
28836524X7K27GA00001V002000
28836528ABK27GA0000CJB002000UTX   0000064300Y
28836549ACK27GA000027B002000WYE   0000035000Y
28836553ABK27GA0000CKB002000TGT   0000517800Y
28836573A1K27GA00003OB002000ABT   0000046800Y
28836581ABK27GA0000CLB002000UTX   0000065100Y
28836587XCK27GA000026002000
28836603A1K27GA00003PB002000ABT   0000047700Y
28836607X1K27GA00003N002000
28836621X2K27G600002F002000
28836626A2K27G600002KB002000BDX   0000756900Y
28836640A2K27G600002LB002000CAG   0000014300Y
28836646A2K27G600002MB002000BDX   0000757700Y
28836654X3K27G6000038002000
28836668A3K27G600003EB002000DD    0000453800Y
28836679A3K27G600003FB002000CVS   0000034800Y
28836684A4K27GA000083B002000EIX   0000039400Y
28836690X4K27GA000082002000
28836702X5K27GA00002B002000
28836853AAK27GA0000OGS002000SPY   0001425300Y
28836853XAK27GA0000O5000500
28836853AAK27GA0000O5S000500SPY   0001425200Y
28836853XAK27GA0000EB001000
28836853AAK27GA0000EBB001000SPY   0001424700Y
28836853XAK27GA0000O8000500
28836853AAK27GA0000O8S000500SPY   0001425300Y
28836853XAK27GA0000FG000500
28836853AAK27GA0000FGB000500SPY   0001424700Y
28836854XAK27GA0000NS001000
28836854XAK27GA0000O4001000
28836854AAK27GA0000OHS001000SPY   0001425200Y
28836855AAK27GA0000OIB000100SH    0000618500Y
28836855AAK27GA0000OJB001000SDS   0000547900Y
28836856ABK27GA0000CMS001000SSO   0000764800Y
28836856XBK27GA0000BZ001000
28836867X9K27G60000K3005000
28836867X9K27G60000K5005000
28836867X9K27G60000K4005000
28836868A9K27G60000K6B005000QQQQ  0000495600Y
28836869A9K27G60000K7S005000QQQQ  0000496100Y
28836869X9K27G60000EU002000
28836869A9K27G60000EUB002000QQQQ  0000495600Y
28836869A9K27G60000K8S005000QQQQ  0000496100Y
28836873XAK27GA0000EX000500
28836873AAK27GA0000EXB000500SPY   0001424600Y
28836873X4K27GA00007Z000047
28836873XAK27GA0000NV003000
28836873XAK27GA0000NT003000
28836873XAK27GA0000NX003000
28836873XAK27GA0000O3001000
28836873XAK27GA0000NU003000
28836874ABK27GA0000CNB000100UWM   0000542100Y
28836874XBK27GA0000CI000100
28836874AAK27GA0000OKS003000SPY   0001425200Y
28836874ABK27GA0000COS000100TWM   0000702400Y
28836874XAK27GA0000NS001000
28836874AAK27GA0000OLS001000SPY   0001425400Y
28836874AAK27GA0000OMB001000SPY   0001424700Y
28836874AAK27GA0000ONS003000SPY   0001425200Y
28836875XBK27GA0000BO001000
28836875AAK27GA0000OOB003000SPY   0001424300Y
28836875AAK27GA0000OPB001000SPY   0001424700Y
28836875AAK27GA0000OQB003000SPY   0001424300Y
28836876XBK27GA0000BM001000
28836876AAK27GA0000ORB001000SPY   0001424700Y
28836877ABK27GA0000CPB001000SSO   0000763600Y
28836878ABK27GA0000CQB001000SSO   0000763800Y
28836878XAK27GA0000E5001000
28836878AAK27GA0000E5S001000SPY   0001425200Y
28836882A4K27GA000084S000047DIA   0001298500Y
28836884XAK27GA0000O0000100
28836884A4K27GA000085B000100DXD   0000499700Y
28836886X6K27GA00004G000500
28836887XBK27GA0000CN000100
28836887XBK27GA0000CO000100
28836889ABK27GA0000CRS000100TWM   0000702600Y
28836889A6K27GA00004TB000500IWM   0000736300Y
28836890X4K27GA00003H000200
28836890A4K27GA00003HB000200DIA   0001298000Y
28836891ABK27GA0000CSB000100UWM   0000542100Y
28836891XBK27GA0000CR000100
28836891ABK27GA0000CTS000100TWM   0000702400Y
28836893A4K27GA000086B000100DOG   0000597200Y
28836894A3K27G600003GS000100DDM   0000802100Y
28836893X6K27GA00004T000500
28836893A6K27GA00004TB000500IWM   0000735900Y
28836896XBK27GA0000CS000100
28836896XBK27GA0000CT000100
28836898ABK27GA0000CUS000100TWM   0000702600Y
28836898AAK27GA0000OSB001000SDS   0000548000Y
28836898XBK27GA0000CM001000
28836899ABK27GA0000CVS001000SSO   0000764700Y
28836899AAK27GA0000OTB001000SDS   0000547900Y
28836914XAK27GA0000OL001000
28836914XAK27GA0000OD001000
28836914AAK27GA0000OUS001000SPY   0001425300Y
28836914XAK27GA0000OR001000
28836975XAK27GA0000OM001000
28836975XAK27GA0000FD000500
28836975AAK27GA0000FDB000500SPY   0001424600Y
28836976AAK27GA0000OVS001000SPY   0001425300Y
28837239X9K27G60000K7005000
28837239X9K27G60000K6005000
28837239X9K27G60000JZ005000
28837239X9K27G60000K8005000
28837241A9K27G60000K9S005000QQQQ  0000495700Y
28837241A9K27G60000KAS005000QQQQ  0000495700Y
28837241X9K27G60000G2002000
28837241A9K27G60000G2B002000QQQQ  0000495000Y
28837241A9K27G60000KBB005000QQQQ  0000495200Y
28837242A9K27G60000KCB005000QQQQ  0000495200Y
28837242X9K27G60000JQ002000
28837243X9K27G60000EU002000
28837243A9K27G60000EUB002000QQQQ  0000495300Y
28837244X9K27G60000JP001000
28837246A9K27G60000KDB001000QQQQ  0000495200Y
28837249X9K27G60000KD001000
28837253X9K27G60000JL001000
28837254A9K27G60000KEB001000QLD   0000888400Y
28837255A9K27G60000KFB001000QQQQ  0000495200Y
28837259X9K27G60000KF001000
28837277A9K27G60000KGS002000QQQQ  0000495800Y
28837309X9K27G60000KG002000
28837355XAK27GA0000OE002000
28837386X3K27G6000037002000
28837411XAK27GA0000LI002000
28837417A6K27GA00004UB002000IMCL  0000318100Y
28837419XBK27GA0000CJ002000
28837421XBK27GA0000CL002000
28837434XCK27GA000027002000
28837444X1K27GA00003P002000
28837446XAK27GA0000FD000500
28837446AAK27GA0000FDB000500SPY   0001425000Y
28837446XAK27GA0000OO003000
28837446XAK27GA0000OK003000
28837446XAK27GA0000ON003000
28837446XAK27GA0000OQ003000
28837446XAK27GA0000OV001000
28837447XAK27GA0000OU001000
28837447AAK27GA0000OWB002000SPY   0001424800Y
28837447AAK27GA0000OXB003000SPY   0001424900Y
28837447AAK27GA0000OYB003000SPY   0001424900Y
28837447AAK27GA0000OZS003000SPY   0001425800Y
28837447AAK27GA0000P0S003000SPY   0001425800Y
28837448AAK27GA0000P1S001000SPY   0001425400Y
28837448AAK27GA0000P2S001000SPY   0001425400Y
28837451XAK27GA0000E5001000
28837451AAK27GA0000E5S001000SPY   0001425600Y
28837451XAK27GA0000EX000500
28837451AAK27GA0000EXB000500SPY   0001425000Y
28837451X1K27GA00003O002000
28837454XAK27GA0000OS001000
28837455XBK27GA0000CV001000
28837456XAK27GA0000O9001000
28837456ABK27GA0000CWS001000SSO   0000764800Y
28837458AAK27GA0000P3B001000SDS   0000547800Y
28837461X4K27GA00003H000200
28837461A4K27GA00003HB000200DIA   0001298300Y
28837465XAK27GA0000OT001000
28837471X2K27G6000029002000
28837474X2K27G600002B002000
28837473X4K27GA000086000100
28837474X3K27G600003G000100
28837478XAK27GA0000NB001000
28837479XAK27GA0000OW001000
28837481XAK27GA0000P2001000
28837487X2K27G600002H002000
28837496X6K27GA00004T000500
28837496A6K27GA00004TB000500IWM   0000736300Y
28837499ABK27GA0000CXB000100UWM   0000542100Y
28837499ABK27GA0000CYS000100TWM   0000702400Y
28837499XBK27GA0000CU000100
28837500X6K27GA00004T000500
28837500A6K27GA00004TB000500IWM   0000735900Y
28837503XBK27GA0000CX000100
28837503XBK27GA0000CY000100
28837505ABK27GA0000CZS000100TWM   0000702600Y
28837506X2K27G6000014002000
28837505X6K27GA00004T000500
28837505A6K27GA00004TB000500IWM   0000736300Y
28837507ABK27GA0000D0B000100UWM   0000542100Y
28837507ABK27GA0000D1S000100TWM   0000702400Y
28837507XBK27GA0000CZ000100
28837506X6K27GA00004T000500
28837506A6K27GA00004TB000500IWM   0000735900Y
28837510XBK27GA0000D0000100
28837510XBK27GA0000D1000100
28837510A6K27GA00004VB000100IWM   0000735800Y
28837510X6K27GA00004V000100
28837512ABK27GA0000D2S000100TWM   0000702600Y
28837510X6K27GA00004T000500
28837510A6K27GA00004TB000500IWM   0000736300Y
28837513ABK27GA0000D3B000100UWM   0000542100Y
28837513XBK27GA0000D2000100
28837513ABK27GA0000D4S000100TWM   0000702400Y
28837514X3K27G600003C002000
28837514X6K27GA00004T000500
28837514A6K27GA00004TB000500IWM   0000735900Y
28837517XBK27GA0000D3000100
28837517XBK27GA0000D4000100
28837516X6K27GA00004T000500
28837516A6K27GA00004TB000500IWM   0000736300Y
28837519ABK27GA0000D5B000100UWM   0000542100Y
28837519ABK27GA0000D6S000100TWM   0000702400Y
28837518X6K27GA00004T000500
28837518A6K27GA00004TB000500IWM   0000735900Y
28837522XBK27GA0000D5000100
28837522XBK27GA0000D6000100
28837522A6K27GA00004WB000100IWM   0000735800Y
28837524ABK27GA0000D7S000100TWM   0000702600Y
28837522X6K27GA00004W000100
28837522X6K27GA00004T000500
28837522A6K27GA00004TB000500IWM   0000736300Y
28837525ABK27GA0000D8B000100UWM   0000542100Y
28837525ABK27GA0000D9S000100TWM   0000702400Y
28837525XBK27GA0000D7000100
28837525X6K27GA00004T000500
28837525A6K27GA00004TB000500IWM   0000735900Y
28837527X6K27GA00004T000500
28837527A6K27GA00004TB000500IWM   0000736300Y
28837529XBK27GA0000D8000100
28837529XBK27GA0000D9000100
28837531ABK27GA0000DAB000100UWM   0000542100Y
28837531ABK27GA0000DBS000100TWM   0000702400Y
28837534XAK27GA0000OW001000
28837535X4K27GA000083002000
28837535X2K27G600002I002000
28837535X6K27GA00004T000500
28837535A6K27GA00004TB000500IWM   0000735900Y
28837536AAK27GA0000P4B001000SPY   0001424700Y
28837536X6K27GA00004T000500
28837536A6K27GA00004TB000500IWM   0000736300Y
28837538XBK27GA0000DA000100
28837538XBK27GA0000DB000100
28837540ABK27GA0000DCB000100UWM   0000542100Y
28837538A6K27GA00004XB000100IWM   0000735800Y
28837538X6K27GA00004X000100
28837540ABK27GA0000DDS000100TWM   0000702400Y
28837539X6K27GA00004T000500
28837539A6K27GA00004TB000500IWM   0000735900Y
28837545X6K27GA00004T000500
28837545A6K27GA00004TB000500IWM   0000736300Y
28837546X6K27GA00004T000500
28837546A6K27GA00004TB000500IWM   0000735900Y
28837548XBK27GA0000DC000100
28837548XBK27GA0000DD000100
28837550ABK27GA0000DES000100TWM   0000702400Y
28837550ABK27GA0000DFB000100UWM   0000542100Y
28837549X6K27GA00004T000500
28837549A6K27GA00004TB000500IWM   0000736300Y
28837554X3K27G600003F002000
28837555X6K27GA00004T000500
28837555A6K27GA00004TB000500IWM   0000735900Y
28837556X6K27GA00004T000500
28837556A6K27GA00004TB000500IWM   0000736300Y
28837559A7K27GA00001YB002000LMT   0000104300Y
28837566X6K27GA00004T000500
28837566A6K27GA00004TB000500IWM   0000735900Y
28837568XBK27GA0000DF000100
28837568XBK27GA0000DE000100
28837568A6K27GA00004YB000100IWM   0000735800Y
28837568X6K27GA00004Y000100
28837570ABK27GA0000DGS000100TWM   0000702600Y
28837569X6K27GA00004T000500
28837569A6K27GA00004TB000500IWM   0000736300Y
28837572A6K27GA00004ZB002000JNJ   0000640000Y
28837576A1K27GA00003QB002000AFL   0000060800Y
28837575X6K27GA00004T000500
28837575A6K27GA00004TB000500IWM   0000735900Y
28837576X6K27GA00004T000500
28837576A6K27GA00004TB000500IWM   0000736300Y
28837578ABK27GA0000DHB000100UWM   0000542100Y
28837578ABK27GA0000DIS000100TWM   0000702400Y
28837578XBK27GA0000DG000100
28837578XBK27GA0000DH000100
28837578XBK27GA0000DI000100
28837580ABK27GA0000DJS000100TWM   0000702600Y
28837579X6K27GA00004T000500
28837579A6K27GA00004TB000500IWM   0000735900Y
28837584A3K27G600003HB002000CVS   0000035200Y
28837585X6K27GA00004T000500
28837585A6K27GA00004TB000500IWM   0000736300Y
28837586X6K27GA00004T000500
28837586A6K27GA00004TB000500IWM   0000735900Y
28837596X6K27GA00004T000500
28837596A6K27GA00004TB000500IWM   0000736300Y
28837598ABK27GA0000DKB000100UWM   0000542100Y
28837598XBK27GA0000DJ000100
28837598ABK27GA0000DLS000100TWM   0000702400Y
28837599X6K27GA00004T000500
28837599A6K27GA00004TB000500IWM   0000735900Y
28837602A5K27GA00002DB002000HNZ   0000037600Y
28837605X6K27GA00004T000500
28837605A6K27GA00004TB000500IWM   0000736300Y
28837606X6K27GA00004T000500
28837606A6K27GA00004TB000500IWM   0000735900Y
28837608XBK27GA0000DK000100
28837608XBK27GA0000DL000100
28837610ABK27GA0000DMB000100UWM   0000542100Y
28837610ABK27GA0000DNS000100TWM   0000702400Y
28837609X6K27GA00004T000500
28837609A6K27GA00004TB000500IWM   0000736300Y
28837610A5K27GA00002EB002000HOT   0000038300Y
28837615X6K27GA00004T000500
28837615A6K27GA00004TB000500IWM   0000735900Y
28837616X6K27GA00004T000500
28837616A6K27GA00004TB000500IWM   0000736300Y
28837620A7K27GA00001ZB002000LMT   0000105100Y
28837624A5K27GA00002FB002000HUM   0000431500Y
28837626X6K27GA00004T000500
28837626A6K27GA00004TB000500IWM   0000735900Y
28837628XBK27GA0000DM000100
28837628XBK27GA0000DN000100
28837630ABK27GA0000DOS000100TWM   0000702600Y
28837629ACK27GA000028B002000WYE   0000037000Y
28837629X6K27GA00004T000500
28837629A6K27GA00004TB000500IWM   0000736300Y
28837635X6K27GA00004T000500
28837635A6K27GA00004TB000500IWM   0000735900Y
28837636X6K27GA00004T000500
28837636A6K27GA00004TB000500IWM   0000736300Y
28837644A6K27GA000050B002000IP    0000259900Y
28837646X6K27GA00004T000500
28837646A6K27GA00004TB000500IWM   0000735900Y
28837648ABK27GA0000DPB000100UWM   0000542100Y
28837648XBK27GA0000DO000100
28837648ABK27GA0000DQS000100TWM   0000702400Y
28837649X9K27G60000G2002000
28837649A9K27G60000G2B002000QQQQ  0000495500Y
28837649A9K27G60000KHB002000QQQQ  0000495600Y
28837649X9K27G60000KB005000
28837649X9K27G60000K9005000
28837649X9K27G60000KA005000
28837649X9K27G60000KC005000
28837650A9K27G60000KIB005000QQQQ  0000495600Y
28837650A9K27G60000KJB005000QQQQ  0000495600Y
28837650X9K27G60000KE001000
28837650A9K27G60000KKB001000QLD   0000888600Y
28837650X4K27GA000084000047
28837650X9K27G60000EU002000
28837650A9K27G60000EUB002000QQQQ  0000495600Y
28837651A9K27G60000KLB001000QLD   0000888500Y
28837651A9K27G60000KMS005000QQQQ  0000496100Y
28837651A9K27G60000KNS005000QQQQ  0000496100Y
28837651X4K27GA000085000100
28837652A9K27G60000KOB001000QQQQ  0000495200Y
28837653X9K27G60000EN002000
28837653A9K27G60000ENS002000QQQQ  0000496000Y
28837654X6K27GA00004T000500
28837654A6K27GA00004TB000500IWM   0000736300Y
28837657A1K27GA00003RB002000AFL   0000061600Y
28837656X6K27GA00004T000500
28837656A6K27GA00004TB000500IWM   0000735900Y
28837658XBK27GA0000DP000100
28837658XBK27GA0000DQ000100
28837659X9K27G60000KO001000
28837658X6K27GA00004T000500
28837658A6K27GA00004TB000500IWM   0000736300Y
28837660ABK27GA0000DRS000100TWM   0000702600Y
28837663A4K27GA000087S000047DIA   0001298800Y
28837662A6K27GA000051B002000IR    0000431500Y
28837664XAK27GA0000EX000500
28837664AAK27GA0000EXB000500SPY   0001424600Y
28837665XAK27GA0000F2000500
28837665AAK27GA0000F2B000500SPY   0001424500Y
28837665XAK27GA0000EW000500
28837665AAK27GA0000EWS000500SPY   0001425100Y
28837665XAK27GA0000OZ003000
28837665XAK27GA0000OX003000
28837665XAK27GA0000E4001000
28837665AAK27GA0000E4B001000SPY   0001424600Y
28837665XAK27GA0000E5001000
28837665AAK27GA0000E5S001000SPY   0001425200Y
28837665XAK27GA0000FD000500
28837665AAK27GA0000FDB000500SPY   0001424600Y
28837665XAK27GA0000P4001000
28837665XAK27GA0000O6000500
28837665AAK27GA0000O6S000500SPY   0001425200Y
28837665AAK27GA0000P5S003000SPY   0001425200Y
28837665XAK27GA0000P0003000
28837665XAK27GA0000OY003000
28837665AAK27GA0000P6S003000SPY   0001425200Y
28837666AAK27GA0000P7S002000SPY   0001425300Y
28837666X4K27GA00003H000200
28837666A4K27GA00003HB000200DIA   0001298000Y
28837666X4K27GA000087000047
28837666XAK27GA0000OJ001000
28837666AAK27GA0000P8B001000SDS   0000548000Y
28837666XAK27GA0000KE001000
28837667AAK27GA0000P9S001000SPY   0001425100Y
28837667AAK27GA0000PAB003000SPY   0001424300Y
28837668A2K27G600002NB002000BBT   0000027100Y
28837667AAK27GA0000PBB001000SPY   0001424600Y
28837667XBK27GA0000CW001000
28837667ABK27GA0000DSS001000SSO   0000764700Y
28837667AAK27GA0000PCB003000SPY   0001424300Y
28837668XAK27GA0000K1001000
28837668AAK27GA0000K1S001000SPY   0001425100Y
28837668AAK27GA0000PDB001000SDS   0000547900Y
28837671XAK27GA0000FE000500
28837671AAK27GA0000FEB000500SPY   0001424500Y
28837673XAK27GA0000F2000500
28837673AAK27GA0000F2B000500SPY   0001424900Y
28837673A4K27GA000088S000047DIA   0001298500Y
28837673A4K27GA000089B000100DOG   0000597200Y
28837673X4K27GA00007Y000100
28837673A4K27GA00008AB000100DXD   0000499700Y
28837674X3K27G600003B000100
28837674X3K27G600002I000100
28837674A3K27G600003IS000100DDM   0000802100Y
28837674XBK27GA0000CP001000
28837676X9K27G60000KM005000
28837676X9K27G60000KN005000
28837676X9K27G60000G2002000
28837676A9K27G60000G2B002000QQQQ  0000495000Y
28837677A9K27G60000KPS005000QQQQ  0000495700Y
28837677A9K27G60000KQS005000QQQQ  0000495700Y
28837678X9K27G60000EN002000
28837678A9K27G60000ENS002000QQQQ  0000495700Y
28837680X4K27GA00007X000200
28837684A4K27GA00008BS000200DIA   0001298400Y
28837685A4K27GA00008CB000100DXD   0000499800Y
28837686A3K27G600003JS000100DDM   0000802000Y
28837684A6K27GA000052B002000IRF   0000216300Y
28837688XAK27GA0000KF001000
28837688X6K27GA00004T000500
28837688A6K27GA00004TB000500IWM   0000735900Y
28837691A3K27G600003KB002000COH   0000028800Y
28837692AAK27GA0000PEB000600SPY   0001424600Y
28837694XAK27GA0000DU001000
28837694XBK27GA0000CQ001000
28837694ABK27GA0000DTB001000SSO   0000763500Y
28837696ABK27GA0000DUB001000SSO   0000763700Y
28837696AAK27GA0000PFS001000SDS   0000549400Y
28837698X8K27G600001J000500
28837698X8K27G600001K000100
28837707X6K27GA00002B000500
28837707A6K27GA00002BS000500IWM   0000736400Y
28837710ABK27GA0000DVS000100UWM   0000542900Y
28837710ABK27GA0000DWB000100TWM   0000701500Y
28837710ABK27GA0000DXB000100TWM   0000701600Y
28837727A4K27GA00008DB002000EIX   0000041600Y
28837739X6K27GA00004O002000
28837741A5K27GA00002GB002000HNZ   0000038400Y
28837754A5K27GA00002HB002000HOT   0000039100Y
28837786X9K27G60000KP005000
28837787A9K27G60000KRS005000QQQQ  0000496100Y
28837792X9K27G60000G2002000
28837792A9K27G60000G2B002000QQQQ  0000495500Y
28837793X9K27G60000EN002000
28837793A9K27G60000ENS002000QQQQ  0000496000Y
28837809X9K27G60000KJ005000
28837810X9K27G60000KI005000
28837810X9K27G60000G2002000
28837810A9K27G60000G2B002000QQQQ  0000495000Y
28837810X9K27G60000KR005000
28837810A9K27G60000KSS005000QQQQ  0000495700Y
28837810X9K27G60000EN002000
28837810A9K27G60000ENS002000QQQQ  0000495700Y
28837811A9K27G60000KTB005000QQQQ  0000495200Y
28837811A9K27G60000KUB005000QQQQ  0000495200Y
28837813X9K27G60000EU002000
28837813A9K27G60000EUB002000QQQQ  0000495300Y
28837908X9K27G60000KS005000
28837908X9K27G60000KT005000
28837908X9K27G60000KU005000
28837908A9K27G60000KVB005000QQQQ  0000495600Y
28837908A9K27G60000KWB005000QQQQ  0000495600Y
28837909X9K27G60000EU002000
28837909A9K27G60000EUB002000QQQQ  0000495600Y
28837909X9K27G60000G2002000
28837909A9K27G60000G2B002000QQQQ  0000495500Y
28837910A9K27G60000KXS005000QQQQ  0000496100Y
28837913X9K27G60000EN002000
28837913A9K27G60000ENS002000QQQQ  0000496000Y
28837919X4K27GA000080000100
28837928A4K27GA00008EB000100DRYS  0001068000Y
28837938X4K27GA000081000100
28837948A4K27GA00008FB000100DRYS  0001068000Y
28837958X4K27GA00008F000100
28837958A4K27GA00008GB000100DRYS  0001066900Y
28837986X9K27G60000KX005000
28837986X9K27G60000KV005000
28837986X9K27G60000KW005000
28837986X9K27G60000EN002000
28837986A9K27G60000ENS002000QQQQ  0000495700Y
28837986A9K27G60000KYS005000QQQQ  0000495700Y
28837986X9K27G60000G2002000
28837986A9K27G60000G2B002000QQQQ  0000495000Y
28837987A9K27G60000KZB005000QQQQ  0000495200Y
28837988A9K27G60000L0B005000QQQQ  0000495200Y
28838002X9K27G60000EU002000
28838002A9K27G60000EUB002000QQQQ  0000495300Y
28838066X9K27G60000KY005000
28838066X9K27G60000KZ005000
28838066X9K27G60000L0005000
28838066A9K27G60000L1B005000QQQQ  0000495600Y
28838066A9K27G60000L2B005000QQQQ  0000495600Y
28838067X9K27G60000EU002000
28838067A9K27G60000EUB002000QQQQ  0000495600Y
28838067X9K27G60000G2002000
28838067A9K27G60000G2B002000QQQQ  0000495500Y
28838067A9K27G60000L3S005000QQQQ  0000496100Y
28838073X9K27G60000EN002000
28838073A9K27G60000ENS002000QQQQ  0000496000Y
28838189XAK27GA0000K1001000
28838189AAK27GA0000K1S001000SPY   0001425500Y
28838189X4K27GA00008B000200
28838189XAK27GA0000EW000500
28838189AAK27GA0000EWS000500SPY   0001425500Y
28838189XAK27GA0000O6000500
28838189AAK27GA0000O6S000500SPY   0001425600Y
28838189XAK27GA0000FE000500
28838189AAK27GA0000FEB000500SPY   0001424900Y
28838189XAK27GA0000P9001000
28838189XAK27GA0000PE000600
28838189AAK27GA0000PGB000600SPY   0001425000Y
28838190XAK27GA0000E4001000
28838190AAK27GA0000E4B001000SPY   0001425000Y
28838190AAK27GA0000PHS001000SDS   0000549300Y
28838191XBK27GA0000DU001000
28838191AAK27GA0000PIS001000SPY   0001425500Y
28838191ABK27GA0000DYB001000SSO   0000763800Y
28838191XAK27GA0000EX000500
28838191AAK27GA0000EXB000500SPY   0001425000Y
28838193ABK27GA0000DZB001000SSO   0000763600Y
28838193XBK27GA0000DT001000
28838193A4K27GA00008HS000200DIA   0001298700Y
28838194X3K27G600003J000100
28838194X4K27GA00008C000100
28838194A3K27G600003LB000100DDM   0000800600Y
28838194A4K27GA00008IS000100DXD   0000500500Y
28838201XAK27GA0000FD000500
28838201AAK27GA0000FDB000500SPY   0001425000Y
28838201XAK27GA0000P5003000
28838201XAK27GA0000P6003000
28838201XAK27GA0000PA003000
28838201XAK27GA0000O8000500
28838201AAK27GA0000O8S000500SPY   0001425700Y
28838202XAK27GA0000E5001000
28838202AAK27GA0000E5S001000SPY   0001425600Y
28838202XAK27GA0000O5000500
28838202AAK27GA0000O5S000500SPY   0001425600Y
28838202XAK27GA0000OG002000
28838202AAK27GA0000PJB002000SPY   0001425000Y
28838202XAK27GA0000PC003000
28838202AAK27GA0000PKB003000SPY   0001424900Y
28838202AAK27GA0000PLB003000SPY   0001424900Y
28838202AAK27GA0000PMB002000SPY   0001424800Y
28838203AAK27GA0000PNS003000SPY   0001425800Y
28838203X4K27GA00003H000200
28838203A4K27GA00003HB000200DIA   0001298300Y
28838204AAK27GA0000POS003000SPY   0001425800Y
28838205XAK27GA0000E5001000
28838205AAK27GA0000E5S001000SPY   0001425200Y
28838204A6K27GA000053B002000IWM   0000736100Y
28838206XAK27GA0000O8000500
28838206AAK27GA0000O8S000500SPY   0001425300Y
28838207XAK27GA0000O5000500
28838207AAK27GA0000O5S000500SPY   0001425200Y
28838214X4K27GA000088000047
28838217X9K27G60000KQ005000
28838217A4K27GA00008JS000047DIA   0001298800Y
28838219A9K27G60000L4S005000QQQQ  0000496100Y
28838223X9K27G60000L4005000
28838223X9K27G60000L3005000
28838223A9K27G60000L5S005000QQQQ  0000495700Y
28838223A9K27G60000L6S005000QQQQ  0000495700Y
28838224XAK27GA0000P7001000
28838225XAK27GA0000EX000500
28838225AAK27GA0000EXB000500SPY   0001424600Y
28838224X6K27GA00002B000500
28838224A6K27GA00002BS000500IWM   0000736800Y
28838232X9K27G60000EN002000
28838232A9K27G60000ENS002000QQQQ  0000495700Y
28838238XBK27GA0000DV000100
28838238XBK27GA0000DW000100
28838238XBK27GA0000DX000100
28838239A6K27GA000054S000100IWM   0000736900Y
28838241X9K27G60000IR002000
28838243X4K27GA00008A000100
28838243X4K27GA000089000100
28838244X3K27G600003I000100
28838244X4K27GA00007C000200
28838244A4K27GA00007CB000200DIA   0001298400Y
28838243X6K27GA00004T000500
28838243A6K27GA00004TB000500IWM   0000736300Y
28838245XAK27GA0000P7001000
28838244X6K27GA000054000100
28838246ABK27GA0000E0B000100UWM   0000542100Y
28838246XBK27GA0000DR000100
28838246ABK27GA0000E1S000100TWM   0000702400Y
28838246A4K27GA00008KS000100DXD   0000500400Y
28838246A4K27GA00008LS000100DOG   0000598500Y
28838246A3K27G600003MB000100DDM   0000800700Y
