28816007A6K27GA000031B000500IWM   0000736000Y
28816017X6K27GA000031000500
28816017A6K27GA000031B000500IWM   0000736400Y
28816020X6K27GA000031000500
28816020A6K27GA000031B000500IWM   0000736000Y
28816021X6K27GA000031000500
28816021A6K27GA000031B000500IWM   0000736400Y
28816027X6K27GA000031000500
28816027A6K27GA000031B000500IWM   0000736000Y
28816038X6K27GA000031000500
28816038A6K27GA000031B000500IWM   0000736400Y
28816040X6K27GA000031000500
28816040A6K27GA000031B000500IWM   0000736000Y
28816140A4K27GA00004UB000100DXD   0000499500Y
28816332XAK27GA0000E3000100
28816332AAK27GA0000GUB000100SPY   0001424100Y
28816360X7K27GA000015002000
28816362A6K27GA000033B002000IMCL  0000295400Y
28816372ABK27GA00003IB002000UTX   0000024300Y
28816388X6K27GA000031000500
28816397A6K27GA000034B000500IWM   0000736400Y
28816400ABK27GA00003JB000100UWM   0000542300Y
28816401ABK27GA00003KS000100TWM   0000702200Y
28816401XBK27GA00003H000100
28816402X6K27GA000034000500
28816402A6K27GA000034B000500IWM   0000736000Y
28816405XBK27GA00003J000100
28816405XBK27GA00003K000100
28816406X7K27GA000014002000
28816407ABK27GA00003LS000100TWM   0000702400Y
28816406X6K27GA000034000500
28816406A6K27GA000034B000500IWM   0000736400Y
28816407X6K27GA000034000500
28816407A6K27GA000034B000500IWM   0000736000Y
28816409ABK27GA00003MB000100UWM   0000542300Y
28816409XBK27GA00003L000100
28816409ABK27GA00003NS000100TWM   0000702200Y
28816410XBK27GA00003M000100
28816410XBK27GA00003N000100
28816412ABK27GA00003OS000100TWM   0000702400Y
28816416X6K27GA000034000500
28816416A6K27GA000034B000500IWM   0000736400Y
28816421ABK27GA00003PS000100TWM   0000702200Y
28816421ABK27GA00003QB000100UWM   0000542300Y
28816421XBK27GA00003O000100
28816420X6K27GA000034000500
28816420A6K27GA000034B000500IWM   0000736000Y
28816424XBK27GA00003Q000100
28816424XBK27GA00003P000100
28816425ABK27GA00003RS000100TWM   0000702400Y
28816426X6K27GA000034000500
28816426A6K27GA000034B000500IWM   0000736400Y
28816427X6K27GA000034000500
28816427A6K27GA000034B000500IWM   0000736000Y
28816429ABK27GA00003SB000100UWM   0000542300Y
28816429XBK27GA00003R000100
28816429ABK27GA00003TS000100TWM   0000702200Y
28816430XBK27GA00003S000100
28816430XBK27GA00003T000100
28816432ABK27GA00003US000100TWM   0000702400Y
28816434A4K27GA00004VB000100DRYS  0001065100Y
28816434A4K27GA00004WS000100DRYS  0001071400Y
28816436X6K27GA000034000500
28816436A6K27GA000034B000500IWM   0000736400Y
28816439ABK27GA00003VB000100UWM   0000542300Y
28816439ABK27GA00003WS000100TWM   0000702200Y
28816440XBK27GA00003U000100
28816440X6K27GA000034000500
28816440A6K27GA000034B000500IWM   0000736000Y
28816443XBK27GA00003V000100
28816443XBK27GA00003W000100
28816445ABK27GA00003XS000100TWM   0000702400Y
28816445XCK27GA00001H002000
28816446X6K27GA000034000500
28816446A6K27GA000034B000500IWM   0000736400Y
28816447X6K27GA000034000500
28816447A6K27GA000034B000500IWM   0000736000Y
28816449ABK27GA00003YB000100UWM   0000542300Y
28816449XBK27GA00003X000100
28816449ABK27GA00003ZS000100TWM   0000702200Y
28816450XBK27GA00003Y000100
28816450XBK27GA00003Z000100
28816452ABK27GA000040S000100TWM   0000702400Y
28816456X6K27GA000034000500
28816456A6K27GA000034B000500IWM   0000736400Y
28816459ABK27GA000041B000100UWM   0000542300Y
28816459ABK27GA000042S000100TWM   0000702200Y
28816460XBK27GA000040000100
28816461X6K27GA000034000500
28816461A6K27GA000034B000500IWM   0000736000Y
28816464XBK27GA000041000100
28816464XBK27GA000042000100
28816466ABK27GA000043S000100TWM   0000702400Y
28816466X6K27GA000034000500
28816466A6K27GA000034B000500IWM   0000736400Y
28816467ACK27GA00001IB002000WYE   0000010800Y
28816468AAK27GA0000GVB002000SHLD  0000625300Y
28816469X6K27GA000034000500
28816469A6K27GA000034B000500IWM   0000736000Y
28816478X6K27GA000034000500
28816478A6K27GA000034B000500IWM   0000736400Y
28816488X6K27GA000034000500
28816488A6K27GA000034B000500IWM   0000736000Y
28816491X1K27GA00002E002000
28816498A8K27G600000RB002000OSIP  0000340300Y
28816498X6K27GA000034000500
28816498A6K27GA000034B000500IWM   0000736400Y
28816508X6K27GA000034000500
28816508A6K27GA000034B000500IWM   0000736000Y
28816515A1K27GA00002GB002000ABT   0000016200Y
28816516ABK27GA000044B002000UTX   0000025100Y
28816518X6K27GA000034000500
28816518A6K27GA000034B000500IWM   0000736400Y
28816528X6K27GA000034000500
28816528A6K27GA000034B000500IWM   0000736000Y
28816538X6K27GA000034000500
28816538A6K27GA000034B000500IWM   0000736400Y
28816548X6K27GA000034000500
28816548A6K27GA000034B000500IWM   0000736000Y
28816558X6K27GA000034000500
28816558A6K27GA000034B000500IWM   0000736400Y
28816568X6K27GA000034000500
28816568A6K27GA000034B000500IWM   0000736000Y
28816571A8K27G600000SB002000OVTI  0000149700Y
28816570X1K27GA00002F002000
28816578X6K27GA000034000500
28816578A6K27GA000034B000500IWM   0000736400Y
28816583A1K27GA00002HB002000ABT   0000017100Y
28816588X6K27GA000034000500
28816588A6K27GA000034B000500IWM   0000736000Y
28816598X6K27GA000034000500
28816598A6K27GA000034B000500IWM   0000736400Y
28816608X6K27GA000034000500
28816608A6K27GA000034B000500IWM   0000736000Y
28816616A8K27G600000TB002000PAYX  0000340300Y
28816618X6K27GA000034000500
28816618A6K27GA000034B000500IWM   0000736400Y
28816621A2K27G6000014B002000BK    0000424100Y
28816628X6K27GA000034000500
28816628A6K27GA000034B000500IWM   0000736000Y
28816638X6K27GA000034000500
28816638A6K27GA000034B000500IWM   0000736400Y
28816648X6K27GA000034000500
28816648A6K27GA000034B000500IWM   0000736000Y
28816658X6K27GA000034000500
28816658A6K27GA000034B000500IWM   0000736400Y
28816668X6K27GA000034000500
28816668A6K27GA000034B000500IWM   0000736000Y
28816673A9K27G60000H5B002000PCAR  0000471200Y
28816675A2K27G6000015B002000BMC   0000365000Y
28816678X6K27GA000034000500
28816678A6K27GA000034B000500IWM   0000736400Y
28816688X6K27GA000034000500
28816688A6K27GA000034B000500IWM   0000736000Y
28816698X6K27GA000034000500
28816698A6K27GA000034B000500IWM   0000736400Y
28816708X6K27GA000034000500
28816708A6K27GA000034B000500IWM   0000736000Y
28816718X6K27GA000034000500
28816718A6K27GA000034B000500IWM   0000736400Y
28816730A2K27G6000016B002000BNI   0001056100Y
28816728X6K27GA000034000500
28816728A6K27GA000034B000500IWM   0000736000Y
28816735X1K27GA000011000100
28816738X6K27GA000034000500
28816738A6K27GA000034B000500IWM   0000736400Y
28816741P1K27GA000011B000100AAPL  0001830100000N1AQ00002
28816748X6K27GA000034000500
28816748A6K27GA000034B000500IWM   0000736000Y
28816758X6K27GA000034000500
28816758A6K27GA000034B000500IWM   0000736400Y
28816768X6K27GA000034000500
28816768A6K27GA000034B000500IWM   0000736000Y
28816774A2K27G6000017B002000BP    0000739100Y
28816778X6K27GA000034000500
28816778A6K27GA000034B000500IWM   0000736400Y
28816788X6K27GA000034000500
28816788A6K27GA000034B000500IWM   0000736000Y
28816798X6K27GA000034000500
28816798A6K27GA000034B000500IWM   0000736400Y
28816802A2K27G6000018B002000BJS   0000300300Y
28816807X6K27GA000034000500
28816807A6K27GA000034B000500IWM   0000736000Y
28816817X6K27GA000034000500
28816817A6K27GA000034B000500IWM   0000736400Y
28816827A2K27G6000019B002000BR    0000191600Y
28816827X6K27GA000034000500
28816827A6K27GA000034B000500IWM   0000736000Y
28816840X9K27G60000GX000500
28816851A2K27G600001AB002000BK    0000423300Y
28816872A2K27G600001BB002000BSX   0000118800Y
28816878A2K27G600001CB002000BMC   0000364200Y
28816913A2K27G600001DB002000BNI   0001055300Y
28816945X9K27G60000GZ005000
28816945X9K27G60000G8002000
28816945A9K27G60000G8B002000QQQQ  0000495200Y
28816945X9K27G60000G1002000
28816945A9K27G60000G1S002000QQQQ  0000495800Y
28816945A9K27G60000H6S005000QQQQ  0000495800Y
28816945X9K27G60000GT005000
28816945X9K27G60000GU005000
28816946A9K27G60000H7S002000QQQQ  0000495800Y
28816946X9K27G60000GY002000
28816947X9K27G60000EQ002000
28816947A9K27G60000EQS002000QQQQ  0000495800Y
28816947A9K27G60000H8B005000QQQQ  0000495300Y
28816947A9K27G60000H9B005000QQQQ  0000495300Y
28816967AAK27GA0000GWB001000SPY   0001425200Y
28816970X9K27G60000H8005000
28816970X9K27G60000H9005000
28816970A9K27G60000HAB005000QQQQ  0000495700Y
28816970A9K27G60000HBB005000QQQQ  0000495700Y
28817104XAK27GA0000E4001000
28817104AAK27GA0000E4B001000SPY   0001425400Y
28817177X6K27GA000034000500
28817178A6K27GA000035B000500IWM   0000735900Y
28817187X6K27GA000035000500
28817187A6K27GA000035B000500IWM   0000736000Y
28817197X6K27GA000035000500
28817197A6K27GA000035B000500IWM   0000736400Y
28817202ABK27GA000045B000100UWM   0000542300Y
28817202XBK27GA000043000100
28817202ABK27GA000046S000100TWM   0000702200Y
28817203X6K27GA000035000500
28817203A6K27GA000035B000500IWM   0000736000Y
28817205X6K27GA000035000500
28817205A6K27GA000035B000500IWM   0000736400Y
28817207XBK27GA000045000100
28817207XBK27GA000046000100
28817208ABK27GA000047B000100UWM   0000542300Y
28817208ABK27GA000048S000100TWM   0000702200Y
28817208X6K27GA000035000500
28817208A6K27GA000035B000500IWM   0000736000Y
28817211XBK27GA000047000100
28817211XBK27GA000048000100
28817211A6K27GA000036B000100IWM   0000735900Y
28817213ABK27GA000049S000100TWM   0000702400Y
28817212X6K27GA000036000100
28817216X6K27GA000035000500
28817216A6K27GA000035B000500IWM   0000736400Y
28817218X6K27GA000035000500
28817218A6K27GA000035B000500IWM   0000736000Y
28817221XBK27GA000049000100
28817221ABK27GA00004AB000100UWM   0000542300Y
28817221ABK27GA00004BS000100TWM   0000702200Y
28817221XBK27GA00004A000100
28817221XBK27GA00004B000100
28817221X6K27GA000035000500
28817221A6K27GA000035B000500IWM   0000736400Y
28817223ABK27GA00004CS000100TWM   0000702400Y
28817225ABK27GA00004DB000100UWM   0000542300Y
28817225ABK27GA00004ES000100TWM   0000702200Y
28817225XBK27GA00004C000100
28817226X6K27GA000035000500
28817226A6K27GA000035B000500IWM   0000736000Y
28817230XBK27GA00004D000100
28817230XBK27GA00004E000100
28817230A6K27GA000037B000100IWM   0000735900Y
28817232ABK27GA00004FS000100TWM   0000702400Y
28817230X6K27GA000037000100
28817231X6K27GA000035000500
28817231A6K27GA000035B000500IWM   0000736400Y
28817234ABK27GA00004GS000100TWM   0000702200Y
28817234XBK27GA00004F000100
28817234ABK27GA00004HB000100UWM   0000542300Y
28817236X6K27GA000035000500
28817236A6K27GA000035B000500IWM   0000736000Y
28817237X6K27GA000035000500
28817237A6K27GA000035B000500IWM   0000736400Y
28817239XBK27GA00004H000100
28817239XBK27GA00004G000100
28817241ABK27GA00004IB000100UWM   0000542300Y
28817239A6K27GA000038B000100IWM   0000735900Y
28817240X6K27GA000038000100
28817241ABK27GA00004JS000100TWM   0000702200Y
28817240X6K27GA000035000500
28817240A6K27GA000035B000500IWM   0000736000Y
28817244XBK27GA00004I000100
28817244XBK27GA00004J000100
28817245ABK27GA00004KS000100TWM   0000702400Y
28817246X6K27GA000035000500
28817246A6K27GA000035B000500IWM   0000736400Y
28817247X6K27GA000035000500
28817247A6K27GA000035B000500IWM   0000736000Y
28817249ABK27GA00004LB000100UWM   0000542300Y
28817249ABK27GA00004MS000100TWM   0000702200Y
28817249XBK27GA00004K000100
28817251XBK27GA00004L000100
28817251XBK27GA00004M000100
28817251A6K27GA000039B000100IWM   0000735900Y
28817251X6K27GA000039000100
28817253ABK27GA00004NS000100TWM   0000702400Y
28817256X6K27GA000035000500
28817256A6K27GA000035B000500IWM   0000736400Y
28817267X6K27GA000035000500
28817267A6K27GA000035B000500IWM   0000736000Y
28817277X6K27GA000035000500
28817277A6K27GA000035B000500IWM   0000736400Y
28817287X6K27GA000035000500
28817287A6K27GA000035B000500IWM   0000736000Y
28817297X6K27GA000035000500
28817297A6K27GA000035B000500IWM   0000736400Y
28817299X6K27GA000035000500
28817299A6K27GA000035B000500IWM   0000736000Y
28817308X6K27GA000035000500
28817308A6K27GA000035B000500IWM   0000736400Y
28817318X6K27GA000035000500
28817318A6K27GA000035B000500IWM   0000736000Y
28817328X6K27GA000035000500
28817328A6K27GA000035B000500IWM   0000736400Y
28817338X6K27GA000035000500
28817338A6K27GA000035B000500IWM   0000736000Y
28817348XAK27GA0000GV002000
28817348X6K27GA000035000500
28817348A6K27GA000035B000500IWM   0000736400Y
28817358X6K27GA000035000500
28817358A6K27GA000035B000500IWM   0000736000Y
28817366X9K27G60000HB005000
28817368X6K27GA000035000500
28817368A6K27GA000035B000500IWM   0000736400Y
28817378X6K27GA000035000500
28817378A6K27GA000035B000500IWM   0000736000Y
28817388X6K27GA000035000500
28817388A6K27GA000035B000500IWM   0000736400Y
28817398X6K27GA000035000500
28817398A6K27GA000035B000500IWM   0000736000Y
28817407XBK27GA000044002000
28817407A7K27GA000017B002000LMT   0000044300Y
28817408X6K27GA000035000500
28817408A6K27GA000035B000500IWM   0000736400Y
28817419XBK27GA00003I002000
28817418X6K27GA000035000500
28817418A6K27GA000035B000500IWM   0000736000Y
28817420A9K27G60000HCB002000PETM  0000203300Y
28817428A7K27GA000018B002000LMT   0000045100Y
28817428X6K27GA000035000500
28817428A6K27GA000035B000500IWM   0000736400Y
28817434XCK27GA00001I002000
28817438X6K27GA000035000500
28817438A6K27GA000035B000500IWM   0000736000Y
28817443XAK27GA0000G4000500
28817443AAK27GA0000G4S000500SPY   0001425900Y
28817445XAK27GA0000GC001000
28817447AAK27GA0000GXB001000SDS   0000547600Y
28817448X6K27GA000035000500
28817448A6K27GA000035B000500IWM   0000736400Y
28817455XAK27GA0000G4000500
28817455AAK27GA0000G4S000500SPY   0001425500Y
28817455X1K27GA00002G002000
28817455XAK27GA0000FD000500
28817455AAK27GA0000FDB000500SPY   0001425400Y
28817457AAK27GA0000GYB001000SDS   0000547700Y
28817457XAK27GA0000GX001000
28817457X6K27GA000035000500
28817457A6K27GA000035B000500IWM   0000736000Y
28817461XAK27GA0000G4000500
28817461AAK27GA0000G4S000500SPY   0001425900Y
28817462X4K27GA00004T000047
28817462XAK27GA0000GY001000
28817464AAK27GA0000GZB001000SDS   0000547600Y
28817465XAK27GA0000G4000500
28817465AAK27GA0000G4S000500SPY   0001425500Y
28817465A9K27G60000HDB005000QQQQ  0000495300Y
28817466XAK27GA0000GZ001000
28817467AAK27GA0000H0B001000SDS   0000547700Y
28817467X6K27GA000035000500
28817467A6K27GA000035B000500IWM   0000736400Y
28817469XAK27GA0000G4000500
28817469AAK27GA0000G4S000500SPY   0001425900Y
28817469A4K27GA00004XS000047DIA   0001299100Y
28817470XAK27GA0000H0001000
28817472AAK27GA0000H1B001000SDS   0000547600Y
28817473XAK27GA0000G4000500
28817473AAK27GA0000G4S000500SPY   0001425500Y
28817474XAK27GA0000H1001000
28817475AAK27GA0000H2B001000SDS   0000547700Y
28817474X6K27GA000035000500
28817474A6K27GA000035B000500IWM   0000736000Y
28817476XAK27GA0000G4000500
28817476AAK27GA0000G4S000500SPY   0001425900Y
28817476XAK27GA0000H2001000
28817478AAK27GA0000H3B001000SDS   0000547600Y
28817478X6K27GA000035000500
28817478A6K27GA000035B000500IWM   0000736400Y
28817485XAK27GA0000G4000500
28817485AAK27GA0000G4S000500SPY   0001425500Y
28817486XAK27GA0000H3001000
28817486AAK27GA0000H4B001000SDS   0000547700Y
28817486X6K27GA000035000500
28817486A6K27GA000035B000500IWM   0000736000Y
28817488X6K27GA000035000500
28817488A6K27GA000035B000500IWM   0000736400Y
28817491X1K27GA00002H002000
28817494XAK27GA0000G4000500
28817494AAK27GA0000G4S000500SPY   0001425900Y
28817493X6K27GA000035000500
28817493A6K27GA000035B000500IWM   0000736000Y
28817495X6K27GA000035000500
28817495A6K27GA000035B000500IWM   0000736400Y
28817496XAK27GA0000H4001000
28817498AAK27GA0000H5B001000SDS   0000547600Y
28817497X6K27GA000035000500
28817497A6K27GA000035B000500IWM   0000736000Y
28817503X6K27GA000035000500
28817503A6K27GA000035B000500IWM   0000736400Y
28817505A9K27G60000HEB002000PLCM  0000229800Y
28817505XAK27GA0000G4000500
28817505AAK27GA0000G4S000500SPY   0001425500Y
28817506XAK27GA0000H5001000
28817506AAK27GA0000H6B001000SDS   0000547700Y
28817507X6K27GA000035000500
28817507A6K27GA000035B000500IWM   0000736000Y
28817513X6K27GA000035000500
28817513A6K27GA000035B000500IWM   0000736400Y
28817515XAK27GA0000G4000500
28817515AAK27GA0000G4S000500SPY   0001425900Y
28817517XAK27GA0000H6001000
28817518AAK27GA0000H7B001000SDS   0000547600Y
28817517X6K27GA000035000500
28817517A6K27GA000035B000500IWM   0000736000Y
28817524XAK27GA0000G4000500
28817524AAK27GA0000G4S000500SPY   0001425500Y
28817524X6K27GA000035000500
28817524A6K27GA000035B000500IWM   0000736400Y
28817526XAK27GA0000H7001000
28817526AAK27GA0000H8B001000SDS   0000547700Y
28817526X6K27GA000035000500
28817526A6K27GA000035B000500IWM   0000736000Y
28817534XAK27GA0000G4000500
28817534AAK27GA0000G4S000500SPY   0001425900Y
28817536XAK27GA0000H8001000
28817538AAK27GA0000H9B001000SDS   0000547600Y
28817539XAK27GA0000H9001000
28817539AAK27GA0000HAB001000SDS   0000547700Y
28817542ACK27GA00001JB002000WYE   0000012800Y
28817545XAK27GA0000HA001000
28817546A1K27GA00002IB002000AFL   0000023700Y
28817546AAK27GA0000HBB001000SDS   0000547600Y
28817566A9K27G60000HFB002000PSUN  0000087100Y
28817570ABK27GA00004OB000100UWM   0000542300Y
28817570XBK27GA00004N000100
28817570ABK27GA00004PS000100TWM   0000702200Y
28817579XBK27GA00004O000100
28817579XBK27GA00004P000100
28817581ABK27GA00004QS000100TWM   0000702400Y
28817589ABK27GA00004RB000100UWM   0000542300Y
28817589XBK27GA00004Q000100
28817589ABK27GA00004SS000100TWM   0000702200Y
28817589XBK27GA00004S000100
28817589XBK27GA00004R000100
28817591ABK27GA00004TS000100TWM   0000702400Y
28817605AAK27GA0000HCB002000SBUX  0000158300Y
28817628A1K27GA00002JB002000AFL   0000024500Y
28817629ABK27GA00004UB000100UWM   0000542300Y
28817629XBK27GA00004T000100
28817629ABK27GA00004VS000100TWM   0000702200Y
28817639XBK27GA00004U000100
28817639XBK27GA00004V000100
28817641ABK27GA00004WB000100UWM   0000542300Y
28817639A6K27GA00003AB000100IWM   0000735900Y
28817641ABK27GA00004XS000100TWM   0000702200Y
28817639X6K27GA00003A000100
28817649XBK27GA00004W000100
28817649XBK27GA00004X000100
28817651ABK27GA00004YB000100UWM   0000542300Y
28817651ABK27GA00004ZS000100TWM   0000702200Y
28817659XBK27GA00004Y000100
28817659XBK27GA00004Z000100
28817659A6K27GA00003BB000100IWM   0000735900Y
28817659X6K27GA00003B000100
28817661ABK27GA000050S000100TWM   0000702400Y
28817665A2K27G600001EB002000CA    0000228700Y
28817668XAK27GA0000GU000100
28817668AAK27GA0000HDB000100SPY   0001425000Y
28817669ABK27GA000051B001000SSO   0000763700Y
28817669ABK27GA000052B000100UWM   0000542300Y
28817669XBK27GA000050000100
28817669ABK27GA000053S000100TWM   0000702200Y
28817679XBK27GA000052000100
28817679XBK27GA000053000100
28817681ABK27GA000054S000100TWM   0000702400Y
28817699ABK27GA000055B000100UWM   0000542300Y
28817699ABK27GA000056S000100TWM   0000702200Y
28817699XBK27GA000054000100
28817709XBK27GA000055000100
28817709XBK27GA000056000100
28817711A2K27G600001FB002000CAH   0000544300Y
28817711ABK27GA000057B000100UWM   0000542300Y
28817711ABK27GA000058S000100TWM   0000702200Y
28817719XBK27GA000057000100
28817719XBK27GA000058000100
28817720XAK27GA0000G4000500
28817720AAK27GA0000G4S000500SPY   0001425500Y
28817719A6K27GA00003CB000100IWM   0000735900Y
28817719X6K27GA00003C000100
28817722AAK27GA0000HEB001000SDS   0000547700Y
28817722XAK27GA0000HB001000
28817733X9K27G60000EP002000
28817733A9K27G60000EPB002000QQQQ  0000495400Y
28817735A2K27G600001GB002000CAT   0000814700Y
28817767A3K27G6000013B002000CCE   0000189100Y
28817773A2K27G600001HB002000BP    0000738300Y
28817798A2K27G600001IB002000BR    0000190800Y
28817821A2K27G600001JB002000BSX   0000118000Y
28817835A2K27G600001KB002000CA    0000227900Y
28817867X6K27GA000035000500
28817867A6K27GA00003DB000500IWM   0000736400Y
28817871ABK27GA000059B000100UWM   0000542300Y
28817871ABK27GA00005AS000100TWM   0000702200Y
28817872X6K27GA00003D000500
28817872A6K27GA00003DB000500IWM   0000736000Y
28817875XBK27GA000059000100
28817875XBK27GA00005A000100
28817875X6K27GA00003D000500
28817875A6K27GA00003DB000500IWM   0000736400Y
28817876A6K27GA00003EB000100IWM   0000735900Y
28817876X6K27GA00003E000100
28817877X6K27GA00003D000500
28817877A6K27GA00003DB000500IWM   0000736000Y
28817879ABK27GA00005BB000100UWM   0000542300Y
28817879ABK27GA00005CS000100TWM   0000702200Y
28817881XBK27GA00005C000100
28817881XBK27GA00005B000100
28817882X6K27GA00003D000500
28817882A6K27GA00003DB000500IWM   0000736400Y
28817885ABK27GA00005DS000100TWM   0000702400Y
28817886ABK27GA00005EB000100UWM   0000542300Y
28817886XBK27GA00005D000100
28817886ABK27GA00005FS000100TWM   0000702200Y
28817886X6K27GA00003D000500
28817886A6K27GA00003DB000500IWM   0000736000Y
28817889XBK27GA00005E000100
28817889XBK27GA00005F000100
28817889XAK27GA0000G4000500
28817889AAK27GA0000G4S000500SPY   0001425900Y
28817888X6K27GA00003D000500
28817888A6K27GA00003DB000500IWM   0000736400Y
28817891ABK27GA00005GS000100TWM   0000702400Y
28817892ABK27GA00005HB000100UWM   0000542300Y
28817892XBK27GA00005G000100
28817892ABK27GA00005IS000100TWM   0000702200Y
28817895XAK27GA0000HE001000
28817896AAK27GA0000HFB001000SDS   0000547600Y
28817896X6K27GA00003D000500
28817896A6K27GA00003DB000500IWM   0000736000Y
28817900XBK27GA00005H000100
28817900XBK27GA00005I000100
28817900A6K27GA00003FB000100IWM   0000735900Y
28817902ABK27GA00005JS000100TWM   0000702400Y
28817900X6K27GA00003F000100
28817902X6K27GA00003D000500
28817902A6K27GA00003DB000500IWM   0000736400Y
28817905ABK27GA00005KB000100UWM   0000542300Y
28817905XBK27GA00005J000100
28817905ABK27GA00005LS000100TWM   0000702200Y
28817906X6K27GA00003D000500
28817906A6K27GA00003DB000500IWM   0000736000Y
28817910XBK27GA00005K000100
28817910XBK27GA00005L000100
28817910A6K27GA00003GB000100IWM   0000735900Y
28817910X6K27GA00003G000100
28817912ABK27GA00005MS000100TWM   0000702400Y
28817915X6K27GA00003D000500
28817915A6K27GA00003DB000500IWM   0000736400Y
28817918ABK27GA00005NB000100UWM   0000542300Y
28817916X6K27GA00003D000500
28817916A6K27GA00003DB000500IWM   0000736000Y
28817918ABK27GA00005OS000100TWM   0000702200Y
28817918XBK27GA00005M000100
28817918X6K27GA00003D000500
28817918A6K27GA00003DB000500IWM   0000736400Y
28817920XBK27GA00005O000100
28817920XBK27GA00005N000100
28817922ABK27GA00005PB000100UWM   0000542300Y
28817922ABK27GA00005QS000100TWM   0000702200Y
28817923X6K27GA00003D000500
28817923A6K27GA00003DB000500IWM   0000736000Y
28817924X6K27GA00003D000500
28817924A6K27GA00003DB000500IWM   0000736400Y
28817926XBK27GA00005P000100
28817926XBK27GA00005Q000100
28817926X6K27GA00003D000500
28817926A6K27GA00003DB000500IWM   0000736000Y
28817928ABK27GA00005RS000100TWM   0000702400Y
28817931X6K27GA00003D000500
28817931A6K27GA00003DB000500IWM   0000736400Y
28817936X6K27GA00003D000500
28817936A6K27GA00003DB000500IWM   0000736000Y
28817948X6K27GA00003D000500
28817948A6K27GA00003DB000500IWM   0000736400Y
28817964XAK27GA0000FA000600
28817968X6K27GA00003D000500
28817968A6K27GA00003DB000500IWM   0000736000Y
28817969AAK27GA0000HGB001000SPY   0001419600Y
28817973X6K27GA00003D000500
28817973A6K27GA00003DB000500IWM   0000736400Y
28817976X6K27GA00003D000500
28817976A6K27GA00003DB000500IWM   0000736000Y
28817978X6K27GA00003D000500
28817978A6K27GA00003DB000500IWM   0000736400Y
28817988X6K27GA00003D000500
28817988A6K27GA00003DB000500IWM   0000736000Y
28817990A9K27G60000HGS001000QQQQ  0000496200Y
28817990A9K27G60000HHS001000QQQQ  0000496100Y
28817990A9K27G60000HIS000500QQQQ  0000496100Y
28817990A9K27G60000HJS000500QQQQ  0000496200Y
28817991X9K27G60000HA005000
28817993A9K27G60000HKB005000QQQQ  0000495300Y
28817993X6K27GA00003D000500
28817993A6K27GA00003DB000500IWM   0000736400Y
28817998X6K27GA00003D000500
28817998A6K27GA00003DB000500IWM   0000736000Y
28818008X6K27GA00003D000500
28818008A6K27GA00003DB000500IWM   0000736400Y
28818018X6K27GA00003D000500
28818018A6K27GA00003DB000500IWM   0000736000Y
28818038X6K27GA00003D000500
28818038A6K27GA00003DB000500IWM   0000736400Y
28818048X6K27GA00003D000500
28818048A6K27GA00003DB000500IWM   0000736000Y
28818058X6K27GA00003D000500
28818058A6K27GA00003DB000500IWM   0000736400Y
28818068X6K27GA00003D000500
28818068A6K27GA00003DB000500IWM   0000736000Y
28818078X6K27GA00003D000500
28818078A6K27GA00003DB000500IWM   0000736400Y
28818085X6K27GA00003D000500
28818085A6K27GA00003DB000500IWM   0000736000Y
28818087X6K27GA00003D000500
28818087A6K27GA00003DB000500IWM   0000736400Y
28818093X6K27GA00003D000500
28818093A6K27GA00003DB000500IWM   0000736000Y
28818095X6K27GA00003D000500
28818095A6K27GA00003DB000500IWM   0000736400Y
28818097X6K27GA00003D000500
28818097A6K27GA00003DB000500IWM   0000736000Y
28818103X6K27GA00003D000500
28818103A6K27GA00003DB000500IWM   0000736400Y
28818107X6K27GA00003D000500
28818107A6K27GA00003DB000500IWM   0000736000Y
28818111X6K27GA00003D000500
28818111A6K27GA00003DB000500IWM   0000736400Y
28818117X6K27GA00003D000500
28818117A6K27GA00003DB000500IWM   0000736000Y
28818123X6K27GA00003D000500
28818123A6K27GA00003DB000500IWM   0000736400Y
28818125X6K27GA00003D000500
28818125A6K27GA00003DB000500IWM   0000736000Y
28818127X6K27GA00003D000500
28818127A6K27GA00003DB000500IWM   0000736400Y
28818137X6K27GA00003D000500
28818137A6K27GA00003DB000500IWM   0000736000Y
28818139X6K27GA00003D000500
28818139A6K27GA00003DB000500IWM   0000736400Y
28818147X6K27GA00003D000500
28818147A6K27GA00003DB000500IWM   0000736000Y
28818150X6K27GA00003D000500
28818150A6K27GA00003DB000500IWM   0000736400Y
28818157X6K27GA00003D000500
28818157A6K27GA00003DB000500IWM   0000736000Y
28818163X6K27GA00003D000500
28818163A6K27GA00003DB000500IWM   0000736400Y
28818167X6K27GA00003D000500
28818167A6K27GA00003DB000500IWM   0000736000Y
28818184X1K27GA00000V000100
28818184A1K27GA00000VB000100AAPL  0001830100Y
28818374X7K27GA000017002000
28818375X4K27GA00003L000200
28818375A4K27GA00003LB000200DIA   0001298700Y
28818378A3K27G6000014B000100DDM   0000801100Y
28818400X7K27GA000018002000
28818399X6K27GA000033002000
28818409X7K27GA000012002000
28818421XCK27GA00001J002000
28818430AAK27GA0000HHB002000SHLD  0000630400Y
28818440A9K27G60000HLB000500QQQQ  0000495100Y
28818444ABK27GA00005SB002000UTX   0000028300Y
28818457AAK27GA0000HIB002000SEPR  0000177400Y
28818473X1K27GA00002J002000
28818488ABK27GA00005TB002000UTX   0000029100Y
28818501ACK27GA00001KB002000WYE   0000013200Y
28818508X6K27GA00003D000500
28818517A6K27GA00003HB000500IWM   0000736400Y
28818519XAK27GA0000FH000500
28818519AAK27GA0000FHS000500SPY   0001426000Y
28818519X4K27GA00004N000200
28818521ABK27GA00005UB000100UWM   0000542300Y
28818521XBK27GA00005R000100
28818521ABK27GA00005VS000100TWM   0000702200Y
28818521XAK27GA0000E5001000
28818521AAK27GA0000E5S001000SPY   0001426000Y
28818522A4K27GA00004YS000200DIA   0001299200Y
28818522XAK27GA0000EX000500
28818522AAK27GA0000EXB000500SPY   0001425400Y
28818522XAK27GA0000EN003000
28818522XAK27GA0000FW002000
28818522AAK27GA0000FWB002000SPY   0001425400Y
28818522XAK27GA0000ER001000
28818522XAK27GA0000EZ003000
28818522AAK27GA0000HJB000900SPY   0001425500Y
28818522XAK27GA0000ES000900
28818522AAK27GA0000HKB003000SPY   0001425400Y
28818522AAK27GA0000HLB003000SPY   0001425400Y
28818522XAK27GA0000F6000500
28818522AAK27GA0000F6S000500SPY   0001426000Y
28818522AAK27GA0000HMB001000SPY   0001425300Y
28818522XAK27GA0000G0002000
28818522AAK27GA0000HNS000100SH    0000618900Y
28818523XBK27GA00001R001000
28818523ABK27GA00005WB001000SSO   0000764200Y
28818523XAK27GA0000EB001000
28818523AAK27GA0000EBB001000SPY   0001425500Y
28818522X6K27GA00003H000500
28818522A6K27GA00003HB000500IWM   0000736000Y
28818524AAK27GA0000HOB002000SHPGY 0000516300Y
28818524ABK27GA00005XS001000SSO   0000765300Y
28818524XBK27GA00005W001000
28818524ABK27GA00005YB001000SSO   0000764200Y
28818525XBK27GA00005X001000
28818524AAK27GA0000HPS001000SPY   0001426000Y
28818525ABK27GA00005ZS001000SSO   0000765200Y
28818525XBK27GA00005Y001000
28818526XBK27GA00005U000100
28818526XBK27GA00005V000100
28818526AAK27GA0000HQB001000SDS   0000547500Y
28818526ABK27GA000060B001000SSO   0000764100Y
28818526AAK27GA0000HRB001000SDS   0000547400Y
28818526XAK27GA0000GO001000
28818527ABK27GA000061B001000SSO   0000764200Y
28818527XBK27GA00001S001000
28818526X6K27GA00003H000500
28818526A6K27GA00003HB000500IWM   0000736400Y
28818528ABK27GA000062S000100TWM   0000702400Y
28818527X6K27GA00003H000500
28818527A6K27GA00003HB000500IWM   0000736000Y
28818529ABK27GA000063B000100UWM   0000542300Y
28818529ABK27GA000064S000100TWM   0000702200Y
28818529XBK27GA000062000100
28818531XBK27GA000063000100
28818531XBK27GA000064000100
28818533ABK27GA000065S000100TWM   0000702400Y
28818534X6K27GA00003H000500
28818534A6K27GA00003HB000500IWM   0000736400Y
28818535A6K27GA00003IB002000IWM   0000736300Y
28818537ABK27GA000066B000100UWM   0000542300Y
28818537XBK27GA000065000100
28818537ABK27GA000067S000100TWM   0000702200Y
28818537A1K27GA00002KB002000ABT   0000020100Y
28818541XBK27GA000061001000
28818541ABK27GA000061B001000SSO   0000764300Y
28818545XAK27GA0000F6000500
28818545AAK27GA0000F6S000500SPY   0001425600Y
28818546XAK27GA0000EB001000
28818546AAK27GA0000EBB001000SPY   0001425100Y
28818546XAK27GA0000HL003000
28818546XAK27GA0000HK003000
28818547X9K27G60000HK005000
28818547X9K27G60000HD005000
28818547A9K27G60000HMB005000QQQQ  0000495700Y
28818547A9K27G60000HNB005000QQQQ  0000495700Y
28818546XAK27GA0000HM001000
28818547X9K27G60000G1002000
28818547A9K27G60000G1S002000QQQQ  0000496300Y
28818548X9K27G60000EP002000
28818548A9K27G60000EPB002000QQQQ  0000495700Y
28818547AAK27GA0000HSB003000SPY   0001424700Y
28818547AAK27GA0000HTB003000SPY   0001424700Y
28818548AAK27GA0000HUB001000SPY   0001425200Y
28818549XBK27GA000051001000
28818549ABK27GA000068B001000SSO   0000763800Y
28818554A1K27GA00002LB002000ABT   0000019300Y
28818564X4K27GA00004U000100
28818565X3K27G6000011000100
28818569AAK27GA0000HVB002000SLAB  0000352200Y
28818573X9K27G60000HM005000
28818574X9K27G60000HN005000
28818574X9K27G60000G1002000
28818574A9K27G60000G1S002000QQQQ  0000495800Y
28818575A9K27G60000HOB005000QQQQ  0000495300Y
28818575A9K27G60000HPB005000QQQQ  0000495300Y
28818579A3K27G6000015B002000CCL   0000380800Y
28818595X1K27GA00002I002000
28818599XAK27GA0000FW002000
28818602X9K27G60000HO005000
28818602X9K27G60000HP005000
28818603A9K27G60000HQB005000QQQQ  0000495700Y
28818603A9K27G60000HRB005000QQQQ  0000495700Y
28818614XAK27GA0000HU001000
28818619A3K27G6000016B002000CCU   0000337000Y
28818647X9K27G60000HQ005000
28818649A9K27G60000HSB005000QQQQ  0000495300Y
28818657A3K27G6000017B002000CFC   0000038000Y
28818671AAK27GA0000HWB002000SNDK  0000215000Y
28818680A2K27G600001LB002000CAH   0000543500Y
28818696A3K27G6000018B002000CHS   0000061700Y
28818709ABK27GA000069B002000TASR  0000063800Y
28818712A2K27G600001MB002000CAT   0000814000Y
28818766A3K27G6000019B002000CCE   0000188300Y
28818768A3K27G600001AB002000CL    0000692900Y
28818786A3K27G600001BB002000CCL   0000380000Y
28818895X9K27G60000HR005000
28818995A9K27G60000HTB005000QQQQ  0000495300Y
28819068XAK27GA0000E5001000
28819068AAK27GA0000E5S001000SPY   0001425600Y
28819068XAK27GA0000GT003000
28819069XAK27GA0000FH000500
28819069AAK27GA0000FHS000500SPY   0001425600Y
28819069XAK27GA0000FD000500
28819069AAK27GA0000FDB000500SPY   0001425000Y
28819069XAK27GA0000EX000500
28819069AAK27GA0000EXB000500SPY   0001425000Y
28819069X4K27GA00004Y000200
28819070X4K27GA00003L000200
28819070A4K27GA00003LB000200DIA   0001298400Y
28819070AAK27GA0000HXS003000SPY   0001425600Y
28819070XAK27GA0000GS003000
28819070AAK27GA0000HYS003000SPY   0001425600Y
28819070XAK27GA0000HP001000
28819071AAK27GA0000HZS001000SPY   0001425600Y
28819072XAK27GA0000HJ000900
28819072XBK27GA000060001000
28819074A4K27GA00004ZS000200DIA   0001298900Y
28819075AAK27GA0000I0B000400SPY   0001425100Y
28819078X6K27GA00003H000500
28819078A6K27GA00003HB000500IWM   0000736000Y
28819079X6K27GA00003I002000
28819085X3K27G6000014000100
28819084X6K27GA00003H000500
28819084A6K27GA00003HB000500IWM   0000736400Y
28819085X6K27GA00003H000500
28819085A6K27GA00003HB000500IWM   0000736000Y
28819088X6K27GA00003H000500
28819088A6K27GA00003HB000500IWM   0000736400Y
28819096XAK27GA0000HN000100
28819095X6K27GA00003H000500
28819095A6K27GA00003HB000500IWM   0000736000Y
28819097XBK27GA000061001000
28819097ABK27GA00006AB001000SSO   0000764000Y
28819099ABK27GA00006BB001000SSO   0000764200Y
28819098X6K27GA00003H000500
28819098A6K27GA00003HB000500IWM   0000736400Y
28819108X6K27GA00003H000500
28819108A6K27GA00003HB000500IWM   0000736000Y
28819110X6K27GA00003H000500
28819110A6K27GA00003HB000500IWM   0000736400Y
28819111XBK27GA000066000100
28819111XBK27GA000067000100
28819113ABK27GA00006CS000100TWM   0000702200Y
28819113ABK27GA00006DB000100UWM   0000542300Y
28819115AAK27GA0000I1S000100SH    0000618900Y
28819113X6K27GA00003H000500
28819113A6K27GA00003HB000500IWM   0000736000Y
28819115ABK27GA00006EB001000SSO   0000764300Y
28819115XBK27GA00006B001000
28819116X6K27GA00003H000500
28819116A6K27GA00003HB000500IWM   0000736400Y
28819118XBK27GA00006D000100
28819118XBK27GA00006C000100
28819123XAK27GA0000HY003000
28819124XAK27GA0000HX003000
28819125AAK27GA0000I2S003000SPY   0001426200Y
28819125AAK27GA0000I3S003000SPY   0001426200Y
28819128ABK27GA00006FS000100TWM   0000702200Y
28819128ABK27GA00006GB000100UWM   0000542300Y
28819127X4K27GA00003L000200
28819127A4K27GA00003LB000200DIA   0001298700Y
28819130A3K27G600001CB000100DDM   0000801100Y
28819133XAK27GA0000I0000400
28819133AAK27GA0000I4B000400SPY   0001425500Y
28819134XAK27GA0000EX000500
28819134AAK27GA0000EXB000500SPY   0001425400Y
28819138A6K27GA00003JB002000IWM   0000736300Y
28819147XAK27GA0000EX000500
28819147AAK27GA0000EXB000500SPY   0001425000Y
28819349X3K27G6000010002000
28819397XAK27GA0000FD000500
28819397AAK27GA0000FDB000500SPY   0001425400Y
28819398XBK27GA00006A001000
28819398ABK27GA00006HB001000SSO   0000764100Y
28819404XAK27GA0000HH002000
28819420A7K27GA000019B002000LMT   0000050300Y
28819420XAK27GA0000E5001000
28819420AAK27GA0000E5S001000SPY   0001426000Y
28819420A7K27GA00001AB002000LMT   0000051100Y
28819420XAK27GA0000HZ001000
28819425AAK27GA0000I5S001000SPY   0001426000Y
28819428A6K27GA00003KB002000IMCL  0000298600Y
28819437XBK27GA00005S002000
28819470XCK27GA00001K002000
28819484XAK27GA0000GE001000
28819486AAK27GA0000I6S001000SPY   0001425800Y
28819490X1K27GA00002L002000
28819495XBK27GA00005T002000
28819498XAK27GA0000I6001000
28819500AAK27GA0000I7S001000SPY   0001425900Y
28819511A7K27GA00001BB002000LPNT  0000174500Y
28819517XAK27GA0000EB001000
28819517AAK27GA0000EBB001000SPY   0001425500Y
28819517XAK27GA0000HS003000
28819517XAK27GA0000HT003000
28819518X9K27G60000G1002000
28819518A9K27G60000G1S002000QQQQ  0000496300Y
28819517XAK27GA0000F6000500
28819517AAK27GA0000F6S000500SPY   0001426000Y
28819517XAK27GA0000EX000500
28819517AAK27GA0000EXB000500SPY   0001425400Y
28819517AAK27GA0000I8B002000SPY   0001425500Y
28819517X4K27GA00004Z000200
28819518X4K27GA00003Q000200
28819518A4K27GA00003QB000200DIA   0001298800Y
28819518XAK27GA0000FH000500
28819518AAK27GA0000FHS000500SPY   0001426000Y
28819518XAK27GA0000FG000500
28819518AAK27GA0000FGB000500SPY   0001425500Y
28819518XAK27GA0000FJ000500
28819518AAK27GA0000I9B003000SPY   0001425400Y
28819518AAK27GA0000IAB003000SPY   0001425400Y
28819519X4K27GA00004D000200
28819519A4K27GA00004DS000200DIA   0001299200Y
28819519AAK27GA0000IBS000500SPY   0001426100Y
28819520A4K27GA000050S000100DOG   0000598300Y
28819520X4K27GA00003I000100
28819520A4K27GA000051S000100DXD   0000500100Y
28819520A3K27G600001DB000100DDM   0000801200Y
28819520X3K27G600000D000100
28819519ACK27GA00001LB002000WYE   0000015200Y
28819521XAK27GA0000F7000500
28819521AAK27GA0000F7B000500SPY   0001425500Y
28819522XAK27GA0000E6001000
28819522AAK27GA0000E6S001000SPY   0001426100Y
28819524A4K27GA000052S000200DIA   0001299300Y
28819525XAK27GA0000HF001000
28819525XBK27GA00005Z001000
28819527XAK27GA0000HR001000
28819527AAK27GA0000ICB001000SDS   0000547500Y
28819527ABK27GA00006IS001000SSO   0000765300Y
28819529AAK27GA0000IDB001000SDS   0000547400Y
28819574X1K27GA00002K002000
28819578X2K27G600000S002000
28819579A1K27GA00002MB002000AFL   0000027400Y
28819583ABK27GA00006JB002000TECD  0000349200Y
28819610A1K27GA00002NB002000AFL   0000028200Y
28819655X2K27G600000O002000
28819675ABK27GA00006KB002000TEVA  0000448200Y
28819688A2K27G600001NB002000BBT   0000010100Y
28819734A3K27G600001EB002000CNX   0000930500Y
28819749A3K27G600001FB002000CCU   0000336200Y
28819774X4K27GA000052000200
28819776ABK27GA00006LB002000THQI  0000175200Y
28819809A3K27G600001GB002000COH   0000011000Y
28819816A3K27G600001HB002000CFC   0000037200Y
28819871A3K27G600001IB002000CHS   0000060900Y
28819890A3K27G600001JB002000CL    0000692100Y
28819895A3K27G600001KB002000COP   0000916000Y
28819927A3K27G600001LB002000CTX   0000218200Y
28820058XAK27GA0000I8002000
28820059X9K27G60000G1002000
28820059A9K27G60000G1S002000QQQQ  0000495800Y
28820059XAK27GA0000EB001000
28820059AAK27GA0000EBB001000SPY   0001425100Y
28820059XAK27GA0000IB000500
28820059AAK27GA0000IBS000500SPY   0001425600Y
28820059XAK27GA0000FG000500
28820059AAK27GA0000FGB000500SPY   0001425100Y
28820059XAK27GA0000E6001000
28820059AAK27GA0000E6S001000SPY   0001425700Y
28820059XAK27GA0000I4000400
28820059XAK27GA0000F6000500
28820059AAK27GA0000F6S000500SPY   0001425600Y
28820059XAK27GA0000F7000500
28820059AAK27GA0000F7B000500SPY   0001425100Y
28820059A4K27GA000053S000200DIA   0001298900Y
28820059X4K27GA00003Q000200
28820059A4K27GA00003QB000200DIA   0001298500Y
28820059XAK27GA0000FH000500
28820059AAK27GA0000FHS000500SPY   0001425700Y
28820059XAK27GA0000EX000500
28820059AAK27GA0000EXB000500SPY   0001425000Y
28820061X9K27G60000H6005000
28820061X9K27G60000HS005000
28820061X9K27G60000HT005000
28820060AAK27GA0000IEB001000SDS   0000547600Y
28820061A9K27G60000HUB005000QQQQ  0000495700Y
28820061A9K27G60000HVB005000QQQQ  0000495700Y
28820062A9K27G60000HWS005000QQQQ  0000496200Y
28820062X9K27G60000G1002000
28820062A9K27G60000G1S002000QQQQ  0000496300Y
28820062AAK27GA0000IFB001000SPY   0001425100Y
28820062XAK27GA0000I5001000
28820062AAK27GA0000IGS001000SPY   0001425600Y
28820061ABK27GA00006MS001000SSO   0000765200Y
28820061XBK27GA00006I001000
28820064X9K27G60000EQ002000
28820064A9K27G60000EQS002000QQQQ  0000496100Y
28820064X4K27GA00004D000200
28820064X4K27GA000050000100
28820064X4K27GA000051000100
28820065X3K27G600001D000100
28820065XBK27GA00006H001000
28820073A4K27GA000054S000200DIA   0001299000Y
28820078X9K27G60000H7002000
28820079X9K27G60000H3005000
28820080X9K27G60000H4001000
28820081XAK27GA0000IB000500
28820081AAK27GA0000IBS000500SPY   0001426000Y
28820081XAK27GA0000I9003000
28820081XAK27GA0000IA003000
28820082AAK27GA0000IHS001000SPY   0001425800Y
28820082XAK27GA0000I7001000
28820083AAK27GA0000IIB003000SPY   0001424700Y
28820083AAK27GA0000IJB003000SPY   0001424700Y
28820083A9K27G60000HXS005000QQQQ  0000496200Y
28820164XAK27GA0000F6000500
28820164AAK27GA0000F6S000500SPY   0001426000Y
28820165XAK27GA0000EX000500
28820165AAK27GA0000EXB000500SPY   0001425400Y
28820225X9K27G60000HX005000
28820266A9K27G60000HYS005000QQQQ  0000495800Y
28820340A3K27G600001MB002000CELG  0000459800Y
28820409X7K27GA000019002000
28820412X7K27GA00001A002000
28820419XCK27GA00001L002000
28820424X1K27GA00002M002000
28820432ABK27GA00006NB002000UTX   0000032300Y
28820436X1K27GA00002N002000
28820441AAK27GA0000IKB002000SHLD  0000635500Y
28820448ABK27GA00006OB002000UTX   0000033100Y
28820462ACK27GA00001MB002000WYE   0000015600Y
28820470ABK27GA00006PB002000UNTD  0000098500Y
28820482PCK27GA00001NB000100ZVZZT 0020000000000I000HV1Z0
28820483PCK27GA00001NB000100ZVZZT 0020002500000I000HV1Z1
28820492A1K27GA00002OB002000ABT   0000023200Y
28820506A1K27GA00002PB002000ABT   0000022300Y
28820508ABK27GA00006QB002000URBN  0000290200Y
28820555A2K27G600001OB002000AXP   0000395600Y
28820572ABK27GA00006RB002000UTSI  0000035300Y
28820576X6K27GA00002S002000
28820591X6K27GA000028000500
28820591A6K27GA000028S000500IWM   0000737000Y
28820599XBK27GA00001Q000100
28820599XBK27GA000021000100
28820597A6K27GA00003LS000100IWM   0000737200Y
28820601A2K27G600001PB002000AXP   0000394800Y
28820600ABK27GA00006SS000100UWM   0000543400Y
28820599A6K27GA00003MS000100IWM   0000737100Y
28820599X6K27GA00003M000100
28820601ABK27GA00006TB000100TWM   0000700900Y
28820601A6K27GA00003NS000100IWM   0000737100Y
28820601A6K27GA00003OS002000IWM   0000737000Y
28820604ACK27GA00001OB002000VECO  0000169200Y
28820605X6K27GA00003N000100
28820611A2K27G600001QB002000BBT   0000010200Y
28820625A3K27G600001NB002000CVC   0000231000Y
28820654A3K27G600001OB002000CVS   0000015900Y
28820659A3K27G600001PB002000CNX   0000929700Y
28820678A3K27G600001QB002000DD    0000453300Y
28820688A3K27G600001RB002000COH   0000011100Y
28820693XAK27GA0000IG001000
28820693XAK27GA0000IF001000
28820694AAK27GA0000ILB001000SPY   0001425500Y
28820695AAK27GA0000IMS001000SPY   0001426000Y
28820695ABK27GA00006UB001000SSO   0000764100Y
28820707A3K27G600001SB002000DE    0000791700Y
28820710A3K27G600001TB002000COP   0000915200Y
28820728XAK27GA0000IH001000
28820730AAK27GA0000INS001000SPY   0001425900Y
28820737A3K27G600001UB002000CTX   0000217400Y
28820743XAK27GA0000IN001000
28820743AAK27GA0000IOS001000SPY   0001425800Y
28820745X4K27GA00003B000100
28820745X4K27GA00004V000100
28820749A4K27GA000055B000100DRYS  0001066500Y
28820749A4K27GA000056B000100DRYS  0001066500Y
28820774A3K27G600001VB002000CVC   0000230200Y
28821094A6K27GA00003PS002000IWM   0000736800Y
28821096X5K27GA00001C000100
28821098A5K27GA00001FB000100FXP   0000655100Y
28821104A5K27GA00001GS000100FXP   0000657100Y
28821142XAK27GA0000IJ003000
28821144AAK27GA0000IPB003000SPY   0001425400Y
28821144AAK27GA0000IQB003000SPY   0001425400Y
28821144XAK27GA0000II003000
28821155XBK27GA00006M001000
28821155XAK27GA0000IE001000
28821156XAK27GA0000ID001000
28821157ABK27GA00006VS001000SSO   0000765300Y
28821158AAK27GA0000IRB001000SDS   0000547400Y
28821163XAK27GA0000IP003000
28821163XAK27GA0000IQ003000
28821164XAK27GA0000IO001000
28821164AAK27GA0000ISS001000SPY   0001425700Y
28821165AAK27GA0000ITB003000SPY   0001424700Y
28821166AAK27GA0000IUB003000SPY   0001424700Y
28821166X6K27GA00003P002000
28821173XAK27GA0000IS001000
28821174AAK27GA0000IVS001000SPY   0001425700Y
28821176AAK27GA0000IWB001000SDS   0000547600Y
28821182A6K27GA00003QS002000IWM   0000736800Y
28821185XBK27GA00006V001000
28821185ABK27GA00006WS001000SSO   0000765200Y
28821199XAK27GA0000IV001000
28821201AAK27GA0000IXS001000SPY   0001425800Y
28821204X9K27G60000G1002000
28821204A9K27G60000G1S002000QQQQ  0000495800Y
28821204AAK27GA0000IYS001000SPY   0001425700Y
28821274X6K27GA000028000500
28821274A6K27GA000028S000500IWM   0000736600Y
28821277ABK27GA00006XS000100UWM   0000543200Y
28821277ABK27GA00006YB000100TWM   0000701200Y
28821357X6K27GA00003K002000
28821369XAK27GA0000IK002000
28821418XBK27GA00006N002000
28821420A9K27G60000HZB002000PDLI  0000010100Y
28821420A7K27GA00001CB002000LMT   0000057100Y
28821443XCK27GA00001M002000
28821449XBK27GA00006O002000
28821451X1K27GA00002P002000
28821499ACK27GA00001PB002000WYE   0000017700Y
28821540ACK27GA00001QB002000VRSN  0000381200Y
28821542X1K27GA00002O002000
28821557X2K27G6000012002000
28821590A1K27GA00002QB002000AFL   0000031900Y
28821602X2K27G600001N002000
28821617X2K27G600000X002000
28821622A7K27GA00001DB002000LMT   0000056300Y
28821624X3K27G600001G002000
28821637X3K27G600001O002000
28821657A3K27G600001WB002000DHI   0000138600Y
28821664A1K27GA00002RB002000AFL   0000031100Y
28821681X4K27GA00003L000200
28821681A4K27GA00003LB000200DIA   0001298400Y
28821685A3K27G600001XB002000DHR   0000758900Y
28821718A3K27G600001YB002000CVS   0000016300Y
28821718A4K27GA000057B002000DIS   0000327000Y
28821733A3K27G600001ZB002000DD    0000452600Y
28821744A4K27GA000058B002000DOW   0000397200Y
28821756A3K27G6000020B002000DE    0000790900Y
28821773A4K27GA000059B002000DOX   0000302400Y
28821782A3K27G6000021B002000DHI   0000137800Y
28821814A3K27G6000022B002000DHR   0000758100Y
28822021X4K27GA00003L000200
28822021A4K27GA00003LB000200DIA   0001298700Y
28822025A6K27GA00003RB000100IYF   0000856600Y
28822025X6K27GA00001Y000100
28822027ABK27GA00006ZB000100UYG   0000320200Y
28822271X9K27G60000HU005000
28822271X9K27G60000HV005000
28822271X9K27G60000HW005000
28822271A9K27G60000I0S005000QQQQ  0000495800Y
28822271A9K27G60000I1S002000QQQQ  0000495800Y
28822272X9K27G60000EQ002000
28822272A9K27G60000EQS002000QQQQ  0000495800Y
28822272A9K27G60000I2B005000QQQQ  0000495300Y
28822273A9K27G60000I3B005000QQQQ  0000495300Y
28822366X7K27GA00001C002000
28822369X7K27GA00001D002000
28822396A6K27GA00003SB002000IMCL  0000301900Y
28822414ABK27GA000070B002000UTX   0000036300Y
28822424ABK27GA000071B002000UTX   0000037100Y
28822427AAK27GA0000IZB002000SHLD  0000640600Y
28822447A3K27G6000023B002000CTSH  0000010000Y
28822467XCK27GA00001P002000
28822471ACK27GA00001RB002000WYE   0000018100Y
28822500A1K27GA00002SB002000ABT   0000026300Y
28822504A1K27GA00002TB002000ABT   0000025400Y
28822514X1K27GA00002R002000
28822521X1K27GA00002Q002000
28822524X4K27GA00003L000200
28822524A4K27GA00003LB000200DIA   0001298400Y
28822525X2K27G600001Q002000
28822524XAK27GA0000E5001000
28822524AAK27GA0000E5S001000SPY   0001425600Y
28822529XAK27GA0000F6000500
28822529AAK27GA0000F6S000500SPY   0001425600Y
28822539X3K27G600001R002000
28822548X3K27G600001Y002000
28822572A2K27G600001RB002000BBT   0000012900Y
28822589A2K27G600001SB002000BDX   0000754100Y
28822613A2K27G600001TB002000BDX   0000754900Y
28822613A4K27GA00005AB002000DIS   0000326300Y
28822638A4K27GA00005BB002000DOW   0000396400Y
28822643A3K27G6000024B002000COH   0000013900Y
28822660A4K27GA00005CB002000DOX   0000301600Y
28822669A3K27G6000025B002000CVS   0000018300Y
28822763X6K27GA000028000500
28822763A6K27GA000028S000500IWM   0000737000Y
28822764X6K27GA00003Q002000
28822769XBK27GA00006Y000100
28822769XBK27GA00006X000100
28822769A6K27GA00003TS000100IWM   0000737100Y
28822775X6K27GA00003T000100
28823203A5K27GA00001HB000100FSLR  0002930500Y
28823357XAK27GA0000IZ002000
28823388X4K27GA000055000100
28823388A4K27GA00005DB000100DRYS  0001065100Y
28823398X7K27GA00001B002000
28823399XBK27GA000070002000
28823411XBK27GA000071002000
28823416XCK27GA00001R002000
28823432X1K27GA00002S002000
28823434X1K27GA00002T002000
28823442X3K27G6000025002000
28823460A7K27GA00001EB002000LMT   0000063100Y
28823485ACK27GA00001SB002000WYE   0000020100Y
28823487A7K27GA00001FB002000LMT   0000062300Y
28823506A1K27GA00002UB002000AFL   0000034800Y
28823520A1K27GA00002VB002000AFL   0000035600Y
28823527A2K27G600001UB002000BBT   0000013100Y
28823529A4K27GA00005EB002000DUK   0000161900Y
28823561A4K27GA00005FB002000EAT   0000197300Y
28823567A3K27G6000026B002000COH   0000014100Y
28823578X4K27GA000056000100
28823579A4K27GA00005GB000100DRYS  0001065100Y
28823582A4K27GA00005HB002000EDS   0000226000Y
28823589X4K27GA00005G000100
28823597A4K27GA00005IB002000EIX   0000022000Y
28823599X4K27GA00005D000100
28823599A4K27GA00005JB000100DRYS  0001067100Y
28823609A4K27GA00005KB000100DRYS  0001065100Y
28823609A4K27GA00005LB002000EK    0000145400Y
28823619X4K27GA00005K000100
28823629A4K27GA00005MB000100DRYS  0001067100Y
28823638X4K27GA00005M000100
28823639A4K27GA00005NB000100DRYS  0001065100Y
28823648A3K27G6000027B002000CVS   0000018600Y
28823649X4K27GA00005N000100
28823659A4K27GA00005OB000100DRYS  0001067100Y
28823670A4K27GA00005PB002000DUK   0000161100Y
28823680A4K27GA00005QB002000EAT   0000196500Y
28823692A4K27GA00005RB002000EDS   0000225200Y
28823719X4K27GA00005O000100
28823719A4K27GA00005SB000100DRYS  0001065100Y
28823719X4K27GA00005J000100
28823719A4K27GA00005TB000100DRYS  0001065100Y
28824349X6K27GA00003S002000
28824392X5K27GA000014002000
28824395AAK27GA0000J0B002000SHLD  0000645700Y
28824395X7K27GA00001F002000
28824397X7K27GA00001E002000
28824403X1K27GA00002U002000
28824402XCK27GA00001S002000
28824415X3K27G6000027002000
28824447A7K27GA00001GB002000LPNT  0000177900Y
28824450X1K27GA00002V002000
28824463X2K27G600001R002000
28824487ABK27GA000072B002000UTX   0000040300Y
28824496X3K27G6000024002000
28824512X4K27GA00005I002000
28824522ACK27GA00001TB002000WYE   0000020500Y
28824542ABK27GA000073B002000UTX   0000041100Y
28824548A1K27GA00002WB002000ABT   0000028500Y
28824568A1K27GA00002XB002000ABT   0000029300Y
28824608A4K27GA00005UB002000EIX   0000022600Y
28824622A3K27G6000028B002000CVS   0000020600Y
28824631A4K27GA00005VB002000EK    0000144700Y
28824643A4K27GA00005WB002000EL    0000451200Y
28824654A4K27GA00005XB002000EL    0000450400Y
28824669A4K27GA00005YB002000ELN   0000225900Y
28824701A4K27GA00005ZB002000ELX   0000128700Y
28824716A4K27GA000060B002000EMC   0000167000Y
28824769XAK27GA0000IM001000
28824769X4K27GA00004X000047
28824770AAK27GA0000J1S001000SPY   0001425600Y
28824772XAK27GA0000GI002000
28824774X3K27G600001C000100
28824774A4K27GA000061S000047DIA   0001298800Y
28824785X6K27GA000028000500
28824785A6K27GA000028S000500IWM   0000736600Y
28824788ABK27GA000074S000100UWM   0000543200Y
28824786A6K27GA00003US002000IWM   0000736800Y
28824788ABK27GA000075B000100TWM   0000701200Y
28824789X9K27G60000F4003200
28824789A9K27G60000F4S003200QQQQ  0000495800Y
28824795XAK27GA0000E4001000
28824795AAK27GA0000E4B001000SPY   0001425000Y
28824795XAK27GA0000I2003000
28824795XAK27GA0000FD000500
28824795AAK27GA0000FDB000500SPY   0001425000Y
28824795XAK27GA0000IB000500
28824795AAK27GA0000IBS000500SPY   0001425600Y
28824796X8K27G600000M000100
28824795XAK27GA0000EX000500
28824795AAK27GA0000EXB000500SPY   0001425000Y
28824795XAK27GA0000I3003000
28824795AAK27GA0000J2S002000SPY   0001425600Y
28824795XAK27GA0000IL001000
28824795XAK27GA0000G2002000
28824795X4K27GA00003Q000200
28824795X4K27GA00003H000200
28824795A4K27GA00003HB000200DIA   0001298300Y
28824795AAK27GA0000J3S003000SPY   0001425600Y
28824795AAK27GA0000J4S003000SPY   0001425600Y
28824796XAK27GA0000G4000500
28824796XBK27GA00006U001000
28824796AAK27GA0000J5S000500SPY   0001425600Y
28824798A8K27G600000UB000100MVV   0000806000Y
28824797AAK27GA0000J6B001000SPY   0001425100Y
28824800A8K27G600000VB000500MZZ   0000491700Y
28824800A8K27G600000WS000100MVV   0000809100Y
28824803XAK27GA0000J5000500
28824803AAK27GA0000J5S000500SPY   0001425900Y
28824804A4K27GA000062B000200DIA   0001298200Y
28824804A4K27GA000063B000100DXD   0000499500Y
28824805A3K27G6000029S000100DDM   0000802500Y
28824804XAK27GA0000IY001000
28824805XBK27GA00006E001000
28824805ABK27GA000076B001000SSO   0000764000Y
28824805AAK27GA0000J7B001000SPY   0001425100Y
28824805XAK27GA0000GW001000
28824806XAK27GA0000I1000100
28824806AAK27GA0000J8S001000SPY   0001425800Y
28824807ABK27GA000077B001000SSO   0000764200Y
28824807AAK27GA0000J9B001000SPY   0001425100Y
28824807AAK27GA0000JAS000100SH    0000618900Y
28824809XAK27GA0000F2000500
28824809AAK27GA0000F2B000500SPY   0001424900Y
28824809XAK27GA0000FX003000
28824809X9K27G60000G0002000
28824809A9K27G60000G0B002000QQQQ  0000495100Y
28824809XAK27GA0000FE000500
28824809AAK27GA0000FEB000500SPY   0001424900Y
28824809XAK27GA0000FZ003000
28824809XAK27GA0000E7001000
28824809AAK27GA0000E7B001000SPY   0001424900Y
28824809XAK27GA0000GM000900
28824809X4K27GA00003L000200
28824809A4K27GA00003LB000200DIA   0001298100Y
28824810XAK27GA0000J5000500
28824810AAK27GA0000J5S000500SPY   0001425600Y
28824810XAK27GA0000JA000100
28824810XAK27GA0000F4000500
28824810AAK27GA0000F4S000500SPY   0001425600Y
28824810XAK27GA0000F5000500
28824810AAK27GA0000F5B000500SPY   0001424800Y
28824811XBK27GA000076001000
28824810AAK27GA0000JBB003000SPY   0001424500Y
28824811AAK27GA0000JCB003000SPY   0001424500Y
28824811AAK27GA0000JDB001000SPY   0001425000Y
28824811XAK27GA0000J9001000
28824811AAK27GA0000JES001000SPY   0001425600Y
28824811XAK27GA0000GN001000
28824812XAK27GA0000F4000500
28824813AAK27GA0000JFS001000SPY   0001425600Y
28824813XAK27GA0000JE001000
28824813XAK27GA0000F5000500
28824813AAK27GA0000F5B000500SPY   0001425200Y
28824813AAK27GA0000JGS000100SH    0000618900Y
28824813XAK27GA0000JG000100
28824813XAK27GA0000E7001000
28824813AAK27GA0000E7B001000SPY   0001425300Y
28824814X4K27GA00004J000100
28824814X4K27GA00004K000100
28824814X3K27G600000W000100
28824814XAK27GA0000F5000500
28824814AAK27GA0000F5B000500SPY   0001424800Y
28824815AAK27GA0000JHS001000SPY   0001425600Y
28824814X6K27GA00003H000500
28824814A6K27GA00003HB000500IWM   0000736000Y
28824815XAK27GA0000E7001000
28824815AAK27GA0000E7B001000SPY   0001424900Y
28824814X6K27GA00003J002000
28824816XAK27GA0000FH000500
28824816XAK27GA0000IB000500
28824816XAK27GA0000FC000500
28824816XAK27GA0000FF000500
28824816ABK27GA000078B001000SSO   0000763900Y
28824816XBK27GA000077001000
28824817XAK27GA0000F5000500
28824817AAK27GA0000F5B000500SPY   0001425200Y
28824818ABK27GA000079B001000SSO   0000764100Y
28824818XAK27GA0000E7001000
28824818AAK27GA0000E7B001000SPY   0001425300Y
28824817X6K27GA00003H000500
28824817A6K27GA00003HB000500IWM   0000736400Y
28824819XBK27GA00006G000100
28824819XBK27GA00006F000100
28824820XAK27GA0000E7001000
28824820AAK27GA0000E7B001000SPY   0001424900Y
28824820X6K27GA00003H000500
28824820A6K27GA00003HB000500IWM   0000736000Y
28824822ABK27GA00007AS000100TWM   0000702200Y
28824822ABK27GA00007BB000100UWM   0000542300Y
28824822XAK27GA0000E7001000
28824822AAK27GA0000E7B001000SPY   0001425300Y
28824823XBK27GA00007B000100
28824823XBK27GA00007A000100
28824825ABK27GA00007CS000100TWM   0000702400Y
28824826X6K27GA00003H000500
28824826A6K27GA00003HB000500IWM   0000736400Y
28824828ABK27GA00007DB000100UWM   0000542300Y
28824828XBK27GA00007C000100
28824828ABK27GA00007ES000100TWM   0000702200Y
28824829X6K27GA00003H000500
28824829A6K27GA00003HB000500IWM   0000736000Y
28824834XAK27GA0000J7001000
28824834AAK27GA0000JIB001000SPY   0001425000Y
28824833X6K27GA00003H000500
28824833A6K27GA00003HB000500IWM   0000736400Y
28824834XBK27GA00007D000100
28824835XBK27GA00007E000100
28824834XAK27GA0000E7001000
28824834AAK27GA0000E7B001000SPY   0001424900Y
28824834X6K27GA00003H000500
28824834A6K27GA00003HB000500IWM   0000736000Y
28824835AAK27GA0000JJB001000SPY   0001425100Y
28824836XAK27GA0000E7001000
28824836AAK27GA0000E7B001000SPY   0001425300Y
28824836ABK27GA00007FB000100UWM   0000542300Y
28824836ABK27GA00007GS000100TWM   0000702200Y
28824838XBK27GA00007F000100
28824838XBK27GA00007G000100
28824838XAK27GA0000E7001000
28824838AAK27GA0000E7B001000SPY   0001424900Y
28824840ABK27GA00007HB000100UWM   0000542300Y
28824839A6K27GA00003VB000100IWM   0000735900Y
28824840ABK27GA00007IS000100TWM   0000702200Y
28824839X6K27GA00003V000100
28824844XAK27GA0000E7001000
28824844AAK27GA0000E7B001000SPY   0001425300Y
28824847XAK27GA0000JJ001000
28824848A8K27G600000XB000500MZZ   0000491800Y
28824849A8K27G600000YS000100MVV   0000809000Y
28824848XBK27GA00007H000100
28824849XBK27GA00007I000100
28824850ABK27GA00007JS000100TWM   0000702400Y
28824853X4K27GA000054000200
28824854X8K27G600000L000500
28824854X8K27G600000U000100
28824855AAK27GA0000JKB001000SDS   0000547700Y
28824855XBK27GA00006W001000
28824855ABK27GA00007KS001000SSO   0000765100Y
28824856AAK27GA0000JLB001000SDS   0000547600Y
28824856XAK27GA0000IR001000
28824858A4K27GA000064S000200DIA   0001298700Y
28824858XAK27GA0000E7001000
28824858AAK27GA0000E7B001000SPY   0001424900Y
28824859AAK27GA0000JMB001000SDS   0000547400Y
28824858A6K27GA00003WS002000IWM   0000736700Y
28824859XAK27GA0000J5000500
28824859AAK27GA0000J5S000500SPY   0001425500Y
28824860A4K27GA000065B000100DOG   0000597100Y
28824861A3K27G600002AS000100DDM   0000802400Y
28824861XAK27GA0000E7001000
28824861AAK27GA0000E7B001000SPY   0001425300Y
28824866X4K27GA00003L000200
28824866A4K27GA00003LB000200DIA   0001298400Y
28824869XAK27GA0000EA001000
28824869AAK27GA0000EAS001000SPY   0001425500Y
28824869XAK27GA0000E7001000
28824869AAK27GA0000E7B001000SPY   0001424900Y
28824869XAK27GA0000GK001000
28824870AAK27GA0000JNS001000SPY   0001425500Y
28824871XAK27GA0000E7001000
28824871AAK27GA0000E7B001000SPY   0001425300Y
28824874XAK27GA0000J5000500
28824879XAK27GA0000E7001000
28824879AAK27GA0000E7B001000SPY   0001424900Y
28824882XAK27GA0000E7001000
28824882AAK27GA0000E7B001000SPY   0001425300Y
28824885AAK27GA0000JOB000100SH    0000618400Y
28824885AAK27GA0000JPB001000SDS   0000547800Y
28824885ABK27GA00007LS001000SSO   0000765000Y
28824885XBK27GA00007K001000
28824886AAK27GA0000JQB001000SDS   0000547700Y
28824886XAK27GA0000GH000100
28824886AAK27GA0000JRS000100SPY   0001426600Y
28824888XAK27GA0000JI001000
28824890AAK27GA0000JSB001000SPY   0001424900Y
28824890XAK27GA0000E7001000
28824890AAK27GA0000E7B001000SPY   0001424900Y
28824892XAK27GA0000JN001000
28824892XAK27GA0000J1001000
28824892XAK27GA0000JD001000
28824892XAK27GA0000E7001000
28824892AAK27GA0000E7B001000SPY   0001425300Y
28824892AAK27GA0000JTB001000SPY   0001425400Y
28824893AAK27GA0000JUS001000SDS   0000549000Y
28824894XBK27GA000079001000
28824894ABK27GA00007MB001000SSO   0000764200Y
28824894AAK27GA0000JVS001000SPY   0001425600Y
28824896XBK27GA000078001000
28824896ABK27GA00007NB001000SSO   0000764000Y
28824903XAK27GA0000E7001000
28824903AAK27GA0000E7B001000SPY   0001424900Y
28824903XAK27GA0000JT001000
28824903XBK27GA00007N001000
28824903AAK27GA0000JWS001000SPY   0001425500Y
28824904XAK27GA0000JV001000
28824905XBK27GA00007M001000
28824905XAK27GA0000JU001000
28824905ABK27GA00007OB001000SSO   0000763900Y
28824906AAK27GA0000JXS001000SPY   0001425600Y
28824906AAK27GA0000JYB001000SPY   0001425000Y
28824906XAK27GA0000E7001000
28824906AAK27GA0000E7B001000SPY   0001425300Y
28824907ABK27GA00007PB001000SSO   0000764100Y
28824914XAK27GA0000JK001000
28824917XAK27GA0000EA001000
28824917XAK27GA0000JW001000
28824919XAK27GA0000E7001000
28824919AAK27GA0000E7B001000SPY   0001424900Y
28824923PAK27GA0000EAS000500SPY   0001425500000NAAQ00001
28824923PAK27GA0000JWS000500SPY   0001425500000NAAQ00004
28824923PAK27GA0000EAS000500SPY   0001425500000NAAQ00002
28824923PAK27GA0000JWS000500SPY   0001425500000NAAQ00003
28824931X9K27G60000F4003200
28824931A9K27G60000F4S003200QQQQ  0000496300Y
28824931X9K27G60000I2005000
28824931X9K27G60000I3005000
28824931A9K27G60000I4B005000QQQQ  0000495700Y
28824932A9K27G60000I5B005000QQQQ  0000495700Y
28824932XBK27GA000068001000
28824934ABK27GA00007QB001000SSO   0000763700Y
28824945AAK27GA0000JZS001000SDS   0000549000Y
28824945ABK27GA00007RB001000SSO   0000764200Y
28824945XBK27GA00007P001000
28824946XAK27GA0000F2000500
28824946AAK27GA0000F2B000500SPY   0001425300Y
28824946XAK27GA0000JX001000
28824946XAK27GA0000JY001000
28824946XAK27GA0000E7001000
28824946AAK27GA0000E7B001000SPY   0001425300Y
28824946AAK27GA0000K0B001000SPY   0001425300Y
28824947AAK27GA0000K1S001000SPY   0001425900Y
28824948AAK27GA0000K2S001000SPY   0001425600Y
28824951AAK27GA0000K3S001000SPY   0001425900Y
28824951XAK27GA0000F2000500
28824951AAK27GA0000F2B000500SPY   0001424900Y
28824951XAK27GA0000K0001000
28824952XAK27GA0000JZ001000
28824952XBK27GA00007R001000
28824952AAK27GA0000K4B001000SPY   0001425000Y
28824953XAK27GA0000F2000500
28824953AAK27GA0000F2B000500SPY   0001425300Y
28824954ABK27GA00007SB001000SSO   0000764200Y
28824954XAK27GA0000K4001000
28824954AAK27GA0000K5S001000SDS   0000549000Y
28824954XAK27GA0000JP001000
28824955XAK27GA0000JO000100
28824955XBK27GA00007L001000
28824954X6K27GA000026000500
28824954A6K27GA000026S000500IWM   0000736500Y
28824956XAK27GA0000HQ001000
28824956XAK27GA0000JM001000
28824957ABK27GA00007TS001000SSO   0000765100Y
28824956AAK27GA0000K6B001000SDS   0000547700Y
28824957ABK27GA00007US000100UWM   0000543100Y
28824958ABK27GA00007VB000100TWM   0000701400Y
28824958ABK27GA00007WB000100TWM   0000701300Y
28824966XAK27GA0000JQ001000
28824966AAK27GA0000K7B001000SPY   0001425300Y
28824966XAK27GA0000K3001000
28824967AAK27GA0000K8S001000SPY   0001425500Y
28824968XAK27GA0000K2001000
28824969XAK27GA0000K8001000
28824973X9K27G60000I5005000
28824974AAK27GA0000K9S001000SPY   0001425600Y
28824975A9K27G60000I6B005000QQQQ  0000495300Y
28824974AAK27GA0000KAB000100SH    0000618400Y
28824974AAK27GA0000KBB001000SDS   0000547800Y
28824975XBK27GA00007T001000
28824975ABK27GA00007XS001000SSO   0000765000Y
28824976AAK27GA0000KCS001000SPY   0001425900Y
28824976AAK27GA0000KDB001000SDS   0000547700Y
28824980XAK27GA0000KC001000
28824980XAK27GA0000K7001000
28824980AAK27GA0000KES001000SPY   0001425600Y
28824981XBK27GA00007S001000
28824980XAK27GA0000K5001000
28824981XAK27GA0000F2000500
28824981AAK27GA0000F2B000500SPY   0001424900Y
28824983ABK27GA00007YB001000SSO   0000764100Y
28824984X9K27G60000I6005000
28824984XAK27GA0000F2000500
28824984AAK27GA0000F2B000500SPY   0001425300Y
28824985A9K27G60000I7B005000QQQQ  0000495700Y
28824985AAK27GA0000KFB001000SPY   0001425000Y
28824988XAK27GA0000F2000500
28824988AAK27GA0000F2B000500SPY   0001424900Y
28824989X9K27G60000G0002000
28824989A9K27G60000G0B002000QQQQ  0000495600Y
28824988XAK27GA0000JB003000
28824988X4K27GA000062000200
28824988A4K27GA000062B000200DIA   0001298500Y
28824988XAK27GA0000JC003000
28824988AAK27GA0000KGB003000SPY   0001425100Y
28824988AAK27GA0000KHB003000SPY   0001425100Y
28824995XAK27GA0000KE001000
28824995AAK27GA0000KES001000SPY   0001425500Y
28824999X9K27G60000I7005000
28824999X9K27G60000I4005000
28824999X9K27G60000G0002000
28824999A9K27G60000G0B002000QQQQ  0000495100Y
28825000A9K27G60000I8B005000QQQQ  0000495300Y
28825001A9K27G60000I9B005000QQQQ  0000495300Y
28825008XAK27GA0000F2000500
28825008AAK27GA0000F2B000500SPY   0001425300Y
28825008XAK27GA0000JS001000
28825009AAK27GA0000KIB001000SPY   0001425000Y
28825009XAK27GA0000JH001000
28825018AAK27GA0000KJB002000SPY   0001425100Y
28825023X9K27G60000I9005000
28825023X9K27G60000I8005000
28825023A9K27G60000IAB005000QQQQ  0000495700Y
28825023A9K27G60000IBB005000QQQQ  0000495700Y
28825040X9K27G60000G0002000
28825040A9K27G60000G0B002000QQQQ  0000495600Y
28825039XAK27GA0000J4003000
28825039XAK27GA0000J3003000
28825041AAK27GA0000KKS003000SPY   0001426200Y
28825041AAK27GA0000KLS003000SPY   0001426200Y
28825045XAK27GA0000FE000500
28825045AAK27GA0000FEB000500SPY   0001425300Y
28825047XAK27GA0000K6001000
28825065XAK27GA0000KL003000
28825065XAK27GA0000KK003000
28825066AAK27GA0000KMS003000SPY   0001425600Y
28825066AAK27GA0000KNS003000SPY   0001425600Y
28825072X6K27GA000026000500
28825072A6K27GA000026S000500IWM   0000736900Y
28825073X6K27GA00003W002000
28825077XBK27GA00007X001000
28825079XBK27GA00007U000100
28825079XBK27GA00007V000100
28825079XBK27GA00007W000100
28825079XAK27GA0000JL001000
28825080ABK27GA00007ZS001000SSO   0000765100Y
28825079A6K27GA00003XS000100IWM   0000737000Y
28825081AAK27GA0000KOB001000SDS   0000547600Y
28825083X9K27G60000IB005000
28825083X9K27G60000IA005000
28825086XAK27GA0000KD001000
28825085X6K27GA00003X000100
28825088X6K27GA00003H000500
28825088A6K27GA00003HB000500IWM   0000736400Y
28825091ABK27GA000080B000100UWM   0000542300Y
28825091XBK27GA00007J000100
28825089X6K27GA00003H000500
28825089A6K27GA00003HB000500IWM   0000736000Y
28825091ABK27GA000081S000100TWM   0000702200Y
28825093A9K27G60000ICB005000QQQQ  0000495300Y
28825093A9K27G60000IDB005000QQQQ  0000495300Y
28825092X6K27GA00003H000500
28825092A6K27GA00003HB000500IWM   0000736400Y
28825094XBK27GA000080000100
28825094XBK27GA000081000100
28825096ABK27GA000082S000100TWM   0000702200Y
28825096ABK27GA000083B000100UWM   0000542300Y
28825095X6K27GA00003H000500
28825095A6K27GA00003HB000500IWM   0000736000Y
28825097X6K27GA00003H000500
28825097A6K27GA00003HB000500IWM   0000736400Y
28825099XBK27GA000083000100
28825099XBK27GA000082000100
28825100ABK27GA000084B000100UWM   0000542300Y
28825099A6K27GA00003YB000100IWM   0000735900Y
28825100ABK27GA000085S000100TWM   0000702200Y
28825099X6K27GA00003Y000100
28825107X6K27GA00003H000500
28825107A6K27GA00003HB000500IWM   0000736000Y
28825109X6K27GA00003H000500
28825109A6K27GA00003HB000500IWM   0000736400Y
28825160X8K27G600000X000500
28825160X8K27G600000W000100
28825160X8K27G600000Y000100
28825162A8K27G600000ZS000100MVV   0000809100Y
28825169X8K27G600000J000500
28825169X8K27G600000D000100
28825170X8K27G600000K000100
28825171A8K27G6000010B000100MVV   0000805800Y
28825188A8K27G6000011S000500MZZ   0000494000Y
28825188A8K27G6000012B000100MVV   0000806000Y
28825194XAK27GA0000KA000100
28825194XAK27GA0000KB001000
28825196AAK27GA0000KPB001000SDS   0000547700Y
28825319X4K27GA00005T000100
28825319X4K27GA00005S000100
28825362XAK27GA0000J0002000
28825395XBK27GA000072002000
28825395X3K27G6000023002000
28825400XCK27GA00001T002000
28825408A6K27GA00003ZB002000IMCL  0000305100Y
28825429X1K27GA00002W002000
28825438XBK27GA000073002000
28825458X1K27GA00002X002000
28825460A5K27GA00001IB002000GM    0000172200Y
28825469A1K27GA00002YB000095AAPL  0001830100Y
28825485X2K27G600001O002000
28825495X2K27G600001P002000
28825496A7K27GA00001HB002000LMT   0000069100Y
28825505X2K27G600001U002000
28825510A7K27GA00001IB002000LMT   0000068300Y
28825515ACK27GA00001UB002000WYE   0000022500Y
28825517X3K27G6000026002000
28825541A1K27GA00002ZB002000AFL   0000038600Y
28825546X3K27G6000028002000
28825555A1K27GA000030B002000AFL   0000039400Y
28825560A3K27G600002BB002000CVS   0000021000Y
28825571X4K27GA00005U002000
28825576A2K27G600001VB002000BBT   0000015700Y
28825599A3K27G600002CB002000COH   0000016900Y
28825625A4K27GA000066B002000EIX   0000024800Y
28825660A4K27GA000067B002000ELN   0000225200Y
28825666A4K27GA000068B002000EOG   0001386000Y
28825689A4K27GA000069B002000ELX   0000127900Y
28825705A4K27GA00006AB002000EMC   0000166200Y
28825720A4K27GA00006BB002000EOG   0001385200Y
28825938XAK27GA0000F6000500
28825940ABK27GA000086B001000SSO   0000764200Y
28825940XBK27GA00007Y001000
28825944AAK27GA0000KQS001000SDS   0000549000Y
28826278XAK27GA0000KN003000
28826278XAK27GA0000KM003000
28826284AAK27GA0000KRS003000SPY   0001426200Y
28826284AAK27GA0000KSS003000SPY   0001426200Y
28826355X3K27G600001M002000
28826380X7K27GA00001I002000
28826383X5K27GA000018002000
28826397AAK27GA0000KTB002000SHLD  0000650800Y
28826398X7K27GA00001H002000
28826423ABK27GA000087B002000UTX   0000044300Y
28826440A3K27G600002DB002000CTSH  0000013500Y
28826445ABK27GA000088B002000UTX   0000045100Y
28826474XCK27GA00001U002000
28826489X1K27GA00002Z002000
28826492AAK27GA0000KUS001000SPY   0001425600Y
28826493XAK27GA0000KR003000
28826493XAK27GA0000KS003000
28826494AAK27GA0000KVS003000SPY   0001425600Y
28826495AAK27GA0000KWS003000SPY   0001425600Y
28826499ACK27GA00001VB002000WYE   0000022900Y
28826513A1K27GA000031B002000ABT   0000032400Y
28826517A4K27GA00006CB000100DRYS  0001067100Y
28826517X4K27GA00004W000100
28826517A4K27GA00006DB000100DRYS  0001067100Y
28826520X1K27GA000030002000
28826530A1K27GA000032B002000ABT   0000031500Y
28826561A2K27G600001WB002000AXP   0000396900Y
28826563A2K27G600001XB002000AXP   0000396100Y
28826578X3K27G600002B002000
28826585A2K27G600001YB002000BBT   0000015900Y
28826591A6K27GA000040S000100IYF   0000859000Y
28826602A3K27G600002EB002000COH   0000017100Y
28826602A3K27G600002FB002000CVS   0000023000Y
28826613X4K27GA000066002000
28826636A4K27GA00006EB002000EIX   0000025400Y
28826645A4K27GA00006FB002000ESI   0000615400Y
28826666A4K27GA00006GB002000ESI   0000614600Y
28826672A4K27GA00006HB002000ESV   0000727300Y
28826687A4K27GA00006IB002000ESV   0000726500Y
28826697A4K27GA00006JB002000EXC   0000857100Y
28826710X9K27G60000IC005000
28826710X9K27G60000ID005000
28826711A9K27G60000IEB005000QQQQ  0000495700Y
28826711A9K27G60000IFB005000QQQQ  0000495700Y
28826760XAK27GA0000KJ001000
28826767XAK27GA0000KQ001000
28826767XBK27GA000086001000
28826769ABK27GA000089B001000SSO   0000764100Y
28826780XAK27GA0000KG003000
28826780XAK27GA0000KJ001000
28826780XAK27GA0000KI001000
28826780XAK27GA0000KH003000
28826782AAK27GA0000KXB003000SPY   0001424500Y
28826782AAK27GA0000KYB003000SPY   0001424500Y
28826782AAK27GA0000KZB001000SPY   0001424900Y
28826782AAK27GA0000L0B001000SPY   0001424900Y
28826784XAK27GA0000F2000500
28826784AAK27GA0000F2B000500SPY   0001424900Y
28826785XAK27GA0000FE000500
28826785AAK27GA0000FEB000500SPY   0001424900Y
28826787AAK27GA0000L1B000100SH    0000618400Y
28826787XAK27GA0000KP001000
28826787AAK27GA0000L2B001000SDS   0000547800Y
28826794X4K27GA000062000200
28826794A4K27GA000062B000200DIA   0001298200Y
28826800X6K27GA00003H000500
28826800A6K27GA00003HB000500IWM   0000736000Y
28826802X6K27GA00003H000500
28826802A6K27GA00003HB000500IWM   0000736400Y
28826805XBK27GA00007Z001000
28826805ABK27GA00008AS001000SSO   0000765000Y
28826806AAK27GA0000L3B001000SDS   0000547700Y
28826807X6K27GA00003H000500
28826807A6K27GA00003HB000500IWM   0000736000Y
28826810XBK27GA000084000100
28826810XBK27GA000085000100
28826809X6K27GA00003H000500
28826809A6K27GA00003HB000500IWM   0000736400Y
28826812ABK27GA00008BB000100UWM   0000542300Y
28826812ABK27GA00008CS000100TWM   0000702200Y
28826811X6K27GA00003H000500
28826811A6K27GA00003HB000500IWM   0000736000Y
28826814XBK27GA00008B000100
28826814XBK27GA00008C000100
28826817ABK27GA00008DS000100TWM   0000702400Y
28826818ABK27GA00008EB000100UWM   0000542300Y
28826819ABK27GA00008FS000100TWM   0000702200Y
28826819XBK27GA00008D000100
28826822XAK27GA0000L0001000
28826852X8K27G6000011000500
28826852X8K27G6000012000100
28826858A8K27G6000013S000500MZZ   0000494100Y
28826858A8K27G6000014B000100MVV   0000805900Y
28826863A8K27G6000015B000500MZZ   0000491800Y
28826863A8K27G6000016S000100MVV   0000809000Y
28826862XAK27GA0000FE000500
28826862AAK27GA0000FEB000500SPY   0001425300Y
28826862XAK27GA0000F2000500
28826862AAK27GA0000F2B000500SPY   0001425300Y
28826863XAK27GA0000KX003000
28826863XAK27GA0000KY003000
28826863AAK27GA0000L4B003000SPY   0001425100Y
28826863AAK27GA0000L5B003000SPY   0001425100Y
28826863XAK27GA0000KZ001000
28826863AAK27GA0000L6B001000SPY   0001425000Y
28826867XBK27GA00008A001000
28826869XAK27GA0000KO001000
28826869ABK27GA00008GS001000SSO   0000765100Y
28826869XAK27GA0000L1000100
28826869XAK27GA0000L2001000
28826870AAK27GA0000L7B001000SDS   0000547600Y
28826871AAK27GA0000L8B001000SDS   0000547700Y
28826876XAK27GA0000L3001000
28826885X4K27GA000062000200
28826885A4K27GA000062B000200DIA   0001298500Y
28826887X6K27GA00003H000500
28826887A6K27GA00003HB000500IWM   0000736400Y
28826888X6K27GA00003H000500
28826888A6K27GA00003HB000500IWM   0000736000Y
28826890X6K27GA00003H000500
28826890A6K27GA00003HB000500IWM   0000736400Y
28826895X9K27G60000G0002000
28826895A9K27G60000G0B002000QQQQ  0000495100Y
28826895XAK27GA0000FE000500
28826895AAK27GA0000FEB000500SPY   0001424900Y
28826895XAK27GA0000L6001000
28826897AAK27GA0000L9B001000SPY   0001424900Y
28826897X6K27GA00003H000500
28826897A6K27GA00003HB000500IWM   0000736000Y
28826907X6K27GA00003H000500
28826907A6K27GA00003HB000500IWM   0000736400Y
28826908XBK27GA00008E000100
28826908XBK27GA00008F000100
28826910ABK27GA00008HB000100UWM   0000542300Y
28826910ABK27GA00008IS000100TWM   0000702200Y
28826910X6K27GA00003H000500
28826910A6K27GA00003HB000500IWM   0000736000Y
28826913XBK27GA00008H000100
28826913XBK27GA00008I000100
28826915ABK27GA00008JS000100TWM   0000702400Y
28826914X6K27GA00003H000500
28826914A6K27GA00003HB000500IWM   0000736400Y
28826917ABK27GA00008KB000100UWM   0000542300Y
28826917XBK27GA00008J000100
28826917ABK27GA00008LS000100TWM   0000702200Y
28826917X6K27GA00003H000500
28826917A6K27GA00003HB000500IWM   0000736000Y
28826919XAK27GA0000FE000500
28826919AAK27GA0000FEB000500SPY   0001425300Y
28826920A6K27GA000041S002000IWM   0000736700Y
28826920X6K27GA00003U002000
28826925AAK27GA0000LAB000100SH    0000618400Y
28826925AAK27GA0000LBB001000SDS   0000547800Y
28826926ABK27GA00008MS001000SSO   0000765000Y
28826926XBK27GA00008G001000
28826926AAK27GA0000LCB001000SDS   0000547700Y
28826928XBK27GA00008L000100
28826928XBK27GA00008K000100
28826928A6K27GA000042S002000IWM   0000736800Y
28826930ABK27GA00008NS000100TWM   0000702400Y
28826932X9K27G60000IE005000
28826937X4K27GA000064000200
28826939A4K27GA00006KS000200DIA   0001298700Y
28826943A9K27G60000IGB005000QQQQ  0000495300Y
28826943X9K27G60000EP002000
28826943A9K27G60000EPB002000QQQQ  0000495400Y
28826943X6K27GA000041002000
28826952XAK27GA0000L4003000
28826953XAK27GA0000L5003000
28826957X9K27G60000IF005000
28826963A9K27G60000IHB005000QQQQ  0000495300Y
28826969AAK27GA0000LDB003000SPY   0001424500Y
28826969AAK27GA0000LEB003000SPY   0001424500Y
28826968A6K27GA000043S002000IWM   0000736700Y
28826989XAK27GA0000F2000500
28826989AAK27GA0000F2B000500SPY   0001424900Y
28826994XAK27GA0000FE000500
28826994AAK27GA0000FEB000500SPY   0001424900Y
28827355X6K27GA00003Z002000
28827361XAK27GA0000KT002000
28827404XAK27GA0000HW002000
28827407XBK27GA000088002000
28827419XBK27GA000087002000
28827422A3K27G600002GB002000CELG  0000462300Y
28827423X1K27GA000031002000
28827424XCK27GA00001V002000
28827447X1K27GA000032002000
28827453X2K27G600001V002000
28827468X2K27G6000016002000
28827477X2K27G600001D002000
28827486X4K27GA00006E002000
28827495A7K27GA00001JB002000LMT   0000074300Y
28827508X3K27G600002C002000
28827518X3K27G600002F002000
28827520X9K27G60000F4003200
28827520A9K27G60000F4S003200QQQQ  0000495800Y
28827531A5K27GA00001JB002000GM    0000173200Y
28827537A1K27GA000033B002000AFL   0000042300Y
28827564A3K27G600002HB002000CVS   0000023400Y
28827569A7K27GA00001KB002000LMT   0000075100Y
28827602ACK27GA00001WB002000WYE   0000024900Y
28827616A1K27GA000034B002000AFL   0000043100Y
28827622A4K27GA00006LB002000EIX   0000027600Y
28827640A4K27GA00006MB002000FCX   0001223100Y
28827700A4K27GA00006NB002000EXC   0000856300Y
28827711A4K27GA00006OB002000FCX   0001222300Y
28827721A4K27GA00006PB002000FDO   0000181000Y
28827948A4K27GA00006QS000100DRYS  0001069800Y
28828018A4K27GA00006RB000100DXD   0000499600Y
28828019A3K27G600002IS000100DDM   0000802200Y
28828030XAK27GA0000J8001000
28828031AAK27GA0000LFS001000SPY   0001425500Y
28828031XAK27GA0000IX001000
28828043XAK27GA0000E7001000
28828043AAK27GA0000E7B001000SPY   0001424900Y
28828043XAK27GA0000G8001000
28828044AAK27GA0000LGS001000SPY   0001425400Y
28828359X7K27GA00001K002000
28828375X7K27GA00001J002000
28828374XCK27GA00001W002000
28828418X7K27GA00001G002000
28828426A6K27GA000044B002000IMCL  0000308400Y
28828434ABK27GA00008OB002000UTX   0000048300Y
28828453X1K27GA000034002000
28828459ABK27GA00008PB002000UTX   0000049100Y
28828460AAK27GA0000LHB002000SHLD  0000655900Y
28828475X1K27GA00002D002000
28828479AAK27GA0000LIB002000SNDK  0000217400Y
28828492ACK27GA00001XB002000WYE   0000025300Y
28828513X4K27GA00006C000100
28828514X4K27GA00006D000100
28828519A4K27GA00006SB000100DRYS  0001067400Y
28828519A4K27GA00006TB000100DRYS  0001067400Y
28828528A1K27GA000035B002000ABT   0000035400Y
28828529X1K27GA000033002000
28828532A1K27GA000036B002000ABT   0000034600Y
28828545X2K27G600001T002000
28828554X1K27GA000029002000
28828573X2K27G600001Y002000
28828573X2K27G600001S002000
28828597A2K27G600001ZB002000BBT   0000018600Y
28828613A2K27G6000020B002000BNI   0001057300Y
28828622X3K27G600002E002000
28828623A2K27G6000021B002000BNI   0001056500Y
28828629X3K27G600002H002000
28828646X4K27GA00006L002000
28828660A3K27G600002JB002000COH   0000019900Y
28828667A4K27GA00006UB002000EIX   0000028200Y
28828683A3K27G600002KB002000CVS   0000025300Y
28828711A4K27GA00006VB002000FDX   0000875900Y
28828795XAK27GA0000K1001000
28828795AAK27GA0000K1S001000SPY   0001425500Y
28828817X4K27GA000062000200
28828817A4K27GA000062B000200DIA   0001298200Y
28828844AAK27GA0000LJS001000SPY   0001425500Y
28828919XAK27GA0000GB000900
28828921XBK27GA00007O001000
28828922AAK27GA0000LKB000900SPY   0001424900Y
28828926XAK27GA0000GA001000
28828926ABK27GA00008QB001000SSO   0000763800Y
28828926XBK27GA000089001000
28828928ABK27GA00008RB001000SSO   0000764000Y
28828934XAK27GA0000G9000100
28828947ABK27GA00008SS001000SSO   0000764900Y
28828947XBK27GA00008M001000
28828948AAK27GA0000LLB001000SDS   0000547800Y
28829278X9K27G60000GW002000
28829279X9K27G60000GV001000
28829282A9K27G60000IIB001000QQQQ  0000495200Y
28829283X9K27G60000GL001000
28829283X9K27G60000GN001000
28829285A9K27G60000IJB001000QLD   0000888700Y
28829289X9K27G60000GO000100
28829290X9K27G60000II001000
28829295X9K27G60000IJ001000
28829295A9K27G60000IKB001000QQQQ  0000495100Y
28829296A9K27G60000ILB001000QLD   0000888600Y
28829297A9K27G60000IMB001000QQQQ  0000495200Y
28829299X9K27G60000IM001000
28829304X9K27G60000GH002000
28829304X4K27GA00004C000100
28829304X3K27G600000T000100
28829305X9K27G60000G9002000
28829305A9K27G60000G9S002000QQQQ  0000495700Y
28829306A4K27GA00006WS000100DXD   0000500600Y
28829306A3K27G600002LB000100DDM   0000800700Y
28829306A9K27G60000INS001000QLD   0000890400Y
28829307X9K27G60000IN001000
28829307A9K27G60000IOS001000QLD   0000890300Y
28829313A9K27G60000IPS001000QLD   0000890400Y
28829320A9K27G60000IQS002000QQQQ  0000495800Y
28829352X9K27G60000IQ002000
28829383XAK27GA0000LH002000
28829393X3K27G600002D002000
28829402XBK27GA00008O002000
28829411X9K27G60000HZ002000
28829413XBK27GA00008P002000
28829426XCK27GA00001X002000
28829449X1K27GA000035002000
28829457X1K27GA000036002000
28829489A7K27GA00001LB002000LMT   0000081100Y
28829490A7K27GA00001MB002000LPNT  0000181200Y
28829503X4K27GA00006U002000
28829518ACK27GA00001YB002000WYE   0000027300Y
28829527XAK27GA0000G1003000
28829527XAK27GA0000G5003000
28829527XAK27GA0000FI000500
28829527AAK27GA0000FIB000500SPY   0001424800Y
28829527XAK27GA0000F5000500
28829527AAK27GA0000F5B000500SPY   0001424800Y
28829528AAK27GA0000LMS003000SPY   0001425400Y
28829528AAK27GA0000LNS003000SPY   0001425400Y
28829531A7K27GA00001NB002000LMT   0000080300Y
28829540X4K27GA000053000200
28829542A4K27GA00006XS000200DIA   0001298600Y
28829549AAK27GA0000LOB001000SPY   0001424800Y
28829549XAK27GA0000L9001000
28829551AAK27GA0000LPB001000SPY   0001424800Y
28829552X4K27GA00003L000200
28829552A4K27GA00003LB000200DIA   0001298100Y
28829560AAK27GA0000LQS002000SPY   0001425300Y
28829561A1K27GA000037B002000AFL   0000046000Y
28829562A1K27GA000038B002000AFL   0000046800Y
28829564XAK27GA0000E8001000
28829564AAK27GA0000E8B001000SPY   0001424800Y
28829570X4K27GA00003L000200
28829570A4K27GA00003LB000200DIA   0001298400Y
28829570A4K27GA00006YB000100DOG   0000597200Y
28829571X4K27GA00004G000100
28829571A4K27GA00006ZB000100DXD   0000499700Y
28829571A3K27G600002MS000100DDM   0000802100Y
28829571X3K27G600000Z000100
28829574A1K27GA000039B002000ARO   0000292200Y
28829578A1K27GA00003AB002000ARO   0000293000Y
28829583A2K27G6000022B002000BBT   0000018700Y
28829593A2K27G6000023B002000BDX   0000755500Y
28829601X3K27G600002K002000
28829602A3K27G600002NB002000COH   0000020100Y
28829624A3K27G600002OB002000CVS   0000025700Y
28829634A2K27G6000024B002000BDX   0000756300Y
28829652A2K27G6000025B002000CAG   0000010600Y
28829661A4K27GA000070B002000FE    0000751600Y
28829678A4K27GA000071B002000EIX   0000030400Y
28829681AAK27GA0000LRS001000SPY   0001425400Y
28829681XAK27GA0000JF001000
28829681XAK27GA0000KU001000
28829700A9K27G60000IRS002000QQQQ  0000495800Y
28829706A4K27GA000072B002000FDO   0000181800Y
28830378X6K27GA000044002000
28830384X7K27GA00001L002000
28830398XCK27GA00001Y002000
28830403X7K27GA00001N002000
28830424AAK27GA0000LSB002000SHLD  0000661000Y
28830426X1K27GA000038002000
28830428XCK27GA00001D002000
28830436X2K27G600001Z002000
28830440X1K27GA000037002000
28830455X3K27G600002J002000
28830477A3K27G600002PB002000CTSH  0000016900Y
28830489X4K27GA000071002000
28830489X3K27G600002O002000
28830512A2K27G6000026B002000BMY   0000010000Y
28830522A9K27G60000ISB002000PDLI  0000012500Y
28830531ABK27GA00008TB002000UTX   0000052300Y
28830568ACK27GA00001ZB002000WYE   0000027700Y
28830576ABK27GA00008UB002000UTX   0000053100Y
28830600A1K27GA00003BB002000ABT   0000037700Y
28830600A1K27GA00003CB002000ABT   0000038500Y
28830624A2K27G6000027B002000CAG   0000010400Y
28830624A3K27G600002QB002000CVS   0000027700Y
28830640A4K27GA000073B002000EIX   0000031000Y
28830654A4K27GA000074B002000FDX   0000876700Y
28830656A5K27GA00001KB002000FL    0000110200Y
28830674A4K27GA000075B002000FE    0000752400Y
28830681A5K27GA00001LB002000FRE   0000252000Y
28830697A5K27GA00001MB002000FL    0000111000Y
28830700A5K27GA00001NB002000G     0000107700Y
28830983XAK27GA0000E9001000
28830983AAK27GA0000E9S001000SPY   0001425400Y
28830983X4K27GA00003L000200
28830983A4K27GA00003LB000200DIA   0001298100Y
28830983XAK27GA0000G6001000
28830983XAK27GA0000G7000900
28830984AAK27GA0000LTS001000SPY   0001425300Y
28830985XBK27GA00008Q001000
28830985AAK27GA0000LUB000900SPY   0001424800Y
28830994XAK27GA0000G3001000
28830994XBK27GA00008R001000
28830994ABK27GA00008VB001000SSO   0000763700Y
28830996ABK27GA00008WB001000SSO   0000763900Y
28831009X4K27GA000061000047
28831014A4K27GA000076S000047DIA   0001298500Y
28831013X6K27GA000026000500
28831013A6K27GA000026S000500IWM   0000736500Y
28831016ABK27GA00008XS000100UWM   0000543100Y
28831016ABK27GA00008YB000100TWM   0000701300Y
28831016ABK27GA00008ZB000100TWM   0000701400Y
28831017XAK27GA0000F7000500
28831017AAK27GA0000F7B000500SPY   0001424700Y
28831023X8K27G6000013000500
28831023X8K27G6000014000100
28831023X8K27G6000010000100
28831024X4K27GA00003T000100
28831024X4K27GA00003U000100
28831025X3K27G600002L000100
28831025A8K27G6000017B000100MVV   0000805800Y
28831026A4K27GA000077S000100DXD   0000500700Y
28831026A3K27G600002RB000100DDM   0000800600Y
28831040A8K27G6000018B000500MZZ   0000491900Y
28831040A8K27G6000019S000100MVV   0000808800Y
28831108X4K27GA00006S000100
28831108X4K27GA00006T000100
28831108A4K27GA000078B000100DRYS  0001065100Y
28831108A4K27GA000079B000100DRYS  0001065100Y
28831364X6K27GA00002C000500
28831364A6K27GA00002CB000500IWM   0000735900Y
28831366XAK27GA0000FG000500
28831366AAK27GA0000FGB000500SPY   0001424700Y
28831367XAK27GA0000J6001000
28831367XAK27GA0000E6001000
28831367AAK27GA0000E6S001000SPY   0001425300Y
28831367XAK27GA0000EB001000
28831367AAK27GA0000EBB001000SPY   0001424700Y
28831367XAK27GA0000EL003000
28831367XAK27GA0000ET003000
28831367XAK27GA0000EQ003000
28831367XAK27GA0000K9001000
28831367XAK27GA0000EX000500
28831367AAK27GA0000EXB000500SPY   0001424600Y
28831367XAK27GA0000F0003000
28831365A6K27GA000045B002000IMCL  0000311600Y
28831366X6K27GA00002C000500
28831366A6K27GA00002CB000500IWM   0000736300Y
28831367X4K27GA000062000200
28831367A4K27GA000062B000200DIA   0001297900Y
28831367X4K27GA00006K000200
28831367X4K27GA00003H000200
28831367A4K27GA00003HB000200DIA   0001298000Y
28831367AAK27GA0000LVS001000SPY   0001425200Y
28831367AAK27GA0000LWS003000SPY   0001425200Y
28831367XAK27GA0000LO001000
28831368XAK27GA0000LP001000
28831368XAK27GA0000LJ001000
28831368AAK27GA0000LXS002000SPY   0001425300Y
28831368AAK27GA0000LYS003000SPY   0001425200Y
28831368AAK27GA0000LZB000100SH    0000618500Y
28831368ABK27GA000090S001000SSO   0000764800Y
28831368AAK27GA0000M0B001000SDS   0000547900Y
28831368XBK27GA00008S001000
28831368AAK27GA0000M1B000900SPY   0001424700Y
28831369AAK27GA0000M2B003000SPY   0001424300Y
28831369AAK27GA0000M3B003000SPY   0001424300Y
28831369AAK27GA0000M4B001000SPY   0001424700Y
28831369AAK27GA0000M5B001000SPY   0001424700Y
28831374A4K27GA00007AS000200DIA   0001298400Y
28831374A4K27GA00007BB000100DXD   0000499800Y
28831374X4K27GA00004I000100
28831374X3K27G6000029000100
28831374A3K27G600002SS000100DDM   0000802000Y
28831377X6K27GA00002C000500
28831377A6K27GA00002CB000500IWM   0000735900Y
28831378XAK27GA0000LS002000
28831380XBK27GA00001I000100
28831380XBK27GA00008N000100
28831383ABK27GA000091S000100TWM   0000702600Y
28831382X6K27GA00002C000500
28831382A6K27GA00002CB000500IWM   0000736300Y
28831384ABK27GA000092B000100UWM   0000542100Y
28831384XBK27GA000091000100
28831384ABK27GA000093S000100TWM   0000702400Y
28831383X6K27GA00002C000500
28831383A6K27GA00002CB000500IWM   0000735900Y
28831386X9K27G60000G2002000
28831386A9K27G60000G2B002000QQQQ  0000495000Y
28831386XBK27GA000092000100
28831387XBK27GA000093000100
28831387X9K27G60000F9003200
28831387A9K27G60000F9B003200QQQQ  0000495100Y
28831385X6K27GA00002C000500
28831385A6K27GA00002CB000500IWM   0000736300Y
28831388ABK27GA000094B000100UWM   0000542100Y
28831388ABK27GA000095S000100TWM   0000702400Y
28831397X6K27GA00002C000500
28831397A6K27GA00002CB000500IWM   0000735900Y
28831399X9K27G60000FS005000
28831400X6K27GA00002C000500
28831400A6K27GA00002CB000500IWM   0000736300Y
28831401A9K27G60000ITS005000QQQQ  0000495700Y
28831407X6K27GA00002C000500
28831407A6K27GA00002CB000500IWM   0000735900Y
28831410XAK27GA0000M5001000
28831411XAK27GA0000EX000500
28831411AAK27GA0000EXB000500SPY   0001425000Y
28831410X6K27GA00002C000500
28831410A6K27GA00002CB000500IWM   0000736300Y
28831412X6K27GA00002C000500
28831412A6K27GA00002CB000500IWM   0000735900Y
28831415X9K27G60000FT005000
28831416A9K27G60000IUS005000QQQQ  0000495700Y
28831416X9K27G60000FW002000
28831417A9K27G60000IVB002000QQQQ  0000495200Y
28831417X6K27GA00002C000500
28831417A6K27GA00002CB000500IWM   0000736300Y
28831418A9K27G60000IWB002000QQQQ  0000495200Y
28831419XBK27GA000094000100
28831419XBK27GA000095000100
28831419A7K27GA00001OB002000LMT   0000086300Y
28831418X6K27GA00002C000500
28831418A6K27GA00002CB000500IWM   0000735900Y
28831420ABK27GA000096B000100UWM   0000542100Y
28831421ABK27GA000097S000100TWM   0000702400Y
28831420X6K27GA00002C000500
28831420A6K27GA00002CB000500IWM   0000736300Y
28831423XBK27GA000097000100
28831423XBK27GA000096000100
28831423A9K27G60000IXB002000QQQQ  0000495400Y
28831425ABK27GA000098S000100TWM   0000702600Y
28831425X6K27GA00002C000500
28831425A6K27GA00002CB000500IWM   0000735900Y
28831426AAK27GA0000M6B001000SPY   0001424600Y
28831426XAK27GA0000M4001000
28831427X6K27GA00002C000500
28831427A6K27GA00002CB000500IWM   0000736300Y
28831428ABK27GA000099B000100UWM   0000542100Y
28831428AAK27GA0000M7B001000SPY   0001424600Y
28831429XBK27GA000098000100
28831429ABK27GA00009AS000100TWM   0000702400Y
28831429XBK27GA00009A000100
28831429XBK27GA000099000100
28831430XBK27GA00008U002000
28831429A6K27GA000046B000100IWM   0000735800Y
28831431ABK27GA00009BS000100TWM   0000702600Y
28831429X6K27GA000046000100
28831430X6K27GA00002C000500
28831430A6K27GA00002CB000500IWM   0000735900Y
28831435X6K27GA00002R002000
28831437X4K27GA000062000200
28831437A4K27GA000062B000200DIA   0001298200Y
28831438XAK27GA0000FD000500
28831438AAK27GA0000FDB000500SPY   0001424600Y
28831438XAK27GA0000EX000500
28831438AAK27GA0000EXB000500SPY   0001424600Y
28831438XAK27GA0000LX001000
28831438XAK27GA0000LX001000
28831439X4K27GA000062000200
28831439A4K27GA000062B000200DIA   0001297900Y
28831439X4K27GA00003L000200
28831440AAK27GA0000M8S001000SPY   0001425400Y
28831443A4K27GA00007CB000200DIA   0001297800Y
28831444X4K27GA00003F000100
28831444X3K27G600002R000100
28831445X9K27G60000IX002000
28831446A4K27GA00007DS000100DXD   0000500800Y
28831446A3K27G600002TB000100DDM   0000800500Y
28831448AAK27GA0000M9S002000SPY   0001425200Y
28831450XBK27GA00008W001000
28831450ABK27GA00009CB001000SSO   0000763600Y
28831451X4K27GA00007C000200
28831451A4K27GA00007CB000200DIA   0001298100Y
28831452XBK27GA00008V001000
28831452ABK27GA00009DB001000SSO   0000763800Y
28831452XBK27GA00008T002000
28831451XCK27GA00001G002000
28831456XAK27GA0000LF001000
28831456AAK27GA0000MAS002000SPY   0001425300Y
28831458X6K27GA00002B000500
28831458A6K27GA00002BS000500IWM   0000736400Y
28831461ABK27GA00009ES000100UWM   0000542900Y
28831461ABK27GA00009FB000100TWM   0000701600Y
28831461XBK27GA000022000100
28831461ABK27GA00009GB000100TWM   0000701500Y
28831461XBK27GA00006T000100
28831464X6K27GA000025000500
28831464A6K27GA000025B000500IWM   0000735800Y
28831465AAK27GA0000MBB002000SPLS  0000010400Y
28831465X6K27GA00002N002000
28831468X8K27G6000017000100
28831466A6K27GA000047B002000IWM   0000735900Y
28831467X6K27GA000025000500
28831467A6K27GA000025B000500IWM   0000736200Y
28831469XBK27GA00000Q000100
28831469XBK27GA00009B000100
28831469A8K27G600001AB000100MVV   0000805700Y
28831471ABK27GA00009HB000100UWM   0000542000Y
28831471ABK27GA00009IS000100TWM   0000702600Y
28831476X1K27GA00003C002000
28831477X6K27GA000025000500
28831477A6K27GA000025B000500IWM   0000735800Y
28831482XAK27GA0000E6001000
28831482AAK27GA0000E6S001000SPY   0001425700Y
28831482XAK27GA0000LW003000
28831482XAK27GA0000M2003000
28831482X9K27G60000G2002000
28831482A9K27G60000G2B002000QQQQ  0000495500Y
28831482XAK27GA0000EX000500
28831482AAK27GA0000EXB000500SPY   0001425000Y
28831482XAK27GA0000M9002000
28831482XAK27GA0000M3003000
28831482XAK27GA0000FD000500
28831482AAK27GA0000FDB000500SPY   0001425000Y
28831482XAK27GA0000LY003000
28831482X4K27GA00007A000200
28831482X4K27GA000062000200
28831482A4K27GA000062B000200DIA   0001298200Y
28831483AAK27GA0000MCB003000SPY   0001424900Y
28831483AAK27GA0000MDB003000SPY   0001424900Y
28831483XAK27GA0000M7001000
28831483AAK27GA0000MEB002000SPY   0001424800Y
28831483XAK27GA0000EB001000
28831483AAK27GA0000EBB001000SPY   0001425100Y
28831483AAK27GA0000MFS003000SPY   0001425800Y
28831484X9K27G60000H1002000
28831484XBK27GA00009D001000
28831484ABK27GA00009JB001000SSO   0000763900Y
28831484AAK27GA0000MGS003000SPY   0001425800Y
28831484A4K27GA00007ES000200DIA   0001298700Y
28831485A9K27G60000IYS002000QQQQ  0000495700Y
28831485A4K27GA00007FS000100DXD   0000500500Y
28831485A3K27G600002UB000100DDM   0000800600Y
28831486X9K27G60000EN002000
28831486A9K27G60000ENS002000QQQQ  0000495700Y
28831488XBK27GA00009H000100
28831488XBK27GA00009I000100
28831487X6K27GA000025000500
28831487A6K27GA000025B000500IWM   0000736200Y
28831490ABK27GA00009KB000100UWM   0000542000Y
28831488A6K27GA000048B000100IWM   0000735700Y
28831489X6K27GA000048000100
28831490ABK27GA00009LS000100TWM   0000702600Y
28831493X8K27G600000C000500
28831493X8K27G600001A000100
28831493X8K27G600000V000500
28831493X8K27G6000018000500
28831493X8K27G6000015000500
28831493X8K27G600000H000500
28831493A7K27GA00001PS000100MDY   0001606300Y
28831494X8K27G6000019000100
28831494X8K27G6000016000100
28831494X8K27G600000Z000100
28831494X8K27G600000I000100
28831494X4K27GA00007B000100
28831494X3K27G600002S000100
28831495A8K27G600001BB000100MVV   0000805600Y
28831495A8K27G600001CS000500MZZ   0000494300Y
28831495A8K27G600001DB000500MZZ   0000491900Y
28831496A8K27G600001ES000100MVV   0000808900Y
28831497X6K27GA000025000500
28831497A6K27GA000025B000500IWM   0000735800Y
28831499XAK27GA0000MA001000
28831500X2K27G600001W002000
28831503X6K27GA000025000500
28831503A6K27GA000025B000500IWM   0000736200Y
28831504A6K27GA000049B002000IWM   0000736100Y
28831519A7K27GA00001QB002000LMT   0000087100Y
28831519XAK27GA0000M1000900
28831520AAK27GA0000MHB000900SPY   0001425100Y
28831521ABK27GA00009MB001000SSO   0000763700Y
28831521XBK27GA00009C001000
28831527XCK27GA00001Z002000
28831539X8K27G600001D000500
28831539X8K27G600001E000100
28831541A8K27G600001FB000500MZZ   0000491700Y
28831541A8K27G600001GS000100MVV   0000809100Y
28831543X9K27G60000EU002000
28831543A9K27G60000EUB002000QQQQ  0000495300Y
28831543X9K27G60000FR005000
28831543X9K27G60000FE005000
28831543X9K27G60000G2002000
28831543A9K27G60000G2B002000QQQQ  0000495000Y
28831543X1K27GA00003B002000
28831545XBK27GA00007Q001000
28831547ABK27GA00009NB001000SSO   0000763600Y
28831546ACK27GA000020B002000WMT   0000535500Y
28831549X2K27G6000025002000
28831552XAK27GA0000M8001000
28831552XAK27GA0000MA001000
28831553A9K27G60000IZB005000QQQQ  0000495200Y
28831553A9K27G60000J0B005000QQQQ  0000495200Y
28831570X9K27G60000FX002000
28831572ACK27GA000021B002000WYE   0000029700Y
28831588A1K27GA00003DB002000AFL   0000049700Y
28831591X9K27G60000J0005000
28831591X9K27G60000IZ005000
28831592A9K27G60000J1B005000QQQQ  0000495600Y
28831592A9K27G60000J2B005000QQQQ  0000495600Y
28831592A9K27G60000J3B002000QQQQ  0000495300Y
28831592X9K27G60000G2002000
28831592A9K27G60000G2B002000QQQQ  0000495500Y
28831598X2K27G600001X002000
28831601X2K27G6000022002000
28831635XAK27GA0000JR000100
28831637AAK27GA0000MIS000100SPY   0001426900Y
28831642X3K27G600002N002000
28831672XAK27GA0000F7000500
28831672AAK27GA0000F7B000500SPY   0001425100Y
28831672XAK27GA0000LV001000
28831673X4K27GA000073002000
28831675XBK27GA000090001000
28831675X3K27G600002Q002000
28831675XAK27GA0000L7001000
28831676ABK27GA00009OS001000SSO   0000764900Y
28831678AAK27GA0000MJB001000SDS   0000547600Y
28831683AAK27GA0000MKS001000SPY   0001425600Y
28831683XAK27GA0000F7000500
28831683AAK27GA0000F7B000500SPY   0001424700Y
28831684XAK27GA0000LZ000100
28831684XAK27GA0000M0001000
28831699A1K27GA00003EB002000AFL   0000050500Y
28831714A3K27G600002VB002000CVS   0000028100Y
28831720A2K27G6000028B002000BBT   0000021400Y
28831744A3K27G600002WB002000COH   0000022900Y
28831758A5K27GA00001OB002000GE    0000297100Y
28831766XAK27GA0000MI000100
28831766AAK27GA0000MLS000100SPY   0001426600Y
28831769A4K27GA00007GB002000EIX   0000033200Y
28831776A5K27GA00001PB002000GGP   0000401900Y
28831790A5K27GA00001QB002000FRE   0000252800Y
28831798A5K27GA00001RB002000GIS   0000591900Y
28831813A5K27GA00001SB002000G     0000108500Y
28831818A5K27GA00001TB002000GPS   0000171300Y
28831840A5K27GA00001UB002000GE    0000297900Y
28831923X9K27G60000EU002000
28831923A9K27G60000EUB002000QQQQ  0000495600Y
28832126A8K27G600001HB000500MZZ   0000491800Y
28832126A8K27G600001IS000100MVV   0000809000Y
28832209X4K27GA00003H000200
28832209A4K27GA00003HB000200DIA   0001298300Y
28832226XAK27GA0000MK001000
28832226AAK27GA0000MMS001000SPY   0001425200Y
28832227AAK27GA0000MNB000100SH    0000618500Y
28832227AAK27GA0000MOB001000SDS   0000547900Y
28832228ABK27GA00009PS001000SSO   0000764800Y
28832228XBK27GA00009O001000
28832350AAK27GA0000MPB002000SHLD  0000666100Y
28832405X7K27GA00001O002000
28832414X2K27G6000026002000
28832417X1K27GA00003D002000
28832424X2K27G6000027002000
28832428X3K27G600002V002000
28832429X7K27GA00001Q002000
28832436XCK27GA000021002000
28832448X1K27GA00003E002000
28832453ABK27GA00009QB002000UTX   0000056300Y
28832462X4K27GA00007G002000
28832470ACK27GA000022B002000WYE   0000030100Y
28832482ABK27GA00009RB002000UTX   0000057100Y
28832490A1K27GA00003FB002000ABT   0000040700Y
28832507ACK27GA000023B002000WMT   0000536300Y
28832517A2K27G6000029B002000AXP   0000397400Y
28832526A2K27G600002AB002000BBT   0000021600Y
28832543A3K27G600002XB002000COH   0000023100Y
28832547A1K27GA00003GB002000ABT   0000041600Y
28832565A4K27GA00007HB002000EIX   0000033800Y
28832572A2K27G600002BB002000AXP   0000398200Y
28832590A2K27G600002CB002000CAG   0000012500Y
28832596XAK27GA0000F7000500
28832596AAK27GA0000F7B000500SPY   0001425100Y
28832597XAK27GA0000MM001000
28832598XAK27GA0000F7000500
28832598AAK27GA0000F7B000500SPY   0001424700Y
28832599XBK27GA00009P001000
28832599AAK27GA0000MQS001000SPY   0001425600Y
28832600XAK27GA0000MJ001000
28832601XAK27GA0000LC001000
28832601ABK27GA00009SS001000SSO   0000764900Y
28832603AAK27GA0000MRB001000SDS   0000547700Y
28832603AAK27GA0000MSB001000SDS   0000547600Y
28832604XAK27GA0000MN000100
28832604XAK27GA0000MO001000
28832607X4K27GA00003H000200
28832607A4K27GA00003HB000200DIA   0001298000Y
28832614A3K27G600002YB002000CVS   0000030100Y
28832613X4K27GA00006Y000100
28832614X3K27G600002M000100
28832624A4K27GA00007IB000100DOG   0000597200Y
28832624A3K27G600002ZS000100DDM   0000802100Y
28832645A5K27GA00001VB002000GGP   0000402700Y
28833396XAK27GA0000E6001000
28833396AAK27GA0000E6S001000SPY   0001425300Y
28833396XAK27GA0000MQ001000
28833396XAK27GA0000EB001000
28833396AAK27GA0000EBB001000SPY   0001424700Y
28833397XAK27GA0000MD003000
28833397XAK27GA0000MF003000
28833397X9K27G60000G2002000
28833397A9K27G60000G2B002000QQQQ  0000495000Y
28833397AAK27GA0000MTS003000SPY   0001425200Y
28833397XAK27GA0000MH000900
28833397AAK27GA0000MUS001000SPY   0001425200Y
28833397XAK27GA0000MC003000
28833397XAK27GA0000MG003000
28833397AAK27GA0000MVS003000SPY   0001425200Y
28833398XAK27GA0000ME002000
28833398AAK27GA0000MWS002000SPY   0001425300Y
28833398AAK27GA0000MXB000100SH    0000618500Y
28833398AAK27GA0000MYB001000SDS   0000547900Y
28833398XBK27GA00009S001000
28833398AAK27GA0000MZB003000SPY   0001424300Y
28833399ABK27GA00009TS001000SSO   0000764800Y
28833398AAK27GA0000N0B000900SPY   0001424700Y
28833399XBK27GA00009M001000
28833399AAK27GA0000N1B003000SPY   0001424300Y
28833400AAK27GA0000N2B002000SPY   0001424700Y
28833404XBK27GA00009J001000
28833404ABK27GA00009UB001000SSO   0000763600Y
28833404XAK27GA0000EV000100
28833404AAK27GA0000N3B001000SPY   0001424500Y
28833406ABK27GA00009VB001000SSO   0000763800Y
28833408X6K27GA00002J002000
28833410X9K27G60000J3002000
28833412X3K27G600002G002000
28833414XAK27GA0000FD000500
28833414AAK27GA0000FDB000500SPY   0001424600Y
28833414XAK27GA0000EX000500
28833414AAK27GA0000EXB000500SPY   0001424600Y
28833414X4K27GA00007E000200
28833414X4K27GA000062000200
28833414A4K27GA000062B000200DIA   0001297900Y
28833415XAK27GA0000E5001000
28833415AAK27GA0000E5S001000SPY   0001425200Y
28833415XAK27GA0000MW002000
28833415XAK27GA0000N2001000
28833416A4K27GA00007JS000200DIA   0001298400Y
28833416AAK27GA0000N4S001000SPY   0001425400Y
28833418A3K27G6000030S000100DDM   0000802000Y
28833418A4K27GA00007KB000100DXD   0000499800Y
28833421XAK27GA0000E5001000
28833421AAK27GA0000E5S001000SPY   0001425600Y
28833424A2K27G600002DB002000BMY   0000011900Y
28833424X3K27G600002U000100
28833424X4K27GA00007F000100
28833426XAK27GA0000ML000100
28833426AAK27GA0000N5S000100SPY   0001426500Y
28833426X6K27GA000045002000
28833428XBK27GA000015002000
28833429XAK27GA0000FD000500
28833429AAK27GA0000FDB000500SPY   0001425000Y
28833429XAK27GA0000EX000500
28833429AAK27GA0000EXB000500SPY   0001425000Y
28833430X4K27GA000062000200
28833430A4K27GA000062B000200DIA   0001298200Y
28833431AAK27GA0000N6S000100SH    0000619100Y
28833431X4K27GA00007J000200
28833433XAK27GA0000N6000100
28833433AAK27GA0000N7B001000SDS   0000548000Y
28833434XBK27GA00009T001000
28833434ABK27GA00009WS001000SSO   0000764700Y
28833434A4K27GA00007LS000200DIA   0001298700Y
28833435X3K27G6000030000100
28833434A4K27GA00007MS000100DXD   0000500500Y
28833434X4K27GA00007K000100
28833435A3K27G6000031B000100DDM   0000800600Y
28833435XAK27GA0000MS001000
28833435AAK27GA0000N8B001000SDS   0000547900Y
28833435X9K27G60000EU002000
28833435A9K27G60000EUB002000QQQQ  0000495300Y
28833435X9K27G60000J2005000
28833435AAK27GA0000N9S000100SH    0000619100Y
28833437XBK27GA00009Q002000
28833437A9K27G60000J4B005000QQQQ  0000495200Y
28833436X6K27GA000025000500
28833436A6K27GA000025B000500IWM   0000735800Y
28833437X6K27GA000049002000
28833444XAK27GA0000N9000100
28833445XAK27GA0000MP002000
28833446X6K27GA000025000500
28833446A6K27GA000025B000500IWM   0000736200Y
28833448XBK27GA00009K000100
28833448XBK27GA00009L000100
28833450ABK27GA00009XS000100TWM   0000702600Y
28833450ABK27GA00009YB000100UWM   0000542000Y
28833449X6K27GA000025000500
28833449A6K27GA000025B000500IWM   0000735800Y
28833452XBK27GA00009Y000100
28833453XBK27GA00009X000100
28833453X6K27GA000025000500
28833453A6K27GA000025B000500IWM   0000736200Y
28833455ABK27GA00009ZB000100UWM   0000541800Y
28833455ABK27GA0000A0S000100TWM   0000702800Y
28833455ABK27GA0000A1B000100UWM   0000542000Y
28833455XBK27GA0000A0000100
28833455ABK27GA0000A2S000100TWM   0000702600Y
28833455X6K27GA000025000500
28833455A6K27GA000025B000500IWM   0000735800Y
28833458XBK27GA0000A1000100
28833457X6K27GA000025000500
28833457A6K27GA000025B000500IWM   0000736200Y
28833458XBK27GA0000A2000100
28833460ABK27GA0000A3S000100TWM   0000702600Y
28833460XAK27GA0000N2001000
28833460AAK27GA0000NAS001000SPY   0001425300Y
28833460ABK27GA0000A4B000100UWM   0000542000Y
28833462AAK27GA0000NBB001000SPY   0001424600Y
28833461XCK27GA000022002000
28833466X3K27G600002P002000
28833466X1K27GA00003F002000
28833466X6K27GA000025000500
28833466A6K27GA000025B000500IWM   0000735800Y
28833472X7K27GA00001M002000
28833474X4K27GA00007H002000
28833474A7K27GA00001RB002000LMT   0000093100Y
28833478XBK27GA0000A4000100
28833476X6K27GA000025000500
28833476A6K27GA000025B000500IWM   0000736200Y
28833478XBK27GA0000A3000100
28833480ABK27GA0000A5B000100UWM   0000542000Y
28833480ABK27GA0000A6S000100TWM   0000702600Y
28833479X6K27GA000025000500
28833479A6K27GA000025B000500IWM   0000735800Y
28833482XBK27GA0000A5000100
28833482XBK27GA0000A6000100
28833484ABK27GA0000A7S000100TWM   0000702800Y
28833485X6K27GA000025000500
28833485A6K27GA000025B000500IWM   0000736200Y
28833488ABK27GA0000A8B000100UWM   0000542000Y
28833488ABK27GA0000A9S000100TWM   0000702600Y
28833488XBK27GA0000A7000100
28833490XAK27GA0000FD000500
28833490AAK27GA0000FDB000500SPY   0001424600Y
28833490XBK27GA00009R002000
28833490XAK27GA0000E4001000
28833490AAK27GA0000E4B001000SPY   0001424600Y
28833490XAK27GA0000E5001000
28833490AAK27GA0000E5S001000SPY   0001425200Y
28833490XAK27GA0000EX000500
28833490AAK27GA0000EXB000500SPY   0001424600Y
28833490X4K27GA00007L000200
28833490X4K27GA000062000200
28833490A4K27GA000062B000200DIA   0001297900Y
28833492AAK27GA0000NCS002000SPY   0001425100Y
28833494XAK27GA0000MV003000
28833494XAK27GA0000MT003000
28833494A4K27GA00007NS000200DIA   0001298400Y
28833494X4K27GA00007M000100
28833494A4K27GA00007OB000100DXD   0000499800Y
28833495X3K27G6000031000100
28833495A3K27G6000032S000100DDM   0000802000Y
28833496AAK27GA0000NDS003000SPY   0001425800Y
28833496AAK27GA0000NES003000SPY   0001425800Y
28833497X6K27GA000025000500
28833497A6K27GA000025B000500IWM   0000735800Y
28833502X6K27GA000025000500
28833502A6K27GA000025B000500IWM   0000736200Y
28833507X6K27GA000025000500
28833507A6K27GA000025B000500IWM   0000735800Y
28833518XBK27GA0000A8000100
28833518XBK27GA0000A9000100
28833517X6K27GA000025000500
28833517A6K27GA000025B000500IWM   0000736200Y
28833518A6K27GA00004AB000100IWM   0000735700Y
28833519X6K27GA00004A000100
28833521ABK27GA0000AAS000100TWM   0000702800Y
28833528ABK27GA0000ABB000100UWM   0000542000Y
28833528XBK27GA0000AA000100
28833528ABK27GA0000ACS000100TWM   0000702600Y
28833531A7K27GA00001SB002000LMT   0000092300Y
28833532ACK27GA000024B002000WYE   0000032200Y
28833560X1K27GA00003G002000
28833602A1K27GA00003HB002000AFL   0000053400Y
28833606A2K27G600002EB002000CAG   0000012400Y
28833616A3K27G6000033B002000CVS   0000030400Y
28833627A1K27GA00003IB002000AFL   0000054200Y
28833631A5K27GA00001WB002000HAL   0000478000Y
28833637X2K27G6000028002000
28833649X3K27G600002W002000
28833658A5K27GA00001XB002000HD    0000273100Y
28833660X3K27G600002Y002000
28833674X3K27G600001Q002000
28833674X4K27GA000078000100
28833674X4K27GA000079000100
28833678A4K27GA00007PB000100DRYS  0001066900Y
28833678A4K27GA00007QB000100DRYS  0001066900Y
28833692A5K27GA00001YB002000HIG   0000675300Y
28833694A4K27GA00007RB002000EIX   0000036000Y
28833716A5K27GA00001ZB002000HMY   0000082700Y
28833717A5K27GA000020B002000GIS   0000592700Y
28833737A5K27GA000021B002000HMA   0000062900Y
28833747XAK27GA0000E4001000
28833747AAK27GA0000E4B001000SPY   0001425000Y
28833747XAK27GA0000NC002000
28833747XAK27GA0000E5001000
28833747AAK27GA0000E5S001000SPY   0001425600Y
28833747XAK27GA0000FD000500
28833747AAK27GA0000FDB000500SPY   0001425000Y
28833747X4K27GA000062000200
28833747A4K27GA000062B000200DIA   0001298200Y
28833747XAK27GA0000EX000500
28833747AAK27GA0000EXB000500SPY   0001425000Y
28833747X4K27GA00007N000200
28833748X9K27G60000FQ002000
28833748A5K27GA000022B002000GPS   0000172100Y
28833749X9K27G60000J1005000
28833748XAK27GA0000MY001000
28833749AAK27GA0000NFS001000SPY   0001425300Y
28833750X9K27G60000FD001000
28833750A4K27GA00007SS000200DIA   0001298700Y
28833750A9K27G60000J5B005000QQQQ  0000495200Y
28833751XAK27GA0000ND003000
28833751XAK27GA0000NE003000
28833751AAK27GA0000NGS003000SPY   0001425200Y
28833751AAK27GA0000NHS003000SPY   0001425200Y
28833753X9K27G60000IL001000
28833753A9K27G60000J6B001000QQQQ  0000495200Y
28833754XAK27GA0000N7001000
28833754XBK27GA00009W001000
28833755A9K27G60000J7B001000QLD   0000888400Y
28833755XAK27GA0000MR001000
28833756XAK27GA0000LL001000
28833756AAK27GA0000NIB001000SDS   0000548000Y
28833756ABK27GA0000ADS001000SSO   0000764700Y
28833757AAK27GA0000NJB001000SDS   0000547800Y
28833758AAK27GA0000NKB001000SDS   0000547700Y
28833759X9K27G60000J6001000
28833760X4K27GA00007O000100
28833761A3K27G6000034B000100DDM   0000800600Y
28833761X3K27G6000032000100
28833761A4K27GA00007TS000100DXD   0000500500Y
28833765XAK27GA0000NK001000
28833767AAK27GA0000NLB001000SDS   0000547700Y
28833770X9K27G60000F2003200
28833770A9K27G60000F2S003200QQQQ  0000495700Y
28833772A5K27GA000023B002000HAL   0000478800Y
28833773A9K27G60000J8B002000QQQQ  0000495400Y
28833773X9K27G60000CZ001000
28833775A9K27G60000J9S001000QID   0000382300Y
28833783A5K27GA000024B002000HD    0000273900Y
28833806X9K27G60000J9001000
28833806X9K27G60000J7001000
28833807A9K27G60000JAS001000QID   0000382400Y
28833808A9K27G60000JBB001000QQQQ  0000495200Y
28833809X9K27G60000JB001000
28833820X9K27G60000G7002000
28833820A9K27G60000G7S002000QQQQ  0000495700Y
28833869X9K27G60000FX002000
28833869A9K27G60000JCB002000QQQQ  0000495100Y
28833868X6K27GA000025000500
28833868A6K27GA000025B000500IWM   0000735800Y
28833869A6K27GA00004BS002000IWM   0000736600Y
28833869X6K27GA00003O002000
28833871A9K27G60000JDB002000QQQQ  0000495100Y
28833870X6K27GA000025000500
28833870A6K27GA000025B000500IWM   0000736200Y
28833872X6K27GA000025000500
28833872A6K27GA000025B000500IWM   0000735800Y
28833876X6K27GA000025000500
28833876A6K27GA000025B000500IWM   0000736200Y
28833886X6K27GA000025000500
28833886A6K27GA000025B000500IWM   0000735800Y
28833890XBK27GA0000AB000100
28833890XBK27GA0000AC000100
28833892ABK27GA0000AES000100TWM   0000702800Y
28833891X6K27GA000025000500
28833891A6K27GA000025B000500IWM   0000736200Y
28833893ABK27GA0000AFB000100UWM   0000542000Y
28833894XBK27GA0000AE000100
28833894ABK27GA0000AGS000100TWM   0000702600Y
28833895X6K27GA000025000500
28833895A6K27GA000025B000500IWM   0000735800Y
28833898XBK27GA0000AF000100
28833897X6K27GA000025000500
28833897A6K27GA000025B000500IWM   0000736200Y
28833898XBK27GA0000AG000100
28833900ABK27GA0000AHB000100UWM   0000542000Y
28833900ABK27GA0000AIS000100TWM   0000702600Y
28833900X6K27GA000025000500
28833900A6K27GA000025B000500IWM   0000735800Y
28833903XBK27GA0000AH000100
28833903XBK27GA0000AI000100
28833905ABK27GA0000AJS000100TWM   0000702800Y
28833905X6K27GA000025000500
28833905A6K27GA000025B000500IWM   0000736200Y
28833907ABK27GA0000AKB000100UWM   0000542000Y
28833907XBK27GA0000AJ000100
28833907ABK27GA0000ALS000100TWM   0000702600Y
28833908X9K27G60000IK001000
28833907X6K27GA000025000500
28833907A6K27GA000025B000500IWM   0000735800Y
28833910XBK27GA0000AK000100
28833910XBK27GA0000AL000100
28833912ABK27GA0000AMS000100TWM   0000702800Y
28833915X6K27GA000025000500
28833915A6K27GA000025B000500IWM   0000736200Y
28833918ABK27GA0000ANB000100UWM   0000542000Y
28833918ABK27GA0000AOS000100TWM   0000702600Y
28833918XBK27GA0000AM000100
28833920X6K27GA000025000500
28833920A6K27GA000025B000500IWM   0000735800Y
28833926X6K27GA000025000500
28833926A6K27GA000025B000500IWM   0000736200Y
28833927X6K27GA000025000500
28833927A6K27GA000025B000500IWM   0000735800Y
28833931A9K27G60000JEB002000QQQQ  0000495300Y
28833938XBK27GA0000AN000100
28833938XBK27GA0000AO000100
28833937X6K27GA000025000500
28833937A6K27GA000025B000500IWM   0000736200Y
28833940ABK27GA0000APS000100TWM   0000702800Y
28833940X6K27GA000025000500
28833940A6K27GA000025B000500IWM   0000735800Y
28833945X6K27GA000025000500
28833945A6K27GA000025B000500IWM   0000736200Y
28833947X6K27GA000025000500
28833947A6K27GA000025B000500IWM   0000735800Y
28833950X6K27GA000025000500
28833950A6K27GA000025B000500IWM   0000736200Y
28833951XAK27GA0000LR001000
28833951AAK27GA0000NMS001000SPY   0001425200Y
28833951XAK27GA0000N4001000
28833953X6K27GA000025000500
28833953A6K27GA000025B000500IWM   0000735800Y
28833955X6K27GA000025000500
28833955A6K27GA000025B000500IWM   0000736200Y
28833959X9K27G60000JE002000
28833957X6K27GA000025000500
28833957A6K27GA000025B000500IWM   0000735800Y
28833960XAK27GA0000E5001000
28833960AAK27GA0000E5S001000SPY   0001425200Y
28833964X4K27GA00007T000100
28833964X3K27G6000034000100
28833968ABK27GA0000AQB000100UWM   0000542000Y
28833968XBK27GA0000AP000100
28833968X4K27GA00007S000200
28833968ABK27GA0000ARS000100TWM   0000702600Y
28833967X6K27GA000025000500
28833967A6K27GA000025B000500IWM   0000736200Y
28833970X6K27GA000025000500
28833970A6K27GA000025B000500IWM   0000735800Y
28833976X6K27GA000025000500
28833976A6K27GA000025B000500IWM   0000736200Y
28833986X6K27GA000025000500
28833986A6K27GA000025B000500IWM   0000735800Y
28833988XBK27GA0000AQ000100
28833988XBK27GA0000AR000100
28833990A9K27G60000JFB002000QQQQ  0000495300Y
28833990ABK27GA0000ASS000100TWM   0000702800Y
28833990X6K27GA000025000500
28833990A6K27GA000025B000500IWM   0000736200Y
28833995X6K27GA000025000500
28833995A6K27GA000025B000500IWM   0000735800Y
28833997X6K27GA000025000500
28833997A6K27GA000025B000500IWM   0000736200Y
28834006X6K27GA000025000500
28834006A6K27GA000025B000500IWM   0000735800Y
28834008ABK27GA0000ATB000100UWM   0000542000Y
28834008XBK27GA0000AS000100
28834008ABK27GA0000AUS000100TWM   0000702600Y
28834023A9K27G60000JGS002000QQQQ  0000495800Y
28834028XBK27GA0000AT000100
28834028XBK27GA0000AU000100
28834030X9K27G60000JF002000
28834030ABK27GA0000AVS000100TWM   0000702800Y
28834048ABK27GA0000AWB000100UWM   0000542000Y
28834048XBK27GA0000AV000100
28834048ABK27GA0000AXS000100TWM   0000702600Y
28834051XAK27GA0000FD000500
28834051AAK27GA0000FDB000500SPY   0001424600Y
28834051A4K27GA00007US000200DIA   0001298400Y
28834053A4K27GA00007VB000100DXD   0000499800Y
28834053A3K27G6000035S000100DDM   0000802000Y
28834057XBK27GA00009N001000
28834057XAK27GA0000HD000100
28834057XAK27GA0000N5000100
28834057AAK27GA0000NNS000100SPY   0001426300Y
28834059AAK27GA0000NOB000100SPY   0001424100Y
28834068XBK27GA0000AW000100
28834068XBK27GA0000AX000100
28834069A6K27GA00004CB000100IWM   0000735700Y
28834069X6K27GA00004C000100
28834070ABK27GA0000AYS000100TWM   0000702800Y
28834078ABK27GA0000AZB000100UWM   0000542000Y
28834078XBK27GA0000AY000100
28834078XBK27GA0000AZ000100
28834078ABK27GA0000B0S000100TWM   0000702600Y
28834078XBK27GA0000B0000100
28834080ABK27GA0000B1S000100TWM   0000702800Y
28834108ABK27GA0000B2B000100UWM   0000542000Y
28834108ABK27GA0000B3S000100TWM   0000702600Y
28834108XBK27GA0000B1000100
28834130XBK27GA0000B3000100
28834130XBK27GA0000B2000100
28834131XAK27GA0000FD000500
28834131AAK27GA0000FDB000500SPY   0001425000Y
28834132ABK27GA0000B4S000100TWM   0000702800Y
28834138ABK27GA0000B5B000100UWM   0000542000Y
28834138ABK27GA0000B6S000100TWM   0000702600Y
28834138XBK27GA0000B4000100
28834148XBK27GA0000B5000100
28834148XBK27GA0000B6000100
28834150ABK27GA0000B7B000100UWM   0000542000Y
28834150ABK27GA0000B8S000100TWM   0000702600Y
28834158XBK27GA0000B7000100
28834158XBK27GA0000B8000100
28834160ABK27GA0000B9S000100TWM   0000702800Y
28834158A6K27GA00004DB000100IWM   0000735700Y
28834159X6K27GA00004D000100
28834305XAK27GA0000NN000100
28834307AAK27GA0000NPS000100SPY   0001426900Y
28834324X6K27GA00002B000500
28834324A6K27GA00002BS000500IWM   0000736800Y
28834326A6K27GA00004EB002000IWM   0000736100Y
28834326X6K27GA00004B002000
28834329XBK27GA00009E000100
28834329XBK27GA00009F000100
28834329XBK27GA00009G000100
28834329A6K27GA00004FS000100IWM   0000736900Y
28834333ABK27GA0000BAB000100UWM   0000542100Y
28834333ABK27GA0000BBS000100TWM   0000702400Y
28834334X6K27GA00004F000100
28834337XBK27GA0000BA000100
28834337XBK27GA0000BB000100
28834339ABK27GA0000BCB000100UWM   0000542100Y
28834339XBK27GA0000B9000100
28834339ABK27GA0000BDS000100TWM   0000702400Y
28834345X6K27GA000025000500
28834345A6K27GA00004GB000500IWM   0000736300Y
28834347X6K27GA00002C000500
28834347A6K27GA00002CB000500IWM   0000736200Y
28834350X6K27GA00004G000500
28834350A6K27GA00004GB000500IWM   0000735900Y
28834353XBK27GA0000BC000100
28834354XBK27GA0000BD000100
28834355ABK27GA0000BEB000100UWM   0000542000Y
28834354A6K27GA00004HB000100IWM   0000735800Y
28834355ABK27GA0000BFS000100TWM   0000702600Y
28834354X6K27GA00002B000500
28834354A6K27GA00002BS000500IWM   0000736400Y
28834354X6K27GA00004H000100
28834357ABK27GA0000BGS000100UWM   0000542900Y
28834357ABK27GA0000BHB000100TWM   0000701600Y
28834357ABK27GA0000BIB000100TWM   0000701500Y
28834365A3K27G6000036B002000CELG  0000464800Y
28834368X2K27G600000H002000
28834393X7K27GA00001R002000
28834395X7K27GA00001S002000
28834394X6K27GA00004E002000
28834405XAK27GA0000NP000100
28834406AAK27GA0000NQS000100SPY   0001426300Y
28834407X1K27GA00001K002000
28834412A6K27GA00004IB002000JNJ   0000639100Y
28834441A6K27GA00004JB002000IMCL  0000314900Y
28834442ABK27GA0000BJB002000UTX   0000061100Y
28834444ABK27GA0000BKB002000TGT   0000516900Y
28834466ABK27GA0000BLB002000UTX   0000060300Y
28834481AAK27GA0000NRB002000SHLD  0000671200Y
28834483XCK27GA000024002000
28834508A1K27GA00003JB002000ABT   0000044600Y
28834510A3K27G6000037B002000CTSH  0000020400Y
28834518A9K27G60000JHB002000QQQQ  0000495300Y
28834520ACK27GA000025B002000WYE   0000032600Y
28834538X1K27GA00003I002000
28834552A7K27GA00001TB002000LPNT  0000184500Y
28834564A1K27GA00003KB002000ABT   0000043800Y
28834573X1K27GA00003H002000
28834574A2K27G600002FB002000BBT   0000024300Y
28834590X2K27G600002C002000
28834613X4K27GA00007R002000
28834620A3K27G6000038B002000COH   0000025800Y
28834636A3K27G6000039B002000CVS   0000032400Y
28834647A3K27G600003AB002000DD    0000454400Y
28834661X6K27GA00001Q000100
28834661A6K27GA00004KS000100IYM   0000872800Y
28834664X2K27G600002A002000
28834667A6K27GA00004LB000100IYM   0000868400Y
28834674X6K27GA00004L000100
28834676A6K27GA00004MB000100IYM   0000867400Y
28834676X6K27GA00004M000100
28834676A6K27GA00004NB000100IYM   0000868600Y
28834681X3K27G600002X002000
28834683A5K27GA000025B002000HIG   0000676100Y
28834684X3K27G6000033002000
28834712A4K27GA00007WB002000EIX   0000036600Y
28834758A6K27GA00004OB002000IWM   0000736100Y
28834938XAK27GA0000E5001000
28834938AAK27GA0000E5S001000SPY   0001425600Y
28834938X4K27GA00007U000200
28834939XAK27GA0000LQ002000
28834939XAK27GA0000NG003000
28834939XAK27GA0000MZ003000
28834940X9K27G60000G7002000
28834940A9K27G60000G7S002000QQQQ  0000496100Y
28834939XAK27GA0000NH003000
28834939XAK27GA0000N1003000
28834940X4K27GA00007V000100
28834940X3K27G6000035000100
28834940AAK27GA0000NSB002000SPY   0001424800Y
28834940AAK27GA0000NTB003000SPY   0001424900Y
28834940AAK27GA0000NUB003000SPY   0001424900Y
28834941AAK27GA0000NVS003000SPY   0001425800Y
28834941AAK27GA0000NWB002000SPY   0001425000Y
28834941X4K27GA00003H000200
28834941A4K27GA00003HB000200DIA   0001298300Y
28834941AAK27GA0000NXS003000SPY   0001425800Y
28834941A4K27GA00007XS000200DIA   0001298700Y
28834941AAK27GA0000NYS000500SPY   0001425400Y
28834941AAK27GA0000NZS000500SPY   0001425400Y
28834942XAK27GA0000EW000500
28834942AAK27GA0000EWS000500SPY   0001425500Y
28834942A4K27GA00007YS000100DXD   0000500500Y
28834942A3K27G600003BB000100DDM   0000800600Y
28834942XAK27GA0000F7000500
28834942AAK27GA0000F7B000500SPY   0001425000Y
28834943AAK27GA0000O0S000100SH    0000619100Y
28834943XAK27GA0000MU001000
28834943XBK27GA00009V001000
28834943ABK27GA0000BMB001000SSO   0000763900Y
28834943XAK27GA0000EB001000
28834943AAK27GA0000EBB001000SPY   0001425000Y
28834943AAK27GA0000O1S000500SPY   0001425300Y
28834943AAK27GA0000O2S000500SPY   0001425500Y
28834943XAK27GA0000N0000900
28834943AAK27GA0000O3B001000SPY   0001425000Y
28834944AAK27GA0000O4S001000SPY   0001425600Y
28834944XAK27GA0000F7000500
28834944AAK27GA0000F7B000500SPY   0001424700Y
28834945XAK27GA0000NI001000
28834945XBK27GA0000AD001000
28834945AAK27GA0000O5S000500SPY   0001425600Y
28834945AAK27GA0000O6S000500SPY   0001425600Y
28834946XAK27GA0000NL001000
28834946AAK27GA0000O7B001000SDS   0000547900Y
28834947XAK27GA0000NJ001000
28834947ABK27GA0000BNS001000SSO   0000764800Y
28834947AAK27GA0000O8S000500SPY   0001425700Y
28834948AAK27GA0000O9B001000SDS   0000547800Y
28834956XAK27GA0000N8001000
28834956X9K27G60000JG002000
28834957XAK27GA0000NM001000
28834958XAK27GA0000NF001000
28834967X9K27G60000G2002000
28834967A9K27G60000G2B002000QQQQ  0000495500Y
28834969A9K27G60000JIB002000QQQQ  0000495300Y
28834967X6K27GA00002B000500
28834967A6K27GA00002BS000500IWM   0000736800Y
28834970A9K27G60000JJS001000QID   0000382200Y
28834970A9K27G60000JKB001000QLD   0000888500Y
28834970XBK27GA00009U001000
28834970ABK27GA0000BOB001000SSO   0000763700Y
28834971X6K27GA00004G000500
28834971A6K27GA00004GB000500IWM   0000736300Y
28834973A9K27G60000JLB001000QLD   0000888600Y
28834973X9K27G60000JK001000
28834973X4K27GA000076000047
28834974ABK27GA0000BPB000100UWM   0000542100Y
28834974ABK27GA0000BQS000100TWM   0000702400Y
28834974XBK27GA0000BF000100
28834975A4K27GA00007ZS000047DIA   0001298800Y
28834975X6K27GA00004G000500
28834975A6K27GA00004GB000500IWM   0000735900Y
28834977XAK27GA0000NA001000
28834978XBK27GA0000BG000100
28834978XBK27GA0000BH000100
28834978XBK27GA0000BI000100
28834979A9K27G60000JMB001000QQQQ  0000495200Y
28834979X9K27G60000JM001000
28834978X6K27GA00004G000500
28834978A6K27GA00004GB000500IWM   0000736300Y
28834979AAK27GA0000OAS001000SPY   0001425400Y
28834979A6K27GA00004PS000100IWM   0000736900Y
28834980X6K27GA00004G000500
28834980A6K27GA00004GB000500IWM   0000735900Y
28834983X4K27GA00007I000100
28834984X4K27GA00006Z000100
28834984X3K27G600002Z000100
28834984X6K27GA00004G000500
28834984A6K27GA00004GB000500IWM   0000736300Y
28834984X6K27GA00004P000100
28834986X9K27G60000J4005000
28834986X9K27G60000F2003200
28834986A9K27G60000F2S003200QQQQ  0000496200Y
28834986X9K27G60000J5005000
28834987A9K27G60000JNB005000QQQQ  0000495600Y
28834987A9K27G60000JOB005000QQQQ  0000495600Y
28834988A9K27G60000JPB001000QLD   0000888500Y
28834986X6K27GA00004G000500
28834986A6K27GA00004GB000500IWM   0000735900Y
28834990X6K27GA00004G000500
28834990A6K27GA00004GB000500IWM   0000736300Y
28834993XAK27GA0000FG000500
28834993AAK27GA0000FGB000500SPY   0001425000Y
28834993X6K27GA00004G000500
28834993A6K27GA00004GB000500IWM   0000735900Y
28834997X6K27GA00004G000500
28834997A6K27GA00004GB000500IWM   0000736300Y
28834999XBK27GA0000BP000100
28834999XBK27GA0000BQ000100
28835000A9K27G60000JQB002000QQQQ  0000495600Y
28835001ABK27GA0000BRB000100UWM   0000542100Y
28834999X6K27GA00004G000500
28834999A6K27GA00004GB000500IWM   0000735900Y
28834999A6K27GA00004QB000100IWM   0000735800Y
28835000X6K27GA00004Q000100
28835001ABK27GA0000BSS000100TWM   0000702400Y
28835001X6K27GA00004G000500
28835001A6K27GA00004GB000500IWM   0000736300Y
28835003XBK27GA0000BR000100
28835003XBK27GA0000BS000100
28835005ABK27GA0000BTB000100UWM   0000542100Y
28835005ABK27GA0000BUS000100TWM   0000702400Y
28835004X6K27GA00004G000500
28835004A6K27GA00004GB000500IWM   0000735900Y
28835006XAK27GA0000OA001000
28835008A8K27G600001JS000500MZZ   0000494200Y
28835008A8K27G600001KB000100MVV   0000805800Y
28835008XBK27GA0000BT000100
28835008XBK27GA0000BU000100
28835008AAK27GA0000OBS001000SPY   0001425500Y
28835007X6K27GA00004G000500
28835007A6K27GA00004GB000500IWM   0000736300Y
28835010ABK27GA0000BVS000100TWM   0000702600Y
28835008A6K27GA00004RB000100IWM   0000735800Y
28835009X6K27GA00004R000100
28835010AAK27GA0000OCS001000SPY   0001425600Y
28835011ABK27GA0000BWB000100UWM   0000542100Y
28835011XBK27GA0000BV000100
28835010XAK27GA0000OB001000
28835011ABK27GA0000BXS000100TWM   0000702400Y
28835010X6K27GA00004G000500
28835010A6K27GA00004GB000500IWM   0000735900Y
28835012AAK27GA0000ODS001000SPY   0001425600Y
28835013XBK27GA0000BW000100
28835013XBK27GA0000BX000100
28835012X6K27GA00004G000500
28835012A6K27GA00004GB000500IWM   0000736300Y
28835013A6K27GA00004SB000100IWM   0000735800Y
28835015ABK27GA0000BYS000100TWM   0000702600Y
28835014X6K27GA00004S000100
28835015XAK27GA0000MX000100
28835014X6K27GA00004G000500
28835014A6K27GA00004GB000500IWM   0000735900Y
28835016XBK27GA0000BN001000
28835016XAK27GA0000O7001000
28835018ABK27GA0000BZS001000SSO   0000764900Y
28835016X6K27GA00004G000500
28835016A6K27GA00004GB000500IWM   0000736300Y
28835018XBK27GA0000BY000100
28835018ABK27GA0000C0S000100TWM   0000702400Y
28835018ABK27GA0000C1B000100UWM   0000542100Y
28835018XBK27GA0000C1000100
28835019XBK27GA0000C0000100
28835020ABK27GA0000C2S000100TWM   0000702600Y
28835039XAK27GA0000EB001000
28835039AAK27GA0000EBB001000SPY   0001425100Y
28835039XAK27GA0000O3001000
28835039AAK27GA0000O3B001000SPY   0001425100Y
28835039XAK27GA0000FG000500
28835039AAK27GA0000FGB000500SPY   0001425100Y
28835048XAK27GA0000NW002000
28835059X9K27G60000EU002000
28835059A9K27G60000EUB002000QQQQ  0000495600Y
28835060X6K27GA00004G000500
28835060A6K27GA00004GB000500IWM   0000735900Y
28835068ABK27GA0000C3B000100UWM   0000542100Y
28835068ABK27GA0000C4S000100TWM   0000702400Y
28835068XBK27GA0000C2000100
28835067X6K27GA00004G000500
28835067A6K27GA00004GB000500IWM   0000736300Y
28835070X6K27GA00004G000500
28835070A6K27GA00004GB000500IWM   0000735900Y
28835076X6K27GA00004G000500
28835076A6K27GA00004GB000500IWM   0000736300Y
28835081X6K27GA00004G000500
28835081A6K27GA00004GB000500IWM   0000735900Y
28835088XBK27GA0000C3000100
28835088XBK27GA0000C4000100
28835087X6K27GA00004G000500
28835087A6K27GA00004GB000500IWM   0000736300Y
28835090ABK27GA0000C5S000100TWM   0000702600Y
28835090X6K27GA00004G000500
28835090A6K27GA00004GB000500IWM   0000735900Y
28835094X9K27G60000JO005000
28835094X9K27G60000JN005000
28835095A9K27G60000JRB005000QQQQ  0000495200Y
28835096A9K27G60000JSB005000QQQQ  0000495200Y
28835095X6K27GA00004G000500
28835095A6K27GA00004GB000500IWM   0000736300Y
28835097X6K27GA00004G000500
28835097A6K27GA00004GB000500IWM   0000735900Y
28835103X9K27G60000EU002000
28835103A9K27G60000EUB002000QQQQ  0000495300Y
28835107X6K27GA00004G000500
28835107A6K27GA00004GB000500IWM   0000736300Y
28835119ABK27GA0000C6B000100UWM   0000542100Y
28835119XBK27GA0000C5000100
28835119ABK27GA0000C7S000100TWM   0000702400Y
28835117X6K27GA00004G000500
28835117A6K27GA00004GB000500IWM   0000735900Y
28835126X6K27GA00004G000500
28835126A6K27GA00004GB000500IWM   0000736300Y
28835128XBK27GA0000C6000100
28835128XBK27GA0000C7000100
28835130ABK27GA0000C8S000100TWM   0000702600Y
28835135X6K27GA00004G000500
28835135A6K27GA00004GB000500IWM   0000735900Y
28835138ABK27GA0000C9B000100UWM   0000542100Y
28835138ABK27GA0000CAS000100TWM   0000702400Y
28835138XBK27GA0000C8000100
28835140X6K27GA00004G000500
28835140A6K27GA00004GB000500IWM   0000736300Y
28835146X6K27GA00004G000500
28835146A6K27GA00004GB000500IWM   0000735900Y
28835148XBK27GA0000C9000100
28835148XBK27GA0000CA000100
28835150ABK27GA0000CBB000100UWM   0000542100Y
28835150ABK27GA0000CCS000100TWM   0000702400Y
28835150X6K27GA00004G000500
28835150A6K27GA00004GB000500IWM   0000736300Y
28835155X6K27GA00004G000500
28835155A6K27GA00004GB000500IWM   0000735900Y
28835157X6K27GA00004G000500
28835157A6K27GA00004GB000500IWM   0000736300Y
28835168XBK27GA0000CB000100
28835168XBK27GA0000CC000100
28835167X6K27GA00004G000500
28835167A6K27GA00004GB000500IWM   0000735900Y
28835170ABK27GA0000CDS000100TWM   0000702600Y
28835170X6K27GA00004G000500
28835170A6K27GA00004GB000500IWM   0000736300Y
28835176X6K27GA00004G000500
28835176A6K27GA00004GB000500IWM   0000735900Y
28835177X6K27GA00004G000500
28835177A6K27GA00004GB000500IWM   0000736300Y
28835186X6K27GA00004G000500
28835186A6K27GA00004GB000500IWM   0000735900Y
28835196X6K27GA00004G000500
28835196A6K27GA00004GB000500IWM   0000736300Y
28835198ABK27GA0000CEB000100UWM   0000542100Y
28835198ABK27GA0000CFS000100TWM   0000702400Y
28835198XBK27GA0000CD000100
28835200X6K27GA00004G000500
28835200A6K27GA00004GB000500IWM   0000735900Y
28835204X9K27G60000JR005000
28835204X9K27G60000JS005000
28835204A9K27G60000JTB005000QQQQ  0000495600Y
28835204A9K27G60000JUB005000QQQQ  0000495600Y
28835206X6K27GA00004G000500
28835206A6K27GA00004GB000500IWM   0000736300Y
28835208XBK27GA0000CE000100
28835208XBK27GA0000CF000100
28835210ABK27GA0000CGB000100UWM   0000542100Y
28835210ABK27GA0000CHS000100TWM   0000702400Y
28835209X6K27GA00004G000500
28835209A6K27GA00004GB000500IWM   0000735900Y
28835213X9K27G60000EU002000
28835213A9K27G60000EUB002000QQQQ  0000495600Y
28835215X6K27GA00004G000500
28835215A6K27GA00004GB000500IWM   0000736300Y
28835216X6K27GA00004G000500
28835216A6K27GA00004GB000500IWM   0000735900Y
28835218XBK27GA0000CG000100
28835218XBK27GA0000CH000100
28835220ABK27GA0000CIS000100TWM   0000702600Y
28835219X6K27GA00004G000500
28835219A6K27GA00004GB000500IWM   0000736300Y
28835221X6K27GA00004G000500
28835221A6K27GA00004GB000500IWM   0000735900Y
28835226X6K27GA00004G000500
28835226A6K27GA00004GB000500IWM   0000736300Y
28835227X6K27GA00004G000500
28835227A6K27GA00004GB000500IWM   0000735900Y
28835286X9K27G60000JT005000
28835286X9K27G60000JU005000
28835288A9K27G60000JVB005000QQQQ  0000495200Y
28835288A9K27G60000JWB005000QQQQ  0000495200Y
28835293X9K27G60000EU002000
28835293A9K27G60000EUB002000QQQQ  0000495300Y
28835395XAK27GA0000NR002000
28835400X7K27GA00000L002000
28835407XAK27GA0000MB002000
28835414X2K27G600002D002000
28835418A2K27G600002GB002000BRL   0000371500Y
28835430X7K27GA00000Q002000
28835460XBK27GA0000BL002000
28835461XBK27GA000019002000
28835466A1K27GA00003LB002000APOL  0000405400Y
28835481XBK27GA0000BJ002000
28835482XCK27GA000025002000
28835501X1K27GA00003K002000
28835511A7K27GA00001UB002000LMT   0000098300Y
28835522A7K27GA00001VB002000LMT   0000099100Y
28835527X1K27GA00003J002000
28835539X2K27G6000023002000
28835543X2K27G600002E002000
28835554X3K27G600001Z002000
28835558X4K27GA00007W002000
28835557ACK27GA000026B002000WYE   0000034600Y
28835586X2K27G6000024002000
28835588A1K27GA00003MB002000AFL   0000057100Y
28835593X4K27GA00007P000100
28835594X4K27GA00007Q000100
28835598A2K27G600002HB002000BBT   0000024400Y
28835598A4K27GA000080B000100DRYS  0001067100Y
28835598A4K27GA000081B000100DRYS  0001067100Y
28835609A3K27G600003CB002000COH   0000026000Y
28835619A3K27G600003DB002000CVS   0000032800Y
28835645A1K27GA00003NB002000AFL   0000057900Y
28835652X3K27G6000039002000
28835655A5K27GA000026B002000HNZ   0000035000Y
28835678A5K27GA000027B002000HON   0000595300Y
28835691A2K27G600002IB002000CAG   0000014500Y
28835702A5K27GA000028B002000HOT   0000035600Y
28835731A4K27GA000082B002000EIX   0000038800Y
28835758A5K27GA000029B002000HMY   0000083700Y
28835776A5K27GA00002AB002000HMA   0000063800Y
28835788A5K27GA00002BB002000HNZ   0000035800Y
28835793X9K27G60000JV005000
28835800A5K27GA00002CB002000HON   0000596100Y
28835892A9K27G60000JXB005000QQQQ  0000495600Y
28835955X9K27G60000JX005000
28835992A9K27G60000JYB005000QQQQ  0000495200Y
28836109X9K27G60000JY005000
28836109X9K27G60000IU005000
28836109X9K27G60000IT005000
28836109X9K27G60000JW005000
28836109A9K27G60000JZB005000QQQQ  0000495600Y
28836109A9K27G60000K0B005000QQQQ  0000495600Y
28836110X9K27G60000EU002000
28836110A9K27G60000EUB002000QQQQ  0000495600Y
28836110A9K27G60000K1S005000QQQQ  0000496100Y
28836110A9K27G60000K2S005000QQQQ  0000496100Y
28836191X9K27G60000K0005000
28836191X9K27G60000K2005000
28836191X9K27G60000K1005000
28836191A9K27G60000K3S005000QQQQ  0000495700Y
28836191A9K27G60000K4S005000QQQQ  0000495700Y
28836192A9K27G60000K5B005000QQQQ  0000495200Y
28836203X9K27G60000EU002000
28836203A9K27G60000EUB002000QQQQ  0000495300Y
28836354X6K27GA00004J002000
28836389AAK27GA0000OEB002000SHLD  0000676300Y
28836394X7K27GA00001U002000
28836416A2K27G600002JB002000BMY   0000013700Y
28836418X1K27GA00003M002000
28836428X3K27G600003D002000
28836445X6K27GA00002M002000
28836462X5K27GA000026002000
28836471AAK27GA0000OFB002000SPLS  0000013500Y
28836472X5K27GA000028002000
28836483A7K27GA00001WB002000KSS   0000454100Y
28836501A7K27GA00001XB002000KSS   0000454900Y
28836524X7K27GA00001V002000
28836528ABK27GA0000CJB002000UTX   0000064300Y
28836549ACK27GA000027B002000WYE   0000035000Y
28836553ABK27GA0000CKB002000TGT   0000517800Y
28836573A1K27GA00003OB002000ABT   0000046800Y
28836581ABK27GA0000CLB002000UTX   0000065100Y
28836587XCK27GA000026002000
28836603A1K27GA00003PB002000ABT   0000047700Y
28836607X1K27GA00003N002000
28836621X2K27G600002F002000
28836626A2K27G600002KB002000BDX   0000756900Y
28836640A2K27G600002LB002000CAG   0000014300Y
28836646A2K27G600002MB002000BDX   0000757700Y
28836654X3K27G6000038002000
28836668A3K27G600003EB002000DD    0000453800Y
28836679A3K27G600003FB002000CVS   0000034800Y
28836684A4K27GA000083B002000EIX   0000039400Y
28836690X4K27GA000082002000
28836702X5K27GA00002B002000
28836853AAK27GA0000OGS002000SPY   0001425300Y
28836853XAK27GA0000O5000500
28836853AAK27GA0000O5S000500SPY   0001425200Y
28836853XAK27GA0000EB001000
28836853AAK27GA0000EBB001000SPY   0001424700Y
28836853XAK27GA0000O8000500
28836853AAK27GA0000O8S000500SPY   0001425300Y
28836853XAK27GA0000FG000500
28836853AAK27GA0000FGB000500SPY   0001424700Y
28836854XAK27GA0000NS001000
28836854XAK27GA0000O4001000
28836854AAK27GA0000OHS001000SPY   0001425200Y
28836855AAK27GA0000OIB000100SH    0000618500Y
28836855AAK27GA0000OJB001000SDS   0000547900Y
28836856ABK27GA0000CMS001000SSO   0000764800Y
28836856XBK27GA0000BZ001000
28836867X9K27G60000K3005000
28836867X9K27G60000K5005000
28836867X9K27G60000K4005000
28836868A9K27G60000K6B005000QQQQ  0000495600Y
28836869A9K27G60000K7S005000QQQQ  0000496100Y
28836869X9K27G60000EU002000
28836869A9K27G60000EUB002000QQQQ  0000495600Y
28836869A9K27G60000K8S005000QQQQ  0000496100Y
28836873XAK27GA0000EX000500
28836873AAK27GA0000EXB000500SPY   0001424600Y
28836873X4K27GA00007Z000047
28836873XAK27GA0000NV003000
28836873XAK27GA0000NT003000
28836873XAK27GA0000NX003000
28836873XAK27GA0000O3001000
28836873XAK27GA0000NU003000
28836874ABK27GA0000CNB000100UWM   0000542100Y
28836874XBK27GA0000CI000100
28836874AAK27GA0000OKS003000SPY   0001425200Y
28836874ABK27GA0000COS000100TWM   0000702400Y
28836874XAK27GA0000NS001000
28836874AAK27GA0000OLS001000SPY   0001425400Y
28836874AAK27GA0000OMB001000SPY   0001424700Y
28836874AAK27GA0000ONS003000SPY   0001425200Y
28836875XBK27GA0000BO001000
28836875AAK27GA0000OOB003000SPY   0001424300Y
28836875AAK27GA0000OPB001000SPY   0001424700Y
28836875AAK27GA0000OQB003000SPY   0001424300Y
28836876XBK27GA0000BM001000
28836876AAK27GA0000ORB001000SPY   0001424700Y
28836877ABK27GA0000CPB001000SSO   0000763600Y
28836878ABK27GA0000CQB001000SSO   0000763800Y
28836878XAK27GA0000E5001000
28836878AAK27GA0000E5S001000SPY   0001425200Y
28836882A4K27GA000084S000047DIA   0001298500Y
28836884XAK27GA0000O0000100
28836884A4K27GA000085B000100DXD   0000499700Y
28836886X6K27GA00004G000500
28836887XBK27GA0000CN000100
28836887XBK27GA0000CO000100
28836889ABK27GA0000CRS000100TWM   0000702600Y
28836889A6K27GA00004TB000500IWM   0000736300Y
28836890X4K27GA00003H000200
28836890A4K27GA00003HB000200DIA   0001298000Y
28836891ABK27GA0000CSB000100UWM   0000542100Y
28836891XBK27GA0000CR000100
28836891ABK27GA0000CTS000100TWM   0000702400Y
28836893A4K27GA000086B000100DOG   0000597200Y
28836894A3K27G600003GS000100DDM   0000802100Y
28836893X6K27GA00004T000500
28836893A6K27GA00004TB000500IWM   0000735900Y
28836896XBK27GA0000CS000100
28836896XBK27GA0000CT000100
28836898ABK27GA0000CUS000100TWM   0000702600Y
28836898AAK27GA0000OSB001000SDS   0000548000Y
28836898XBK27GA0000CM001000
28836899ABK27GA0000CVS001000SSO   0000764700Y
28836899AAK27GA0000OTB001000SDS   0000547900Y
28836914XAK27GA0000OL001000
28836914XAK27GA0000OD001000
28836914AAK27GA0000OUS001000SPY   0001425300Y
28836914XAK27GA0000OR001000
28836975XAK27GA0000OM001000
28836975XAK27GA0000FD000500
28836975AAK27GA0000FDB000500SPY   0001424600Y
28836976AAK27GA0000OVS001000SPY   0001425300Y
28837239X9K27G60000K7005000
28837239X9K27G60000K6005000
28837239X9K27G60000JZ005000
28837239X9K27G60000K8005000
28837241A9K27G60000K9S005000QQQQ  0000495700Y
28837241A9K27G60000KAS005000QQQQ  0000495700Y
28837241X9K27G60000G2002000
28837241A9K27G60000G2B002000QQQQ  0000495000Y
28837241A9K27G60000KBB005000QQQQ  0000495200Y
28837242A9K27G60000KCB005000QQQQ  0000495200Y
28837242X9K27G60000JQ002000
28837243X9K27G60000EU002000
28837243A9K27G60000EUB002000QQQQ  0000495300Y
28837244X9K27G60000JP001000
28837246A9K27G60000KDB001000QQQQ  0000495200Y
28837249X9K27G60000KD001000
28837253X9K27G60000JL001000
28837254A9K27G60000KEB001000QLD   0000888400Y
28837255A9K27G60000KFB001000QQQQ  0000495200Y
28837259X9K27G60000KF001000
28837277A9K27G60000KGS002000QQQQ  0000495800Y
28837309X9K27G60000KG002000
28837355XAK27GA0000OE002000
28837386X3K27G6000037002000
28837411XAK27GA0000LI002000
28837417A6K27GA00004UB002000IMCL  0000318100Y
28837419XBK27GA0000CJ002000
28837421XBK27GA0000CL002000
28837434XCK27GA000027002000
28837444X1K27GA00003P002000
28837446XAK27GA0000FD000500
28837446AAK27GA0000FDB000500SPY   0001425000Y
28837446XAK27GA0000OO003000
28837446XAK27GA0000OK003000
28837446XAK27GA0000ON003000
28837446XAK27GA0000OQ003000
28837446XAK27GA0000OV001000
28837447XAK27GA0000OU001000
28837447AAK27GA0000OWB002000SPY   0001424800Y
28837447AAK27GA0000OXB003000SPY   0001424900Y
28837447AAK27GA0000OYB003000SPY   0001424900Y
28837447AAK27GA0000OZS003000SPY   0001425800Y
28837447AAK27GA0000P0S003000SPY   0001425800Y
28837448AAK27GA0000P1S001000SPY   0001425400Y
28837448AAK27GA0000P2S001000SPY   0001425400Y
28837451XAK27GA0000E5001000
28837451AAK27GA0000E5S001000SPY   0001425600Y
28837451XAK27GA0000EX000500
28837451AAK27GA0000EXB000500SPY   0001425000Y
28837451X1K27GA00003O002000
28837454XAK27GA0000OS001000
28837455XBK27GA0000CV001000
28837456XAK27GA0000O9001000
28837456ABK27GA0000CWS001000SSO   0000764800Y
28837458AAK27GA0000P3B001000SDS   0000547800Y
28837461X4K27GA00003H000200
28837461A4K27GA00003HB000200DIA   0001298300Y
28837465XAK27GA0000OT001000
28837471X2K27G6000029002000
28837474X2K27G600002B002000
28837473X4K27GA000086000100
28837474X3K27G600003G000100
28837478XAK27GA0000NB001000
28837479XAK27GA0000OW001000
28837481XAK27GA0000P2001000
28837487X2K27G600002H002000
28837496X6K27GA00004T000500
28837496A6K27GA00004TB000500IWM   0000736300Y
28837499ABK27GA0000CXB000100UWM   0000542100Y
28837499ABK27GA0000CYS000100TWM   0000702400Y
28837499XBK27GA0000CU000100
28837500X6K27GA00004T000500
28837500A6K27GA00004TB000500IWM   0000735900Y
28837503XBK27GA0000CX000100
28837503XBK27GA0000CY000100
28837505ABK27GA0000CZS000100TWM   0000702600Y
28837506X2K27G6000014002000
28837505X6K27GA00004T000500
28837505A6K27GA00004TB000500IWM   0000736300Y
28837507ABK27GA0000D0B000100UWM   0000542100Y
28837507ABK27GA0000D1S000100TWM   0000702400Y
28837507XBK27GA0000CZ000100
28837506X6K27GA00004T000500
28837506A6K27GA00004TB000500IWM   0000735900Y
28837510XBK27GA0000D0000100
28837510XBK27GA0000D1000100
28837510A6K27GA00004VB000100IWM   0000735800Y
28837510X6K27GA00004V000100
28837512ABK27GA0000D2S000100TWM   0000702600Y
28837510X6K27GA00004T000500
28837510A6K27GA00004TB000500IWM   0000736300Y
28837513ABK27GA0000D3B000100UWM   0000542100Y
28837513XBK27GA0000D2000100
28837513ABK27GA0000D4S000100TWM   0000702400Y
28837514X3K27G600003C002000
28837514X6K27GA00004T000500
28837514A6K27GA00004TB000500IWM   0000735900Y
28837517XBK27GA0000D3000100
28837517XBK27GA0000D4000100
28837516X6K27GA00004T000500
28837516A6K27GA00004TB000500IWM   0000736300Y
28837519ABK27GA0000D5B000100UWM   0000542100Y
28837519ABK27GA0000D6S000100TWM   0000702400Y
28837518X6K27GA00004T000500
28837518A6K27GA00004TB000500IWM   0000735900Y
28837522XBK27GA0000D5000100
28837522XBK27GA0000D6000100
28837522A6K27GA00004WB000100IWM   0000735800Y
28837524ABK27GA0000D7S000100TWM   0000702600Y
28837522X6K27GA00004W000100
28837522X6K27GA00004T000500
28837522A6K27GA00004TB000500IWM   0000736300Y
28837525ABK27GA0000D8B000100UWM   0000542100Y
28837525ABK27GA0000D9S000100TWM   0000702400Y
28837525XBK27GA0000D7000100
28837525X6K27GA00004T000500
28837525A6K27GA00004TB000500IWM   0000735900Y
28837527X6K27GA00004T000500
28837527A6K27GA00004TB000500IWM   0000736300Y
28837529XBK27GA0000D8000100
28837529XBK27GA0000D9000100
28837531ABK27GA0000DAB000100UWM   0000542100Y
28837531ABK27GA0000DBS000100TWM   0000702400Y
28837534XAK27GA0000OW001000
28837535X4K27GA000083002000
28837535X2K27G600002I002000
28837535X6K27GA00004T000500
28837535A6K27GA00004TB000500IWM   0000735900Y
28837536AAK27GA0000P4B001000SPY   0001424700Y
28837536X6K27GA00004T000500
28837536A6K27GA00004TB000500IWM   0000736300Y
28837538XBK27GA0000DA000100
28837538XBK27GA0000DB000100
28837540ABK27GA0000DCB000100UWM   0000542100Y
28837538A6K27GA00004XB000100IWM   0000735800Y
28837538X6K27GA00004X000100
28837540ABK27GA0000DDS000100TWM   0000702400Y
28837539X6K27GA00004T000500
28837539A6K27GA00004TB000500IWM   0000735900Y
28837545X6K27GA00004T000500
28837545A6K27GA00004TB000500IWM   0000736300Y
28837546X6K27GA00004T000500
28837546A6K27GA00004TB000500IWM   0000735900Y
28837548XBK27GA0000DC000100
28837548XBK27GA0000DD000100
28837550ABK27GA0000DES000100TWM   0000702400Y
28837550ABK27GA0000DFB000100UWM   0000542100Y
28837549X6K27GA00004T000500
28837549A6K27GA00004TB000500IWM   0000736300Y
28837554X3K27G600003F002000
28837555X6K27GA00004T000500
28837555A6K27GA00004TB000500IWM   0000735900Y
28837556X6K27GA00004T000500
28837556A6K27GA00004TB000500IWM   0000736300Y
28837559A7K27GA00001YB002000LMT   0000104300Y
28837566X6K27GA00004T000500
28837566A6K27GA00004TB000500IWM   0000735900Y
28837568XBK27GA0000DF000100
28837568XBK27GA0000DE000100
28837568A6K27GA00004YB000100IWM   0000735800Y
28837568X6K27GA00004Y000100
28837570ABK27GA0000DGS000100TWM   0000702600Y
28837569X6K27GA00004T000500
28837569A6K27GA00004TB000500IWM   0000736300Y
28837572A6K27GA00004ZB002000JNJ   0000640000Y
28837576A1K27GA00003QB002000AFL   0000060800Y
28837575X6K27GA00004T000500
28837575A6K27GA00004TB000500IWM   0000735900Y
28837576X6K27GA00004T000500
28837576A6K27GA00004TB000500IWM   0000736300Y
28837578ABK27GA0000DHB000100UWM   0000542100Y
28837578ABK27GA0000DIS000100TWM   0000702400Y
28837578XBK27GA0000DG000100
28837578XBK27GA0000DH000100
28837578XBK27GA0000DI000100
28837580ABK27GA0000DJS000100TWM   0000702600Y
28837579X6K27GA00004T000500
28837579A6K27GA00004TB000500IWM   0000735900Y
28837584A3K27G600003HB002000CVS   0000035200Y
28837585X6K27GA00004T000500
28837585A6K27GA00004TB000500IWM   0000736300Y
28837586X6K27GA00004T000500
28837586A6K27GA00004TB000500IWM   0000735900Y
28837596X6K27GA00004T000500
28837596A6K27GA00004TB000500IWM   0000736300Y
28837598ABK27GA0000DKB000100UWM   0000542100Y
28837598XBK27GA0000DJ000100
28837598ABK27GA0000DLS000100TWM   0000702400Y
28837599X6K27GA00004T000500
28837599A6K27GA00004TB000500IWM   0000735900Y
28837602A5K27GA00002DB002000HNZ   0000037600Y
28837605X6K27GA00004T000500
28837605A6K27GA00004TB000500IWM   0000736300Y
28837606X6K27GA00004T000500
28837606A6K27GA00004TB000500IWM   0000735900Y
28837608XBK27GA0000DK000100
28837608XBK27GA0000DL000100
28837610ABK27GA0000DMB000100UWM   0000542100Y
28837610ABK27GA0000DNS000100TWM   0000702400Y
28837609X6K27GA00004T000500
28837609A6K27GA00004TB000500IWM   0000736300Y
28837610A5K27GA00002EB002000HOT   0000038300Y
28837615X6K27GA00004T000500
28837615A6K27GA00004TB000500IWM   0000735900Y
28837616X6K27GA00004T000500
28837616A6K27GA00004TB000500IWM   0000736300Y
28837620A7K27GA00001ZB002000LMT   0000105100Y
28837624A5K27GA00002FB002000HUM   0000431500Y
28837626X6K27GA00004T000500
28837626A6K27GA00004TB000500IWM   0000735900Y
28837628XBK27GA0000DM000100
28837628XBK27GA0000DN000100
28837630ABK27GA0000DOS000100TWM   0000702600Y
28837629ACK27GA000028B002000WYE   0000037000Y
28837629X6K27GA00004T000500
28837629A6K27GA00004TB000500IWM   0000736300Y
28837635X6K27GA00004T000500
28837635A6K27GA00004TB000500IWM   0000735900Y
28837636X6K27GA00004T000500
28837636A6K27GA00004TB000500IWM   0000736300Y
28837644A6K27GA000050B002000IP    0000259900Y
28837646X6K27GA00004T000500
28837646A6K27GA00004TB000500IWM   0000735900Y
28837648ABK27GA0000DPB000100UWM   0000542100Y
28837648XBK27GA0000DO000100
28837648ABK27GA0000DQS000100TWM   0000702400Y
28837649X9K27G60000G2002000
28837649A9K27G60000G2B002000QQQQ  0000495500Y
28837649A9K27G60000KHB002000QQQQ  0000495600Y
28837649X9K27G60000KB005000
28837649X9K27G60000K9005000
28837649X9K27G60000KA005000
28837649X9K27G60000KC005000
28837650A9K27G60000KIB005000QQQQ  0000495600Y
28837650A9K27G60000KJB005000QQQQ  0000495600Y
28837650X9K27G60000KE001000
28837650A9K27G60000KKB001000QLD   0000888600Y
28837650X4K27GA000084000047
28837650X9K27G60000EU002000
28837650A9K27G60000EUB002000QQQQ  0000495600Y
28837651A9K27G60000KLB001000QLD   0000888500Y
28837651A9K27G60000KMS005000QQQQ  0000496100Y
28837651A9K27G60000KNS005000QQQQ  0000496100Y
28837651X4K27GA000085000100
28837652A9K27G60000KOB001000QQQQ  0000495200Y
28837653X9K27G60000EN002000
28837653A9K27G60000ENS002000QQQQ  0000496000Y
28837654X6K27GA00004T000500
28837654A6K27GA00004TB000500IWM   0000736300Y
28837657A1K27GA00003RB002000AFL   0000061600Y
28837656X6K27GA00004T000500
28837656A6K27GA00004TB000500IWM   0000735900Y
28837658XBK27GA0000DP000100
28837658XBK27GA0000DQ000100
28837659X9K27G60000KO001000
28837658X6K27GA00004T000500
28837658A6K27GA00004TB000500IWM   0000736300Y
28837660ABK27GA0000DRS000100TWM   0000702600Y
28837663A4K27GA000087S000047DIA   0001298800Y
28837662A6K27GA000051B002000IR    0000431500Y
28837664XAK27GA0000EX000500
28837664AAK27GA0000EXB000500SPY   0001424600Y
28837665XAK27GA0000F2000500
28837665AAK27GA0000F2B000500SPY   0001424500Y
28837665XAK27GA0000EW000500
28837665AAK27GA0000EWS000500SPY   0001425100Y
28837665XAK27GA0000OZ003000
28837665XAK27GA0000OX003000
28837665XAK27GA0000E4001000
28837665AAK27GA0000E4B001000SPY   0001424600Y
28837665XAK27GA0000E5001000
28837665AAK27GA0000E5S001000SPY   0001425200Y
28837665XAK27GA0000FD000500
28837665AAK27GA0000FDB000500SPY   0001424600Y
28837665XAK27GA0000P4001000
28837665XAK27GA0000O6000500
28837665AAK27GA0000O6S000500SPY   0001425200Y
28837665AAK27GA0000P5S003000SPY   0001425200Y
28837665XAK27GA0000P0003000
28837665XAK27GA0000OY003000
28837665AAK27GA0000P6S003000SPY   0001425200Y
28837666AAK27GA0000P7S002000SPY   0001425300Y
28837666X4K27GA00003H000200
28837666A4K27GA00003HB000200DIA   0001298000Y
28837666X4K27GA000087000047
28837666XAK27GA0000OJ001000
28837666AAK27GA0000P8B001000SDS   0000548000Y
28837666XAK27GA0000KE001000
28837667AAK27GA0000P9S001000SPY   0001425100Y
28837667AAK27GA0000PAB003000SPY   0001424300Y
28837668A2K27G600002NB002000BBT   0000027100Y
28837667AAK27GA0000PBB001000SPY   0001424600Y
28837667XBK27GA0000CW001000
28837667ABK27GA0000DSS001000SSO   0000764700Y
28837667AAK27GA0000PCB003000SPY   0001424300Y
28837668XAK27GA0000K1001000
28837668AAK27GA0000K1S001000SPY   0001425100Y
28837668AAK27GA0000PDB001000SDS   0000547900Y
28837671XAK27GA0000FE000500
28837671AAK27GA0000FEB000500SPY   0001424500Y
28837673XAK27GA0000F2000500
28837673AAK27GA0000F2B000500SPY   0001424900Y
28837673A4K27GA000088S000047DIA   0001298500Y
28837673A4K27GA000089B000100DOG   0000597200Y
28837673X4K27GA00007Y000100
28837673A4K27GA00008AB000100DXD   0000499700Y
28837674X3K27G600003B000100
28837674X3K27G600002I000100
28837674A3K27G600003IS000100DDM   0000802100Y
28837674XBK27GA0000CP001000
28837676X9K27G60000KM005000
28837676X9K27G60000KN005000
28837676X9K27G60000G2002000
28837676A9K27G60000G2B002000QQQQ  0000495000Y
28837677A9K27G60000KPS005000QQQQ  0000495700Y
28837677A9K27G60000KQS005000QQQQ  0000495700Y
28837678X9K27G60000EN002000
28837678A9K27G60000ENS002000QQQQ  0000495700Y
28837680X4K27GA00007X000200
28837684A4K27GA00008BS000200DIA   0001298400Y
28837685A4K27GA00008CB000100DXD   0000499800Y
28837686A3K27G600003JS000100DDM   0000802000Y
28837684A6K27GA000052B002000IRF   0000216300Y
28837688XAK27GA0000KF001000
28837688X6K27GA00004T000500
28837688A6K27GA00004TB000500IWM   0000735900Y
28837691A3K27G600003KB002000COH   0000028800Y
28837692AAK27GA0000PEB000600SPY   0001424600Y
28837694XAK27GA0000DU001000
28837694XBK27GA0000CQ001000
28837694ABK27GA0000DTB001000SSO   0000763500Y
28837696ABK27GA0000DUB001000SSO   0000763700Y
28837696AAK27GA0000PFS001000SDS   0000549400Y
28837698X8K27G600001J000500
28837698X8K27G600001K000100
28837707X6K27GA00002B000500
28837707A6K27GA00002BS000500IWM   0000736400Y
28837710ABK27GA0000DVS000100UWM   0000542900Y
28837710ABK27GA0000DWB000100TWM   0000701500Y
28837710ABK27GA0000DXB000100TWM   0000701600Y
28837727A4K27GA00008DB002000EIX   0000041600Y
28837739X6K27GA00004O002000
28837741A5K27GA00002GB002000HNZ   0000038400Y
28837754A5K27GA00002HB002000HOT   0000039100Y
28837786X9K27G60000KP005000
28837787A9K27G60000KRS005000QQQQ  0000496100Y
28837792X9K27G60000G2002000
28837792A9K27G60000G2B002000QQQQ  0000495500Y
28837793X9K27G60000EN002000
28837793A9K27G60000ENS002000QQQQ  0000496000Y
28837809X9K27G60000KJ005000
28837810X9K27G60000KI005000
28837810X9K27G60000G2002000
28837810A9K27G60000G2B002000QQQQ  0000495000Y
28837810X9K27G60000KR005000
28837810A9K27G60000KSS005000QQQQ  0000495700Y
28837810X9K27G60000EN002000
28837810A9K27G60000ENS002000QQQQ  0000495700Y
28837811A9K27G60000KTB005000QQQQ  0000495200Y
28837811A9K27G60000KUB005000QQQQ  0000495200Y
28837813X9K27G60000EU002000
28837813A9K27G60000EUB002000QQQQ  0000495300Y
28837908X9K27G60000KS005000
28837908X9K27G60000KT005000
28837908X9K27G60000KU005000
28837908A9K27G60000KVB005000QQQQ  0000495600Y
28837908A9K27G60000KWB005000QQQQ  0000495600Y
28837909X9K27G60000EU002000
28837909A9K27G60000EUB002000QQQQ  0000495600Y
28837909X9K27G60000G2002000
28837909A9K27G60000G2B002000QQQQ  0000495500Y
28837910A9K27G60000KXS005000QQQQ  0000496100Y
28837913X9K27G60000EN002000
28837913A9K27G60000ENS002000QQQQ  0000496000Y
28837919X4K27GA000080000100
28837928A4K27GA00008EB000100DRYS  0001068000Y
28837938X4K27GA000081000100
28837948A4K27GA00008FB000100DRYS  0001068000Y
28837958X4K27GA00008F000100
28837958A4K27GA00008GB000100DRYS  0001066900Y
28837986X9K27G60000KX005000
28837986X9K27G60000KV005000
28837986X9K27G60000KW005000
28837986X9K27G60000EN002000
28837986A9K27G60000ENS002000QQQQ  0000495700Y
28837986A9K27G60000KYS005000QQQQ  0000495700Y
28837986X9K27G60000G2002000
28837986A9K27G60000G2B002000QQQQ  0000495000Y
28837987A9K27G60000KZB005000QQQQ  0000495200Y
28837988A9K27G60000L0B005000QQQQ  0000495200Y
28838002X9K27G60000EU002000
28838002A9K27G60000EUB002000QQQQ  0000495300Y
28838066X9K27G60000KY005000
28838066X9K27G60000KZ005000
28838066X9K27G60000L0005000
28838066A9K27G60000L1B005000QQQQ  0000495600Y
28838066A9K27G60000L2B005000QQQQ  0000495600Y
28838067X9K27G60000EU002000
28838067A9K27G60000EUB002000QQQQ  0000495600Y
28838067X9K27G60000G2002000
28838067A9K27G60000G2B002000QQQQ  0000495500Y
28838067A9K27G60000L3S005000QQQQ  0000496100Y
28838073X9K27G60000EN002000
28838073A9K27G60000ENS002000QQQQ  0000496000Y
28838189XAK27GA0000K1001000
28838189AAK27GA0000K1S001000SPY   0001425500Y
28838189X4K27GA00008B000200
28838189XAK27GA0000EW000500
28838189AAK27GA0000EWS000500SPY   0001425500Y
28838189XAK27GA0000O6000500
28838189AAK27GA0000O6S000500SPY   0001425600Y
28838189XAK27GA0000FE000500
28838189AAK27GA0000FEB000500SPY   0001424900Y
28838189XAK27GA0000P9001000
28838189XAK27GA0000PE000600
28838189AAK27GA0000PGB000600SPY   0001425000Y
28838190XAK27GA0000E4001000
28838190AAK27GA0000E4B001000SPY   0001425000Y
28838190AAK27GA0000PHS001000SDS   0000549300Y
28838191XBK27GA0000DU001000
28838191AAK27GA0000PIS001000SPY   0001425500Y
28838191ABK27GA0000DYB001000SSO   0000763800Y
28838191XAK27GA0000EX000500
28838191AAK27GA0000EXB000500SPY   0001425000Y
28838193ABK27GA0000DZB001000SSO   0000763600Y
28838193XBK27GA0000DT001000
28838193A4K27GA00008HS000200DIA   0001298700Y
28838194X3K27G600003J000100
28838194X4K27GA00008C000100
28838194A3K27G600003LB000100DDM   0000800600Y
28838194A4K27GA00008IS000100DXD   0000500500Y
28838201XAK27GA0000FD000500
28838201AAK27GA0000FDB000500SPY   0001425000Y
28838201XAK27GA0000P5003000
28838201XAK27GA0000P6003000
28838201XAK27GA0000PA003000
28838201XAK27GA0000O8000500
28838201AAK27GA0000O8S000500SPY   0001425700Y
28838202XAK27GA0000E5001000
28838202AAK27GA0000E5S001000SPY   0001425600Y
28838202XAK27GA0000O5000500
28838202AAK27GA0000O5S000500SPY   0001425600Y
28838202XAK27GA0000OG002000
28838202AAK27GA0000PJB002000SPY   0001425000Y
28838202XAK27GA0000PC003000
28838202AAK27GA0000PKB003000SPY   0001424900Y
28838202AAK27GA0000PLB003000SPY   0001424900Y
28838202AAK27GA0000PMB002000SPY   0001424800Y
28838203AAK27GA0000PNS003000SPY   0001425800Y
28838203X4K27GA00003H000200
28838203A4K27GA00003HB000200DIA   0001298300Y
28838204AAK27GA0000POS003000SPY   0001425800Y
28838205XAK27GA0000E5001000
28838205AAK27GA0000E5S001000SPY   0001425200Y
28838204A6K27GA000053B002000IWM   0000736100Y
28838206XAK27GA0000O8000500
28838206AAK27GA0000O8S000500SPY   0001425300Y
28838207XAK27GA0000O5000500
28838207AAK27GA0000O5S000500SPY   0001425200Y
28838214X4K27GA000088000047
28838217X9K27G60000KQ005000
28838217A4K27GA00008JS000047DIA   0001298800Y
28838219A9K27G60000L4S005000QQQQ  0000496100Y
28838223X9K27G60000L4005000
28838223X9K27G60000L3005000
28838223A9K27G60000L5S005000QQQQ  0000495700Y
28838223A9K27G60000L6S005000QQQQ  0000495700Y
28838224XAK27GA0000P7001000
28838225XAK27GA0000EX000500
28838225AAK27GA0000EXB000500SPY   0001424600Y
28838224X6K27GA00002B000500
28838224A6K27GA00002BS000500IWM   0000736800Y
28838232X9K27G60000EN002000
28838232A9K27G60000ENS002000QQQQ  0000495700Y
28838238XBK27GA0000DV000100
28838238XBK27GA0000DW000100
28838238XBK27GA0000DX000100
28838239A6K27GA000054S000100IWM   0000736900Y
28838241X9K27G60000IR002000
28838243X4K27GA00008A000100
28838243X4K27GA000089000100
28838244X3K27G600003I000100
28838244X4K27GA00007C000200
28838244A4K27GA00007CB000200DIA   0001298400Y
28838243X6K27GA00004T000500
28838243A6K27GA00004TB000500IWM   0000736300Y
28838245XAK27GA0000P7001000
28838244X6K27GA000054000100
28838246ABK27GA0000E0B000100UWM   0000542100Y
28838246XBK27GA0000DR000100
28838246ABK27GA0000E1S000100TWM   0000702400Y
28838246A4K27GA00008KS000100DXD   0000500400Y
28838246A4K27GA00008LS000100DOG   0000598500Y
28838246A3K27G600003MB000100DDM   0000800700Y
28838246A3K27G600003NS000100DDM   0000802200Y
28838249X4K27GA00007C000200
28838249A4K27GA00007CB000200DIA   0001298100Y
28838250X4K27GA00008L000100
28838251X3K27G600003M000100
28838250X4K27GA00008K000100
28838254A4K27GA00008MS000100DOG   0000598500Y
28838254A4K27GA00008NS000100DXD   0000500400Y
28838254A3K27G600003OB000100DDM   0000800700Y
28838268A9K27G60000L7S002000QQQQ  0000495800Y
28838271A8K27G600001LS000500MZZ   0000494200Y
28838271A8K27G600001MB000100MVV   0000805800Y
28838293XAK27GA0000P1001000
28838294X8K27G600001H000500
28838294X8K27G600001G000100
28838294X8K27G600001I000100
28838294AAK27GA0000PPS001000SPY   0001425500Y
28838296A8K27G600001NS000100MVV   0000809200Y
28838316A8K27G600001OS000100MVV   0000809100Y
28838330XAK27GA0000EX000500
28838330AAK27GA0000EXB000500SPY   0001425000Y
28838330XAK27GA0000OH001000
28838332AAK27GA0000PQS001000SPY   0001425600Y
28838344XBK27GA0000DS001000
28838343XAK27GA0000P8001000
28838344X4K27GA00007C000200
28838344A4K27GA00007CB000200DIA   0001298400Y
28838345XAK27GA0000P3001000
28838345AAK27GA0000PRB001000SDS   0000547900Y
28838346ABK27GA0000E2S001000SSO   0000764800Y
28838347AAK27GA0000PSB001000SDS   0000547800Y
28838355XAK27GA0000PD001000
28838359X4K27GA00007C000200
28838359A4K27GA00007CB000200DIA   0001298100Y
28838394X4K27GA000043002000
28838397AAK27GA0000PTB002000SHLD  0000681400Y
28838397X7K27GA00001Y002000
28838400X2K27G600002J002000
28838404X7K27GA00001T002000
28838416X4K27GA000046002000
28838420A3K27G600003PB002000CTSH  0000023800Y
28838422X1K27GA00003Q002000
28838429X9K27G60000L7002000
28838433X2K27G600001A002000
28838432X7K27GA00001Z002000
28838440X2K27G600002L002000
28838443X6K27GA000043002000
28838450X3K27G600003H002000
28838452X9K27G60000EN002000
28838452A9K27G60000ENS002000QQQQ  0000496000Y
28838462X5K27GA00002D002000
28838469X5K27GA00002E002000
28838467XCK27GA000028002000
28838489AAK27GA0000PUB002000SNDK  0000219900Y
28838489ABK27GA0000E3B002000UTX   0000069100Y
28838499X9K27G60000IY002000
28838499X9K27G60000L5005000
28838499X9K27G60000F9003200
28838499A9K27G60000F9B003200QQQQ  0000495600Y
28838499X9K27G60000L6005000
28838500A9K27G60000L8B002000QQQQ  0000495400Y
28838501A9K27G60000L9S005000QQQQ  0000496100Y
28838502A9K27G60000LAS005000QQQQ  0000496100Y
28838505XAK27GA0000PP001000
28838507AAK27GA0000PVS001000SPY   0001425600Y
28838527X9K27G60000F9003200
28838527A9K27G60000F9B003200QQQQ  0000495100Y
28838528X9K27G60000L8002000
28838532X9K27G60000F9003200
28838532A9K27G60000F9B003200QQQQ  0000495600Y
28838533A9K27G60000LBB002000QQQQ  0000495400Y
28838540X1K27GA00003R002000
28838552ABK27GA0000E4B002000UTX   0000068300Y
28838558A1K27GA00003SB002000ABT   0000050700Y
28838565A9K27G60000LCB002000QQQQ  0000495400Y
28838565ACK27GA000029B002000WYE   0000037400Y
28838586A2K27G600002OB002000AXP   0000399500Y
28838588XAK27GA0000OP001000
28838589AAK27GA0000PWB000600SPY   0001425100Y
28838590AAK27GA0000PXS000100SH    0000619100Y
28838591ABK27GA0000E5B001000SSO   0000763900Y
28838591XBK27GA0000DY001000
28838593XBK27GA0000DZ001000
28838593ABK27GA0000E6B001000SSO   0000763700Y
28838600A2K27G600002PB002000BK    0000425200Y
28838610X2K27G600001G002000
28838618A2K27G600002QB002000CAG   0000016400Y
28838626X4K27GA00008D002000
28838628A1K27GA00003TB002000ABT   0000049900Y
28838642X9K27G60000LC002000
28838647X5K27GA00002G002000
28838653X5K27GA00002H002000
28838658A2K27G600002RB002000AXP   0000398700Y
28838667A3K27G600003QB002000CVS   0000037100Y
28838673A2K27G600002SB002000BBT   0000027300Y
28838707A3K27G600003RB002000COH   0000029000Y
28838710A5K27GA00002IB002000HUM   0000432300Y
28838731A4K27GA00008OB002000EIX   0000042200Y
28838740A9K27G60000LDB002000QQQQ  0000495400Y
28838888AAK27GA0000PYB000100SPY   0001424400Y
28838888XAK27GA0000NO000100
28838925X9K27G60000LD002000
28839083A9K27G60000LEB002000QQQQ  0000495400Y
28839084XAK27GA0000PJ002000
28839084XAK27GA0000FD000500
28839084AAK27GA0000FDB000500SPY   0001424600Y
28839084XAK27GA0000EX000500
28839084AAK27GA0000EXB000500SPY   0001424600Y
28839084XAK27GA0000O6000500
28839084AAK27GA0000O6S000500SPY   0001425200Y
28839093X4K27GA00008M000100
28839093X4K27GA00008N000100
28839094X3K27G600003O000100
28839094XBK27GA0000E6001000
28839176X9K27G60000LE002000
28839184X4K27GA00008J000047
28839188X9K27G60000F9003200
28839188A9K27G60000F9B003200QQQQ  0000495100Y
28839189X9K27G60000LB002000
28839193A4K27GA00008PS000047DIA   0001298500Y
28839195A4K27GA00008QB000100DXD   0000499700Y
28839364X6K27GA00004U002000
28839368A2K27G600002TB002000BMY   0000015500Y
28839389A4K27GA00008RB002000EMR   0000552100Y
28839405XAK27GA0000PT002000
28839439XBK27GA0000E3002000
28839439X9K27G60000IS002000
28839453A7K27GA000020B002000LMT   0000110300Y
28839483A7K27GA000021B002000LPNT  0000187800Y
28839494A4K27GA00008SB002000EMR   0000552900Y
28839496XBK27GA0000E4002000
28839503XCK27GA000029002000
28839518X1K27GA00003S002000
28839536X1K27GA00003T002000
28839542A7K27GA000022B002000LMT   0000111100Y
28839561A1K27GA00003UB002000AFL   0000064500Y
28839564X2K27G600000Q002000
28839581X2K27G600002N002000
28839584X2K27G600000T002000
28839592A2K27G600002UB002000BK    0000424400Y
28839598X2K27G6000021002000
28839603A2K27G600002VB002000CAG   0000016300Y
28839612A3K27G600003SB002000CVS   0000037500Y
28839619X4K27GA00008O002000
28839626X4K27GA00006O002000
28839633A5K27GA00002JB002000HNZ   0000040100Y
28839653A5K27GA00002KB002000HOT   0000041000Y
28839663X2K27G6000020002000
28839678ACK27GA00002AB002000WYE   0000039400Y
28839702X3K27G600003K002000
28839709A6K27GA000055B002000ITW   0000503400Y
28839715X3K27G600003Q002000
28839732A1K27GA00003VB002000AFL   0000065300Y
28839741X4K27GA00006M002000
28839748A2K27G600002WB002000CAT   0000815800Y
28839764A4K27GA00008TB002000EIX   0000044400Y
28839775A5K27GA00002LB002000HNZ   0000040900Y
28839785A5K27GA00002MB002000HOT   0000041800Y
28840160XAK27GA0000PQ001000
28840160AAK27GA0000PZS001000SPY   0001425200Y
28840161XAK27GA0000FD000500
28840161AAK27GA0000FDB000500SPY   0001425000Y
28840161XAK27GA0000O6000500
28840161AAK27GA0000O6S000500SPY   0001425600Y
28840161XAK27GA0000EX000500
28840161AAK27GA0000EXB000500SPY   0001425000Y
28840162XAK27GA0000PZ001000
28840163ABK27GA0000E7B001000SSO   0000763700Y
28840163AAK27GA0000Q0S001000SPY   0001425600Y
28840172X4K27GA00008P000047
28840173A4K27GA00008US000047DIA   0001298800Y
28840174A4K27GA00008VS000100DOG   0000598500Y
28840174A4K27GA00008WS000100DXD   0000500400Y
28840174X4K27GA00008Q000100
28840176A3K27G600003TB000100DDM   0000800700Y
28840176X6K27GA000026000500
28840176A6K27GA000026S000500IWM   0000736900Y
28840176A6K27GA000056B002000IWM   0000736200Y
28840180X6K27GA00003H000500
28840180A6K27GA00003HB000500IWM   0000736400Y
28840183ABK27GA0000E8B000100UWM   0000542300Y
28840183ABK27GA0000E9S000100TWM   0000702200Y
28840183XBK27GA0000E1000100
28840184X6K27GA00003H000500
28840184A6K27GA00003HB000500IWM   0000736000Y
28840188XBK27GA0000E8000100
28840188XBK27GA0000E9000100
28840188XBK27GA00008X000100
28840188XBK27GA00008Y000100
28840188XBK27GA00008Z000100
28840187X6K27GA00003H000500
28840187A6K27GA00003HB000500IWM   0000736400Y
28840190ABK27GA0000EAB000100UWM   0000542300Y
28840190ABK27GA0000EBS000100TWM   0000702200Y
28840188A6K27GA000057B000100IWM   0000735900Y
28840188A6K27GA000058S000100IWM   0000737000Y
28840191X8K27G600001L000500
28840191X8K27G600001M000100
28840189X6K27GA000057000100
28840190X6K27GA00003H000500
28840190A6K27GA00003HB000500IWM   0000736000Y
28840193A8K27G600001PS000500MZZ   0000494200Y
28840193A8K27G600001QB000100MVV   0000805700Y
28840194X6K27GA000058000100
28840195X6K27GA00003H000500
28840195A6K27GA00003HB000500IWM   0000736400Y
28840196AAK27GA0000Q1B002000SPY   0001425100Y
28840196XAK27GA0000M6001000
28840197XAK27GA0000PB001000
28840197XAK27GA0000E5001000
28840197AAK27GA0000E5S001000SPY   0001425600Y
28840197XAK27GA0000LN003000
28840197XAK27GA0000LD003000
28840198X9K27G60000G0002000
28840198A9K27G60000G0B002000QQQQ  0000495600Y
28840198X9K27G60000G9002000
28840198A9K27G60000G9S002000QQQQ  0000496200Y
28840197XAK27GA0000FG000500
28840197AAK27GA0000FGB000500SPY   0001425100Y
28840197AAK27GA0000Q2B002000SPY   0001425100Y
28840198XAK27GA0000O5000500
28840198XAK27GA0000O8000500
28840198AAK27GA0000O8S000500SPY   0001425700Y
28840198X4K27GA00007C000200
28840198A4K27GA00007CB000200DIA   0001298500Y
28840198X4K27GA00006X000200
28840198X4K27GA00008H000200
28840198XAK27GA0000O1000500
28840198XAK27GA0000NY000500
28840198AAK27GA0000NYS000500SPY   0001425800Y
28840198XAK27GA0000E6001000
28840198AAK27GA0000E6S001000SPY   0001425700Y
28840198XAK27GA0000EB001000
28840198AAK27GA0000EBB001000SPY   0001425100Y
28840198XAK27GA0000LT001000
28840198XAK27GA0000LE003000
28840198XAK27GA0000NZ000500
28840198AAK27GA0000NZS000500SPY   0001425700Y
28840198XAK27GA0000F7000500
28840198AAK27GA0000F7B000500SPY   0001425100Y
28840198XAK27GA0000LM003000
28840198AAK27GA0000Q3B003000SPY   0001425100Y
28840198XAK27GA0000J2002000
28840197X6K27GA00003H000500
28840197A6K27GA00003HB000500IWM   0000736000Y
28840198X4K27GA00008U000047
28840198X4K27GA000062000200
28840198A4K27GA000062B000200DIA   0001298400Y
28840199X9K27G60000IP001000
28840199A9K27G60000LFB002000QQQQ  0000495400Y
28840199X9K27G60000F9003200
28840199A9K27G60000F9B003200QQQQ  0000495600Y
28840199X4K27GA00007D000100
28840199A4K27GA00008XS000100DXD   0000500300Y
28840199A3K27G600003UB000100DDM   0000800800Y
28840199AAK27GA0000Q4S003000SPY   0001426000Y
28840199AAK27GA0000Q5B003000SPY   0001425100Y
28840199AAK27GA0000Q6B002000SPY   0001425100Y
28840200X9K27G60000IO001000
28840200AAK27GA0000Q7S001000SPY   0001425700Y
28840200AAK27GA0000Q8S000500SPY   0001425600Y
28840200A4K27GA00008YS000200DIA   0001298900Y
28840200XBK27GA0000E2001000
28840199X6K27GA00003H000500
28840199A6K27GA00003HB000500IWM   0000736400Y
28840200XAK27GA0000F5000500
28840200AAK27GA0000F5B000500SPY   0001425100Y
28840200AAK27GA0000Q9S003000SPY   0001426000Y
28840200XAK27GA0000LG001000
28840201XBK27GA0000EA000100
28840200XAK27GA0000FI000500
28840200AAK27GA0000FIB000500SPY   0001425100Y
28840201XBK27GA0000EB000100
28840201AAK27GA0000QAS001000SDS   0000549200Y
28840201A9K27G60000LGS001000QQQQ  0000496100Y
28840201A9K27G60000LHS001000QQQQ  0000496000Y
28840201XBK27GA0000E5001000
28840201ABK27GA0000ECB001000SSO   0000764000Y
28840201AAK27GA0000QBS000500SPY   0001425800Y
28840202AAK27GA0000QCS001000SPY   0001425800Y
28840202ABK27GA0000EDS001000SSO   0000764900Y
28840202XAK27GA0000E8001000
28840202AAK27GA0000E8B001000SPY   0001425100Y
28840202XAK27GA0000LU000900
28840202AAK27GA0000QDB000200SPY   0001425100Y
28840203ABK27GA0000EEB000100UWM   0000542300Y
28840201A6K27GA000059B000100IWM   0000735900Y
28840203ABK27GA0000EFS000100TWM   0000702200Y
28840201X6K27GA000059000100
28840203ABK27GA0000EGB001000SSO   0000763800Y
28840203XBK27GA0000E7001000
28840203A4K27GA00008ZS000200DIA   0001299000Y
28840202X6K27GA00003H000500
28840202A6K27GA00003HB000500IWM   0000736000Y
28840204XAK27GA0000OI000100
28840204XAK27GA0000PR001000
28840204X3K27G600003N000100
28840204X4K27GA00006R000100
28840204XAK27GA0000E9001000
28840204AAK27GA0000E9S001000SPY   0001425800Y
28840205XAK27GA0000LK000900
28840205AAK27GA0000QES000100SH    0000619000Y
28840206XBK27GA0000EC001000
28840205AAK27GA0000QFS001000SDS   0000549100Y
28840204X6K27GA00003H000500
28840204A6K27GA00003HB000500IWM   0000736400Y
28840206ABK27GA0000EHB001000SSO   0000764100Y
28840206XAK27GA0000E7001000
28840206AAK27GA0000E7B001000SPY   0001425100Y
28840206XBK27GA0000EF000100
28840206XBK27GA0000EE000100
28840206AAK27GA0000QGB000200SPY   0001425100Y
28840206A4K27GA000090S000047DIA   0001299100Y
28840206A4K27GA000091B000100DXD   0000499300Y
28840208ABK27GA0000EIS000100TWM   0000702200Y
28840206X6K27GA00003H000500
28840206A6K27GA00003HB000500IWM   0000736000Y
28840208ABK27GA0000EJB000100UWM   0000542300Y
28840207A6K27GA00005AB000100IWM   0000735900Y
28840207X6K27GA00005A000100
28840209X9K27G60000LG001000
28840209X9K27G60000LH001000
28840228XBK27GA0000EJ000100
28840228XBK27GA0000EI000100
28840230A9K27G60000LIB002000QQQQ  0000495400Y
28840230ABK27GA0000EKB000100UWM   0000542300Y
28840230ABK27GA0000ELS000100TWM   0000702200Y
28840229X6K27GA000042002000
28840230X6K27GA000028000500
28840230A6K27GA000028S000500IWM   0000737000Y
28840232A8K27G600001RS000500MZZ   0000494100Y
28840232A8K27G600001SB000100MVV   0000805900Y
28840232X8K27G600001F000500
28840232X8K27G600001O000100
28840232X8K27G600001N000100
28840232X6K27GA000028000500
28840232A6K27GA000028S000500IWM   0000736600Y
28840234A8K27G600001TB000500MZZ   0000491600Y
28840234A8K27G600001US000100MVV   0000809300Y
28840234XBK27GA0000ED001000
28840234XAK27GA0000QC001000
28840234A9K27G60000LJS001000QID   0000382100Y
28840234A9K27G60000LKB001000QLD   0000888800Y
28840234X9K27G60000KK001000
28840234X4K27GA000065000100
28840234X4K27GA00008Y000200
28840235X3K27G600002A000100
28840235AAK27GA0000QHS001000SPY   0001425400Y
28840236ABK27GA0000EMS001000SSO   0000765000Y
28840237A3K27G600003VS000100DDM   0000802500Y
28840237A9K27G60000LLB001000QQQQ  0000495200Y
28840238XAK27GA0000PV001000
28840238XBK27GA0000EK000100
28840238XBK27GA0000EL000100
28840239X9K27G60000LL001000
28840239A4K27GA000092S000200DIA   0001298900Y
28840240ABK27GA0000ENB000100UWM   0000542300Y
28840240ABK27GA0000EOS000100TWM   0000702200Y
28840243A9K27G60000LMB001000QLD   0000888900Y
28840243X9K27G60000LK001000
28840244X3K27G600003V000100
28840244A9K27G60000LNS000100QID   0000382300Y
28840244X4K27GA000063000100
28840245A9K27G60000LOB001000QQQQ  0000495200Y
28840245XAK27GA0000PS001000
28840244A6K27GA00005BB002000IWM   0000736300Y
28840244X6K27GA000047002000
28840245A4K27GA000093B000100DXD   0000499200Y
28840246A3K27G600003WS000100DDM   0000802600Y
28840249X9K27G60000LO001000
28840250X4K27GA00003H000200
28840250A4K27GA00003HB000200DIA   0001298600Y
28840252A4K27GA000094S000100DOG   0000598400Y
28840252A4K27GA000095S000100DXD   0000500200Y
28840252X4K27GA000077000100
28840253A3K27G600003XB000100DDM   0000801000Y
28840253X3K27G600002T000100
28840258XAK27GA0000Q3003000
28840258AAK27GA0000Q3B003000SPY   0001425200Y
28840258XAK27GA0000Q5003000
28840258AAK27GA0000Q5B003000SPY   0001425200Y
28840258XAK27GA0000Q6002000
28840258AAK27GA0000Q6B002000SPY   0001425200Y
28840258XAK27GA0000F5000500
28840258AAK27GA0000F5B000500SPY   0001425200Y
28840258XAK27GA0000FI000500
28840258AAK27GA0000FIB000500SPY   0001425200Y
28840258XAK27GA0000E8001000
28840258AAK27GA0000E8B001000SPY   0001425200Y
28840258XAK27GA0000QD000200
28840258AAK27GA0000QDB000200SPY   0001425200Y
28840258XAK27GA0000E7001000
28840258AAK27GA0000E7B001000SPY   0001425200Y
28840258XAK27GA0000QG000200
28840258AAK27GA0000QGB000200SPY   0001425200Y
28840258X6K27GA000028000500
28840258A6K27GA000028S000500IWM   0000737000Y
28840284XAK27GA0000OC001000
28840284AAK27GA0000QIS001000SPY   0001425700Y
28840285XBK27GA0000EG001000
28840286X8K27G600001U000100
28840285ABK27GA0000EPB001000SSO   0000763900Y
28840286AAK27GA0000QJS001000SPY   0001425700Y
28840288A8K27G600001VS000100MVV   0000809400Y
28840293ABK27GA0000EQB000100TWM   0000701000Y
28840300A8K27G600001WS000500MZZ   0000494000Y
28840300A8K27G600001XB000100MVV   0000806100Y
28840308XBK27GA00009Z000100
28840308ABK27GA0000ERB000100UWM   0000542400Y
28840308ABK27GA0000ESS000100TWM   0000702000Y
28840308XBK27GA0000EO000100
28840324X9K27G60000J8002000
28840324X9K27G60000F4003200
28840324A9K27G60000F4S003200QQQQ  0000496300Y
28840324X9K27G60000IH005000
28840324X9K27G60000IG005000
28840324A9K27G60000LPB005000QQQQ  0000495700Y
28840324A9K27G60000LQB005000QQQQ  0000495700Y
28840325A9K27G60000LRB002000QQQQ  0000495700Y
28840325X9K27G60000EP002000
28840325A9K27G60000EPB002000QQQQ  0000495700Y
28840325A9K27G60000LSB001000QLD   0000888800Y
28840331XAK27GA0000QJ001000
28840359X3K27G6000036002000
28840363XAK27GA0000QI001000
28840363AAK27GA0000QKS001000SPY   0001425800Y
28840365AAK27GA0000QLS001000SPY   0001425800Y
28840377X4K27GA000062000200
28840377A4K27GA000062B000200DIA   0001298700Y
28840379A3K27G600003YB000100DDM   0000801100Y
28840379X3K27G600003L000100
28840379XAK27GA0000NQ000100
28840379AAK27GA0000QMB001000SDS   0000547500Y
28840379AAK27GA0000QNB001000SDS   0000547600Y
28840379AAK27GA0000QOB001000SDS   0000547700Y
28840381AAK27GA0000QPS000100SPY   0001426900Y
28840389A6K27GA00005CB002000IMCL  0000321400Y
28840395X5K27GA00001I002000
28840421XAK27GA0000OF002000
28840424X7K27GA000022002000
28840424X7K27GA000020002000
28840435XCK27GA00002A002000
28840437X9K27G60000LP005000
28840437X9K27G60000LQ005000
28840442A9K27G60000LTB005000QQQQ  0000495300Y
28840442A9K27G60000LUB005000QQQQ  0000495300Y
28840449X9K27G60000F4003200
28840449A9K27G60000F4S003200QQQQ  0000495800Y
28840449X9K27G60000EP002000
28840449A9K27G60000EPB002000QQQQ  0000495400Y
28840458X9K27G60000LR002000
28840460X9K27G60000LS001000
28840462A9K27G60000LVB001000QQQQ  0000495200Y
28840467X1K27GA00003V002000
28840467AAK27GA0000QQB002000SHLD  0000686500Y
28840469X9K27G60000LV001000
28840481ABK27GA0000ETB002000UTX   0000072300Y
28840489ABK27GA0000EUB002000UTX   0000073100Y
28840499A9K27G60000LWB002000PDLI  0000015000Y
28840507X1K27GA00003U002000
28840524X9K27G60000LT005000
28840524X9K27G60000F4003200
28840524A9K27G60000F4S003200QQQQ  0000496300Y
28840524X9K27G60000LU005000
28840524A9K27G60000LXB002000QQQQ  0000495700Y
28840525A9K27G60000LYB005000QQQQ  0000495700Y
28840525A9K27G60000LZB005000QQQQ  0000495700Y
28840526A9K27G60000M0B001000QLD   0000888800Y
28840526X9K27G60000EP002000
28840526A9K27G60000EPB002000QQQQ  0000495700Y
28840542ACK27GA00002BB002000WYE   0000039800Y
28840546A1K27GA00003WB002000ABT   0000053800Y
28840548XBK27GA000074000100
28840548XBK27GA000075000100
28840546A6K27GA00005DS002000IWM   0000737000Y
28840548A6K27GA00005ES000100IWM   0000737100Y
28840550ABK27GA0000EVB000100TWM   0000700900Y
28840549X6K27GA00003H000500
28840549A6K27GA00005FB000500IWM   0000736500Y
28840554X6K27GA00005E000100
28840555X6K27GA000027000500
28840555A6K27GA000027B000500IWM   0000736400Y
28840574X2K27G600002S002000
28840574A1K27GA00003XB002000ABT   0000053000Y
28840578A2K27G600002XB002000AZN   0000417500Y
28840584A9K27G60000M1B002000QQQQ  0000495500Y
28840584X9K27G60000JC002000
28840584X9K27G60000JD002000
28840597X2K27G600002Q002000
28840602A2K27G600002YB002000BBT   0000030000Y
28840614A2K27G600002ZB002000BNI   0001058500Y
28840624E4K27GA00006Q000009000N4AQ00004
28840629X4K27GA00008T002000
28840642X4K27GA00008G000100
28840647X2K27G600001M002000
28840648A4K27GA000096B000100DRYS  0001068000Y
28840653A3K27G600003ZB002000COH   0000031800Y
28840654X3K27G600003R002000
28840668X4K27GA00006Q000091
28840669X3K27G600003S002000
28840679X5K27GA00002L002000
28840693A2K27G6000030B002000AZN   0000416700Y
28840693X5K27GA00002M002000
28840703A3K27G6000040B002000CVS   0000039500Y
28840708A2K27G6000031B002000BNI   0001057700Y
28840714X5K27GA00002J002000
28840725X5K27GA00002K002000
28840726A4K27GA000097B002000EIX   0000045000Y
28840726A4K27GA000098B002000FCX   0001224300Y
28840754A4K27GA000099B002000FCX   0001223500Y
28840773A6K27GA00005GB002000IWN   0000663500Y
28840932X9K27G60000EQ002000
28840932A9K27G60000EQS002000QQQQ  0000496100Y
28841147XAK27GA0000O2000500
28841147AAK27GA0000O2S000500SPY   0001425900Y
28841147XAK27GA0000QH001000
28841147AAK27GA0000QRB002000SPY   0001425300Y
28841147XAK27GA0000F2000500
28841147AAK27GA0000F2B000500SPY   0001425300Y
28841148XAK27GA0000L8001000
28841149XAK27GA0000LB001000
28841149XBK27GA0000EM001000
28841149AAK27GA0000QSS001000SPY   0001425800Y
28841150XAK27GA0000QM001000
28841151AAK27GA0000QTB001000SDS   0000547700Y
28841151ABK27GA0000EWS001000SSO   0000765100Y
28841152AAK27GA0000QUB001000SDS   0000547500Y
28841153XAK27GA0000QU001000
28841153XAK27GA0000LA000100
28841155AAK27GA0000QVB001000SDS   0000547500Y
28841155XAK27GA0000QO001000
28841157AAK27GA0000QWB001000SDS   0000547400Y
28841161X4K27GA000092000200
28841163A4K27GA00009AS000200DIA   0001299200Y
28841163AAK27GA0000QXB001000SPY   0001425200Y
28841163XAK27GA0000PM002000
28841165XAK27GA0000KV003000
28841165XAK27GA0000KW003000
28841165X9K27G60000G1002000
28841165A9K27G60000G1S002000QQQQ  0000496300Y
28841168AAK27GA0000QYS003000SPY   0001426200Y
28841168AAK27GA0000QZS003000SPY   0001426200Y
28841195X4K27GA00007C000200
28841195A4K27GA00007CB000200DIA   0001298800Y
28841197A4K27GA00009BS000100DOG   0000598300Y
28841197X4K27GA00006W000100
28841197A4K27GA00009CS000100DXD   0000500100Y
28841198X3K27G600003T000100
28841198A3K27G6000041B000100DDM   0000801200Y
28841301AAK27GA0000R0S001000SDS   0000549000Y
28841301XBK27GA0000EH001000
28841301ABK27GA0000EXB001000SSO   0000764200Y
28841306X4K27GA00008Z000200
28841312A4K27GA00009DS000200DIA   0001299300Y
28841323X9K27G60000I1002000
28841323X9K27G60000I0005000
28841323X9K27G60000HY005000
28841324X9K27G60000GI002000
28841334A9K27G60000M2S005000QQQQ  0000496200Y
28841334A9K27G60000M3S005000QQQQ  0000496200Y
28841359A3K27G6000042B002000CELG  0000467400Y
28841386X2K27G600002T002000
28841426XAK27GA0000QQ002000
28841431XBK27GA0000ET002000
28841431XBK27GA0000EU002000
28841440X3K27G600003P002000
28841449XCK27GA00002B002000
28841457X1K27GA00003W002000
28841467X1K27GA00003X002000
28841468AAK27GA0000R1B002000SPLS  0000016600Y
28841471X3K27G6000040002000
28841475XBK27GA0000EP001000
28841476ABK27GA0000EYB001000SSO   0000764000Y
28841495A7K27GA000023B002000LMT   0000117100Y
28841498X2K27G600002V002000
28841522ACK27GA00002CB002000WYE   0000041800Y
28841543A5K27GA00002NB002000GM    0000173400Y
28841552X4K27GA000097002000
28841562A7K27GA000024B002000LMT   0000116300Y
28841576A1K27GA00003YB002000AFL   0000069100Y
28841588A1K27GA00003ZB002000AFL   0000068300Y
28841601A2K27G6000032B002000BBT   0000030100Y
28841609A2K27G6000033B002000CAG   0000018400Y
28841633A2K27G6000034B002000CAT   0000815100Y
28841639A4K27GA00009EB002000EIX   0000047200Y
28841648A3K27G6000043B002000COH   0000032000Y
28841661A3K27G6000044B002000CVS   0000039900Y
28841667A5K27GA00002OB002000HNZ   0000043500Y
28841678A5K27GA00002PB002000HNZ   0000042700Y
28841691A5K27GA00002QB002000HOT   0000043600Y
28841691A5K27GA00002RB002000HOT   0000044400Y
28841707A6K27GA00005HB002000JBL   0000103100Y
28841710A6K27GA00005IB002000IP    0000260800Y
28841741X4K27GA000096000100
28841741X4K27GA00008E000100
28842061XAK27GA0000FE000500
28842061AAK27GA0000FEB000500SPY   0001425300Y
28842088A4K27GA00009FB000100DRYS  0001068800Y
28842088A4K27GA00009GB000100DRYS  0001068800Y
28842132X9K27G60000M1002000
28842386X6K27GA00005C002000
28842391X7K27GA000024002000
28842414X1K27GA00003Z002000
28842414AAK27GA0000R2B002000SHLD  0000691600Y
28842417X5K27GA00001J002000
28842428X2K27G600002K002000
28842441X3K27G6000044002000
28842445X5K27GA00002P002000
28842445X5K27GA00002Q002000
28842456X7K27GA000023002000
28842466XCK27GA00002C002000
28842469A3K27G6000045B002000CTSH  0000027300Y
28842476X1K27GA00003Y002000
28842482ABK27GA0000EZB002000UTX   0000076300Y
28842485X2K27G600002Y002000
28842503X2K27G600002M002000
28842523X3K27G600003Z002000
28842523ACK27GA00002DB002000WYE   0000042200Y
28842529X4K27GA00009E002000
28842531XAK27GA0000K1001000
28842531AAK27GA0000K1S001000SPY   0001425900Y
28842535X5K27GA00002O002000
28842560X5K27GA00002R002000
28842560A1K27GA000040B002000ABT   0000056000Y
28842561A2K27G6000035B002000BMY   0000017400Y
28842569XAK27GA0000E4001000
28842569AAK27GA0000E4B001000SPY   0001425400Y
28842570XAK27GA0000EW000500
28842570AAK27GA0000EWS000500SPY   0001425900Y
28842574X9K27G60000G8002000
28842574A9K27G60000G8B002000QQQQ  0000495700Y
28842574XAK27GA0000Q2002000
28842574AAK27GA0000Q2B002000SPY   0001425400Y
28842574XAK27GA0000EX000500
28842574AAK27GA0000EXB000500SPY   0001425400Y
28842574XAK27GA0000O6000500
28842574AAK27GA0000O6S000500SPY   0001426000Y
28842574XAK27GA0000PI001000
28842574XAK27GA0000PG000600
28842574XAK27GA0000Q8000500
28842574AAK27GA0000Q8S000500SPY   0001426000Y
28842574AAK27GA0000R3B001000SPY   0001425400Y
28842574XAK27GA0000PO003000
28842574XAK27GA0000IU003000
28842574XAK27GA0000FD000500
28842574AAK27GA0000FDB000500SPY   0001425400Y
28842574XAK27GA0000E5001000
28842574AAK27GA0000E5S001000SPY   0001426000Y
28842575XAK27GA0000IT003000
28842575XAK27GA0000PN003000
28842575AAK27GA0000R4B003000SPY   0001425400Y
28842575XAK27GA0000QL001000
28842575AAK27GA0000R5B003000SPY   0001425400Y
28842575XAK27GA0000QK001000
28842575AAK27GA0000R6B002000SPY   0001425300Y
28842575XAK27GA0000Q1001000
28842576AAK27GA0000R7S001000SPY   0001425900Y
28842576AAK27GA0000R8S003000SPY   0001426400Y
28842576AAK27GA0000R9S003000SPY   0001426400Y
28842577AAK27GA0000RAS001000SPY   0001425900Y
28842577AAK27GA0000RBS001000SPY   0001425900Y
28842584XBK27GA0000EW001000
28842584XAK27GA0000IW001000
28842585ABK27GA0000F0B002000UTX   0000077100Y
28842585XAK27GA0000QW001000
28842586ABK27GA0000F1S001000SSO   0000765200Y
28842586XAK27GA0000QV001000
28842586A6K27GA00005JB002000IWM   0000736400Y
28842586X6K27GA00002O002000
28842588AAK27GA0000RCB001000SDS   0000547500Y
28842588AAK27GA0000RDB001000SDS   0000547400Y
28842593X9K27G60000F7003200
28842593A9K27G60000F7B003200QQQQ  0000495700Y
28842594A9K27G60000M4B004000QQQQ  0000495500Y
28842595XAK27GA0000QN001000
28842602A1K27GA000041B002000ABT   0000056900Y
28842605A2K27G6000036B002000CAG   0000018200Y
28842613X4K27GA00004O000100
28842613X4K27GA00004P000100
28842614X3K27G600003W000100
28842616A3K27G6000046S000100DDM   0000802700Y
28842615A4K27GA00009HB000100DOG   0000596900Y
28842615A4K27GA00009IB000100DXD   0000499100Y
28842618X6K27GA00002A000500
28842618A6K27GA00002AS000500IWM   0000737100Y
28842621A3K27G6000047B002000CVS   0000041900Y
28842621A4K27GA00009JB002000EIX   0000047800Y
28842622XAK27GA0000RA001000
28842622XAK27GA0000RB001000
28842621X6K27GA00002C000500
28842621A6K27GA00002CB000500IWM   0000736600Y
28842624XBK27GA0000BE000100
28842623X6K27GA00002W002000
28842624XAK27GA0000QT001000
28842624ABK27GA0000F2B000100UWM   0000542500Y
28842625XBK27GA0000ES000100
28842625ABK27GA0000F3S000100TWM   0000701800Y
28842624AAK27GA0000RES001000SPY   0001426000Y
28842624AAK27GA0000RFS001000SPY   0001426000Y
28842625X6K27GA00002C000500
28842625A6K27GA00002CB000500IWM   0000736200Y
28842626AAK27GA0000RGB001000SDS   0000547600Y
28842626X6K27GA00002C000500
28842626A6K27GA00002CB000500IWM   0000736600Y
28842628XBK27GA00006S000100
28842628XBK27GA0000EQ000100
28842628XBK27GA000023000100
28842627A6K27GA00005KS002000IWM   0000737100Y
28842630ABK27GA0000F4S000100UWM   0000543500Y
28842630ABK27GA0000F5B000100TWM   0000700700Y
28842630ABK27GA0000F6B000100TWM   0000700800Y
28842631A6K27GA00005LB002000IR    0000432300Y
28842633AAK27GA0000RHS000100SH    0000618900Y
28842634ABK27GA0000F7B001000SSO   0000764300Y
28842634XBK27GA0000EX001000
28842635X6K27GA00002C000500
28842635A6K27GA00002CB000500IWM   0000736200Y
28842637X6K27GA00002C000500
28842637A6K27GA00002CB000500IWM   0000736600Y
28842647X6K27GA00002C000500
28842647A6K27GA00002CB000500IWM   0000736200Y
28842650A6K27GA00005MB002000IRF   0000217100Y
28842656A8K27G600001YS000500MZZ   0000493900Y
28842656X8K27G600001B000100
28842656A8K27G600001ZB000100MVV   0000806200Y
28842661A6K27GA00005NB002000JCI   0000032000Y
28842670X6K27GA00002C000500
28842670A6K27GA00002CB000500IWM   0000736600Y
28842674A6K27GA00005OB002000ITW   0000504200Y
28842693A6K27GA00005PB002000IWN   0000664400Y
28842706XAK27GA0000R6001000
28842713XAK27GA0000RH000100
28842714XBK27GA0000F7001000
28842715ABK27GA0000F8B001000SSO   0000764200Y
28842716AAK27GA0000RIB001000SPY   0001425300Y
28842737X8K27G600001C000500
28842737A8K27G6000020S000500MZZ   0000493800Y
28842738A8K27G6000021B000100MVV   0000806300Y
28842738X8K27G600001Q000100
28842739X8K27G600001P000500
28842769X6K27GA00005D002000
28842774XAK27GA0000PW000600
28842774XAK27GA0000EB001000
28842774AAK27GA0000EBB001000SPY   0001425500Y
28842775AAK27GA0000RJB001000SPY   0001425500Y
28842776AAK27GA0000RKS000100SH    0000618900Y
28842776XBK27GA0000F8001000
28842776ABK27GA0000F9B001000SSO   0000764300Y
28842778XBK27GA0000EY001000
28842778ABK27GA0000FAB001000SSO   0000764100Y
28842781X8K27G600001T000500
28842781X8K27G600001V000100
28842782A8K27G6000022B000500MZZ   0000491400Y
28842783A8K27G6000023S000100MVV   0000809600Y
28842820A8K27G6000024B000500MZZ   0000491500Y
28842820A8K27G6000025S000100MVV   0000809500Y
28842822XAK27GA0000RJ001000
28842822XAK27GA0000R8003000
28842822XAK27GA0000R5003000
28842822XAK27GA0000Q8000500
28842822AAK27GA0000Q8S000500SPY   0001425600Y
28842822XAK27GA0000EB001000
28842822AAK27GA0000EBB001000SPY   0001425100Y
28842822AAK27GA0000RLS003000SPY   0001425700Y
28842822XAK27GA0000R9003000
28842822XAK27GA0000R4003000
28842822AAK27GA0000RMS003000SPY   0001425700Y
28842822XAK27GA0000RI001000
28842823AAK27GA0000RNB001000SPY   0001425100Y
28842823AAK27GA0000ROB003000SPY   0001424700Y
28842825AAK27GA0000RPB003000SPY   0001424700Y
28842832X4K27GA00009D000200
28842836A4K27GA00009KS000200DIA   0001299000Y
28842839A6K27GA00005QS002000IWM   0000737000Y
28842841X9K27G60000M4004000
28842845XAK27GA0000RM003000
28842845XAK27GA0000RP003000
28842846XAK27GA0000RO003000
28842846XAK27GA0000RL003000
28842846AAK27GA0000RQB003000SPY   0001425400Y
28842846AAK27GA0000RRB003000SPY   0001425400Y
28842847XAK27GA0000Q1001000
28842848AAK27GA0000RSS003000SPY   0001425800Y
28842848AAK27GA0000RTS003000SPY   0001425800Y
28842858X6K27GA00002C000500
28842858A6K27GA00002CB000500IWM   0000736200Y
28842862A9K27G60000M5S002000QQQQ  0000496000Y
28842868XBK27GA0000F2000100
28842868XBK27GA0000F3000100
28842870ABK27GA0000FBS000100TWM   0000702000Y
28842869X6K27GA00002C000500
28842869A6K27GA00002CB000500IWM   0000736600Y
28842872ABK27GA0000FCB000100UWM   0000542500Y
28842872XBK27GA0000FB000100
28842872ABK27GA0000FDS000100TWM   0000701800Y
28842876X6K27GA00002C000500
28842876A6K27GA00002CB000500IWM   0000736200Y
28842881X8K27G6000022000500
28842881X8K27G6000024000500
28842881X8K27G6000023000100
28842881X8K27G6000025000100
28842883A8K27G6000026B000500MZZ   0000491400Y
28842883A8K27G6000027S000100MVV   0000809600Y
28842885X6K27GA00002C000500
28842885A6K27GA00002CB000500IWM   0000736600Y
28842898A8K27G6000028B000500MZZ   0000491600Y
28842898A8K27G6000029S000100MVV   0000809400Y
28842927X6K27GA00005Q002000
28842965X8K27G600001Y000500
28842965X8K27G6000020000500
28842965X8K27G600001W000500
28842965X8K27G600001R000500
28842965X8K27G600001X000100
28842965X8K27G600001S000100
28842965X8K27G6000021000100
28842965X8K27G600001Z000100
28842967A8K27G600002AS000500MZZ   0000493900Y
28842967A8K27G600002BB000100MVV   0000806200Y
28843059XAK27GA0000E5001000
28843059AAK27GA0000E5S001000SPY   0001425600Y
28843059X4K27GA00007C000200
28843059A4K27GA00007CB000200DIA   0001298500Y
28843059XAK27GA0000RR003000
28843059XAK27GA0000EX000500
28843059AAK27GA0000EXB000500SPY   0001425000Y
28843059XAK27GA0000RQ003000
28843059XAK27GA0000FD000500
28843059AAK27GA0000FDB000500SPY   0001425000Y
28843060AAK27GA0000RUS001000SPY   0001425800Y
28843060XAK27GA0000RE001000
28843060XAK27GA0000Q2002000
28843061X4K27GA00009B000100
28843061AAK27GA0000RVB003000SPY   0001424700Y
28843061X4K27GA00009C000100
28843061X3K27G6000041000100
28843062AAK27GA0000RWB003000SPY   0001424700Y
28843071A8K27G600002CS000500MZZ   0000493800Y
28843071A8K27G600002DB000100MVV   0000806300Y
28843075X6K27GA00002C000500
28843075A6K27GA00002CB000500IWM   0000736200Y
28843077XBK27GA0000FA001000
28843076A6K27GA00005RS002000IWM   0000737000Y
28843088XBK27GA0000FC000100
28843088XBK27GA0000FD000100
28843088A6K27GA00005SB000100IWM   0000736100Y
28843088X6K27GA00005S000100
28843090ABK27GA0000FES000100TWM   0000702000Y
28843111X8K27G600002C000500
28843111X8K27G600002B000100
28843111X8K27G600002A000500
28843111X8K27G600002D000100
28843113A8K27G600002EB000100MVV   0000806100Y
28843113A8K27G600002FS000500MZZ   0000494000Y
28843135XAK27GA0000QX001000
28843149XAK27GA0000R6001000
28843151AAK27GA0000RXB001000SPY   0001425200Y
28843285X8K27G6000028000500
28843285X8K27G6000029000100
28843337XAK27GA0000RU001000
28843337AAK27GA0000RYS001000SPY   0001425900Y
28843339AAK27GA0000RZS001000SPY   0001425900Y
28843364XAK27GA0000R2002000
28843409X7K27GA000021002000
28843430XBK27GA0000EZ002000
28843430XBK27GA0000F0002000
28843437XCK27GA00002D002000
28843445A6K27GA00005TB002000IMCL  0000324600Y
28843449X1K27GA000040002000
28843476X9K27G60000M3005000
28843477X9K27G60000F7003200
28843477A9K27G60000F7B003200QQQQ  0000495200Y
28843477X9K27G60000M2005000
28843477A9K27G60000M6S005000QQQQ  0000495800Y
28843477A9K27G60000M7S005000QQQQ  0000495800Y
28843478A9K27G60000M8S002000QQQQ  0000495800Y
28843478X9K27G60000G8002000
28843478A9K27G60000G8B002000QQQQ  0000495200Y
28843480X1K27GA000041002000
28843482X9K27G60000EQ002000
28843482A9K27G60000EQS002000QQQQ  0000495800Y
28843485X2K27G600002R002000
28843485X2K27G6000032002000
28843493E4K27GA00002Y00010000004AQ00005
28843492X6K27GA00002A000500
28843492A6K27GA00002AS000500IWM   0000736700Y
28843495X9K27G60000G1002000
28843495A9K27G60000G1S002000QQQQ  0000495800Y
28843495X9K27G60000LY005000
28843495ABK27GA0000FFS000100UWM   0000543400Y
28843495ABK27GA0000FGB000100TWM   0000701000Y
28843495ABK27GA0000FHB000100TWM   0000701100Y
28843495A4K27GA00009MS000100DIG   0001246800Y
28843496X4K27GA00009M000100
28843495X6K27GA00001J000100
28843497A9K27G60000M9B005000QQQQ  0000495300Y
28843498X3K27G6000019002000
28843498A4K27GA00009NS000100DIG   0001246800Y
28843499X3K27G6000043002000
28843503A6K27GA00005UB000100IYE   0001532500Y
28843503X6K27GA00001L000100
28843506A6K27GA00005VS000100IYE   0001540600Y
28843512X9K27G60000LZ005000
28843515X2K27G600002O002000
28843514X4K27GA00009J002000
28843516XAK27GA0000RF001000
28843516AAK27GA0000S0S001000SPY   0001425800Y
28843522A9K27G60000MAB005000QQQQ  0000495300Y
28843532X2K27G6000033002000
28843532X1K27GA00000V000100
28843532A1K27GA00000VB000100AAPL  0001828600Y
28843545X9K27G60000MA005000
28843546X9K27G60000M9005000
28843546A9K27G60000MBB005000QQQQ  0000495700Y
28843546A9K27G60000MCB005000QQQQ  0000495700Y
28843549E1K27GA00002Y000090000N1AQ00003
28843551X3K27G6000013002000
28843561X3K27G6000047002000
28843562A7K27GA000025B002000LMT   0000122300Y
28843572X6K27GA00005U000100
28843572A6K27GA00005WB000100IYE   0001533200Y
28843574A5K27GA00002SB002000GM    0000174300Y
28843579A1K27GA000042B002000AFL   0000072000Y
28843588A2K27G6000037B002000BDX   0000758300Y
28843596A3K27G6000049B002000CVS   0000042200Y
28843608A5K27GA00002TB002000HNZ   0000045200Y
28843613A5K27GA00002UB002000HOT   0000046300Y
28843626A6K27GA00005XB002000JCP   0000411900Y
28843641A7K27GA000026B002000LMT   0000123100Y
28843643A6K27GA00005YB002000JPM   0000443300Y
28843652ACK27GA00002EB002000WYE   0000044200Y
28843663A6K27GA00005ZB002000JWN   0000349300Y
28843670A1K27GA000043B002000AFL   0000072800Y
28843681A2K27G6000038B002000BBT   0000032800Y
28843687A6K27GA000060B002000KEY   0000209100Y
28843711A2K27G6000039B002000BDX   0000759100Y
28843728A3K27G600004AB002000COH   0000034800Y
28843739A4K27GA00009OB002000EIX   0000050000Y
28843749A5K27GA00002VB002000HNZ   0000046000Y
28844106XAK27GA0000O6000500
28844106AAK27GA0000O6S000500SPY   0001425600Y
28844184A8K27G600002GB000500MZZ   0000491500Y
28844184A8K27G600002HS000100MVV   0000809500Y
28844355X2K27G6000035002000
28844381X7K27GA000026002000
28844387X7K27GA000025002000
28844387AAK27GA0000S1B002000SHLD  0000696700Y
28844440X1K27GA000042002000
28844451ABK27GA0000FIB002000UTX   0000081100Y
28844453X1K27GA000039002000
28844459X2K27G6000036002000
28844463X9K27G60000MC005000
28844461XCK27GA00002E002000
28844492A9K27G60000MDB005000QQQQ  0000495300Y
28844496A7K27GA000027B002000LPNT  0000191200Y
28844503AAK27GA0000S2S001000SPY   0001425800Y
28844521A1K27GA000044B002000ABT   0000059900Y
28844529X1K27GA000043002000
28844549X1K27GA00003A002000
28844555ABK27GA0000FJB002000UTX   0000080300Y
28844568X3K27G6000049002000
28844583A2K27G600003AB002000AXP   0000400800Y
28844598A2K27G600003BB002000CAG   0000020300Y
28844598XAK27GA0000E5001000
28844598AAK27GA0000E5S001000SPY   0001426000Y
28844598XAK27GA0000RV003000
28844598XAK27GA0000EX000500
28844598AAK27GA0000EXB000500SPY   0001425400Y
28844598XAK27GA0000RW003000
28844598XAK27GA0000S2001000
28844598XAK27GA0000S0001000
28844598AAK27GA0000S3B001000SPY   0001425300Y
28844599AAK27GA0000S4B003000SPY   0001425400Y
28844599AAK27GA0000S5B003000SPY   0001425400Y
28844599XAK27GA0000RS003000
28844599XAK27GA0000RT003000
28844599XAK27GA0000O6000500
28844599AAK27GA0000O6S000500SPY   0001426000Y
28844601AAK27GA0000S6S003000SPY   0001426400Y
28844602AAK27GA0000S7S003000SPY   0001426400Y
28844608ACK27GA00002FB002000WYE   0000044600Y
28844610XAK27GA0000RZ001000
28844613ABK27GA0000FKB001000SSO   0000764100Y
28844614A3K27G600004BB002000CCE   0000190200Y
28844615X6K27GA00002A000500
28844615A6K27GA00002AS000500IWM   0000737100Y
28844617X9K27G60000MD005000
28844617X9K27G60000M7005000
28844617A9K27G60000MEB005000QQQQ  0000495700Y
28844617X4K27GA00007C000200
28844617A4K27GA00007CB000200DIA   0001298800Y
28844618X9K27G60000G1002000
28844618A9K27G60000G1S002000QQQQ  0000496300Y
28844618A9K27G60000MFS005000QQQQ  0000496200Y
28844619A4K27GA00009PS000100DOG   0000598300Y
28844620A3K27G600004CB000100DDM   0000801200Y
28844619A4K27GA00009QS000100DXD   0000500100Y
28844621XAK27GA0000S3001000
28844622X9K27G60000EQ002000
28844622A9K27G60000EQS002000QQQQ  0000496100Y
28844623X9K27G60000M8002000
28844624AAK27GA0000S8B001000SPY   0001425200Y
28844628XBK27GA0000FF000100
28844628XBK27GA0000FH000100
28844628XBK27GA0000FG000100
28844632X5K27GA00001Z002000
28844636X5K27GA00002T002000
28844637XAK27GA0000RY001000
28844637AAK27GA0000S9S001000SPY   0001426000Y
28844637X6K27GA00002C000500
28844637A6K27GA00002CB000500IWM   0000736600Y
28844639AAK27GA0000SAS001000SPY   0001426000Y
28844640ABK27GA0000FLB000100UWM   0000542500Y
28844638X6K27GA00002C000500
28844638A6K27GA00002CB000500IWM   0000736200Y
28844640ABK27GA0000FMS000100TWM   0000701800Y
28844640XBK27GA0000FE000100
28844640XAK27GA0000E5001000
28844640AAK27GA0000E5S001000SPY   0001425600Y
28844640XAK27GA0000S5003000
28844640XAK27GA0000EX000500
28844640AAK27GA0000EXB000500SPY   0001425000Y
28844640XAK27GA0000S4003000
28844640XAK27GA0000S6003000
28844640XAK27GA0000S7003000
28844641AAK27GA0000SBS003000SPY   0001425800Y
28844641AAK27GA0000SCS003000SPY   0001425800Y
28844641AAK27GA0000SDS001000SPY   0001425900Y
28844642AAK27GA0000SEB003000SPY   0001424700Y
28844642AAK27GA0000SFB003000SPY   0001424700Y
28844641X6K27GA00002C000500
28844641A6K27GA00002CB000500IWM   0000736600Y
28844643XBK27GA0000FL000100
28844643XBK27GA0000FM000100
28844645A1K27GA000045B002000ABT   0000059100Y
28844645ABK27GA0000FNB000100UWM   0000542500Y
28844645ABK27GA0000FOS000100TWM   0000701800Y
28844645X6K27GA00002C000500
28844645A6K27GA00002CB000500IWM   0000736200Y
28844647X6K27GA00002C000500
28844647A6K27GA00002CB000500IWM   0000736600Y
28844648XBK27GA0000FN000100
28844648XBK27GA0000FO000100
28844648X6K27GA00002C000500
28844648A6K27GA00002CB000500IWM   0000736200Y
28844650ABK27GA0000FPS000100TWM   0000701800Y
28844650ABK27GA0000FQB000100UWM   0000542500Y
28844651X4K27GA00009O002000
28844650X6K27GA00002C000500
28844650A6K27GA00002CB000500IWM   0000736600Y
28844652XBK27GA0000FQ000100
28844652XBK27GA0000FP000100
28844654ABK27GA0000FRB000100UWM   0000542500Y
28844654ABK27GA0000FSS000100TWM   0000701800Y
28844655X5K27GA00002U002000
28844655X6K27GA00002C000500
28844655A6K27GA00002CB000500IWM   0000736200Y
28844657X6K27GA00002C000500
28844657A6K27GA00002CB000500IWM   0000736600Y
28844659X6K27GA00002C000500
28844659A6K27GA00002CB000500IWM   0000736200Y
28844661X5K27GA00002V002000
28844661XAK27GA0000S8001000
28844662X4K27GA00007C000200
28844662A4K27GA00007CB000200DIA   0001298500Y
28844664X4K27GA00009P000100
28844664X4K27GA00009Q000100
28844665X3K27G600004C000100
28844668XBK27GA0000FR000100
28844668XBK27GA0000FS000100
28844668X9K27G60000G1002000
28844668A9K27G60000G1S002000QQQQ  0000495800Y
28844668X9K27G60000MF005000
28844669A9K27G60000MGS005000QQQQ  0000495800Y
28844670A9K27G60000MHS002000QQQQ  0000495800Y
28844670A3K27G600004DB002000CVS   0000044200Y
28844670ABK27GA0000FTS000100TWM   0000702000Y
28844670XBK27GA0000FK001000
28844672X9K27G60000EQ002000
28844672A9K27G60000EQS002000QQQQ  0000495800Y
28844686X6K27GA00005N002000
28844696X9K27G60000ME005000
28844698A5K27GA00002WB002000HOT   0000048400Y
28844700A2K27G600003CB002000AXP   0000400000Y
28844702A9K27G60000MIB005000QQQQ  0000495300Y
28844708A2K27G600003DB002000BBT   0000033000Y
28844710A4K27GA00009RS000100DRYS  0001071900Y
28844723A3K27G600004EB002000CCE   0000189400Y
28844729A3K27G600004FB002000COH   0000035000Y
28844741A4K27GA00009SB002000EIX   0000050600Y
28844811X4K27GA00009F000100
28844816XAK27GA0000O6000500
28844816AAK27GA0000O6S000500SPY   0001425600Y
28844928XAK27GA0000SD001000
28845041A4K27GA00009TB000100DOG   0000597000Y
28845041A4K27GA00009UB000100DXD   0000499400Y
28845041A3K27G600004GS000100DDM   0000802600Y
28845131E4K27GA00009G00010000004AQ00006
28845133A4K27GA00009WB000100DRYS  0001066900Y
28845165AAK27GA0000SGS002000SPY   0001425800Y
28845292X9K27G60000MB005000
28845353X4K27GA00009A000200
28845375A4K27GA00009XS000200DIA   0001298900Y
28845374X6K27GA00005T002000
28845390A9K27G60000MJB005000QQQQ  0000495300Y
28845419XBK27GA0000FJ002000
28845419XAK27GA0000S1002000
28845448XCK27GA00002F002000
28845450XBK27GA0000FI002000
28845450XAK27GA0000R1002000
28845472X3K27G6000045002000
28845485X1K27GA000045002000
28845495X1K27GA000044002000
28845500X1K27GA000022002000
28845512X2K27G6000038002000
28845531X3K27G600004A002000
28845531A7K27GA000028B002000LMT   0000128300Y
28845540X1K27GA00001X002000
28845547X3K27G600004D002000
28845556X4K27GA000057002000
28845572A1K27GA000046B002000AFL   0000075700Y
28845588A1K27GA000047B002000ARO   0000293400Y
28845596X4K27GA00005F002000
28845607X5K27GA00002W002000
28845615A2K27G600003EB002000CAG   0000020200Y
28845621A2K27G600003FB002000BMY   0000019200Y
28845624X4K27GA00005Q002000
28845627X4K27GA00009S002000
28845642A3K27G600004HB002000CVS   0000044600Y
28845642A7K27GA000029B002000LMT   0000129100Y
28845660ACK27GA00002GB002000WYE   0000046700Y
28845671A5K27GA00002XB002000HMY   0000083900Y
28845681A5K27GA00002YB002000HNZ   0000047800Y
28845681A1K27GA000048B002000AFL   0000076500Y
28845691A1K27GA000049B002000ARO   0000294200Y
28845692A5K27GA00002ZB002000HOT   0000049000Y
28845709A4K27GA00009YB002000EIX   0000052800Y
28845726A5K27GA000030B002000HNZ   0000048600Y
28845740A6K27GA000061B002000JCI   0000034900Y
28845748A6K27GA000062B002000JBL   0000104000Y
28845763A6K27GA000063B002000JCI   0000035700Y
28845839X5K27GA00001F000100
28846044XAK27GA0000EW000500
28846044AAK27GA0000EWS000500SPY   0001425600Y
28846044XAK27GA0000F2000500
28846044AAK27GA0000F2B000500SPY   0001424900Y
28846044X4K27GA000062000200
28846044A4K27GA000062B000200DIA   0001298400Y
28846053XAK27GA0000RK000100
28846054AAK27GA0000SHB001000SDS   0000547700Y
28846054XBK27GA0000F9001000
28846054X3K27G600003Y000100
28846055AAK27GA0000SIB001000SDS   0000547600Y
28846055ABK27GA0000FUS001000SSO   0000765100Y
28846056XBK27GA0000F1001000
28846056ABK27GA0000FVB001000SSO   0000764000Y
28846056ABK27GA0000FWB001000SSO   0000764200Y
28846054X6K27GA00002A000500
28846054A6K27GA00002AS000500IWM   0000736700Y
28846057ABK27GA0000FXS000100UWM   0000543400Y
28846057ABK27GA0000FYB000100TWM   0000701000Y
28846057ABK27GA0000FZB000100TWM   0000701100Y
28846123XAK27GA0000EW000500
28846123AAK27GA0000EWS000500SPY   0001425500Y
28846152X9K27G60000MI005000
28846152X9K27G60000MJ005000
28846152A9K27G60000MKB005000QQQQ  0000495700Y
28846153A9K27G60000MLB005000QQQQ  0000495700Y
28846233X9K27G60000MK005000
28846242A9K27G60000MMB005000QQQQ  0000495300Y
28846277X6K27GA00005J002000
28846326X9K27G60000MM005000
28846326A9K27G60000MNB005000QQQQ  0000495700Y
28846376X9K27G60000MN005000
28846382A9K27G60000MOB005000QQQQ  0000495300Y
28846381A6K27GA000064B002000IWM   0000736400Y
28846408X7K27GA000028002000
28846409XAK27GA0000HG001000
28846413X7K27GA000029002000
28846413AAK27GA0000SJB000600SPY   0001419600Y
28846427XCK27GA00002G002000
28846467X1K27GA000048002000
28846471X6K27GA000064002000
28846480ABK27GA0000G0B002000UTX   0000084300Y
28846481XAK27GA0000FO002000
28846482ABK27GA0000G1B002000UTX   0000085100Y
28846488A6K27GA000065B002000IMCL  0000327900Y
28846514AAK27GA0000SKB002000SHLD  0000701900Y
28846516ACK27GA00002HB002000WYE   0000047100Y
28846538A1K27GA00004AB002000ABT   0000063000Y
28846552AAK27GA0000SLB002000SPLS  0000019800Y
28846560X2K27G600003B002000
28846565A1K27GA00004BB002000ABT   0000062100Y
28846587A1K27GA00004CB002000ANF   0000721000Y
28846598A3K27G600004IB002000CTSH  0000030700Y
28846598X1K27GA000046002000
28846607X9K27G60000MO005000
28846608A9K27G60000MPB005000QQQQ  0000495700Y
28846619A9K27G60000MQS002000QQQQ  0000496000Y
28846619A1K27GA00004DB002000ANF   0000720200Y
28846639A2K27G600003GB002000BBT   0000035700Y
28846645A3K27G600004JS000100DDM   0000802500Y
28846644A4K27GA00009ZB000100DXD   0000499500Y
28846647X2K27G600003D002000
28846658X3K27G600004F002000
28846662X3K27G600004H002000
28846671X4K27GA00006G002000
28846678A3K27G600004KB002000COH   0000037800Y
28846678X5K27GA00002Y002000
28846688X5K27GA00002Z002000
28846707A4K27GA0000A0B002000EAT   0000197600Y
28846709A3K27G600004LB002000CVS   0000046600Y
28846721A4K27GA0000A1B002000EIX   0000053400Y
28846721X4K27GA00009Y002000
28846732X4K27GA00006F002000
28846736X9K27G60000MP005000
28846742A9K27G60000MRB005000QQQQ  0000495300Y
28846743X9K27G60000ML005000
28846746X5K27GA000029002000
28846747A9K27G60000MSB005000QQQQ  0000495300Y
28846747X9K27G60000EP002000
28846747A9K27G60000EPB002000QQQQ  0000495400Y
28846757X5K27GA000030002000
28846782A4K27GA0000A2B002000DIS   0000328100Y
28846781A6K27GA000066B002000KFT   0000304000Y
28846802A7K27GA00002AB002000KMB   0000610800Y
28846802A4K27GA0000A3B002000EAT   0000198400Y
28846822X9K27G60000MS005000
28846822A9K27G60000MTB005000QQQQ  0000495700Y
28846823X9K27G60000MQ002000
28846824X6K27GA00005W000100
28846825A4K27GA0000A4B000100DIG   0001238700Y
28846825X4K27GA000031000100
28846826A6K27GA000067B000100IYE   0001532300Y
28846832X6K27GA000067000100
28846833X4K27GA0000A4000100
28846834A6K27GA000068B000100IYE   0001531500Y
28846843A4K27GA0000A5B000100DIG   0001237700Y
28846843X4K27GA00009Z000100
28846844X3K27G600004J000100
28846871A4K27GA0000A6B000100DXD   0000499500Y
28846872A3K27G600004MS000100DDM   0000802500Y
28846903X4K27GA0000A6000100
28846904X3K27G600004M000100
28846932A4K27GA0000A7B000100DXD   0000499500Y
28846932A3K27G600004NS000100DDM   0000802500Y
28846963X4K27GA0000A7000100
28846964X3K27G600004N000100
28847082A6K27GA000069S000100IYE   0001538500Y
28847083A4K27GA0000A8S000100DIG   0001243500Y
28847083X4K27GA00009N000100
28847350X3K27G6000042002000
28847393X2K27G600003F002000
28847396XBK27GA0000G0002000
28847417XAK27GA0000SK002000
28847426XAK27GA0000PU002000
28847431XCK27GA00002H002000
28847452XBK27GA0000G1002000
28847454X1K27GA00004A002000
28847457X2K27G600000R002000
28847457AAK27GA0000SMB002000SOHU  0000798100Y
28847477X3K27G600004L002000
28847477X1K27GA00004B002000
28847492X3K27G600003A002000
28847508X1K27GA000028002000
28847523X6K27GA000063002000
28847537A7K27GA00002BB002000LMT   0000135100Y
28847548A7K27GA00002CB002000LMT   0000134300Y
28847554ACK27GA00002IB002000WYE   0000049100Y
28847565X2K27G600000U002000
28847569A1K27GA00004EB002000AFL   0000079400Y
28847585X2K27G600003E002000
28847589A1K27GA00004FB002000AFL   0000080200Y
28847610A2K27G600003HB002000CAG   0000022300Y
28847621A2K27G600003IB002000BBT   0000035800Y
28847635A4K27GA0000A9B002000EIX   0000055600Y
28847647X4K27GA0000A1002000
28847661A3K27G600004OB002000COH   0000038000Y
28847663A4K27GA0000AAB002000ESI   0000616600Y
28847683A3K27G600004PB002000CVS   0000047000Y
28847696A5K27GA000031B002000HMY   0000084900Y
28847696A4K27GA0000ABB002000ESI   0000615800Y
28847706XAK27GA0000FE000500
28847706AAK27GA0000FEB000500SPY   0001424900Y
28847706XAK27GA0000R7001000
28847705X6K27GA000061002000
28847707AAK27GA0000SNS001000SPY   0001425500Y
28847707XAK27GA0000E4001000
28847707AAK27GA0000E4B001000SPY   0001425000Y
28847709A5K27GA000032B002000HNZ   0000050300Y
28847717XAK27GA0000RX001000
28847717AAK27GA0000SOB001000SPY   0001425100Y
28847719AAK27GA0000SPB001000SPY   0001425100Y
28847721A5K27GA000033B002000HOT   0000051600Y
28847723A4K27GA0000ACB000100DXD   0000499500Y
28847724A3K27G600004QS000100DDM   0000802500Y
28847761A5K27GA000034B002000HNZ   0000051100Y
28847763X4K27GA0000AC000100
28847764X3K27G600004Q000100
28847770A5K27GA000035B002000HOT   0000052400Y
28848086XAK27GA0000R3001000
28848091A4K27GA0000ADB000100DXD   0000499500Y
28848091A3K27G600004RS000100DDM   0000802500Y
28848101AAK27GA0000SQB001000SPY   0001425000Y
28848123X4K27GA0000AD000100
28848124X3K27G600004R000100
28848258A4K27GA0000AEB000100DRYS  0001066900Y
28848364X6K27GA000065002000
28848369X7K27GA00002B002000
28848369X7K27GA00002C002000
28848394XCK27GA00002I002000
28848402X7K27GA000027002000
28848428X9K27G60000LW002000
28848429A2K27G600003JB002000BMY   0000021000Y
28848431A3K27G600004SB002000CELG  0000469900Y
28848433ABK27GA0000G2B002000UTX   0000088300Y
28848468AAK27GA0000SRB002000SHLD  0000707000Y
28848467ACK27GA00002JB002000WYE   0000049500Y
28848468X1K27GA00004F002000
28848480X1K27GA00004E002000
28848502ABK27GA0000G3B002000UTX   0000089100Y
28848510AAK27GA0000SSB002000SNDK  0000222300Y
28848520A1K27GA00004GB002000ABT   0000065200Y
28848534A3K27G600004TS000100DDM   0000802500Y
28848533A4K27GA0000AFB000100DXD   0000499500Y
28848536X2K27G600003G002000
28848563X4K27GA0000AF000100
28848563X3K27G600004T000100
28848564X3K27G600004K002000
28848572A1K27GA00004HB002000ABT   0000066000Y
28848586A2K27G600003KB002000BA    0000852900Y
28848591X4K27GA0000A9002000
28848608X4K27GA00005Y002000
28848617X5K27GA000034002000
28848622A1K27GA00004IB002000APC   0000763100Y
28848624X5K27GA000035002000
28848638X3K27G600004P002000
28848639A2K27G600003LB002000BA    0000852100Y
28848651X4K27GA00005A002000
28848653A3K27G600004UB002000CVS   0000048900Y
28848660A2K27G600003MB002000CAG   0000022100Y
28848674A3K27G600004VB002000DD    0000455600Y
28848702X5K27GA000032002000
28848703A6K27GA00006AB002000JCI   0000038500Y
28848710X5K27GA000033002000
28848722A6K27GA00006BB002000JCP   0000413000Y
28848729A4K27GA0000AGB002000EIX   0000056200Y
28848938X5K27GA00001B000100
28849164XAK27GA0000QY003000
28849164XAK27GA0000QR002000
28849164XAK27GA0000QZ003000
28849164XAK27GA0000O2000500
28849164AAK27GA0000O2S000500SPY   0001425500Y
28849164XAK27GA0000K1001000
28849164AAK27GA0000K1S001000SPY   0001425500Y
28849164X4K27GA00003H000200
28849164A4K27GA00003HB000200DIA   0001298300Y
28849164X4K27GA000090000047
28849165AAK27GA0000STS003000SPY   0001425600Y
28849165AAK27GA0000SUS003000SPY   0001425600Y
28849169A4K27GA0000AHS000047DIA   0001298800Y
28849173A4K27GA0000AIB000100DXD   0000499500Y
28849174A3K27G600004WS000100DDM   0000802500Y
28849178X4K27GA00003H000200
28849178A4K27GA00003HB000200DIA   0001298600Y
28849355XAK27GA0000SR002000
28849391X3K27G600004I002000
28849416A6K27GA00006CB002000IMCL  0000331100Y
28849421XBK27GA0000G3002000
28849424XBK27GA0000G2002000
28849443XCK27GA00002J002000
28849446X1K27GA00004H002000
28849455X1K27GA00004G002000
28849467X2K27G600003C002000
28849474X2K27G600003I002000
28849489X2K27G600003A002000
28849493X2K27G6000037002000
28849511X3K27G600004O002000
28849514X3K27G600003E002000
28849514A7K27GA00002DB002000LMT   0000141100Y
28849514X4K27GA0000AG002000
28849518A7K27GA00002EB002000LMT   0000140300Y
28849528A7K27GA00002FB002000LPNT  0000194500Y
28849535ACK27GA00002KB002000WYE   0000051500Y
28849544X2K27G6000039002000
28849553A1K27GA00004JB002000AFL   0000083100Y
28849563X2K27G600003H002000
28849575A9K27G60000MUB002000PDLI  0000017400Y
28849575A3K27G600004XB002000CVS   0000049300Y
28849591A4K27GA0000AJB002000DIS   0000327400Y
28849621A1K27GA00004KB002000AFL   0000083900Y
28849623A5K27GA000036B002000HNZ   0000052900Y
28849627X3K27G600004U002000
28849641A5K27GA000037B002000HOT   0000054300Y
28849650A2K27G600003NB002000BBT   0000038500Y
28849656A6K27GA00006DB002000JCI   0000038700Y
28849671A3K27G600004YB002000COH   0000040700Y
28849671A7K27GA00002GB002000KMX   0000185800Y
28849683X5K27GA00001G000100
28849688A5K27GA000038S000100FXP   0000658300Y
28849693X5K27GA000038000100
28849695A5K27GA000039S000100FXP   0000658300Y
28849695A7K27GA00002HB002000LEH   0000416200Y
28849701A4K27GA0000AKB002000EIX   0000058400Y
28849703X5K27GA000039000100
28849740A4K27GA0000ALB002000ELN   0000227000Y
28849758A5K27GA00003AB002000HNZ   0000053700Y
28849769A5K27GA00003BB002000HOT   0000055100Y
28850379XAK27GA0000SL002000
28850388X9K27G60000MT005000
28850389X9K27G60000F4003200
28850389A9K27G60000F4S003200QQQQ  0000495800Y
28850390X4K27GA00003H000200
