28838246A3K27G600003NS000100DDM   0000802200Y
28838249X4K27GA00007C000200
28838249A4K27GA00007CB000200DIA   0001298100Y
28838250X4K27GA00008L000100
28838251X3K27G600003M000100
28838250X4K27GA00008K000100
28838254A4K27GA00008MS000100DOG   0000598500Y
28838254A4K27GA00008NS000100DXD   0000500400Y
28838254A3K27G600003OB000100DDM   0000800700Y
28838268A9K27G60000L7S002000QQQQ  0000495800Y
28838271A8K27G600001LS000500MZZ   0000494200Y
28838271A8K27G600001MB000100MVV   0000805800Y
28838293XAK27GA0000P1001000
28838294X8K27G600001H000500
28838294X8K27G600001G000100
28838294X8K27G600001I000100
28838294AAK27GA0000PPS001000SPY   0001425500Y
28838296A8K27G600001NS000100MVV   0000809200Y
28838316A8K27G600001OS000100MVV   0000809100Y
28838330XAK27GA0000EX000500
28838330AAK27GA0000EXB000500SPY   0001425000Y
28838330XAK27GA0000OH001000
28838332AAK27GA0000PQS001000SPY   0001425600Y
28838344XBK27GA0000DS001000
28838343XAK27GA0000P8001000
28838344X4K27GA00007C000200
28838344A4K27GA00007CB000200DIA   0001298400Y
28838345XAK27GA0000P3001000
28838345AAK27GA0000PRB001000SDS   0000547900Y
28838346ABK27GA0000E2S001000SSO   0000764800Y
28838347AAK27GA0000PSB001000SDS   0000547800Y
28838355XAK27GA0000PD001000
28838359X4K27GA00007C000200
28838359A4K27GA00007CB000200DIA   0001298100Y
28838394X4K27GA000043002000
28838397AAK27GA0000PTB002000SHLD  0000681400Y
28838397X7K27GA00001Y002000
28838400X2K27G600002J002000
28838404X7K27GA00001T002000
28838416X4K27GA000046002000
28838420A3K27G600003PB002000CTSH  0000023800Y
28838422X1K27GA00003Q002000
28838429X9K27G60000L7002000
28838433X2K27G600001A002000
28838432X7K27GA00001Z002000
28838440X2K27G600002L002000
28838443X6K27GA000043002000
28838450X3K27G600003H002000
28838452X9K27G60000EN002000
28838452A9K27G60000ENS002000QQQQ  0000496000Y
28838462X5K27GA00002D002000
28838469X5K27GA00002E002000
28838467XCK27GA000028002000
28838489AAK27GA0000PUB002000SNDK  0000219900Y
28838489ABK27GA0000E3B002000UTX   0000069100Y
28838499X9K27G60000IY002000
28838499X9K27G60000L5005000
28838499X9K27G60000F9003200
28838499A9K27G60000F9B003200QQQQ  0000495600Y
28838499X9K27G60000L6005000
28838500A9K27G60000L8B002000QQQQ  0000495400Y
28838501A9K27G60000L9S005000QQQQ  0000496100Y
28838502A9K27G60000LAS005000QQQQ  0000496100Y
28838505XAK27GA0000PP001000
28838507AAK27GA0000PVS001000SPY   0001425600Y
28838527X9K27G60000F9003200
28838527A9K27G60000F9B003200QQQQ  0000495100Y
28838528X9K27G60000L8002000
28838532X9K27G60000F9003200
28838532A9K27G60000F9B003200QQQQ  0000495600Y
28838533A9K27G60000LBB002000QQQQ  0000495400Y
28838540X1K27GA00003R002000
28838552ABK27GA0000E4B002000UTX   0000068300Y
28838558A1K27GA00003SB002000ABT   0000050700Y
28838565A9K27G60000LCB002000QQQQ  0000495400Y
28838565ACK27GA000029B002000WYE   0000037400Y
28838586A2K27G600002OB002000AXP   0000399500Y
28838588XAK27GA0000OP001000
28838589AAK27GA0000PWB000600SPY   0001425100Y
28838590AAK27GA0000PXS000100SH    0000619100Y
28838591ABK27GA0000E5B001000SSO   0000763900Y
28838591XBK27GA0000DY001000
28838593XBK27GA0000DZ001000
28838593ABK27GA0000E6B001000SSO   0000763700Y
28838600A2K27G600002PB002000BK    0000425200Y
28838610X2K27G600001G002000
28838618A2K27G600002QB002000CAG   0000016400Y
28838626X4K27GA00008D002000
28838628A1K27GA00003TB002000ABT   0000049900Y
28838642X9K27G60000LC002000
28838647X5K27GA00002G002000
28838653X5K27GA00002H002000
28838658A2K27G600002RB002000AXP   0000398700Y
28838667A3K27G600003QB002000CVS   0000037100Y
28838673A2K27G600002SB002000BBT   0000027300Y
28838707A3K27G600003RB002000COH   0000029000Y
28838710A5K27GA00002IB002000HUM   0000432300Y
28838731A4K27GA00008OB002000EIX   0000042200Y
28838740A9K27G60000LDB002000QQQQ  0000495400Y
28838888AAK27GA0000PYB000100SPY   0001424400Y
28838888XAK27GA0000NO000100
28838925X9K27G60000LD002000
28839083A9K27G60000LEB002000QQQQ  0000495400Y
28839084XAK27GA0000PJ002000
28839084XAK27GA0000FD000500
28839084AAK27GA0000FDB000500SPY   0001424600Y
28839084XAK27GA0000EX000500
28839084AAK27GA0000EXB000500SPY   0001424600Y
28839084XAK27GA0000O6000500
28839084AAK27GA0000O6S000500SPY   0001425200Y
28839093X4K27GA00008M000100
28839093X4K27GA00008N000100
28839094X3K27G600003O000100
28839094XBK27GA0000E6001000
28839176X9K27G60000LE002000
28839184X4K27GA00008J000047
28839188X9K27G60000F9003200
28839188A9K27G60000F9B003200QQQQ  0000495100Y
28839189X9K27G60000LB002000
28839193A4K27GA00008PS000047DIA   0001298500Y
28839195A4K27GA00008QB000100DXD   0000499700Y
28839364X6K27GA00004U002000
28839368A2K27G600002TB002000BMY   0000015500Y
28839389A4K27GA00008RB002000EMR   0000552100Y
28839405XAK27GA0000PT002000
28839439XBK27GA0000E3002000
28839439X9K27G60000IS002000
28839453A7K27GA000020B002000LMT   0000110300Y
28839483A7K27GA000021B002000LPNT  0000187800Y
28839494A4K27GA00008SB002000EMR   0000552900Y
28839496XBK27GA0000E4002000
28839503XCK27GA000029002000
28839518X1K27GA00003S002000
28839536X1K27GA00003T002000
28839542A7K27GA000022B002000LMT   0000111100Y
28839561A1K27GA00003UB002000AFL   0000064500Y
28839564X2K27G600000Q002000
28839581X2K27G600002N002000
28839584X2K27G600000T002000
28839592A2K27G600002UB002000BK    0000424400Y
28839598X2K27G6000021002000
28839603A2K27G600002VB002000CAG   0000016300Y
28839612A3K27G600003SB002000CVS   0000037500Y
28839619X4K27GA00008O002000
28839626X4K27GA00006O002000
28839633A5K27GA00002JB002000HNZ   0000040100Y
28839653A5K27GA00002KB002000HOT   0000041000Y
28839663X2K27G6000020002000
28839678ACK27GA00002AB002000WYE   0000039400Y
28839702X3K27G600003K002000
28839709A6K27GA000055B002000ITW   0000503400Y
28839715X3K27G600003Q002000
28839732A1K27GA00003VB002000AFL   0000065300Y
28839741X4K27GA00006M002000
28839748A2K27G600002WB002000CAT   0000815800Y
28839764A4K27GA00008TB002000EIX   0000044400Y
28839775A5K27GA00002LB002000HNZ   0000040900Y
28839785A5K27GA00002MB002000HOT   0000041800Y
28840160XAK27GA0000PQ001000
28840160AAK27GA0000PZS001000SPY   0001425200Y
28840161XAK27GA0000FD000500
28840161AAK27GA0000FDB000500SPY   0001425000Y
28840161XAK27GA0000O6000500
28840161AAK27GA0000O6S000500SPY   0001425600Y
28840161XAK27GA0000EX000500
28840161AAK27GA0000EXB000500SPY   0001425000Y
28840162XAK27GA0000PZ001000
28840163ABK27GA0000E7B001000SSO   0000763700Y
28840163AAK27GA0000Q0S001000SPY   0001425600Y
28840172X4K27GA00008P000047
28840173A4K27GA00008US000047DIA   0001298800Y
28840174A4K27GA00008VS000100DOG   0000598500Y
28840174A4K27GA00008WS000100DXD   0000500400Y
28840174X4K27GA00008Q000100
28840176A3K27G600003TB000100DDM   0000800700Y
28840176X6K27GA000026000500
28840176A6K27GA000026S000500IWM   0000736900Y
28840176A6K27GA000056B002000IWM   0000736200Y
28840180X6K27GA00003H000500
28840180A6K27GA00003HB000500IWM   0000736400Y
28840183ABK27GA0000E8B000100UWM   0000542300Y
28840183ABK27GA0000E9S000100TWM   0000702200Y
28840183XBK27GA0000E1000100
28840184X6K27GA00003H000500
28840184A6K27GA00003HB000500IWM   0000736000Y
28840188XBK27GA0000E8000100
28840188XBK27GA0000E9000100
28840188XBK27GA00008X000100
28840188XBK27GA00008Y000100
28840188XBK27GA00008Z000100
28840187X6K27GA00003H000500
28840187A6K27GA00003HB000500IWM   0000736400Y
28840190ABK27GA0000EAB000100UWM   0000542300Y
28840190ABK27GA0000EBS000100TWM   0000702200Y
28840188A6K27GA000057B000100IWM   0000735900Y
28840188A6K27GA000058S000100IWM   0000737000Y
28840191X8K27G600001L000500
28840191X8K27G600001M000100
28840189X6K27GA000057000100
28840190X6K27GA00003H000500
28840190A6K27GA00003HB000500IWM   0000736000Y
28840193A8K27G600001PS000500MZZ   0000494200Y
28840193A8K27G600001QB000100MVV   0000805700Y
28840194X6K27GA000058000100
28840195X6K27GA00003H000500
28840195A6K27GA00003HB000500IWM   0000736400Y
28840196AAK27GA0000Q1B002000SPY   0001425100Y
28840196XAK27GA0000M6001000
28840197XAK27GA0000PB001000
28840197XAK27GA0000E5001000
28840197AAK27GA0000E5S001000SPY   0001425600Y
28840197XAK27GA0000LN003000
28840197XAK27GA0000LD003000
28840198X9K27G60000G0002000
28840198A9K27G60000G0B002000QQQQ  0000495600Y
28840198X9K27G60000G9002000
28840198A9K27G60000G9S002000QQQQ  0000496200Y
28840197XAK27GA0000FG000500
28840197AAK27GA0000FGB000500SPY   0001425100Y
28840197AAK27GA0000Q2B002000SPY   0001425100Y
28840198XAK27GA0000O5000500
28840198XAK27GA0000O8000500
28840198AAK27GA0000O8S000500SPY   0001425700Y
28840198X4K27GA00007C000200
28840198A4K27GA00007CB000200DIA   0001298500Y
28840198X4K27GA00006X000200
28840198X4K27GA00008H000200
28840198XAK27GA0000O1000500
28840198XAK27GA0000NY000500
28840198AAK27GA0000NYS000500SPY   0001425800Y
28840198XAK27GA0000E6001000
28840198AAK27GA0000E6S001000SPY   0001425700Y
28840198XAK27GA0000EB001000
28840198AAK27GA0000EBB001000SPY   0001425100Y
28840198XAK27GA0000LT001000
28840198XAK27GA0000LE003000
28840198XAK27GA0000NZ000500
28840198AAK27GA0000NZS000500SPY   0001425700Y
28840198XAK27GA0000F7000500
28840198AAK27GA0000F7B000500SPY   0001425100Y
28840198XAK27GA0000LM003000
28840198AAK27GA0000Q3B003000SPY   0001425100Y
28840198XAK27GA0000J2002000
28840197X6K27GA00003H000500
28840197A6K27GA00003HB000500IWM   0000736000Y
28840198X4K27GA00008U000047
28840198X4K27GA000062000200
28840198A4K27GA000062B000200DIA   0001298400Y
28840199X9K27G60000IP001000
28840199A9K27G60000LFB002000QQQQ  0000495400Y
28840199X9K27G60000F9003200
28840199A9K27G60000F9B003200QQQQ  0000495600Y
28840199X4K27GA00007D000100
28840199A4K27GA00008XS000100DXD   0000500300Y
28840199A3K27G600003UB000100DDM   0000800800Y
28840199AAK27GA0000Q4S003000SPY   0001426000Y
28840199AAK27GA0000Q5B003000SPY   0001425100Y
28840199AAK27GA0000Q6B002000SPY   0001425100Y
28840200X9K27G60000IO001000
28840200AAK27GA0000Q7S001000SPY   0001425700Y
28840200AAK27GA0000Q8S000500SPY   0001425600Y
28840200A4K27GA00008YS000200DIA   0001298900Y
28840200XBK27GA0000E2001000
28840199X6K27GA00003H000500
28840199A6K27GA00003HB000500IWM   0000736400Y
28840200XAK27GA0000F5000500
28840200AAK27GA0000F5B000500SPY   0001425100Y
28840200AAK27GA0000Q9S003000SPY   0001426000Y
28840200XAK27GA0000LG001000
28840201XBK27GA0000EA000100
28840200XAK27GA0000FI000500
28840200AAK27GA0000FIB000500SPY   0001425100Y
28840201XBK27GA0000EB000100
28840201AAK27GA0000QAS001000SDS   0000549200Y
28840201A9K27G60000LGS001000QQQQ  0000496100Y
28840201A9K27G60000LHS001000QQQQ  0000496000Y
28840201XBK27GA0000E5001000
28840201ABK27GA0000ECB001000SSO   0000764000Y
28840201AAK27GA0000QBS000500SPY   0001425800Y
28840202AAK27GA0000QCS001000SPY   0001425800Y
28840202ABK27GA0000EDS001000SSO   0000764900Y
28840202XAK27GA0000E8001000
28840202AAK27GA0000E8B001000SPY   0001425100Y
28840202XAK27GA0000LU000900
28840202AAK27GA0000QDB000200SPY   0001425100Y
28840203ABK27GA0000EEB000100UWM   0000542300Y
28840201A6K27GA000059B000100IWM   0000735900Y
28840203ABK27GA0000EFS000100TWM   0000702200Y
28840201X6K27GA000059000100
28840203ABK27GA0000EGB001000SSO   0000763800Y
28840203XBK27GA0000E7001000
28840203A4K27GA00008ZS000200DIA   0001299000Y
28840202X6K27GA00003H000500
28840202A6K27GA00003HB000500IWM   0000736000Y
28840204XAK27GA0000OI000100
28840204XAK27GA0000PR001000
28840204X3K27G600003N000100
28840204X4K27GA00006R000100
28840204XAK27GA0000E9001000
28840204AAK27GA0000E9S001000SPY   0001425800Y
28840205XAK27GA0000LK000900
28840205AAK27GA0000QES000100SH    0000619000Y
28840206XBK27GA0000EC001000
28840205AAK27GA0000QFS001000SDS   0000549100Y
28840204X6K27GA00003H000500
28840204A6K27GA00003HB000500IWM   0000736400Y
28840206ABK27GA0000EHB001000SSO   0000764100Y
28840206XAK27GA0000E7001000
28840206AAK27GA0000E7B001000SPY   0001425100Y
28840206XBK27GA0000EF000100
28840206XBK27GA0000EE000100
28840206AAK27GA0000QGB000200SPY   0001425100Y
28840206A4K27GA000090S000047DIA   0001299100Y
28840206A4K27GA000091B000100DXD   0000499300Y
28840208ABK27GA0000EIS000100TWM   0000702200Y
28840206X6K27GA00003H000500
28840206A6K27GA00003HB000500IWM   0000736000Y
28840208ABK27GA0000EJB000100UWM   0000542300Y
28840207A6K27GA00005AB000100IWM   0000735900Y
28840207X6K27GA00005A000100
28840209X9K27G60000LG001000
28840209X9K27G60000LH001000
28840228XBK27GA0000EJ000100
28840228XBK27GA0000EI000100
28840230A9K27G60000LIB002000QQQQ  0000495400Y
28840230ABK27GA0000EKB000100UWM   0000542300Y
28840230ABK27GA0000ELS000100TWM   0000702200Y
28840229X6K27GA000042002000
28840230X6K27GA000028000500
28840230A6K27GA000028S000500IWM   0000737000Y
28840232A8K27G600001RS000500MZZ   0000494100Y
28840232A8K27G600001SB000100MVV   0000805900Y
28840232X8K27G600001F000500
28840232X8K27G600001O000100
28840232X8K27G600001N000100
28840232X6K27GA000028000500
28840232A6K27GA000028S000500IWM   0000736600Y
28840234A8K27G600001TB000500MZZ   0000491600Y
28840234A8K27G600001US000100MVV   0000809300Y
28840234XBK27GA0000ED001000
28840234XAK27GA0000QC001000
28840234A9K27G60000LJS001000QID   0000382100Y
28840234A9K27G60000LKB001000QLD   0000888800Y
28840234X9K27G60000KK001000
28840234X4K27GA000065000100
28840234X4K27GA00008Y000200
28840235X3K27G600002A000100
28840235AAK27GA0000QHS001000SPY   0001425400Y
28840236ABK27GA0000EMS001000SSO   0000765000Y
28840237A3K27G600003VS000100DDM   0000802500Y
28840237A9K27G60000LLB001000QQQQ  0000495200Y
28840238XAK27GA0000PV001000
28840238XBK27GA0000EK000100
28840238XBK27GA0000EL000100
28840239X9K27G60000LL001000
28840239A4K27GA000092S000200DIA   0001298900Y
28840240ABK27GA0000ENB000100UWM   0000542300Y
28840240ABK27GA0000EOS000100TWM   0000702200Y
28840243A9K27G60000LMB001000QLD   0000888900Y
28840243X9K27G60000LK001000
28840244X3K27G600003V000100
28840244A9K27G60000LNS000100QID   0000382300Y
28840244X4K27GA000063000100
28840245A9K27G60000LOB001000QQQQ  0000495200Y
28840245XAK27GA0000PS001000
28840244A6K27GA00005BB002000IWM   0000736300Y
28840244X6K27GA000047002000
28840245A4K27GA000093B000100DXD   0000499200Y
28840246A3K27G600003WS000100DDM   0000802600Y
28840249X9K27G60000LO001000
28840250X4K27GA00003H000200
28840250A4K27GA00003HB000200DIA   0001298600Y
28840252A4K27GA000094S000100DOG   0000598400Y
28840252A4K27GA000095S000100DXD   0000500200Y
28840252X4K27GA000077000100
28840253A3K27G600003XB000100DDM   0000801000Y
28840253X3K27G600002T000100
28840258XAK27GA0000Q3003000
28840258AAK27GA0000Q3B003000SPY   0001425200Y
28840258XAK27GA0000Q5003000
28840258AAK27GA0000Q5B003000SPY   0001425200Y
28840258XAK27GA0000Q6002000
28840258AAK27GA0000Q6B002000SPY   0001425200Y
28840258XAK27GA0000F5000500
28840258AAK27GA0000F5B000500SPY   0001425200Y
28840258XAK27GA0000FI000500
28840258AAK27GA0000FIB000500SPY   0001425200Y
28840258XAK27GA0000E8001000
28840258AAK27GA0000E8B001000SPY   0001425200Y
28840258XAK27GA0000QD000200
28840258AAK27GA0000QDB000200SPY   0001425200Y
28840258XAK27GA0000E7001000
28840258AAK27GA0000E7B001000SPY   0001425200Y
28840258XAK27GA0000QG000200
28840258AAK27GA0000QGB000200SPY   0001425200Y
28840258X6K27GA000028000500
28840258A6K27GA000028S000500IWM   0000737000Y
28840284XAK27GA0000OC001000
28840284AAK27GA0000QIS001000SPY   0001425700Y
28840285XBK27GA0000EG001000
28840286X8K27G600001U000100
28840285ABK27GA0000EPB001000SSO   0000763900Y
28840286AAK27GA0000QJS001000SPY   0001425700Y
28840288A8K27G600001VS000100MVV   0000809400Y
28840293ABK27GA0000EQB000100TWM   0000701000Y
28840300A8K27G600001WS000500MZZ   0000494000Y
28840300A8K27G600001XB000100MVV   0000806100Y
28840308XBK27GA00009Z000100
28840308ABK27GA0000ERB000100UWM   0000542400Y
28840308ABK27GA0000ESS000100TWM   0000702000Y
28840308XBK27GA0000EO000100
28840324X9K27G60000J8002000
28840324X9K27G60000F4003200
28840324A9K27G60000F4S003200QQQQ  0000496300Y
28840324X9K27G60000IH005000
28840324X9K27G60000IG005000
28840324A9K27G60000LPB005000QQQQ  0000495700Y
28840324A9K27G60000LQB005000QQQQ  0000495700Y
28840325A9K27G60000LRB002000QQQQ  0000495700Y
28840325X9K27G60000EP002000
28840325A9K27G60000EPB002000QQQQ  0000495700Y
28840325A9K27G60000LSB001000QLD   0000888800Y
28840331XAK27GA0000QJ001000
28840359X3K27G6000036002000
28840363XAK27GA0000QI001000
28840363AAK27GA0000QKS001000SPY   0001425800Y
28840365AAK27GA0000QLS001000SPY   0001425800Y
28840377X4K27GA000062000200
28840377A4K27GA000062B000200DIA   0001298700Y
28840379A3K27G600003YB000100DDM   0000801100Y
28840379X3K27G600003L000100
28840379XAK27GA0000NQ000100
28840379AAK27GA0000QMB001000SDS   0000547500Y
28840379AAK27GA0000QNB001000SDS   0000547600Y
28840379AAK27GA0000QOB001000SDS   0000547700Y
28840381AAK27GA0000QPS000100SPY   0001426900Y
28840389A6K27GA00005CB002000IMCL  0000321400Y
28840395X5K27GA00001I002000
28840421XAK27GA0000OF002000
28840424X7K27GA000022002000
28840424X7K27GA000020002000
28840435XCK27GA00002A002000
28840437X9K27G60000LP005000
28840437X9K27G60000LQ005000
28840442A9K27G60000LTB005000QQQQ  0000495300Y
28840442A9K27G60000LUB005000QQQQ  0000495300Y
28840449X9K27G60000F4003200
28840449A9K27G60000F4S003200QQQQ  0000495800Y
28840449X9K27G60000EP002000
28840449A9K27G60000EPB002000QQQQ  0000495400Y
28840458X9K27G60000LR002000
28840460X9K27G60000LS001000
28840462A9K27G60000LVB001000QQQQ  0000495200Y
28840467X1K27GA00003V002000
28840467AAK27GA0000QQB002000SHLD  0000686500Y
28840469X9K27G60000LV001000
28840481ABK27GA0000ETB002000UTX   0000072300Y
28840489ABK27GA0000EUB002000UTX   0000073100Y
28840499A9K27G60000LWB002000PDLI  0000015000Y
28840507X1K27GA00003U002000
28840524X9K27G60000LT005000
28840524X9K27G60000F4003200
28840524A9K27G60000F4S003200QQQQ  0000496300Y
28840524X9K27G60000LU005000
28840524A9K27G60000LXB002000QQQQ  0000495700Y
28840525A9K27G60000LYB005000QQQQ  0000495700Y
28840525A9K27G60000LZB005000QQQQ  0000495700Y
28840526A9K27G60000M0B001000QLD   0000888800Y
28840526X9K27G60000EP002000
28840526A9K27G60000EPB002000QQQQ  0000495700Y
28840542ACK27GA00002BB002000WYE   0000039800Y
28840546A1K27GA00003WB002000ABT   0000053800Y
28840548XBK27GA000074000100
28840548XBK27GA000075000100
28840546A6K27GA00005DS002000IWM   0000737000Y
28840548A6K27GA00005ES000100IWM   0000737100Y
28840550ABK27GA0000EVB000100TWM   0000700900Y
28840549X6K27GA00003H000500
28840549A6K27GA00005FB000500IWM   0000736500Y
28840554X6K27GA00005E000100
28840555X6K27GA000027000500
28840555A6K27GA000027B000500IWM   0000736400Y
28840574X2K27G600002S002000
28840574A1K27GA00003XB002000ABT   0000053000Y
28840578A2K27G600002XB002000AZN   0000417500Y
28840584A9K27G60000M1B002000QQQQ  0000495500Y
28840584X9K27G60000JC002000
28840584X9K27G60000JD002000
28840597X2K27G600002Q002000
28840602A2K27G600002YB002000BBT   0000030000Y
28840614A2K27G600002ZB002000BNI   0001058500Y
28840624E4K27GA00006Q000009000N4AQ00004
28840629X4K27GA00008T002000
28840642X4K27GA00008G000100
28840647X2K27G600001M002000
28840648A4K27GA000096B000100DRYS  0001068000Y
28840653A3K27G600003ZB002000COH   0000031800Y
28840654X3K27G600003R002000
28840668X4K27GA00006Q000091
28840669X3K27G600003S002000
28840679X5K27GA00002L002000
28840693A2K27G6000030B002000AZN   0000416700Y
28840693X5K27GA00002M002000
28840703A3K27G6000040B002000CVS   0000039500Y
28840708A2K27G6000031B002000BNI   0001057700Y
28840714X5K27GA00002J002000
28840725X5K27GA00002K002000
28840726A4K27GA000097B002000EIX   0000045000Y
28840726A4K27GA000098B002000FCX   0001224300Y
28840754A4K27GA000099B002000FCX   0001223500Y
28840773A6K27GA00005GB002000IWN   0000663500Y
28840932X9K27G60000EQ002000
28840932A9K27G60000EQS002000QQQQ  0000496100Y
28841147XAK27GA0000O2000500
28841147AAK27GA0000O2S000500SPY   0001425900Y
28841147XAK27GA0000QH001000
28841147AAK27GA0000QRB002000SPY   0001425300Y
28841147XAK27GA0000F2000500
28841147AAK27GA0000F2B000500SPY   0001425300Y
28841148XAK27GA0000L8001000
28841149XAK27GA0000LB001000
28841149XBK27GA0000EM001000
28841149AAK27GA0000QSS001000SPY   0001425800Y
28841150XAK27GA0000QM001000
28841151AAK27GA0000QTB001000SDS   0000547700Y
28841151ABK27GA0000EWS001000SSO   0000765100Y
28841152AAK27GA0000QUB001000SDS   0000547500Y
28841153XAK27GA0000QU001000
28841153XAK27GA0000LA000100
28841155AAK27GA0000QVB001000SDS   0000547500Y
28841155XAK27GA0000QO001000
28841157AAK27GA0000QWB001000SDS   0000547400Y
28841161X4K27GA000092000200
28841163A4K27GA00009AS000200DIA   0001299200Y
28841163AAK27GA0000QXB001000SPY   0001425200Y
28841163XAK27GA0000PM002000
28841165XAK27GA0000KV003000
28841165XAK27GA0000KW003000
28841165X9K27G60000G1002000
28841165A9K27G60000G1S002000QQQQ  0000496300Y
28841168AAK27GA0000QYS003000SPY   0001426200Y
28841168AAK27GA0000QZS003000SPY   0001426200Y
28841195X4K27GA00007C000200
28841195A4K27GA00007CB000200DIA   0001298800Y
28841197A4K27GA00009BS000100DOG   0000598300Y
28841197X4K27GA00006W000100
28841197A4K27GA00009CS000100DXD   0000500100Y
28841198X3K27G600003T000100
28841198A3K27G6000041B000100DDM   0000801200Y
28841301AAK27GA0000R0S001000SDS   0000549000Y
28841301XBK27GA0000EH001000
28841301ABK27GA0000EXB001000SSO   0000764200Y
28841306X4K27GA00008Z000200
28841312A4K27GA00009DS000200DIA   0001299300Y
28841323X9K27G60000I1002000
28841323X9K27G60000I0005000
28841323X9K27G60000HY005000
28841324X9K27G60000GI002000
28841334A9K27G60000M2S005000QQQQ  0000496200Y
28841334A9K27G60000M3S005000QQQQ  0000496200Y
28841359A3K27G6000042B002000CELG  0000467400Y
28841386X2K27G600002T002000
28841426XAK27GA0000QQ002000
28841431XBK27GA0000ET002000
28841431XBK27GA0000EU002000
28841440X3K27G600003P002000
28841449XCK27GA00002B002000
28841457X1K27GA00003W002000
28841467X1K27GA00003X002000
28841468AAK27GA0000R1B002000SPLS  0000016600Y
28841471X3K27G6000040002000
28841475XBK27GA0000EP001000
28841476ABK27GA0000EYB001000SSO   0000764000Y
28841495A7K27GA000023B002000LMT   0000117100Y
28841498X2K27G600002V002000
28841522ACK27GA00002CB002000WYE   0000041800Y
28841543A5K27GA00002NB002000GM    0000173400Y
28841552X4K27GA000097002000
28841562A7K27GA000024B002000LMT   0000116300Y
28841576A1K27GA00003YB002000AFL   0000069100Y
28841588A1K27GA00003ZB002000AFL   0000068300Y
28841601A2K27G6000032B002000BBT   0000030100Y
28841609A2K27G6000033B002000CAG   0000018400Y
28841633A2K27G6000034B002000CAT   0000815100Y
28841639A4K27GA00009EB002000EIX   0000047200Y
28841648A3K27G6000043B002000COH   0000032000Y
28841661A3K27G6000044B002000CVS   0000039900Y
28841667A5K27GA00002OB002000HNZ   0000043500Y
28841678A5K27GA00002PB002000HNZ   0000042700Y
28841691A5K27GA00002QB002000HOT   0000043600Y
28841691A5K27GA00002RB002000HOT   0000044400Y
28841707A6K27GA00005HB002000JBL   0000103100Y
28841710A6K27GA00005IB002000IP    0000260800Y
28841741X4K27GA000096000100
28841741X4K27GA00008E000100
28842061XAK27GA0000FE000500
28842061AAK27GA0000FEB000500SPY   0001425300Y
28842088A4K27GA00009FB000100DRYS  0001068800Y
28842088A4K27GA00009GB000100DRYS  0001068800Y
28842132X9K27G60000M1002000
28842386X6K27GA00005C002000
28842391X7K27GA000024002000
28842414X1K27GA00003Z002000
28842414AAK27GA0000R2B002000SHLD  0000691600Y
28842417X5K27GA00001J002000
28842428X2K27G600002K002000
28842441X3K27G6000044002000
28842445X5K27GA00002P002000
28842445X5K27GA00002Q002000
28842456X7K27GA000023002000
28842466XCK27GA00002C002000
28842469A3K27G6000045B002000CTSH  0000027300Y
28842476X1K27GA00003Y002000
28842482ABK27GA0000EZB002000UTX   0000076300Y
28842485X2K27G600002Y002000
28842503X2K27G600002M002000
28842523X3K27G600003Z002000
28842523ACK27GA00002DB002000WYE   0000042200Y
28842529X4K27GA00009E002000
28842531XAK27GA0000K1001000
28842531AAK27GA0000K1S001000SPY   0001425900Y
28842535X5K27GA00002O002000
28842560X5K27GA00002R002000
28842560A1K27GA000040B002000ABT   0000056000Y
28842561A2K27G6000035B002000BMY   0000017400Y
28842569XAK27GA0000E4001000
28842569AAK27GA0000E4B001000SPY   0001425400Y
28842570XAK27GA0000EW000500
28842570AAK27GA0000EWS000500SPY   0001425900Y
28842574X9K27G60000G8002000
28842574A9K27G60000G8B002000QQQQ  0000495700Y
28842574XAK27GA0000Q2002000
28842574AAK27GA0000Q2B002000SPY   0001425400Y
28842574XAK27GA0000EX000500
28842574AAK27GA0000EXB000500SPY   0001425400Y
28842574XAK27GA0000O6000500
28842574AAK27GA0000O6S000500SPY   0001426000Y
28842574XAK27GA0000PI001000
28842574XAK27GA0000PG000600
28842574XAK27GA0000Q8000500
28842574AAK27GA0000Q8S000500SPY   0001426000Y
28842574AAK27GA0000R3B001000SPY   0001425400Y
28842574XAK27GA0000PO003000
28842574XAK27GA0000IU003000
28842574XAK27GA0000FD000500
28842574AAK27GA0000FDB000500SPY   0001425400Y
28842574XAK27GA0000E5001000
28842574AAK27GA0000E5S001000SPY   0001426000Y
28842575XAK27GA0000IT003000
28842575XAK27GA0000PN003000
28842575AAK27GA0000R4B003000SPY   0001425400Y
28842575XAK27GA0000QL001000
28842575AAK27GA0000R5B003000SPY   0001425400Y
28842575XAK27GA0000QK001000
28842575AAK27GA0000R6B002000SPY   0001425300Y
28842575XAK27GA0000Q1001000
28842576AAK27GA0000R7S001000SPY   0001425900Y
28842576AAK27GA0000R8S003000SPY   0001426400Y
28842576AAK27GA0000R9S003000SPY   0001426400Y
28842577AAK27GA0000RAS001000SPY   0001425900Y
28842577AAK27GA0000RBS001000SPY   0001425900Y
28842584XBK27GA0000EW001000
28842584XAK27GA0000IW001000
28842585ABK27GA0000F0B002000UTX   0000077100Y
28842585XAK27GA0000QW001000
28842586ABK27GA0000F1S001000SSO   0000765200Y
28842586XAK27GA0000QV001000
28842586A6K27GA00005JB002000IWM   0000736400Y
28842586X6K27GA00002O002000
28842588AAK27GA0000RCB001000SDS   0000547500Y
28842588AAK27GA0000RDB001000SDS   0000547400Y
28842593X9K27G60000F7003200
28842593A9K27G60000F7B003200QQQQ  0000495700Y
28842594A9K27G60000M4B004000QQQQ  0000495500Y
28842595XAK27GA0000QN001000
28842602A1K27GA000041B002000ABT   0000056900Y
28842605A2K27G6000036B002000CAG   0000018200Y
28842613X4K27GA00004O000100
28842613X4K27GA00004P000100
28842614X3K27G600003W000100
28842616A3K27G6000046S000100DDM   0000802700Y
28842615A4K27GA00009HB000100DOG   0000596900Y
28842615A4K27GA00009IB000100DXD   0000499100Y
28842618X6K27GA00002A000500
28842618A6K27GA00002AS000500IWM   0000737100Y
28842621A3K27G6000047B002000CVS   0000041900Y
28842621A4K27GA00009JB002000EIX   0000047800Y
28842622XAK27GA0000RA001000
28842622XAK27GA0000RB001000
28842621X6K27GA00002C000500
28842621A6K27GA00002CB000500IWM   0000736600Y
28842624XBK27GA0000BE000100
28842623X6K27GA00002W002000
28842624XAK27GA0000QT001000
28842624ABK27GA0000F2B000100UWM   0000542500Y
28842625XBK27GA0000ES000100
28842625ABK27GA0000F3S000100TWM   0000701800Y
28842624AAK27GA0000RES001000SPY   0001426000Y
28842624AAK27GA0000RFS001000SPY   0001426000Y
28842625X6K27GA00002C000500
28842625A6K27GA00002CB000500IWM   0000736200Y
28842626AAK27GA0000RGB001000SDS   0000547600Y
28842626X6K27GA00002C000500
28842626A6K27GA00002CB000500IWM   0000736600Y
28842628XBK27GA00006S000100
28842628XBK27GA0000EQ000100
28842628XBK27GA000023000100
28842627A6K27GA00005KS002000IWM   0000737100Y
28842630ABK27GA0000F4S000100UWM   0000543500Y
28842630ABK27GA0000F5B000100TWM   0000700700Y
28842630ABK27GA0000F6B000100TWM   0000700800Y
28842631A6K27GA00005LB002000IR    0000432300Y
28842633AAK27GA0000RHS000100SH    0000618900Y
28842634ABK27GA0000F7B001000SSO   0000764300Y
28842634XBK27GA0000EX001000
28842635X6K27GA00002C000500
28842635A6K27GA00002CB000500IWM   0000736200Y
28842637X6K27GA00002C000500
28842637A6K27GA00002CB000500IWM   0000736600Y
28842647X6K27GA00002C000500
28842647A6K27GA00002CB000500IWM   0000736200Y
28842650A6K27GA00005MB002000IRF   0000217100Y
28842656A8K27G600001YS000500MZZ   0000493900Y
28842656X8K27G600001B000100
28842656A8K27G600001ZB000100MVV   0000806200Y
28842661A6K27GA00005NB002000JCI   0000032000Y
28842670X6K27GA00002C000500
28842670A6K27GA00002CB000500IWM   0000736600Y
28842674A6K27GA00005OB002000ITW   0000504200Y
28842693A6K27GA00005PB002000IWN   0000664400Y
28842706XAK27GA0000R6001000
28842713XAK27GA0000RH000100
28842714XBK27GA0000F7001000
28842715ABK27GA0000F8B001000SSO   0000764200Y
28842716AAK27GA0000RIB001000SPY   0001425300Y
28842737X8K27G600001C000500
28842737A8K27G6000020S000500MZZ   0000493800Y
28842738A8K27G6000021B000100MVV   0000806300Y
28842738X8K27G600001Q000100
28842739X8K27G600001P000500
28842769X6K27GA00005D002000
28842774XAK27GA0000PW000600
28842774XAK27GA0000EB001000
28842774AAK27GA0000EBB001000SPY   0001425500Y
28842775AAK27GA0000RJB001000SPY   0001425500Y
28842776AAK27GA0000RKS000100SH    0000618900Y
28842776XBK27GA0000F8001000
28842776ABK27GA0000F9B001000SSO   0000764300Y
28842778XBK27GA0000EY001000
28842778ABK27GA0000FAB001000SSO   0000764100Y
28842781X8K27G600001T000500
28842781X8K27G600001V000100
28842782A8K27G6000022B000500MZZ   0000491400Y
28842783A8K27G6000023S000100MVV   0000809600Y
28842820A8K27G6000024B000500MZZ   0000491500Y
28842820A8K27G6000025S000100MVV   0000809500Y
28842822XAK27GA0000RJ001000
28842822XAK27GA0000R8003000
28842822XAK27GA0000R5003000
28842822XAK27GA0000Q8000500
28842822AAK27GA0000Q8S000500SPY   0001425600Y
28842822XAK27GA0000EB001000
28842822AAK27GA0000EBB001000SPY   0001425100Y
28842822AAK27GA0000RLS003000SPY   0001425700Y
28842822XAK27GA0000R9003000
28842822XAK27GA0000R4003000
28842822AAK27GA0000RMS003000SPY   0001425700Y
28842822XAK27GA0000RI001000
28842823AAK27GA0000RNB001000SPY   0001425100Y
28842823AAK27GA0000ROB003000SPY   0001424700Y
28842825AAK27GA0000RPB003000SPY   0001424700Y
28842832X4K27GA00009D000200
28842836A4K27GA00009KS000200DIA   0001299000Y
28842839A6K27GA00005QS002000IWM   0000737000Y
28842841X9K27G60000M4004000
28842845XAK27GA0000RM003000
28842845XAK27GA0000RP003000
28842846XAK27GA0000RO003000
28842846XAK27GA0000RL003000
28842846AAK27GA0000RQB003000SPY   0001425400Y
28842846AAK27GA0000RRB003000SPY   0001425400Y
28842847XAK27GA0000Q1001000
28842848AAK27GA0000RSS003000SPY   0001425800Y
28842848AAK27GA0000RTS003000SPY   0001425800Y
28842858X6K27GA00002C000500
28842858A6K27GA00002CB000500IWM   0000736200Y
28842862A9K27G60000M5S002000QQQQ  0000496000Y
28842868XBK27GA0000F2000100
28842868XBK27GA0000F3000100
28842870ABK27GA0000FBS000100TWM   0000702000Y
28842869X6K27GA00002C000500
28842869A6K27GA00002CB000500IWM   0000736600Y
28842872ABK27GA0000FCB000100UWM   0000542500Y
28842872XBK27GA0000FB000100
28842872ABK27GA0000FDS000100TWM   0000701800Y
28842876X6K27GA00002C000500
28842876A6K27GA00002CB000500IWM   0000736200Y
28842881X8K27G6000022000500
28842881X8K27G6000024000500
28842881X8K27G6000023000100
28842881X8K27G6000025000100
28842883A8K27G6000026B000500MZZ   0000491400Y
28842883A8K27G6000027S000100MVV   0000809600Y
28842885X6K27GA00002C000500
28842885A6K27GA00002CB000500IWM   0000736600Y
28842898A8K27G6000028B000500MZZ   0000491600Y
28842898A8K27G6000029S000100MVV   0000809400Y
28842927X6K27GA00005Q002000
28842965X8K27G600001Y000500
28842965X8K27G6000020000500
28842965X8K27G600001W000500
28842965X8K27G600001R000500
28842965X8K27G600001X000100
28842965X8K27G600001S000100
28842965X8K27G6000021000100
28842965X8K27G600001Z000100
28842967A8K27G600002AS000500MZZ   0000493900Y
28842967A8K27G600002BB000100MVV   0000806200Y
28843059XAK27GA0000E5001000
28843059AAK27GA0000E5S001000SPY   0001425600Y
28843059X4K27GA00007C000200
28843059A4K27GA00007CB000200DIA   0001298500Y
28843059XAK27GA0000RR003000
28843059XAK27GA0000EX000500
28843059AAK27GA0000EXB000500SPY   0001425000Y
28843059XAK27GA0000RQ003000
28843059XAK27GA0000FD000500
28843059AAK27GA0000FDB000500SPY   0001425000Y
28843060AAK27GA0000RUS001000SPY   0001425800Y
28843060XAK27GA0000RE001000
28843060XAK27GA0000Q2002000
28843061X4K27GA00009B000100
28843061AAK27GA0000RVB003000SPY   0001424700Y
28843061X4K27GA00009C000100
28843061X3K27G6000041000100
28843062AAK27GA0000RWB003000SPY   0001424700Y
28843071A8K27G600002CS000500MZZ   0000493800Y
28843071A8K27G600002DB000100MVV   0000806300Y
28843075X6K27GA00002C000500
28843075A6K27GA00002CB000500IWM   0000736200Y
28843077XBK27GA0000FA001000
28843076A6K27GA00005RS002000IWM   0000737000Y
28843088XBK27GA0000FC000100
28843088XBK27GA0000FD000100
28843088A6K27GA00005SB000100IWM   0000736100Y
28843088X6K27GA00005S000100
28843090ABK27GA0000FES000100TWM   0000702000Y
28843111X8K27G600002C000500
28843111X8K27G600002B000100
28843111X8K27G600002A000500
28843111X8K27G600002D000100
28843113A8K27G600002EB000100MVV   0000806100Y
28843113A8K27G600002FS000500MZZ   0000494000Y
28843135XAK27GA0000QX001000
28843149XAK27GA0000R6001000
28843151AAK27GA0000RXB001000SPY   0001425200Y
28843285X8K27G6000028000500
28843285X8K27G6000029000100
28843337XAK27GA0000RU001000
28843337AAK27GA0000RYS001000SPY   0001425900Y
28843339AAK27GA0000RZS001000SPY   0001425900Y
28843364XAK27GA0000R2002000
28843409X7K27GA000021002000
28843430XBK27GA0000EZ002000
28843430XBK27GA0000F0002000
28843437XCK27GA00002D002000
28843445A6K27GA00005TB002000IMCL  0000324600Y
28843449X1K27GA000040002000
28843476X9K27G60000M3005000
28843477X9K27G60000F7003200
28843477A9K27G60000F7B003200QQQQ  0000495200Y
28843477X9K27G60000M2005000
28843477A9K27G60000M6S005000QQQQ  0000495800Y
28843477A9K27G60000M7S005000QQQQ  0000495800Y
28843478A9K27G60000M8S002000QQQQ  0000495800Y
28843478X9K27G60000G8002000
28843478A9K27G60000G8B002000QQQQ  0000495200Y
28843480X1K27GA000041002000
28843482X9K27G60000EQ002000
28843482A9K27G60000EQS002000QQQQ  0000495800Y
28843485X2K27G600002R002000
28843485X2K27G6000032002000
28843493E4K27GA00002Y00010000004AQ00005
28843492X6K27GA00002A000500
28843492A6K27GA00002AS000500IWM   0000736700Y
28843495X9K27G60000G1002000
28843495A9K27G60000G1S002000QQQQ  0000495800Y
28843495X9K27G60000LY005000
28843495ABK27GA0000FFS000100UWM   0000543400Y
28843495ABK27GA0000FGB000100TWM   0000701000Y
28843495ABK27GA0000FHB000100TWM   0000701100Y
28843495A4K27GA00009MS000100DIG   0001246800Y
28843496X4K27GA00009M000100
28843495X6K27GA00001J000100
28843497A9K27G60000M9B005000QQQQ  0000495300Y
28843498X3K27G6000019002000
28843498A4K27GA00009NS000100DIG   0001246800Y
28843499X3K27G6000043002000
28843503A6K27GA00005UB000100IYE   0001532500Y
28843503X6K27GA00001L000100
28843506A6K27GA00005VS000100IYE   0001540600Y
28843512X9K27G60000LZ005000
28843515X2K27G600002O002000
28843514X4K27GA00009J002000
28843516XAK27GA0000RF001000
28843516AAK27GA0000S0S001000SPY   0001425800Y
28843522A9K27G60000MAB005000QQQQ  0000495300Y
28843532X2K27G6000033002000
28843532X1K27GA00000V000100
28843532A1K27GA00000VB000100AAPL  0001828600Y
28843545X9K27G60000MA005000
28843546X9K27G60000M9005000
28843546A9K27G60000MBB005000QQQQ  0000495700Y
28843546A9K27G60000MCB005000QQQQ  0000495700Y
28843549E1K27GA00002Y000090000N1AQ00003
28843551X3K27G6000013002000
28843561X3K27G6000047002000
28843562A7K27GA000025B002000LMT   0000122300Y
28843572X6K27GA00005U000100
28843572A6K27GA00005WB000100IYE   0001533200Y
28843574A5K27GA00002SB002000GM    0000174300Y
28843579A1K27GA000042B002000AFL   0000072000Y
28843588A2K27G6000037B002000BDX   0000758300Y
28843596A3K27G6000049B002000CVS   0000042200Y
28843608A5K27GA00002TB002000HNZ   0000045200Y
28843613A5K27GA00002UB002000HOT   0000046300Y
28843626A6K27GA00005XB002000JCP   0000411900Y
28843641A7K27GA000026B002000LMT   0000123100Y
28843643A6K27GA00005YB002000JPM   0000443300Y
28843652ACK27GA00002EB002000WYE   0000044200Y
28843663A6K27GA00005ZB002000JWN   0000349300Y
28843670A1K27GA000043B002000AFL   0000072800Y
28843681A2K27G6000038B002000BBT   0000032800Y
28843687A6K27GA000060B002000KEY   0000209100Y
28843711A2K27G6000039B002000BDX   0000759100Y
28843728A3K27G600004AB002000COH   0000034800Y
28843739A4K27GA00009OB002000EIX   0000050000Y
28843749A5K27GA00002VB002000HNZ   0000046000Y
28844106XAK27GA0000O6000500
28844106AAK27GA0000O6S000500SPY   0001425600Y
28844184A8K27G600002GB000500MZZ   0000491500Y
28844184A8K27G600002HS000100MVV   0000809500Y
28844355X2K27G6000035002000
28844381X7K27GA000026002000
28844387X7K27GA000025002000
28844387AAK27GA0000S1B002000SHLD  0000696700Y
28844440X1K27GA000042002000
28844451ABK27GA0000FIB002000UTX   0000081100Y
28844453X1K27GA000039002000
28844459X2K27G6000036002000
28844463X9K27G60000MC005000
28844461XCK27GA00002E002000
28844492A9K27G60000MDB005000QQQQ  0000495300Y
28844496A7K27GA000027B002000LPNT  0000191200Y
28844503AAK27GA0000S2S001000SPY   0001425800Y
28844521A1K27GA000044B002000ABT   0000059900Y
28844529X1K27GA000043002000
28844549X1K27GA00003A002000
28844555ABK27GA0000FJB002000UTX   0000080300Y
28844568X3K27G6000049002000
28844583A2K27G600003AB002000AXP   0000400800Y
28844598A2K27G600003BB002000CAG   0000020300Y
28844598XAK27GA0000E5001000
28844598AAK27GA0000E5S001000SPY   0001426000Y
28844598XAK27GA0000RV003000
28844598XAK27GA0000EX000500
28844598AAK27GA0000EXB000500SPY   0001425400Y
28844598XAK27GA0000RW003000
28844598XAK27GA0000S2001000
28844598XAK27GA0000S0001000
28844598AAK27GA0000S3B001000SPY   0001425300Y
28844599AAK27GA0000S4B003000SPY   0001425400Y
28844599AAK27GA0000S5B003000SPY   0001425400Y
28844599XAK27GA0000RS003000
28844599XAK27GA0000RT003000
28844599XAK27GA0000O6000500
28844599AAK27GA0000O6S000500SPY   0001426000Y
28844601AAK27GA0000S6S003000SPY   0001426400Y
28844602AAK27GA0000S7S003000SPY   0001426400Y
28844608ACK27GA00002FB002000WYE   0000044600Y
28844610XAK27GA0000RZ001000
28844613ABK27GA0000FKB001000SSO   0000764100Y
28844614A3K27G600004BB002000CCE   0000190200Y
28844615X6K27GA00002A000500
28844615A6K27GA00002AS000500IWM   0000737100Y
28844617X9K27G60000MD005000
28844617X9K27G60000M7005000
28844617A9K27G60000MEB005000QQQQ  0000495700Y
28844617X4K27GA00007C000200
28844617A4K27GA00007CB000200DIA   0001298800Y
28844618X9K27G60000G1002000
28844618A9K27G60000G1S002000QQQQ  0000496300Y
28844618A9K27G60000MFS005000QQQQ  0000496200Y
28844619A4K27GA00009PS000100DOG   0000598300Y
28844620A3K27G600004CB000100DDM   0000801200Y
28844619A4K27GA00009QS000100DXD   0000500100Y
28844621XAK27GA0000S3001000
28844622X9K27G60000EQ002000
28844622A9K27G60000EQS002000QQQQ  0000496100Y
28844623X9K27G60000M8002000
28844624AAK27GA0000S8B001000SPY   0001425200Y
28844628XBK27GA0000FF000100
28844628XBK27GA0000FH000100
28844628XBK27GA0000FG000100
28844632X5K27GA00001Z002000
28844636X5K27GA00002T002000
28844637XAK27GA0000RY001000
28844637AAK27GA0000S9S001000SPY   0001426000Y
28844637X6K27GA00002C000500
28844637A6K27GA00002CB000500IWM   0000736600Y
28844639AAK27GA0000SAS001000SPY   0001426000Y
28844640ABK27GA0000FLB000100UWM   0000542500Y
28844638X6K27GA00002C000500
28844638A6K27GA00002CB000500IWM   0000736200Y
28844640ABK27GA0000FMS000100TWM   0000701800Y
28844640XBK27GA0000FE000100
28844640XAK27GA0000E5001000
28844640AAK27GA0000E5S001000SPY   0001425600Y
28844640XAK27GA0000S5003000
28844640XAK27GA0000EX000500
28844640AAK27GA0000EXB000500SPY   0001425000Y
28844640XAK27GA0000S4003000
28844640XAK27GA0000S6003000
28844640XAK27GA0000S7003000
28844641AAK27GA0000SBS003000SPY   0001425800Y
28844641AAK27GA0000SCS003000SPY   0001425800Y
28844641AAK27GA0000SDS001000SPY   0001425900Y
28844642AAK27GA0000SEB003000SPY   0001424700Y
28844642AAK27GA0000SFB003000SPY   0001424700Y
28844641X6K27GA00002C000500
28844641A6K27GA00002CB000500IWM   0000736600Y
28844643XBK27GA0000FL000100
28844643XBK27GA0000FM000100
28844645A1K27GA000045B002000ABT   0000059100Y
28844645ABK27GA0000FNB000100UWM   0000542500Y
28844645ABK27GA0000FOS000100TWM   0000701800Y
28844645X6K27GA00002C000500
28844645A6K27GA00002CB000500IWM   0000736200Y
28844647X6K27GA00002C000500
28844647A6K27GA00002CB000500IWM   0000736600Y
28844648XBK27GA0000FN000100
28844648XBK27GA0000FO000100
28844648X6K27GA00002C000500
28844648A6K27GA00002CB000500IWM   0000736200Y
28844650ABK27GA0000FPS000100TWM   0000701800Y
28844650ABK27GA0000FQB000100UWM   0000542500Y
28844651X4K27GA00009O002000
28844650X6K27GA00002C000500
28844650A6K27GA00002CB000500IWM   0000736600Y
28844652XBK27GA0000FQ000100
28844652XBK27GA0000FP000100
28844654ABK27GA0000FRB000100UWM   0000542500Y
28844654ABK27GA0000FSS000100TWM   0000701800Y
28844655X5K27GA00002U002000
28844655X6K27GA00002C000500
28844655A6K27GA00002CB000500IWM   0000736200Y
28844657X6K27GA00002C000500
28844657A6K27GA00002CB000500IWM   0000736600Y
28844659X6K27GA00002C000500
28844659A6K27GA00002CB000500IWM   0000736200Y
28844661X5K27GA00002V002000
28844661XAK27GA0000S8001000
28844662X4K27GA00007C000200
28844662A4K27GA00007CB000200DIA   0001298500Y
28844664X4K27GA00009P000100
28844664X4K27GA00009Q000100
28844665X3K27G600004C000100
28844668XBK27GA0000FR000100
28844668XBK27GA0000FS000100
28844668X9K27G60000G1002000
28844668A9K27G60000G1S002000QQQQ  0000495800Y
28844668X9K27G60000MF005000
28844669A9K27G60000MGS005000QQQQ  0000495800Y
28844670A9K27G60000MHS002000QQQQ  0000495800Y
28844670A3K27G600004DB002000CVS   0000044200Y
28844670ABK27GA0000FTS000100TWM   0000702000Y
28844670XBK27GA0000FK001000
28844672X9K27G60000EQ002000
28844672A9K27G60000EQS002000QQQQ  0000495800Y
28844686X6K27GA00005N002000
28844696X9K27G60000ME005000
28844698A5K27GA00002WB002000HOT   0000048400Y
28844700A2K27G600003CB002000AXP   0000400000Y
28844702A9K27G60000MIB005000QQQQ  0000495300Y
28844708A2K27G600003DB002000BBT   0000033000Y
28844710A4K27GA00009RS000100DRYS  0001071900Y
28844723A3K27G600004EB002000CCE   0000189400Y
28844729A3K27G600004FB002000COH   0000035000Y
28844741A4K27GA00009SB002000EIX   0000050600Y
28844811X4K27GA00009F000100
28844816XAK27GA0000O6000500
28844816AAK27GA0000O6S000500SPY   0001425600Y
28844928XAK27GA0000SD001000
28845041A4K27GA00009TB000100DOG   0000597000Y
28845041A4K27GA00009UB000100DXD   0000499400Y
28845041A3K27G600004GS000100DDM   0000802600Y
28845131E4K27GA00009G00010000004AQ00006
28845133A4K27GA00009WB000100DRYS  0001066900Y
28845165AAK27GA0000SGS002000SPY   0001425800Y
28845292X9K27G60000MB005000
28845353X4K27GA00009A000200
28845375A4K27GA00009XS000200DIA   0001298900Y
28845374X6K27GA00005T002000
28845390A9K27G60000MJB005000QQQQ  0000495300Y
28845419XBK27GA0000FJ002000
28845419XAK27GA0000S1002000
28845448XCK27GA00002F002000
28845450XBK27GA0000FI002000
28845450XAK27GA0000R1002000
28845472X3K27G6000045002000
28845485X1K27GA000045002000
28845495X1K27GA000044002000
28845500X1K27GA000022002000
28845512X2K27G6000038002000
28845531X3K27G600004A002000
28845531A7K27GA000028B002000LMT   0000128300Y
28845540X1K27GA00001X002000
28845547X3K27G600004D002000
28845556X4K27GA000057002000
28845572A1K27GA000046B002000AFL   0000075700Y
28845588A1K27GA000047B002000ARO   0000293400Y
28845596X4K27GA00005F002000
28845607X5K27GA00002W002000
28845615A2K27G600003EB002000CAG   0000020200Y
28845621A2K27G600003FB002000BMY   0000019200Y
28845624X4K27GA00005Q002000
28845627X4K27GA00009S002000
28845642A3K27G600004HB002000CVS   0000044600Y
28845642A7K27GA000029B002000LMT   0000129100Y
28845660ACK27GA00002GB002000WYE   0000046700Y
28845671A5K27GA00002XB002000HMY   0000083900Y
28845681A5K27GA00002YB002000HNZ   0000047800Y
28845681A1K27GA000048B002000AFL   0000076500Y
28845691A1K27GA000049B002000ARO   0000294200Y
28845692A5K27GA00002ZB002000HOT   0000049000Y
28845709A4K27GA00009YB002000EIX   0000052800Y
28845726A5K27GA000030B002000HNZ   0000048600Y
28845740A6K27GA000061B002000JCI   0000034900Y
28845748A6K27GA000062B002000JBL   0000104000Y
28845763A6K27GA000063B002000JCI   0000035700Y
28845839X5K27GA00001F000100
28846044XAK27GA0000EW000500
28846044AAK27GA0000EWS000500SPY   0001425600Y
28846044XAK27GA0000F2000500
28846044AAK27GA0000F2B000500SPY   0001424900Y
28846044X4K27GA000062000200
28846044A4K27GA000062B000200DIA   0001298400Y
28846053XAK27GA0000RK000100
28846054AAK27GA0000SHB001000SDS   0000547700Y
28846054XBK27GA0000F9001000
28846054X3K27G600003Y000100
28846055AAK27GA0000SIB001000SDS   0000547600Y
28846055ABK27GA0000FUS001000SSO   0000765100Y
28846056XBK27GA0000F1001000
28846056ABK27GA0000FVB001000SSO   0000764000Y
28846056ABK27GA0000FWB001000SSO   0000764200Y
28846054X6K27GA00002A000500
28846054A6K27GA00002AS000500IWM   0000736700Y
28846057ABK27GA0000FXS000100UWM   0000543400Y
28846057ABK27GA0000FYB000100TWM   0000701000Y
28846057ABK27GA0000FZB000100TWM   0000701100Y
28846123XAK27GA0000EW000500
28846123AAK27GA0000EWS000500SPY   0001425500Y
28846152X9K27G60000MI005000
28846152X9K27G60000MJ005000
28846152A9K27G60000MKB005000QQQQ  0000495700Y
28846153A9K27G60000MLB005000QQQQ  0000495700Y
28846233X9K27G60000MK005000
28846242A9K27G60000MMB005000QQQQ  0000495300Y
28846277X6K27GA00005J002000
28846326X9K27G60000MM005000
28846326A9K27G60000MNB005000QQQQ  0000495700Y
28846376X9K27G60000MN005000
28846382A9K27G60000MOB005000QQQQ  0000495300Y
28846381A6K27GA000064B002000IWM   0000736400Y
28846408X7K27GA000028002000
28846409XAK27GA0000HG001000
28846413X7K27GA000029002000
28846413AAK27GA0000SJB000600SPY   0001419600Y
28846427XCK27GA00002G002000
28846467X1K27GA000048002000
28846471X6K27GA000064002000
28846480ABK27GA0000G0B002000UTX   0000084300Y
28846481XAK27GA0000FO002000
28846482ABK27GA0000G1B002000UTX   0000085100Y
28846488A6K27GA000065B002000IMCL  0000327900Y
28846514AAK27GA0000SKB002000SHLD  0000701900Y
28846516ACK27GA00002HB002000WYE   0000047100Y
28846538A1K27GA00004AB002000ABT   0000063000Y
28846552AAK27GA0000SLB002000SPLS  0000019800Y
28846560X2K27G600003B002000
28846565A1K27GA00004BB002000ABT   0000062100Y
28846587A1K27GA00004CB002000ANF   0000721000Y
28846598A3K27G600004IB002000CTSH  0000030700Y
28846598X1K27GA000046002000
28846607X9K27G60000MO005000
28846608A9K27G60000MPB005000QQQQ  0000495700Y
28846619A9K27G60000MQS002000QQQQ  0000496000Y
28846619A1K27GA00004DB002000ANF   0000720200Y
28846639A2K27G600003GB002000BBT   0000035700Y
28846645A3K27G600004JS000100DDM   0000802500Y
28846644A4K27GA00009ZB000100DXD   0000499500Y
28846647X2K27G600003D002000
28846658X3K27G600004F002000
28846662X3K27G600004H002000
28846671X4K27GA00006G002000
28846678A3K27G600004KB002000COH   0000037800Y
28846678X5K27GA00002Y002000
28846688X5K27GA00002Z002000
28846707A4K27GA0000A0B002000EAT   0000197600Y
28846709A3K27G600004LB002000CVS   0000046600Y
28846721A4K27GA0000A1B002000EIX   0000053400Y
28846721X4K27GA00009Y002000
28846732X4K27GA00006F002000
28846736X9K27G60000MP005000
28846742A9K27G60000MRB005000QQQQ  0000495300Y
28846743X9K27G60000ML005000
28846746X5K27GA000029002000
28846747A9K27G60000MSB005000QQQQ  0000495300Y
28846747X9K27G60000EP002000
28846747A9K27G60000EPB002000QQQQ  0000495400Y
28846757X5K27GA000030002000
28846782A4K27GA0000A2B002000DIS   0000328100Y
28846781A6K27GA000066B002000KFT   0000304000Y
28846802A7K27GA00002AB002000KMB   0000610800Y
28846802A4K27GA0000A3B002000EAT   0000198400Y
28846822X9K27G60000MS005000
28846822A9K27G60000MTB005000QQQQ  0000495700Y
28846823X9K27G60000MQ002000
28846824X6K27GA00005W000100
28846825A4K27GA0000A4B000100DIG   0001238700Y
28846825X4K27GA000031000100
28846826A6K27GA000067B000100IYE   0001532300Y
28846832X6K27GA000067000100
28846833X4K27GA0000A4000100
28846834A6K27GA000068B000100IYE   0001531500Y
28846843A4K27GA0000A5B000100DIG   0001237700Y
28846843X4K27GA00009Z000100
28846844X3K27G600004J000100
28846871A4K27GA0000A6B000100DXD   0000499500Y
28846872A3K27G600004MS000100DDM   0000802500Y
28846903X4K27GA0000A6000100
28846904X3K27G600004M000100
28846932A4K27GA0000A7B000100DXD   0000499500Y
28846932A3K27G600004NS000100DDM   0000802500Y
28846963X4K27GA0000A7000100
28846964X3K27G600004N000100
28847082A6K27GA000069S000100IYE   0001538500Y
28847083A4K27GA0000A8S000100DIG   0001243500Y
28847083X4K27GA00009N000100
28847350X3K27G6000042002000
28847393X2K27G600003F002000
28847396XBK27GA0000G0002000
28847417XAK27GA0000SK002000
28847426XAK27GA0000PU002000
28847431XCK27GA00002H002000
28847452XBK27GA0000G1002000
28847454X1K27GA00004A002000
28847457X2K27G600000R002000
28847457AAK27GA0000SMB002000SOHU  0000798100Y
28847477X3K27G600004L002000
28847477X1K27GA00004B002000
28847492X3K27G600003A002000
28847508X1K27GA000028002000
28847523X6K27GA000063002000
28847537A7K27GA00002BB002000LMT   0000135100Y
28847548A7K27GA00002CB002000LMT   0000134300Y
28847554ACK27GA00002IB002000WYE   0000049100Y
28847565X2K27G600000U002000
28847569A1K27GA00004EB002000AFL   0000079400Y
28847585X2K27G600003E002000
28847589A1K27GA00004FB002000AFL   0000080200Y
28847610A2K27G600003HB002000CAG   0000022300Y
28847621A2K27G600003IB002000BBT   0000035800Y
28847635A4K27GA0000A9B002000EIX   0000055600Y
28847647X4K27GA0000A1002000
28847661A3K27G600004OB002000COH   0000038000Y
28847663A4K27GA0000AAB002000ESI   0000616600Y
28847683A3K27G600004PB002000CVS   0000047000Y
28847696A5K27GA000031B002000HMY   0000084900Y
28847696A4K27GA0000ABB002000ESI   0000615800Y
28847706XAK27GA0000FE000500
28847706AAK27GA0000FEB000500SPY   0001424900Y
28847706XAK27GA0000R7001000
28847705X6K27GA000061002000
28847707AAK27GA0000SNS001000SPY   0001425500Y
28847707XAK27GA0000E4001000
28847707AAK27GA0000E4B001000SPY   0001425000Y
28847709A5K27GA000032B002000HNZ   0000050300Y
28847717XAK27GA0000RX001000
28847717AAK27GA0000SOB001000SPY   0001425100Y
28847719AAK27GA0000SPB001000SPY   0001425100Y
28847721A5K27GA000033B002000HOT   0000051600Y
28847723A4K27GA0000ACB000100DXD   0000499500Y
28847724A3K27G600004QS000100DDM   0000802500Y
28847761A5K27GA000034B002000HNZ   0000051100Y
28847763X4K27GA0000AC000100
28847764X3K27G600004Q000100
28847770A5K27GA000035B002000HOT   0000052400Y
28848086XAK27GA0000R3001000
28848091A4K27GA0000ADB000100DXD   0000499500Y
28848091A3K27G600004RS000100DDM   0000802500Y
28848101AAK27GA0000SQB001000SPY   0001425000Y
28848123X4K27GA0000AD000100
28848124X3K27G600004R000100
28848258A4K27GA0000AEB000100DRYS  0001066900Y
28848364X6K27GA000065002000
28848369X7K27GA00002B002000
28848369X7K27GA00002C002000
28848394XCK27GA00002I002000
28848402X7K27GA000027002000
28848428X9K27G60000LW002000
28848429A2K27G600003JB002000BMY   0000021000Y
28848431A3K27G600004SB002000CELG  0000469900Y
28848433ABK27GA0000G2B002000UTX   0000088300Y
28848468AAK27GA0000SRB002000SHLD  0000707000Y
28848467ACK27GA00002JB002000WYE   0000049500Y
28848468X1K27GA00004F002000
28848480X1K27GA00004E002000
28848502ABK27GA0000G3B002000UTX   0000089100Y
28848510AAK27GA0000SSB002000SNDK  0000222300Y
28848520A1K27GA00004GB002000ABT   0000065200Y
28848534A3K27G600004TS000100DDM   0000802500Y
28848533A4K27GA0000AFB000100DXD   0000499500Y
28848536X2K27G600003G002000
28848563X4K27GA0000AF000100
28848563X3K27G600004T000100
28848564X3K27G600004K002000
28848572A1K27GA00004HB002000ABT   0000066000Y
28848586A2K27G600003KB002000BA    0000852900Y
28848591X4K27GA0000A9002000
28848608X4K27GA00005Y002000
28848617X5K27GA000034002000
28848622A1K27GA00004IB002000APC   0000763100Y
28848624X5K27GA000035002000
28848638X3K27G600004P002000
28848639A2K27G600003LB002000BA    0000852100Y
28848651X4K27GA00005A002000
28848653A3K27G600004UB002000CVS   0000048900Y
28848660A2K27G600003MB002000CAG   0000022100Y
28848674A3K27G600004VB002000DD    0000455600Y
28848702X5K27GA000032002000
28848703A6K27GA00006AB002000JCI   0000038500Y
28848710X5K27GA000033002000
28848722A6K27GA00006BB002000JCP   0000413000Y
28848729A4K27GA0000AGB002000EIX   0000056200Y
28848938X5K27GA00001B000100
28849164XAK27GA0000QY003000
28849164XAK27GA0000QR002000
28849164XAK27GA0000QZ003000
28849164XAK27GA0000O2000500
28849164AAK27GA0000O2S000500SPY   0001425500Y
28849164XAK27GA0000K1001000
28849164AAK27GA0000K1S001000SPY   0001425500Y
28849164X4K27GA00003H000200
28849164A4K27GA00003HB000200DIA   0001298300Y
28849164X4K27GA000090000047
28849165AAK27GA0000STS003000SPY   0001425600Y
28849165AAK27GA0000SUS003000SPY   0001425600Y
28849169A4K27GA0000AHS000047DIA   0001298800Y
28849173A4K27GA0000AIB000100DXD   0000499500Y
28849174A3K27G600004WS000100DDM   0000802500Y
28849178X4K27GA00003H000200
28849178A4K27GA00003HB000200DIA   0001298600Y
28849355XAK27GA0000SR002000
28849391X3K27G600004I002000
28849416A6K27GA00006CB002000IMCL  0000331100Y
28849421XBK27GA0000G3002000
28849424XBK27GA0000G2002000
28849443XCK27GA00002J002000
28849446X1K27GA00004H002000
28849455X1K27GA00004G002000
28849467X2K27G600003C002000
28849474X2K27G600003I002000
28849489X2K27G600003A002000
28849493X2K27G6000037002000
28849511X3K27G600004O002000
28849514X3K27G600003E002000
28849514A7K27GA00002DB002000LMT   0000141100Y
28849514X4K27GA0000AG002000
28849518A7K27GA00002EB002000LMT   0000140300Y
28849528A7K27GA00002FB002000LPNT  0000194500Y
28849535ACK27GA00002KB002000WYE   0000051500Y
28849544X2K27G6000039002000
28849553A1K27GA00004JB002000AFL   0000083100Y
28849563X2K27G600003H002000
28849575A9K27G60000MUB002000PDLI  0000017400Y
28849575A3K27G600004XB002000CVS   0000049300Y
28849591A4K27GA0000AJB002000DIS   0000327400Y
28849621A1K27GA00004KB002000AFL   0000083900Y
28849623A5K27GA000036B002000HNZ   0000052900Y
28849627X3K27G600004U002000
28849641A5K27GA000037B002000HOT   0000054300Y
28849650A2K27G600003NB002000BBT   0000038500Y
28849656A6K27GA00006DB002000JCI   0000038700Y
28849671A3K27G600004YB002000COH   0000040700Y
28849671A7K27GA00002GB002000KMX   0000185800Y
28849683X5K27GA00001G000100
28849688A5K27GA000038S000100FXP   0000658300Y
28849693X5K27GA000038000100
28849695A5K27GA000039S000100FXP   0000658300Y
28849695A7K27GA00002HB002000LEH   0000416200Y
28849701A4K27GA0000AKB002000EIX   0000058400Y
28849703X5K27GA000039000100
28849740A4K27GA0000ALB002000ELN   0000227000Y
28849758A5K27GA00003AB002000HNZ   0000053700Y
28849769A5K27GA00003BB002000HOT   0000055100Y
28850379XAK27GA0000SL002000
28850388X9K27G60000MT005000
28850389X9K27G60000F4003200
28850389A9K27G60000F4S003200QQQQ  0000495800Y
28850390X4K27GA00003H000200
28850390A4K27GA00003HB000200DIA   0001298300Y
28850390A9K27G60000MVB005000QQQQ  0000495300Y
28850398X2K27G600003J002000
28850400X3K27G600000O002000
28850400X7K27GA00002E002000
28850408X9K27G60000MV005000
28850409X9K27G60000F4003200
28850409A9K27G60000F4S003200QQQQ  0000496300Y
28850409A9K27G60000MWB005000QQQQ  0000495700Y
28850413X9K27G60000MR005000
28850413A9K27G60000MXB005000QQQQ  0000495700Y
28850413X7K27GA00002D002000
28850419X9K27G60000MW005000
28850419X9K27G60000F4003200
28850419A9K27G60000F4S003200QQQQ  0000495800Y
28850419X9K27G60000MX005000
28850419X1K27GA00004J002000
28850420A9K27G60000MYB005000QQQQ  0000495300Y
28850420A9K27G60000MZB005000QQQQ  0000495300Y
28850424XCK27GA00002K002000
28850427AAK27GA0000SVB002000SHLD  0000712100Y
28850439X2K27G600003M002000
28850440X1K27GA00004K002000
28850446X1K27GA00002B002000
28850451X4K27GA00005E002000
28850457A3K27G6000050B002000CTSH  0000034200Y
28850459X4K27GA0000AK002000
28850468X4K27GA00005L002000
28850484X3K27G600004X002000
28850487X5K27GA00001U002000
28850498X4K27GA00005P002000
28850523X5K27GA00003A002000
28850526X5K27GA00003B002000
28850526X6K27GA00006A002000
28850534X4K27GA000067002000
28850540X5K27GA00001O002000
28850542X5K27GA000036002000
28850549X5K27GA000037002000
28850558ABK27GA0000G4B002000UTX   0000093100Y
28850571ABK27GA0000G5B002000UTX   0000092300Y
28850581A1K27GA00004LB002000ABT   0000069100Y
28850584ACK27GA00002LB002000WYE   0000051900Y
28850600A1K27GA00004MB002000ABT   0000068300Y
28850602A2K27G600003OB002000AXP   0000402200Y
28850620A2K27G600003PB002000AXP   0000401400Y
28850621A2K27G600003QB002000BDX   0000760500Y
28850631A2K27G600003RB002000BBT   0000038700Y
28850640A2K27G600003SB002000CAG   0000024200Y
28850644A2K27G600003TB002000BDX   0000759700Y
28850651A3K27G6000051B002000COH   0000040900Y
28850653A8K27G600002IB000500MZZ   0000491600Y
28850653A8K27G600002JS000100MVV   0000809300Y
28850664A3K27G6000052B002000CVS   0000051300Y
28850664A3K27G6000053B002000DD    0000454900Y
28850676A4K27GA0000AMB002000EIX   0000059000Y
28850695A7K27GA00002IB002000LEN   0000180900Y
28850725A6K27GA00006EB002000JPM   0000444100Y
28850924X4K27GA00003H000200
28850924A4K27GA00003HB000200DIA   0001298600Y
28851346X4K27GA00009R000100
28851392X6K27GA00006C002000
28851400XAK27GA0000SV002000
28851404XBK27GA0000G4002000
28851409XBK27GA0000G5002000
28851414XCK27GA000023002000
28851427X1K27GA00004L002000
28851428XCK27GA000020002000
28851440X2K27G600003N002000
28851440AAK27GA0000SWB002000SPLS  0000022900Y
28851444X3K27G600004Y002000
28851451XCK27GA00002L002000
28851459X3K27G6000052002000
28851465X1K27GA00004M002000
28851481X3K27G600001X002000
28851491X3K27G6000022002000
28851498A3K27G6000054B002000COST  0000695100Y
28851499X4K27GA0000AM002000
28851520A2K27G600003UB002000BMY   0000022900Y
28851521X6K27GA00006D002000
28851539A7K27GA00002JB002000LMT   0000146300Y
28851559A7K27GA00002KB002000LMT   0000147100Y
28851567X4K27GA000032000100
28851567A4K27GA0000ANS000100DRYS  0001070900Y
28851575A1K27GA00004NB002000AFL   0000086800Y
28851583A2K27G600003VB002000CAG   0000024100Y
28851589ACK27GA00002MB002000WYE   0000053900Y
28851593A3K27G6000055B002000CVS   0000051700Y
28851611A4K27GA0000AOB002000DUK   0000162200Y
28851615A1K27GA00004OB002000AFL   0000087600Y
28851623A4K27GA0000APB002000ELN   0000226300Y
28851628A1K27GA00004PB002000APC   0000764000Y
28851632A5K27GA00003CB002000GE    0000298200Y
28851651A5K27GA00003DB002000HNZ   0000055500Y
28851654A4K27GA0000AQB002000DUK   0000163000Y
28851658A5K27GA00003EB002000HOT   0000057000Y
28851674A4K27GA0000ARB002000EIX   0000061200Y
28851686A7K27GA00002LB002000LLL   0001086200Y
28851689A4K27GA0000ASB002000EK    0000146500Y
28851719A5K27GA00003FB002000GE    0000299000Y
28851731A5K27GA00003GB000100GOOG  0005770100Y
28852278XAK27GA0000SU003000
28852279XAK27GA0000ST003000
28852281AAK27GA0000SXS003000SPY   0001426200Y
28852281AAK27GA0000SYS003000SPY   0001426200Y
28852356A6K27GA00006FB002000IMCL  0000334400Y
28852358X7K27GA00002K002000
28852360X7K27GA00002J002000
28852391XCK27GA00002M002000
28852420X1K27GA00004O002000
28852424X2K27G600003S002000
28852427ABK27GA0000G6B002000UTX   0000096300Y
28852431X4K27GA000058002000
28852434AAK27GA0000SZB002000SHLD  0000717200Y
28852443X4K27GA0000AR002000
28852469ABK27GA0000G7B002000UTX   0000097100Y
28852467ACK27GA00002NB002000WMT   0000536700Y
28852477ACK27GA00002OB002000WYE   0000054300Y
28852492ACK27GA00002PB002000WMT   0000537500Y
28852499A1K27GA00004QB002000ABT   0000071300Y
28852507X1K27GA00004N002000
28852516X2K27G600003R002000
28852519X3K27G6000051002000
28852526X3K27G6000055002000
28852527X4K27GA00005B002000
28852531X4K27GA00005V002000
28852532A1K27GA00004RB002000ABT   0000072200Y
28852535X5K27GA00003D002000
28852537P8K27G600002KB005000OIH   0002170000000I000HV288
28852539X5K27GA00003E002000
28852551A2K27G600003WB002000BBT   0000041300Y
28852576A3K27G6000056B002000COH   0000043700Y
28852584A3K27G6000057B002000CVS   0000053700Y
28852596A3K27G6000058B002000DHR   0000760000Y
28852615AAK27GA0000T0S000100SPY   0001426600Y
28852615XAK27GA0000QP000100
28852629A3K27G6000059B002000DHR   0000759200Y
28852636A4K27GA0000ATB002000EIX   0000061800Y
28852651A6K27GA00006GB002000JCI   0000041500Y
28853027X5K27GA00003G000100
28853027A5K27GA00003GB000100GOOG  0005775100Y
28853109X9K27G60000F4003200
28853109A9K27G60000F4S003200QQQQ  0000496300Y
28853111A9K27G60000N0B005000QQQQ  0000495700Y
28853111X9K27G60000MZ005000
28853111X9K27G60000MY005000
28853111X9K27G60000EP002000
28853111A9K27G60000EPB002000QQQQ  0000495700Y
28853111A9K27G60000N1B005000QQQQ  0000495700Y
28853114X3K27G600004W000100
28853113X4K27GA0000AI000100
28853359XAK27GA0000SZ002000
28853406X3K27G6000050002000
28853409X2K27G600003U002000
28853411X7K27GA00002F002000
28853427XBK27GA0000G6002000
28853433XBK27GA0000G7002000
28853445XCK27GA00002O002000
28853453X9K27G60000MG005000
28853453X9K27G60000EQ002000
28853453A9K27G60000EQS002000QQQQ  0000496100Y
28853453X9K27G60000M6005000
28853453X9K27G60000MH002000
28853454A9K27G60000N2B002000QQQQ  0000495500Y
28853454A9K27G60000N3S005000QQQQ  0000496200Y
28853454A9K27G60000N4S005000QQQQ  0000496200Y
28853460X1K27GA00004Q002000
28853466X1K27GA00004R002000
28853468A6K27GA00006HB002000IWM   0000736400Y
28853474X3K27G6000057002000
28853493X2K27G600003V002000
28853497A7K27GA00002MB002000LMT   0000153100Y
28853509X4K27GA0000AT002000
28853515ACK27GA00002QB002000WYE   0000056300Y
28853541A7K27GA00002NB002000LMT   0000152300Y
28853551A1K27GA00004SB002000AFL   0000091300Y
28853561A1K27GA00004TB002000AFL   0000090500Y
28853576A2K27G600003XB002000BBT   0000041500Y
28853577A4K27GA0000AUS000100DRYS  0001070900Y
28853580A2K27G600003YB002000CAG   0000026200Y
28853593A3K27G600005AB002000COH   0000043900Y
28853601A4K27GA0000AVB002000DOW   0000398300Y
28853606A3K27G600005BB002000CVS   0000054100Y
28853614A4K27GA0000AWB002000DOW   0000397500Y
28853619A4K27GA0000AXB002000EIX   0000064000Y
28853622A4K27GA0000AYB002000EK    0000145800Y
28853625A5K27GA00003HB002000HNZ   0000058800Y
28853630A5K27GA00003IB002000HNZ   0000058000Y
28853636A5K27GA00003JB002000HOT   0000059600Y
28853644A5K27GA00003KB002000HOT   0000060400Y
28853648A7K27GA00002OB002000LLY   0000463400Y
28853661A6K27GA00006IB002000JCI   0000043200Y
28853666A7K27GA00002PB002000LTD   0000166600Y
28854357X3K27G600004S002000
28854387X7K27GA00002M002000
28854389X7K27GA00002N002000
28854396XCK27GA00002Q002000
28854400X6K27GA00006F002000
28854418X9K27G60000HC002000
28854419X1K27GA00004S002000
28854428X1K27GA00004T002000
28854442AAK27GA0000T1B002000SHLD  0000722300Y
28854443X2K27G600003W002000
28854444X3K27G600005B002000
28854449X3K27G6000056002000
28854458X4K27GA00006V002000
28854471X5K27GA00003I002000
28854471A3K27G600005CB002000CTSH  0000037600Y
28854476X5K27GA00003J002000
28854478X6K27GA00006G002000
28854484A2K27G600003ZB002000BMY   0000024700Y
28854500X4K27GA0000AX002000
28854504A7K27GA00002QB002000LPNT  0000197800Y
28854505ABK27GA0000G8B002000UTX   0000100300Y
28854529X4K27GA000074002000
28854552X5K27GA00003H002000
28854553ACK27GA00002RB002000WYE   0000056700Y
28854573X5K27GA00003K002000
28854578ABK27GA0000G9B002000UTX   0000101100Y
28854584ABK27GA0000GAB000500TSEM  0000011800Y
28854600A1K27GA00004UB002000ABT   0000074400Y
28854600A1K27GA00004VB002000ABT   0000075200Y
28854620A3K27G600005DB002000CVS   0000056000Y
28854624A2K27G6000040B002000CAG   0000026000Y
28854653A6K27GA00006JB002000JWN   0000350600Y
28854660A4K27GA0000AZB002000EIX   0000064600Y
28854671A6K27GA00006KB002000KEY   0000210500Y
28854677A9K27G60000N5B002000QQQQ  0000495500Y
28854687A6K27GA00006LB002000KFT   0000305100Y
28854720X9K27G60000F7003200
28854720A9K27G60000F7B003200QQQQ  0000495700Y
28855040AAK27GA0000T2B000500SPY   0001425200Y
28855041XAK27GA0000F2000500
28855041AAK27GA0000F2B000500SPY   0001425300Y
28855085X4K27GA0000AH000047
28855092XAK27GA0000O2000500
28855092AAK27GA0000O2S000500SPY   0001425900Y
28855092A4K27GA0000B0S000047DIA   0001299100Y
28855143XAK27GA0000EW000500
28855143AAK27GA0000EWS000500SPY   0001425900Y
28855144XAK27GA0000K1001000
28855144AAK27GA0000K1S001000SPY   0001425900Y
28855158X8K27G600002J000100
28855158X8K27G600002I000500
28855160X4K27GA000062000200
28855160A4K27GA000062B000200DIA   0001298700Y
28855162A3K27G600005EB000100DDM   0000801100Y
28855165X4K27GA000062000200
28855165A4K27GA000062B000200DIA   0001298400Y
28855165XAK27GA0000T0000100
28855167AAK27GA0000T3S000100SPY   0001426900Y
28855233X1K27GA00002Y000005
28855236X6K27GA00002A000500
28855236A6K27GA00002AS000500IWM   0000737100Y
28855237A1K27GA00004WB000100AAPL  0001828600Y
28855247XBK27GA0000FX000100
28855248XBK27GA0000FZ000100
28855248XBK27GA0000FY000100
28855252XAK27GA0000E4001000
28855252AAK27GA0000E4B001000SPY   0001425400Y
28855252X4K27GA000062000200
28855252A4K27GA000062B000200DIA   0001298700Y
28855252XAK27GA0000FE000500
28855252AAK27GA0000FEB000500SPY   0001425300Y
28855252XAK27GA0000SQ001000
28855253XAK27GA0000EX000500
28855253AAK27GA0000EXB000500SPY   0001425400Y
28855253AAK27GA0000T4B002000SPY   0001425400Y
28855253XAK27GA0000SB003000
28855253XAK27GA0000SE003000
28855253AAK27GA0000T5B003000SPY   0001425400Y
28855253XAK27GA0000Q8000500
28855253AAK27GA0000Q8S000500SPY   0001426000Y
28855253XAK27GA0000SN001000
28855253X4K27GA00009X000200
28855253X9K27G60000G8002000
28855253A9K27G60000G8B002000QQQQ  0000495700Y
28855253AAK27GA0000T6B001000SPY   0001425400Y
28855253XAK27GA0000O6000500
28855253AAK27GA0000O6S000500SPY   0001426000Y
28855254X9K27G60000G1002000
28855254A9K27G60000G1S002000QQQQ  0000496300Y
28855253XAK27GA0000SC003000
28855253XAK27GA0000SF003000
28855253AAK27GA0000T7B002000SPY   0001425300Y
28855254XAK27GA0000SG002000
28855254AAK27GA0000T8B003000SPY   0001425400Y
28855254XAK27GA0000FD000500
28855254AAK27GA0000FDB000500SPY   0001425400Y
28855254XAK27GA0000E5001000
28855254AAK27GA0000E5S001000SPY   0001426000Y
28855254AAK27GA0000T9S000500SPY   0001425700Y
28855255AAK27GA0000TAS001000SPY   0001425900Y
28855255AAK27GA0000TBS003000SPY   0001426400Y
28855255XAK27GA0000T2000500
28855255AAK27GA0000TCS003000SPY   0001426400Y
28855256X3K27G6000046000100
28855255AAK27GA0000TDS002000SPY   0001425900Y
28855260A4K27GA0000B1S000200DIA   0001299200Y
28855263XAK27GA0000RG001000
28855263XBK27GA0000FU001000
28855263X3K27G600004G000100
28855263X4K27GA00009T000100
28855263X4K27GA00009U000100
28855264XAK27GA0000RD001000
28855264XAK27GA0000RC001000
28855265ABK27GA0000GBS001000SSO   0000765200Y
28855265A3K27G600005FS000100DDM   0000802700Y
28855271X9K27G60000FZ002000
28855271XAK27GA0000T9000500
28855273A9K27G60000N6S002000QQQQ  0000496000Y
28855275XAK27GA0000SI001000
28855281XAK27GA0000Q0001000
28855282AAK27GA0000TES001000SPY   0001426000Y
28855281X6K27GA00002C000500
28855281A6K27GA00002CB000500IWM   0000736600Y
28855284ABK27GA0000GCB000100UWM   0000542500Y
28855283X6K27GA00005R002000
28855285XBK27GA0000FT000100
28855285ABK27GA0000GDS000100TWM   0000701800Y
28855291X4K27GA00007C000200
28855291A4K27GA00007CB000200DIA   0001298800Y
28855293A4K27GA0000B2S000100DOG   0000598300Y
28855293A4K27GA0000B3S000100DXD   0000500100Y
28855294A3K27G600005GB000100DDM   0000801200Y
28855295XAK27GA0000TD002000
28855297XAK27GA0000F7000500
28855297AAK27GA0000F7B000500SPY   0001425400Y
28855298XAK27GA0000TE001000
28855298AAK27GA0000TFS000100SH    0000618900Y
28855298XAK27GA0000EB001000
28855298AAK27GA0000EBB001000SPY   0001425400Y
28855299ABK27GA0000GEB001000SSO   0000764300Y
28855298AAK27GA0000TGS001000SPY   0001425600Y
28855299XBK27GA0000FW001000
28855298XAK27GA0000F7000500
28855298AAK27GA0000F7B000500SPY   0001425100Y
28855299XAK27GA0000RN001000
28855299AAK27GA0000THB001000SPY   0001425400Y
28855301XBK27GA0000FV001000
28855301ABK27GA0000GFB001000SSO   0000764100Y
28855301XAK27GA0000TH001000
28855302XBK27GA0000GF001000
28855303AAK27GA0000TIB001000SPY   0001425100Y
28855303XAK27GA0000SH001000
28855305AAK27GA0000TJB001000SDS   0000547600Y
28855305A6K27GA00006MB002000IWM   0000736500Y
28855305X6K27GA000053002000
28855322XAK27GA0000SA001000
28855323XAK27GA0000Q8000500
28855323AAK27GA0000Q8S000500SPY   0001425600Y
28855327X1K27GA00000W000100
28855327A1K27GA00000WS000100AAPL  0001830100Y
28855330A8K27G600002LS000500MZZ   0000493800Y
28855331A8K27G600002MB000100MVV   0000806300Y
28855337X1K27GA00000V000100
28855337A1K27GA00000VB000100AAPL  0001827600Y
28855337X1K27GA00000Y000100
28855337A1K27GA00000YS000100AAPL  0001830100Y
28855370X1K27GA00000W000100
28855370A1K27GA00000WS000100AAPL  0001830000Y
28855370X1K27GA00000Y000100
28855370A1K27GA00000YS000100AAPL  0001830000Y
28855375X8K27G600002G000500
28855375X8K27G6000027000100
28855375X8K27G600002H000100
28855377A8K27G600002NS000100MVV   0000809700Y
28855383X7K27GA00000U002000
28855384A3K27G600005HB002000CELG  0000472400Y
28855386A8K27G600002OS000100MVV   0000809600Y
28855385X7K27GA00000O002000
28855386XBK27GA0000G8002000
28855391XAK27GA0000T1002000
28855392X8K27G600002L000500
28855392X8K27G600002F000500
28855392X8K27G600002E000100
28855392X8K27G600002M000100
28855394A8K27G600002PS000500MZZ   0000493900Y
28855394A8K27G600002QB000100MVV   0000806200Y
28855403XCK27GA00002R002000
28855414XAK27GA0000SW002000
28855427XBK27GA0000G9002000
28855432X1K27GA00004U002000
28855443X2K27G600003P002000
28855446X2K27G600003X002000
28855453X3K27G600005A002000
28855455AAK27GA0000TKB000500SPY   0001425400Y
28855468A6K27GA00006NB002000IMCL  0000337600Y
28855474X1K27GA00004V002000
28855476A7K27GA00002RB002000LMT   0000158300Y
28855484X4K27GA0000AZ002000
28855485A7K27GA00002SB002000LMT   0000159100Y
28855518A9K27G60000N7B002000PETM  0000205400Y
28855516ACK27GA00002SB002000WYE   0000058700Y
28855547A1K27GA00004XB002000AFL   0000094200Y
28855552X2K27G600003O002000
28855579A3K27G600005IB002000CVS   0000056400Y
28855589A4K27GA0000B4B002000FDX   0000877000Y
28855590A8K27G600002RS000500MZZ   0000493800Y
28855590A8K27G600002SB000100MVV   0000806300Y
28855596A1K27GA00004YB002000AFL   0000095000Y
28855601A5K27GA00003LB002000HNZ   0000060600Y
28855613X2K27G600003Y002000
28855635A2K27G6000041B002000BBT   0000044200Y
28855641A5K27GA00003MB002000HOT   0000062300Y
28855656X3K27G600005D002000
28855668A6K27GA00006OB002000JCI   0000044300Y
28855673A3K27G600005JB002000COH   0000046700Y
28855696A7K27GA00002TB002000LXK   0000335800Y
28855700AAK27GA0000TLS000500SPY   0001426000Y
28855702A4K27GA0000B5B002000EIX   0000066800Y
28855717A4K27GA0000B6B002000FDX   0000877800Y
28855717A7K27GA00002UB002000MAR   0000330600Y
28855738A5K27GA00003NB002000HNZ   0000061400Y
28855748X6K27GA00006I002000
28855756A5K27GA00003OB002000HOT   0000063100Y
28856093AAK27GA0000TMB002000SPY   0001425400Y
28856093XAK27GA0000Q8000500
28856093AAK27GA0000Q8S000500SPY   0001426000Y
28856093XAK27GA0000TI001000
28856094AAK27GA0000TNB001000SPY   0001425400Y
28856094ABK27GA0000GGB001000SSO   0000764100Y
28856243XAK27GA0000EB001000
28856243AAK27GA0000EBB001000SPY   0001425500Y
28856243XAK27GA0000TM002000
28856243AAK27GA0000TMB002000SPY   0001425500Y
28856243XAK27GA0000TN001000
28856243AAK27GA0000TNB001000SPY   0001425500Y
28856373X5K27GA00002N002000
28856376X2K27G600003Z002000
28856411X7K27GA00002R002000
28856423X7K27GA00002S002000
28856423AAK27GA0000TOB002000SHLD  0000727400Y
28856446A7K27GA00002VB002000MMM   0000763100Y
28856450XCK27GA00002S002000
28856452A7K27GA00002WB002000MMM   0000763900Y
28856460AAK27GA0000TPB002000SPLS  0000026000Y
28856463ABK27GA0000GHB002000UTX   0000104300Y
28856480XAK27GA0000TG001000
28856482XBK27GA0000GB001000
28856484ABK27GA0000GIS001000SSO   0000765300Y
28856493XAK27GA0000TJ001000
28856494X1K27GA00004X002000
28856501X1K27GA00004Y002000
28856508ABK27GA0000GJB002000UTX   0000105100Y
28856530AAK27GA0000TQS001000SPY   0001426000Y
28856528ACK27GA00002TB002000WYE   0000059100Y
28856552X2K27G600003Q002000
28856568A1K27GA00004ZB002000ABT   0000078300Y
28856580A2K27G6000042B002000AXP   0000403500Y
28856594X4K27GA0000B5002000
28856599A2K27G6000043B002000CAG   0000028100Y
28856610X5K27GA00003N002000
28856611A1K27GA000050B002000ABT   0000077400Y
28856624X5K27GA00003O002000
28856629X2K27G600003T002000
28856632X2K27G6000040002000
28856645A3K27G600005KB002000CVS   0000058400Y
28856649A2K27G6000044B002000AXP   0000402700Y
28856659A2K27G6000045B002000BBT   0000044300Y
28856666X3K27G600005I002000
28856680A3K27G600005LB002000COH   0000046900Y
28856683A6K27GA00006PB002000JCI   0000046100Y
28856702X5K27GA00002X002000
28856704X5K27GA00003L002000
28856709X5K27GA00003M002000
28856727A4K27GA0000B7B002000EIX   0000067400Y
28857099X4K27GA00009K000200
28857103A4K27GA0000B8S000200DIA   0001299300Y
28857126A9K27G60000N8S001000QID   0000381900Y
28857126A9K27G60000N9B001000QLD   0000889100Y
28857126A9K27G60000NAS002000QQQQ  0000496100Y
28857126A9K27G60000NBS001000QID   0000382000Y
28857126X9K27G60000FZ002000
28857126X9K27G60000NB001000
28857126A9K27G60000NCB001000QLD   0000889200Y
28857126X9K27G60000N9001000
28857126A9K27G60000NDS000100QID   0000382200Y
28857128A9K27G60000NES002000QQQQ  0000496100Y
28857132X9K27G60000NC001000
28857132A9K27G60000NFB001000QLD   0000889300Y
28857132AAK27GA0000TRS001000SDS   0000548900Y
28857133XBK27GA0000GE001000
28857133ABK27GA0000GKB001000SSO   0000764400Y
28857134A9K27G60000NGB001000QQQQ  0000495400Y
28857135XAK27GA0000O8000500
28857135AAK27GA0000O8S000500SPY   0001426100Y
28857139X9K27G60000NG001000
28857139X9K27G60000N6002000
28857150X9K27G60000F6003200
28857150A9K27G60000F6S003200QQQQ  0000496400Y
28857151X9K27G60000GG002000
28857151A9K27G60000NHS002000QQQQ  0000496200Y
28857151X9K27G60000FO002000
28857152A9K27G60000NIB002000QQQQ  0000495800Y
28857152A9K27G60000NJS002000QQQQ  0000496200Y
28857153X9K27G60000LM001000
28857153A9K27G60000NKB001000QLD   0000889200Y
28857166X9K27G60000FH005000
28857166X9K27G60000EW005000
28857167A9K27G60000NLB005000QQQQ  0000495800Y
28857167A9K27G60000NMB005000QQQQ  0000495800Y
28857168AAK27GA0000TSS001000SPY   0001426100Y
28857168XAK27GA0000S9001000
28857170AAK27GA0000TTS001000SPY   0001426100Y
28857174X4K27GA00003H000200
28857174A4K27GA00003HB000200DIA   0001298900Y
28857174X4K27GA0000B0000047
28857176X4K27GA00008I000100
28857176A4K27GA0000B9S000100DXD   0000500000Y
28857177A3K27G600005MB000100DDM   0000801300Y
28857177X3K27G600003U000100
28857177A4K27GA0000BAS000047DIA   0001299400Y
28857183X4K27GA000091000100
28857184X3K27G600005F000100
28857185A4K27GA0000BBB000100DXD   0000499000Y
28857185A3K27G600005NS000100DDM   0000802800Y
28857185X6K27GA00002B000500
28857185A6K27GA00002BS000500IWM   0000737200Y
28857206X4K27GA0000BA000047
28857208X9K27G60000EO002000
28857208A9K27G60000EOB002000QQQQ  0000495800Y
28857208A4K27GA0000BCS000047DIA   0001299100Y
28857213X3K27G600005N000100
28857215A3K27G600005OS000100DDM   0000802900Y
28857223X3K27G600005O000100
28857223A3K27G600005PS000100DDM   0000802800Y
28857227X6K27GA00004T000500
28857227A6K27GA00004TB000500IWM   0000736700Y
28857230ABK27GA0000GLB000100UWM   0000542700Y
28857230ABK27GA0000GMS000100TWM   0000701700Y
28857230XBK27GA0000GD000100
28857230XBK27GA0000E0000100
28857232XBK27GA0000GM000100
28857231X6K27GA00004T000500
28857231A6K27GA00004TB000500IWM   0000736300Y
28857234ABK27GA0000GNS000100TWM   0000702000Y
28857235XBK27GA0000GL000100
28857235XBK27GA0000GG001000
28857235ABK27GA0000GOB001000SSO   0000764200Y
28857235XBK27GA0000GN000100
28857234X6K27GA00004T000500
28857234A6K27GA00004TB000500IWM   0000736700Y
28857237ABK27GA0000GPB000100UWM   0000542700Y
28857235A6K27GA00006QB000100IWM   0000736200Y
28857235X6K27GA00006Q000100
28857235X6K27GA00004T000500
28857235A6K27GA00004TB000500IWM   0000736300Y
28857237ABK27GA0000GQS000100TWM   0000702000Y
28857239XBK27GA0000GQ000100
28857239XBK27GA0000GP000100
28857241ABK27GA0000GRS000100TWM   0000702200Y
28857244X6K27GA00004T000500
28857244A6K27GA00004TB000500IWM   0000736700Y
28857246XBK27GA0000GR000100
28857246ABK27GA0000GSS000100TWM   0000702000Y
28857247ABK27GA0000GTB000100UWM   0000542700Y
28857246X6K27GA00004T000500
28857246A6K27GA00004TB000500IWM   0000736300Y
28857256X6K27GA00004T000500
28857256A6K27GA00004TB000500IWM   0000736700Y
28857258XBK27GA0000GT000100
28857258XBK27GA0000GS000100
28857258XBK27GA0000F4000100
28857258XBK27GA0000EV000100
28857258XBK27GA0000F6000100
28857256A6K27GA00006RS002000IWM   0000737200Y
28857259ABK27GA0000GUB000100UWM   0000542700Y
28857260ABK27GA0000GVB000100TWM   0000700500Y
28857260ABK27GA0000GWS000100TWM   0000702000Y
28857260ABK27GA0000GXB000100TWM   0000700600Y
28857260ABK27GA0000GYS000100UWM   0000543700Y
28857298X9K27G60000NM005000
28857298X9K27G60000NL005000
28857301A9K27G60000NNB005000QQQQ  0000495400Y
28857301A9K27G60000NOB005000QQQQ  0000495400Y
28857344X1K27GA000014002000
28857378X6K27GA00006N002000
28857384X5K27GA000015002000
28857384X5K27GA000019002000
28857395XBK27GA0000BK002000
28857402XBK27GA0000GJ002000
28857415XBK27GA0000GH002000
28857423X1K27GA00004Z002000
28857430XAK27GA0000TO002000
28857429XCK27GA00002T002000
28857437A5K27GA00003PS000100GOOG  0005793400Y
28857443X9K27G60000NN005000
28857443X9K27G60000EY005000
28857443X9K27G60000NO005000
28857443X9K27G60000FK005000
28857443A9K27G60000NPB005000QQQQ  0000495800Y
28857443A9K27G60000NQB005000QQQQ  0000495800Y
28857444A9K27G60000NRS005000QQQQ  0000496300Y
28857445A9K27G60000NSS005000QQQQ  0000496300Y
28857446X3K27G600005C002000
28857451X9K27G60000ET002000
28857451A9K27G60000ETS002000QQQQ  0000496200Y
28857452X9K27G60000GA002000
28857456X1K27GA000050002000
28857457X2K27G6000041002000
28857466X1K27GA00001O002000
28857472X3K27G600005J002000
28857492X4K27GA0000B7002000
28857501X3K27G600005K002000
28857501XAK27GA0000SS002000
28857535A2K27G6000046B002000BMY   0000026500Y
28857536X6K27GA00006O002000
28857549A5K27GA00003QB002000GM    0000174500Y
28857557A7K27GA00002XB002000LMT   0000164300Y
28857561A7K27GA00002YB002000LMT   0000165100Y
28857575A1K27GA000051B002000AFL   0000098000Y
28857584A2K27G6000047B002000BDX   0000761100Y
28857590A2K27G6000048B002000CAG   0000028000Y
28857591ACK27GA00002UB002000WYE   0000061200Y
28857595X6K27GA00004T000500
28857599XBK27GA0000GU000100
28857599XBK27GA0000GW000100
28857601ABK27GA0000GZS000100TWM   0000702200Y
28857600A6K27GA00006SB000500IWM   0000736700Y
28857603ABK27GA0000H0B000100UWM   0000542700Y
28857603XBK27GA0000GZ000100
28857603ABK27GA0000H1S000100TWM   0000702000Y
28857606A3K27G600005QB002000CVS   0000058800Y
28857605X6K27GA00006S000500
28857605A6K27GA00006SB000500IWM   0000736300Y
28857609XBK27GA0000H0000100
28857609XBK27GA0000H1000100
28857609A1K27GA000052B002000AFL   0000098800Y
28857611ABK27GA0000H2S000100TWM   0000702200Y
28857615X6K27GA00006S000500
28857615A6K27GA00006SB000500IWM   0000736700Y
28857618A5K27GA00003RB002000HMY   0000085100Y
28857619ABK27GA0000H3B000100UWM   0000542700Y
28857619XBK27GA0000H2000100
28857619ABK27GA0000H4S000100TWM   0000702000Y
28857621A2K27G6000049B002000BDX   0000761900Y
28857626A5K27GA00003SB002000HNZ   0000063100Y
28857626X6K27GA00006S000500
28857626A6K27GA00006SB000500IWM   0000736300Y
28857629XBK27GA0000H3000100
28857629XBK27GA0000H4000100
28857631ABK27GA0000H5S000100TWM   0000702200Y
28857630X6K27GA00006S000500
28857630A6K27GA00006SB000500IWM   0000736700Y
28857633ABK27GA0000H6B000100UWM   0000542700Y
28857633ABK27GA0000H7S000100TWM   0000702000Y
28857633XBK27GA0000H5000100
28857635X6K27GA00006S000500
28857635A6K27GA00006SB000500IWM   0000736300Y
28857639XBK27GA0000H6000100
28857639XBK27GA0000H7000100
28857638A4K27GA0000BDB002000EIX   0000069600Y
28857639A6K27GA00006TB000100IWM   0000736200Y
28857641ABK27GA0000H8S000100TWM   0000702200Y
28857639X6K27GA00006T000100
28857640X6K27GA00006S000500
28857640A6K27GA00006SB000500IWM   0000736700Y
28857643ABK27GA0000H9B000100UWM   0000542700Y
28857643ABK27GA0000HAS000100TWM   0000702000Y
28857643XBK27GA0000H8000100
28857646A5K27GA00003TB002000HOT   0000065000Y
28857646X6K27GA00006S000500
28857646A6K27GA00006SB000500IWM   0000736300Y
28857646A6K27GA00006US010000IOM   0000038400Y
28857649XBK27GA0000H9000100
28857649XBK27GA0000HA000100
28857649A5K27GA00003UB002000HNZ   0000063900Y
28857649A6K27GA00006VB000100IWM   0000736200Y
28857649X6K27GA00006V000100
28857651ABK27GA0000HBS000100TWM   0000702200Y
28857650X6K27GA00006S000500
28857650A6K27GA00006SB000500IWM   0000736700Y
28857653XBK27GA0000HB000100
28857653ABK27GA0000HCS000100TWM   0000702000Y
28857653ABK27GA0000HDB000100UWM   0000542700Y
28857655X6K27GA00006S000500
28857655A6K27GA00006SB000500IWM   0000736300Y
28857659XBK27GA0000HD000100
28857659XBK27GA0000HC000100
28857659A7K27GA00002ZB002000MAS   0000167500Y
28857661ABK27GA0000HES000100TWM   0000702200Y
28857663A5K27GA00003VB002000HOT   0000065800Y
28857664X6K27GA00006S000500
28857664A6K27GA00006SB000500IWM   0000736700Y
28857665X6K27GA00006S000500
28857665A6K27GA00006SB000500IWM   0000736300Y
28857667ABK27GA0000HFB000100UWM   0000542700Y
28857667ABK27GA0000HGS000100TWM   0000702000Y
28857667XBK27GA0000HE000100
28857669XBK27GA0000HF000100
28857669XBK27GA0000HG000100
28857671ABK27GA0000HHS000100TWM   0000702200Y
28857674X6K27GA00006S000500
28857674A6K27GA00006SB000500IWM   0000736700Y
28857676A7K27GA000030B002000MAT   0000184100Y
28857677ABK27GA0000HIB000100UWM   0000542700Y
28857675X6K27GA00006S000500
28857675A6K27GA00006SB000500IWM   0000736300Y
28857677ABK27GA0000HJS000100TWM   0000702000Y
28857677XBK27GA0000HH000100
28857679XBK27GA0000HI000100
28857679XBK27GA0000HJ000100
28857681ABK27GA0000HKS000100TWM   0000702200Y
28857686X6K27GA00006S000500
28857686A6K27GA00006SB000500IWM   0000736700Y
28857690X6K27GA00006S000500
28857690A6K27GA00006SB000500IWM   0000736300Y
28857693A7K27GA000031B002000KMB   0000611900Y
28857696X6K27GA00006S000500
28857696A6K27GA00006SB000500IWM   0000736700Y
28857706X6K27GA00006S000500
28857706A6K27GA00006SB000500IWM   0000736300Y
28857716X6K27GA00006S000500
28857716A6K27GA00006SB000500IWM   0000736700Y
28857720A7K27GA000032B002000KMX   0000186900Y
28857726X6K27GA00006S000500
28857726A6K27GA00006SB000500IWM   0000736300Y
28857736X6K27GA00006S000500
28857736A6K27GA00006SB000500IWM   0000736700Y
28857746X6K27GA00006S000500
28857746A6K27GA00006SB000500IWM   0000736300Y
28857756X6K27GA00006S000500
28857756A6K27GA00006SB000500IWM   0000736700Y
28857766X6K27GA00006S000500
28857766A6K27GA00006SB000500IWM   0000736300Y
28857776X6K27GA00006S000500
28857776A6K27GA00006SB000500IWM   0000736700Y
28857778A9K27G60000NTB000500QQQQ  0000495200Y
28857786X6K27GA00006S000500
28857786A6K27GA00006SB000500IWM   0000736300Y
28857796X6K27GA00006S000500
28857796A6K27GA00006SB000500IWM   0000736700Y
28857806X6K27GA00006S000500
28857806A6K27GA00006SB000500IWM   0000736300Y
28857816X6K27GA00006S000500
28857816A6K27GA00006SB000500IWM   0000736700Y
28857826X6K27GA00006S000500
28857826A6K27GA00006SB000500IWM   0000736300Y
28857836X6K27GA00006S000500
28857836A6K27GA00006SB000500IWM   0000736700Y
28857846X6K27GA00006S000500
28857846A6K27GA00006SB000500IWM   0000736300Y
28857856X6K27GA00006S000500
28857856A6K27GA00006SB000500IWM   0000736700Y
28857866X6K27GA00006S000500
28857866A6K27GA00006SB000500IWM   0000736300Y
28857876X6K27GA00006S000500
28857876A6K27GA00006SB000500IWM   0000736700Y
28857883A9K27G60000NUB002000QQQQ  0000495600Y
28857883X9K27G60000IV002000
28857883X9K27G60000IW002000
28857886X6K27GA00006S000500
28857886A6K27GA00006SB000500IWM   0000736300Y
28857896X6K27GA00006S000500
28857896A6K27GA00006SB000500IWM   0000736700Y
28857906X6K27GA00006S000500
28857906A6K27GA00006SB000500IWM   0000736300Y
28857916X6K27GA00006S000500
28857916A6K27GA00006SB000500IWM   0000736700Y
28857926X6K27GA00006S000500
28857926A6K27GA00006SB000500IWM   0000736300Y
28857936X6K27GA00006S000500
28857936A6K27GA00006SB000500IWM   0000736700Y
28857946X6K27GA00006S000500
28857946A6K27GA00006SB000500IWM   0000736300Y
28857956X6K27GA00006S000500
28857956A6K27GA00006SB000500IWM   0000736700Y
28857989X9K27G60000NR005000
28857989X9K27G60000NP005000
28857989X9K27G60000NS005000
28857989A9K27G60000NVS005000QQQQ  0000495900Y
28857990A9K27G60000NWS005000QQQQ  0000495900Y
28857990A9K27G60000NXS002000QQQQ  0000495900Y
28857991A9K27G60000NYB005000QQQQ  0000495400Y
28857991X9K27G60000ET002000
28857991A9K27G60000ETS002000QQQQ  0000495900Y
28857994X9K27G60000NU002000
28858026X9K27G60000NY005000
28858027A9K27G60000NZB005000QQQQ  0000495800Y
28858028A9K27G60000O0S002000QQQQ  0000496000Y
28858036X9K27G60000NV005000
28858037X9K27G60000NW005000
28858038X9K27G60000O0002000
28858038A9K27G60000O1S005000QQQQ  0000495900Y
28858038A9K27G60000O2S005000QQQQ  0000495900Y
28858048XAK27GA0000E6001000
28858048AAK27GA0000E6S001000SPY   0001426100Y
28858048XAK27GA0000E8001000
28858048AAK27GA0000E8B001000SPY   0001425600Y
28858048XAK27GA0000FG000500
28858048AAK27GA0000FGB000500SPY   0001425500Y
28858048XAK27GA0000F7000500
28858048AAK27GA0000F7B000500SPY   0001425500Y
28858048XAK27GA0000NZ000500
28858048AAK27GA0000NZS000500SPY   0001426100Y
28858049XAK27GA0000Q6002000
28858049AAK27GA0000Q6B002000SPY   0001425600Y
28858049X4K27GA0000BC000047
28858049XAK27GA0000QD000200
28858050AAK27GA0000TUB001000SPY   0001425600Y
28858051X3K27G600005P000100
28858053A3K27G600005RS000100DDM   0000802900Y
28858053A4K27GA0000BES000047DIA   0001299400Y
28858053X4K27GA00009H000100
28858053X3K27G600005R000100
28858055A3K27G600005SS000100DDM   0000803000Y
28858055A4K27GA0000BFB000100DOG   0000596800Y
28858077ABK27GA0000HLB000100UWM   0000542700Y
28858077XBK27GA0000HK000100
28858077ABK27GA0000HMS000100TWM   0000702000Y
28858076X6K27GA00006S000500
28858076A6K27GA00006SB000500IWM   0000736300Y
28858078X6K27GA00006S000500
28858078A6K27GA00006SB000500IWM   0000736700Y
28858079A6K27GA00006WB002000IWM   0000736600Y
28858079X6K27GA000056002000
28858080X6K27GA00006S000500
28858080A6K27GA00006SB000500IWM   0000736300Y
28858084XAK27GA0000PK003000
28858084XAK27GA0000FI000500
28858084AAK27GA0000FIB000500SPY   0001425600Y
28858084XAK27GA0000F5000500
28858084AAK27GA0000F5B000500SPY   0001425600Y
28858084XAK27GA0000Q4003000
28858084XAK27GA0000NY000500
28858084AAK27GA0000NYS000500SPY   0001426200Y
28858084XAK27GA0000Q7001000
28858084XAK27GA0000PL003000
28858084XAK27GA0000T4002000
28858084XAK27GA0000QB000500
28858084AAK27GA0000QBS000500SPY   0001426200Y
28858084X4K27GA0000B1000200
28858084X4K27GA000062000200
28858084A4K27GA000062B000200DIA   0001299000Y
28858084AAK27GA0000TVB003000SPY   0001425600Y
28858084XAK27GA0000Q9003000
28858084XAK27GA0000E9001000
28858084AAK27GA0000E9S001000SPY   0001426200Y
28858084XAK27GA0000TT001000
28858085AAK27GA0000TWB002000SPY   0001425600Y
28858085XAK27GA0000SP001000
28858085XAK27GA0000SO001000
28858085AAK27GA0000TXB003000SPY   0001425600Y
28858085AAK27GA0000TYS003000SPY   0001426600Y
28858086AAK27GA0000TZB002000SPY   0001425600Y
28858086AAK27GA0000U0S001000SPY   0001426100Y
28858086ABK27GA0000HNB001000SSO   0000764600Y
28858086AAK27GA0000U1S003000SPY   0001426600Y
28858086XAK27GA0000PF001000
28858086XBK27GA0000GK001000
28858086AAK27GA0000U2S001000SDS   0000548800Y
28858086XAK27GA0000QS001000
28858087X3K27G600003X000100
28858086A4K27GA0000BGS000100DXD   0000499900Y
28858086A4K27GA0000BHS000100DOG   0000598200Y
28858086X4K27GA00008W000100
28858087X4K27GA00003S000100
28858087XBK27GA0000GI001000
28858087A3K27G600005TB000100DDM   0000801500Y
28858087XBK27GA0000HL000100
28858087XAK27GA0000E7001000
28858087AAK27GA0000E7B001000SPY   0001425600Y
28858086X6K27GA00006S000500
28858086A6K27GA00006SB000500IWM   0000736700Y
28858087XAK27GA0000QG000200
28858087XBK27GA0000HM000100
28858087AAK27GA0000U3B001000SPY   0001425600Y
28858088AAK27GA0000U4S001000SPY   0001426200Y
28858088A4K27GA0000BIS000200DIA   0001299500Y
28858088X6K27GA00006S000500
28858088A6K27GA00006SB000500IWM   0000736300Y
28858089ABK27GA0000HOS001000SSO   0000765400Y
28858089ABK27GA0000HPB000100UWM   0000542700Y
28858089ABK27GA0000HQS000100TWM   0000702000Y
28858091XAK27GA0000TL000500
28858091AAK27GA0000U5B000500SPY   0001425600Y
28858091XAK27GA0000TK000500
28858092XAK27GA0000GG000100
28858092XBK27GA0000HO001000
28858094ABK27GA0000HRS001000SSO   0000765500Y
28858094AAK27GA0000U6B000100SH    0000618200Y
28858095ABK27GA0000HSS001000SSO   0000766400Y
28858095X6K27GA00006S000500
28858095A6K27GA00006SB000500IWM   0000736700Y
28858097XBK27GA0000HP000100
28858097XBK27GA0000HQ000100
28858099ABK27GA0000HTB000100UWM   0000542700Y
28858100ABK27GA0000HUS000100TWM   0000702000Y
28858102X6K27GA00005K002000
28858105XAK27GA0000TW002000
28858106AAK27GA0000U7B001000SPY   0001425500Y
28858121A8K27G600002TS000500MZZ   0000493700Y
28858121A8K27G600002UB000100MVV   0000806500Y
28858120X9K27G60000O1005000
28858121X9K27G60000G3002000
28858121A9K27G60000G3S002000QQQQ  0000496400Y
28858121X9K27G60000O2005000
28858121X9K27G60000ET002000
28858121A9K27G60000ETS002000QQQQ  0000496200Y
28858121X9K27G60000NX002000
28858122A9K27G60000O3S005000QQQQ  0000496300Y
28858122A9K27G60000O4S005000QQQQ  0000496300Y
28858122XAK27GA0000TZ002000
28858126X9K27G60000G6002000
28858126A9K27G60000G6B002000QQQQ  0000495800Y
28858132A9K27G60000O5S002000QQQQ  0000496100Y
28858133AAK27GA0000U8B002000SPY   0001425600Y
28858133XAK27GA0000U7001000
28858133XAK27GA0000TS001000
28858133AAK27GA0000U9S001000SPY   0001426200Y
28858133XAK27GA0000T7001000
28858133XAK27GA0000U9001000
28858135X8K27G600002O000100
28858135X8K27G600002N000100
28858135X8K27G6000026000500
28858135AAK27GA0000UAS001000SPY   0001426300Y
28858135AAK27GA0000UBS001000SPY   0001426300Y
28858136A8K27G600002VB000500MZZ   0000491300Y
28858137A8K27G600002WS000100MVV   0000809800Y
28858153XAK27GA0000IC001000
28858154XBK27GA0000HR001000
28858155AAK27GA0000UCB001000SDS   0000547400Y
28858156ABK27GA0000HVS001000SSO   0000765600Y
28858164XAK27GA0000PY000100
28858164AAK27GA0000UDB000100SPY   0001424600Y
28858184XBK27GA0000HS001000
28858189XAK27GA0000TV003000
28858189AAK27GA0000TVB003000SPY   0001425700Y
28858189XAK27GA0000TX003000
28858189AAK27GA0000TXB003000SPY   0001425700Y
28858189XAK27GA0000E7001000
28858189AAK27GA0000E7B001000SPY   0001425700Y
28858189XAK27GA0000U3001000
28858189AAK27GA0000U3B001000SPY   0001425700Y
28858204X9K27G60000F5003200
28858204A9K27G60000F5B003200QQQQ  0000495800Y
28858232XAK27GA0000DT000100
28858232AAK27GA0000UES000100SH    0000618800Y
28858233XAK27GA0000PH001000
28858233AAK27GA0000UFS001000SDS   0000548700Y
28858293AAK27GA0000UGS000500SPY   0001426200Y
28858402X5K27GA00002S002000
28858402X7K27GA00002X002000
28858404X7K27GA00002Q002000
28858407X9K27G60000MU002000
28858409X7K27GA00002Y002000
28858423A1K27GA000053B002000AMZN  0000798900Y
28858424XCK27GA00002U002000
28858438A5K27GA00003WB002000GS    0001817600Y
28858443X1K27GA000052002000
28858460X2K27G6000043002000
28858479X4K27GA0000BD002000
28858490ABK27GA0000HWB002000TGT   0000518000Y
28858489A6K27GA00006XB002000IMCL  0000340900Y
28858491X5K27GA000031002000
28858511ABK27GA0000HXB002000UTX   0000108300Y
28858512X5K27GA00003U002000
28858525X5K27GA00003V002000
28858534AAK27GA0000UHB002000SHLD  0000732500Y
28858539X6K27GA00006P002000
28858562A5K27GA00003XB002000GS    0001818400Y
28858560ACK27GA00002VB002000WYE   0000061500Y
28858577A3K27G600005UB002000CTSH  0000041100Y
28858594AAK27GA0000UIB002000SNDK  0000224800Y
28858610ABK27GA0000HYB002000UTX   0000109100Y
28858612X1K27GA000051002000
28858612A1K27GA000054B002000ABT   0000080500Y
28858647A1K27GA000055B002000ABT   0000081300Y
28858649X2K27G6000045002000
28858657A1K27GA000056B002000ACF   0000118500Y
28858664X3K27G600005L002000
28858671X3K27G600005Q002000
28858684A2K27G600004AB002000BBT   0000047000Y
28858698A4K27GA0000BJB002000EIX   0000070200Y
28858706X5K27GA00003S002000
28858707A3K27G600005VB002000COH   0000049700Y
28858718X5K27GA00003T002000
28858733A3K27G600005WB002000CVS   0000060800Y
28858762A6K27GA00006YB002000JCI   0000047200Y
28858773A7K27GA000033B002000MAY   0000091400Y
28858792A7K27GA000034B002000LEN   0000181700Y
28859002A9K27G60000O6B004000QQQQ  0000495600Y
28859143XAK27GA0000O2000500
28859143AAK27GA0000O2S000500SPY   0001426300Y
28859156X9K27G60000F8003200
28859156A9K27G60000F8S003200QQQQ  0000496500Y
28859157X9K27G60000KH002000
28859158XBK27GA0000HN001000
28859158ABK27GA0000HZB001000SSO   0000764700Y
28859157XAK27GA0000F2000500
28859157AAK27GA0000F2B000500SPY   0001425700Y
28859157A9K27G60000O7B002000QQQQ  0000495800Y
28859159A9K27G60000O8S001000QID   0000381800Y
28859159A9K27G60000O9B001000QLD   0000889500Y
28859159X9K27G60000KL001000
28859160A9K27G60000OAS000100QID   0000382100Y
28859162X9K27G60000O9001000
28859162A9K27G60000OBB001000QLD   0000889700Y
28859163A9K27G60000OCS000100QID   0000382000Y
28859174X9K27G60000O7002000
28859174A9K27G60000O7B002000QQQQ  0000495900Y
28859182A9K27G60000ODB001000QLD   0000889600Y
28859182X9K27G60000M0001000
28859192XAK27GA0000F2000500
28859192AAK27GA0000F2B000500SPY   0001425300Y
28859197X6K27GA000026000500
28859197A6K27GA000026S000500IWM   0000737300Y
28859207XBK27GA0000GY000100
28859207XBK27GA0000F5000100
28859207XBK27GA0000GX000100
28859206A6K27GA00006ZS002000IWM   0000737300Y
28859209ABK27GA0000I0S000100UWM   0000543800Y
28859209ABK27GA0000I1B000100TWM   0000700300Y
28859210ABK27GA0000I2B000100TWM   0000700400Y
28859383X6K27GA00004I002000
28859385XAK27GA0000UH002000
28859388XBK27GA0000HX002000
28859388X1K27GA00003L002000
28859408X2K27G6000046002000
28859410X1K27GA00001L002000
28859410XCK27GA00002V002000
28859429X1K27GA000054002000
28859437XBK27GA0000CK002000
28859440A7K27GA000035B002000LPNT  0000201200Y
28859446X2K27G6000031002000
28859451XBK27GA0000HY002000
28859452X2K27G6000048002000
28859460X4K27GA0000BJ002000
28859470A5K27GA00003YB002000GM    0000175500Y
28859472A9K27G60000OEB002000PDLI  0000020000Y
28859487A7K27GA000036B002000LMT   0000170300Y
28859504X1K27GA000055002000
28859535A7K27GA000037B002000LMT   0000171100Y
28859552X2K27G600002P002000
28859565AAK27GA0000UJB002500SPY   0001425600Y
28859576A1K27GA000057B002000AFL   0000101700Y
28859582X2K27G600002Z002000
28859591A2K27G600004BB002000BBT   0000047200Y
28859605A3K27G600005XB002000COH   0000049900Y
28859617A3K27G600005YB002000CVS   0000061100Y
28859624ACK27GA00002WB002000WYE   0000063600Y
28859630X3K27G600005W002000
28859634A5K27GA00003ZB002000HNZ   0000065700Y
28859651A5K27GA000040B002000HOT   0000067600Y
28859663A1K27GA000058B002000AFL   0000102500Y
28859675A2K27G600004CB002000CAG   0000030100Y
28859676A7K27GA000038B002000MCD   0000588000Y
28859705A4K27GA0000BKB002000EIX   0000072400Y
28859716A5K27GA000041B002000HMY   0000086100Y
28859724A5K27GA000042B002000HNZ   0000066500Y
28859732A5K27GA000043B002000HOT   0000068400Y
28859948ABK27GA0000I3B001000SSO   0000764500Y
28860395X7K27GA000037002000
28860398X2K27G600002G002000
28860403XAK27GA0000TP002000
28860406XCK27GA00002W002000
28860416X7K27GA000036002000
28860421AAK27GA0000UKB002000SHLD  0000735600Y
28860421X1K27GA000058002000
28860437X1K27GA000049002000
28860437X1K27GA000057002000
28860445X1K27GA000047002000
28860448X2K27G600002X002000
28860468X2K27G6000030002000
28860469A1K27GA000059B002000APOL  0000407500Y
28860471X2K27G600002U002000
28860472X2K27G600004A002000
28860490X3K27G600005Y002000
28860506A2K27G600004DB002000BMY   0000028400Y
28860508X5K27GA00003Z002000
28860525X5K27GA000040002000
28860539A1K27GA00005AB002000APPX  0000094500Y
28860544X2K27G600002W002000
28860545X6K27GA00006Y002000
28860556X3K27G600005V002000
28860578ABK27GA0000I4B002000TGT   0000518900Y
28860582X4K27GA0000BK002000
28860595X5K27GA000042002000
28860615X5K27GA000043002000
28860620A6K27GA000070B002000JNJ   0000640200Y
28860634ABK27GA0000I5B002000UTX   0000112300Y
28860635ABK27GA0000I6B002000UTX   0000113100Y
28860644ACK27GA00002XB002000WYE   0000064000Y
28860650A1K27GA00005BB002000ABT   0000084400Y
28860664A1K27GA00005CB002000ABT   0000083600Y
28860665A2K27G600004EB002000BK    0000426300Y
28860682A2K27G600004FB002000BNI   0001058800Y
28860682A2K27G600004GB002000BNI   0001059600Y
28860689A2K27G600004HB002000CAG   0000029900Y
28860699A3K27G600005ZB002000CVS   0000063100Y
28860709A4K27GA0000BLB002000EIX   0000073000Y
28860718A6K27GA000071B002000JCI   0000049900Y
28860736XBK27GA0000GA000500
28860739A7K27GA000039B002000MDY   0001573900Y
28860757A7K27GA00003AB002000MEE   0000623300Y
28861085XAK27GA0000O2000500
28861085AAK27GA0000O2S000500SPY   0001425900Y
28861085X4K27GA0000BI000200
28861085XAK27GA0000TY003000
28861085XAK27GA0000TX003000
28861085XAK27GA0000U1003000
28861085XAK27GA0000TV003000
28861086AAK27GA0000ULS003000SPY   0001426000Y
28861086AAK27GA0000UMS003000SPY   0001426000Y
28861086X4K27GA000062000200
28861086A4K27GA000062B000200DIA   0001298700Y
28861086XAK27GA0000QB000500
28861086AAK27GA0000QBS000500SPY   0001425900Y
28861086XAK27GA0000U8002000
28861086AAK27GA0000UNS002000SPY   0001426100Y
28861087XBK27GA0000I3001000
28861087XAK27GA0000F5000500
28861087AAK27GA0000F5B000500SPY   0001425200Y
28861087XAK27GA0000E7001000
28861087AAK27GA0000E7B001000SPY   0001425300Y
28861087AAK27GA0000UOB003000SPY   0001425000Y
28861087XAK27GA0000U3001000
28861087AAK27GA0000UPB003000SPY   0001425000Y
28861088AAK27GA0000UQB002000SPY   0001425500Y
28861089AAK27GA0000URB001000SPY   0001425300Y
28861089XAK27GA0000Q6002000
28861091XAK27GA0000UJ002500
28861091AAK27GA0000USB002500SPY   0001425500Y
28861092XAK27GA0000U5000500
28861092AAK27GA0000UTB000500SPY   0001425400Y
28861092XAK27GA0000UG000500
28861092A4K27GA0000BMS000200DIA   0001299200Y
28861093XAK27GA0000UE000100
28861093XAK27GA0000UF001000
28861094X3K27G600005T000100
28861093XBK27GA0000HZ001000
28861093X4K27GA0000BG000100
28861093X4K27GA0000BH000100
28861095ABK27GA0000I7B001000SSO   0000764600Y
28861112XAK27GA0000UQ001000
28861120A4K27GA0000BNB000100DOG   0000596900Y
28861120A3K27G6000060S000100DDM   0000802800Y
28861122XAK27GA0000F5000500
28861122AAK27GA0000F5B000500SPY   0001425600Y
28861122X4K27GA000062000200
28861122A4K27GA000062B000200DIA   0001299000Y
28861122XAK27GA0000E7001000
28861122AAK27GA0000E7B001000SPY   0001425700Y
28861122XAK27GA0000QB000500
28861122AAK27GA0000QBS000500SPY   0001426200Y
28861122XAK27GA0000UL003000
28861122XAK27GA0000UO003000
28861122XAK27GA0000UR001000
28861122XAK27GA0000UP003000
28861122XAK27GA0000UM003000
28861122AAK27GA0000UUB003000SPY   0001425600Y
28861122AAK27GA0000UVB003000SPY   0001425600Y
28861122XAK27GA0000UN002000
28861123AAK27GA0000UWB001000SPY   0001425700Y
28861123AAK27GA0000UXB002000SPY   0001425600Y
28861124A4K27GA0000BOS000100DOG   0000598200Y
28861124AAK27GA0000UYS003000SPY   0001426600Y
28861124A4K27GA0000BPS000100DXD   0000499900Y
28861124A3K27G6000061B000100DDM   0000801500Y
28861124AAK27GA0000UZS003000SPY   0001426600Y
28861124AAK27GA0000V0S002000SPY   0001426200Y
28861133AAK27GA0000V1S001000SDS   0000548700Y
28861134AAK27GA0000V2S000100SH    0000618800Y
28861135XAK27GA0000UB001000
28861135AAK27GA0000V3S001000SPY   0001426100Y
28861136XAK27GA0000UA001000
28861140X4K27GA000062000200
28861140A4K27GA000062B000200DIA   0001298700Y
28861142X4K27GA000062000200
28861142A4K27GA000062B000200DIA   0001299000Y
28861142XAK27GA0000O2000500
28861142AAK27GA0000O2S000500SPY   0001426300Y
28861142X4K27GA0000BO000100
28861143X3K27G6000061000100
28861142X4K27GA0000BP000100
28861143X4K27GA0000BN000100
28861143X4K27GA0000BM000200
28861143X3K27G6000060000100
28861143XAK27GA0000UX002000
28861144ABK27GA0000I8B001000SSO   0000764700Y
28861144XBK27GA0000I7001000
28861144A4K27GA0000BQS000100DOG   0000598200Y
28861145A3K27G6000062B000100DDM   0000801500Y
28861144A4K27GA0000BRS000100DXD   0000499900Y
28861148A4K27GA0000BSS000200DIA   0001299500Y
28861155XAK27GA0000V3001000
28861183X6K27GA000026000500
28861183A6K27GA000026S000500IWM   0000736900Y
28861185XAK27GA0000V0002000
28861186ABK27GA0000I9S000100UWM   0000543700Y
28861186ABK27GA0000IAB000100TWM   0000700700Y
28861186ABK27GA0000IBB000100TWM   0000700600Y
28861186AAK27GA0000V4S002000SPY   0001426300Y
28861194A4K27GA0000BTB000100DOG   0000596900Y
28861195A3K27G6000063S000100DDM   0000802800Y
28861231X6K27GA000026000500
28861231A6K27GA000026S000500IWM   0000737300Y
28861234X9K27G60000F8003200
28861234A9K27G60000F8S003200QQQQ  0000496000Y
28861237XBK27GA0000I9000100
28861237XBK27GA0000IB000100
28861237XBK27GA0000IA000100
28861313AAK27GA0000V5B005000SPY   0001425500Y
28861315AAK27GA0000V6S000500SPY   0001426200Y
28861315XAK27GA0000UT000500
28861355XAK27GA0000O2000500
28861355AAK27GA0000O2S000500SPY   0001425900Y
28861356X4K27GA0000BS000200
28861356XAK27GA0000T7001000
28861356AAK27GA0000V7B001000SPY   0001425600Y
28861357XAK27GA0000V5005000
28861357XBK27GA0000I8001000
28861359ABK27GA0000ICB001000SSO   0000764600Y
28861362A4K27GA0000BUS000200DIA   0001299200Y
28861371X3K27G600005H002000
28861374X7K27GA00001W002000
28861388X6K27GA00004Z002000
28861411X7K27GA00001X002000
28861421X3K27G600005U002000
28861429X4K27GA00004Q002000
28861441XBK27GA0000I5002000
28861445XBK27GA0000I6002000
28861454XCK27GA00002X002000
28861472X1K27GA00005B002000
28861476X1K27GA00005C002000
28861480AAK27GA0000V8B002000SPLS  0000029200Y
28861484X1K27GA00001Y002000
28861488X2K27G6000044002000
28861491AAK27GA0000V9B002500SPY   0001425600Y
28861492XAK27GA0000US002500
28861497X2K27G600004B002000
28861509X2K27G6000042002000
28861519AAK27GA0000VAB000500SPY   0001425600Y
28861530X3K27G600005X002000
28861531X2K27G600004C002000
28861546X4K27GA0000BL002000
28861548X3K27G600005Z002000
28861550XAK27GA0000O2000500
28861550AAK27GA0000O2S000500SPY   0001426300Y
28861550X4K27GA0000BU000200
28861551XAK27GA0000V7001000
28861552XAK27GA0000VA000500
28861552XAK27GA0000V9002500
28861553A4K27GA0000BVS000200DIA   0001299500Y
28861554XBK27GA0000IC001000
28861554ABK27GA0000IDB001000SSO   0000764700Y
28861566A2K27G600004IB002000BRL   0000372600Y
28861572XAK27GA0000O2000500
28861572AAK27GA0000O2S000500SPY   0001425900Y
28861572XAK27GA0000UZ003000
28861572XAK27GA0000UY003000
28861572X4K27GA0000BV000200
28861572AAK27GA0000VBS003000SPY   0001426000Y
28861572AAK27GA0000VCS003000SPY   0001426000Y
28861573XBK27GA0000ID001000
28861573XAK27GA0000QB000500
28861573AAK27GA0000QBS000500SPY   0001425900Y
28861574XAK27GA0000U4001000
28861575ABK27GA0000IES001000SSO   0000765500Y
28861575XBK27GA0000HV001000
28861575ABK27GA0000IFB001000SSO   0000764600Y
28861575AAK27GA0000VDS001000SPY   0001425900Y
28861576XAK27GA0000UW001000
28861576XAK27GA0000UC001000
28861576AAK27GA0000VEB001000SDS   0000547500Y
28861576XAK27GA0000F5000500
28861576AAK27GA0000F5B000500SPY   0001425200Y
28861582XAK27GA0000V1001000
28861582XAK27GA0000V2000100
28861582A4K27GA0000BWS000200DIA   0001299200Y
28861583A7K27GA00003BB002000LMT   0000176300Y
28861591X4K27GA000062000200
28861591A4K27GA000062B000200DIA   0001298700Y
28861591XAK27GA0000O2000500
28861591AAK27GA0000O2S000500SPY   0001426300Y
28861592X4K27GA0000BW000200
28861592AAK27GA0000VFB002000SPY   0001425700Y
28861592XAK27GA0000QB000500
28861592AAK27GA0000QBS000500SPY   0001426200Y
28861592XAK27GA0000F5000500
28861592AAK27GA0000F5B000500SPY   0001425600Y
28861592XAK27GA0000VD001000
28861592AAK27GA0000VGB001000SPY   0001425700Y
28861592XAK27GA0000VE001000
28861593XBK27GA0000IE001000
28861593X4K27GA000062000200
28861593A4K27GA000062B000200DIA   0001299000Y
28861593X4K27GA0000BQ000100
28861593X3K27G6000062000100
28861593X4K27GA0000BR000100
28861593AAK27GA0000VHS001000SPY   0001426200Y
28861594AAK27GA0000VIS000100SH    0000618800Y
28861594AAK27GA0000VJS001000SDS   0000548700Y
28861594ABK27GA0000IGB001000SSO   0000764700Y
28861594XBK27GA0000IF001000
28861594AAK27GA0000VKB001000SDS   0000547400Y
28861595ABK27GA0000IHS001000SSO   0000765600Y
28861595A4K27GA0000BXS000100DOG   0000598200Y
28861595A4K27GA0000BYS000100DXD   0000499900Y
28861595A1K27GA00005DB002000AFL   0000105400Y
28861596A3K27G6000064B000100DDM   0000801500Y
28861597A4K27GA0000BZS000200DIA   0001299500Y
28861601A1K27GA00005EB002000ARO   0000294500Y
28861607A2K27G600004JB002000AZN   0000417800Y
28861613A7K27GA00003CB002000LMT   0000177100Y
28861614A2K27G600004KB002000BK    0000425500Y
28861621A3K27G6000065B002000CVS   0000063500Y
28861628ACK27GA00002YB002000WYE   0000066000Y
28861637A5K27GA000044B002000HNZ   0000068200Y
28861644X4K27GA0000BZ000200
28861644XAK27GA0000VF002000
28861644XAK27GA0000O2000500
28861644AAK27GA0000O2S000500SPY   0001425900Y
28861645XAK27GA0000QB000500
28861645AAK27GA0000QBS000500SPY   0001425900Y
28861645XBK27GA0000IG001000
28861645XAK27GA0000VJ001000
28861646A1K27GA00005FB002000AFL   0000106200Y
28861647ABK27GA0000IIB001000SSO   0000764600Y
28861649A4K27GA0000C0S000200DIA   0001299200Y
28861652XAK27GA0000VI000100
28861653A5K27GA000045B002000HOT   0000070300Y
28861664A1K27GA00005GB002000ARO   0000295300Y
28861669A6K27GA000072B002000JCI   0000050000Y
28861677X4K27GA000062000200
28861677A4K27GA000062B000200DIA   0001298700Y
28861679X4K27GA0000BX000100
28861679X4K27GA0000BY000100
28861679X3K27G6000064000100
28861679XAK27GA0000O2000500
28861679AAK27GA0000O2S000500SPY   0001426300Y
28861679AAK27GA0000VLB002000SPY   0001425700Y
28861679XAK27GA0000QB000500
28861679AAK27GA0000QBS000500SPY   0001426200Y
28861679X4K27GA0000C0000200
28861679X4K27GA000062000200
28861679A4K27GA000062B000200DIA   0001299000Y
28861681A8K27G600002XB000500MZZ   0000491400Y
28861681A8K27G600002YS000100MVV   0000809600Y
28861682A3K27G6000066B000100DDM   0000801500Y
28861682XBK27GA0000II001000
28861681AAK27GA0000VMS000100SH    0000618800Y
28861681AAK27GA0000VNS001000SDS   0000548700Y
28861682ABK27GA0000IJB001000SSO   0000764700Y
28861681A4K27GA0000C1S000100DOG   0000598200Y
28861681A4K27GA0000C2S000100DXD   0000499900Y
28861681A4K27GA0000C3S000200DIA   0001299500Y
28861684XAK27GA0000VB003000
28861684XAK27GA0000VL002000
28861684XAK27GA0000O2000500
28861684AAK27GA0000O2S000500SPY   0001425900Y
28861684XAK27GA0000VC003000
28861684X4K27GA0000C3000200
28861685AAK27GA0000VOB001000SPY   0001425500Y
28861685XAK27GA0000QB000500
28861685AAK27GA0000QBS000500SPY   0001425900Y
28861685X4K27GA000062000200
28861685A4K27GA000062B000200DIA   0001298700Y
28861685XBK27GA0000IJ001000
28861685XAK27GA0000VN001000
28861685XAK27GA0000VM000100
28861686AAK27GA0000VPS003000SPY   0001426600Y
28861686AAK27GA0000VQS003000SPY   0001426600Y
28861687A2K27G600004LB002000AZN   0000418600Y
28861687ABK27GA0000IKB001000SSO   0000764600Y
28861689A4K27GA0000C4S000200DIA   0001299200Y
28861692AAK27GA0000VRS000100SH    0000618800Y
28861692XAK27GA0000VR000100
28861693X4K27GA0000C1000100
28861694X3K27G6000066000100
28861693X4K27GA0000C2000100
28861706X4K27GA000062000200
28861706A4K27GA000062B000200DIA   0001299000Y
28861709A4K27GA0000C5S000100DOG   0000598200Y
28861709A4K27GA0000C6S000100DXD   0000499900Y
28861710A3K27G6000067B000100DDM   0000801500Y
28861714A2K27G600004MB002000BBT   0000049900Y
28861718AAK27GA0000VSB005000SPY   0001425400Y
28861720AAK27GA0000VTB000500SPY   0001425600Y
28861724XAK27GA0000QB000500
28861724AAK27GA0000QBS000500SPY   0001425800Y
28861726XBK27GA0000IH001000
28861726ABK27GA0000ILS001000SSO   0000765500Y
28861727A2K27G600004NB002000CAT   0000816900Y
28861736A3K27G6000068B002000COH   0000052700Y
28861746A4K27GA0000C7B002000EIX   0000075300Y
28861839X6K27GA000026000500
28861839A6K27GA000026S000500IWM   0000736900Y
28861842ABK27GA0000IMS000100UWM   0000543700Y
28861842ABK27GA0000INB000100TWM   0000700700Y
28861842ABK27GA0000IOB000100TWM   0000700600Y
28861893AAK27GA0000VUB002500SPY   0001425600Y
28861901XAK27GA0000VP003000
28861901XAK27GA0000VQ003000
28861901XAK27GA0000VO001000
28861901AAK27GA0000VVS003000SPY   0001426000Y
28861901AAK27GA0000VWS003000SPY   0001426000Y
28861903XAK27GA0000VU002500
28861905XAK27GA0000VT000500
28861917X4K27GA000062000200
28861917A4K27GA000062B000200DIA   0001298700Y
28861919X4K27GA0000C5000100
28861919X4K27GA0000C6000100
28861920X3K27G6000067000100
28861922AAK27GA0000VXS000500SPY   0001426000Y
28861922XAK27GA0000V6000500
28861923XAK27GA0000O2000500
28861923AAK27GA0000O2S000500SPY   0001426300Y
28861923XAK27GA0000QB000500
28861923AAK27GA0000QBS000500SPY   0001426200Y
28861923AAK27GA0000VYB002000SPY   0001425700Y
28861923X4K27GA000062000200
28861923A4K27GA000062B000200DIA   0001299000Y
28861924X4K27GA0000C4000200
28861925A4K27GA0000C8S000100DOG   0000598200Y
28861925A4K27GA0000C9S000100DXD   0000499900Y
28861926A3K27G6000069B000100DDM   0000801500Y
28861926A4K27GA0000CAS000200DIA   0001299500Y
28861931XAK27GA0000VX000500
28861932XBK27GA0000IL001000
28861934ABK27GA0000IPS001000SSO   0000765600Y
28861966X1K27GA00000Y000100
28861966A1K27GA00000YS000100AAPL  0001833400Y
28862031AAK27GA0000VZS000100SH    0000618800Y
28862031AAK27GA0000W0S001000SDS   0000548700Y
28862032XBK27GA0000IK001000
28862032ABK27GA0000IQB001000SSO   0000764700Y
28862037X6K27GA000026000500
28862037A6K27GA000026S000500IWM   0000737300Y
28862047XBK27GA0000IM000100
28862049XBK27GA0000IN000100
28862049XBK27GA0000IO000100
28862062X4K27GA0000CA000200
28862063XAK27GA0000VV003000
28862063XAK27GA0000VW003000
28862063XAK27GA0000O2000500
28862063AAK27GA0000O2S000500SPY   0001425900Y
28862063XAK27GA0000VY002000
28862063AAK27GA0000W1B001000SPY   0001425600Y
28862064AAK27GA0000W2S003000SPY   0001426600Y
28862064AAK27GA0000W3S003000SPY   0001426600Y
28862072XBK27GA0000IQ001000
28862072A4K27GA0000CBS000200DIA   0001299200Y
28862074ABK27GA0000IRB001000SSO   0000764600Y
28862112X4K27GA000062000200
28862112A4K27GA000062B000200DIA   0001298700Y
28862114X4K27GA0000C8000100
28862114X4K27GA0000C9000100
28862114X3K27G6000069000100
28862128AAK27GA0000W4S005000SPY   0001426400Y
28862129AAK27GA0000W5B000500SPY   0001425600Y
28862299AAK27GA0000W6B002500SPY   0001425600Y
28862330AAK27GA0000W7S000500SPY   0001426200Y
28862330ACK27GA00002ZB000737ZVZZT 0000000100Y
28862331XCK27GA00002Z000737
28862331ACK27GA00002ZB000737ZVZZT 0000000100Y
28862332XCK27GA00002Z000737
28862351A3K27G600006AB002000CELG  0000474900Y
28862366A3K27G600006BB002000CTSH  0000044500Y
28862371X2K27G600004D002000
28862414X7K27GA00003B002000
28862417A6K27GA000073B002000JNJ   0000641100Y
28862439X1K27GA00005D002000
28862439A4K27GA0000CCB002000FITB  0000178700Y
28862471X2K27G600004H002000
28862475X7K27GA00003C002000
28862482A7K27GA00003DB002000KSS   0000456000Y
28862484X2K27G6000034002000
28862490X3K27G6000065002000
28862497X5K27GA000044002000
28862500X5K27GA000045002000
28862505A7K27GA00003EB002000KSS   0000455200Y
28862517XCK27GA00002Y002000
28862525ABK27GA0000ISB002000UTX   0000117100Y
28862542ABK27GA0000ITB002000UTX   0000116300Y
28862553ACK27GA000030B002000WYE   0000066400Y
28862556A1K27GA00005HB002000ABT   0000087500Y
28862570X1K27GA00005F002000
28862573A1K27GA00005IB002000ACF   0000119400Y
28862584A1K27GA00005JB002000ABT   0000086600Y
28862597A2K27G600004OB002000AXP   0000404800Y
28862599A2K27G600004PB002000AXP   0000404000Y
28862611A2K27G600004QB002000BBT   0000050000Y
28862620A2K27G600004RB002000CAG   0000032000Y
28862629A3K27G600006CB002000COH   0000052800Y
28862643X3K27G600004V002000
28862657A4K27GA0000CDB002000EIX   0000075900Y
28862662AAK27GA0000W8B001000SPY   0001425600Y
28862667X4K27GA0000C7002000
28862670A3K27G600006DB002000CVS   0000065500Y
28862681X6K27GA000071002000
28863107XAK27GA0000VZ000100
28863107XAK27GA0000W8001000
28863107XAK27GA0000W0001000
28863107XAK27GA0000W1001000
28863108ABK27GA0000IUS001000SSO   0000765500Y
28863108XBK27GA0000IP001000
28863109AAK27GA0000W9S001000SPY   0001425900Y
28863109XAK27GA0000QB000500
28863109AAK27GA0000QBS000500SPY   0001425900Y
28863109XAK27GA0000VH001000
28863109AAK27GA0000WAB001000SPY   0001425500Y
28863109XAK27GA0000VK001000
28863109AAK27GA0000WBB001000SDS   0000547500Y
28863111XAK27GA0000WA001000
28863112AAK27GA0000WCB001000SPY   0001425600Y
28863130XAK27GA0000WC001000
28863132AAK27GA0000WDB001000SPY   0001425500Y
28863151XAK27GA0000W4005000
28863194XAK27GA0000W9001000
28863194AAK27GA0000W9S001000SPY   0001425800Y
28863194XAK27GA0000QB000500
28863194AAK27GA0000QBS000500SPY   0001425800Y
28863282X4K27GA000062000200
28863282A4K27GA000062B000200DIA   0001299000Y
28863282XAK27GA0000W9001000
28863282XAK27GA0000O2000500
28863282AAK27GA0000O2S000500SPY   0001426300Y
28863282XAK27GA0000WD001000
28863282AAK27GA0000WEB002000SPY   0001425700Y
28863282XAK27GA0000QB000500
28863282AAK27GA0000QBS000500SPY   0001426200Y
28863283AAK27GA0000WFS001000SPY   0001426200Y
28863283XAK27GA0000W3003000
28863283XAK27GA0000W2003000
28863284AAK27GA0000WGS003000SPY   0001426000Y
28863284A4K27GA0000CES000100DOG   0000598200Y
28863284AAK27GA0000WHS003000SPY   0001426000Y
28863284A4K27GA0000CFS000100DXD   0000499900Y
28863284A3K27G600006EB000100DDM   0000801500Y
28863284XAK27GA0000W5000500
28863284XAK27GA0000WB001000
28863285XAK27GA0000W6002500
28863286AAK27GA0000WIS000100SH    0000618800Y
28863286AAK27GA0000WJB002500SPY   0001425500Y
28863286AAK27GA0000WKB001000SDS   0000547400Y
28863286AAK27GA0000WLS001000SDS   0000548700Y
28863287AAK27GA0000WMB005000SPY   0001425500Y
28863288XAK27GA0000VS005000
28863292XBK27GA0000IU001000
28863294ABK27GA0000IVS001000SSO   0000765600Y
28863294ABK27GA0000IWS001000SSO   0000766700Y
28863326ABK27GA0000IXB001000SSO   0000764700Y
28863326XBK27GA0000IR001000
28863359XAK27GA0000E7001000
28863359AAK27GA0000E7B001000SPY   0001425300Y
28863359XAK27GA0000UU003000
28863359XAK27GA0000WE002000
28863359XAK27GA0000F5000500
28863359AAK27GA0000F5B000500SPY   0001425200Y
28863359X4K27GA000062000200
28863359A4K27GA000062B000200DIA   0001298700Y
28863359XAK27GA0000O2000500
28863359AAK27GA0000O2S000500SPY   0001425900Y
28863359XAK27GA0000FI000500
28863359AAK27GA0000FIB000500SPY   0001425200Y
28863359XAK27GA0000UV003000
28863359AAK27GA0000WNS002000SPY   0001426100Y
28863359X4K27GA0000BE000047
28863360XAK27GA0000QB000500
28863360AAK27GA0000QBS000500SPY   0001425800Y
28863360XAK27GA0000VG001000
28863360XBK27GA0000IX001000
28863360XAK27GA0000WF001000
28863360XAK27GA0000WI000100
28863360AAK27GA0000WOS001000SPY   0001425800Y
28863360XAK27GA0000WL001000
28863360XAK27GA0000WM005000
28863360AAK27GA0000WPB003000SPY   0001425000Y
28863361XAK27GA0000E9001000
28863361AAK27GA0000E9S001000SPY   0001425800Y
28863361XAK27GA0000NY000500
28863361AAK27GA0000NYS000500SPY   0001425800Y
28863361X4K27GA0000CE000100
28863361X4K27GA0000CF000100
28863362X3K27G600006E000100
28863362XBK27GA0000IV001000
28863361AAK27GA0000WQB003000SPY   0001425000Y
28863361XAK27GA0000WK001000
28863361AAK27GA0000WRB001000SDS   0000547500Y
28863362ABK27GA0000IYS001000SSO   0000765500Y
28863362AAK27GA0000WSB001000SPY   0001425300Y
28863362ABK27GA0000IZB001000SSO   0000764600Y
28863362AAK27GA0000WTB000500SPY   0001425400Y
28863362XAK27GA0000W7000500
28863363A4K27GA0000CGS000200DIA   0001299100Y
28863364XBK27GA0000IS002000
28863372X9K27G60000NF001000
28863371X6K27GA000026000500
28863371A6K27GA000026S000500IWM   0000736900Y
28863372X6K27GA00006S000500
28863372A6K27GA00006SB000500IWM   0000736300Y
28863374A9K27G60000OFB001000QQQQ  0000495400Y
28863374ABK27GA0000J0S000100UWM   0000543700Y
28863374ABK27GA0000J1B000100TWM   0000700700Y
28863374ABK27GA0000J2B000100TWM   0000700600Y
28863375X6K27GA00006S000500
28863375A6K27GA00006SB000500IWM   0000736700Y
28863377XBK27GA0000HT000100
28863377XBK27GA0000HU000100
28863377X9K27G60000OF001000
28863379ABK27GA0000J3B000100UWM   0000542700Y
28863379ABK27GA0000J4S000100TWM   0000702000Y
28863391X8K27G600002T000500
28863391X8K27G600002U000100
28863393A8K27G600002ZB000100MVV   0000806400Y
28863398A7K27GA00003FB002000LMT   0000182300Y
28863404X1K27GA00005H002000
28863414XAK27GA0000UQ001000
28863415XBK27GA0000IT002000
28863415A2K27G600004SB002000BMY   0000030200Y
28863415AAK27GA0000WUB001000SPY   0001425400Y
28863419XCK27GA000030002000
28863433X1K27GA00005J002000
28863434X2K27G600004M002000
28863440X2K27G6000049002000
28863442A4K27GA0000CHB000100DXD   0000499300Y
28863443A3K27G600006FS000100DDM   0000802700Y
28863455X3K27G6000068002000
28863464X2K27G6000047002000
28863474X3K27G600006D002000
28863477X3K27G6000053002000
28863484X4K27GA0000CD002000
28863499A7K27GA00003GB002000LMT   0000183100Y
28863499X6K27GA000072002000
28863506X6K27GA000060002000
28863509A1K27GA00005KB002000AFL   0000109100Y
28863511ACK27GA000031B002000WYE   0000068400Y
28863528A1K27GA00005LB002000AFL   0000109900Y
28863546A3K27G600006GB002000DD    0000456800Y
28863546A2K27G600004TB002000CAG   0000031900Y
28863551X6K27GA00006S000500
28863551A6K27GA00006SB000500IWM   0000736300Y
28863557XBK27GA0000J3000100
28863557XBK27GA0000J4000100
28863557A6K27GA000074B000100IWM   0000736200Y
28863558X6K27GA000074000100
28863559ABK27GA0000J5S000100TWM   0000702200Y
28863560ABK27GA0000J6B000100UWM   0000542700Y
28863560XBK27GA0000J5000100
28863560ABK27GA0000J7S000100TWM   0000702000Y
28863561A4K27GA0000CIB002000EIX   0000078100Y
28863562XBK27GA0000J6000100
28863562XBK27GA0000J7000100
28863564A2K27G600004UB002000CAT   0000816200Y
28863564ABK27GA0000J8S000100TWM   0000702200Y
28863566AAK27GA0000WVS000500SPY   0001426000Y
28863567ABK27GA0000J9B000100UWM   0000542700Y
28863567ABK27GA0000JAS000100TWM   0000702000Y
28863567XBK27GA0000J8000100
28863570A3K27G600006HB002000CVS   0000065900Y
28863572X9K27G60000G6002000
28863572A9K27G60000G6B002000QQQQ  0000495300Y
28863575A5K27GA000046B002000HNZ   0000070800Y
28863578XBK27GA0000J9000100
28863578XBK27GA0000JA000100
28863580ABK27GA0000JBS000100TWM   0000702200Y
28863582A5K27GA000047B002000HOT   0000072900Y
28863587ABK27GA0000JCB000100UWM   0000542700Y
28863587XBK27GA0000JB000100
28863587ABK27GA0000JDS000100TWM   0000702000Y
28863591A7K27GA00003HB002000MER   0000463100Y
28863597XBK27GA0000JC000100
28863597XBK27GA0000JD000100
28863599ABK27GA0000JES000100TWM   0000702200Y
28863602A5K27GA000048B002000HNZ   0000071600Y
28863607ABK27GA0000JFB000100UWM   0000542700Y
28863607XBK27GA0000JE000100
28863607ABK27GA0000JGS000100TWM   0000702000Y
28863618XBK27GA0000JF000100
28863618XBK27GA0000JG000100
28863619ABK27GA0000JHS000100TWM   0000702200Y
28863628ABK27GA0000JIB000100UWM   0000542700Y
28863628ABK27GA0000JJS000100TWM   0000702000Y
28863628XBK27GA0000JH000100
28863630A5K27GA000049B002000HOT   0000073700Y
28863638XBK27GA0000JI000100
28863638XBK27GA0000JJ000100
28863638A6K27GA000075B002000JCI   0000052700Y
28863640ABK27GA0000JKS000100TWM   0000702200Y
28863647ABK27GA0000JLB000100UWM   0000542700Y
28863647XBK27GA0000JK000100
28863647ABK27GA0000JMS000100TWM   0000702000Y
28863658XBK27GA0000JL000100
28863658XBK27GA0000JM000100
28863660ABK27GA0000JNS000100TWM   0000702200Y
28863667ABK27GA0000JOB000100UWM   0000542700Y
28863667XBK27GA0000JN000100
28863667ABK27GA0000JPS000100TWM   0000702000Y
28863677XBK27GA0000JO000100
28863677XBK27GA0000JP000100
28863679ABK27GA0000JQS000100TWM   0000702200Y
28863687ABK27GA0000JRB000100UWM   0000542700Y
28863687XBK27GA0000JQ000100
28863687ABK27GA0000JSS000100TWM   0000702000Y
28863707XBK27GA0000JR000100
28863707XBK27GA0000JS000100
28863709ABK27GA0000JTS000100TWM   0000702200Y
28863758AAK27GA0000WWB005000SPY   0001425400Y
28863759AAK27GA0000WXS002500SPY   0001426000Y
28863890X6K27GA00006S000500
28863891A6K27GA000076B000500IWM   0000736200Y
28863895X6K27GA000076000500
28863895A6K27GA000076B000500IWM   0000736300Y
28863905X6K27GA000076000500
28863905A6K27GA000076B000500IWM   0000736700Y
28863909ABK27GA0000JUB000100UWM   0000542700Y
28863909XBK27GA0000JT000100
28863909ABK27GA0000JVS000100TWM   0000702000Y
28863911X6K27GA000076000500
28863911A6K27GA000076B000500IWM   0000736300Y
28863914XBK27GA0000JU000100
28863914XBK27GA0000JV000100
28863916ABK27GA0000JWS000100TWM   0000702200Y
28863915X6K27GA000076000500
28863915A6K27GA000076B000500IWM   0000736700Y
28863918ABK27GA0000JXB000100UWM   0000542700Y
28863919ABK27GA0000JYS000100TWM   0000702000Y
28863919XBK27GA0000JW000100
28863925X6K27GA000076000500
28863925A6K27GA000076B000500IWM   0000736300Y
28863928XBK27GA0000JX000100
28863928XBK27GA0000JY000100
28863930ABK27GA0000JZS000100TWM   0000702200Y
28863929A6K27GA000077B000100IWM   0000736200Y
28863929X6K27GA000077000100
28863929X6K27GA000076000500
28863929A6K27GA000076B000500IWM   0000736700Y
28863931X6K27GA000076000500
28863931A6K27GA000076B000500IWM   0000736300Y
28863933ABK27GA0000K0B000100UWM   0000542700Y
28863933XBK27GA0000JZ000100
28863933ABK27GA0000K1S000100TWM   0000702000Y
28863934XBK27GA0000K0000100
28863934XBK27GA0000K1000100
28863936ABK27GA0000K2S000100TWM   0000702200Y
28863935X6K27GA000076000500
28863935A6K27GA000076B000500IWM   0000736700Y
28863938ABK27GA0000K3B000100UWM   0000542700Y
28863939XBK27GA0000K2000100
28863939ABK27GA0000K4S000100TWM   0000702000Y
28863945X6K27GA000076000500
28863945A6K27GA000076B000500IWM   0000736300Y
28863948XBK27GA0000K3000100
28863948XBK27GA0000K4000100
28863950ABK27GA0000K5S000100TWM   0000702200Y
28863949A6K27GA000078B000100IWM   0000736200Y
28863949X6K27GA000078000100
28863949X6K27GA000076000500
28863949A6K27GA000076B000500IWM   0000736700Y
28863953ABK27GA0000K6B000100UWM   0000542700Y
28863953XBK27GA0000K5000100
28863953ABK27GA0000K7S000100TWM   0000702000Y
28863956X6K27GA000076000500
28863956A6K27GA000076B000500IWM   0000736300Y
28863959XBK27GA0000K6000100
28863959XBK27GA0000K7000100
28863961ABK27GA0000K8S000100TWM   0000702200Y
28863965X6K27GA000076000500
28863965A6K27GA000076B000500IWM   0000736700Y
28863969ABK27GA0000K9B000100UWM   0000542700Y
28863969ABK27GA0000KAS000100TWM   0000702000Y
28863969XBK27GA0000K8000100
28863975X6K27GA000076000500
28863975A6K27GA000076B000500IWM   0000736300Y
28863978XBK27GA0000K9000100
28863978XBK27GA0000KA000100
28863980ABK27GA0000KBS000100TWM   0000702200Y
28863982X6K27GA000076000500
28863982A6K27GA000076B000500IWM   0000736700Y
28863986ABK27GA0000KCB000100UWM   0000542700Y
28863986ABK27GA0000KDS000100TWM   0000702000Y
28863986XBK27GA0000KB000100
28863985X6K27GA000076000500
28863985A6K27GA000076B000500IWM   0000736300Y
28863989XBK27GA0000KC000100
28863989XBK27GA0000KD000100
28863991ABK27GA0000KES000100TWM   0000702200Y
28863995X6K27GA000076000500
28863995A6K27GA000076B000500IWM   0000736700Y
28863998X6K27GA000076000500
28863998A6K27GA000076B000500IWM   0000736300Y
28864002X6K27GA000076000500
28864002A6K27GA000076B000500IWM   0000736700Y
28864005X6K27GA000076000500
28864005A6K27GA000076B000500IWM   0000736300Y
28864011X6K27GA000076000500
28864011A6K27GA000076B000500IWM   0000736700Y
28864015X6K27GA000076000500
28864015A6K27GA000076B000500IWM   0000736300Y
28864025X6K27GA000076000500
28864025A6K27GA000076B000500IWM   0000736700Y
28864036X6K27GA000076000500
28864036A6K27GA000076B000500IWM   0000736300Y
28864047X6K27GA000076000500
28864047A6K27GA000076B000500IWM   0000736700Y
28864053X6K27GA000076000500
28864053A6K27GA000076B000500IWM   0000736300Y
28864056X6K27GA000076000500
28864056A6K27GA000076B000500IWM   0000736700Y
28864065X6K27GA000076000500
28864065A6K27GA000076B000500IWM   0000736300Y
28864076X6K27GA000076000500
28864076A6K27GA000076B000500IWM   0000736700Y
28864081X6K27GA000076000500
28864081A6K27GA000076B000500IWM   0000736300Y
28864086X6K27GA000076000500
28864086A6K27GA000076B000500IWM   0000736700Y
28864096X6K27GA000076000500
28864096A6K27GA000076B000500IWM   0000736300Y
28864106X6K27GA000076000500
28864106A6K27GA000076B000500IWM   0000736700Y
28864116X6K27GA000076000500
28864116A6K27GA000076B000500IWM   0000736300Y
28864126X6K27GA000076000500
28864126A6K27GA000076B000500IWM   0000736700Y
28864132X6K27GA000076000500
28864132A6K27GA000076B000500IWM   0000736300Y
28864136X6K27GA000076000500
28864136A6K27GA000076B000500IWM   0000736700Y
28864142X6K27GA000076000500
28864142A6K27GA000076B000500IWM   0000736300Y
28864153X6K27GA000076000500
28864153A6K27GA000076B000500IWM   0000736700Y
28864155X6K27GA000076000500
28864155A6K27GA000076B000500IWM   0000736300Y
28864165X6K27GA000076000500
28864165A6K27GA000076B000500IWM   0000736700Y
28864167X6K27GA000076000500
28864167A6K27GA000076B000500IWM   0000736300Y
28864175X6K27GA000076000500
28864175A6K27GA000076B000500IWM   0000736700Y
28864180X6K27GA000076000500
28864180A6K27GA000076B000500IWM   0000736300Y
28864185X6K27GA000076000500
28864185A6K27GA000076B000500IWM   0000736700Y
28864192X6K27GA000076000500
28864192A6K27GA000076B000500IWM   0000736300Y
28864195X6K27GA000076000500
28864195A6K27GA000076B000500IWM   0000736700Y
28864201X6K27GA000076000500
28864201A6K27GA000076B000500IWM   0000736300Y
28864206X6K27GA000076000500
28864206A6K27GA000076B000500IWM   0000736700Y
28864212X6K27GA000076000500
28864212A6K27GA000076B000500IWM   0000736300Y
28864216X6K27GA000076000500
28864216A6K27GA000076B000500IWM   0000736700Y
28864223X6K27GA000076000500
28864223A6K27GA000076B000500IWM   0000736300Y
28864260AAK27GA0000WYS005000SPY   0001426200Y
28864360XAK27GA0000UK002000
28864386X7K27GA00003G002000
28864391X7K27GA00003F002000
28864395XCK27GA000031002000
28864410X1K27GA00005K002000
28864411X1K27GA00005L002000
28864417X2K27G600004R002000
28864420X2K27G600004Q002000
28864423X4K27GA0000CI002000
28864429X3K27G600006C002000
28864432X5K27GA000048002000
28864435X3K27G600006H002000
28864441X5K27GA000046002000
28864442X5K27GA000049002000
28864448X5K27GA000047002000
28864461ABK27GA0000KFB002000UTX   0000121100Y
28864466ABK27GA0000KGB002000UTX   0000120300Y
28864482A1K27GA00005MB002000ABT   0000090500Y
28864483ACK27GA000032B002000WYE   0000068800Y
28864496A1K27GA00005NB002000ABT   0000089700Y
28864501A2K27G600004VB002000BBT   0000052700Y
28864517A2K27G600004WB002000BDX   0000763300Y
28864523A2K27G600004XB002000BDX   0000762500Y
28864532A3K27G600006IB002000COH   0000055600Y
28864545A3K27G600006JB002000DD    0000456100Y
28864554A4K27GA0000CJB002000EIX   0000078700Y
28864555A3K27G600006KB002000CVS   0000067800Y
28864566X6K27GA000076000500
28864567A6K27GA000079B000500IWM   0000736200Y
28864575X6K27GA000079000500
28864575A6K27GA000079B000500IWM   0000736300Y
28864577A7K27GA00003IB002000LLL   0001087000Y
28864587XBK27GA0000IZ001000
28864587XAK27GA0000NZ000500
28864587AAK27GA0000NZS000500SPY   0001425800Y
28864589ABK27GA0000KHB001000SSO   0000764500Y
28864591XAK27GA0000NZ000500
28864591AAK27GA0000NZS000500SPY   0001426100Y
28864592XAK27GA0000U2001000
28864592XBK27GA0000KH001000
28864592X6K27GA000079000500
28864592A6K27GA000079B000500IWM   0000736700Y
28864594ABK27GA0000KIB001000SSO   0000764400Y
28864593X6K27GA000079000500
28864593A6K27GA000079B000500IWM   0000736300Y
28864595ABK27GA0000KJB000100UWM   0000542700Y
28864595ABK27GA0000KKS000100TWM   0000702000Y
28864595XBK27GA0000KE000100
28864597XBK27GA0000KJ000100
28864597XBK27GA0000KK000100
28864596X6K27GA000079000500
28864596A6K27GA000079B000500IWM   0000736700Y
28864599ABK27GA0000KLS000100TWM   0000702200Y
28864599ABK27GA0000KMB000100UWM   0000542700Y
28864599XBK27GA0000KL000100
28864599ABK27GA0000KNS000100TWM   0000702000Y
28864606X6K27GA000079000500
28864606A6K27GA000079B000500IWM   0000736300Y
28864609XBK27GA0000KM000100
28864610XBK27GA0000KN000100
28864609A6K27GA00007AB000100IWM   0000736200Y
28864611ABK27GA0000KOS000100TWM   0000702200Y
28864610X6K27GA00007A000100
28864611A6K27GA00007BB002000JCI   0000052900Y
28864616X6K27GA000079000500
28864616A6K27GA000079B000500IWM   0000736700Y
28864619ABK27GA0000KPB000100UWM   0000542700Y
28864619XBK27GA0000KO000100
28864619ABK27GA0000KQS000100TWM   0000702000Y
28864643X6K27GA000079000500
28864643A6K27GA000079B000500IWM   0000736300Y
28864646XBK27GA0000KP000100
28864646XBK27GA0000KQ000100
28864648ABK27GA0000KRS000100TWM   0000702200Y
28864647X6K27GA000079000500
28864647A6K27GA000079B000500IWM   0000736700Y
28864650ABK27GA0000KSB000100UWM   0000542700Y
28864650ABK27GA0000KTS000100TWM   0000702000Y
28864650XBK27GA0000KR000100
28864655X6K27GA000079000500
28864655A6K27GA000079B000500IWM   0000736300Y
28864658XBK27GA0000KS000100
28864659XBK27GA0000KT000100
28864659A6K27GA00007CB000100IWM   0000736200Y
28864659X6K27GA00007C000100
28864660ABK27GA0000KUS000100TWM   0000702200Y
28864660X6K27GA000079000500
28864660A6K27GA000079B000500IWM   0000736700Y
28864663XBK27GA0000KU000100
28864663ABK27GA0000KVB000100UWM   0000542700Y
28864663ABK27GA0000KWS000100TWM   0000702000Y
28864665X6K27GA000079000500
28864665A6K27GA000079B000500IWM   0000736300Y
28864668XBK27GA0000KV000100
28864669XBK27GA0000KW000100
28864670ABK27GA0000KXS000100TWM   0000702200Y
28864682X6K27GA000079000500
28864682A6K27GA000079B000500IWM   0000736700Y
28864686ABK27GA0000KYB000100UWM   0000542700Y
28864686ABK27GA0000KZS000100TWM   0000702000Y
28864686XBK27GA0000KX000100
28864695X6K27GA000079000500
28864695A6K27GA000079B000500IWM   0000736300Y
28864699XBK27GA0000KY000100
28864699XBK27GA0000KZ000100
28864701ABK27GA0000L0S000100TWM   0000702200Y
28864706X6K27GA000079000500
28864706A6K27GA000079B000500IWM   0000736700Y
28864709ABK27GA0000L1B000100UWM   0000542700Y
28864709ABK27GA0000L2S000100TWM   0000702000Y
28864709XBK27GA0000L0000100
28864716X6K27GA000079000500
28864716A6K27GA000079B000500IWM   0000736300Y
28864719XBK27GA0000L1000100
28864719XBK27GA0000L2000100
28864721ABK27GA0000L3S000100TWM   0000702200Y
28864726X6K27GA000079000500
28864726A6K27GA000079B000500IWM   0000736700Y
28864736X6K27GA000079000500
28864736A6K27GA000079B000500IWM   0000736300Y
28864746X6K27GA000079000500
28864746A6K27GA000079B000500IWM   0000736700Y
28864756X6K27GA000079000500
28864756A6K27GA000079B000500IWM   0000736300Y
28864766X6K27GA000079000500
28864766A6K27GA000079B000500IWM   0000736700Y
28864776X6K27GA000079000500
28864776A6K27GA000079B000500IWM   0000736300Y
28864786X6K27GA000079000500
28864786A6K27GA000079B000500IWM   0000736700Y
28864796X6K27GA000079000500
28864796A6K27GA000079B000500IWM   0000736300Y
28864806X6K27GA000079000500
28864806A6K27GA000079B000500IWM   0000736700Y
28864816X6K27GA000079000500
28864816A6K27GA000079B000500IWM   0000736300Y
28864826X6K27GA000079000500
28864826A6K27GA000079B000500IWM   0000736700Y
28864836X6K27GA000079000500
28864836A6K27GA000079B000500IWM   0000736300Y
28864847X6K27GA000079000500
28864847A6K27GA000079B000500IWM   0000736700Y
28864856X6K27GA000079000500
28864856A6K27GA000079B000500IWM   0000736300Y
28864866X6K27GA000079000500
28864866A6K27GA000079B000500IWM   0000736700Y
28864876X6K27GA000079000500
28864876A6K27GA000079B000500IWM   0000736300Y
28864886X6K27GA000079000500
28864886A6K27GA000079B000500IWM   0000736700Y
28864896X6K27GA000079000500
28864896A6K27GA000079B000500IWM   0000736300Y
28864906X6K27GA000079000500
28864906A6K27GA000079B000500IWM   0000736700Y
28864916X6K27GA000079000500
28864916A6K27GA000079B000500IWM   0000736300Y
28864926X6K27GA000079000500
28864926A6K27GA000079B000500IWM   0000736700Y
28864936X6K27GA000079000500
28864936A6K27GA000079B000500IWM   0000736300Y
28864946X6K27GA000079000500
28864946A6K27GA000079B000500IWM   0000736700Y
28864956X6K27GA000079000500
28864956A6K27GA000079B000500IWM   0000736300Y
28864966X6K27GA000079000500
28864966A6K27GA000079B000500IWM   0000736700Y
28864976X6K27GA000079000500
28864976A6K27GA000079B000500IWM   0000736300Y
28864986X6K27GA000079000500
28864986A6K27GA000079B000500IWM   0000736700Y
28864996X6K27GA000079000500
28864996A6K27GA000079B000500IWM   0000736300Y
28865016X6K27GA000079000500
28865016A6K27GA000079B000500IWM   0000736700Y
28865026X6K27GA000079000500
28865026A6K27GA000079B000500IWM   0000736300Y
28865036X6K27GA000079000500
28865036A6K27GA000079B000500IWM   0000736700Y
28865047X6K27GA000079000500
28865047A6K27GA000079B000500IWM   0000736300Y
28865056X6K27GA000079000500
28865056A6K27GA000079B000500IWM   0000736700Y
28865066X6K27GA000079000500
28865066A6K27GA000079B000500IWM   0000736300Y
28865076X6K27GA000079000500
28865076A6K27GA000079B000500IWM   0000736700Y
28865086X6K27GA000079000500
28865086A6K27GA000079B000500IWM   0000736300Y
28865141XAK27GA0000E9001000
28865141AAK27GA0000E9S001000SPY   0001426200Y
28865142X9K27G60000G6002000
28865142A9K27G60000G6B002000QQQQ  0000495800Y
28865141AAK27GA0000WZB002000SPY   0001425600Y
28865141XAK27GA0000WP003000
28865141XAK27GA0000F5000500
28865141AAK27GA0000F5B000500SPY   0001425600Y
28865141XAK27GA0000QB000500
28865141AAK27GA0000QBS000500SPY   0001426200Y
28865141XAK27GA0000FI000500
28865141AAK27GA0000FIB000500SPY   0001425600Y
28865141AAK27GA0000X0B003000SPY   0001425700Y
28865141XAK27GA0000WG003000
28865142XAK27GA0000WQ003000
28865142XAK27GA0000E7001000
28865142AAK27GA0000E7B001000SPY   0001425700Y
28865142XAK27GA0000WH003000
28865142XAK27GA0000NY000500
28865142AAK27GA0000NYS000500SPY   0001426200Y
28865142AAK27GA0000X1B003000SPY   0001425700Y
28865142XAK27GA0000WN001000
28865142XAK27GA0000WS001000
28865143AAK27GA0000X2B001000SPY   0001425700Y
28865143AAK27GA0000X3S001000SDS   0000548800Y
28865143X4K27GA0000CG000200
28865143ABK27GA0000L4B001000SSO   0000764500Y
28865143ABK27GA0000L5B001000SSO   0000764600Y
28865143XBK27GA0000KI001000
28865143AAK27GA0000X4B002000SPY   0001425600Y
28865143XBK27GA0000L4001000
28865143XAK27GA0000WO001000
28865143AAK27GA0000X5S003000SPY   0001426600Y
28865143AAK27GA0000X6S003000SPY   0001426600Y
28865144XAK27GA0000WT000500
28865144AAK27GA0000X7B005000SPY   0001425500Y
28865145XAK27GA0000WW005000
28865145AAK27GA0000X8S001000SPY   0001426200Y
28865145XAK27GA0000F2000500
28865145AAK27GA0000F2B000500SPY   0001425700Y
28865146XAK27GA0000WX002500
28865146AAK27GA0000X9B002500SPY   0001425600Y
28865147XAK27GA0000WJ002500
28865147XAK27GA0000X7005000
28865148XAK27GA0000WV000500
28865149AAK27GA0000XAB000500SPY   0001425600Y
28865150A4K27GA0000CKS000200DIA   0001299400Y
28865152XAK27GA0000WR001000
28865153XBK27GA0000IY001000
28865154AAK27GA0000XBB001000SDS   0000547400Y
28865155ABK27GA0000L6S001000SSO   0000765600Y
28865163X4K27GA0000CH000100
28865163X3K27G600006F000100
28865164XAK27GA0000WN001000
28865164AAK27GA0000XCS001000SPY   0001426200Y
28865166AAK27GA0000XDS001000SPY   0001426200Y
28865168XAK27GA0000F2000500
28865168AAK27GA0000F2B000500SPY   0001425300Y
28865170XAK27GA0000X4002000
28865172AAK27GA0000XEB001000SPY   0001425400Y
28865178AAK27GA0000XFB001000SPY   0001425500Y
28865197XAK27GA0000XC001000
28865197XAK27GA0000XD001000
28865227XAK27GA0000XE001000
28865238AAK27GA0000XGB001000SPY   0001425500Y
28865309AAK27GA0000XHB001000SPY   0001425600Y
28865309XAK27GA0000XG001000
28865309XAK27GA0000WU001000
28865361AAK27GA0000XIS000500SPY   0001426200Y
28865369XAK27GA0000V8002000
28865373XBK27GA0000KG002000
28865373X2K27G600004S002000
28865405XCK27GA000032002000
28865410XBK27GA0000KF002000
28865412X3K27G600006B002000
28865423X1K27GA00005N002000
28865427X1K27GA00005M002000
28865433X3K27G600006K002000
28865438AAK27GA0000XJB002000SHLD  0000738500Y
28865460A7K27GA00003JB002000LMT   0000189100Y
28865460A7K27GA00003KB002000LMT   0000188300Y
28865471X6K27GA000075002000
28865484X2K27G600004T002000
28865492ACK27GA000033B002000WYE   0000070800Y
28865514A1K27GA00005OB002000AFL   0000112800Y
28865517A1K27GA00005PB002000AFL   0000113600Y
28865536X4K27GA0000CJ002000
28865540A2K27G600004YB002000CAG   0000034000Y
28865540A2K27G600004ZB002000BBT   0000052900Y
28865553A4K27GA0000CLB002000EIX   0000080900Y
28865569AAK27GA0000XKB005000SPY   0001425400Y
28865568X6K27GA00005G002000
28865574A3K27G600006LB002000COH   0000055800Y
28865575A5K27GA00004AB002000HNZ   0000074100Y
28865604A3K27G600006MB002000CVS   0000068200Y
28865609A5K27GA00004BB002000HOT   0000076400Y
28865619A5K27GA00004CB002000HNZ   0000073300Y
28865626A7K27GA00003LB002000LLY   0000464600Y
28865630A5K27GA00004DB002000HOT   0000075600Y
28865634A6K27GA00007DB002000KEY   0000210300Y
28865646A7K27GA00003MB002000MET   0000588700Y
28865646A7K27GA00003NB002000LTD   0000167600Y
28866354AAK27GA0000XLB002000SPLS  0000032300Y
28866363X7K27GA00003J002000
28866397X8K27G600000Q002000
28866406X7K27GA00003K002000
28866431A2K27G6000050B002000BMY   0000032000Y
28866440X1K27GA00005O002000
28866462A3K27G600006NB002000CTSH  0000048000Y
28866469X3K27G600006M002000
28866479XCK27GA000033002000
28866491X4K27GA00009W000100
28866497A4K27GA0000CMB000100DRYS  0001067100Y
28866508X5K27GA00004C002000
28866514X5K27GA00004D002000
28866516ABK27GA0000L7B002000UTX   0000125100Y
28866520X6K27GA00007B002000
28866533X1K27GA00005P002000
28866546X2K27G600004V002000
28866556ABK27GA0000L8B002000UTX   0000124300Y
28866557X3K27G600006I002000
28866566ACK27GA000034B002000WYE   0000071200Y
28866591A1K27GA00005QB002000ABT   0000092700Y
28866609A2K27G6000051B002000CAG   0000033800Y
28866610A1K27GA00005RB002000ABT   0000093600Y
28866622X4K27GA0000CL002000
28866632X5K27GA00004A002000
28866642A4K27GA0000CNB002000EIX   0000081500Y
28866645X5K27GA00004B002000
28866651A6K27GA00007EB002000IWN   0000664600Y
28866657A3K27G600006OB002000CVS   0000070200Y
28866660A7K27GA00003OB002000MFE   0000341500Y
28866674A6K27GA00007FB002000JCI   0000055600Y
28866681A7K27GA00003PB002000MMC   0000034500Y
28866700A7K27GA00003QB002000MON   0001192500Y
28866706A7K27GA00003RB002000LXK   0000336600Y
28866719A7K27GA00003SB002000MOT   0000089000Y
28866729A7K27GA00003TB002000MAR   0000331400Y
28866754A7K27GA00003UB002000MAS   0000168600Y
28866828X1K27GA00000V000100
28866828A1K27GA00000VB000100AAPL  0001828600Y
28866837X1K27GA00000W000100
28866846A1K27GA00005SS000090AAPL  0001833400Y
28867387X4K27GA00008S002000
28867389X4K27GA00008R002000
28867396XBK27GA0000L7002000
28867402XAK27GA0000UI002000
28867402A7K27GA00003VB002000LMT   0000194300Y
28867402X1K27GA00005R002000
28867407X2K27G600004O002000
28867425X2K27G600004Y002000
28867426A8K27G6000030B002000NVTL  0000078600Y
28867441X3K27G600006O002000
28867449X3K27G600001S002000
28867459XBK27GA0000L8002000
28867462X4K27GA0000AA002000
28867477X6K27GA00005P002000
28867486XCK27GA000034002000
28867493A7K27GA00003WB002000LMT   0000195100Y
28867497X1K27GA00005Q002000
28867504A1K27GA00005TB002000AFL   0000116500Y
28867521X2K27G600004P002000
28867524X2K27G600004Z002000
28867524ACK27GA000035B002000WYE   0000073200Y
28867548A1K27GA00005UB002000AFL   0000117300Y
28867549X3K27G600006L002000
28867562A3K27G600006PB002000CVS   0000070600Y
28867578A2K27G6000052B002000BBT   0000055600Y
28867583A3K27G600006QB002000COH   0000058600Y
28867599A4K27GA0000COB002000EIX   0000083700Y
28867606X3K27G6000020002000
28867610X4K27GA0000CN002000
28867616X4K27GA0000AB002000
28867625A5K27GA00004EB002000HNZ   0000076700Y
28867629A5K27GA00004FB002000HNZ   0000075900Y
28867640A5K27GA00004GB002000HOT   0000079100Y
28867652A5K27GA00004HB002000HOT   0000078300Y
28867674A6K27GA00007GB002000JCI   0000055700Y
28867681X6K27GA00005X002000
28867704XAK27GA0000F2000500
28867704AAK27GA0000F2B000500SPY   0001425700Y
28867704X7K27GA000039002000
28867721E4K27GA0000A800010000004AQ00007
28867724X4K27GA0000A5000100
28867724A4K27GA0000CQB000100DIG   0001237800Y
28867724A4K27GA0000CRS000100DIG   0001246900Y
28867725X4K27GA0000CR000100
28867727A4K27GA0000CSS000100DIG   0001246900Y
28867732X4K27GA0000CS000100
28867732A4K27GA0000CTS000100DIG   0001244200Y
28867731X6K27GA000069000100
28867733X4K27GA0000CT000100
28867732X6K27GA000068000100
28867732A6K27GA00007HB000100IYE   0001532300Y
28867735A4K27GA0000CUS000100DIG   0001246900Y
28867741A6K27GA00007IB000100IYE   0001532800Y
28867741X6K27GA00007H000100
28867832X4K27GA0000AU000100
28867832A4K27GA0000CVS000100DRYS  0001071900Y
28867877X4K27GA0000CV000100
28867880X4K27GA0000AE000100
28867880A4K27GA0000CWS000100DRYS  0001070900Y
28867883X4K27GA0000CW000100
28867884A4K27GA0000CXB000100DRYS  0001067100Y
28867884A4K27GA0000CYS000100DRYS  0001071900Y
28867887X4K27GA0000CX000100
28867887X4K27GA0000CM000100
28867887X4K27GA0000AN000100
28867887A4K27GA0000CZB000100DRYS  0001069900Y
28867887A4K27GA0000D0B000100DRYS  0001069900Y
28867887A4K27GA0000D1S000100DRYS  0001071900Y
28867928XAK27GA0000F2000500
28867928AAK27GA0000F2B000500SPY   0001425300Y
28867928XAK27GA0000X0003000
28867928XAK27GA0000X5003000
28867928XAK27GA0000X6003000
28867929XAK27GA0000X1003000
28867929XAK27GA0000XH001000
28867929AAK27GA0000XMS003000SPY   0001426000Y
28867929AAK27GA0000XNS003000SPY   0001426000Y
28867929AAK27GA0000XOS002000SPY   0001426100Y
28867929XAK27GA0000X8001000
28867929XAK27GA0000E7001000
28867929AAK27GA0000E7B001000SPY   0001425300Y
28867929AAK27GA0000XPS001000SPY   0001425800Y
28867930XAK27GA0000X2001000
28867930AAK27GA0000XQB003000SPY   0001425000Y
28867930XAK27GA0000QB000500
28867930AAK27GA0000QBS000500SPY   0001425800Y
28867930AAK27GA0000XRB003000SPY   0001425000Y
28867930XAK27GA0000XK005000
28867931XAK27GA0000XB001000
28867931AAK27GA0000XSB001000SDS   0000547500Y
28867931ABK27GA0000L9S001000SSO   0000765500Y
28867931XBK27GA0000L6001000
28867931AAK27GA0000XTB001000SPY   0001425300Y
28867932XAK27GA0000X9002500
28867933AAK27GA0000XUB002500SPY   0001425500Y
28867934XAK27GA0000XA000500
28867934AAK27GA0000XVS000500SPY   0001426000Y
28867934XAK27GA0000XI000500
28867940X6K27GA000079000500
28867942ABK27GA0000LAB000100UWM   0000542700Y
28867942XBK27GA0000L3000100
28867942ABK27GA0000LBS000100TWM   0000702000Y
28867944A6K27GA00007JB000500IWM   0000736700Y
28867947XBK27GA0000LA000100
28867947XBK27GA0000LB000100
28867949ABK27GA0000LCB000100UWM   0000542700Y
28867949ABK27GA0000LDS000100TWM   0000702000Y
28867949X6K27GA00007J000500
28867949A6K27GA00007JB000500IWM   0000736300Y
28867954X6K27GA00007J000500
28867954A6K27GA00007JB000500IWM   0000736700Y
28867956XBK27GA0000LC000100
28867956XBK27GA0000LD000100
28867956X6K27GA00007J000500
28867956A6K27GA00007JB000500IWM   0000736300Y
28867957ABK27GA0000LEB000100UWM   0000542700Y
28867958ABK27GA0000LFS000100TWM   0000702000Y
28867959X4K27GA0000CK000200
28867959XBK27GA0000LE000100
28867959XBK27GA0000LF000100
28867959A4K27GA0000D2S000047DIA   0001299100Y
28867960A4K27GA0000D3B000100DXD   0000499300Y
28867960A3K27G600006RS000100DDM   0000802700Y
28867961ABK27GA0000LGS000100TWM   0000702200Y
28867965X6K27GA00007J000500
28867965A6K27GA00007JB000500IWM   0000736700Y
28867967ABK27GA0000LHB000100UWM   0000542700Y
28867967ABK27GA0000LIS000100TWM   0000702000Y
28867967XBK27GA0000LG000100
28867970X4K27GA0000CZ000100
28867970A4K27GA0000CZB000100DRYS  0001070000Y
28867970X4K27GA0000D0000100
28867970A4K27GA0000D0B000100DRYS  0001070000Y
28867975X6K27GA00007J000500
28867975A6K27GA00007JB000500IWM   0000736300Y
28867978XBK27GA0000LH000100
28867978XBK27GA0000LI000100
28867980ABK27GA0000LJS000100TWM   0000702200Y
28867985X6K27GA00007J000500
28867985A6K27GA00007JB000500IWM   0000736700Y
28867987ABK27GA0000LKB000100UWM   0000542700Y
28867987ABK27GA0000LLS000100TWM   0000702000Y
28867987XBK27GA0000LJ000100
28867995X6K27GA00007J000500
28867995A6K27GA00007JB000500IWM   0000736300Y
28867998XBK27GA0000LK000100
28867998XBK27GA0000LL000100
28867997X6K27GA00007J000500
28867997A6K27GA00007JB000500IWM   0000736700Y
28868000ABK27GA0000LMB000100UWM   0000542700Y
28868000ABK27GA0000LNS000100TWM   0000702000Y
28868001XAK27GA0000E9001000
28868001AAK27GA0000E9S001000SPY   0001425800Y
28868005X6K27GA00007J000500
28868005A6K27GA00007JB000500IWM   0000736300Y
28868015X6K27GA00007J000500
28868015A6K27GA00007JB000500IWM   0000736700Y
28868017XBK27GA0000LM000100
28868017XBK27GA0000LN000100
28868017XAK27GA0000XF001000
28868017A6K27GA00007KB000100IWM   0000736200Y
28868018ABK27GA0000LOB000100UWM   0000542700Y
28868017X6K27GA00007K000100
28868019ABK27GA0000LPS000100TWM   0000702000Y
28868019AAK27GA0000XWB001000SPY   0001425400Y
28868025X6K27GA00007J000500
28868025A6K27GA00007JB000500IWM   0000736300Y
28868035X6K27GA00007J000500
28868035A6K27GA00007JB000500IWM   0000736700Y
28868037XBK27GA0000LO000100
28868037XBK27GA0000LP000100
28868037A6K27GA00007LB000100IWM   0000736200Y
28868039ABK27GA0000LQS000100TWM   0000702200Y
28868038X6K27GA00007L000100
28868039ABK27GA0000LRS000100TWM   0000702000Y
28868039XBK27GA0000LQ000100
28868039ABK27GA0000LSB000100UWM   0000542700Y
28868045X6K27GA00007J000500
28868045A6K27GA00007JB000500IWM   0000736300Y
28868055X6K27GA00007J000500
28868055A6K27GA00007JB000500IWM   0000736700Y
28868057XBK27GA0000LS000100
28868057XBK27GA0000LR000100
28868057A6K27GA00007MB000100IWM   0000736200Y
28868059ABK27GA0000LTS000100TWM   0000702200Y
28868059X6K27GA00007M000100
28868067X6K27GA00007J000500
28868067A6K27GA00007JB000500IWM   0000736300Y
28868068ABK27GA0000LUB000100UWM   0000542700Y
28868068XBK27GA0000LT000100
28868068ABK27GA0000LVS000100TWM   0000702000Y
28868075X6K27GA00007J000500
28868075A6K27GA00007JB000500IWM   0000736700Y
28868077XBK27GA0000LU000100
28868077XBK27GA0000LV000100
28868077A6K27GA00007NB000100IWM   0000736200Y
28868078ABK27GA0000LWS000100TWM   0000702200Y
28868077X6K27GA00007N000100
28868085X6K27GA00007J000500
28868085A6K27GA00007JB000500IWM   0000736300Y
28868095X6K27GA00007J000500
28868095A6K27GA00007JB000500IWM   0000736700Y
28868105X6K27GA00007J000500
28868105A6K27GA00007JB000500IWM   0000736300Y
28868115X6K27GA00007J000500
28868115A6K27GA00007JB000500IWM   0000736700Y
28868125X6K27GA00007J000500
28868125A6K27GA00007JB000500IWM   0000736300Y
28868135X6K27GA00007J000500
28868135A6K27GA00007JB000500IWM   0000736700Y
28868145X6K27GA00007J000500
28868145A6K27GA00007JB000500IWM   0000736300Y
28868155X6K27GA00007J000500
28868155A6K27GA00007JB000500IWM   0000736700Y
28868162X6K27GA00007J000500
28868162A6K27GA00007JB000500IWM   0000736300Y
28868165X6K27GA00007J000500
28868165A6K27GA00007JB000500IWM   0000736700Y
28868175X6K27GA00007J000500
28868175A6K27GA00007JB000500IWM   0000736300Y
28868185X6K27GA00007J000500
28868185A6K27GA00007JB000500IWM   0000736700Y
28868195X6K27GA00007J000500
28868195A6K27GA00007JB000500IWM   0000736300Y
28868205X6K27GA00007J000500
28868205A6K27GA00007JB000500IWM   0000736700Y
28868215X6K27GA00007J000500
28868215A6K27GA00007JB000500IWM   0000736300Y
28868225X6K27GA00007J000500
28868225A6K27GA00007JB000500IWM   0000736700Y
28868235X6K27GA00007J000500
28868235A6K27GA00007JB000500IWM   0000736300Y
28868247X6K27GA00007J000500
28868247A6K27GA00007JB000500IWM   0000736700Y
28868256X6K27GA00007J000500
28868256A6K27GA00007JB000500IWM   0000736300Y
28868265X6K27GA00007J000500
28868265A6K27GA00007JB000500IWM   0000736700Y
28868275X6K27GA00007J000500
28868275A6K27GA00007JB000500IWM   0000736300Y
28868285X6K27GA00007J000500
28868285A6K27GA00007JB000500IWM   0000736700Y
28868295X6K27GA00007J000500
28868295A6K27GA00007JB000500IWM   0000736300Y
28868305X6K27GA00007J000500
28868305A6K27GA00007JB000500IWM   0000736700Y
28868315X6K27GA00007J000500
28868315A6K27GA00007JB000500IWM   0000736300Y
28868325X6K27GA00007J000500
28868325A6K27GA00007JB000500IWM   0000736700Y
28868335X6K27GA00007J000500
28868335A6K27GA00007JB000500IWM   0000736300Y
28868342X3K27G600006A002000
28868345X6K27GA00007J000500
28868345A6K27GA00007JB000500IWM   0000736700Y
28868354X6K27GA00006X002000
28868355X6K27GA00007J000500
28868355A6K27GA00007JB000500IWM   0000736300Y
28868357X9K27G60000ER005000
28868357X9K27G60000FG005000
28868357X9K27G60000F8003200
28868357A9K27G60000F8S003200QQQQ  0000496500Y
28868357A9K27G60000OGB005000QQQQ  0000495900Y
28868357A9K27G60000OHB005000QQQQ  0000495900Y
28868358X9K27G60000EU002000
28868358A9K27G60000EUB002000QQQQ  0000495900Y
28868361X7K27GA00003V002000
28868365X6K27GA00007J000500
28868365A6K27GA00007JB000500IWM   0000736700Y
28868369X2K27G6000050002000
28868375AAK27GA0000XXS002500SPY   0001426000Y
28868375X6K27GA00007J000500
28868375A6K27GA00007JB000500IWM   0000736300Y
28868386A4K27GA0000D4B002000EMR   0000553200Y
28868385X6K27GA00007J000500
28868385A6K27GA00007JB000500IWM   0000736700Y
28868388X6K27GA00007J000500
28868388A6K27GA00007JB000500IWM   0000736300Y
28868396X6K27GA00007J000500
28868396A6K27GA00007JB000500IWM   0000736700Y
28868406X6K27GA00007J000500
28868406A6K27GA00007JB000500IWM   0000736300Y
28868410A4K27GA0000D5B002000EMR   0000554000Y
28868414AAK27GA0000XYB002000SNDK  0000227300Y
28868417ABK27GA0000LXB002000UTX   0000128300Y
28868435X7K27GA00003W002000
28868460ACK27GA000036B002000WYE   0000073600Y
28868486X9K27G60000OH005000
28868488A9K27G60000OIB005000QQQQ  0000495500Y
28868489ABK27GA0000LYB002000UTX   0000129100Y
28868488A1K27GA00005VB002000ABT   0000095800Y
28868492X1K27GA00005T002000
28868491XCK27GA000035002000
28868495A9K27G60000OJB000500QQQQ  0000495300Y
28868502A2K27G6000053B002000AXP   0000405300Y
28868510A2K27G6000054B002000BBT   0000055700Y
28868510A1K27GA00005WB002000ABT   0000096600Y
28868529X2K27G6000051002000
28868534X1K27GA00005U002000
28868559A2K27G6000055B002000AXP   0000406100Y
28868566A3K27G600006SB002000COH   0000058800Y
28868580X3K27G600006P002000
28868591X4K27GA0000A0002000
28868598X5K27GA00003R002000
28868600X5K27GA00004F002000
28868609A2K27G6000056B002000CAG   0000035900Y
28868609X5K27GA00004H002000
28868611A3K27G600006TB002000DE    0000792000Y
28868622A4K27GA0000D6B002000EIX   0000084300Y
28868630A4K27GA0000D7B002000ESI   0000616900Y
28868631A3K27G600006UB002000CVS   0000072600Y
28868633X7K27GA00003P002000
28868652A3K27G600006VB002000DE    0000792800Y
28868651A6K27GA00007OB002000JCP   0000413000Y
28868673X4K27GA0000A3002000
28868690XAK27GA0000FI000500
28868690AAK27GA0000FIB000500SPY   0001425200Y
28868691X4K27GA0000CO002000
28868695A4K27GA0000D8B002000ESI   0000617700Y
28868706X5K27GA00004E002000
28868712X5K27GA00004G002000
28868718X6K27GA00007F002000
28868755X6K27GA00007J000500
28868756A6K27GA00007PB000500IWM   0000736200Y
28868765X6K27GA00007P000500
28868765A6K27GA00007PB000500IWM   0000736700Y
28868768ABK27GA0000LZB000100UWM   0000542700Y
28868769ABK27GA0000M0S000100TWM   0000702000Y
28868769XBK27GA0000LW000100
28868776X6K27GA00007P000500
28868776A6K27GA00007PB000500IWM   0000736300Y
28868779XBK27GA0000LZ000100
28868779XBK27GA0000M0000100
28868781ABK27GA0000M1S000100TWM   0000702200Y
28868795X6K27GA00007P000500
28868795A6K27GA00007PB000500IWM   0000736700Y
28868799XBK27GA0000M1000100
28868799ABK27GA0000M2B000100UWM   0000542700Y
28868799ABK27GA0000M3S000100TWM   0000702000Y
28868806X6K27GA00007P000500
28868806A6K27GA00007PB000500IWM   0000736300Y
28868809XBK27GA0000M2000100
28868809XBK27GA0000M3000100
28868811ABK27GA0000M4S000100TWM   0000702200Y
28868811X4K27GA0000CY000100
28868815X6K27GA00007P000500
28868815A6K27GA00007PB000500IWM   0000736700Y
28868818ABK27GA0000M5B000100UWM   0000542700Y
28868818ABK27GA0000M6S000100TWM   0000702000Y
28868818XBK27GA0000M4000100
28868825X6K27GA00007P000500
28868825A6K27GA00007PB000500IWM   0000736300Y
28868828XBK27GA0000M5000100
28868828XBK27GA0000M6000100
28868830ABK27GA0000M7S000100TWM   0000702200Y
28868829A6K27GA00007QB000100IWM   0000736200Y
28868829X6K27GA00007Q000100
28868829X6K27GA00007P000500
28868829A6K27GA00007PB000500IWM   0000736700Y
28868833ABK27GA0000M8B000100UWM   0000542700Y
28868833XBK27GA0000M7000100
28868833ABK27GA0000M9S000100TWM   0000702000Y
28868832X6K27GA00007P000500
28868832A6K27GA00007PB000500IWM   0000736300Y
28868836XBK27GA0000M8000100
28868836XBK27GA0000M9000100
28868836X6K27GA00007P000500
28868836A6K27GA00007PB000500IWM   0000736700Y
28868838ABK27GA0000MAS000100TWM   0000702200Y
28868839ABK27GA0000MBB000100UWM   0000542700Y
28868840ABK27GA0000MCS000100TWM   0000702000Y
28868840XBK27GA0000MA000100
28868839X6K27GA00007P000500
28868839A6K27GA00007PB000500IWM   0000736300Y
28868842XBK27GA0000MB000100
28868842XBK27GA0000MC000100
28868844ABK27GA0000MDS000100TWM   0000702200Y
28868847X6K27GA00007P000500
28868847A6K27GA00007PB000500IWM   0000736700Y
28868851ABK27GA0000MEB000100UWM   0000542700Y
28868851ABK27GA0000MFS000100TWM   0000702000Y
28868851XBK27GA0000MD000100
28868856X6K27GA00007P000500
28868856A6K27GA00007PB000500IWM   0000736300Y
28868859XBK27GA0000ME000100
28868859XBK27GA0000MF000100
28868859A6K27GA00007RB000100IWM   0000736200Y
28868861ABK27GA0000MGS000100TWM   0000702200Y
28868860X6K27GA00007R000100
28868865X6K27GA00007P000500
28868865A6K27GA00007PB000500IWM   0000736700Y
28868869ABK27GA0000MHB000100UWM   0000542700Y
28868869XBK27GA0000MG000100
28868869ABK27GA0000MIS000100TWM   0000702000Y
28868875X6K27GA00007P000500
28868875A6K27GA00007PB000500IWM   0000736300Y
28868879XBK27GA0000MH000100
28868879XBK27GA0000MI000100
28868881ABK27GA0000MJS000100TWM   0000702200Y
28868895X6K27GA00007P000500
28868895A6K27GA00007PB000500IWM   0000736700Y
28868897X6K27GA00007P000500
28868897A6K27GA00007PB000500IWM   0000736300Y
28868906X6K27GA00007P000500
28868906A6K27GA00007PB000500IWM   0000736700Y
28868916X6K27GA00007P000500
28868916A6K27GA00007PB000500IWM   0000736300Y
28868926X6K27GA00007P000500
28868926A6K27GA00007PB000500IWM   0000736700Y
28868936X6K27GA00007P000500
28868936A6K27GA00007PB000500IWM   0000736300Y
28868946X6K27GA00007P000500
28868946A6K27GA00007PB000500IWM   0000736700Y
28868956X6K27GA00007P000500
28868956A6K27GA00007PB000500IWM   0000736300Y
28868966X6K27GA00007P000500
28868966A6K27GA00007PB000500IWM   0000736700Y
28868975XAK27GA0000QB000500
28868975AAK27GA0000QBS000500SPY   0001426200Y
28868975XAK27GA0000FI000500
28868975AAK27GA0000FIB000500SPY   0001425600Y
28868975XAK27GA0000E9001000
28868975AAK27GA0000E9S001000SPY   0001426200Y
28868975XAK27GA0000XM003000
28868975AAK27GA0000XZB003000SPY   0001425600Y
28868976XAK27GA0000XQ003000
28868976XAK27GA0000XR003000
28868976XAK27GA0000XN003000
28868976XAK27GA0000XO001000
28868976XAK27GA0000E7001000
28868976AAK27GA0000E7B001000SPY   0001425700Y
28868976AAK27GA0000Y0B003000SPY   0001425600Y
28868976AAK27GA0000Y1B001000SPY   0001425400Y
28868976XAK27GA0000XO001000
28868977AAK27GA0000Y2B005000SPY   0001425500Y
28868976X6K27GA00007P000500
28868976A6K27GA00007PB000500IWM   0000736300Y
28868978AAK27GA0000Y3S001000SPY   0001426200Y
28868978AAK27GA0000Y4S003000SPY   0001426600Y
28868978AAK27GA0000Y5S003000SPY   0001426600Y
28868978AAK27GA0000Y6S001000SPY   0001426200Y
28868979XAK27GA0000XX002500
28868979XAK27GA0000Y2005000
28868979AAK27GA0000Y7B002500SPY   0001425600Y
28868980XAK27GA0000XU002500
28868980XAK27GA0000XV000500
28868981AAK27GA0000Y8B000500SPY   0001425600Y
28868986X6K27GA00007P000500
28868986A6K27GA00007PB000500IWM   0000736700Y
28868990X6K27GA00007P000500
28868990A6K27GA00007PB000500IWM   0000736300Y
28868996XAK27GA0000XT001000
28868996X6K27GA00007P000500
28868996A6K27GA00007PB000500IWM   0000736700Y
28868997XAK27GA0000Y1001000
28868997AAK27GA0000Y9B001000SPY   0001425700Y
28868997AAK27GA0000YAB001000SPY   0001425600Y
28868997X6K27GA00007P000500
28868997A6K27GA00007PB000500IWM   0000736300Y
28868999X6K27GA00007P000500
28868999A6K27GA00007PB000500IWM   0000736700Y
28869008X9K27G60000OI005000
28869006X6K27GA00007P000500
28869006A6K27GA00007PB000500IWM   0000736300Y
28869008A9K27G60000OKB005000QQQQ  0000495900Y
28869007X4K27GA0000D2000047
28869009A4K27GA0000D9S000200DIA   0001299400Y
28869013X3K27G600006R000100
28869013X4K27GA0000D3000100
28869015X6K27GA00007P000500
28869015A6K27GA00007PB000500IWM   0000736700Y
28869016A6K27GA00007SS015000IOM   0000038400Y
28869018XAK27GA0000Y6001000
28869018XAK27GA0000Y3001000
28869018X6K27GA00007P000500
28869018A6K27GA00007PB000500IWM   0000736300Y
28869021X6K27GA00007P000500
28869021A6K27GA00007PB000500IWM   0000736700Y
28869025X6K27GA00007P000500
28869025A6K27GA00007PB000500IWM   0000736300Y
28869036X6K27GA00007P000500
28869036A6K27GA00007PB000500IWM   0000736700Y
28869047X6K27GA00007P000500
28869047A6K27GA00007PB000500IWM   0000736300Y
28869056X6K27GA00007P000500
28869056A6K27GA00007PB000500IWM   0000736700Y
28869066X6K27GA00007P000500
28869066A6K27GA00007PB000500IWM   0000736300Y
28869076X6K27GA00007P000500
28869076A6K27GA00007PB000500IWM   0000736700Y
28869086X6K27GA00007P000500
28869086A6K27GA00007PB000500IWM   0000736300Y
28869096X6K27GA00007P000500
28869096A6K27GA00007PB000500IWM   0000736700Y
28869105X6K27GA00007P000500
28869105A6K27GA00007PB000500IWM   0000736300Y
28869116X6K27GA00007P000500
28869116A6K27GA00007PB000500IWM   0000736700Y
28869125X6K27GA00007P000500
28869125A6K27GA00007PB000500IWM   0000736300Y
28869135X6K27GA00007P000500
28869135A6K27GA00007PB000500IWM   0000736700Y
28869141X6K27GA00007P000500
28869141A6K27GA00007PB000500IWM   0000736300Y
28869144X6K27GA00007P000500
28869144A6K27GA00007PB000500IWM   0000736700Y
28869155X6K27GA00007P000500
28869155A6K27GA00007PB000500IWM   0000736300Y
28869165X6K27GA00007P000500
28869165A6K27GA00007PB000500IWM   0000736700Y
28869175X6K27GA00007P000500
28869175A6K27GA00007PB000500IWM   0000736300Y
28869186X6K27GA00007P000500
28869186A6K27GA00007PB000500IWM   0000736700Y
28869198X4K27GA0000D1000100
28869198A4K27GA0000DAS000100DRYS  0001078300Y
28869210AAK27GA0000YBS000500SPY   0001426200Y
28869297ABK27GA0000MKB000100UWM   0000542700Y
28869297XBK27GA0000MJ000100
28869297ABK27GA0000MLS000100TWM   0000702000Y
28869319XAK27GA0000Y4003000
28869319XAK27GA0000Y5003000
28869319XAK27GA0000Y9001000
28869319XAK27GA0000YA001000
28869319AAK27GA0000YCS003000SPY   0001426000Y
28869320AAK27GA0000YDS001000SPY   0001426200Y
28869320AAK27GA0000YES003000SPY   0001426000Y
28869321AAK27GA0000YFB001000SPY   0001425300Y
28869321AAK27GA0000YGB001000SPY   0001425400Y
28869321XAK27GA0000Y7002500
28869321XAK27GA0000Y0003000
28869322XAK27GA0000Y8000500
28869324AAK27GA0000YHB003000SPY   0001425000Y
28869329AAK27GA0000YIS001000SPY   0001426100Y
28869330XAK27GA0000V4001000
28869338X9K27G60000OK005000
28869341A9K27G60000OLB005000QQQQ  0000495500Y
28869343A4K27GA0000DBB000100DXD   0000499300Y
28869344A3K27G600006WS000100DDM   0000802700Y
28869366XAK27GA0000YI001000
28869368XAK27GA0000XJ002000
28869368AAK27GA0000YJS001000SPY   0001426200Y
28869370XBK27GA0000LX002000
28869371A2K27G6000057B002000BMY   0000033900Y
28869376XAK27GA0000YG001000
28869378AAK27GA0000YKB005000SPY   0001425500Y
28869381AAK27GA0000YLB002500SPY   0001425500Y
28869384XAK27GA0000YJ001000
28869389X3K27G600006N002000
28869403X9K27G60000OE002000
28869411AAK27GA0000YMS000500SPY   0001426000Y
28869411XAK27GA0000YB000500
28869416X4K27GA0000D0000100
28869419XCK27GA000036002000
28869422X1K27GA00005V002000
28869422A7K27GA00003XB002000LMT   0000200300Y
28869423A3K27G600006XB002000CELG  0000477400Y
28869428A4K27GA0000DCB000100DRYS  0001070100Y
28869436X4K27GA0000DA000100
28869438XAK27GA0000XZ003000
28869438XAK27GA0000E7001000
28869438AAK27GA0000E7B001000SPY   0001425300Y
28869438X4K27GA0000D9000200
28869439XAK27GA0000V4001000
28869439AAK27GA0000YNS001000SPY   0001426100Y
28869440AAK27GA0000YOB003000SPY   0001425000Y
28869446A4K27GA0000DDS000100DRYS  0001071900Y
28869447A6K27GA00007TB002000IMCL  0000343200Y
28869455X2K27G600004X002000
28869456A7K27GA00003YB002000LMT   0000201100Y
28869467A4K27GA0000DES000200DIA   0001299100Y
28869475XBK27GA0000LY002000
28869495X3K27G600004E002000
28869511X4K27GA0000DD000100
28869516P4K27GA0000DDS000100DRYS  0001071900000N4AQ00008
28869523A1K27GA00005XB002000AFL   0000120200Y
28869531X4K27GA0000D6002000
28869533ACK27GA000037B002000WYE   0000075700Y
28869546X6K27GA00007P000500
28869549XBK27GA0000MK000100
28869549XBK27GA0000ML000100
28869551X1K27GA00005W002000
28869551ABK27GA0000MMS000100TWM   0000702200Y
28869552X5K27GA00003C002000
28869550A6K27GA00007UB000500IWM   0000736300Y
28869554X6K27GA00007U000500
28869554A6K27GA00007UB000500IWM   0000736700Y
28869557ABK27GA0000MNB000100UWM   0000542700Y
28869557XBK27GA0000MM000100
28869557ABK27GA0000MOS000100TWM   0000702000Y
28869575A1K27GA00005YB002000AFL   0000121000Y
28869580X2K27G6000052002000
28869581A2K27G6000058B002000CAG   0000035800Y
28869595X2K27G600004W002000
28869611X3K27G600004B002000
28869613A3K27G600006YB002000CVS   0000072900Y
28869624X3K27G600006Q002000
28869633X3K27G600006U002000
28869635X6K27GA00007G002000
28869643X6K27GA00005Z002000
28869651A4K27GA0000DFB002000EAT   0000198700Y
28869661A4K27GA0000DGB002000EAT   0000199500Y
28869663A5K27GA00004IB002000HMY   0000086300Y
28869672A5K27GA00004JB002000HNZ   0000078400Y
28869684A5K27GA00004KB002000HOT   0000080900Y
28869689X5K27GA00003F002000
28869702A4K27GA0000DHB002000EIX   0000086500Y
28869718A7K27GA00003ZB002000MDY   0001575400Y
28869722A5K27GA00004LB002000HNZ   0000079200Y
28869743A5K27GA00004MB002000HOT   0000081700Y
28869746A6K27GA00007VB002000IWN   0000665600Y
28869809AAK27GA0000YPS002500SPY   0001426000Y
28869817X6K27GA00007U000500
28869817A6K27GA00007UB000500IWM   0000736300Y
28869821XBK27GA0000MN000100
28869821XBK27GA0000MO000100
28869823ABK27GA0000MPS000100TWM   0000702200Y
28869828X6K27GA00007U000500
28869828A6K27GA00007UB000500IWM   0000736700Y
28869831ABK27GA0000MQB000100UWM   0000542700Y
28869831XBK27GA0000MP000100
28869831ABK27GA0000MRS000100TWM   0000702000Y
28869835XAK27GA0000QB000500
28869835AAK27GA0000QBS000500SPY   0001425800Y
28869835AAK27GA0000YQS001000SPY   0001426100Y
28869835X6K27GA00007U000500
28869835A6K27GA00007UB000500IWM   0000736300Y
28869838XBK27GA0000MQ000100
28869838XBK27GA0000MR000100
28869838A6K27GA00007WB000100IWM   0000736200Y
28869838X6K27GA00007W000100
28869840ABK27GA0000MSS000100TWM   0000702200Y
28869839X6K27GA00007U000500
28869839A6K27GA00007UB000500IWM   0000736700Y
28869841ABK27GA0000MTB000100UWM   0000542700Y
28869841XBK27GA0000MS000100
28869841ABK27GA0000MUS000100TWM   0000702000Y
28869845X6K27GA00007U000500
28869845A6K27GA00007UB000500IWM   0000736300Y
28869848XBK27GA0000MT000100
28869848XBK27GA0000MU000100
28869848X6K27GA00007U000500
28869848A6K27GA00007UB000500IWM   0000736700Y
28869850ABK27GA0000MVS000100TWM   0000702200Y
28869851ABK27GA0000MWB000100UWM   0000542700Y
28869851XBK27GA0000MV000100
28869851ABK27GA0000MXS000100TWM   0000702000Y
28869856X6K27GA00007U000500
28869856A6K27GA00007UB000500IWM   0000736300Y
28869876X6K27GA00007U000500
28869876A6K27GA00007UB000500IWM   0000736700Y
28869877XBK27GA0000MW000100
28869877XBK27GA0000MX000100
28869879ABK27GA0000MYB000100UWM   0000542700Y
28869877A6K27GA00007XB000100IWM   0000736200Y
28869879ABK27GA0000MZS000100TWM   0000702000Y
28869878X6K27GA00007X000100
28869879X6K27GA00007U000500
28869879A6K27GA00007UB000500IWM   0000736300Y
28869882XBK27GA0000MY000100
28869882XBK27GA0000MZ000100
28869882A6K27GA00007YB000100IWM   0000736200Y
28869884ABK27GA0000N0S000100TWM   0000702200Y
28869882X6K27GA00007Y000100
28869886ABK27GA0000N1B000100UWM   0000542700Y
28869887XBK27GA0000N0000100
28869887ABK27GA0000N2S000100TWM   0000702000Y
28869887XBK27GA0000N1000100
28869887XBK27GA0000N2000100
28869886X6K27GA00007U000500
28869886A6K27GA00007UB000500IWM   0000736700Y
28869887A6K27GA00007ZB000100IWM   0000736200Y
28869889ABK27GA0000N3S000100TWM   0000702200Y
28869888X6K27GA00007Z000100
28869889ABK27GA0000N4B000100UWM   0000542700Y
28869889XBK27GA0000N3000100
28869889ABK27GA0000N5S000100TWM   0000702000Y
28869889X6K27GA00007U000500
28869889A6K27GA00007UB000500IWM   0000736300Y
28869892XBK27GA0000N4000100
28869892XBK27GA0000N5000100
28869894ABK27GA0000N6S000100TWM   0000702200Y
28869896X6K27GA00007U000500
28869896A6K27GA00007UB000500IWM   0000736700Y
28869899ABK27GA0000N7B000100UWM   0000542700Y
28869899XBK27GA0000N6000100
28869899ABK27GA0000N8S000100TWM   0000702000Y
28869905X6K27GA00007U000500
28869905A6K27GA00007UB000500IWM   0000736300Y
28869925X6K27GA00007U000500
28869925A6K27GA00007UB000500IWM   0000736700Y
28869926XBK27GA0000N7000100
28869926XBK27GA0000N8000100
28869927A6K27GA000080B000100IWM   0000736200Y
28869928ABK27GA0000N9S000100TWM   0000702200Y
28869927X6K27GA00007U000500
28869927A6K27GA00007UB000500IWM   0000736300Y
28869927X6K27GA000080000100
28869944XAK27GA0000FI000500
28869944AAK27GA0000FIB000500SPY   0001425200Y
28869944XAK27GA0000E9001000
28869944AAK27GA0000E9S001000SPY   0001425800Y
28869951A6K27GA000081S002000IWM   0000737100Y
28870028X4K27GA0000DC000100
28870028X4K27GA0000CZ000100
28870135XAK27GA0000XW001000
28870135AAK27GA0000YRB001000SPY   0001425300Y
28870137AAK27GA0000YSB001000SPY   0001425300Y
28870147XAK27GA0000E9001000
28870147AAK27GA0000E9S001000SPY   0001426200Y
28870147XAK27GA0000FI000500
28870147AAK27GA0000FIB000500SPY   0001425600Y
28870147XAK27GA0000QB000500
28870147AAK27GA0000QBS000500SPY   0001426200Y
28870147XAK27GA0000YC003000
28870147XAK27GA0000YE003000
28870147XAK27GA0000YH003000
28870147XAK27GA0000YO003000
28870147AAK27GA0000YTB003000SPY   0001425600Y
28870147XAK27GA0000E7001000
28870147AAK27GA0000E7B001000SPY   0001425700Y
28870148AAK27GA0000YUB003000SPY   0001425600Y
28870148XAK27GA0000YQ001000
28870148AAK27GA0000YVB001000SPY   0001425400Y
28870148XAK27GA0000YN001000
28870148A4K27GA0000DIB000100DRYS  0001070100Y
28870148A4K27GA0000DJB000100DRYS  0001070100Y
28870149AAK27GA0000YWS003000SPY   0001426600Y
28870149AAK27GA0000YXS003000SPY   0001426600Y
28870150AAK27GA0000YYS001000SPY   0001426200Y
28870155XAK27GA0000YP002500
28870156XAK27GA0000YK005000
28870156XAK27GA0000YM000500
28870156AAK27GA0000YZB000500SPY   0001425600Y
28870156AAK27GA0000Z0B005000SPY   0001425400Y
28870165XAK27GA0000E7001000
28870165AAK27GA0000E7B001000SPY   0001425300Y
28870165XAK27GA0000YW003000
28870165XAK27GA0000YX003000
28870165XAK27GA0000YV001000
28870166AAK27GA0000Z1S003000SPY   0001426000Y
28870166AAK27GA0000Z2S001000SPY   0001426100Y
28870166AAK27GA0000Z3S003000SPY   0001426000Y
28870165X6K27GA000081002000
28870168XAK27GA0000YZ000500
28870172X6K27GA00007I000100
28870175A4K27GA0000DKB000100DIG   0001238500Y
28870175X4K27GA0000CQ000100
28870175A6K27GA000082B000100IYE   0001532100Y
28870182X4K27GA0000DK000100
28870181X6K27GA000082000100
28870183A6K27GA000083B000100IYE   0001531500Y
28870188XAK27GA0000YT003000
28870187A6K27GA000084S002000IWM   0000737100Y
28870189XAK27GA0000YU003000
28870192AAK27GA0000Z4B003000SPY   0001425000Y
28870192AAK27GA0000Z5B003000SPY   0001425000Y
28870192A4K27GA0000DLB000100DIG   0001237800Y
28870210AAK27GA0000Z6S002500SPY   0001426000Y
28870261AAK27GA0000Z7S001000SPY   0001426100Y
28870353AAK27GA0000Z8S000500SPY   0001426000Y
28870353XAK27GA0000XL002000
28870364X7K27GA00003X002000
28870387X9K27G60000OG005000
28870387X9K27G60000F8003200
28870387A9K27G60000F8S003200QQQQ  0000496000Y
28870391A9K27G60000OMB005000QQQQ  0000495500Y
28870391X9K27G60000EU002000
28870391A9K27G60000EUB002000QQQQ  0000495600Y
28870398X4K27GA000049002000
28870398X7K27GA00003Y002000
28870413X9K27G60000O7002000
28870414X9K27G60000OD001000
28870414AAK27GA0000Z9B002000SHLD  0000741400Y
28870416A9K27G60000ONB001000QQQQ  0000495500Y
28870416A9K27G60000OOB001000QQQQ  0000495400Y
28870417X9K27G60000ON001000
28870417X9K27G60000OO001000
28870416XCK27GA000037002000
28870421X9K27G60000OB001000
28870421A9K27G60000OPB001000QLD   0000889300Y
28870423A9K27G60000OQB001000QLD   0000889400Y
28870423A9K27G60000ORB001000QQQQ  0000495500Y
28870423A9K27G60000OSB001000QQQQ  0000495400Y
28870424X9K27G60000G6002000
28870424A9K27G60000G6B002000QQQQ  0000495300Y
28870424X9K27G60000F5003200
28870424A9K27G60000F5B003200QQQQ  0000495300Y
28870424X9K27G60000O8001000
28870425A9K27G60000OTB001000QQQQ  0000495300Y
28870425X9K27G60000OQ001000
28870425X9K27G60000O6002000
28870426X9K27G60000O6002000
28870426A9K27G60000OUS002000QQQQ  0000496000Y
28870429X9K27G60000OC000100
28870429X9K27G60000OR001000
28870429X9K27G60000OA000100
28870429X9K27G60000OS001000
28870443XAK27GA0000QB000500
28870443AAK27GA0000QBS000500SPY   0001425800Y
28870447ABK27GA0000NAB002000UTX   0000132300Y
28870449X1K27GA00005Y002000
28870451X9K27G60000OU002000
28870467X2K27G6000056002000
28870472A3K27G600006ZB002000CTSH  0000051400Y
28870473X1K27GA00005X002000
28870476X6K27GA00006W002000
28870487X9K27G60000O3005000
28870487A9K27G60000OVS000200QQQQ  0000495900Y
28870487X9K27G60000O4005000
28870487X9K27G60000G3002000
28870487A9K27G60000G3S002000QQQQ  0000495900Y
28870487A9K27G60000OWS005000QQQQ  0000495900Y
28870487A9K27G60000OXS005000QQQQ  0000495900Y
28870504X2K27G6000054002000
28870506X4K27GA0000DH002000
28870524ABK27GA0000NBB002000UTX   0000133100Y
28870522ACK27GA000038B002000WYE   0000076000Y
28870532X9K27G60000OW005000
28870532X9K27G60000F5003200
28870532A9K27G60000F5B003200QQQQ  0000495800Y
28870532X9K27G60000OX005000
28870534A9K27G60000OYS005000QQQQ  0000496300Y
28870534A9K27G60000OZS005000QQQQ  0000496300Y
28870534A9K27G60000P0B002000PDLI  0000022300Y
28870540A1K27GA00005ZB002000ABT   0000098900Y
28870547X3K27G600006S002000
28870549X5K27GA000041002000
28870554X3K27G600006Y002000
28870565X5K27GA00004L002000
28870578X5K27GA00004M002000
28870582A2K27G6000059B002000BDX   0000763800Y
28870590A3K27G6000070B002000CCE   0000190500Y
28870593AAK27GA0000ZAB005000SPY   0001425500Y
28870594XAK27GA0000E9001000
28870594AAK27GA0000E9S001000SPY   0001425800Y
28870594XAK27GA0000Z0005000
28870616A1K27GA000060B002000ABT   0000099700Y
28870619A4K27GA0000DMB002000EIX   0000087100Y
28870631X5K27GA00004J002000
28870632A2K27G600005AB002000BBT   0000058400Y
28870645X5K27GA00004K002000
28870648A2K27G600005BB002000BDX   0000764600Y
28870658A5K27GA00004NB002000GE    0000299300Y
28870664XAK27GA0000FI000500
28870664AAK27GA0000FIB000500SPY   0001425200Y
28870665A3K27G6000071B002000CCE   0000191300Y
28870668XAK27GA0000F5000500
28870668AAK27GA0000F5B000500SPY   0001425200Y
28870669XAK27GA0000ZA005000
28870670AAK27GA0000ZBB000500SPY   0001425400Y
28870672XBK27GA0000L5001000
28870674ABK27GA0000NCB001000SSO   0000764500Y
28870685X8K27G600002X000500
28870685X8K27G600002Y000100
28870686A3K27G6000072B002000COH   0000061600Y
28870686A8K27G6000031S000100MVV   0000809700Y
28870687A8K27G6000032B000500MZZ   0000491400Y
28870689X6K27GA00002B000500
28870689A6K27GA00002BS000500IWM   0000736800Y
28870691XBK27GA0000NC001000
28870691XAK27GA0000X3001000
28870692ABK27GA0000NDS000100UWM   0000543500Y
28870692ABK27GA0000NEB000100TWM   0000700900Y
28870692ABK27GA0000NFB000100TWM   0000700800Y
28870692XBK27GA0000I1000100
28870693ABK27GA0000NGB001000SSO   0000764400Y
28870693X6K27GA00002C000500
28870693A6K27GA00002CB000500IWM   0000736200Y
28870693A6K27GA000085B002000JCI   0000058600Y
28870695X6K27GA00002C000500
28870695A6K27GA00002CB000500IWM   0000736600Y
28870698A8K27G6000033B000500MZZ   0000491500Y
28870698A8K27G6000034S000100MVV   0000809500Y
28870697X6K27GA00002C000500
28870697A6K27GA00002CB000500IWM   0000736200Y
28870706A3K27G6000073B002000CVS   0000074900Y
28870705X6K27GA00002C000500
28870705A6K27GA00002CB000500IWM   0000736600Y
28870716X6K27GA00002C000500
28870716A6K27GA00002CB000500IWM   0000736200Y
28870720X8K27G600002R000500
28870720X8K27G600002S000100
28870720X8K27G600002Z000100
28870722A8K27G6000035S000500MZZ   0000493800Y
28870722A8K27G6000036B000100MVV   0000806300Y
28870720X6K27GA00002C000500
28870720A6K27GA00002CB000500IWM   0000736600Y
28870722XBK27GA0000GC000100
28870722XBK27GA0000N9000100
28870724ABK27GA0000NHB000100UWM   0000542500Y
28870724ABK27GA0000NIS000100TWM   0000702200Y
28870726X6K27GA00002C000500
28870726A6K27GA00002CB000500IWM   0000736200Y
28870729X9K27G60000OJ000500
28870729X9K27G60000OT001000
28870732A5K27GA00004OB002000GE    0000300100Y
28870736X6K27GA00002C000500
28870736A6K27GA00002CB000500IWM   0000736600Y
28870746X6K27GA00002C000500
28870746A6K27GA00002CB000500IWM   0000736200Y
28870767XBK27GA0000NH000100
28870767XBK27GA0000NI000100
28870768ABK27GA0000NJS000100TWM   0000702200Y
28870769ABK27GA0000NKB000100UWM   0000542500Y
28870786XBK27GA0000NK000100
28870787XBK27GA0000NJ000100
28870788ABK27GA0000NLB000100UWM   0000542500Y
28870787A6K27GA000086B000100IWM   0000736100Y
28870787X6K27GA000086000100
28870788ABK27GA0000NMS000100TWM   0000702200Y
28870806XBK27GA0000NL000100
28870806XBK27GA0000NM000100
28870808ABK27GA0000NNS000100TWM   0000702400Y
28870811AAK27GA0000ZCB000100SH    0000618300Y
28870812ABK27GA0000NOS001000SSO   0000765400Y
28870812XBK27GA0000L9001000
28870816XBK27GA0000NN000100
28870816ABK27GA0000NPB000100UWM   0000542500Y
28870817ABK27GA0000NQS000100TWM   0000702200Y
28870826XBK27GA0000NP000100
28870827XBK27GA0000NQ000100
28870829ABK27GA0000NRS000100TWM   0000702400Y
28870925XAK27GA0000NY000500
28870925AAK27GA0000NYS000500SPY   0001425800Y
28870925XAK27GA0000WZ002000
28870934X4K27GA00003H000200
28870934A4K27GA00003HB000200DIA   0001298600Y
28870936X4K27GA0000B9000100
28870937X3K27G600005M000100
28871095X6K27GA00002C000500
28871104A4K27GA0000DNB000100DOG   0000597000Y
28871104A4K27GA0000DOB000100DXD   0000499400Y
28871105A3K27G6000074S000100DDM   0000802600Y
28871105AAK27GA0000ZDB005000SPY   0001425400Y
28871105A6K27GA000087B000500IWM   0000736600Y
28871108ABK27GA0000NSB000100UWM   0000542500Y
28871108XBK27GA0000NR000100
28871108ABK27GA0000NTS000100TWM   0000702200Y
28871115X6K27GA000087000500
28871115A6K27GA000087B000500IWM   0000736200Y
28871118XBK27GA0000NT000100
28871118XBK27GA0000NS000100
28871120ABK27GA0000NUS000100TWM   0000702400Y
28871119X6K27GA000087000500
28871119A6K27GA000087B000500IWM   0000736600Y
28871123ABK27GA0000NVB000100UWM   0000542500Y
28871123ABK27GA0000NWS000100TWM   0000702200Y
28871123XBK27GA0000NU000100
28871125X6K27GA000087000500
28871125A6K27GA000087B000500IWM   0000736200Y
28871128XBK27GA0000NV000100
28871128XBK27GA0000NW000100
28871130ABK27GA0000NXS000100TWM   0000702400Y
28871133X6K27GA000087000500
28871133A6K27GA000087B000500IWM   0000736600Y
28871135X6K27GA000087000500
28871135A6K27GA000087B000500IWM   0000736200Y
28871136ABK27GA0000NYB000100UWM   0000542500Y
28871137XBK27GA0000NX000100
28871137ABK27GA0000NZS000100TWM   0000702200Y
28871138XBK27GA0000NZ000100
28871138XBK27GA0000NY000100
28871140ABK27GA0000O0S000100TWM   0000702400Y
28871145X6K27GA000087000500
28871145A6K27GA000087B000500IWM   0000736600Y
28871148ABK27GA0000O1B000100UWM   0000542500Y
28871148XBK27GA0000O0000100
28871148ABK27GA0000O2S000100TWM   0000702200Y
28871155X6K27GA000087000500
28871155A6K27GA000087B000500IWM   0000736200Y
28871158XBK27GA0000O1000100
28871158XBK27GA0000O2000100
28871160ABK27GA0000O3S000100TWM   0000702400Y
28871159A6K27GA000088B000100IWM   0000736100Y
28871159X6K27GA000088000100
28871159X6K27GA000087000500
28871159A6K27GA000087B000500IWM   0000736600Y
28871162ABK27GA0000O4B000100UWM   0000542500Y
28871163ABK27GA0000O5S000100TWM   0000702200Y
28871163XBK27GA0000O3000100
28871165X6K27GA000087000500
28871165A6K27GA000087B000500IWM   0000736200Y
28871168XBK27GA0000O4000100
28871168XBK27GA0000O5000100
28871170ABK27GA0000O6S000100TWM   0000702400Y
28871175X6K27GA000087000500
28871175A6K27GA000087B000500IWM   0000736600Y
28871178ABK27GA0000O7B000100UWM   0000542500Y
28871178XBK27GA0000O6000100
28871178ABK27GA0000O8S000100TWM   0000702200Y
28871183X4K27GA0000DJ000100
28871183X4K27GA0000DI000100
28871185X6K27GA000087000500
28871185A6K27GA000087B000500IWM   0000736200Y
28871188XBK27GA0000O7000100
28871188XBK27GA0000O8000100
28871190ABK27GA0000O9S000100TWM   0000702400Y
28871189X6K27GA000087000500
28871189A6K27GA000087B000500IWM   0000736600Y
28871193ABK27GA0000OAB000100UWM   0000542500Y
28871193ABK27GA0000OBS000100TWM   0000702200Y
28871193XBK27GA0000O9000100
28871195X6K27GA000087000500
28871195A6K27GA000087B000500IWM   0000736200Y
28871198XBK27GA0000OA000100
28871198XBK27GA0000OB000100
28871200ABK27GA0000OCS000100TWM   0000702400Y
28871205X6K27GA000087000500
28871205A6K27GA000087B000500IWM   0000736600Y
28871215X6K27GA000087000500
28871215A6K27GA000087B000500IWM   0000736200Y
28871217XAK27GA0000YL002500
28871217AAK27GA0000ZEB002500SPY   0001425400Y
28871235X6K27GA000087000500
28871235A6K27GA000087B000500IWM   0000736600Y
28871245X6K27GA000087000500
28871245A6K27GA000087B000500IWM   0000736200Y
28871255X6K27GA000087000500
28871255A6K27GA000087B000500IWM   0000736600Y
28871265X6K27GA000087000500
28871265A6K27GA000087B000500IWM   0000736200Y
28871275X6K27GA000087000500
28871275A6K27GA000087B000500IWM   0000736600Y
28871285X6K27GA000087000500
28871285A6K27GA000087B000500IWM   0000736200Y
28871295X6K27GA000087000500
28871295A6K27GA000087B000500IWM   0000736600Y
28871305X6K27GA000087000500
28871305A6K27GA000087B000500IWM   0000736200Y
28871315X6K27GA000087000500
28871315A6K27GA000087B000500IWM   0000736600Y
28871325X6K27GA000087000500
28871325A6K27GA000087B000500IWM   0000736200Y
28871335X6K27GA000087000500
28871335A6K27GA000087B000500IWM   0000736600Y
28871345X6K27GA000087000500
28871345A6K27GA000087B000500IWM   0000736200Y
28871353AAK27GA0000ZFB002000SPLS  0000035500Y
28871355X6K27GA000087000500
28871355A6K27GA000087B000500IWM   0000736600Y
28871364X2K27G6000057002000
28871365X6K27GA000087000500
28871365A6K27GA000087B000500IWM   0000736200Y
28871375X5K27GA000013002000
28871375X6K27GA000087000500
28871375A6K27GA000087B000500IWM   0000736600Y
28871383X5K27GA00003Q002000
28871385X6K27GA000087000500
28871385A6K27GA000087B000500IWM   0000736200Y
28871395X6K27GA000087000500
28871395A6K27GA000087B000500IWM   0000736600Y
28871405X6K27GA000087000500
28871405A6K27GA000087B000500IWM   0000736200Y
28871415A4K27GA0000DPB002000FFIV  0000264600Y
28871415A7K27GA000040B002000LMT   0000206300Y
28871416X5K27GA000017002000
28871415X6K27GA000087000500
28871415A6K27GA000087B000500IWM   0000736600Y
28871425X6K27GA000087000500
28871425A6K27GA000087B000500IWM   0000736200Y
28871435X6K27GA000087000500
28871435A6K27GA000087B000500IWM   0000736600Y
28871444XBK27GA0000NA002000
28871445X6K27GA000087000500
28871445A6K27GA000087B000500IWM   0000736200Y
28871450XBK27GA0000NB002000
28871455X6K27GA000087000500
28871455A6K27GA000087B000500IWM   0000736600Y
28871459XCK27GA000038002000
28871460X1K27GA000060002000
28871465X6K27GA000087000500
28871465A6K27GA000087B000500IWM   0000736200Y
28871473X3K27G6000073002000
28871475X6K27GA000087000500
28871475A6K27GA000087B000500IWM   0000736600Y
28871481X1K27GA00005Z002000
28871485X4K27GA0000A2002000
28871485X6K27GA000087000500
28871485A6K27GA000087B000500IWM   0000736200Y
28871490A4K27GA0000DQB000100DRYS  0001070100Y
28871490A4K27GA0000DRB000100DRYS  0001070100Y
28871495X6K27GA000087000500
28871495A6K27GA000087B000500IWM   0000736600Y
28871505X6K27GA000087000500
28871505A6K27GA000087B000500IWM   0000736200Y
28871506A1K27GA000061B002000AFL   0000123900Y
28871510A7K27GA000041B002000LMT   0000207100Y
28871515X6K27GA000087000500
28871515A6K27GA000087B000500IWM   0000736600Y
28871525X6K27GA000087000500
28871525A6K27GA000087B000500IWM   0000736200Y
28871529A2K27G600005CB002000BBT   0000058600Y
28871534ACK27GA000039B002000WYE   0000078100Y
28871535X6K27GA000087000500
28871535A6K27GA000087B000500IWM   0000736600Y
28871545X6K27GA000087000500
28871545A6K27GA000087B000500IWM   0000736200Y
28871550X2K27G6000058002000
28871555X6K27GA000087000500
28871555A6K27GA000087B000500IWM   0000736600Y
28871560A1K27GA000062B002000AFL   0000124700Y
28871562A3K27G6000075B002000COH   0000061800Y
28871565X6K27GA000087000500
28871565A6K27GA000087B000500IWM   0000736200Y
28871574A2K27G600005DB002000CAG   0000037900Y
28871575X6K27GA000087000500
28871575A6K27GA000087B000500IWM   0000736600Y
28871585A4K27GA0000DSB002000EIX   0000089300Y
28871585X6K27GA000087000500
28871585A6K27GA000087B000500IWM   0000736200Y
28871592A5K27GA00004PB002000HMY   0000087300Y
28871602A5K27GA00004QB002000HNZ   0000081800Y
28871626A5K27GA00004RB002000HOT   0000084400Y
28871630X9K27G60000F5003200
28871630A9K27G60000F5B003200QQQQ  0000495300Y
28871630X9K27G60000OY005000
28871630X9K27G60000OZ005000
28871631A9K27G60000P1S005000QQQQ  0000495900Y
28871631A9K27G60000P2S005000QQQQ  0000495900Y
28871634A3K27G6000076B002000CVS   0000075300Y
28871645A6K27GA000089B002000JCI   0000060300Y
28871652X4K27GA0000DM002000
28871678A5K27GA00004SB002000HNZ   0000081000Y
28871687A5K27GA00004TB002000HOT   0000083600Y
28871695A6K27GA00008AB002000JWN   0000350500Y
28871699A7K27GA000042B002000MMC   0000037900Y
28871734X9K27G60000F5003200
28871734A9K27G60000F5B003200QQQQ  0000495800Y
28871734X9K27G60000P1005000
28871734X9K27G60000P2005000
28871736A9K27G60000P3S005000QQQQ  0000496300Y
28871736A9K27G60000P4S005000QQQQ  0000496300Y
28872204X4K27GA0000B8000200
28872205A4K27GA0000DTS000047DIA   0001299000Y
28872231AAK27GA0000ZGS002500SPY   0001425900Y
28872231XAK27GA0000Z6002500
28872346X9K27G60000F5003200
28872346A9K27G60000F5B003200QQQQ  0000495300Y
28872347A9K27G60000P5S002000QQQQ  0000496000Y
28872389A5K27GA00004UB002000GG    0000385200Y
28872393A2K27G600005EB002000BMY   0000035700Y
28872404A5K27GA00004VB002000GM    0000175600Y
28872414X7K27GA000040002000
28872423ABK27GA0000ODB002000UTX   0000136300Y
28872423X7K27GA000041002000
28872437XCK27GA00002N002000
28872445ACK27GA00003AB002000WYE   0000078500Y
28872450A5K27GA00004WB002000GG    0000386000Y
28872463X9K27G60000P4005000
28872464A1K27GA000063B002000ABT   0000101900Y
28872462XCK27GA00002P002000
28872465A9K27G60000P6S005000QQQQ  0000495900Y
28872474XCK27GA000039002000
28872487X1K27GA000061002000
28872498ABK27GA0000OEB002000UTX   0000137100Y
28872509X1K27GA000062002000
28872511A2K27G600005FB002000CAG   0000037700Y
28872532X2K27G600005A002000
28872532X3K27G6000072002000
28872550A1K27GA000064B002000ABT   0000102800Y
28872555X3K27G6000076002000
28872584A4K27GA0000DUB002000EIX   0000089900Y
28872595X5K27GA00004S002000
28872600X5K27GA00004T002000
28872608X6K27GA000085002000
28872629A3K27G6000077B002000CVS   0000077300Y
28872639X4K27GA0000DS002000
28872647X4K27GA0000AL002000
28872650X6K27GA000087000500
28872651A4K27GA0000DVB002000DIS   0000329200Y
28872650A6K27GA00008BB000500IWM   0000736100Y
28872652XBK27GA0000OC000100
28872652ABK27GA0000OFS000100TWM   0000702200Y
28872652ABK27GA0000OGB000100UWM   0000542500Y
28872654X5K27GA00004Q002000
28872655X6K27GA00008B000500
28872655A6K27GA00008BB000500IWM   0000736200Y
28872657XBK27GA0000OF000100
28872657XBK27GA0000OG000100
28872659ABK27GA0000OHS000100TWM   0000702400Y
28872658X6K27GA00008B000500
28872658A6K27GA00008BB000500IWM   0000736600Y
28872661ABK27GA0000OIB000100UWM   0000542500Y
28872661XBK27GA0000OH000100
28872661X5K27GA00004R002000
28872661ABK27GA0000OJS000100TWM   0000702200Y
28872665X6K27GA00008B000500
28872665A6K27GA00008BB000500IWM   0000736200Y
28872668XBK27GA0000OI000100
28872668XBK27GA0000OJ000100
28872670ABK27GA0000OKS000100TWM   0000702400Y
28872669X6K27GA00008B000500
28872669A6K27GA00008BB000500IWM   0000736600Y
28872672ABK27GA0000OLB000100UWM   0000542500Y
28872672XBK27GA0000OK000100
28872672ABK27GA0000OMS000100TWM   0000702200Y
28872675X6K27GA00008B000500
28872675A6K27GA00008BB000500IWM   0000736200Y
28872678XBK27GA0000OL000100
28872678XBK27GA0000OM000100
28872680ABK27GA0000ONS000100TWM   0000702400Y
28872684A7K27GA000043B002000MAT   0000185000Y
28872686ABK27GA0000OOB000100UWM   0000542500Y
28872685X6K27GA00008B000500
28872685A6K27GA00008BB000500IWM   0000736600Y
28872687ABK27GA0000OPS000100TWM   0000702200Y
28872687XBK27GA0000ON000100
28872695X6K27GA00008B000500
28872695A6K27GA00008BB000500IWM   0000736200Y
28872698XBK27GA0000OO000100
28872698XBK27GA0000OP000100
28872700ABK27GA0000OQS000100TWM   0000702400Y
28872699X6K27GA00008B000500
28872699A6K27GA00008BB000500IWM   0000736600Y
28872702ABK27GA0000ORB000100UWM   0000542500Y
28872702XBK27GA0000OQ000100
28872702ABK27GA0000OSS000100TWM   0000702200Y
28872705X6K27GA00008B000500
28872705A6K27GA00008BB000500IWM   0000736200Y
28872708XBK27GA0000OR000100
28872708XBK27GA0000OS000100
28872710ABK27GA0000OTS000100TWM   0000702400Y
28872709X6K27GA00008B000500
28872709A6K27GA00008BB000500IWM   0000736600Y
28872712ABK27GA0000OUB000100UWM   0000542500Y
28872712XBK27GA0000OT000100
28872712ABK27GA0000OVS000100TWM   0000702200Y
28872715X6K27GA00008B000500
28872715A6K27GA00008BB000500IWM   0000736200Y
28872718XBK27GA0000OU000100
28872718XBK27GA0000OV000100
28872718A6K27GA00008CB000100IWM   0000736100Y
28872718X6K27GA00008C000100
28872720ABK27GA0000OWS000100TWM   0000702400Y
28872719X6K27GA00008B000500
28872719A6K27GA00008BB000500IWM   0000736600Y
28872721ABK27GA0000OXB000100UWM   0000542500Y
28872722ABK27GA0000OYS000100TWM   0000702200Y
28872722XBK27GA0000OW000100
28872725X6K27GA00008B000500
28872725A6K27GA00008BB000500IWM   0000736200Y
28872728XBK27GA0000OX000100
28872729XBK27GA0000OY000100
28872728A6K27GA00008DB000100IWM   0000736100Y
28872730ABK27GA0000OZS000100TWM   0000702400Y
28872729X6K27GA00008D000100
28872729X6K27GA00008B000500
28872729A6K27GA00008BB000500IWM   0000736600Y
28872733ABK27GA0000P0B000100UWM   0000542500Y
28872733XBK27GA0000OZ000100
28872733ABK27GA0000P1S000100TWM   0000702200Y
28872735X6K27GA00008B000500
28872735A6K27GA00008BB000500IWM   0000736200Y
28872738XBK27GA0000P0000100
28872738XBK27GA0000P1000100
28872740ABK27GA0000P2S000100TWM   0000702400Y
28872745X6K27GA00008B000500
28872745A6K27GA00008BB000500IWM   0000736600Y
28872746ABK27GA0000P3B000100UWM   0000542500Y
28872747ABK27GA0000P4S000100TWM   0000702200Y
28872747XBK27GA0000P2000100
28872755X6K27GA00008B000500
28872755A6K27GA00008BB000500IWM   0000736200Y
28872756XBK27GA0000P3000100
28872756XBK27GA0000P4000100
28872758ABK27GA0000P5S000100TWM   0000702400Y
28872758X6K27GA00008B000500
28872758A6K27GA00008BB000500IWM   0000736600Y
28872765X6K27GA00008B000500
28872765A6K27GA00008BB000500IWM   0000736200Y
28872773XAK27GA0000SJ000600
28872773AAK27GA0000SJB000600SPY   0001419800Y
28872775X6K27GA00008B000500
28872775A6K27GA00008BB000500IWM   0000736600Y
28872776ABK27GA0000P6B000100UWM   0000542500Y
28872777XBK27GA0000P5000100
28872777ABK27GA0000P7S000100TWM   0000702200Y
28872785X6K27GA00008B000500
28872785A6K27GA00008BB000500IWM   0000736200Y
28872786XBK27GA0000P6000100
28872787XBK27GA0000P7000100
28872788ABK27GA0000P8S000100TWM   0000702400Y
28872788X6K27GA00008B000500
28872788A6K27GA00008BB000500IWM   0000736600Y
28872795X6K27GA00008B000500
28872795A6K27GA00008BB000500IWM   0000736200Y
28872805X6K27GA00008B000500
28872805A6K27GA00008BB000500IWM   0000736600Y
28872806ABK27GA0000P9B000100UWM   0000542500Y
28872807ABK27GA0000PAS000100TWM   0000702200Y
28872807XBK27GA0000P8000100
28872815X6K27GA00008B000500
28872815A6K27GA00008BB000500IWM   0000736200Y
28872816XBK27GA0000P9000100
28872816XBK27GA0000PA000100
28872818ABK27GA0000PBS000100TWM   0000702400Y
28872818X6K27GA00008B000500
28872818A6K27GA00008BB000500IWM   0000736600Y
28872825X6K27GA00008B000500
28872825A6K27GA00008BB000500IWM   0000736200Y
28872836ABK27GA0000PCB000100UWM   0000542500Y
28872836XBK27GA0000PB000100
28872836ABK27GA0000PDS000100TWM   0000702200Y
28872835X6K27GA00008B000500
28872835A6K27GA00008BB000500IWM   0000736600Y
28872846XBK27GA0000PC000100
28872846XBK27GA0000PD000100
28872845X6K27GA00008B000500
28872845A6K27GA00008BB000500IWM   0000736200Y
28872848ABK27GA0000PES000100TWM   0000702400Y
28872855X6K27GA00008B000500
28872855A6K27GA00008BB000500IWM   0000736600Y
28872857ABK27GA0000PFS000100TWM   0000702200Y
28872857XBK27GA0000PE000100
28872857ABK27GA0000PGB000100UWM   0000542500Y
28872866XBK27GA0000PG000100
28872866XBK27GA0000PF000100
28872865X6K27GA00008B000500
28872865A6K27GA00008BB000500IWM   0000736200Y
28872867A6K27GA00008EB000100IWM   0000736100Y
28872867X6K27GA00008E000100
28872868ABK27GA0000PHS000100TWM   0000702400Y
28872875X6K27GA00008B000500
28872875A6K27GA00008BB000500IWM   0000736600Y
28872886X6K27GA00008B000500
28872886A6K27GA00008BB000500IWM   0000736200Y
28872895X6K27GA00008B000500
28872895A6K27GA00008BB000500IWM   0000736600Y
28872905X6K27GA00008B000500
28872905A6K27GA00008BB000500IWM   0000736200Y
28872915X6K27GA00008B000500
28872915A6K27GA00008BB000500IWM   0000736600Y
28872925X6K27GA00008B000500
28872925A6K27GA00008BB000500IWM   0000736200Y
28872935X6K27GA00008B000500
28872935A6K27GA00008BB000500IWM   0000736600Y
28872945X6K27GA00008B000500
28872945A6K27GA00008BB000500IWM   0000736200Y
28872955X6K27GA00008B000500
28872955A6K27GA00008BB000500IWM   0000736600Y
28872965X6K27GA00008B000500
28872965A6K27GA00008BB000500IWM   0000736200Y
28872975X6K27GA00008B000500
28872975A6K27GA00008BB000500IWM   0000736600Y
28872986X6K27GA00008B000500
28872986A6K27GA00008BB000500IWM   0000736200Y
28872995X6K27GA00008B000500
28872995A6K27GA00008BB000500IWM   0000736600Y
28873005X6K27GA00008B000500
28873005A6K27GA00008BB000500IWM   0000736200Y
28873015X6K27GA00008B000500
28873015A6K27GA00008BB000500IWM   0000736600Y
28873025X6K27GA00008B000500
28873025A6K27GA00008BB000500IWM   0000736200Y
28873027XAK27GA0000TB003000
28873029XBK27GA0000NO001000
28873029ABK27GA0000PIS001000SSO   0000765300Y
28873028XAK27GA0000F7000500
28873028AAK27GA0000F7B000500SPY   0001425100Y
28873029XAK27GA0000ZG002500
28873029XAK27GA0000TM002000
28873029AAK27GA0000ZHS003000SPY   0001425800Y
28873029XAK27GA0000NZ000500
28873029AAK27GA0000NZS000500SPY   0001425700Y
28873029AAK27GA0000ZIS003000SPY   0001425800Y
28873030XAK27GA0000FG000500
28873030AAK27GA0000FGB000500SPY   0001425100Y
28873030XAK27GA0000U0001000
28873030XAK27GA0000O8000500
28873030AAK27GA0000O8S000500SPY   0001425700Y
28873030AAK27GA0000ZJS001000SPY   0001425700Y
28873030XAK27GA0000E6001000
28873030AAK27GA0000E6S001000SPY   0001425700Y
28873030AAK27GA0000ZKS002000SPY   0001425800Y
28873030XAK27GA0000E8001000
28873030AAK27GA0000E8B001000SPY   0001425200Y
28873030XAK27GA0000TU001000
28873030XAK27GA0000TC003000
28873030XAK27GA0000Q8000500
28873030XAK27GA0000ZD005000
28873030AAK27GA0000ZLB005000SPY   0001425200Y
28873032AAK27GA0000ZMS000500SPY   0001425700Y
28873032AAK27GA0000ZNB001000SDS   0000547600Y
28873032AAK27GA0000ZOB001000SPY   0001425200Y
28873032XAK27GA0000TQ001000
28873032XAK27GA0000TR001000
28873032XBK27GA0000NG001000
28873033ABK27GA0000PJB001000SSO   0000764100Y
28873032AAK27GA0000ZPS001000SPY   0001425700Y
28873033XAK27GA0000TN001000
28873034XBK27GA0000PI001000
28873034ABK27GA0000PKS001000SSO   0000765200Y
28873034XAK27GA0000EB001000
28873034AAK27GA0000EBB001000SPY   0001425100Y
28873035ABK27GA0000PLB001000SSO   0000764300Y
28873035XBK27GA0000GO001000
28873035X6K27GA00008B000500
28873035A6K27GA00008BB000500IWM   0000736600Y
28873038X6K27GA00008B000500
28873038A6K27GA00008BB000500IWM   0000736200Y
28873042X4K27GA00007C000200
28873042A4K27GA00007CB000200DIA   0001298500Y
28873044X4K27GA0000B2000100
28873044AAK27GA0000ZQB001000SPY   0001425100Y
28873045X4K27GA0000B3000100
28873045XAK27GA0000E5001000
28873045AAK27GA0000E5S001000SPY   0001425700Y
28873045XAK27GA0000FD000500
28873045AAK27GA0000FDB000500SPY   0001425000Y
28873045XAK27GA0000EX000500
28873045AAK27GA0000EXB000500SPY   0001425000Y
28873045XAK27GA0000O6000500
28873045AAK27GA0000O6S000500SPY   0001425700Y
28873045X4K27GA0000CB000200
28873045A4K27GA0000CBS000200DIA   0001298900Y
28873045XAK27GA0000T5003000
28873046XAK27GA0000F2000500
28873046AAK27GA0000F2B000500SPY   0001424900Y
28873046AAK27GA0000ZRS002000SPY   0001425700Y
28873046XAK27GA0000E4001000
28873046AAK27GA0000E4B001000SPY   0001425000Y
28873046XAK27GA0000FE000500
28873046AAK27GA0000FEB000500SPY   0001424900Y
28873046X4K27GA00003H000200
28873046X4K27GA000062000200
28873046A4K27GA000062B000200DIA   0001298400Y
28873045X3K27G600005G000100
28873046XAK27GA0000T8003000
28873046XAK27GA0000YS001000
28873046XAK27GA0000YR001000
28873046XAK27GA0000T6001000
28873046AAK27GA0000ZSS002000SPY   0001425800Y
28873046XAK27GA0000YY001000
28873046XAK27GA0000YD001000
28873047X9K27G60000G8002000
28873047A9K27G60000G8B002000QQQQ  0000495200Y
28873047A4K27GA0000DWS000100DXD   0000500400Y
28873047XAK27GA0000EW000500
28873047AAK27GA0000EWS000500SPY   0001425700Y
28873047XBK27GA0000PJ001000
28873047AAK27GA0000ZTB003000SPY   0001424800Y
28873048AAK27GA0000ZUB001000SPY   0001425000Y
28873048AAK27GA0000ZVB003000SPY   0001424800Y
28873048AAK27GA0000ZWB002000SPY   0001425200Y
28873048XAK27GA0000TA001000
28873048AAK27GA0000ZXS001000SPY   0001425700Y
28873049XAK27GA0000ZN001000
28873049AAK27GA0000ZYB001000SDS   0000547700Y
28873049XAK27GA0000ZL005000
28873050X9K27G60000P3005000
28873050A9K27G60000P7S005000QQQQ  0000495900Y
28873050XAK27GA0000ZB000500
28873050AAK27GA0000ZZB000500SPY   0001425200Y
28873050XAK27GA0000K1001000
28873050AAK27GA0000K1S001000SPY   0001425700Y
28873051X8K27G6000036000100
28873051X8K27G6000035000500
28873051X9K27G60000ET002000
28873051A9K27G60000ETS002000QQQQ  0000495900Y
28873050XAK27GA0000Z8000500
28873050XAK27GA0000ZE002500
28873051A4K27GA0000DXB000200DIA   0001298300Y
28873052AAK27GA000100S002500SPY   0001425700Y
28873052ABK27GA0000PMS001000SSO   0000765100Y
28873052XBK27GA0000PK001000
28873052XAK27GA0000TF000100
28873053XBK27GA0000PL001000
28873053ABK27GA0000PNB001000SSO   0000764000Y
28873053X3K27G600005E000100
28873055ABK27GA0000POB001000SSO   0000764200Y
28873055A3K27G6000078B000100DDM   0000801000Y
28873061A9K27G60000P8S002000QQQQ  0000496000Y
28873061X9K27G60000NE002000
28873064ABK27GA0000PPB001000SSO   0000763700Y
28873068XAK27GA0000ZM000500
28873068AAK27GA0000ZMS000500SPY   0001425600Y
28873068XAK27GA0000ZP001000
28873068AAK27GA0000ZPS001000SPY   0001425600Y
28873068XAK27GA0000E5001000
28873068AAK27GA0000E5S001000SPY   0001425600Y
28873068XAK27GA0000O6000500
28873068AAK27GA0000O6S000500SPY   0001425600Y
28873068XAK27GA0000ZR002000
28873068AAK27GA0000ZRS002000SPY   0001425600Y
28873068XAK27GA0000EW000500
28873068AAK27GA0000EWS000500SPY   0001425600Y
28873068XAK27GA0000ZX001000
28873068AAK27GA0000ZXS001000SPY   0001425600Y
28873068XAK27GA0000K1001000
28873068AAK27GA0000K1S001000SPY   0001425600Y
28873068X9K27G60000NZ005000
28873068XAK27GA0000O2000500
28873068AAK27GA0000O2S000500SPY   0001425600Y
28873069A9K27G60000P9S002000QQQQ  0000496100Y
28873070A9K27G60000PAB005000QQQQ  0000495400Y
28873071X9K27G60000EO002000
28873071A9K27G60000EOB002000QQQQ  0000495500Y
28873074XBK27GA0000PN001000
28873082X6K27GA00002A000500
28873082A6K27GA00002AS000500IWM   0000736700Y
28873084XAK27GA0000ZW001000
28873085ABK27GA0000PQS000100UWM   0000543400Y
28873085XBK27GA0000I2000100
28873085ABK27GA0000PRB000100TWM   0000701100Y
28873086ABK27GA0000PSB000100TWM   0000701000Y
28873086XBK27GA0000GV000100
28873086A6K27GA00008FS002000IWM   0000737000Y
28873086X6K27GA00006M002000
28873087X6K27GA00005F000500
28873087A6K27GA00005FB000500IWM   0000736100Y
28873089X4K27GA0000DE000200
28873089A4K27GA0000DES000200DIA   0001298800Y
28873091X9K27G60000NQ005000
28873091X4K27GA0000BB000100
28873091A4K27GA0000DYB000100DXD   0000499500Y
28873092A3K27G6000079S000100DDM   0000802500Y
28873092X3K27G600005S000100
28873092X9K27G60000NI002000
28873092X9K27G60000F6003200
28873092A9K27G60000F6S003200QQQQ  0000495900Y
28873093X9K27G60000NK001000
28873093A9K27G60000PBB005000QQQQ  0000495400Y
28873094X9K27G60000OP001000
28873095A9K27G60000PCB001000QQQQ  0000495400Y
28873096A9K27G60000PDB001000QLD   0000889200Y
28873095X6K27GA00005F000500
28873095A6K27GA00005FB000500IWM   0000736500Y
28873097X9K27G60000PC001000
28873097XBK27GA0000ER000100
28873097XBK27GA0000PH000100
28873096X6K27GA00005F000500
28873096A6K27GA00005FB000500IWM   0000736100Y
28873098ABK27GA0000PTB000100UWM   0000542400Y
28873098XAK27GA0000ZW001000
28873098AAK27GA000101B001000SPY   0001425100Y
28873097A6K27GA00008GB000100IWM   0000736000Y
28873097X6K27GA00008G000100
28873099ABK27GA0000PUS000100TWM   0000702400Y
28873100XBK27GA0000PT000100
28873100XBK27GA0000PU000100
28873101A9K27G60000PEB002000QQQQ  0000495600Y
28873100AAK27GA000102B001000SPY   0001425100Y
28873101X9K27G60000N8001000
28873101A9K27G60000PFB001000QQQQ  0000495200Y
28873101X9K27G60000PD001000
28873101A9K27G60000PGB001000QLD   0000888800Y
28873102ABK27GA0000PVS000100TWM   0000702600Y
28873103A9K27G60000PHB001000QLD   0000888900Y
28873103X9K27G60000ND000100
28873103X9K27G60000LN000100
28873103A9K27G60000PIB001000QQQQ  0000495400Y
28873103X9K27G60000PI001000
28873105A8K27G6000037B000500MZZ   0000491600Y
28873105A8K27G6000038S000100MVV   0000809300Y
28873106ABK27GA0000PWB000100UWM   0000542400Y
28873107ABK27GA0000PXS000100TWM   0000702400Y
28873107XBK27GA0000PV000100
28873107XBK27GA0000PW000100
28873107XBK27GA0000PX000100
28873109ABK27GA0000PYS000100TWM   0000702600Y
28873111X9K27G60000P8002000
28873123X8K27G600002P000500
28873123X8K27G600002Q000100
28873125A8K27G6000039S000500MZZ   0000494000Y
28873125A8K27G600003AB000100MVV   0000806100Y
28873127XAK27GA0000O2000500
28873127AAK27GA0000O2S000500SPY   0001425500Y
28873135X4K27GA0000DT000047
28873136A3K27G600007AS000100DDM   0000802400Y
28873136X3K27G6000063000100
28873135A4K27GA0000DZS000200DIA   0001298700Y
28873135A4K27GA0000E0B000100DOG   0000597100Y
28873158X9K27G60000N5002000
28873157X6K27GA00006H002000
28873159A6K27GA00008HB002000IWM   0000736200Y
28873163XAK27GA0000UD000100
28873163XBK27GA0000PP001000
28873165AAK27GA000103B000100SPY   0001424400Y
28873171X6K27GA00006U010000
28873196X9K27G60000G1002000
28873196A9K27G60000G1S002000QQQQ  0000495800Y
28873202X8K27G600003A000100
28873204A8K27G600003BB000100MVV   0000806000Y
28873258AAK27GA000104S000500SPY   0001425700Y
28873349X3K27G600006Z002000
28873389A7K27GA000044B002000LMT   0000213100Y
28873404X8K27G6000039000500
28873404X8K27G600003B000100
28873406A8K27G600003CS000500MZZ   0000494100Y
28873406A8K27G600003DB000100MVV   0000805900Y
28873406XBK27GA0000OD002000
28873408XCK27GA00003A002000
28873414XBK27GA0000OE002000
28873416X1K27GA000063002000
28873434X2K27G6000053002000
28873433AAK27GA000105B005000SPY   0001424900Y
28873434XAK27GA0000WY005000
28873439X2K27G600005C002000
28873443ACK27GA00003BB002000WMT   0000538700Y
28873449X3K27G6000075002000
28873452AAK27GA000106B002500SPY   0001425200Y
28873463X4K27GA0000DU002000
28873471ACK27GA00003CB002000WYE   0000080500Y
28873488X7K27GA000042002000
28873496X1K27GA000064002000
28873497X9K27G60000NT000500
28873497A9K27G60000PJS000100QID   0000382300Y
28873497X9K27G60000PF001000
28873501A7K27GA000045B002000LMT   0000212300Y
28873514A1K27GA000065B002000AFL   0000128500Y
28873529X2K27G6000055002000
28873533ACK27GA00003DB002000WMT   0000537900Y
28873543A2K27G600005GB002000BBT   0000061300Y
28873550A1K27GA000066B002000AFL   0000127700Y
28873558X2K27G600005D002000
28873564A3K27G600007BB002000CVS   0000077700Y
28873579A3K27G600007CB002000COH   0000064600Y
28873586X3K27G6000077002000
28873592A4K27GA0000E1B002000EIX   0000092100Y
28873603A5K27GA00004XB002000HNZ   0000083600Y
28873609A4K27GA0000E2B002000ELN   0000228100Y
28873612A5K27GA00004YB002000HOT   0000086300Y
28873622A6K27GA00008IB002000JCI   0000061400Y
28873630X6K27GA000089002000
28873636A5K27GA00004ZB002000HNZ   0000084400Y
28873640A7K27GA000046B002000MRK   0000072000Y
28873656A8K27G600003EB002000MU    0000074400Y
28873660XAK27GA0000R0001000
28873660ABK27GA0000PZB001000SSO   0000763900Y
28873660XBK27GA0000PO001000
28873661X4K27GA00007C000200
28873661A4K27GA00007CB000200DIA   0001298200Y
28873662X4K27GA000094000100
28873662ABK27GA0000Q0B001000SSO   0000764100Y
28873662X4K27GA000095000100
28873663X3K27G6000078000100
28873664A4K27GA0000E3S000100DXD   0000500500Y
28873665A3K27G600007DB000100DDM   0000800800Y
28873666A7K27GA000047B002000MRO   0000520600Y
28873879AAK27GA000107S005000SPY   0001425700Y
28874352XAK27GA0000Z9002000
28874391X7K27GA000045002000
28874392X2K27G600005E002000
28874402X5K27GA00003Y002000
28874406A3K27G600007EB002000CTSH  0000054900Y
28874412X1K27GA000066002000
28874416X7K27GA000044002000
28874425X1K27GA000026002000
28874433X2K27G600005F002000
28874450XCK27GA00003C002000
28874452X3K27G600007B002000
28874457X4K27GA0000AJ002000
28874468X4K27GA0000AP002000
28874478X5K27GA00004X002000
28874478X5K27GA00004Y002000
28874481X4K27GA0000DQ000100
28874481X4K27GA0000DR000100
28874483X1K27GA000065002000
28874486A4K27GA0000E4B000100DRYS  0001070600Y
28874486A4K27GA0000E5B000100DRYS  0001070600Y
28874495X1K27GA000023002000
28874496X7K27GA000046002000
28874500X4K27GA0000E1002000
28874503X5K27GA00004Z002000
28874510ABK27GA0000Q1B002000UTX   0000141100Y
28874518ABK27GA0000Q2B002000UTX   0000140300Y
28874523A1K27GA000067B002000ABT   0000105800Y
28874526ACK27GA00003EB002000WYE   0000080900Y
28874546A2K27G600005HB002000AXP   0000407400Y
28874553A1K27GA000068B002000ABT   0000105000Y
28874565A2K27G600005IB002000CAG   0000039800Y
28874576A2K27G600005JB002000AXP   0000406600Y
28874583A2K27G600005KB002000BBT   0000061400Y
28874596A3K27G600007FB002000CVS   0000079600Y
28874597A3K27G600007GB002000COH   0000064800Y
28874620A4K27GA0000E6B002000EIX   0000092700Y
28874637A5K27GA000050B002000HOT   0000088400Y
28874664A6K27GA00008JB002000JCI   0000063200Y
28874691XAK27GA0000QB000500
28874691AAK27GA0000QBS000500SPY   0001425400Y
28874691XAK27GA0000XP001000
28874691XAK27GA0000FI000500
28874691AAK27GA0000FIB000500SPY   0001424800Y
28874691AAK27GA000108S001000SPY   0001425400Y
28874691XAK27GA0000E7001000
28874691AAK27GA0000E7B001000SPY   0001424900Y
28874692XAK27GA0000YF001000
28874692XAK27GA0000F5000500
28874692AAK27GA0000F5B000500SPY   0001424800Y
28874692X4K27GA0000CB000200
28874693AAK27GA000109B001000SDS   0000547800Y
28874693AAK27GA00010AB000100SH    0000618400Y
28874693X3K27G600006W000100
28874693A3K27G600007HS000100DDM   0000802200Y
28874693ABK27GA0000Q3S001000SSO   0000765000Y
28874693X4K27GA00009I000100
28874693A4K27GA0000E7B000100DXD   0000499600Y
28874693XBK27GA0000PM001000
28874693AAK27GA00010BS005000SPY   0001425600Y
28874693XAK27GA0000NY000500
28874693AAK27GA0000NYS000500SPY   0001425400Y
28874693AAK27GA00010CB001000SPY   0001424900Y
28874693XAK27GA000107005000
28874694XAK27GA000106002500
28874694AAK27GA00010DB002500SPY   0001425100Y
28874694XAK27GA0000ZZ000500
28874695XAK27GA000100002500
28874695AAK27GA00010EB000500SPY   0001425100Y
28874695XAK27GA000104000500
28874703X8K27G6000037000500
28874702A4K27GA0000E8S000200DIA   0001298600Y
28874703X8K27G6000038000100
28874704XAK27GA0000SY003000
28874704XAK27GA0000SX003000
28874704A8K27G600003FS000100MVV   0000809400Y
28874704A8K27G600003GB000500MZZ   0000491600Y
28874704XAK27GA0000E9001000
28874704AAK27GA0000E9S001000SPY   0001425400Y
28874704AAK27GA00010FS003000SPY   0001425600Y
28874704AAK27GA00010GS003000SPY   0001425600Y
28874706XAK27GA0000Z7001000
28874706XAK27GA0000Z2001000
28874706AAK27GA00010HS001000SPY   0001425700Y
28874711XBK27GA0000PZ001000
28874717X8K27G600002W000100
28874717A8K27G600003HS000100MVV   0000809200Y
28874717A8K27G600003IB000500MZZ   0000491700Y
28874721A6K27GA00008KS002000IWM   0000736900Y
28874721X6K27GA00006Z002000
28874727X8K27G600002V000500
28874909AAK27GA00010IS000500SPY   0001425600Y
28875101AAK27GA00010JS002500SPY   0001425600Y
28875350X3K27G600006X002000
28875383XAK27GA0000ZF002000
28875408XBK27GA0000Q2002000
28875411AAK27GA00010KB002000SHLD  0000744300Y
28875412XBK27GA0000Q1002000
28875413XCK27GA00003E002000
28875423X1K27GA000068002000
28875428X1K27GA000067002000
28875452X4K27GA0000E6002000
28875461X2K27G600005G002000
28875462X6K27GA00008K002000
28875463X6K27GA00008I002000
28875476X3K27G600007C002000
28875484A7K27GA000048B002000LMT   0000218300Y
28875488X3K27G600007F002000
28875499X5K27GA000050002000
28875502X6K27GA00006B002000
28875515X6K27GA00006K002000
28875526A2K27G600005LB002000BMY   0000037600Y
28875540X4K27GA0000E8000200
28875541A5K27GA000051B002000GM    0000176600Y
28875545A1K27GA000069B002000AFL   0000131400Y
28875552A4K27GA0000E9S000200DIA   0001298900Y
28875552A1K27GA00006AB002000ANN   0000258100Y
28875559A7K27GA000049B002000LMT   0000219100Y
28875561A2K27G600005MB002000CAG   0000039700Y
28875574ACK27GA00003FB002000WYE   0000082900Y
28875578XAK27GA0000NY000500
28875578AAK27GA0000NYS000500SPY   0001425800Y
28875578XAK27GA0000E9001000
28875578AAK27GA0000E9S001000SPY   0001425800Y
28875581XAK27GA00010B005000
28875581XAK27GA00010I000500
28875581XAK27GA0000ZR002000
28875581AAK27GA00010LS000500SPY   0001425700Y
28875581XAK27GA0000FI000500
28875581AAK27GA0000FIB000500SPY   0001425200Y
28875581XAK27GA0000E7001000
28875581AAK27GA0000E7B001000SPY   0001425300Y
28875581XAK27GA0000QB000500
28875581AAK27GA0000QBS000500SPY   0001425800Y
28875581AAK27GA00010MS005000SPY   0001425700Y
28875581XAK27GA0000O2000500
28875581AAK27GA0000O2S000500SPY   0001425900Y
28875581XAK27GA0000F5000500
28875581AAK27GA0000F5B000500SPY   0001425200Y
28875581X4K27GA00007C000200
28875581A4K27GA00007CB000200DIA   0001298500Y
28875582X4K27GA0000DZ000200
28875581AAK27GA00010NB002000SPY   0001425300Y
28875581XAK27GA00010C001000
28875581XAK27GA000108001000
28875582AAK27GA00010OB001000SPY   0001425300Y
28875583XAK27GA0000F2000500
28875583AAK27GA0000F2B000500SPY   0001425300Y
28875583ABK27GA0000Q4B001000SSO   0000763900Y
28875583AAK27GA00010PS001000SPY   0001425800Y
28875583XAK27GA00010M005000
28875584XAK27GA0000ZY001000
28875584XBK27GA0000Q3001000
28875585XAK27GA00010J002500
28875586AAK27GA00010QS002500SPY   0001425700Y
28875586ABK27GA0000Q5S001000SSO   0000765100Y
28875586XAK27GA00010D002500
28875586A4K27GA0000EAS000200DIA   0001299000Y
28875587X4K27GA0000DE000200
